Workbook

Sheet AMD Financials
A1: Income Statement ($mm)
A3: Line Item | B3: Q1 2016 | C3: Q2 2016 | D3: Q3 2016 | E3: Q4 2016 | F3: Q1 2017 | G3: Q2 2017 | H3: Q3 2017 | I3: Q4 2017 | J3: Q1 2018 | K3: Q2 2018 | L3: Q3 2018 | M3: Q4 2018 | N3: Q1 2019 | O3: Q2 2019 | P3: Q3 2019 | Q3: Q4 2019 | R3: Q1 2020 | S3: Q2 2020 | T3: Q3 2020 | U3: Q4 2020 | V3: Q1 2021 | W3: Q2 2021 | X3: Q3 2021 | Y3: Q4 2021 | Z3: Q1 2022 | AA3: Q2 2022 | AB3: Q3 2022 | AC3: Q4 2022 | AD3: Q1 2023 | AE3: Q2 2023 | AF3: Q3 2023 | AG3: Q4 2023 | AH3: Q1 2024 | AI3: Q2 2024 | AJ3: Q3 2024 | AK3: Q4 2024 | AL3: Q1 2025 | AM3: Q2 2025 | AN3: Q3 2025 | AO3: Q4 2025
A4: Revenue | B4: 832 | C4: 1027 | D4: 1307 | E4: 1106 | F4: 1178 | G4: 1151 | H4: 1584 | I4: 1340 | J4: 1647 | K4: 1756 | L4: 1653 | M4: 1419 | N4: 1272 | O4: 1531 | P4: 1801 | Q4: 2127 | R4: 1786 | S4: 1932 | T4: 2801 | U4: 3244 | V4: 3445 | W4: 3850 | X4: 4313 | Y4: 4826 | Z4: 5887 | AA4: 6550 | AB4: 5565 | AC4: 5599 | AD4: 5353 | AE4: 5359 | AF4: 5800 | AG4: 6168 | AH4: 5473 | AI4: 5835 | AJ4: 6819 | AK4: 7658 | AL4: 7438 | AM4: 7685 | AN4: 9246 | AO4: 10270
A5: Cost of Revenue | B5: 563 | C5: 708 | D5: 908 | E5: 1095 | F5: 800 | G5: 765 | H5: 1013 | I5: 888 | J5: 1050 | K5: 1104 | L5: 992 | M5: 837 | N5: 751 | O5: 910 | P5: 1024 | Q5: 1178 | R5: 968 | S5: 1084 | T5: 1571 | U5: 1793 | V5: 1858 | W5: 2020 | X5: 2227 | Y5: 2400 | Z5: 2883 | AA5: 3115 | AB5: 2799 | AC5: 2753 | AD5: 2689 | AE5: 2704 | AF5: 2843 | AG5: 3042 | AH5: 2683 | AI5: 2740 | AJ5: 3167 | AK5: 3524 | AL5: 3451 | AM5: 4366 | AN5: 4206 | AO5: 4433
A6: Gross Profit | B6: =B4-B5 -> 269 | C6: =C4-C5 -> 319 | D6: =D4-D5 -> 399 | E6: =E4-E5 -> 11 | F6: =F4-F5 -> 378 | G6: =G4-G5 -> 386 | H6: =H4-H5 -> 571 | I6: =I4-I5 -> 452 | ... AO6: =AO4-AO5 -> 5837
A7: SG&A | B7: 105 | C7: 117 | D7: 117 | E7: 121 | F7: 123 | G7: 127 | H7: 132 | I7: 134 | J7: 134 | K7: 142 | L7: 148 | M7: 138 | N7: 170 | O7: 189 | P7: 185 | Q7: 206 | R7: 199 | S7: 215 | T7: 273 | U7: 308 | V7: 319 | W7: 341 | X7: 368 | Y7: 445 | Z7: 597 | AA7: 592 | AB7: 557 | AC7: 590 | AD7: 585 | AE7: 547 | AF7: 576 | AG7: 644 | AH7: 607 | AI7: 640 | AJ7: 707 | AK7: 781 | AL7: 886 | AM7: 955 | AN7: 1069 | AO7: 1198
A8: Research & Development | B8: 242 | C8: 243 | D8: 259 | E8: 264 | F8: 271 | G8: 285 | H8: 320 | I8: 320 | J8: 343 | K8: 357 | L8: 363 | M8: 371 | N8: 373 | O8: 373 | P8: 406 | Q8: 395 | R8: 442 | S8: 460 | T8: 508 | U8: 573 | V8: 610 | W8: 659 | X8: 765 | Y8: 811 | Z8: 1060 | AA8: 1300 | AB8: 1279 | AC8: 1366 | AD8: 1411 | AE8: 1443 | AF8: 1507 | AG8: 1511 | AH8: 1525 | AI8: 1583 | AJ8: 1636 | AK8: 1712 | AL8: 1728 | AM8: 1894 | AN8: 2139 | AO8: 2330
A9: Amortization of Goodwill & Intangibles | B9: 0 | C9: 0 | D9: 0 | E9: 0 | F9: 0 | G9: 0 | H9: 0 | I9: 0 | J9: 0 | K9: 0 | L9: 0 | M9: 0 | N9: 0 | O9: 0 | P9: 0 | Q9: 0 | R9: 0 | S9: 0 | T9: 0 | U9: 0 | V9: 0 | W9: 0 | X9: 0 | Y9: 0 | Z9: 479 | AA9: 1023 | AB9: 1002 | AC9: 1044 | AD9: 823 | AE9: 693 | AF9: 660 | AG9: 635 | AH9: 622 | AI9: 603 | AJ9: 585 | AK9: 584 | AL9: 567 | AM9: 568 | AN9: 562 | AO9: 557
A10: Other Operating Expenses | B10: -7 | C10: -26 | D10: -24 | E10: -31 | F10: -27 | G10: -25 | H10: 0 | I10: 0 | J10: 0 | K10: 0 | L10: 0 | M10: 0 | N10: -60 | O10: 0 | P10: 0 | Q10: 0 | R10: 0 | S10: 0 | T10: 0 | U10: 0 | V10: -4 | W10: -1 | X10: -3 | Y10: -4 | Z10: -83 | AA10: -6 | AB10: -8 | AC10: -5 | AD10: -10 | AE10: -8 | AF10: -10 | AG10: -6 | AH10: 0 | AI10: 0 | AJ10: 0 | AK10: 0 | AL10: 0 | AM10: 0 | AN10: 0 | AO10: 0
A11: Operating Income | B11: =B6-B7-B8-B9-B10 -> -71 | C11: =C6-C7-C8-C9-C10 -> -15 | D11: =D6-D7-D8-D9-D10 -> 47 | E11: =E6-E7-E8-E9-E10 -> -343 | F11: =F6-F7-F8-F9-F10 -> 11 | G11: =G6-G7-G8-G9-G10 -> -1 | H11: =H6-H7-H8-H9-H10 -> 119 | I11: =I6-I7-I8-I9-I10 -> -2 | ... AO11: =AO6-AO7-AO8-AO9-AO10 -> 1752
A12: Interest Expense | B12: -40 | C12: -41 | D12: -41 | E12: -34 | F12: -32 | G12: -32 | H12: -31 | I12: -31 | J12: -31 | K12: -31 | L12: -30 | M12: -29 | N12: -27 | O12: -25 | P12: -24 | Q12: -18 | R12: -13 | S12: -14 | T12: -11 | U12: -9 | V12: -9 | W12: -10 | X12: -7 | Y12: -8 | Z12: -13 | AA12: -25 | AB12: -31 | AC12: -19 | AD12: -25 | AE12: -28 | AF12: -26 | AG12: -27 | AH12: -25 | AI12: -25 | AJ12: -23 | AK12: -19 | AL12: -20 | AM12: -38 | AN12: -37 | AO12: -36
A13: Interest & Investment Income | B13: 0 | C13: 0 | D13: 0 | E13: 2 | F13: 0 | G13: 0 | H13: 0 | I13: 6 | J13: 0 | K13: 0 | L13: 0 | M13: 18 | N13: 0 | O13: 0 | P13: 0 | Q13: 15 | R13: 0 | S13: 0 | T13: 0 | U13: 8 | V13: 0 | W13: 0 | X13: 0 | Y13: 8 | Z13: 0 | AA13: 0 | AB13: 22 | AC13: 32 | AD13: 0 | AE13: 0 | AF13: 0 | AG13: 206 | AH13: 0 | AI13: 0 | AJ13: 0 | AK13: 182 | AL13: 0 | AM13: 0 | AN13: 0 | AO13: 215
A14: Earnings From Equity Investments | B14: 0 | C14: -3 | D14: -5 | E14: -2 | F14: -2 | G14: -3 | H14: -2 | I14: 0 | J14: -1 | K14: -1 | L14: 0 | M14: 0 | N14: -1 | O14: 0 | P14: 1 | Q14: 0 | R14: 0 | S14: 1 | T14: 1 | U14: 3 | V14: 2 | W14: 2 | X14: 2 | Y14: 0 | Z14: 3 | AA14: 4 | AB14: 4 | AC14: 3 | AD14: 1 | AE14: 6 | AF14: 3 | AG14: 6 | AH14: 7 | AI14: 7 | AJ14: 7 | AK14: 12 | AL14: 7 | AM14: 8 | AN14: 10 | AO14: 1
A15: Currency Exchange Gain (Loss) | B15: 0 | C15: 2 | D15: 0 | E15: 1 | F15: 0 | G15: -1 | H15: -2 | I15: 0 | J15: -2 | K15: 0 | L15: 0 | M15: -1 | N15: 0 | O15: 0 | P15: 0 | Q15: 0 | R15: 0 | S15: 0 | T15: 0 | U15: 0 | V15: 0 | W15: 0 | X15: 0 | Y15: 0 | Z15: 0 | AA15: 0 | AB15: 0 | AC15: 0 | AD15: 0 | AE15: 0 | AF15: 0 | AG15: 0 | AH15: 0 | AI15: 0 | AJ15: 0 | AK15: 0 | AL15: 0 | AM15: 0 | AN15: 0 | AO15: 0
A16: Other Non Operating Income (Expenses) | B16: 0 | C16: -2 | D16: -2 | E16: 1 | F16: 2 | G16: 1 | H16: -1 | I16: -4 | J16: 4 | K16: 1 | L16: 0 | M16: -8 | N16: 1 | O16: 3 | P16: 0 | Q16: -12 | R16: 4 | S16: 1 | T16: -59 | U16: 51 | V16: 3 | W16: 0 | X16: 2 | Y16: 0 | Z16: 2 | AA16: -4 | AB16: 0 | AC16: 5 | AD16: 43 | AE16: 46 | AF16: 59 | AG16: -156 | AH16: 53 | AI16: 55 | AJ16: 36 | AK16: -147 | AL16: 39 | AM16: 98 | AN16: 82 | AO16: 509
A17: Merger & Restructuring Charges | B17: 3 | C17: 7 | D17: 0 | E17: 0 | F17: 0 | G17: 0 | H17: 0 | I17: 0 | J17: 0 | K17: 0 | L17: 0 | M17: 0 | N17: 0 | O17: 0 | P17: 0 | Q17: 0 | R17: 0 | S17: 0 | T17: 0 | U17: 0 | V17: 0 | W17: 0 | X17: -8 | Y17: 33 | Z17: 0 | AA17: 0 | AB17: 0 | AC17: 0 | AD17: 0 | AE17: 0 | AF17: 0 | AG17: 0 | AH17: 0 | AI17: 0 | AJ17: 0 | AK17: -186 | AL17: 0 | AM17: -36 | AN17: 0 | AO17: 0
A18: Gain (Loss) on Sale of Investments | B18: 0 | C18: 150 | D18: 0 | E18: -4 | F18: -3 | G18: 0 | H18: 0 | I18: 3 | J18: 0 | K18: 0 | L18: 0 | M18: 0 | N18: 0 | O18: 0 | P18: 0 | Q18: 0 | R18: 0 | S18: 0 | T18: 60 | U18: -58 | V18: -8 | W18: 0 | X18: 60 | Y18: -4 | Z18: -44 | AA18: 0 | AB18: 0 | AC18: -5 | AD18: 0 | AE18: 0 | AF18: 0 | AG18: -1 | AH18: 0 | AI18: 0 | AJ18: 0 | AK18: 2 | AL18: 0 | AM18: 0 | AN18: 0 | AO18: -366
A19: Asset Writedown | B19: 0 | C19: 0 | D19: 0 | E19: 0 | F19: 0 | G19: 0 | H19: 0 | I19: 0 | J19: 0 | K19: 0 | L19: 0 | M19: -45 | N19: 0 | O19: 0 | P19: 0 | Q19: 0 | R19: 0 | S19: 0 | T19: 0 | U19: 0 | V19: 0 | W19: 0 | X19: 0 | Y19: 0 | Z19: 0 | AA19: 0 | AB19: 0 | AC19: 0 | AD19: 0 | AE19: 0 | AF19: 0 | AG19: 0 | AH19: 0 | AI19: 0 | AJ19: 0 | AK19: 0 | AL19: 0 | AM19: 0 | AN19: 0 | AO19: 0
A20: Other Unusual Items | B20: 0 | C20: 0 | D20: -401 | E20: 333 | F20: -4 | G20: -3 | H20: 0 | I20: -3 | J20: -1 | K20: 0 | L20: -6 | M20: -5 | N20: -8 | O20: 0 | P20: -36 | Q20: -128 | R20: 0 | S20: 0 | T20: -38 | U20: -16 | V20: -6 | W20: 0 | X20: 0 | Y20: 0 | Z20: 0 | AA20: 0 | AB20: 0 | AC20: 0 | AD20: 0 | AE20: 0 | AF20: 0 | AG20: 0 | AH20: 0 | AI20: 0 | AJ20: 0 | AK20: 0 | AL20: 0 | AM20: 0 | AN20: 0 | AO20: 0
A21: Pretax Income | B21: =SUM(B11:B20) -> -108 | C21: =SUM(C11:C20) -> 98 | D21: =SUM(D11:D20) -> -402 | E21: =SUM(E11:E20) -> -46 | F21: =SUM(F11:F20) -> -28 | G21: =SUM(G11:G20) -> -39 | H21: =SUM(H11:H20) -> 83 | I21: =SUM(I11:I20) -> -31 | ... AO21: =SUM(AO11:AO20) -> 2075
A22: Income Tax Expense | B22: 1 | C22: 29 | D22: 4 | E22: 5 | F22: 5 | G22: 3 | H22: 22 | I22: -12 | J22: 8 | K22: 6 | L22: 12 | M22: -35 | N22: -13 | O22: 2 | P22: 7 | Q22: 35 | R22: 6 | S22: 4 | T22: 12 | U22: -1232 | V22: 89 | W22: 113 | X22: 82 | Y22: 229 | Z22: 113 | AA22: 54 | AB22: -135 | AC22: -154 | AD22: 13 | AE22: -23 | AF22: -39 | AG22: -297 | AH22: -52 | AI22: 41 | AJ22: -27 | AK22: 419 | AL22: 123 | AM22: -834 | AN22: 153 | AO22: 455
A23: Earnings From Discontinued Operations | B23: 0 | C23: 0 | D23: 0 | E23: 0 | F23: 0 | G23: 0 | H23: 0 | I23: 0 | J23: 0 | K23: 0 | L23: 0 | M23: 0 | N23: 0 | O23: 0 | P23: 0 | Q23: 0 | R23: 0 | S23: 0 | T23: 0 | U23: 0 | V23: 0 | W23: 0 | X23: 0 | Y23: 0 | Z23: 0 | AA23: 0 | AB23: 0 | AC23: 0 | AD23: 0 | AE23: 0 | AF23: 0 | AG23: 0 | AH23: 0 | AI23: 0 | AJ23: 0 | AK23: 0 | AL23: 0 | AM23: 104 | AN23: 71 | AO23: -109
A24: Net Income | B24: =B21-B22+B23 -> -109 | C24: =C21-C22+C23 -> 69 | D24: =D21-D22+D23 -> -406 | E24: =E21-E22+E23 -> -51 | F24: =F21-F22+F23 -> -33 | G24: =G21-G22+G23 -> -42 | H24: =H21-H22+H23 -> 61 | I24: =I21-I22+I23 -> -19 | ... AO24: =AO21-AO22+AO23 -> 1511
A25: Shares Outstanding (Basic) | B25: 793 | C25: 794 | D25: 815 | E25: 931 | F25: 939 | G25: 945 | H25: 957 | I25: 965 | J25: 968 | K25: 972 | L25: 987 | M25: 1002 | N25: 1044 | O25: 1084 | P25: 1097 | Q25: 1140 | R25: 1170 | S25: 1174 | T25: 1184 | U25: 1205 | V25: 1213 | W25: 1216 | X25: 1214 | Y25: 1208 | Z25: 1393 | AA25: 1618 | AB25: 1615 | AC25: 1613 | AD25: 1611 | AE25: 1612 | AF25: 1616 | AG25: 1616 | AH25: 1617 | AI25: 1618 | AJ25: 1620 | AK25: 1623 | AL25: 1620 | AM25: 1623 | AN25: 1626 | AO25: 1630
A26: Shares Outstanding (Diluted) | B26: 793 | C26: 821 | D26: 815 | E26: 931 | F26: 939 | G26: 945 | H26: 1042 | I26: 1037 | J26: 1039 | K26: 1147 | L26: 1076 | M26: 1079 | N26: 1094 | O26: 1109 | P26: 1117 | Q26: 1188 | R26: 1224 | S26: 1227 | T26: 1215 | U26: 1226 | V26: 1231 | W26: 1232 | X26: 1230 | Y26: 1222 | Z26: 1410 | AA26: 1632 | AB26: 1625 | AC26: 1618 | AD26: 1611 | AE26: 1627 | AF26: 1629 | AG26: 1628 | AH26: 1639 | AI26: 1637 | AJ26: 1636 | AK26: 1634 | AL26: 1626 | AM26: 1630 | AN26: 1641 | AO26: 1649
A27: EPS (Basic) | B27: =B$24/B25 -> -0.13745271 | C27: =C$24/C25 -> 0.086901763 | D27: =D$24/D25 -> -0.49815951 | E27: =E$24/E25 -> -0.054779807 | F27: =F$24/F25 -> -0.03514377 | G27: =G$24/G25 -> -0.044444444 | H27: =H$24/H25 -> 0.063740857 | I27: =I$24/I25 -> -0.019689119 | ... AO27: =AO$24/AO25 -> 0.92699387
A28: EPS (Diluted) | B28: =B$24/B26 -> -0.13745271 | C28: =C$24/C26 -> 0.084043849 | D28: =D$24/D26 -> -0.49815951 | E28: =E$24/E26 -> -0.054779807 | F28: =F$24/F26 -> -0.03514377 | G28: =G$24/G26 -> -0.044444444 | H28: =H$24/H26 -> 0.058541267 | I28: =I$24/I26 -> -0.018322083 | ... AO28: =AO$24/AO26 -> 0.91631292
A29: EBITDA | B29: =B31+B30 -> -45 | C29: =C31+C30 -> -8 | D29: =D31+D30 -> 56 | E29: =E31+E30 -> -340 | F29: =F31+F30 -> 18 | G29: =G31+G30 -> 9 | H29: =H31+H30 -> 155 | I29: =I31+I30 -> 37 | ... AO29: =AO31+AO30 -> 3060
A30: D&A For EBITDA | B30: =B84 -> 33 | C30: =C84 -> 33 | D30: =D84 -> 33 | E30: =E84 -> 34 | F30: =F84 -> 34 | G30: =G84 -> 35 | H30: =H84 -> 36 | I30: =I84 -> 39 | ... AO30: =AO84 -> 751
A31: EBIT | B31: =B11+B10+B9 -> -78 | C31: =C11+C10+C9 -> -41 | D31: =D11+D10+D9 -> 23 | E31: =E11+E10+E9 -> -374 | F31: =F11+F10+F9 -> -16 | G31: =G11+G10+G9 -> -26 | H31: =H11+H10+H9 -> 119 | I31: =I11+I10+I9 -> -2 | ... AO31: =AO11+AO10+AO9 -> 2309
A32: Normalized NI | B32: =B31+B12-B22 -> -119 | C32: =C31+C12-C22 -> -111 | D32: =D31+D12-D22 -> -22 | E32: =E31+E12-E22 -> -413 | F32: =F31+F12-F22 -> -53 | G32: =G31+G12-G22 -> -61 | H32: =H31+H12-H22 -> 66 | I32: =I31+I12-I22 -> -21 | ... AO32: =AO31+AO12-AO22 -> 1818
A33: Normalized EPS | B33: =B32/B26 -> -0.15006305 | C33: =C32/C26 -> -0.13520097 | D33: =D32/D26 -> -0.026993865 | E33: =E32/E26 -> -0.44360902 | F33: =F32/F26 -> -0.056443024 | G33: =G32/G26 -> -0.064550265 | H33: =H32/H26 -> 0.063339731 | I33: =I32/I26 -> -0.020250723 | ... AO33: =AO32/AO26 -> 1.1024864
A36: Balance Sheet ($mm)
A38: Line Item | B38: Q1 2016 | C38: Q2 2016 | D38: Q3 2016 | E38: Q4 2016 | F38: Q1 2017 | G38: Q2 2017 | H38: Q3 2017 | I38: Q4 2017 | J38: Q1 2018 | K38: Q2 2018 | L38: Q3 2018 | M38: Q4 2018 | N38: Q1 2019 | O38: Q2 2019 | P38: Q3 2019 | Q38: Q4 2019 | R38: Q1 2020 | S38: Q2 2020 | T38: Q3 2020 | U38: Q4 2020 | V38: Q1 2021 | W38: Q2 2021 | X38: Q3 2021 | Y38: Q4 2021 | Z38: Q1 2022 | AA38: Q2 2022 | AB38: Q3 2022 | AC38: Q4 2022 | AD38: Q1 2023 | AE38: Q2 2023 | AF38: Q3 2023 | AG38: Q4 2023 | AH38: Q1 2024 | AI38: Q2 2024 | AJ38: Q3 2024 | AK38: Q4 2024 | AL38: Q1 2025 | AM38: Q2 2025 | AN38: Q3 2025 | AO38: Q4 2025
A39: Cash & Equivalents | B39: 716 | C39: 957 | D39: 1258 | E39: 1264 | F39: 722 | G39: 760 | H39: 879 | I39: 1185 | J39: 1045 | K39: 948 | L39: 1046 | M39: 1078 | N39: 978 | O39: 963 | P39: 1156 | Q39: 1466 | R39: 1330 | S39: 1775 | T39: 1296 | U39: 1595 | V39: 1763 | W39: 2623 | X39: 2440 | Y39: 2535 | Z39: 4740 | AA39: 4964 | AB39: 3398 | AC39: 4835 | AD39: 3825 | AE39: 3841 | AF39: 3561 | AG39: 3933 | AH39: 4190 | AI39: 4113 | AJ39: 3897 | AK39: 3787 | AL39: 6049 | AM39: 4442 | AN39: 4808 | AO39: 5539
A40: Short-Term Investments | B40: 0 | C40: 0 | D40: 0 | E40: 0 | F40: 221 | G40: 84 | H40: 0 | I40: 0 | J40: 0 | K40: 35 | L40: 10 | M40: 78 | N40: 216 | O40: 165 | P40: 53 | Q40: 37 | R40: 55 | S40: 0 | T40: 475 | U40: 695 | V40: 1353 | W40: 1170 | X40: 1168 | Y40: 1073 | Z40: 1792 | AA40: 1028 | AB40: 2193 | AC40: 1020 | AD40: 2114 | AE40: 2444 | AF40: 2224 | AG40: 1840 | AH40: 1845 | AI40: 1227 | AJ40: 647 | AK40: 1345 | AL40: 1261 | AM40: 1425 | AN40: 2435 | AO40: 5013
A41: Cash & Short-Term Investments | B41: =SUM(B39:B40) -> 716 | C41: =SUM(C39:C40) -> 957 | D41: =SUM(D39:D40) -> 1258 | E41: =SUM(E39:E40) -> 1264 | F41: =SUM(F39:F40) -> 943 | G41: =SUM(G39:G40) -> 844 | H41: =SUM(H39:H40) -> 879 | I41: =SUM(I39:I40) -> 1185 | ... AO41: =SUM(AO39:AO40) -> 10552
A42: Receivables | B42: 508 | C42: 671 | D42: 640 | E42: 311 | F42: 514 | G42: 616 | H42: 776 | I42: 457 | J42: 745 | K42: 1118 | L42: 1245 | M42: 1251 | N42: 1279 | O42: 1363 | P42: 1410 | Q42: 1879 | R42: 1695 | S42: 1799 | T42: 2138 | U42: 2076 | V42: 2185 | W42: 2026 | X42: 2229 | Y42: 2708 | Z42: 3681 | AA42: 4053 | AB42: 4340 | AC42: 4128 | AD42: 4042 | AE42: 4314 | AF42: 5055 | AG42: 5385 | AH42: 5069 | AI42: 5773 | AJ42: 7270 | AK42: 6192 | AL42: 6286 | AM42: 5686 | AN42: 6513 | AO42: 6315
A43: Inventory | B43: 675 | C43: 743 | D43: 772 | E43: 751 | F43: 839 | G43: 833 | H43: 794 | I43: 694 | J43: 715 | K43: 750 | L43: 738 | M43: 845 | N43: 955 | O43: 1015 | P43: 1040 | Q43: 982 | R43: 1056 | S43: 1324 | T43: 1292 | U43: 1399 | V43: 1653 | W43: 1765 | X43: 1902 | Y43: 1955 | Z43: 2880 | AA43: 3048 | AB43: 4088 | AC43: 3771 | AD43: 5102 | AE43: 5409 | AF43: 5358 | AG43: 4351 | AH43: 4652 | AI43: 4991 | AJ43: 5374 | AK43: 5734 | AL43: 6416 | AM43: 6677 | AN43: 7313 | AO43: 7920
A44: Prepaid Expenses | B44: 75 | C44: 80 | D44: 76 | E44: 95 | F44: 84 | G44: 76 | H44: 93 | I44: 107 | J44: 78 | K44: 93 | L44: 75 | M44: 277 | N44: 77 | O44: 235 | P44: 242 | Q44: 225 | R44: 246 | S44: 207 | T44: 295 | U44: 378 | V44: 243 | W44: 234 | X44: 249 | Y44: 312 | Z44: 0 | AA44: 0 | AB44: 0 | AC44: 1265 | AD44: 0 | AE44: 0 | AF44: 0 | AG44: 0 | AH44: 1328 | AI44: 1361 | AJ44: 1547 | AK44: 1967 | AL44: 0 | AM44: 0 | AN44: 0 | AO44: 2143
...

Sheet Key Metrics
B2: AMD | C2: 215
B3: Shares | C3: ='AMD Financials'!AO26 -> 1649
B4: MC | C4: =C3*C2 -> 354535
B5: Cash | C5: ='AMD Financials'!AO41 -> 10552
B6: Debt | C6: =SUM('AMD Financials'!AO57,'AMD Financials'!AO58,'AMD Financials'!AO59,'AMD Financials'!AO64,'AMD Financials'!AO65) -> 4006
B7: EV | C7: =C4-C5+C6 -> 347989
B8: EPS Yield | C8: =SUM('AMD Financials'!AL33:AO33)/'Key Metrics'!C2 -> 0.016912746
B9: EBIT Yield | C9: =SUM('AMD Financials'!AL31:AO31)/'Key Metrics'!C7 -> 0.017195946
B10: EBITDA Yield | C10: =SUM('AMD Financials'!AL29:AO29)/'Key Metrics'!C7 -> 0.025828403
B11: FCF Yield | C11: =SUM('AMD Financials'!AL114:AO114)/'Key Metrics'!C2 -> 0.011003157
