Workbook

Sheet IS - Quarterly
A1: AeroVironment, Inc. - Income Statement
A2: USD mm, except per share data
B3: Actual | AU3: Forecast
A4: Fiscal quarter end | B4: 1/31/15 | C4: 4/30/15 | D4: 8/1/15 | E4: 10/31/15 | F4: 1/30/16 | G4: 4/30/16 | H4: 7/30/16 | I4: 10/29/16 | J4: 1/28/17 | K4: 4/30/17 | L4: 7/29/17 | M4: 10/28/17 | N4: 1/27/18 | O4: 4/30/18 | P4: 7/28/18 | Q4: 10/27/18 | R4: 1/26/19 | S4: 4/30/19 | T4: 7/27/19 | U4: 10/26/19 | V4: 1/25/20 | W4: 4/30/20 | X4: 8/1/20 | Y4: 10/31/20 | Z4: 1/30/21 | AA4: 4/30/21 | AB4: 7/31/21 | AC4: 10/30/21 | AD4: 1/29/22 | AE4: 4/30/22 | AF4: 7/30/22 | AG4: 10/29/22 | AH4: 1/28/23 | AI4: 4/30/23 | AJ4: 7/29/23 | AK4: 10/28/23 | AL4: 1/27/24 | AM4: 4/30/24 | AN4: 7/27/24 | AO4: 10/26/24 | AP4: 1/25/25 | AQ4: 4/30/25 | AR4: 8/2/25 | AS4: 11/1/25 | AT4: 1/31/26 | AU4: 4/30/26 | AV4: 8/1/26 | AW4: 10/31/26 | AX4: 1/30/27 | AY4: 4/30/27 | AZ4: 7/31/27 | BA4: 10/30/27 | BB4: 1/29/28
A5: Revenue
A6: Product sales | B6: 56.308 | C6: 63.034 | D6: 26.639 | E6: 49.492 | F6: 53.305 | G6: 60.04 | H6: 15.737 | I6: 29.35 | J6: 36.746 | K6: 111.505 | L6: 18.78 | M6: 48.42 | N6: 39.447 | O6: 85.065 | P6: 55.313 | Q6: 47.056 | R6: 50.024 | S6: 59.696 | T6: 65.839 | U6: 57.386 | V6: 36.432 | W6: 97.101 | X6: 58.357 | Y6: 65.528 | Z6: 58.348 | AA6: 96.655 | AB6: 53.116 | AC6: 70.998 | AD6: 42.599 | AE6: 73.97 | AF6: 57.974 | AG6: 62.343 | AH6: 91.216 | AI6: 141.529 | AJ6: 119.471 | AK6: 145.779 | AL6: 155.923 | AM6: 164.598 | AN6: 159.504 | AO6: 151.231 | AP6: 139.753 | AQ6: 242.234 | AR6: 313.533 | AS6: 325.037 | AT6: 277.814 | AU6: ='KPI Rev by Type'!AA6 -> 395.32932 | AV6: ='KPI Rev by Type'!AB6 -> 376.2396 | AW6: ='KPI Rev by Type'!AC6 -> 390.0444 | AX6: ='KPI Rev by Type'!AD6 -> 333.3768 | AY6: ='KPI Rev by Type'!AE6 -> 474.39519 | AZ6: ='KPI Rev by Type'!AF6 -> 425.15075 | BA6: ='KPI Rev by Type'!AG6 -> 440.75017 | BB6: ='KPI Rev by Type'!AH6 -> 376.71578
A7: Contract services | B7: 12.089 | C7: 23.437 | D7: 20.411 | E7: 15.239 | F7: 14.255 | G7: 24.717 | H7: 20.481 | I7: 20.766 | J7: 16.417 | K7: 13.871 | L7: 15.581 | M7: 17.381 | N7: 15.186 | O7: 28.564 | P7: 22.73 | Q7: 25.923 | R7: 25.298 | S7: 28.234 | T7: 21.072 | U7: 25.885 | V7: 25.459 | W7: 38.122 | X7: 29.093 | Y7: 27.137 | Z7: 20.434 | AA7: 39.36 | AB7: 47.893 | AC7: 51.01 | AD7: 47.494 | AE7: 58.652 | AF7: 50.542 | AG7: 49.241 | AH7: 43.179 | AI7: 44.512 | AJ7: 32.876 | AK7: 35.037 | AL7: 30.655 | AM7: 32.381 | AN7: 29.979 | AO7: 37.227 | AP7: 27.883 | AQ7: 32.816 | AR7: 141.143 | AS7: 147.471 | AT7: 130.231 | AU7: ='KPI Rev by Type'!AA7 -> 169.43053 | AV7: ='KPI Rev by Type'!AB7 -> 151.02301 | AW7: ='KPI Rev by Type'!AC7 -> 157.79397 | AX7: ='KPI Rev by Type'!AD7 -> 139.34717 | AY7: ='KPI Rev by Type'!AE7 -> 181.29067 | AZ7: ='KPI Rev by Type'!AF7 -> 160.08439 | BA7: ='KPI Rev by Type'!AG7 -> 167.26161 | BB7: ='KPI Rev by Type'!AH7 -> 147.708
A8: Total revenue | B8: =SUM(B6,B7) -> 68.397 | C8: =SUM(C6,C7) -> 86.471 | D8: =SUM(D6,D7) -> 47.05 | E8: =SUM(E6,E7) -> 64.731 | F8: =SUM(F6,F7) -> 67.56 | G8: =SUM(G6,G7) -> 84.757 | H8: =SUM(H6,H7) -> 36.218 | I8: =SUM(I6,I7) -> 50.116 | ... AT8: =SUM(AT6,AT7) -> 408.045 | AU8: =SUM(AU6:AU7) -> 564.75985 | AV8: =SUM(AV6:AV7) -> 527.26261 | AW8: =SUM(AW6:AW7) -> 547.83837 | AX8: =SUM(AX6:AX7) -> 472.72397 | AY8: =SUM(AY6:AY7) -> 655.68585 | AZ8: =SUM(AZ6:AZ7) -> 585.23514 | BA8: =SUM(BA6:BA7) -> 608.01178 | BB8: =SUM(BB6:BB7) -> 524.42378
A9: Cost of Sales
A10: Product sales | B10: 32.901 | C10: 27.357 | D10: 16.765 | E10: 24.802 | F10: 31.91 | G10: 32.51 | H10: 15.222 | I10: 19.197 | J10: 23.641 | K10: 57.453 | L10: 15.972 | M10: 25.196 | N10: 24.87 | O10: 43.355 | P10: 29.811 | Q10: 26.567 | R10: 26.78 | S10: 30.331 | T10: 30.408 | U10: 30.802 | V10: 21.034 | W10: 56.887 | X10: 32.084 | Y10: 34.209 | Z10: 35.746 | AA10: 47.675 | AB10: 32.59 | AC10: 38.937 | AD10: 29.294 | AE10: 39.775 | AF10: 32.899 | AG10: 39.445 | AH10: 54.866 | AI10: 76.209 | AJ10: 61.608 | AK10: 79.032 | AL10: 99.486 | AM10: 100.048 | AN10: 85.519 | AO10: 87.052 | AP10: 81.001 | AQ10: 150.775 | AR10: 230.687 | AS10: 241.397 | AT10: 199.973 | AU10: =AU6*(1-Assumptions!$D$43) -> 276.73053 | AV10: =AV6*(1-Assumptions!$E$43) -> 259.60532 | AW10: =AW6*(1-Assumptions!$F$43) -> 269.13064 | AX10: =AX6*(1-Assumptions!$G$43) -> 230.02999 | AY10: =AY6*(1-Assumptions!$H$43) -> 327.33268 | AZ10: =AZ6*(1-Assumptions!$I$43) -> 286.97675 | BA10: =BA6*(1-Assumptions!$J$43) -> 297.50637 | BB10: =BB6*(1-Assumptions!$K$43) -> 254.28315
A11: Contract services | B11: 8.503 | C11: 13.764 | D11: 14.262 | E11: 8.396 | F11: 9.025 | G11: 14.325 | H11: 14.313 | I11: 13.502 | J11: 10.171 | K11: 9.207 | L11: 9.691 | M11: 10.462 | N11: 11.513 | O11: 19.68 | P11: 15.643 | Q11: 18.013 | R11: 18.15 | S11: 20.576 | T11: 15.231 | U11: 17.303 | V11: 17.361 | W11: 25.168 | X11: 19.955 | Y11: 17.605 | Z11: 14.395 | AA11: 28.685 | AB11: 39.696 | AC11: 40.616 | AD11: 39.363 | AE11: 44.225 | AF11: 41.903 | AG11: 46.249 | AH11: 34.019 | AI11: 41.432 | AJ11: 25.079 | AK11: 26.434 | AL11: 19.805 | AM11: 21.297 | AN11: 22.497 | AO11: 27.768 | AP11: 23.436 | AQ11: 23.943 | AR11: 128.871 | AS11: 127.006 | AT11: 109.278 | AU11: =AU7*(1-Assumptions!$D$44) -> 141.47449 | AV11: =AV7*(1-Assumptions!$E$44) -> 124.59398 | AW11: =AW7*(1-Assumptions!$F$44) -> 130.18003 | AX11: =AX7*(1-Assumptions!$G$44) -> 114.96142 | AY11: =AY7*(1-Assumptions!$H$44) -> 149.5648 | AZ11: =AZ7*(1-Assumptions!$I$44) -> 130.46878 | BA11: =BA7*(1-Assumptions!$J$44) -> 136.31821 | BB11: =BB7*(1-Assumptions!$K$44) -> 120.38202
A12: Total cost of sales | B12: =SUM(B10,B11) -> 41.404 | C12: =SUM(C10,C11) -> 41.121 | D12: =SUM(D10,D11) -> 31.027 | E12: =SUM(E10,E11) -> 33.198 | F12: =SUM(F10,F11) -> 40.935 | G12: =SUM(G10,G11) -> 46.835 | H12: =SUM(H10,H11) -> 29.535 | I12: =SUM(I10,I11) -> 32.699 | ... BB12: =SUM(BB10,BB11) -> 374.66517
A13: Gross Profit
A14: Product sales gross profit | B14: =B6-B10 -> 23.407 | C14: =C6-C10 -> 35.677 | D14: =D6-D10 -> 9.874 | E14: =E6-E10 -> 24.69 | F14: =F6-F10 -> 21.395 | G14: =G6-G10 -> 27.53 | H14: =H6-H10 -> 0.515 | I14: =I6-I10 -> 10.153 | ... BB14: =BB6-BB10 -> 122.43263
A15: Contract services gross profit | B15: =B7-B11 -> 3.586 | C15: =C7-C11 -> 9.673 | D15: =D7-D11 -> 6.149 | E15: =E7-E11 -> 6.843 | F15: =F7-F11 -> 5.23 | G15: =G7-G11 -> 10.392 | H15: =H7-H11 -> 6.168 | I15: =I7-I11 -> 7.264 | ... BB15: =BB7-BB11 -> 27.32598
A16: Gross profit | B16: =B8-B12 -> 26.993 | C16: =C8-C12 -> 45.35 | D16: =D8-D12 -> 16.023 | E16: =E8-E12 -> 31.533 | F16: =F8-F12 -> 26.625 | G16: =G8-G12 -> 37.922 | H16: =H8-H12 -> 6.683 | I16: =I8-I12 -> 17.417 | ... BB16: =BB8-BB12 -> 149.75861
A17: Operating Expenses
A18: Selling, general and administrative | B18: 13.268 | C18: 15.622 | D18: 15.256 | E18: 14.733 | F18: 13.313 | G18: 16.775 | H18: 13.663 | I18: 13.387 | J18: 12.788 | K18: 16.699 | L18: 11.287 | M18: 12.768 | N18: 11.484 | O18: 15.287 | P18: 11.956 | Q18: 13.646 | R18: 14.464 | S18: 20.277 | T18: 13.668 | U18: 16.255 | V18: 13.223 | W18: 16.344 | X18: 12.011 | Y18: 14.977 | Z18: 15.652 | AA18: 24.841 | AB18: 27.128 | AC18: 24.819 | AD18: 22.549 | AE18: 21.938 | AF18: 21.943 | AG18: 23.613 | AH18: 24.746 | AI18: 61.603 | AJ18: 23.827 | AK18: 28.147 | AL18: 27.826 | AM18: 34.62 | AN18: 33.795 | AO18: 37.916 | AP18: 43.788 | AQ18: 43.254 | AR18: 131.276 | AS18: 98.336 | AT18: 99.414 | AU18: =AU8*Assumptions!$D$45 -> 112.95197 | AV18: =AV8*Assumptions!$E$45 -> 97.543583 | AW18: =AW8*Assumptions!$F$45 -> 101.3501 | AX18: =AX8*Assumptions!$G$45 -> 87.453934 | AY18: =AY8*Assumptions!$H$45 -> 121.30188 | AZ18: =AZ8*Assumptions!$I$45 -> 99.489974 | BA18: =BA8*Assumptions!$J$45 -> 103.362 | BB18: =BB8*Assumptions!$K$45 -> 89.152043
A19: Research and development | B19: 8.577 | C19: 22.259 | D19: 9.831 | E19: 9.897 | F19: 8.247 | G19: 14.316 | H19: 8.6 | I19: 8.517 | J19: 7.988 | K19: 7.937 | L19: 5.542 | M19: 6.844 | N19: 6.607 | O19: 7.44 | P19: 6.435 | Q19: 8.109 | R19: 8.087 | S19: 11.603 | T19: 8.709 | U19: 10.858 | V19: 11.381 | W19: 15.529 | X19: 11.103 | Y19: 11.976 | Z19: 13.631 | AA19: 17.054 | AB19: 13.708 | AC19: 14.297 | AD19: 13.013 | AE19: 13.671 | AF19: 15.045 | AG19: 16.591 | AH19: 16.157 | AI19: 16.462 | AJ19: 15.466 | AK19: 22.025 | AL19: 25.127 | AM19: 35.069 | AN19: 24.613 | AO19: 28.716 | AP19: 22.498 | AQ19: 24.902 | AR19: 33.114 | AS19: 35.993 | AT19: 27.112 | AU19: =AU8*Assumptions!$D$46 -> 36.70939 | AV19: =AV8*Assumptions!$E$46 -> 34.27207 | AW19: =AW8*Assumptions!$F$46 -> 35.609494 | AX19: =AX8*Assumptions!$G$46 -> 30.727058 | AY19: =AY8*Assumptions!$H$46 -> 42.619581 | AZ19: =AZ8*Assumptions!$I$46 -> 38.040284 | BA19: =BA8*Assumptions!$J$46 -> 39.520766 | BB19: =BB8*Assumptions!$K$46 -> 34.087546
A20: Impairment of goodwill | AQ20: 18.359 | AT20: 240.708 | AU20: =Assumptions!$D$47 -> 0 | AV20: =Assumptions!$E$47 -> 0 | AW20: =Assumptions!$F$47 -> 0 | AX20: =Assumptions!$G$47 -> 0 | AY20: =Assumptions!$H$47 -> 0 | AZ20: =Assumptions!$I$47 -> 0 | BA20: =Assumptions!$J$47 -> 0 | BB20: =Assumptions!$K$47 -> 0
A21: Other operating expense, net | AI21: 156.017 | AU21: =Assumptions!$D$48 -> 0 | AV21: =Assumptions!$E$48 -> 0 | AW21: =Assumptions!$F$48 -> 0 | AX21: =Assumptions!$G$48 -> 0 | AY21: =Assumptions!$H$48 -> 0 | AZ21: =Assumptions!$I$48 -> 0 | BA21: =Assumptions!$J$48 -> 0 | BB21: =Assumptions!$K$48 -> 0
A22: Total operating expenses | B22: =SUM(B18,B19,B20,B21) -> 21.845 | C22: =SUM(C18,C19,C20,C21) -> 37.881 | D22: =SUM(D18,D19,D20,D21) -> 25.087 | E22: =SUM(E18,E19,E20,E21) -> 24.63 | F22: =SUM(F18,F19,F20,F21) -> 21.56 | G22: =SUM(G18,G19,G20,G21) -> 31.091 | H22: =SUM(H18,H19,H20,H21) -> 22.263 | I22: =SUM(I18,I19,I20,I21) -> 21.904 | ... BB22: =SUM(BB18,BB19,BB20,BB21) -> 123.23959
A23: Operating income | B23: =B16-B22 -> 5.148 | C23: =C16-C22 -> 7.469 | D23: =D16-D22 -> -9.064 | E23: =E16-E22 -> 6.903 | F23: =F16-F22 -> 5.065 | G23: =G16-G22 -> 6.831 | H23: =H16-H22 -> -15.58 | I23: =I16-I22 -> -4.487 | ... BB23: =BB16-BB22 -> 26.519021
A24: Other Income / Expense
A25: Interest income (expense), net | B25: 0.224 | C25: 0.253 | D25: 0.224 | E25: 0.268 | F25: 0.181 | G25: 0.359 | H25: 0.375 | I25: 0.397 | J25: 0.39 | K25: 0.456 | L25: 0.512 | M25: 0.432 | N25: 0.545 | O25: 0.751 | P25: 0.906 | Q25: 1.068 | R25: 1.272 | S25: 1.426 | T25: 1.329 | U25: 1.266 | V25: 1.122 | W25: 1.111 | X25: 0.208 | Y25: 0.115 | Z25: 0.094 | AA25: -1.035 | AB25: -1.275 | AC25: -1.379 | AD25: -1.51 | AE25: -1.276 | AF25: -1.603 | AG25: -2.309 | AH25: -2.81 | AI25: -2.646 | AJ25: -2.008 | AK25: -1.95 | AL25: -0.114 | AM25: -0.148 | AN25: -0.239 | AO25: -0.69 | AP25: -0.248 | AQ25: -1.011 | AR25: -17.415 | AS25: 4.669 | AT25: 3.696 | AU25: =Assumptions!$D$49 -> 2 | AV25: =Assumptions!$E$49 -> 2 | AW25: =Assumptions!$F$49 -> 2 | AX25: =Assumptions!$G$49 -> 2 | AY25: =Assumptions!$H$49 -> 2 | AZ25: =Assumptions!$I$49 -> 2 | BA25: =Assumptions!$J$49 -> 2 | BB25: =Assumptions!$K$49 -> 2
A26: Other income (expense), net | B26: -0.284 | C26: -0.727 | D26: -2.389 | E26: -0.192 | F26: -0.215 | G26: 0.097 | H26: -0.3 | I26: -0.13 | J26: -0.038 | K26: 0.529 | L26: 0.004 | M26: -0.055 | N26: -0.108 | O26: 0.11 | P26: 8.388 | Q26: 1.291 | R26: 0.962 | S26: 1.339 | T26: 0.355 | U26: 0.157 | V26: 0.12 | W26: 0.075 | X26: 0.033 | Y26: 0.072 | Z26: -0.037 | AA26: -8.398 | AB26: -0.346 | AC26: -10.048 | AD26: 0.034 | AE26: 0.047 | AF26: -0.406 | AG26: 0.81 | AH26: -2.587 | AI26: 1.837 | AJ26: -1.129 | AK26: -2.858 | AL26: 1.004 | AM26: -1.39 | AN26: -0.234 | AO26: 0.016 | AP26: 0.976 | AQ26: 0.299 | AR26: 2.361 | AS26: 4.951 | AT26: -0.4 | AU26: =Assumptions!$D$50 -> 0 | AV26: =Assumptions!$E$50 -> 0 | AW26: =Assumptions!$F$50 -> 0 | AX26: =Assumptions!$G$50 -> 0 | AY26: =Assumptions!$H$50 -> 0 | AZ26: =Assumptions!$I$50 -> 0 | BA26: =Assumptions!$J$50 -> 0 | BB26: =Assumptions!$K$50 -> 0
A27: Other income (expense) / source adjustment | AE27: 6.497 | AU27: 0 | AV27: 0 | AW27: 0 | AX27: 0 | AY27: 0 | AZ27: 0 | BA27: 0 | BB27: 0
A28: Total other income (expense), net | B28: =SUM(B25,B26,B27) -> -0.06 | C28: =SUM(C25,C26,C27) -> -0.474 | D28: =SUM(D25,D26,D27) -> -2.165 | E28: =SUM(E25,E26,E27) -> 0.076 | F28: =SUM(F25,F26,F27) -> -0.034 | G28: =SUM(G25,G26,G27) -> 0.456 | H28: =SUM(H25,H26,H27) -> 0.075 | I28: =SUM(I25,I26,I27) -> 0.267 | ... BB28: =SUM(BB25,BB26,BB27) -> 2
A29: Income before income taxes | B29: =B23+B28 -> 5.088 | C29: =C23+C28 -> 6.995 | D29: =D23+D28 -> -11.229 | E29: =E23+E28 -> 6.979 | F29: =F23+F28 -> 5.031 | G29: =G23+G28 -> 7.287 | H29: =H23+H28 -> -15.505 | I29: =I23+I28 -> -4.22 | ... BB29: =BB23+BB28 -> 28.519021
A30: Provision for income taxes | B30: 2.763 | C30: -0.085 | D30: -4.248 | E30: 2.56 | F30: -1.133 | G30: 1.923 | H30: -3.863 | I30: -0.048 | J30: 1.102 | K30: 4.561 | L30: -3.221 | M30: 3.358 | N30: 0.834 | O30: 8.829 | P30: 2.567 | Q30: 1.211 | R30: 0.946 | S30: -0.083 | T30: 2.133 | U30: 1.108 | V30: -0.038 | W30: 2.645 | X30: 1.207 | Y30: 2.491 | Z30: -0.924 | AA30: -2.235 | AB30: -0.957 | AC30: -9.511 | AD30: -15.396 | AE30: 15.495 | AF30: 2.606 | AG30: -10.457 | AH30: -0.531 | AI30: -6.281 | AJ30: 1.314 | AK30: 1.137 | AL30: 1.259 | AM30: -1.819 | AN30: 1.485 | AO30: -0.221 | AP30: -0.605 | AQ30: 0.223 | AR30: -15.169 | AS30: -2.305 | AT30: -21.616 | AU30: =AU29*Assumptions!$D$52 -> -0.18810956 | AV30: =AV29*Assumptions!$E$52 -> 2.2521005 | AW30: =AW29*Assumptions!$F$52 -> 2.3065798 | AX30: =AX29*Assumptions!$G$52 -> 1.9637669 | AY30: =AY29*Assumptions!$H$52 -> 2.8673749 | AZ30: =AZ29*Assumptions!$I$52 -> 5.4840891 | BA30: =BA29*Assumptions!$J$52 -> 5.661754 | BB30: =BB29*Assumptions!$K$52 -> 4.8482335
A31: Equity method investment income (loss), net of tax | J31: -0.008 | K31: 0 | N31: -0.418 | O31: -0.865 | P31: -0.602 | Q31: -0.752 | R31: -0.717 | S31: -1.873 | T31: -1.347 | U31: -0.863 | V31: -1.2 | W31: -2.077 | X31: -1.288 | Y31: -9.522 | Z31: -0.081 | AA31: 0.41 | AB31: -1.141 | AC31: 1.133 | AD31: 0.171 | AE31: 4.426 | AF31: -0.5 | AG31: -1.273 | AH31: -0.417 | AI31: -0.263 | AJ31: -0.021 | AK31: -1.393 | AL31: -0.08 | AM31: -0.18 | AN31: 0.065 | AO31: 0.99 | AQ31: 3.782 | AR31: 1.787 | AS31: 1.196 | AT31: -0.295 | AU31: =Assumptions!$D$51 -> 0 | AV31: =Assumptions!$E$51 -> 0 | AW31: =Assumptions!$F$51 -> 0 | AX31: =Assumptions!$G$51 -> 0 | AY31: =Assumptions!$H$51 -> 0 | AZ31: =Assumptions!$I$51 -> 0 | BA31: =Assumptions!$J$51 -> 0 | BB31: =Assumptions!$K$51 -> 0
A32: Net income from continuing operations | B32: =B29-B30+B31 -> 2.325 | C32: =C29-C30+C31 -> 7.08 | D32: =D29-D30+D31 -> -6.981 | E32: =E29-E30+E31 -> 4.419 | F32: =F29-F30+F31 -> 6.164 | G32: =G29-G30+G31 -> 5.364 | H32: =H29-H30+H31 -> -11.642 | I32: =I29-I30+I31 -> -4.172 | ... BB32: =BB29-BB30+BB31 -> 23.670787
A33: Discontinued operations, net of tax | L33: -1.488 | M33: -0.033 | N33: -0.129 | O33: -2.237 | P33: 6.993 | Q33: -0.99 | R33: -0.062 | S33: -0.415 | AU33: 0 | AV33: 0 | AW33: 0 | AX33: 0 | AY33: 0 | AZ33: 0 | BA33: 0 | BB33: 0
A34: Net income | B34: =B32+B33 -> 2.325 | C34: =C32+C33 -> 7.08 | D34: =D32+D33 -> -6.981 | E34: =E32+E33 -> 4.419 | F34: =F32+F33 -> 6.164 | G34: =G32+G33 -> 5.364 | H34: =H32+H33 -> -11.642 | I34: =I32+I33 -> -4.172 | ... BB34: =BB32+BB33 -> 23.670787
A35: Net income attributable to noncontrolling interest | K35: 0.022 | L35: 0.023 | M35: 0.206 | N35: 0.009 | O35: -0.022 | P35: 0.014 | Q35: 0.007 | R35: 0.019 | S35: -0.021 | T35: 0.011 | U35: -0.004 | V35: 0.02 | W35: -0.023 | X35: 0.037 | Y35: 0.022 | Z35: -0.047 | AA35: -0.026 | AB35: -0.063 | AC35: -0.031 | AD35: 0.045 | AE35: 0.046 | AF35: -0.006 | AG35: -0.039 | AI35: 0 | AU35: =Assumptions!$D$55 -> 0 | AV35: =Assumptions!$E$55 -> 0 | AW35: =Assumptions!$F$55 -> 0 | AX35: =Assumptions!$G$55 -> 0 | AY35: =Assumptions!$H$55 -> 0 | AZ35: =Assumptions!$I$55 -> 0 | BA35: =Assumptions!$J$55 -> 0 | BB35: =Assumptions!$K$55 -> 0
A36: Net income attributable to AeroVironment, Inc. | B36: =B34+B35 -> 2.325 | C36: =C34+C35 -> 7.08 | D36: =D34+D35 -> -6.981 | E36: =E34+E35 -> 4.419 | F36: =F34+F35 -> 6.164 | G36: =G34+G35 -> 5.364 | H36: =H34+H35 -> -11.642 | I36: =I34+I35 -> -4.172 | ... BB36: =BB34+BB35 -> 23.670787
A37: Per Share Data
A38: Weighted average shares outstanding - basic | B38: 22.8905 | C38: 22.9052 | D38: 22.9475 | E38: 22.986 | F38: 22.8905 | G38: 22.9215 | H38: 22.9566 | I38: 23.0491 | J38: 23.083 | K38: 23.1466 | L38: 23.3363 | M38: 23.4779 | N38: 23.5156 | O38: 23.5519 | P38: 23.5746 | Q38: 23.6674 | R38: 23.6877 | S38: 23.718 | T38: 23.7452 | U38: 23.8044 | V38: 23.8211 | W38: 23.8496 | X38: 23.893 | Y38: 23.937 | Z38: 23.9428 | AA38: 24.4343 | AB38: 24.6202 | AC38: 24.6416 | AD38: 24.711 | AE38: 24.7689 | AF38: 24.8042 | AG38: 24.9009 | AH38: 25.0124 | AI38: 25.451 | AJ38: 26.0883 | AK38: 26.8658 | AL38: 27.9076 | AM38: 27.9163 | AN38: 27.9597 | AO38: 28.01 | AP38: 28.0319 | AQ38: 28.0686 | AR38: 46.8824 | AS38: 49.7233 | AT38: 49.7414 | AU38: =Assumptions!$D$54 -> 49.8 | AV38: =Assumptions!$E$54 -> 49.9 | AW38: =Assumptions!$F$54 -> 50 | AX38: =Assumptions!$G$54 -> 50.1 | AY38: =Assumptions!$H$54 -> 50.2 | AZ38: =Assumptions!$I$54 -> 50.3 | BA38: =Assumptions!$J$54 -> 50.4 | BB38: =Assumptions!$K$54 -> 50.5
A39: Weighted average shares outstanding - diluted | B39: 23.1094 | C39: 23.1483 | D39: 22.9475 | E39: 23.1485 | F39: 23.0838 | G39: 23.1435 | H39: 22.9566 | I39: 23.0491 | J39: 23.083 | K39: 23.3714 | L39: 23.3363 | M39: 23.833 | N39: 23.5156 | O39: 23.9169 | P39: 24.0103 | Q39: 24.0988 | R39: 24.0818 | S39: 24.0947 | T39: 24.0699 | U39: 24.0618 | V39: 23.8211 | W39: 24.1338 | X39: 24.1862 | Y39: 24.1969 | Z39: 24.2609 | AA39: 24.7799 | AB39: 24.6202 | AC39: 24.8859 | AD39: 24.8796 | AE39: 24.9362 | AF39: 24.8042 | AG39: 24.9009 | AH39: 25.0124 | AI39: 25.451 | AJ39: 26.179 | AK39: 26.9568 | AL39: 28.0441 | AM39: 28.0967 | AN39: 28.2818 | AO39: 28.1456 | AP39: 28.0319 | AQ39: 28.265 | AR39: 46.8824 | AS39: 49.7233 | AT39: 49.7414 | AU39: =Assumptions!$D$53 -> 50 | AV39: =Assumptions!$E$53 -> 50.1 | AW39: =Assumptions!$F$53 -> 50.2 | AX39: =Assumptions!$G$53 -> 50.3 | AY39: =Assumptions!$H$53 -> 50.4 | AZ39: =Assumptions!$I$53 -> 50.5 | BA39: =Assumptions!$J$53 -> 50.6 | BB39: =Assumptions!$K$53 -> 50.7
A40: Basic EPS | B40: =IF(B38=0,"",B36/B38) -> 0.10157052 | C40: =IF(C38=0,"",C36/C38) -> 0.30910012 | D40: =IF(D38=0,"",D36/D38) -> -0.30421615 | E40: =IF(E38=0,"",E36/E38) -> 0.19224745 | F40: =IF(F38=0,"",F36/F38) -> 0.26928202 | G40: =IF(G38=0,"",G36/G38) -> 0.2340161 | H40: =IF(H38=0,"",H36/H38) -> -0.50713085 | I40: =IF(I38=0,"",I36/I38) -> -0.1810049 | ... BB40: =IF(BB38=0,"",BB36/BB38) -> 0.46872846
...

Sheet BS - Quarterly
A1: AeroVironment, Inc. - Balance Sheet
A2: USD mm
A4: Fiscal quarter end | B4: 1/31/15 | C4: 4/30/15 | D4: 8/1/15 | E4: 10/31/15 | F4: 1/30/16 | G4: 4/30/16 | H4: 7/30/16 | I4: 10/29/16 | J4: 1/28/17 | K4: 4/30/17 | L4: 7/29/17 | M4: 10/28/17 | N4: 1/27/18 | O4: 4/30/18 | P4: 7/28/18 | Q4: 10/27/18 | R4: 1/26/19 | S4: 4/30/19 | T4: 7/27/19 | U4: 10/26/19 | V4: 1/25/20 | W4: 4/30/20 | X4: 8/1/20 | Y4: 10/31/20 | Z4: 1/30/21 | AA4: 4/30/21 | AB4: 7/31/21 | AC4: 10/30/21 | AD4: 1/29/22 | AE4: 4/30/22 | AF4: 7/30/22 | AG4: 10/29/22 | AH4: 1/28/23 | AI4: 4/30/23 | AJ4: 7/29/23 | AK4: 10/28/23 | AL4: 1/27/24 | AM4: 4/30/24 | AN4: 7/27/24 | AO4: 10/26/24 | AP4: 1/25/25 | AQ4: 4/30/25 | AR4: 8/2/25 | AS4: 11/1/25 | AT4: 1/31/26
A5: Assets
A6: Cash and cash equivalents | B6: 125.977 | C6: 143.41 | D6: 146.45 | E6: 128.032 | F6: 122.706 | G6: 124.287 | H6: 122.313 | I6: 88.876 | J6: 73.278 | K6: 79.904 | L6: 117.473 | M6: 117.109 | N6: 112.304 | O6: 143.517 | P6: 170.788 | Q6: 151.255 | R6: 149.369 | S6: 172.708 | T6: 137.094 | U6: 130.742 | V6: 131.496 | W6: 255.142 | X6: 246.839 | Y6: 280.099 | Z6: 324.543 | AA6: 148.741 | AB6: 93.924 | AC6: 104.77 | AD6: 82.528 | AE6: 77.231 | AF6: 93.183 | AG6: 101.417 | AH6: 78.276 | AI6: 132.859 | AJ6: 105.871 | AK6: 100.908 | AL6: 107.694 | AM6: 73.301 | AN6: 81.162 | AO6: 68.96 | AP6: 47 | AQ6: 40.862 | AR6: 685.803 | AS6: 359.434 | AT6: 289.878
A7: Short-term investments | B7: 77.581 | C7: 85.381 | D7: 71.018 | E7: 77.967 | F7: 97.69 | G7: 103.404 | H7: 101.802 | I7: 118.208 | J7: 121.095 | K7: 119.971 | L7: 107.831 | M7: 110.751 | N7: 109.543 | O7: 113.649 | P7: 118.303 | Q7: 138.536 | R7: 144.815 | S7: 150.487 | T7: 163.634 | U7: 161.635 | V7: 148.502 | W7: 47.507 | X7: 71.334 | Y7: 67.137 | Z7: 48.499 | AA7: 31.971 | AB7: 17.953 | AC7: 6.311 | AD7: 3.969 | AE7: 24.716 | AF7: 12.655 | AH7: 0 | AS7: 229.046 | AT7: 297.259
A8: Accounts receivable, net | B8: 37.834 | C8: 33.607 | D8: 28.205 | E8: 42.746 | F8: 38.991 | G8: 56.045 | H8: 32.635 | I8: 26.102 | J8: 23.121 | K8: 68.719 | L8: 30.685 | M8: 35.106 | N8: 25.69 | O8: 56.813 | P8: 13.802 | Q8: 34.639 | R8: 34.064 | S8: 31.051 | T8: 42.724 | U8: 40.564 | V8: 27.936 | W8: 73.66 | X8: 43.357 | Y8: 30.701 | Z8: 26.621 | AA8: 62.647 | AB8: 45.764 | AC8: 26.552 | AD8: 41.739 | AE8: 60.17 | AF8: 52.062 | AG8: 31.664 | AH8: 52.871 | AI8: 87.633 | AJ8: 79.214 | AK8: 73.865 | AL8: 53.236 | AM8: 70.305 | AN8: 35.487 | AO8: 73.935 | AP8: 81.231 | AQ8: 101.967 | AR8: 198.293 | AS8: 232.342 | AT8: 201.046
A9: Unbilled receivables and retentions | B9: 8.345 | C9: 17.356 | D9: 13.998 | E9: 11.798 | F9: 10.44 | G9: 18.899 | H9: 14.493 | I9: 16.87 | J9: 14.82 | K9: 14.12 | L9: 10.753 | M9: 13.494 | N9: 24.961 | O9: 16.872 | P9: 59.87 | Q9: 45.654 | R9: 51.632 | S9: 53.047 | T9: 47.935 | U9: 62.397 | V9: 77.411 | W9: 75.837 | X9: 73.791 | Y9: 70.573 | Z9: 61.084 | AA9: 71.632 | AB9: 87.131 | AC9: 119.031 | AD9: 97.993 | AE9: 104.194 | AF9: 89.397 | AG9: 92.457 | AH9: 109.289 | AI9: 105.653 | AJ9: 107.258 | AK9: 141.812 | AL9: 148.588 | AM9: 199.474 | AN9: 219.766 | AO9: 204.18 | AP9: 229.651 | AQ9: 290.009 | AR9: 463.87 | AS9: 513.486 | AT9: 528.557
A10: Inventories, net | B10: 48.799 | C10: 39.414 | D10: 43.921 | E10: 48.336 | F10: 46.434 | G10: 37.486 | H10: 44.105 | I10: 55.168 | J10: 68.806 | K10: 40.908 | L10: 72.017 | M10: 76.039 | N10: 77.327 | O10: 37.425 | P10: 42.244 | Q10: 46.096 | R10: 50.379 | S10: 54.056 | T10: 56.336 | U10: 52.769 | V10: 65.156 | W10: 45.535 | X10: 45.53 | Y10: 51.779 | Z10: 53.104 | AA10: 71.646 | AB10: 84.852 | AC10: 81.944 | AD10: 89.616 | AE10: 90.629 | AF10: 98.603 | AG10: 109.81 | AH10: 125.942 | AI10: 138.814 | AJ10: 175.396 | AK10: 181.767 | AL10: 161.384 | AM10: 150.168 | AN10: 143.835 | AO10: 139.698 | AP10: 147.973 | AQ10: 144.09 | AR10: 232.888 | AS10: 259.213 | AT10: 299.277
A11: Deferred income taxes | B11: 5.217 | C11: 5.265 | D11: 5.062 | E11: 5.05 | F11: 5.247
A12: Income taxes receivable | B12: 1.94 | D12: 5.569 | E12: 2.836 | F12: 3.901 | H12: 4.25 | I12: 3.957 | J12: 2.487 | L12: 2.969 | N12: 0.292 | S12: 0.821 | AB12: 0.322 | AC12: 11.708 | AD12: 26.578 | AE12: 0.442 | AG12: 8.94 | AH12: 9.18 | AK12: 5.735 | AL12: 8.081 | AN12: 0.338 | AO12: 9.628 | AP12: 15.112 | AQ12: 0.622 | AR12: 20.778 | AS12: 26.446 | AT12: 43.031
A13: Current assets of discontinued operations | K13: 24.93 | O13: 25.668
A14: Prepaid expenses and other current assets | B14: 4.203 | C14: 4.599 | D14: 3.958 | E14: 4.555 | F14: 4.219 | G14: 4.15 | H14: 4.167 | I14: 4.706 | J14: 5.341 | K14: 5.533 | L14: 5.266 | M14: 5.175 | N14: 5.138 | O14: 5.103 | P14: 5.196 | Q14: 5.732 | R14: 6.616 | S14: 7.418 | T14: 7.606 | U14: 8.045 | V14: 6.833 | W14: 6.246 | X14: 5.941 | Y14: 7.31 | Z14: 7.693 | AA14: 15.001 | AB14: 14.972 | AC14: 13.761 | AD14: 12.099 | AE14: 11.527 | AF14: 11.368 | AG14: 13.244 | AH14: 15.323 | AI14: 12.043 | AJ14: 13.949 | AK14: 19.958 | AL14: 21.708 | AM14: 22.333 | AN14: 19.758 | AO14: 18.444 | AP14: 22.919 | AQ14: 28.966 | AR14: 37.707 | AS14: 46.49 | AT14: 45.199
A15: Total current assets | B15: =SUM(B6,B7,B8,B9,B10,B11,B12,B13,B14) -> 309.896 | C15: =SUM(C6,C7,C8,C9,C10,C11,C12,C13,C14) -> 329.032 | D15: =SUM(D6,D7,D8,D9,D10,D11,D12,D13,D14) -> 318.181 | E15: =SUM(E6,E7,E8,E9,E10,E11,E12,E13,E14) -> 321.32 | F15: =SUM(F6,F7,F8,F9,F10,F11,F12,F13,F14) -> 329.628 | G15: =SUM(G6,G7,G8,G9,G10,G11,G12,G13,G14) -> 344.271 | H15: =SUM(H6,H7,H8,H9,H10,H11,H12,H13,H14) -> 323.765 | I15: =SUM(I6,I7,I8,I9,I10,I11,I12,I13,I14) -> 313.887 | ... AT15: =SUM(AT6,AT7,AT8,AT9,AT10,AT11,AT12,AT13,AT14) -> 1704.247
A16: Long-term investments | B16: 54.575 | C16: 46.769 | D16: 44.727 | E16: 37.715 | F16: 38.175 | G16: 33.859 | H16: 33.097 | I16: 42.559 | J16: 43.749 | K16: 42.096 | L16: 35.844 | M16: 33.024 | N16: 38.822 | O16: 40.656 | P16: 36.712 | Q16: 30.459 | R16: 27.954 | S16: 9.386 | T16: 4.887 | U16: 13.478 | V16: 26.409 | W16: 15.03 | X16: 20.338 | Y16: 20.976 | Z16: 11.222 | AA16: 12.156 | AB16: 10.165 | AC16: 11.971 | AD16: 12.388 | AE16: 15.433 | AF16: 17.707 | AG16: 22.462 | AH16: 19.319 | AI16: 23.613 | AJ16: 22.578 | AK16: 20.611 | AL16: 21.282 | AM16: 20.96 | AN16: 21.887 | AO16: 22.942 | AP16: 25.522 | AQ16: 31.627 | AR16: 36.267 | AS16: 80.97 | AT16: 61.659
A17: Property and equipment, net | B17: 16.143 | C17: 13.499 | D17: 13.023 | E17: 13.579 | F17: 14.313 | G17: 16.762 | H17: 16.91 | I17: 17.445 | J17: 18.41 | K17: 15.962 | L17: 20.317 | M17: 21.614 | N17: 21.626 | O17: 19.219 | P17: 19.347 | Q17: 20.46 | R17: 20.542 | S17: 16.905 | T17: 17.747 | U17: 20.571 | V17: 19.877 | W17: 21.694 | X17: 22.907 | Y17: 22.868 | Z17: 22.92 | AA17: 58.896 | AB17: 66.563 | AC17: 68.217 | AD17: 65.377 | AE17: 62.296 | AF17: 61.862 | AG17: 52.415 | AH17: 45.388 | AI17: 39.795 | AJ17: 39.77 | AK17: 43.772 | AL17: 45.053 | AM17: 46.602 | AN17: 48.071 | AO17: 49.681 | AP17: 49.587 | AQ17: 50.704 | AR17: 148.807 | AS17: 155.383 | AT17: 158.867
A18: Operating lease right-of-use assets | T18: 9.917 | U18: 8.902 | V18: 9.472 | W18: 8.793 | X18: 13.612 | Y18: 12.363 | Z18: 11.281 | AA18: 22.902 | AB18: 27.649 | AC18: 22.902 | AD18: 24.848 | AE18: 26.769 | AF18: 25.385 | AG18: 25.58 | AH18: 28.336 | AI18: 27.363 | AJ18: 25.742 | AK18: 30.632 | AL18: 28.904 | AM18: 41.303 | AN18: 28.283 | AO18: 32.502 | AP18: 31.696 | AQ18: 61.46 | AR18: 98.514 | AS18: 94.291 | AT18: 91.81
A19: Deferred income taxes | B19: 4.638 | C19: 7.426 | D19: 6.671 | E19: 6.725 | F19: 6.72 | G19: 15.016 | H19: 15.104 | I19: 15.409 | J19: 15.779 | K19: 15.089 | L19: 15.646 | M19: 16.113 | N19: 14.837 | O19: 11.494 | P19: 11.8 | Q19: 12.108 | R19: 12.708 | S19: 6.685 | T19: 7.699 | U19: 8.019 | V19: 8.296 | W19: 4.928 | X19: 5.262 | Y19: 5.546 | Z19: 5.821 | AA19: 2.061 | AB19: 2.534 | AC19: 2.9 | AD19: 3.258 | AE19: 7.29 | AF19: 7.671 | AG19: 8.098 | AH19: 8.54 | AI19: 27.206 | AJ19: 27.633 | AK19: 20.78 | AL19: 21.378 | AM19: 30.033 | AN19: 41.303 | AO19: 41.303 | AP19: 41.303 | AQ19: 31.879
A20: Intangibles, net | S20: 0.459 | T20: 16.727 | U20: 15.952 | V20: 14.357 | W20: 13.637 | X20: 12.928 | Y20: 12.213 | Z20: 11.552 | AA20: 106.268 | AB20: 117.855 | AC20: 110.62 | AD20: 103.825 | AE20: 97.224 | AF20: 91.009 | AG20: 88.66 | AH20: 83.442 | AI20: 43.577 | AJ20: 40.54 | AK20: 82.848 | AL20: 77.597 | AM20: 72.224 | AN20: 67.521 | AO20: 62.703 | AP20: 57.78 | AQ20: 48.711 | AR20: 1118.85 | AS20: 971.787 | AT20: 925.925
A21: Goodwill | T21: 8.08 | U21: 8.08 | V21: 6.34 | W21: 6.34 | X21: 6.34 | Y21: 6.34 | Z21: 6.34 | AA21: 314.205 | AB21: 335.029 | AC21: 335.888 | AD21: 335.164 | AE21: 334.347 | AF21: 333.791 | AG21: 334.963 | AH21: 336.555 | AI21: 180.801 | AJ21: 180.797 | AK21: 274.781 | AL21: 275.189 | AM21: 275.652 | AN21: 275.932 | AO21: 275.827 | AP21: 275.289 | AQ21: 256.781 | AR21: 2539.56 | AS21: 2623.67 | AT21: 2372.31
A22: Other assets | B22: 1.219 | C22: 0.741 | D22: 0.672 | E22: 0.69 | F22: 0.653 | G22: 0.75 | H22: 0.658 | I22: 0.598 | J22: 0.57 | K22: 2.01 | L22: 1.938 | M22: 0.838 | N22: 2.305 | O22: 3.002 | P22: 2.299 | Q22: 1.628 | R22: 0.884 | S22: 5.821 | T22: 14.196 | U22: 13.339 | V22: 16.995 | W22: 10.605 | X22: 9.64 | Y22: 0.102 | Z22: 0.312 | AA22: 10.44 | AB22: 3.84 | AC22: 6.276 | AD22: 5.881 | AE22: 1.932 | AF22: 1.961 | AG22: 1.972 | AH22: 8.741 | AI22: 5.22 | AJ22: 7.312 | AK22: 9.231 | AL22: 10.205 | AM22: 13.505 | AN22: 15.826 | AO22: 19.282 | AP22: 23.08 | AQ22: 32.889 | AR22: 42.702 | AS22: 45.909 | AT22: 49.414
A23: Long-term assets of discontinued operations | K23: 3.258
A24: Other assets / source adjustment | AC24: 2.456
A25: Total assets | B25: =SUM(B15,B16,B17,B18,B19,B20,B21,B22,B23,B24) -> 386.471 | C25: =SUM(C15,C16,C17,C18,C19,C20,C21,C22,C23,C24) -> 397.467 | D25: =SUM(D15,D16,D17,D18,D19,D20,D21,D22,D23,D24) -> 383.274 | E25: =SUM(E15,E16,E17,E18,E19,E20,E21,E22,E23,E24) -> 380.029 | F25: =SUM(F15,F16,F17,F18,F19,F20,F21,F22,F23,F24) -> 389.489 | G25: =SUM(G15,G16,G17,G18,G19,G20,G21,G22,G23,G24) -> 410.658 | H25: =SUM(H15,H16,H17,H18,H19,H20,H21,H22,H23,H24) -> 389.534 | I25: =SUM(I15,I16,I17,I18,I19,I20,I21,I22,I23,I24) -> 389.898 | ... AT25: =SUM(AT15,AT16,AT17,AT18,AT19,AT20,AT21,AT22,AT23,AT24) -> 5364.232
A26: Liabilities
A27: Accounts payable | B27: 16.215 | C27: 19.243 | D27: 12.944 | E27: 11.59 | F27: 9.786 | G27: 17.712 | H27: 10.529 | I27: 18.662 | J27: 13.792 | K27: 15.896 | L27: 13.966 | M27: 15.724 | N27: 13.249 | O27: 21.34 | P27: 12.939 | Q27: 14.149 | R27: 11.629 | S27: 15.972 | T27: 11.45 | U27: 11.022 | V27: 14.269 | W27: 19.859 | X27: 11.74 | Y27: 14.225 | Z27: 15.837 | AA27: 24.841 | AB27: 18.046 | AC27: 21.443 | AD27: 15.118 | AE27: 19.244 | AF27: 21.945 | AG27: 26.317 | AH27: 26.42 | AI27: 31.355 | AJ27: 28.824 | AK27: 28.834 | AL27: 26.969 | AM27: 48.298 | AN27: 43.596 | AO27: 40.646 | AP27: 48.766 | AQ27: 72.462 | AR27: 91.133 | AS27: 119.531 | AT27: 109.633
A28: Wages and related accruals | B28: 12.968 | C28: 13.395 | D28: 10.438 | E28: 10.503 | F28: 13.463 | G28: 13.973 | H28: 9.934 | I28: 10.021 | J28: 10.967 | K28: 10.947 | L28: 10.608 | M28: 10.415 | N28: 15.09 | O28: 16.851 | P28: 10.624 | Q28: 11.071 | R28: 14.363 | S28: 18.507 | T28: 12.085 | U28: 13.218 | V28: 17.636 | W28: 23.972 | X28: 13.025 | Y28: 18.737 | Z28: 20.081 | AA28: 28.068 | AB28: 20.067 | AC28: 21.697 | AD28: 21.207 | AE28: 25.398 | AF28: 17.403 | AG28: 25.049 | AH28: 27.135 | AI28: 35.637 | AJ28: 16.875 | AK28: 26.671 | AL28: 28.443 | AM28: 44.312 | AN28: 20.413 | AO28: 31.594 | AP28: 36.55 | AQ28: 44.253 | AR28: 73.752 | AS28: 79.294 | AT28: 75.765
A29: Customer advances | B29: 4.213 | C29: 4.235 | D29: 4.259 | E29: 3.835 | F29: 3.213 | G29: 2.544 | H29: 2.416 | I29: 3.72 | J29: 5.456 | K29: 2.057 | L29: 4.593 | M29: 3.921 | N29: 3.555 | O29: 3.564 | P29: 1.627 | Q29: 2.449 | R29: 2.875 | S29: 2.962 | T29: 3.268 | U29: 2.55 | V29: 10.633 | W29: 7.899 | X29: 5.725 | Y29: 2.957 | Z29: 4.279 | AA29: 7.183 | AB29: 9.117 | AC29: 10.322 | AD29: 6.864 | AE29: 8.968 | AF29: 10.258 | AG29: 7.074 | AH29: 22.553 | AI29: 16.645 | AJ29: 19.94 | AK29: 20.44 | AL29: 17.536 | AM29: 11.192 | AN29: 10.993 | AO29: 10.64 | AP29: 12.064 | AQ29: 15.952 | AR29: 61.269 | AS29: 71.167 | AT29: 67.543
A30: Current portion of long-term debt | AA30: 10 | AB30: 10 | AC30: 10 | AD30: 10 | AE30: 10 | AF30: 10 | AG30: 10 | AH30: 10 | AI30: 7.5 | AJ30: 10 | AK30: 5 | AL30: 7.5 | AM30: 10 | AN30: 10
A31: Current operating lease liabilities | T31: 2.771 | U31: 2.29 | V31: 2.083 | W31: 3.38 | X31: 4.478 | Y31: 4.03 | Z31: 4.403 | AA31: 6.154 | AB31: 6.747 | AC31: 6.44 | AD31: 6.15 | AE31: 6.819 | AF31: 7.029 | AG31: 7.564 | AH31: 7.794 | AI31: 8.229 | AJ31: 8.272 | AK31: 8.818 | AL31: 8.934 | AM31: 9.841 | AN31: 9.428 | AO31: 9.591 | AP31: 9.365 | AQ31: 10.479 | AR31: 16.759 | AS31: 14.829 | AT31: 15.569
A32: Income taxes payable | C32: 0.692 | G32: 0.943 | K32: 1.418 | M32: 0.35 | O32: 4.085 | P32: 8.898 | Q32: 4.851 | R32: 4.857 | T32: 1.367 | U32: 2.57 | V32: 2.809 | W32: 1.065 | X32: 2.62 | Y32: 3.018 | Z32: 2.37 | AA32: 0.861 | AB32: 0.549 | AC32: 0.214 | AD32: 0.247 | AE32: 0.759 | AF32: 2.962 | AG32: 0.026 | AH32: 0.026 | AI32: 2.342 | AJ32: 4.058 | AK32: 0.595 | AL32: 0.797 | AM32: 4.162 | AN32: 5.597 | AO32: 0.028 | AP32: 0.025 | AQ32: 0.356 | AS32: 0.215 | AT32: 0.32
A33: Other current liabilities | B33: 10.264 | C33: 9.17 | D33: 8.757 | E33: 5.669 | F33: 6.408 | G33: 11.173 | H33: 12.708 | I33: 6.997 | J33: 7.753 | K33: 8.444 | L33: 8.53 | M33: 7.441 | N33: 8.651 | O33: 6.954 | P33: 6.664 | Q33: 6.971 | R33: 8.062 | S33: 7.425 | T33: 12.167 | U33: 13.141 | V33: 13.046 | W33: 10.778 | X33: 8.735 | Y33: 10.511 | Z33: 9.158 | AA33: 19.078 | AB33: 18.134 | AC33: 31.313 | AD33: 27.897 | AE33: 30.203 | AF33: 26.279 | AG33: 27.824 | AH33: 22.469 | AI33: 19.626 | AJ33: 19.22 | AK33: 18.946 | AL33: 17.352 | AM33: 17.074 | AN33: 17.331 | AO33: 19.112 | AP33: 22.138 | AQ33: 28.659 | AR33: 32.017 | AS33: 42.991 | AT33: 40.489
A34: Current liabilities of discontinued operations | K34: 9.301 | O34: 9.294
A35: Total current liabilities | B35: =SUM(B27,B28,B29,B30,B31,B32,B33,B34) -> 43.66 | C35: =SUM(C27,C28,C29,C30,C31,C32,C33,C34) -> 46.735 | D35: =SUM(D27,D28,D29,D30,D31,D32,D33,D34) -> 36.398 | E35: =SUM(E27,E28,E29,E30,E31,E32,E33,E34) -> 31.597 | F35: =SUM(F27,F28,F29,F30,F31,F32,F33,F34) -> 32.87 | G35: =SUM(G27,G28,G29,G30,G31,G32,G33,G34) -> 46.345 | H35: =SUM(H27,H28,H29,H30,H31,H32,H33,H34) -> 35.587 | I35: =SUM(I27,I28,I29,I30,I31,I32,I33,I34) -> 39.4 | ... AT35: =SUM(AT27,AT28,AT29,AT30,AT31,AT32,AT33,AT34) -> 309.319
A36: Deferred rent | B36: 1.336 | C36: 1.381 | D36: 1.33 | E36: 1.266 | F36: 1.223 | G36: 1.714 | H36: 1.864 | I36: 1.82 | J36: 1.769 | K36: 1.719 | L36: 1.673 | M36: 1.637 | N36: 1.589 | O36: 1.536 | P36: 1.476 | Q36: 1.478 | R36: 1.352 | S36: 1.173
A37: Capital lease obligations - net of current portion | F37: 0.388 | G37: 0.449 | H37: 0.357 | I37: 0.276 | J37: 0.218 | K37: 0.161 | L37: 0.104 | M37: 0.05 | N37: 0.007
A38: Long-term debt | AA38: 187.512 | AB38: 185.141 | AC38: 182.769 | AD38: 180.398 | AE38: 177.84 | AF38: 175.481 | AG38: 155.622 | AH38: 155.763 | AI38: 125.904 | AJ38: 118.537 | AK38: 73.678 | AL38: 31.292 | AM38: 17.092 | AN38: 6.788 | AO38: 15 | AP38: 25 | AQ38: 30 | AR38: 725.703 | AS38: 726.793 | AT38: 727.877
A39: Non-current operating lease liabilities | T39: 7.597 | U39: 6.843 | V39: 7.556 | W39: 6.833 | X39: 10.344 | Y39: 9.422 | Z39: 8.426 | AA39: 19.103 | AB39: 23.048 | AC39: 21.665 | AD39: 20.678 | AE39: 21.915 | AF39: 20.371 | AG39: 20.043 | AH39: 22.63 | AI39: 21.189 | AJ39: 19.454 | AK39: 23.727 | AL39: 21.978 | AM39: 22.745 | AN39: 21.086 | AO39: 25.69 | AP39: 24.82 | AQ39: 23.812 | AR39: 87.246 | AS39: 84.313 | AT39: 82.567
A40: Other non-current liabilities | G40: 0.184 | H40: 0.184 | I40: 0.193 | J40: 0.193 | K40: 0.184 | L40: 0.184 | M40: 0.184 | N40: 0.184 | O40: 0.622 | P40: 0.958 | Q40: 1.306 | R40: 0.16 | S40: 0.15 | T40: 2.298 | U40: 2.422 | V40: 0.25 | W40: 0.25 | X40: 0.243 | Y40: 0.243 | Z40: 0.243 | AA40: 10.141 | AB40: 10.336 | AC40: 10.302 | AD40: 5.273 | AE40: 0.768 | AF40: 0.759 | AG40: 0.748 | AH40: 0.742 | AI40: 0.746 | AJ40: 1.901 | AK40: 1.898 | AL40: 2.105 | AM40: 2.132 | AN40: 2.123 | AO40: 2.114 | AP40: 2.106 | AQ40: 2.026 | AR40: 2.016 | AS40: 2.003 | AT40: 1.995
A41: Liability for uncertain tax positions | B41: 0.645 | C41: 0.439 | D41: 0.439 | E41: 0.439 | F41: 0.439 | G41: 0.441 | H41: 0.062 | I41: 0.062 | J41: 0.062 | K41: 0.064 | L41: 0.064 | M41: 0.064 | N41: 0.064 | O41: 0.049 | P41: 0.049 | Q41: 0.049 | R41: 0.049 | S41: 0.051 | T41: 0.051 | U41: 0.051 | V41: 0.051 | W41: 1.017 | X41: 1.017 | Y41: 1.017 | Z41: 1.017 | AA41: 3.518 | AB41: 3.518 | AC41: 3.518 | AD41: 3.518 | AE41: 1.45 | AF41: 1.45 | AG41: 1.45 | AH41: 1.45 | AI41: 2.705 | AJ41: 2.705 | AK41: 2.705 | AL41: 2.705 | AM41: 5.603 | AN41: 5.603 | AO41: 5.603 | AP41: 5.603 | AQ41: 6.061 | AR41: 6.061 | AS41: 6.061 | AT41: 6.061
...

Sheet CF - Quarterly
A1: AeroVironment, Inc. - Cash Flow Statement
A2: USD mm
A4: Fiscal quarter end | B4: 4/30/15 | C4: 8/1/15 | D4: 10/31/15 | E4: 1/30/16 | F4: 4/30/16 | G4: 7/30/16 | H4: 10/29/16 | I4: 1/28/17 | J4: 4/30/17 | K4: 7/29/17 | L4: 10/28/17 | M4: 1/27/18 | N4: 4/30/18 | O4: 7/28/18 | P4: 10/27/18 | Q4: 1/26/19 | R4: 4/30/19 | S4: 7/27/19 | T4: 10/26/19 | U4: 1/25/20 | V4: 4/30/20 | W4: 8/1/20 | X4: 10/31/20 | Y4: 1/30/21 | Z4: 4/30/21 | AA4: 7/31/21 | AB4: 10/30/21 | AC4: 1/29/22 | AD4: 4/30/22 | AE4: 7/30/22 | AF4: 10/29/22 | AG4: 1/28/23 | AH4: 4/30/23 | AI4: 7/29/23 | AJ4: 10/28/23 | AK4: 1/27/24 | AL4: 4/30/24 | AM4: 7/27/24 | AN4: 10/26/24 | AO4: 1/25/25 | AP4: 4/30/25 | AQ4: 8/2/25 | AR4: 11/1/25 | AS4: 1/31/26
A5: Operating Activities
A6: Net income | B6: 7.08 | C6: -6.981 | D6: 4.419 | E6: 6.164 | F6: 5.364 | G6: -11.642 | H6: -4.172 | I6: -2.183 | J6: 30.454 | K6: -5.882 | L6: 7.517 | M6: -0.785 | N6: 16.797 | O6: 27.316 | P6: 6.05 | Q6: 8.35 | R6: 5.703 | S6: 17.099 | T6: 7.505 | U6: -1.028 | V6: 17.494 | W6: 10.043 | X6: 2.072 | Y6: 0.258 | Z6: 10.972 | AA6: -13.918 | AB6: 2.556 | AC6: -0.035 | AD6: 7.212 | AE6: -8.389 | AF6: -6.629 | AG6: -0.676 | AH6: -160.473 | AI6: 21.895 | AJ6: 17.84 | AK6: 13.885 | AL6: 6.046 | AM6: 21.166 | AN6: 7.543 | AO6: -1.754 | AP6: 16.664 | AQ6: -67.37 | AR6: -17.103 | AS6: -156.551
A7: Gain on sale of business, net of tax | K7: 1.488 | L7: -1.488 | O7: -8.843 | P7: 0.391 | Q7: 0
A8: Loss from discontinued operations, net of tax | L8: 1.521 | M8: 0.129 | N8: -1.65 | O8: 1.05 | P8: 1.399 | Q8: 0.062 | R8: 0.453
A9: Net income from continuing operations | K9: -4.394 | L9: 7.55 | M9: -0.656 | O9: 20.323 | P9: 7.04 | Q9: 8.412 | R9: 6.118
A10: Depreciation and amortization | B10: 1.998 | C10: 1.402 | D10: 1.363 | E10: 1.782 | F10: 1.527 | G10: 1.653 | H10: 1.748 | I10: 1.787 | J10: 1.866 | K10: 1.406 | L10: 1.378 | M10: 1.493 | N10: 1.705 | O10: 1.746 | P10: 1.838 | Q10: 1.946 | R10: 2.139 | S10: 2.079 | T10: 2.407 | U10: 2.621 | V10: 2.781 | W10: 2.779 | X10: 2.914 | Y10: 2.957 | Z10: 10.612 | AA10: 13.654 | AB10: 16.365 | AC10: 17.418 | AD10: 13.388 | AE10: 14 | AF10: 18.275 | AG10: 15.834 | AH10: 51.89 | AI10: 6.951 | AJ10: 8.436 | AK10: 9.582 | AL10: 10.78 | AM10: 8.852 | AN10: 9.002 | AO10: 9.29 | AP10: 13.854 | AQ10: 90.254 | AR10: 58.073 | AS10: 54.633
A11: Equity method investment loss (income), net | B11: 0.088 | C11: 0.065 | D11: 0.057 | E11: 0.126 | F11: -0.11 | G11: 0.072 | H11: 0.039 | I11: 0.008 | K11: 0.009 | M11: 0.418 | O11: 0.602 | P11: 0.752 | Q11: 0.717 | S11: 1.347 | T11: 0.863 | U11: 1.2 | W11: 1.288 | X11: 5.405 | Y11: 0.081 | AA11: 1.141 | AB11: -1.661 | AC11: -0.279 | AE11: 0.5 | AF11: 1.273 | AG11: 0.417 | AI11: 0.021 | AJ11: 1.393 | AK11: 0.08 | AL11: 0.18 | AM11: -0.065 | AN11: -0.5275 | AO11: 0 | AP11: -3.782 | AQ11: -1.787 | AR11: -1.4915 | AS11: 0.295
A12: Impairment of available-for-sale securities | C12: 2.186 | D12: 0 | E12: 0 | F12: 0
A13: Impairment of goodwill | AP13: 18.359
A14: Loss on deconsolidation of previously controlled subsidiary | AF14: 0.0945 | AG14: -0.001 | AH14: 0.6
A15: Amortization of debt issuance costs | Y15: 0 | Z15: 10.481 | AA15: 0.129 | AB15: 0.129 | AC15: 0.128 | AD15: 0.403 | AE15: 0.211 | AF15: 0.211 | AG15: 0.212 | AH15: 0.211 | AI15: 0.214 | AJ15: 0.21 | AK15: 0.214 | AL15: 0.351 | AM15: 0.266 | AN15: 0.781 | AO15: 0.074 | AP15: 0.074 | AQ15: 7.829 | AR15: 1.225 | AS15: 1.219
A16: Realized gain from sale of available-for-sale investments | U16: -0.002 | V16: -0.178 | W16: -0.011 | X16: 0 | Y16: 0 | Z16: 0.156
A17: Impairment of long-lived assets | G17: 0.171 | H17: -0.171 | I17: 0 | J17: 0.046 | K17: 0.209 | L17: 0.046 | M17: 0 | N17: 0
A18: Provision for credit losses | B18: -0.005 | C18: -0.147 | D18: -0.084 | E18: -0.021 | F18: 0.074 | G18: 0.226 | H18: -0.107 | I18: -0.004 | J18: -0.069 | K18: -0.106 | L18: 1.031 | M18: 0.159 | N18: 0.037 | O18: -0.048 | P18: 0.021 | Q18: -0.006 | R18: -0.006 | S18: 0.011 | T18: 0.003 | U18: -0.016 | V18: 0.39 | W18: -0.136 | X18: -0.02 | Y18: 0.011 | Z18: 0.031 | AA18: -0.02 | AB18: -0.015 | AC18: 0.015 | AD18: 0.014 | AE18: 0.023 | AF18: -0.004 | AG18: -0.014 | AH18: 0.094 | AI18: -0.015 | AJ18: 0.019 | AK18: -0.071 | AL18: 0.071 | AM18: -0.101 | AN18: 0.034 | AO18: -0.097 | AP18: 0.207 | AQ18: 0.173 | AR18: 1.805 | AS18: -0.111
A19: Foreign currency transaction loss (gain), net | C19: 0.058 | D19: 0.005 | E19: 0 | G19: -0.069 | H19: 0.338 | I19: 0.003 | J19: 0.012 | L19: -0.108 | M19: 0.072 | O19: -0.306 | P19: -0.308 | T19: -0.669 | U19: -0.277 | W19: 0.001 | X19: 0.001 | Y19: -0.001 | AA19: 0.019 | AB19: 0.011 | AE19: -0.044 | AF19: -0.0295 | AH19: -2.995 | AI19: 0.132 | AJ19: -0.092 | AK19: 0.238 | AM19: 0.142 | AN19: -0.11 | AO19: 0.2295 | AP19: 0.2295 | AQ19: 0.161 | AR19: 0.054
A20: Impairment of intangible assets and goodwill | L20: 0.5105 | M20: 0
A21: Loss on sale of equity securities | B21: 0.391 | C21: 0.145 | D21: 0.074 | E21: 0 | F21: 0
A22: Other non-cash expense (gain), net | R22: -0.421 | S22: 0.032 | T22: 0.049 | X22: -0.473 | Y22: 0 | AA22: 0.048 | AB22: 0.109 | AC22: 0.283 | AE22: 0.153 | AF22: 0.412 | AG22: 0.37 | AH22: 1.06 | AI22: 0.173 | AJ22: 0.158 | AK22: 0.452 | AL22: 0.533 | AM22: 0.616 | AN22: 0.578 | AO22: 0.616 | AP22: 0.796 | AQ22: 0.616 | AR22: 1.473 | AS22: 1.454
A23: Reserve for inventory excess and obsolescence | AE23: 0.22 | AF23: 2.639 | AG23: 0.928 | AH23: 4.349 | AI23: 3.33 | AJ23: 5.008 | AK23: 3.33 | AL23: 2.269 | AM23: 2.667 | AN23: -0.635 | AO23: -0.007 | AP23: 0.857 | AQ23: 1.178 | AR23: 1.501 | AS23: 2.446
A24: Non-cash lease expense | P24: -0.013 | Q24: 0.013 | R24: 3.878 | S24: -0.251 | T24: 2.506 | U24: 1.198 | V24: 1.121 | W24: 1.19 | X24: 1.203 | Y24: 1.202 | Z24: 1.555 | AA24: 1.677 | AB24: 1.681 | AC24: 1.675 | AD24: 1.781 | AE24: 1.59 | AF24: 2.185 | AG24: 2.091 | AH24: 2.182 | AI24: 2.184 | AJ24: 2.302 | AK24: 2.437 | AL24: 3.477 | AM24: 2.43 | AN24: 2.55 | AO24: 2.399 | AP24: 2.784 | AQ24: 6.85 | AR24: 5.805 | AS24: 6.234
A25: Unrealized loss (gain) on available-for-sale equity securities, net | AF25: -0.464 | AG25: 0.53 | AH25: 0.53 | AI25: 1.013 | AJ25: 2.45 | AL25: 1.233 | AM25: 0.321 | AN25: -0.054 | AO25: -1.454 | AP25: 1.01 | AQ25: -2.702 | AR25: -6.156 | AS25: 1.412
A26: Deferred income taxes | B26: -3.18 | C26: 0.203 | D26: 0.012 | E26: -0.197 | F26: -2.93 | G26: 0.992 | H26: -1.321 | I26: -0.369 | J26: 0.646 | K26: -0.597 | L26: -0.497 | M26: 1.268 | N26: 3.66 | P26: 1.2585 | Q26: -3.731 | R26: 6.006 | S26: -0.349 | T26: 3.333 | U26: -3.93 | V26: -1.332 | W26: 0.002 | X26: -0.623 | Y26: -0.276 | Z26: -0.797 | AA26: -0.472 | AB26: -0.368 | AC26: -0.355 | AD26: -6.087 | AE26: -0.381 | AF26: -0.427 | AG26: -0.442 | AH26: -17.411 | AI26: -0.427 | AJ26: -0.579 | AK26: -0.598 | AL26: -21.846 | AP26: -20.157 | AQ26: -0.001
A27: Change in fair value of conversion feature of convertible bonds | B27: 0
A28: Stock-based compensation | B28: 1.054 | C28: 1.039 | D28: 1.043 | E28: 1.088 | F28: 1.392 | G28: 0.022 | H28: 1.791 | I28: 0.923 | J28: 0.973 | K28: 1.326 | L28: 1.209 | M28: 1.291 | N28: 1.254 | O28: 1.287 | P28: -1.287 | Q28: 5.599 | R28: 1.386 | S28: 1.566 | T28: -1.641 | U28: 4.826 | V28: 6.298 | W28: -0.339 | X28: 3.848 | Y28: 1.245 | Z28: 2.178 | AA28: 0.09 | AB28: 2.252 | AC28: 1.615 | AD28: 4.433 | AE28: 2.217 | AF28: 2.185 | AG28: 2.706 | AH28: 3.657 | AI28: 3.204 | AJ28: 5.04 | AK28: 4.181 | AL28: 4.644 | AM28: 4.536 | AN28: 5.601 | AO28: 5.381 | AP28: 5.943 | AQ28: 11.429 | AR28: 8.566 | AS28: 8.07
A29: Tax benefit from stock-based compensation | B29: 0.22 | C29: 0.101 | D29: 0 | E29: 0.106 | F29: -0.141 | G29: -0.007 | H29: 0.029 | I29: 0
A30: Loss (gain) on disposition of property and equipment | F30: 0.032 | G30: 0.661 | H30: -0.0035 | I30: 0.044 | J30: 0 | L30: 0.0075 | M30: 0 | P30: -0.459 | Q30: 0.51 | S30: -0.075 | T30: -0.909 | U30: -0.307 | W30: 1.595 | X30: 0.001 | Y30: 0 | AA30: 1.922 | AB30: 1.114 | AC30: 2.027 | AE30: 0.485 | AF30: 0.34 | AG30: 0.368 | AH30: 0.304 | AI30: 0.116 | AJ30: 0.02 | AK30: -0.021 | AL30: 0.506 | AM30: 0.143 | AN30: 0.058 | AO30: 0.055 | AP30: 0.055 | AQ30: 0.048 | AR30: 0.546
A31: Accounts receivable | B31: 4.232 | C31: 5.549 | D31: -14.457 | E31: 3.856 | F31: -17.208 | G31: 23.019 | H31: 6.543 | I31: 2.991 | J31: -51.18 | K31: 43.819 | L31: -5.137 | M31: 9.01 | N31: -37.801 | O31: 43.189 | P31: -20.928 | Q31: 0.556 | R31: 3.004 | S31: -11.557 | T31: 2.157 | U31: 12.645 | V31: -46.114 | W31: 30.439 | X31: 12.676 | Y31: 4.069 | Z31: -30.007 | AA31: 17.914 | AB31: 19.22 | AC31: -15.233 | AD31: -18.817 | AE31: 8.053 | AF31: 19.959 | AG31: -21.165 | AH31: -34.27 | AI31: 8.207 | AJ31: 7.346 | AK31: 20.834 | AL31: -17.179 | AM31: 34.993 | AN31: -1.75 | AP31: -20.666 | AQ31: -15.693 | AR31: -25.7595
A32: Unbilled receivables and retentions | B32: -9.011 | C32: 3.358 | D32: 2.2 | E32: 1.358 | F32: -8.471 | G32: 4.406 | H32: -2.377 | I32: 2.05 | J32: 0.7 | K32: 6.234 | L32: -5.634 | M32: -12.668 | N32: 14.321 | O32: -42.998 | P32: 14.216 | Q32: -5.978 | R32: -1.415 | S32: 5.112 | T32: -14.462 | U32: -15.014 | V32: 1.574 | W32: 2.046 | X32: 3.218 | Y32: 9.489 | Z32: -6.372 | AA32: -14.684 | AB32: -31.935 | AC32: 21.022 | AD32: -6.286 | AE32: 14.754 | AF32: -3.058 | AG32: -16.794 | AH32: 3.652 | AI32: -1.603 | AJ32: -33.572 | AK32: -6.775 | AL32: -50.9 | AM32: -20.274 | AN32: -2.342 | AP32: -60.342 | AQ32: -74.51 | AR32: -62.0735
A33: Inventories | B33: 9.385 | C33: -4.507 | D33: -4.415 | E33: 1.902 | F33: 8.948 | G33: -6.619 | H33: -11.063 | I33: -13.638 | J33: 8.73 | K33: -10.224 | L33: -3.548 | M33: -1.536 | N33: 16.5 | O33: -4.819 | P33: -3.852 | Q33: -4.283 | R33: -3.677 | S33: -1.946 | T33: 3.567 | U33: -12.387 | V33: 19.621 | W33: 0.005 | X33: -6.249 | Y33: -1.325 | Z33: 2.39 | AA33: -6.058 | AB33: -4.017 | AC33: -11.515 | AD33: -7.841 | AE33: -11.927 | AF33: -12.129 | AG33: -16.416 | AH33: -18.735 | AI33: -40.004 | AJ33: -9.325 | AK33: 17.428 | AL33: 8.856 | AM33: 3.867 | AN33: 3.7425 | AP33: 4.133 | AQ33: -12.704 | AR33: -24.68
A34: Income taxes receivable | B34: 1.94 | C34: -5.569 | D34: 2.682 | E34: -1.065 | G34: -4.25 | H34: 0.293 | I34: 1.47 | J34: 2.487 | K34: -3.385 | L34: 3.078 | M34: -0.292 | N34: 0.72 | Q34: 0 | R34: -0.821 | S34: 0.821 | T34: 0 | U34: 0 | AA34: -0.326 | AB34: -10.341 | AC34: -15.541 | AD34: 25.766 | AE34: 0.442 | AF34: -8.981 | AG34: -0.849 | AH34: 9.246 | AJ34: -5.735 | AK34: -2.279 | AL34: 8.014 | AM34: -0.336 | AN34: -4.818 | AP34: 14.148 | AQ34: -16.39 | AR34: -11.115
A35: Prepaid expenses and other assets | C35: 0.71 | D35: -0.591 | E35: 0.336 | F35: 0.062 | G35: -0.017 | H35: -0.538 | I35: -0.635 | J35: -0.294 | K35: 0.358 | L35: 0.055 | M35: 0.004 | N35: -0.278 | O35: -0.133 | P35: -0.698 | Q35: -0.96 | R35: -0.61 | S35: -0.616 | T35: -0.435 | U35: 1.267 | V35: 0.615 | W35: 0.324 | X35: -1.353 | Y35: -0.593 | Z35: -4.482 | AA35: 0.481 | AB35: -0.209 | AC35: 1.517 | AD35: -6.323 | AE35: 0.046 | AF35: -1.163 | AG35: -1.997 | AH35: -0.707 | AI35: -4.401 | AJ35: -8.319 | AK35: -3.176 | AL35: -4.383 | AM35: -0.814 | AN35: -1.1235 | AP35: -11.696 | AQ35: -1.749 | AR35: -6.3735
A36: Accounts payable | B36: 3.028 | C36: -6.299 | D36: -1.354 | E36: -1.804 | F36: 6.752 | G36: -6.336 | H36: 7.749 | I36: -4.583 | J36: 6.013 | K36: -5.504 | L36: 2.532 | M36: -1.479 | N36: 10.187 | O36: -9.893 | P36: 1.052 | Q36: -1.804 | R36: 3.591 | S36: -5.11 | T36: 0.064 | U36: 3.745 | V36: 4.428 | W36: -7.338 | X36: 2.31 | Y36: 1.682 | Z36: 5.911 | AA36: -7.997 | AB36: 4.41 | AC36: -6.643 | AD36: 3.676 | AE36: 3.323 | AF36: 3.5 | AG36: 0.966 | AH36: 4.749 | AI36: -2.78 | AJ36: -3.325 | AK36: -3.898 | AL36: 22.971 | AM36: -4.976 | AN36: -3.812 | AP36: 23.69 | AQ36: -29.625 | AR36: -3.886
A37: Other liabilities | B37: -0.089 | C37: -3.766 | D37: -3.651 | E37: 2.671 | F37: 6.267 | G37: -3.594 | H37: -4.339 | I37: 3.423 | J37: 3.564 | K37: -4.306 | L37: 0.081 | M37: 4.8 | N37: 8.649 | O37: -3.797 | P37: -2.387 | Q37: 3.586 | R37: 6.441 | S37: -4.524 | T37: -0.059 | U37: 12.53 | V37: 0.233 | W37: -15.004 | X37: 4.248 | Y37: 1.238 | Z37: 15.73 | AA37: -9.283 | AB37: 18.925 | AC37: -15.449 | AD37: 4.311 | AE37: -9.519 | AF37: 0.855 | AG37: 8.507 | AH37: -2.478 | AI37: -15.272 | AJ37: 2.421 | AK37: -2.47 | AL37: 12.489 | AM37: -25.081 | AN37: -10.208 | AP37: 13.337 | AQ37: -19.734 | AR37: -1.053
A38: Amortization of debt securities | B38: 1.144 | C38: 1.149 | D38: 0.997 | E38: 0.94 | F38: 0.789 | H38: 0.6295 | I38: 0.568 | J38: 0.655 | K38: 0.474 | L38: 0.423 | M38: 0.353 | N38: 0.174 | O38: -0.115 | P38: 0.115 | Q38: -0.941 | R38: -0.565 | S38: -0.527 | T38: 0.527 | U38: 0 | V38: -1.423 | W38: -0.043 | X38: 0.031 | Y38: 0.155 | Z38: 0.166 | AA38: 0.379 | AB38: -0.266 | AC38: 0.004 | AD38: 0.125 | AE38: 0.13 | AF38: -0.005 | AG38: 0 | AR38: -0.1005 | AS38: -0.46
A39: Other operating activities / source adjustment | B39: 3.922 | D39: 0.095 | F39: 3.903 | G39: 0.069 | H39: -0.104 | J39: -0.678 | K39: 4.394 | L39: -5.852 | M39: 0.257 | N39: 3.725 | O39: -19.525 | P39: -6.5795 | Q39: -7.808 | R39: -11.155 | U39: 0.076 | V39: 4.523 | X39: 2.543 | Y39: 0.177 | Z39: -10.954 | AB39: -6 | AC39: -0.486 | AD39: -2.197 | AF39: -2.994 | AG39: 2.294 | AH39: 157.144 | AJ39: -0.224 | AK39: -0.818 | AL39: 0.215 | AN39: -8.1515 | AO39: -40.4955 | AP39: 0.2385 | AR39: 35.6595 | AS39: 76.252
A40: Net cash provided by operating activities | B40: =SUM(B6,B7,B8,B9,B10,B11,B12,B13,B14,B15,B16,B17,B18,B19,B20,B21,B22,B23,B24,B25,B26,B27,B28,B29,B30,B31,B32,B33,B34,B35,B36,B37,B38,B39) -> 22.197 | C40: =SUM(C6,C7,C8,C9,C10,C11,C12,C13,C14,C15,C16,C17,C18,C19,C20,C21,C22,C23,C24,C25,C26,C27,C28,C29,C30,C31,C32,C33,C34,C35,C36,C37,C38,C39) -> -11.304 | D40: =SUM(D6,D7,D8,D9,D10,D11,D12,D13,D14,D15,D16,D17,D18,D19,D20,D21,D22,D23,D24,D25,D26,D27,D28,D29,D30,D31,D32,D33,D34,D35,D36,D37,D38,D39) -> -11.605 | E40: =SUM(E6,E7,E8,E9,E10,E11,E12,E13,E14,E15,E16,E17,E18,E19,E20,E21,E22,E23,E24,E25,E26,E27,E28,E29,E30,E31,E32,E33,E34,E35,E36,E37,E38,E39) -> 17.242 | F40: =SUM(F6,F7,F8,F9,F10,F11,F12,F13,F14,F15,F16,F17,F18,F19,F20,F21,F22,F23,F24,F25,F26,F27,F28,F29,F30,F31,F32,F33,F34,F35,F36,F37,F38,F39) -> 6.25 | G40: =SUM(G6,G7,G8,G9,G10,G11,G12,G13,G14,G15,G16,G17,G18,G19,G20,G21,G22,G23,G24,G25,G26,G27,G28,G29,G30,G31,G32,G33,G34,G35,G36,G37,G38,G39) -> -1.243 | H40: =SUM(H6,H7,H8,H9,H10,H11,H12,H13,H14,H15,H16,H17,H18,H19,H20,H21,H22,H23,H24,H25,H26,H27,H28,H29,H30,H31,H32,H33,H34,H35,H36,H37,H38,H39) -> -5.036 | I40: =SUM(I6,I7,I8,I9,I10,I11,I12,I13,I14,I15,I16,I17,I18,I19,I20,I21,I22,I23,I24,I25,I26,I27,I28,I29,I30,I31,I32,I33,I34,I35,I36,I37,I38,I39) -> -8.145 | ... AS40: =SUM(AS6,AS7,AS8,AS9,AS10,AS11,AS12,AS13,AS14,AS15,AS16,AS17,AS18,AS19,AS20,AS21,AS22,AS23,AS24,AS25,AS26,AS27,AS28,AS29,AS30,AS31,AS32,AS33,AS34,AS35,AS36,AS37,AS38,AS39) -> -5.107
A41: Investing Activities
...

Sheet Ratios - Quarterly
A1: AeroVironment, Inc. - Ratios
A2: USD mm for market value rows; ratios and percentages as shown
A4: Fiscal quarter end | B4: 1/31/15 | C4: 4/30/15 | D4: 8/1/15 | E4: 10/31/15 | F4: 1/30/16 | G4: 4/30/16 | H4: 7/30/16 | I4: 10/29/16 | J4: 1/28/17 | K4: 4/30/17 | L4: 7/29/17 | M4: 10/28/17 | N4: 1/27/18 | O4: 4/30/18 | P4: 7/28/18 | Q4: 10/27/18 | R4: 1/26/19 | S4: 4/30/19 | T4: 7/27/19 | U4: 10/26/19 | V4: 1/25/20 | W4: 4/30/20 | X4: 8/1/20 | Y4: 10/31/20 | Z4: 1/30/21 | AA4: 4/30/21 | AB4: 7/31/21 | AC4: 10/30/21 | AD4: 1/29/22 | AE4: 4/30/22 | AF4: 7/30/22 | AG4: 10/29/22 | AH4: 1/28/23 | AI4: 4/30/23 | AJ4: 7/29/23 | AK4: 10/28/23 | AL4: 1/27/24 | AM4: 4/30/24 | AN4: 7/27/24 | AO4: 10/26/24 | AP4: 1/25/25 | AQ4: 4/30/25 | AR4: 8/2/25 | AS4: 11/1/25 | AT4: 1/31/26 | AU4: TTM
A5: Valuation and Operating Ratios
A6: Market Cap | B6: 597.037 | C6: 596.855 | D6: 613.209 | E6: 537.962 | F6: 595.888 | G6: 674.635 | H6: 663.249 | I6: 553.681 | J6: 608.932 | K6: 675.121 | L6: 899.971 | M6: 1226.2 | N6: 1271.08 | O6: 1303.03 | P6: 1724.63 | Q6: 2152.36 | R6: 1883.48 | S6: 1641.76 | T6: 1300.76 | U6: 1362.43 | V6: 1629.99 | W6: 1450.07 | X6: 1845.2 | Y6: 1840.58 | Z6: 2766.27 | AA6: 2734.67 | AB6: 2508.47 | AC6: 2210.45 | AD6: 1339.93 | AE6: 2004.09 | AF6: 2165.18 | AG6: 2267.71 | AH6: 2238.39 | AI6: 2639.78 | AJ6: 2498.54 | AK6: 3205.48 | AL6: 3435.5 | AM6: 4495.6 | AN6: 4902.85 | AO6: 6230.54 | AP6: 5089.66 | AQ6: 4283.09 | AR6: 12985.9 | AS6: 18470.4 | AT6: 13901.3 | AU6: 6950.4213
A7: Enterprise Value | B7: 393.479 | C7: 368.064 | D7: 395.741 | E7: 331.963 | F7: 375.88 | G7: 447.393 | H7: 439.491 | I7: 346.873 | J7: 414.777 | K7: 475.646 | L7: 674.987 | M7: 998.4 | N7: 1049.25 | O7: 1045.88 | P7: 1435.55 | Q7: 1862.57 | R7: 1589.28 | S7: 1318.57 | T7: 1010.4 | U7: 1079.18 | V7: 1359.61 | W7: 1157.64 | X7: 1541.82 | Y7: 1506.74 | Z7: 2406.04 | AA7: 2776.74 | AB7: 2621.61 | AC7: 2320.57 | AD7: 1470.95 | AE7: 2118.96 | AF7: 2272.47 | AG7: 2359.52 | AH7: 2356.3 | AI7: 2669.74 | AJ7: 2548.93 | AK7: 3215.8 | AL7: 3397.51 | AM7: 4481.98 | AN7: 4868.99 | AO7: 6211.86 | AP7: 5101.84 | AQ7: 4306.52 | AR7: 13129.8 | AS7: 18707.9 | AT7: 14140.2 | AU7: 7189.2973
A8: Last Close Price | B8: 25.59 | C8: 25.6 | D8: 26.06 | E8: 23.07 | F8: 25.51 | G8: 28.88 | H8: 28.35 | I8: 23.69 | J8: 25.96 | K8: 28.57 | L8: 37.75 | M8: 51.38 | N8: 53.17 | O8: 54.5 | P8: 72.09 | Q8: 89.95 | R8: 78.7 | S8: 68.56 | T8: 54.22 | U8: 56.79 | V8: 67.93 | W8: 60.26 | X8: 76.55 | Y8: 76.36 | Z8: 114.77 | AA8: 110.37 | AB8: 101.1 | AC8: 89.11 | AD8: 53.78 | AE8: 80.32 | AF8: 86.64 | AG8: 90.14 | AH8: 88.6 | AI8: 100.69 | AJ8: 95.03 | AK8: 113.93 | AL8: 122.1 | AM8: 159.79 | AN8: 173.82 | AO8: 220.9 | AP8: 180.36 | AQ8: 151.52 | AR8: 260.07 | AS8: 369.91 | AT8: 278.39 | AU8: 137.95
A9: PE Ratio | C9: 196.923 | E9: 76.9 | F9: 54.2766 | G9: 74.0513 | H9: 157.5 | K9: 51.0179 | L9: 54.7101 | M9: 43.1765 | N9: 42.536 | O9: 59.8901 | P9: 33.8451 | Q9: 43.665 | R9: 32.2541 | S9: 34.802 | T9: 34.9806 | U9: 35.2733 | V9: 55.6803 | W9: 35.2398 | X9: 54.2908 | Y9: 64.1681 | Z9: 92.5565 | AA9: 114.969 | AF9: 1732.8 | AM9: 73.2982 | AN9: 81.6056 | AO9: 126.954 | AP9: 152.847 | AQ9: 97.7548
A10: PS Ratio | C10: 2.30092 | E10: 2.01749 | F10: 2.24176 | G10: 2.88629 | H10: 2.61878 | I10: 2.32005 | J10: 2.71537 | K10: 2.89621 | L10: 3.42174 | M10: 4.3997 | N10: 4.53682 | O10: 4.85436 | P10: 5.52579 | Q10: 6.7412 | R10: 5.5401 | S10: 5.22397 | T10: 4.02536 | U10: 4.08605 | V10: 5.09366 | W10: 3.94797 | X10: 5.01639 | Y10: 4.87921 | Z10: 7.01884 | AA10: 6.92476 | AB10: 6.14113 | AC10: 5.04883 | AD10: 2.98343 | AE10: 4.49617 | AF10: 4.77714 | AG10: 5.12112 | AH10: 4.59518 | AI10: 4.88363 | AJ10: 4.27564 | AK10: 4.90436 | AL10: 4.86764 | AM10: 6.27247 | AN10: 6.5037 | AO10: 8.18195 | AP10: 6.85424 | AQ10: 5.21929 | AR10: 11.9595 | AS10: 13.4833 | AT10: 8.63287 | AU10: 4.31628
A11: PB Ratio | B11: 1.75172 | C11: 1.71062 | D11: 1.77687 | E11: 1.55154 | F11: 1.68059 | G11: 1.86608 | H11: 1.88702 | I11: 1.59037 | J11: 1.75361 | K11: 1.76755 | L11: 2.36385 | M11: 3.14894 | N11: 3.25595 | O11: 3.18563 | P11: 3.94608 | Q11: 4.84575 | R11: 4.13438 | S11: 3.5492 | T11: 2.70145 | U11: 2.77842 | V11: 3.32148 | W11: 2.84384 | X11: 3.54895 | Y11: 3.51319 | Z11: 5.26717 | AA11: 4.46774 | AB11: 4.19309 | AC11: 3.68468 | AD11: 2.22422 | AE11: 3.29636 | AF11: 3.6091 | AG11: 3.73296 | AH11: 3.60152 | AI11: 4.79115 | AJ11: 4.34873 | AK11: 4.0385 | AL11: 4.22578 | AM11: 5.46415 | AN11: 5.7985 | AO11: 7.25834 | AP11: 5.91096 | AQ11: 4.83143 | AR11: 2.93329 | AS11: 4.18064 | AT11: 3.32177 | AU11: 1.60525
A12: P/TBV Ratio | B12: 1.735 | C12: 1.698 | D12: 1.733 | E12: 1.54 | F12: 1.661 | G12: 1.849 | H12: 1.852 | I12: 1.568 | J12: 1.726 | K12: 1.748 | L12: 2.314 | M12: 3.145 | N12: 3.203 | O12: 3.187 | P12: 3.96 | Q12: 4.88 | R12: 4.16 | S12: 3.575 | T12: 2.858 | U12: 2.93 | V12: 3.443 | W12: 2.968 | X12: 3.698 | Y12: 3.656 | Z12: 5.489 | AA12: 14.273 | AB12: 17.124 | AC12: 14.457 | AD12: 8.187 | AE12: 11.354 | AF12: 12.272 | AG12: 12.208 | AH12: 10.997 | AI12: 7.847 | AJ12: 7.043 | AK12: 7.042 | AL12: 7.441 | AM12: 9.454 | AN12: 9.791 | AO12: 11.96 | AP12: 9.576 | AQ12: 7.371 | AR12: 15.862 | AS12: 22.359 | AT12: 15.617 | AU12: 6.792
A13: P/FCF Ratio | C13: 17.4856 | F13: 64.1705 | H13: 322.749 | I13: 64.0687 | L13: 146.814 | M13: 81.9051 | N13: 49.328 | O13: 21.6202 | P13: 41.7911 | Q13: 62.8389 | R13: 51.9711 | S13: 90.9561 | T13: 83.1264 | U13: 66.1469 | V13: 66.4731 | W13: 104.495 | X13: 52.0656 | Y13: 28.1654 | Z13: 35.5538 | AA13: 36.332 | AB13: 78.9747 | AC13: 354.409 | AG13: 253.971 | AH13: 318.95 | AL13: 314.865 | AN13: 136.478 | AO13: 147.416
A14: P/OCF Ratio | C14: 15.1436 | F14: 36.1188 | G14: 111.565 | H14: 62.4999 | I14: 32.2264 | L14: 56.0276 | M14: 47.5751 | N14: 35.5478 | O14: 18.6594 | P14: 34.8066 | Q14: 50.6497 | R14: 41.9512 | S14: 60.9277 | T14: 51.9827 | U14: 42.3009 | V14: 46.4186 | W14: 57.7788 | X14: 37.7922 | Y14: 24.2914 | Z14: 31.0841 | AA14: 31.603 | AB14: 56.5137 | AC14: 89.8739 | AF14: 100.365 | AG14: 88.3821 | AH14: 100.111 | AI14: 231.56 | AL14: 116.205 | AM14: 293.984 | AN14: 80.7652 | AO14: 94.9907
A15: EV/Revenue | C15: 1.41892 | E15: 1.24494 | F15: 1.41408 | G15: 1.91408 | H15: 1.73529 | I15: 1.45348 | J15: 1.84959 | K15: 2.04048 | L15: 2.56634 | M15: 3.58233 | N15: 3.74502 | O15: 3.89638 | P15: 4.59956 | Q15: 5.83358 | R15: 4.67473 | S15: 4.1956 | T15: 3.12679 | U15: 3.23656 | V15: 4.24873 | W15: 3.15179 | X15: 4.1916 | Y15: 3.99422 | Z15: 6.10484 | AA15: 7.03129 | AB15: 6.4181 | AC15: 5.30036 | AD15: 3.27515 | AE15: 4.75388 | AF15: 5.01386 | AG15: 5.32845 | AH15: 4.83724 | AI15: 4.93906 | AJ15: 4.36187 | AK15: 4.92014 | AL15: 4.81382 | AM15: 6.25346 | AN15: 6.45878 | AO15: 8.15742 | AP15: 6.87065 | AQ15: 5.24784 | AR15: 12.0921 | AS15: 13.6567 | AT15: 8.78122 | AU15: 4.46463
A16: EV/EBITDA | C16: 35.4589 | E16: 31.7486 | F16: 22.2177 | G16: 13.2911 | H16: 46.0489 | K16: 109.9 | L16: 754.176 | M16: 199.202 | N16: 23.3249 | O16: 28.7267 | P16: 24.2997 | Q16: 33.4693 | R16: 24.9163 | S16: 31.7765 | T16: 37.5654 | U16: 30.3832 | V16: 38.7507 | W16: 13.9705 | X16: 51.6868 | Y16: 41.6433 | Z16: 41.2849 | AA16: 34.5645 | AB16: 39.2456 | AC16: 33.2975 | AD16: 20.8146 | AE16: 41.5987 | AF16: 37.7971 | AG16: 53.1663 | AH16: 38.2958 | AM16: 41.6645 | AN16: 45.862 | AO16: 70.1429 | AP16: 72.0121 | AQ16: 52.6515 | AR16: 185.282 | AS16: 226.2 | AU16: 47.55927
A17: EV/EBIT | C17: 182.753 | E17: 31.7486 | F17: 36.2363 | G17: 15.0102 | H17: 136.53 | N17: 27.0139 | O17: 34.3747 | P17: 27.2117 | Q17: 38.1143 | R17: 28.104 | S17: 38.9809 | T17: 53.4742 | U17: 40.0468 | V17: 52.6163 | W17: 15.8635 | X17: 80.1277 | Y17: 60.0605 | Z17: 51.3585 | AA17: 45.4659 | AB17: 71.5056 | AC17: 88.8972 | AD17: 116.557 | AH17: 73634.5 | AM17: 62.4022 | AN17: 71.0636 | AO17: 123.388 | AP17: 154.963 | AQ17: 105.565
A18: EV/FCF | C18: 10.7829 | F18: 40.4781 | H18: 213.864 | I18: 40.1381 | L18: 110.112 | M18: 66.6889 | N18: 40.7189 | O18: 17.3536 | P18: 34.7861 | Q18: 54.3784 | R18: 43.8532 | S18: 73.0508 | T18: 64.5703 | U18: 52.395 | V18: 55.4466 | W18: 83.4214 | X18: 43.505 | Y18: 23.0568 | Z18: 30.924 | AA18: 36.8909 | AB18: 82.5366 | AC18: 372.065 | AG18: 264.254 | AH18: 335.751 | AL18: 311.383 | AN18: 135.536 | AO18: 146.974
A19: Debt/Equity | B19: 0 | C19: 0 | D19: 0 | E19: 0 | F19: 0.00109428 | G19: 0.00124196 | H19: 0.00101571 | I19: 0.000792769 | J19: 0.000627797 | K19: 0.000421253 | L19: 0.00027301 | M19: 0.000128399 | N19: 1.79308e-05 | O19: 0 | P19: 0 | Q19: 0 | R19: 0 | S19: 0 | T19: 0.0157778 | U19: 0.0139551 | V19: 0.0153978 | W19: 0.0134006 | X19: 0.0198964 | Y19: 0.0179862 | Z19: 0.0160441 | AA19: 0.337547 | AB19: 0.347958 | AC19: 0.340591 | AD19: 0.333617 | AE19: 0.328431 | AF19: 0.326328 | AG19: 0.289169 | AH19: 0.28703 | AI19: 0.266971 | AJ19: 0.240174 | AK19: 0.122718 | AL19: 0.065524 | AM19: 0.0484196 | AN19: 0.032966 | AO19: 0.0474023 | AP19: 0.0578593 | AQ19: 0.0607012 | AR19: 0.183631 | AS19: 0.183588 | AT19: 0.193658 | AU19: 0.193658
