Workbook

Sheet Summary
A1: CAT | B1: 818
A2: Shares | B2: ='Income-Quarterly'!AT24 -> 465.8
A3: MC | B3: =B2*B1 -> 381024.4
A4: Cash | B4: =SUM('Balance-Sheet-Quarterly'!AT2) -> 4072
A5: Debt | B5: 43066
A6: EV | B6: =B3-B4+B5 -> 420018.4
A7: TTM EV/EBIT | B7: =B6/SUM('Income-Quarterly'!AQ26:AT26) -> 29.477044
A8: Fwd EV/EBIT | B8: =B6/SUM('Income-Quarterly'!AU26:AW26) -> 31.248872
C9: Peer Group | D9: Company | E9: Ticker | F9: Currency | G9: EBIT Period | H9: EV | I9: Clean EBIT | J9: EV / Clean EBIT | K9: Forward Period | L9: Forward Clean EBIT | M9: Forward EV / Clean EBIT
C10: Core Equipment | D10: Caterpillar | E10: CAT | F10: USD | G10: FY2026E | H10: =B6 -> 420018.4 | I10: =SUM('Income-Quarterly'!AQ26:AT26) -> 14249 | J10: =H10/I10 -> 29.477044 | K10: FY2027E | L10: =SUM('Income-Quarterly'!AU26:AW26) -> 13441.074 | M10: =H10/L10 -> 31.248872
C11: Core Equipment | D11: Deere & Company | E11: DE | F11: USD | G11: FY2026E | H11: 164984 | I11: 6033 | J11: =H11/I11 -> 27.346925 | K11: FY2027E | L11: 7473 | M11: =H11/L11 -> 22.077345
C12: Core Equipment | D12: Komatsu | E12: 6301 JP | F12: JPY | G12: Mar-2027E | H12: 6691000 | I12: 555000 | J12: =H12/I12 -> 12.055856 | K12: Mar-2028E | L12: 612173 | M12: =H12/L12 -> 10.929917
C13: Core Equipment | D13: AB Volvo | E13: VOLV B SS | F13: SEK | G13: FY2026E | H13: 682967 | I13: 57816 | J13: =H13/I13 -> 11.812768 | K13: FY2027E | L13: 67495 | M13: =H13/L13 -> 10.118779
C14: Core Equipment | D14: CNH Industrial | E14: CNH | F14: USD | G14: FY2026E | H14: 16276 | I14: 485.5 | J14: =H14/I14 -> 33.524202 | K14: FY2027E | L14: 975.8 | M14: =H14/L14 -> 16.679647
C15: Core Equipment | D15: Hitachi Construction Machinery | E15: 6305 JP | F15: JPY | G15: Mar-2027E | H15: 1534086 | I15: 145485 | J15: =H15/I15 -> 10.544633 | K15: Mar-2028E | L15: 172701 | M15: =H15/L15 -> 8.8829017
C16: Core Equipment | D16: Doosan Bobcat | E16: 241560 KS | F16: USD | G16: FY2026E | H16: 3430 | I16: 482 | J16: =H16/I16 -> 7.1161826 | K16: FY2027E | L16: 647 | M16: =H16/L16 -> 5.301391
C17: Core Equipment | D17: HD Construction Equipment | E17: 267270 KS | F17: KRW | G17: FY2026E | H17: 7740000 | I17: 686700 | J17: =H17/I17 -> 11.271298 | K17: FY2027E | L17: 825600 | M17: =H17/L17 -> 9.375
C18: Core Equipment | D18: Kubota | E18: 6326 JP | F18: JPY | G18: FY2026E | H18: 5003315 | I18: 322795 | J18: =H18/I18 -> 15.499977 | K18: FY2027E | L18: 356415 | M18: =H18/L18 -> 14.037891
C19: Core Equipment | D19: Sany Heavy Industry | E19: 600031 CH | F19: CNY | G19: FY2026E | H19: 148363 | I19: 12123 | J19: =H19/I19 -> 12.238142 | K19: FY2027E | L19: 15174 | M19: =H19/L19 -> 9.7774483
C20: Core Equipment | D20: XCMG Machinery | E20: 000425 CH | F20: CNY | G20: FY2026E | H20: 128550 | I20: 10413 | J20: =H20/I20 -> 12.345145 | K20: FY2027E | L20: 12896 | M20: =H20/L20 -> 9.9682072
C21: Mining Systems | D21: Epiroc | E21: EPI A SS | F21: SEK | G21: FY2026E | H21: 279759 | I21: 13684 | J21: =H21/I21 -> 20.444241 | K21: FY2027E | L21: 16227 | M21: =H21/L21 -> 17.24034
C22: Mining Systems | D22: Sandvik | E22: SAND SS | F22: SEK | G22: FY2026E | H22: 463267 | I22: 29586 | J22: =H22/I22 -> 15.658318 | K22: FY2027E | L22: 32374 | M22: =H22/L22 -> 14.309847
... C30: Power, Engines & Rail | D30: Wabtec | E30: WAB | F30: USD | G30: FY2026E | H30: 50679 | I30: 2652 | J30: =H30/I30 -> 19.109729 | K30: FY2027E | L30: 2939 | M30: =H30/L30 -> 17.24362
C32: Peer Summary
D33: Core Equipment Median | J33: =MEDIAN(J11:J20) -> 12.146999 | M33: =MEDIAN(M11:M20) -> 10.043493
D34: Mining Systems Median | J34: =MEDIAN(J21:J23) -> 15.658318 | M34: =MEDIAN(M21:M23) -> 14.309847
D35: Power, Engines & Rail Median | J35: =MEDIAN(J24:J30) -> 18.501401 | M35: =MEDIAN(M24:M30) -> 15.603591
D36: Overall Peer Median | J36: =MEDIAN(J11:J30) -> 15.466499 | M36: =MEDIAN(M11:M30) -> 14.079503
D37: Overall Peer Mean | J37: =AVERAGE(J11:J30) -> 17.898587 | M37: =AVERAGE(M11:M30) -> 13.798718

Sheet Income-Quarterly
A1: Date | B1: Q115 | C1: Q215 | D1: Q315 | E1: Q415 | F1: Q116 | G1: Q216 | H1: Q316 | I1: Q416 | J1: Q117 | K1: Q217 | L1: Q317 | M1: Q417 | N1: Q118 | O1: Q218 | P1: Q318 | Q1: Q418 | R1: Q119 | S1: Q219 | T1: Q319 | U1: Q419 | V1: Q120 | W1: Q220 | X1: Q320 | Y1: Q420 | Z1: Q121 | AA1: Q221 | AB1: Q321 | AC1: Q421 | AD1: Q122 | AE1: Q222 | AF1: Q322 | AG1: Q422 | AH1: Q123 | AI1: Q223 | AJ1: Q323 | AK1: Q423 | AL1: Q124 | AM1: Q224 | AN1: Q324 | AO1: Q424 | AP1: Q125 | AQ1: Q225 | AR1: Q325 | AS1: Q425 | AT1: Q126 | AU1: Q226 | AV1: Q326 | AW1: Q426 | BC1: FY15 | BD1: FY16 | BE1: FY17 | BF1: FY18 | BG1: FY19 | BH1: FY20 | BI1: FY21 | BJ1: FY22 | BK1: FY23 | BL1: FY24 | BM1: FY25 | BN1: FY26 | BO1: FY27 | BP1: FY28 | BQ1: FY29 | BR1: FY30 | BS1: FY31
A2: Sales of Machinery, Power & Energy | B2: 11961 | C2: 11583 | D2: 10285 | E2: 11118 | F2: 8780 | G2: 9645 | H2: 8463 | I2: 8885 | J2: 9130 | K2: 10639 | L2: 10713 | M2: 12194 | N2: 12150 | O2: 13279 | P2: 12763 | Q2: 13630 | R2: 12724 | S2: 13671 | T2: 11974 | U2: 12386 | V2: 9914 | W2: 9310 | X2: 9228 | Y2: 10570 | Z2: 11191 | AA2: 12193 | AB2: 11707 | AC2: 13097 | AD2: 12886 | AE2: 13539 | AF2: 14278 | AG2: 15871 | AH2: 15099 | AI2: 16545 | AJ2: 15988 | AK2: 16237 | AL2: 14960 | AM2: 15840 | AN2: 15231 | AO2: 15332 | AP2: 13378 | AQ2: 15674 | AR2: 16726 | AS2: 18202 | AT2: 16473 | AU2: 19000 | AV2: 20100 | AW2: 21500 | BC2: =SUM(B2:E2) -> 44947 | BD2: =SUM(F2:I2) -> 35773 | BE2: =SUM(J2:M2) -> 42676 | BF2: =SUM(N2:Q2) -> 51822 | BG2: =SUM(R2:U2) -> 50755 | BH2: =SUM(V2:Y2) -> 39022 | BI2: =SUM(Z2:AC2) -> 48188 | BJ2: =SUM(AD2:AG2) -> 56574 | BK2: =SUM(AH2:AK2) -> 63869 | BL2: =SUM(AL2:AO2) -> 61363 | BM2: =SUM(AP2:AS2) -> 63980 | BN2: =SUM(AT2:AW2) -> 77073 | BO2: 79200 | BP2: 83500 | BQ2: 87400 | BR2: 90900 | BS2: 94100
A3: Revenues of Financial Products | B3: 741 | C3: 734 | D3: 677 | E3: 712 | F3: 681 | G3: 697 | H3: 697 | I3: 689 | J3: 692 | K3: 692 | L3: 700 | M3: 702 | N3: 709 | O3: 732 | P3: 747 | Q3: 712 | R3: 742 | S3: 761 | T3: 784 | U3: 758 | V3: 721 | W3: 687 | X3: 653 | Y3: 665 | Z3: 696 | AA3: 696 | AB3: 690 | AC3: 701 | AD3: 703 | AE3: 708 | AF3: 716 | AG3: 726 | AH3: 763 | AI3: 773 | AJ3: 822 | AK3: 833 | AL3: 839 | AM3: 849 | AN3: 875 | AO3: 883 | AP3: 871 | AQ3: 895 | AR3: 912 | AS3: 931 | AT3: 942 | AU3: 0 | AV3: 0 | AW3: 0 | BC3: =SUM(B3:E3) -> 2864 | BD3: =SUM(F3:I3) -> 2764 | BE3: =SUM(J3:M3) -> 2786 | BF3: =SUM(N3:Q3) -> 2900 | BG3: =SUM(R3:U3) -> 3045 | BH3: =SUM(V3:Y3) -> 2726 | BI3: =SUM(Z3:AC3) -> 2783 | BJ3: =SUM(AD3:AG3) -> 2853 | BK3: =SUM(AH3:AK3) -> 3191 | BL3: =SUM(AL3:AO3) -> 3446 | BM3: =SUM(AP3:AS3) -> 3609 | BN3: =SUM(AT3:AW3) -> 942 | BO3: 0 | BP3: 0 | BQ3: 0 | BR3: 0 | BS3: 0
A4: Total sales and revenues | B4: =SUM(B2:B3) -> 12702 | C4: =SUM(C2:C3) -> 12317 | D4: =SUM(D2:D3) -> 10962 | E4: =SUM(E2:E3) -> 11830 | F4: =SUM(F2:F3) -> 9461 | G4: =SUM(G2:G3) -> 10342 | H4: =SUM(H2:H3) -> 9160 | I4: =SUM(I2:I3) -> 9574 | ... AW4: =SUM(AW2:AW3) -> 21500 | BC4: =SUM(B4:E4) -> 47811 | BD4: =SUM(F4:I4) -> 38537 | BE4: =SUM(J4:M4) -> 45462 | BF4: =SUM(N4:Q4) -> 54722 | BG4: =SUM(R4:U4) -> 53800 | BH4: =SUM(V4:Y4) -> 41748 | BI4: =SUM(Z4:AC4) -> 50971 | BJ4: =SUM(AD4:AG4) -> 59427 | BK4: =SUM(AH4:AK4) -> 67060 | BL4: =SUM(AL4:AO4) -> 64809 | BM4: =SUM(AP4:AS4) -> 67589 | BN4: =SUM(AT4:AW4) -> 78015 | BO4: =SUM(BO2:BO3) -> 79200 | BP4: =SUM(BP2:BP3) -> 83500 | BQ4: =SUM(BQ2:BQ3) -> 87400 | BR4: =SUM(BR2:BR3) -> 90900 | BS4: =SUM(BS2:BS3) -> 94100
A5: Cost of goods sold | B5: 8760 | C5: 8674 | D5: 7872 | E5: 7987 | F5: 6822 | G5: 7419 | H5: 6527 | I5: 7276 | J5: 6801 | K5: 7816 | L5: 7678 | M5: 8965 | N5: 8566 | O5: 9422 | P5: 9022 | Q5: 9987 | R5: 9003 | S5: 9941 | T5: 8569 | U5: 9117 | V5: 7266 | W5: 7113 | X5: 6919 | Y5: 7784 | Z5: 8012 | AA5: 8881 | AB5: 8617 | AC5: 10003 | AD5: 9559 | AE5: 9975 | AF5: 10202 | AG5: 11614 | AH5: 10103 | AI5: 11065 | AJ5: 10583 | AK5: 11016 | AL5: 9662 | AM5: 10150 | AN5: 10066 | AO5: 10321 | AP5: 8965 | AQ5: 10807 | AR5: 11673 | AS5: 13307 | AT5: 11306 | AU5: =AU$4*AU43 -> 12277.999 | AV5: =AV$4*AV43 -> 12928.53 | AW5: =AW$4*AW43 -> 13764.525 | BC5: =SUM(B5:E5) -> 33293 | BD5: =SUM(F5:I5) -> 28044 | BE5: =SUM(J5:M5) -> 31260 | BF5: =SUM(N5:Q5) -> 36997 | BG5: =SUM(R5:U5) -> 36630 | BH5: =SUM(V5:Y5) -> 29082 | BI5: =SUM(Z5:AC5) -> 35513 | BJ5: =SUM(AD5:AG5) -> 41350 | BK5: =SUM(AH5:AK5) -> 42767 | BL5: =SUM(AL5:AO5) -> 40199 | BM5: =SUM(AP5:AS5) -> 44752 | BN5: =SUM(AT5:AW5) -> 50277.053
A6: Financial products interest | B6: 150 | C6: 148 | D6: 142 | E6: 147 | F6: 152 | G6: 148 | H6: 147 | I6: 149 | J6: 159 | K6: 162 | L6: 163 | M6: 162 | N6: 166 | O6: 182 | P6: 185 | Q6: 189 | R6: 190 | S6: 192 | T6: 189 | U6: 183 | V6: 175 | W6: 149 | X6: 137 | Y6: 128 | Z6: 125 | AA6: 116 | AB6: 111 | AC6: 103 | AD6: 106 | AE6: 120 | AF6: 151 | AG6: 188 | AH6: 217 | AI6: 245 | AJ6: 280 | AK6: 288 | AL6: 298 | AM6: 314 | AN6: 336 | AO6: 338 | AP6: 326 | AQ6: 336 | AR6: 346 | AS6: 351 | AT6: 345 | AU6: =AU$4*AU44 -> 380 | AV6: =AV$4*AV44 -> 402 | AW6: =AW$4*AW44 -> 430 | BC6: =SUM(B6:E6) -> 587 | BD6: =SUM(F6:I6) -> 596 | BE6: =SUM(J6:M6) -> 646 | BF6: =SUM(N6:Q6) -> 722 | BG6: =SUM(R6:U6) -> 754 | BH6: =SUM(V6:Y6) -> 589 | BI6: =SUM(Z6:AC6) -> 455 | BJ6: =SUM(AD6:AG6) -> 565 | BK6: =SUM(AH6:AK6) -> 1030 | BL6: =SUM(AL6:AO6) -> 1286 | BM6: =SUM(AP6:AS6) -> 1359 | BN6: =SUM(AT6:AW6) -> 1557
A7: Gross profit | B7: =B4-B5-B6 -> 3792 | C7: =C4-C5-C6 -> 3495 | D7: =D4-D5-D6 -> 2948 | E7: =E4-E5-E6 -> 3696 | F7: =F4-F5-F6 -> 2487 | G7: =G4-G5-G6 -> 2775 | H7: =H4-H5-H6 -> 2486 | I7: =I4-I5-I6 -> 2149 | ... AW7: =AW4-AW5-AW6 -> 7305.4753 | BC7: =SUM(B7:E7) -> 13931 | BD7: =SUM(F7:I7) -> 9897 | BE7: =SUM(J7:M7) -> 13556 | BF7: =SUM(N7:Q7) -> 17003 | BG7: =SUM(R7:U7) -> 16416 | BH7: =SUM(V7:Y7) -> 12077 | BI7: =SUM(Z7:AC7) -> 15003 | BJ7: =SUM(AD7:AG7) -> 17512 | BK7: =SUM(AH7:AK7) -> 23263 | BL7: =SUM(AL7:AO7) -> 23324 | BM7: =SUM(AP7:AS7) -> 21478 | BN7: =SUM(AT7:AW7) -> 26180.947
A8: SGA | B8: 1249 | C8: 1318 | D8: 1129 | E8: 1267 | F8: 1088 | G8: 1123 | H8: 992 | I8: 1483 | J8: 1061 | K8: 1304 | L8: 1254 | M8: 1606 | N8: 1276 | O8: 1440 | P8: 1299 | Q8: 1463 | R8: 1319 | S8: 1309 | T8: 1251 | U8: 1283 | V8: 1121 | W8: 1179 | X8: 1126 | Y8: 1216 | Z8: 1239 | AA8: 1364 | AB8: 1340 | AC8: 1422 | AD8: 1346 | AE8: 1425 | AF8: 1401 | AG8: 1479 | AH8: 1463 | AI8: 1528 | AJ8: 1624 | AK8: 1756 | AL8: 1577 | AM8: 1652 | AN8: 1669 | AO8: 1769 | AP8: 1593 | AQ8: 1694 | AR8: 1822 | AS8: 1876 | AT8: 1816 | AU8: =AU$4*AU46 -> 1981.2805 | AV8: =AV$4*AV46 -> 2095.9862 | AW8: =AW$4*AW46 -> 2241.9753 | BC8: =SUM(B8:E8) -> 4963 | BD8: =SUM(F8:I8) -> 4686 | BE8: =SUM(J8:M8) -> 5225 | BF8: =SUM(N8:Q8) -> 5478 | BG8: =SUM(R8:U8) -> 5162 | BH8: =SUM(V8:Y8) -> 4642 | BI8: =SUM(Z8:AC8) -> 5365 | BJ8: =SUM(AD8:AG8) -> 5651 | BK8: =SUM(AH8:AK8) -> 6371 | BL8: =SUM(AL8:AO8) -> 6667 | BM8: =SUM(AP8:AS8) -> 6985 | BN8: =SUM(AT8:AW8) -> 8135.242
A9: RD | B9: 524 | C9: 510 | D9: 513 | E9: 507 | F9: 508 | G9: 468 | H9: 453 | I9: 522 | J9: 425 | K9: 458 | L9: 461 | M9: 579 | N9: 443 | O9: 462 | P9: 479 | Q9: 466 | R9: 435 | S9: 441 | T9: 431 | U9: 386 | V9: 356 | W9: 341 | X9: 344 | Y9: 374 | Z9: 374 | AA9: 446 | AB9: 427 | AC9: 439 | AD9: 457 | AE9: 480 | AF9: 476 | AG9: 401 | AH9: 472 | AI9: 528 | AJ9: 554 | AK9: 554 | AL9: 520 | AM9: 535 | AN9: 533 | AO9: 519 | AP9: 480 | AQ9: 551 | AR9: 555 | AS9: 562 | AT9: 537 | AU9: =AU$4*AU47 -> 585.87425 | AV9: =AV$4*AV47 -> 619.79328 | AW9: =AW$4*AW47 -> 662.96296 | BC9: =SUM(B9:E9) -> 2054 | BD9: =SUM(F9:I9) -> 1951 | BE9: =SUM(J9:M9) -> 1923 | BF9: =SUM(N9:Q9) -> 1850 | BG9: =SUM(R9:U9) -> 1693 | BH9: =SUM(V9:Y9) -> 1415 | BI9: =SUM(Z9:AC9) -> 1686 | BJ9: =SUM(AD9:AG9) -> 1814 | BK9: =SUM(AH9:AK9) -> 2108 | BL9: =SUM(AL9:AO9) -> 2107 | BM9: =SUM(AP9:AS9) -> 2148 | BN9: =SUM(AT9:AW9) -> 2405.6305
A10: Other operating expenses | B10: 317 | C10: 334 | D10: 381 | E10: 955 | F10: 397 | G10: 399 | H10: 560 | I10: 548 | J10: 996 | K10: 407 | L10: 348 | M10: 504 | N10: 300 | O10: 338 | P10: 390 | Q10: 354 | R10: 312 | S10: 336 | T10: 298 | U10: 325 | V10: 313 | W10: 431 | X10: 370 | Y10: 353 | Z10: 323 | AA10: 293 | AB10: 238 | AC10: 220 | AD10: 266 | AE10: 303 | AF10: 339 | AG10: 310 | AH10: 876 | AI10: 300 | AJ10: 320 | AK10: 322 | AL10: 223 | AM10: 556 | AN10: 355 | AO10: 344 | AP10: 306 | AQ10: 321 | AR10: 190 | AS10: 377 | AT10: 326 | AU10: =AU$4*AU48 -> 355.6704 | AV10: =AV$4*AV48 -> 376.26184 | AW10: =AW$4*AW48 -> 402.46914 | BC10: =SUM(B10:E10) -> 1987 | BD10: =SUM(F10:I10) -> 1904 | BE10: =SUM(J10:M10) -> 2255 | BF10: =SUM(N10:Q10) -> 1382 | BG10: =SUM(R10:U10) -> 1271 | BH10: =SUM(V10:Y10) -> 1467 | BI10: =SUM(Z10:AC10) -> 1074 | BJ10: =SUM(AD10:AG10) -> 1218 | BK10: =SUM(AH10:AK10) -> 1818 | BL10: =SUM(AL10:AO10) -> 1478 | BM10: =SUM(AP10:AS10) -> 1194 | BN10: =SUM(AT10:AW10) -> 1460.4014
A11: Operating profit | B11: =B7-B8-B9-B10 -> 1702 | C11: =C7-C8-C9-C10 -> 1333 | D11: =D7-D8-D9-D10 -> 925 | E11: =E7-E8-E9-E10 -> 967 | F11: =F7-F8-F9-F10 -> 494 | G11: =G7-G8-G9-G10 -> 785 | H11: =H7-H8-H9-H10 -> 481 | I11: =I7-I8-I9-I10 -> -404 | ... AW11: =AW7-AW8-AW9-AW10 -> 3998.0679 | BC11: =SUM(B11:E11) -> 4927 | BD11: =SUM(F11:I11) -> 1356 | BE11: =SUM(J11:M11) -> 4153 | BF11: =SUM(N11:Q11) -> 8293 | BG11: =SUM(R11:U11) -> 8290 | BH11: =SUM(V11:Y11) -> 4553 | BI11: =SUM(Z11:AC11) -> 6878 | BJ11: =SUM(AD11:AG11) -> 8829 | BK11: =SUM(AH11:AK11) -> 12966 | BL11: =SUM(AL11:AO11) -> 13072 | BM11: =SUM(AP11:AS11) -> 11151 | BN11: =SUM(AT11:AW11) -> 14179.673
A12: Interest expense | B12: 129 | C12: 125 | D12: 127 | E12: 126 | F12: 129 | G12: 130 | H12: 126 | I12: 120 | J12: 123 | K12: 121 | L12: 118 | M12: 169 | N12: 101 | O12: 102 | P12: 102 | Q12: 99 | R12: 103 | S12: 103 | T12: 103 | U12: 112 | V12: 113 | W12: 135 | X12: 136 | Y12: 130 | Z12: 142 | AA12: 120 | AB12: 114 | AC12: 112 | AD12: 109 | AE12: 108 | AF12: 109 | AG12: 117 | AH12: 129 | AI12: 127 | AJ12: 129 | AK12: 126 | AL12: 143 | AM12: 137 | AN12: 125 | AO12: 107 | AP12: 116 | AQ12: 126 | AR12: 133 | AS12: 127 | AT12: 134 | AU12: =AU$4*AU50 -> 146.19581 | AV12: =AV$4*AV50 -> 154.65978 | AW12: =AW$4*AW50 -> 165.4321 | BC12: =SUM(B12:E12) -> 507 | BD12: =SUM(F12:I12) -> 505 | BE12: =SUM(J12:M12) -> 531 | BF12: =SUM(N12:Q12) -> 404 | BG12: =SUM(R12:U12) -> 421 | BH12: =SUM(V12:Y12) -> 514 | BI12: =SUM(Z12:AC12) -> 488 | BJ12: =SUM(AD12:AG12) -> 443 | BK12: =SUM(AH12:AK12) -> 511 | BL12: =SUM(AL12:AO12) -> 512 | BM12: =SUM(AP12:AS12) -> 502 | BN12: =SUM(AT12:AW12) -> 600.28768
A13: Other income | B13: 194 | C13: -72 | D13: -15 | E13: 30 | G13: 84 | H13: 28 | I13: 34 | J13: 32 | K13: 96 | L13: 132 | M13: -107 | N13: 127 | O13: 121 | P13: 102 | Q13: -417 | R13: 160 | S13: 68 | T13: 88 | U13: -373 | V13: 222 | W13: 29 | X13: 14 | Y13: -309 | Z13: 325 | AA13: 201 | AB13: 225 | AC13: 1063 | AD13: 253 | AE13: 260 | AF13: 242 | AG13: 536 | AH13: 32 | AI13: 127 | AJ13: 195 | AK13: 241 | AL13: 156 | AM13: 155 | AN13: 76 | AO13: 426 | AP13: 107 | AQ13: 84 | AR13: 208 | AS13: 493 | AT13: 260 | AU13: =AU$4*AU51 -> 0 | AV13: =AV$4*AV51 -> 0 | AW13: =AW$4*AW51 -> 0 | BC13: =SUM(B13:E13) -> 137 | BD13: =SUM(F13:I13) -> 146 | BE13: =SUM(J13:M13) -> 153 | BF13: =SUM(N13:Q13) -> -67 | BG13: =SUM(R13:U13) -> -57 | BH13: =SUM(V13:Y13) -> -44 | BI13: =SUM(Z13:AC13) -> 1814 | BJ13: =SUM(AD13:AG13) -> 1291 | BK13: =SUM(AH13:AK13) -> 595 | BL13: =SUM(AL13:AO13) -> 813 | BM13: =SUM(AP13:AS13) -> 892 | BN13: =SUM(AT13:AW13) -> 260
A14: Consolidated profit before taxes | B14: =B11-B12+B13 -> 1767 | C14: =C11-C12+C13 -> 1136 | D14: =D11-D12+D13 -> 783 | E14: =E11-E12+E13 -> 871 | F14: =F11-F12+F13 -> 365 | G14: =G11-G12+G13 -> 739 | H14: =H11-H12+H13 -> 383 | I14: =I11-I12+I13 -> -490 | ... AW14: =AW11-AW12+AW13 -> 3832.6358 | BC14: =SUM(B14:E14) -> 4557 | BD14: =SUM(F14:I14) -> 997 | BE14: =SUM(J14:M14) -> 3775 | BF14: =SUM(N14:Q14) -> 7822 | BG14: =SUM(R14:U14) -> 7812 | BH14: =SUM(V14:Y14) -> 3995 | BI14: =SUM(Z14:AC14) -> 8204 | BJ14: =SUM(AD14:AG14) -> 9677 | BK14: =SUM(AH14:AK14) -> 13050 | BL14: =SUM(AL14:AO14) -> 13373 | BM14: =SUM(AP14:AS14) -> 11541 | BN14: =SUM(AT14:AW14) -> 13839.385
A15: Provision for income taxes | B15: 521 | C15: 335 | D15: 218 | E15: -128 | F15: 92 | G15: 184 | H15: 96 | I15: -180 | J15: 90 | K15: 361 | L15: 470 | M15: 2418 | N15: 472 | O15: 490 | P15: 415 | Q15: 321 | R15: 387 | S15: 565 | T15: 518 | U15: 276 | V15: 425 | W15: 227 | X15: 187 | Y15: 167 | Z15: 475 | AA15: 470 | AB15: 368 | AC15: 429 | AD15: 469 | AE15: 427 | AF15: 527 | AG15: 644 | AH15: 708 | AI15: 752 | AJ15: 734 | AK15: 587 | AL15: 688 | AM15: 836 | AN15: 642 | AO15: 463 | AP15: 574 | AQ15: 646 | AR15: 836 | AS15: 712 | AT15: 670 | AU15: =+AU14*AU29 -> 687.3259 | AV15: =+AV14*AV29 -> 739.78145 | AW15: =+AW14*AW29 -> 804.85352 | BC15: =SUM(B15:E15) -> 946 | BD15: =SUM(F15:I15) -> 192 | BE15: =SUM(J15:M15) -> 3339 | BF15: =SUM(N15:Q15) -> 1698 | BG15: =SUM(R15:U15) -> 1746 | BH15: =SUM(V15:Y15) -> 1006 | BI15: =SUM(Z15:AC15) -> 1742 | BJ15: =SUM(AD15:AG15) -> 2067 | BK15: =SUM(AH15:AK15) -> 2781 | BL15: =SUM(AL15:AO15) -> 2629 | BM15: =SUM(AP15:AS15) -> 2768 | BN15: =SUM(AT15:AW15) -> 2901.9609
A16: Profit of consolidated companies | B16: =B14-B15 -> 1246 | C16: =C14-C15 -> 801 | D16: =D14-D15 -> 565 | E16: =E14-E15 -> 999 | F16: =F14-F15 -> 273 | G16: =G14-G15 -> 555 | H16: =H14-H15 -> 287 | I16: =I14-I15 -> -310 | ... AW16: =AW14-AW15 -> 3027.7823 | BC16: =SUM(B16:E16) -> 3611 | BD16: =SUM(F16:I16) -> 805 | BE16: =SUM(J16:M16) -> 436 | BF16: =SUM(N16:Q16) -> 6124 | BG16: =SUM(R16:U16) -> 6066 | BH16: =SUM(V16:Y16) -> 2989 | BI16: =SUM(Z16:AC16) -> 6462 | BJ16: =SUM(AD16:AG16) -> 7610 | BK16: =SUM(AH16:AK16) -> 10269 | BL16: =SUM(AL16:AO16) -> 10744 | BM16: =SUM(AP16:AS16) -> 8773 | BN16: =SUM(AT16:AW16) -> 10937.424
A17: Equity in earnings | B17: 2 | C17: 2 | D17: -3 | E17: -1 | F17: -1 | G17: -2 | H17: -4 | I17: 1 | J17: -5 | K17: 5 | L17: 8 | M17: 8 | N17: 5 | O17: 9 | P17: 7 | Q17: 3 | R17: 7 | S17: 6 | T17: 7 | U17: 8 | V17: 5 | W17: 8 | X17: -5 | Y17: 6 | Z17: 9 | AA17: 14 | AB17: 21 | AC17: -13 | AD17: 7 | AE17: 4 | AF17: 9 | AG17: -1 | AH17: 16 | AI17: 24 | AJ17: 12 | AK17: 11 | AL17: 10 | AM17: 17 | AN17: 7 | AO17: 10 | AP17: 7 | AQ17: 7 | AR17: 8 | AS17: 87 | AT17: 7 | AU17: =AU$4*AU55 -> 7.6370945 | AV17: =AV$4*AV55 -> 8.079242 | AW17: =AW$4*AW55 -> 8.6419753 | BC17: =SUM(B17:E17) -> 0 | BD17: =SUM(F17:I17) -> -6 | BE17: =SUM(J17:M17) -> 16 | BF17: =SUM(N17:Q17) -> 24 | BG17: =SUM(R17:U17) -> 28 | BH17: =SUM(V17:Y17) -> 14 | BI17: =SUM(Z17:AC17) -> 31 | BJ17: =SUM(AD17:AG17) -> 19 | BK17: =SUM(AH17:AK17) -> 63 | BL17: =SUM(AL17:AO17) -> 44 | BM17: =SUM(AP17:AS17) -> 109 | BN17: =SUM(AT17:AW17) -> 31.358312
A18: Affiliates profit | B18: =B16+B17 -> 1248 | C18: =C16+C17 -> 803 | D18: =D16+D17 -> 562 | E18: =E16+E17 -> 998 | F18: =F16+F17 -> 272 | G18: =G16+G17 -> 553 | H18: =H16+H17 -> 283 | I18: =I16+I17 -> -309 | ... AW18: =AW16+AW17 -> 3036.4243 | BC18: =SUM(B18:E18) -> 3611 | BD18: =SUM(F18:I18) -> 799 | BE18: =SUM(J18:M18) -> 452 | BF18: =SUM(N18:Q18) -> 6148 | BG18: =SUM(R18:U18) -> 6094 | BH18: =SUM(V18:Y18) -> 3003 | BI18: =SUM(Z18:AC18) -> 6493 | BJ18: =SUM(AD18:AG18) -> 7629 | BK18: =SUM(AH18:AK18) -> 10332 | BL18: =SUM(AL18:AO18) -> 10788 | BM18: =SUM(AP18:AS18) -> 8882 | BN18: =SUM(AT18:AW18) -> 10968.783
A19: NCI | B19: 3 | C19: 1 | D19: 3 | E19: 4 | F19: 1 | G19: 3 | I19: 4 | J19: 2 | K19: 1 | L19: -3 | M19: 5 | N19: 2 | O19: -2 | P19: 0 | Q19: 1 | R19: 3 | S19: -1 | U19: -1 | V19: 1 | W19: 1 | X19: 3 | Y19: 0 | Z19: 1 | AA19: 1 | AB19: 2 | AC19: 0 | AF19: -1 | AG19: 0 | AH19: -1 | AI19: 2 | AJ19: -1 | AK19: -3 | AL19: -2 | AM19: 0 | AN19: -1 | AO19: -1 | AR19: -1 | AS19: -1 | AT19: -1 | AU19: =AU$4*AU57 -> -1.0910135 | AV19: =AV$4*AV57 -> -1.1541774 | AW19: =AW$4*AW57 -> -1.2345679 | BC19: =SUM(B19:E19) -> 11 | BD19: =SUM(F19:I19) -> 8 | BE19: =SUM(J19:M19) -> 5 | BF19: =SUM(N19:Q19) -> 1 | BG19: =SUM(R19:U19) -> 1 | BH19: =SUM(V19:Y19) -> 5 | BI19: =SUM(Z19:AC19) -> 4 | BJ19: =SUM(AD19:AG19) -> -1 | BK19: =SUM(AH19:AK19) -> -3 | BL19: =SUM(AL19:AO19) -> -4 | BM19: =SUM(AP19:AS19) -> -2 | BN19: =SUM(AT19:AW19) -> -4.4797588
A20: Profit | B20: =B18-B19 -> 1245 | C20: =C18-C19 -> 802 | D20: =D18-D19 -> 559 | E20: =E18-E19 -> 994 | F20: =F18-F19 -> 271 | G20: =G18-G19 -> 550 | H20: =H18-H19 -> 283 | I20: =I18-I19 -> -313 | ... AW20: =AW18-AW19 -> 3037.6588 | BC20: =SUM(B20:E20) -> 3600 | BD20: =SUM(F20:I20) -> 791 | BE20: =SUM(J20:M20) -> 447 | BF20: =SUM(N20:Q20) -> 6147 | BG20: =SUM(R20:U20) -> 6093 | BH20: =SUM(V20:Y20) -> 2998 | BI20: =SUM(Z20:AC20) -> 6489 | BJ20: =SUM(AD20:AG20) -> 7630 | BK20: =SUM(AH20:AK20) -> 10335 | BL20: =SUM(AL20:AO20) -> 10792 | BM20: =SUM(AP20:AS20) -> 8884 | BN20: =SUM(AT20:AW20) -> 10973.262
A21: Profit per common share | B21: =B$20/B23 -> 2.0581914 | C21: =C$20/C23 -> 1.3295756 | D21: =D$20/D23 -> 0.95003399 | E21: =E$20/E23 -> 1.7070239 | F21: =F$20/F23 -> 0.46499657 | G21: =G$20/G23 -> 0.94161959 | H21: =H$20/H23 -> 0.48400889 | I21: =I$20/I23 -> -0.53431205 | ... AW21: =AW$20/AW23 -> 6.555155 | BC21: =SUM(B21:E21) -> 6.0448249 | BD21: =SUM(F21:I21) -> 1.356313 | BE21: =SUM(J21:M21) -> 0.77805212 | BF21: =SUM(N21:Q21) -> 10.368643 | BG21: =SUM(R21:U21) -> 10.820157 | BH21: =SUM(V21:Y21) -> 5.50717 | BI21: =SUM(Z21:AC21) -> 11.939668 | BJ21: =SUM(AD21:AG21) -> 14.511112 | BK21: =SUM(AH21:AK21) -> 20.246072 | BL21: =SUM(AL21:AO21) -> 22.170753 | BM21: =SUM(AP21:AS21) -> 18.906874 | BN21: =SUM(AT21:AW21) -> 23.679893
A22: Profit per common share - diluted | B22: =B$20/B24 -> 2.0319896 | C22: =C$20/C24 -> 1.3132471 | D22: =D$20/D24 -> 0.9398117 | E22: =E$20/E24 -> 1.7070239 | F22: =F$20/F24 -> 0.46111962 | G22: =G$20/G24 -> 0.93442066 | H22: =H$20/H24 -> 0.47998643 | I22: =I$20/I24 -> -0.53431205 | ... AW22: =AW$20/AW24 -> 6.52138 | BC22: =SUM(B22:E22) -> 5.9920722 | BD22: =SUM(F22:I22) -> 1.3412147 | BE22: =SUM(J22:M22) -> 0.74026915 | BF22: =SUM(N22:Q22) -> 10.229413 | BG22: =SUM(R22:U22) -> 10.713177 | BH22: =SUM(V22:Y22) -> 5.4646501 | BI22: =SUM(Z22:AC22) -> 11.848135 | BJ22: =SUM(AD22:AG22) -> 14.44498 | BK22: =SUM(AH22:AK22) -> 20.142408 | BL22: =SUM(AL22:AO22) -> 22.049685 | BM22: =SUM(AP22:AS22) -> 18.818475 | BN22: =SUM(AT22:AW22) -> 23.557884
A23: Basic | B23: 604.9 | C23: 603.2 | D23: 588.4 | E23: 582.3 | F23: 582.8 | G23: 584.1 | H23: 584.7 | I23: 585.8 | J23: 587.5 | K23: 590.1 | L23: 593.3 | M23: 596.4 | N23: 598 | O23: 596 | P23: 591.9 | Q23: 581.4 | R23: 572.4 | S23: 567.8 | T23: 556.3 | U23: 550.3 | V23: 546.8 | W23: 541.5 | X23: 542.3 | Y23: 544.5 | Z23: 546.4 | AA23: 547.9 | AB23: 543.2 | AC23: 538.7 | AD23: 534.5 | AE23: 531 | AF23: 525.1 | AG23: 517.4 | AH23: 516.2 | AI23: 512.4 | AJ23: 510.4 | AK23: 504.4 | AL23: 493.9 | AM23: 487.5 | AN23: 485.6 | AO23: 480 | AP23: 474.9 | AQ23: 469.9 | AR23: 469.1 | AS23: 466.5 | AT23: 463.4 | AU23: 463.4 | AV23: 463.4 | AW23: 463.4 | BC23: =E23 -> 582.3 | BD23: =I23 -> 585.8 | BE23: =M23 -> 596.4 | BF23: =M23 -> 596.4 | BG23: =U23 -> 550.3 | BH23: =Y23 -> 544.5 | BI23: =AC23 -> 538.7 | BJ23: =AG23 -> 517.4 | BK23: =AK23 -> 504.4 | BL23: =AO23 -> 480 | BM23: =AS23 -> 466.5 | BN23: =AW23 -> 463.4
A24: Diluted | B24: 612.7 | C24: 610.7 | D24: 594.8 | E24: 582.3 | F24: 587.7 | G24: 588.6 | H24: 589.6 | I24: 585.8 | J24: 593.2 | K24: 595.6 | L24: 600.7 | M24: 596.4 | N24: 608 | O24: 604.2 | P24: 599.2 | Q24: 587.6 | R24: 578.8 | S24: 573.1 | T24: 561.2 | U24: 556.1 | V24: 551.1 | W24: 544.5 | X24: 546.4 | Y24: 549.5 | Z24: 551.4 | AA24: 552.1 | AB24: 547 | AC24: 542.6 | AD24: 534.5 | AE24: 534.1 | AF24: 527.4 | AG24: 520.9 | AH24: 519.4 | AI24: 514.8 | AJ24: 512.9 | AK24: 507 | AL24: 496.9 | AM24: 489.7 | AN24: 488.5 | AO24: 482.6 | AP24: 477.1 | AQ24: 471.9 | AR24: 471.2 | AS24: 469 | AT24: 465.8 | AU24: 465.8 | AV24: 465.8 | AW24: 465.8 | BC24: =E24 -> 582.3 | BD24: =I24 -> 585.8 | BE24: =M24 -> 596.4 | BF24: =M24 -> 596.4 | BG24: =U24 -> 556.1 | BH24: =Y24 -> 549.5 | BI24: =AC24 -> 542.6 | BJ24: =AG24 -> 520.9 | BK24: =AK24 -> 507 | BL24: =AO24 -> 482.6 | BM24: =AS24 -> 469 | BN24: =AW24 -> 465.8
A26: EBIT | B26: =B11+B10+B6 -> 2169 | C26: =C11+C10+C6 -> 1815 | D26: =D11+D10+D6 -> 1448 | E26: =E11+E10+E6 -> 2069 | F26: =F11+F10+F6 -> 1043 | G26: =G11+G10+G6 -> 1332 | H26: =H11+H10+H6 -> 1188 | I26: =I11+I10+I6 -> 293 | ... AW26: =AW11+AW10+AW6 -> 4830.537 | BC26: =BC11+BC10+BC6 -> 7501 | BD26: =BD11+BD10+BD6 -> 3856 | BE26: =BE11+BE10+BE6 -> 7054 | BF26: =BF11+BF10+BF6 -> 10397 | BG26: =BG11+BG10+BG6 -> 10315 | BH26: =BH11+BH10+BH6 -> 6609 | BI26: =BI11+BI10+BI6 -> 8407 | BJ26: =BJ11+BJ10+BJ6 -> 10612 | ... BS26: =BS11+BS10+BS6 -> 0
A27: Adj Earnings | B27: =B26-B6-B12-B15+B17-B19 -> 1368 | C27: =C26-C6-C12-C15+C17-C19 -> 1208 | D27: =D26-D6-D12-D15+D17-D19 -> 955 | E27: =E26-E6-E12-E15+E17-E19 -> 1919 | F27: =F26-F6-F12-F15+F17-F19 -> 668 | G27: =G26-G6-G12-G15+G17-G19 -> 865 | H27: =H26-H6-H12-H15+H17-H19 -> 815 | I27: =I26-I6-I12-I15+I17-I19 -> 201 | ... AW27: =AW26-AW6-AW12-AW15+AW17-AW19 -> 3440.128 | BC27: =BC26-BC6-BC12-BC15+BC17-BC19 -> 5450 | BD27: =BD26-BD6-BD12-BD15+BD17-BD19 -> 2549 | BE27: =BE26-BE6-BE12-BE15+BE17-BE19 -> 2549 | BF27: =BF26-BF6-BF12-BF15+BF17-BF19 -> 7596 | BG27: =BG26-BG6-BG12-BG15+BG17-BG19 -> 7421 | BH27: =BH26-BH6-BH12-BH15+BH17-BH19 -> 4509 | BI27: =BI26-BI6-BI12-BI15+BI17-BI19 -> 5749 | BJ27: =BJ26-BJ6-BJ12-BJ15+BJ17-BJ19 -> 7557 | ... BS27: =BS26-BS6-BS12-BS15+BS17-BS19 -> 0
A28: Adj EPS | B28: =B27/B24 -> 2.2327403 | C28: =C27/C24 -> 1.978058 | D28: =D27/D24 -> 1.6055817 | E28: =E27/E24 -> 3.2955521 | F28: =F27/F24 -> 1.1366343 | G28: =G27/G24 -> 1.4695889 | H28: =H27/H24 -> 1.3822931 | I28: =I27/I24 -> 0.34312052 | ... AW28: =AW27/AW24 -> 7.3854186 | BC28: =BC27/BC24 -> 9.3594367 | BD28: =BD27/BD24 -> 4.3513144 | BE28: =BE27/BE24 -> 4.2739772 | BF28: =BF27/BF24 -> 12.736419 | BG28: =BG27/BG24 -> 13.344722 | BH28: =BH27/BH24 -> 8.2056415 | BI28: =BI27/BI24 -> 10.595282 | BJ28: =BJ27/BJ24 -> 14.507583 | ... BS28: =BS27/BS24 -> #DIV/0!
A29: ETR | B29: 0.21 | C29: 0.21 | D29: 0.21 | E29: 0.21 | F29: 0.21 | G29: 0.21 | H29: 0.21 | I29: 0.21 | J29: 0.21 | K29: 0.21 | L29: 0.21 | M29: 0.21 | N29: 0.21 | O29: 0.21 | P29: 0.21 | Q29: 0.21 | R29: 0.21 | S29: 0.21 | T29: 0.21 | U29: 0.21 | V29: 0.21 | W29: 0.21 | X29: 0.21 | Y29: 0.21 | Z29: 0.21 | AA29: 0.21 | AB29: 0.21 | AC29: 0.21 | AD29: 0.21 | AE29: 0.21 | AF29: 0.21 | AG29: 0.21 | AH29: 0.21 | AI29: 0.21 | AJ29: 0.21 | AK29: 0.21 | AL29: 0.21 | AM29: 0.21 | AN29: 0.21 | AO29: 0.21 | AP29: 0.21 | AQ29: 0.21 | AR29: 0.21 | AS29: 0.21 | AT29: 0.21 | AU29: 0.21 | AV29: 0.21 | AW29: 0.21 | BC29: 0.21 | BD29: 0.21 | BE29: 0.21 | BF29: 0.21 | BG29: 0.21 | BH29: 0.21 | BI29: 0.21 | BJ29: 0.21 | BK29: 0.21 | BL29: 0.21 | BM29: 0.21 | BN29: 0.21 | BO29: 1.21 | BP29: 2.21 | BQ29: 3.21 | BR29: 4.21 | BS29: 5.21
A30: NOPAT | B30: =B26*(1-B29) -> 1713.51 | C30: =C26*(1-C29) -> 1433.85 | D30: =D26*(1-D29) -> 1143.92 | E30: =E26*(1-E29) -> 1634.51 | F30: =F26*(1-F29) -> 823.97 | G30: =G26*(1-G29) -> 1052.28 | H30: =H26*(1-H29) -> 938.52 | I30: =I26*(1-I29) -> 231.47 | ... AW30: =AW26*(1-AW29) -> 3816.1243 | BC30: =BC26*(1-BC29) -> 5925.79 | BD30: =BD26*(1-BD29) -> 3046.24 | BE30: =BE26*(1-BE29) -> 5572.66 | BF30: =BF26*(1-BF29) -> 8213.63 | BG30: =BG26*(1-BG29) -> 8148.85 | BH30: =BH26*(1-BH29) -> 5221.11 | BI30: =BI26*(1-BI29) -> 6641.53 | BJ30: =BJ26*(1-BJ29) -> 8383.48 | ... BS30: =BS26*(1-BS29) -> 0
A32: Gross Margin | B32: =B7/B4 -> 0.29853566 | C32: =C7/C4 -> 0.28375416 | D32: =D7/D4 -> 0.26892903 | E32: =E7/E4 -> 0.31242604 | F32: =F7/F4 -> 0.26286862 | G32: =G7/G4 -> 0.26832334 | H32: =H7/H4 -> 0.27139738 | I32: =I7/I4 -> 0.22446208 | ... AW32: =AW7/AW4 -> 0.33978955 | BC32: =BC7/BC4 -> 0.29137646 | BD32: =BD7/BD4 -> 0.25681812 | BE32: =BE7/BE4 -> 0.2981831 | BF32: =BF7/BF4 -> 0.31071598 | BG32: =BG7/BG4 -> 0.30513011 | BH32: =BH7/BH4 -> 0.28928332 | BI32: =BI7/BI4 -> 0.29434384 | BJ32: =BJ7/BJ4 -> 0.29468087 | ... BS32: =BS7/BS4 -> 0
A33: EBIT Margin | B33: =B26/B4 -> 0.17076051 | C33: =C26/C4 -> 0.14735731 | D33: =D26/D4 -> 0.13209268 | E33: =E26/E4 -> 0.17489434 | F33: =F26/F4 -> 0.11024205 | G33: =G26/G4 -> 0.1287952 | H33: =H26/H4 -> 0.12969432 | I33: =I26/I4 -> 0.030603718 | ... AW33: =AW26/AW4 -> 0.22467614 | BC33: =BC26/BC4 -> 0.15688858 | BD33: =BD26/BD4 -> 0.10005968 | BE33: =BE26/BE4 -> 0.15516255 | BF33: =BF26/BF4 -> 0.18999671 | BG33: =BG26/BG4 -> 0.19172862 | BH33: =BH26/BH4 -> 0.15830698 | BI33: =BI26/BI4 -> 0.16493692 | BJ33: =BJ26/BJ4 -> 0.17857203 | ... BS33: =BS26/BS4 -> 0
A34: Adj Net Margin | B34: =B27/B4 -> 0.10769957 | C34: =C27/C4 -> 0.09807583 | D34: =D27/D4 -> 0.087119139 | E34: =E27/E4 -> 0.16221471 | F34: =F27/F4 -> 0.070605644 | G34: =G27/G4 -> 0.083639528 | H34: =H27/H4 -> 0.088973799 | I34: =I27/I4 -> 0.02099436 | ... AW34: =AW27/AW4 -> 0.16000595 | BC34: =BC27/BC4 -> 0.1139905 | BD34: =BD27/BD4 -> 0.066144225 | BE34: =BE27/BE4 -> 0.056068805 | BF34: =BF27/BF4 -> 0.13881072 | BG34: =BG27/BG4 -> 0.1379368 | BH34: =BH27/BH4 -> 0.10800517 | BI34: =BI27/BI4 -> 0.11278963 | BJ34: =BJ27/BJ4 -> 0.12716442 | ... BS34: =BS27/BS4 -> 0
A36: Sales Growth QoQ | C36: =C4/B4-1 -> -0.030310187 | D36: =D4/C4-1 -> -0.11001055 | E36: =E4/D4-1 -> 0.079182631 | F36: =F4/E4-1 -> -0.20025359 | G36: =G4/F4-1 -> 0.093119121 | H36: =H4/G4-1 -> -0.11429124 | I36: =I4/H4-1 -> 0.045196507 | J36: =J4/I4-1 -> 0.025903489 | ... AW36: =AW4/AV4-1 -> 0.069651741
A37: Sales Growth YoY | F37: =F4/B4-1 -> -0.25515667 | G37: =G4/C4-1 -> -0.16034749 | H37: =H4/D4-1 -> -0.16438606 | I37: =I4/E4-1 -> -0.19070161 | J37: =J4/F4-1 -> 0.038156643 | K37: =K4/G4-1 -> 0.095629472 | L37: =L4/H4-1 -> 0.2459607 | M37: =M4/I4-1 -> 0.34698141 | ... AW37: =AW4/AS4-1 -> 0.12371296 | BD37: =BD4/BC4-1 -> -0.1939721 | BE37: =BE4/BD4-1 -> 0.17969743 | BF37: =BF4/BE4-1 -> 0.2036866 | BG37: =BG4/BF4-1 -> -0.016848799 | BH37: =BH4/BG4-1 -> -0.22401487 | BI37: =BI4/BH4-1 -> 0.22092076 | BJ37: =BJ4/BI4-1 -> 0.16589826 | BK37: =BK4/BJ4-1 -> 0.1284433 | ... BS37: =BS4/BR4-1 -> 0.03520352
A39: Common size
A40: Sales of Machinery, Power & Energy | B40: =B2/B$4 -> 0.94166273 | C40: =C2/C$4 -> 0.94040757 | D40: =D2/D$4 -> 0.9382412 | E40: =E2/E$4 -> 0.93981403 | F40: =F2/F$4 -> 0.92802029 | G40: =G2/G$4 -> 0.93260491 | H40: =H2/H$4 -> 0.9239083 | I40: =I2/I$4 -> 0.92803426 | ... AW40: =AW2/AW$4 -> 1 | BC40: =BC2/BC$4 -> 0.94009747 | BD40: =BD2/BD$4 -> 0.92827672 | BE40: =BE2/BE$4 -> 0.93871805 | BF40: =BF2/BF$4 -> 0.94700486 | BG40: =BG2/BG$4 -> 0.94340149 | BH40: =BH2/BH$4 -> 0.93470346 | BI40: =BI2/BI$4 -> 0.94540033 | BJ40: =BJ2/BJ$4 -> 0.95199152 | ... BS40: =BS2/BS$4 -> 1
A41: Revenues of Financial Products | B41: =B3/B$4 -> 0.05833727 | C41: =C3/C$4 -> 0.059592433 | D41: =D3/D$4 -> 0.061758803 | E41: =E3/E$4 -> 0.060185968 | F41: =F3/F$4 -> 0.071979706 | G41: =G3/G$4 -> 0.067395088 | H41: =H3/H$4 -> 0.076091703 | I41: =I3/I$4 -> 0.071965741 | ... AW41: =AW3/AW$4 -> 0 | BC41: =BC3/BC$4 -> 0.059902533 | BD41: =BD3/BD$4 -> 0.071723279 | BE41: =BE3/BE$4 -> 0.06128195 | BF41: =BF3/BF$4 -> 0.052995139 | BG41: =BG3/BG$4 -> 0.056598513 | BH41: =BH3/BH$4 -> 0.065296541 | BI41: =BI3/BI$4 -> 0.054599674 | BJ41: =BJ3/BJ$4 -> 0.048008481 | ... BN41: =BN3/BN$4 -> 0.012074601 | BO41: 0 | BP41: 0 | BQ41: 0 | BR41: 0 | BS41: 0
A42: Total sales and revenues | B42: =B4/B$4 -> 1 | C42: =C4/C$4 -> 1 | D42: =D4/D$4 -> 1 | E42: =E4/E$4 -> 1 | F42: =F4/F$4 -> 1 | G42: =G4/G$4 -> 1 | H42: =H4/H$4 -> 1 | I42: =I4/I$4 -> 1 | ... AW42: =AW4/AW$4 -> 1 | BC42: =BC4/BC$4 -> 1 | BD42: =BD4/BD$4 -> 1 | BE42: =BE4/BE$4 -> 1 | BF42: =BF4/BF$4 -> 1 | BG42: =BG4/BG$4 -> 1 | BH42: =BH4/BH$4 -> 1 | BI42: =BI4/BI$4 -> 1 | BJ42: =BJ4/BJ$4 -> 1 | ... BS42: =BS4/BS$4 -> 1
A43: Cost of goods sold | B43: =B5/B$4 -> 0.68965517 | C43: =C5/C$4 -> 0.70422993 | D43: =D5/D$4 -> 0.71811713 | E43: =E5/E$4 -> 0.67514793 | F43: =F5/F$4 -> 0.72106543 | G43: =G5/G$4 -> 0.71736608 | H43: =H5/H$4 -> 0.71255459 | I43: =I5/I$4 -> 0.75997493 | ... AT43: =AT5/AT$4 -> 0.64921045 | AU43: =+AT43-0.3% -> 0.64621045 | AV43: =+AU43-0.3% -> 0.64321045 | AW43: =+AV43-0.3% -> 0.64021045 | BC43: =BC5/BC$4 -> 0.69634603 | BD43: =BD5/BD$4 -> 0.72771622 | BE43: =BE5/BE$4 -> 0.68760723 | BF43: =BF5/BF$4 -> 0.67609006 | BG43: =BG5/BG$4 -> 0.68085502 | BH43: =BH5/BH$4 -> 0.69660822 | BI43: =BI5/BI$4 -> 0.69672951 | BJ43: =BJ5/BJ$4 -> 0.69581167 | ... BS43: =BS5/BS$4 -> 0
A44: Financial products interest | B44: =B6/B$4 -> 0.011809164 | C44: =C6/C$4 -> 0.012015913 | D44: =D6/D$4 -> 0.012953841 | E44: =E6/E$4 -> 0.012426036 | F44: =F6/F$4 -> 0.016065955 | G44: =G6/G$4 -> 0.014310578 | H44: =H6/H$4 -> 0.016048035 | I44: =I6/I$4 -> 0.015562983 | ... AT44: =AT6/AT$4 -> 0.019810508 | AU44: 0.02 | AV44: 0.02 | AW44: 0.02 | BC44: =BC6/BC$4 -> 0.012277509 | BD44: =BD6/BD$4 -> 0.015465656 | BE44: =BE6/BE$4 -> 0.01420967 | BF44: =BF6/BF$4 -> 0.013193962 | BG44: =BG6/BG$4 -> 0.01401487 | BH44: =BH6/BH$4 -> 0.01410846 | BI44: =BI6/BI$4 -> 0.0089266446 | BJ44: =BJ6/BJ$4 -> 0.0095074629 | ... BS44: =BS6/BS$4 -> 0
...

Sheet Balance-Sheet-Quarterly
A1: Date | B1: 2015-03-31 | C1: 2015-06-30 | D1: 2015-09-30 | E1: 2015-12-31 | F1: 2016-03-31 | G1: 2016-06-30 | H1: 2016-09-30 | I1: 2016-12-31 | J1: 2017-03-31 | K1: 2017-06-30 | L1: 2017-09-30 | M1: 2017-12-31 | N1: 2018-03-31 | O1: 2018-06-30 | P1: 2018-09-30 | Q1: 2018-12-31 | R1: 2019-03-31 | S1: 2019-06-30 | T1: 2019-09-30 | U1: 2019-12-31 | V1: 2020-03-31 | W1: 2020-06-30 | X1: 2020-09-30 | Y1: 2020-12-31 | Z1: 2021-03-31 | AA1: 2021-06-30 | AB1: 2021-09-30 | AC1: 2021-12-31 | AD1: 2022-03-31 | AE1: 2022-06-30 | AF1: 2022-09-30 | AG1: 2022-12-31 | AH1: 2023-03-31 | AI1: 2023-06-30 | AJ1: 2023-09-30 | AK1: 2023-12-31 | AL1: 2024-03-31 | AM1: 2024-06-30 | AN1: 2024-09-30 | AO1: 2024-12-31 | AP1: 2025-03-31 | AQ1: 2025-06-30 | AR1: 2025-09-30 | AS1: 2025-12-31 | AT1: 2026-03-31
A2: Cash and cash equivalents | B2: 7563 | C2: 7821 | D2: 6046 | E2: 6460 | F2: 5886 | G2: 6764 | H2: 6113 | I2: 7168 | J2: 9472 | K2: 10232 | L2: 9591 | M2: 8261 | N2: 7888 | O2: 8654 | P2: 8007 | Q2: 7857 | R2: 7128 | S2: 7429 | T2: 7906 | U2: 8284 | V2: 7123 | W2: 8784 | X2: 9315 | Y2: 9352 | Z2: 11342 | AA2: 10831 | AB2: 9446 | AC2: 9254 | AD2: 6526 | AE2: 6014 | AF2: 6346 | AG2: 7004 | AH2: 6789 | AI2: 7387 | AJ2: 6545 | AK2: 6978 | AL2: 4959 | AM2: 4341 | AN2: 5638 | AO2: 6889 | AP2: 3562 | AQ2: 5442 | AR2: 7538 | AS2: 9980 | AT2: 4072
A3: Receivables - trade and other | B3: 7586 | C3: 7212 | D3: 6783 | E3: 6695 | F3: 6856 | G3: 6326 | H3: 5797 | I3: 5981 | J3: 6533 | K3: 6675 | L3: 6691 | M3: 7436 | N3: 7894 | O3: 7991 | P3: 7974 | Q3: 8802 | R3: 8961 | S3: 8996 | T3: 8275 | U3: 8568 | V3: 7834 | W3: 7134 | X3: 6969 | Y3: 7317 | Z3: 7955 | AA3: 7840 | AB3: 7647 | AC3: 8477 | AD3: 9135 | AE3: 8393 | AF3: 8158 | AG3: 8856 | AH3: 9230 | AI3: 9416 | AJ3: 9134 | AK3: 9310 | AL3: 9296 | AM3: 9421 | AN3: 9086 | AO3: 9282 | AP3: 9116 | AQ3: 9704 | AR3: 10146 | AS3: 10920 | AT3: 11447
A4: Receivables - finance | B4: 9037 | C4: 9213 | D4: 8862 | E4: 8991 | F4: 9310 | G4: 9201 | H4: 8719 | I4: 8522 | J4: 8684 | K4: 8920 | L4: 8984 | M4: 8757 | N4: 8772 | O4: 8906 | P4: 8824 | Q4: 8650 | R4: 8932 | S4: 9539 | T4: 9192 | U4: 9336 | V4: 9120 | W4: 8781 | X4: 8966 | Y4: 9463 | Z4: 9333 | AA4: 9523 | AB4: 8919 | AC4: 8898 | AD4: 9003 | AE4: 8922 | AF4: 8918 | AG4: 9013 | AH4: 9119 | AI4: 9288 | AJ4: 9608 | AK4: 9510 | AL4: 9446 | AM4: 9516 | AN4: 9816 | AO4: 9565 | AP4: 9655 | AQ4: 10147 | AR4: 10315 | AS4: 10649 | AT4: 10443
A5: Deferred and Refundable Income Taxes | B5: 1438 | C5: 1441 | D5: 1446
A6: Prepaid expenses and other current assets | B6: 768 | C6: 859 | D6: 993 | E6: 1662 | F6: 1847 | G6: 1857 | H6: 1892 | I6: 1682 | J6: 1777 | K6: 1776 | L6: 1707 | M6: 1772 | N6: 1856 | O6: 1835 | P6: 1835 | Q6: 1765 | R6: 1765 | S6: 1818 | T6: 1607 | U6: 1739 | V6: 1761 | W6: 1792 | X6: 1831 | Y6: 1930 | Z6: 1802 | AA6: 2080 | AB6: 2215 | AC6: 2788 | AD6: 2868 | AE6: 2772 | AF6: 2295 | AG6: 2642 | AH6: 2889 | AI6: 3163 | AJ6: 5138 | AK6: 4586 | AL6: 3010 | AM6: 2736 | AN6: 3094 | AO6: 3119 | AP6: 2824 | AQ6: 2867 | AR6: 2861 | AS6: 2801 | AT6: 2980
A7: Inventories | B7: 12099 | C7: 11681 | D7: 11150 | E7: 9700 | F7: 9849 | G7: 9458 | H7: 9478 | I7: 8614 | J7: 9082 | K7: 9388 | L7: 10212 | M7: 10018 | N7: 10947 | O7: 11255 | P7: 11814 | Q7: 11529 | R7: 12340 | S7: 12007 | T7: 12180 | U7: 11266 | V7: 11748 | W7: 11371 | X7: 11453 | Y7: 11402 | Z7: 12149 | AA7: 12672 | AB7: 13666 | AC7: 14038 | AD7: 15038 | AE7: 15881 | AF7: 16860 | AG7: 16270 | AH7: 17633 | AI7: 17746 | AJ7: 17580 | AK7: 16565 | AL7: 16953 | AM7: 17082 | AN7: 17312 | AO7: 16827 | AP7: 17862 | AQ7: 18595 | AR7: 18958 | AS7: 18135 | AT7: 19626
A8: Total current assets | B8: 38491 | C8: 38227 | D8: 35280 | E8: 33508 | F8: 33748 | G8: 33606 | H8: 31999 | I8: 31967 | J8: 35548 | K8: 36991 | L8: 37185 | M8: 36244 | N8: 37357 | O8: 38641 | P8: 38454 | Q8: 38603 | R8: 39126 | S8: 39789 | T8: 39160 | U8: 39193 | V8: 37586 | W8: 37862 | X8: 38534 | Y8: 39464 | Z8: 42581 | AA8: 42946 | AB8: 41893 | AC8: 43455 | AD8: 42570 | AE8: 41982 | AF8: 42577 | AG8: 43785 | AH8: 45660 | AI8: 47000 | AJ8: 48005 | AK8: 46949 | AL8: 43664 | AM8: 43096 | AN8: 44946 | AO8: 45682 | AP8: 43019 | AQ8: 46755 | AR8: 49818 | AS8: 52485 | AT8: 48568
A9: Property, plant and equipment - net | B9: 16277 | C9: 16136 | D9: 15955 | E9: 16090 | F9: 15935 | G9: 15916 | H9: 15680 | I9: 15322 | J9: 14727 | K9: 14420 | L9: 14187 | M9: 14155 | N9: 13912 | O9: 13752 | P9: 13607 | Q9: 13574 | R9: 13259 | S9: 13172 | T9: 12842 | U9: 12904 | V9: 12488 | W9: 12357 | X9: 12232 | Y9: 12401 | Z9: 12132 | AA9: 12014 | AB9: 11904 | AC9: 12090 | AD9: 11932 | AE9: 11744 | AF9: 11643 | AG9: 12028 | AH9: 11973 | AI9: 12124 | AJ9: 12287 | AK9: 12680 | AL9: 12538 | AM9: 12582 | AN9: 12837 | AO9: 13361 | AP9: 13432 | AQ9: 13896 | AR9: 14310 | AS9: 15140 | AT9: 15249
A10: Long-term receivables - trade and other | B10: 1252 | C10: 1290 | D10: 1266 | E10: 1170 | F10: 1159 | G10: 1180 | H10: 1102 | I10: 1029 | J10: 944 | K10: 940 | L10: 969 | M10: 990 | N10: 1004 | O10: 1084 | P10: 1129 | Q10: 1161 | R10: 1149 | S10: 1154 | T10: 1193 | U10: 1193 | V10: 1196 | W10: 1167 | X10: 1149 | Y10: 1185 | Z10: 1115 | AA10: 1206 | AB10: 1273 | AC10: 1204 | AD10: 1204 | AE10: 1197 | AF10: 1278 | AG10: 1265 | AH10: 1209 | AI10: 1161 | AJ10: 1110 | AK10: 1238 | AL10: 1200 | AM10: 1181 | AN10: 1346 | AO10: 1225 | AP10: 1261 | AQ10: 1607 | AR10: 1618 | AS10: 2142 | AT10: 2490
A11: Long-term receivables - finance | B11: 13713 | C11: 13698 | D11: 13551 | E11: 13651 | F11: 13527 | G11: 13689 | H11: 13835 | I11: 13556 | J11: 13426 | K11: 13197 | L11: 13192 | M11: 13542 | N11: 13359 | O11: 13318 | P11: 13244 | Q11: 13286 | R11: 12674 | S11: 12461 | T11: 12412 | U11: 12651 | V11: 12021 | W11: 12560 | X11: 12209 | Y11: 12222 | Z11: 11966 | AA11: 12590 | AB11: 12605 | AC11: 12707 | AD11: 12665 | AE11: 12372 | AF11: 11859 | AG11: 12013 | AH11: 11845 | AI11: 12022 | AJ11: 11907 | AK11: 12664 | AL11: 12531 | AM11: 12797 | AN11: 13263 | AO11: 13242 | AP11: 13452 | AQ11: 13835 | AR11: 13985 | AS11: 14272 | AT11: 14341
A12: Investments in Unconsolidated Affiliated Companies | B12: 230 | C12: 229 | D12: 231
A13: Noncurrent deferred and refundable income taxes | B13: 1342 | C13: 1473 | D13: 1559 | E13: 2489 | F13: 2486 | G13: 2536 | H13: 2579 | I13: 2790 | J13: 2940 | K13: 2866 | L13: 2845 | M13: 1693 | N13: 1687 | O13: 1626 | P13: 1288 | Q13: 1439 | R13: 1378 | S13: 1473 | T13: 1372 | U13: 1411 | V13: 1426 | W13: 1459 | X13: 1440 | Y13: 1523 | Z13: 1391 | AA13: 1455 | AB13: 1744 | AC13: 1840 | AD13: 1973 | AE13: 2121 | AF13: 2218 | AG13: 2213 | AH13: 2405 | AI13: 2607 | AJ13: 2719 | AK13: 2816 | AL13: 2860 | AM13: 2920 | AN13: 3050 | AO13: 3312 | AP13: 3334 | AQ13: 3427 | AR13: 3000 | AS13: 2882 | AT13: 2419
A14: Intangible assets | B14: 2890 | C14: 2863 | D14: 2841 | E14: 2821 | F14: 2741 | G14: 2652 | H14: 2453 | I14: 2349 | J14: 2287 | K14: 2232 | L14: 2175 | M14: 2111 | N14: 2163 | O14: 2039 | P14: 1976 | Q14: 1897 | R14: 1807 | S14: 1733 | T14: 1630 | U14: 1565 | V14: 1478 | W14: 1420 | X14: 1363 | Y14: 1308 | Z14: 1246 | AA14: 1176 | AB14: 1121 | AC14: 1042 | AD14: 967 | AE14: 889 | AF14: 806 | AG14: 758 | AH14: 694 | AI14: 630 | AJ14: 604 | AK14: 564 | AL14: 516 | AM14: 488 | AN14: 448 | AO14: 399 | AP14: 361 | AQ14: 321 | AR14: 281 | AS14: 241 | AT14: 419
A15: Goodwill | B15: 6493 | C15: 6550 | D15: 6546 | E15: 6615 | F15: 6710 | G15: 6677 | H15: 6725 | I15: 6020 | J15: 6051 | K15: 6142 | L15: 6196 | M15: 6200 | N15: 6376 | O15: 6249 | P15: 6233 | Q15: 6217 | R15: 6191 | S15: 6211 | T15: 6142 | U15: 6196 | V15: 6140 | W15: 6192 | X15: 6304 | Y15: 6394 | Z15: 6343 | AA15: 6372 | AB15: 6353 | AC15: 6324 | AD15: 6293 | AE15: 6195 | AF15: 6092 | AG15: 5288 | AH15: 5309 | AI15: 5293 | AJ15: 5268 | AK15: 5308 | AL15: 5277 | AM15: 5264 | AN15: 5317 | AO15: 5241 | AP15: 5270 | AQ15: 5331 | AR15: 5329 | AS15: 5321 | AT15: 5865
A16: Other assets | B16: 1802 | C16: 1776 | D16: 1740 | E16: 1998 | F16: 2001 | G16: 2044 | H16: 2029 | I16: 1671 | J16: 1626 | K16: 1722 | L16: 1811 | M16: 2027 | N16: 2156 | O16: 2278 | P16: 2278 | Q16: 2332 | R16: 3142 | S16: 3194 | T16: 3242 | U16: 3340 | V16: 3559 | W16: 3549 | X16: 3510 | Y16: 3827 | Z16: 3955 | AA16: 3938 | AB16: 3891 | AC16: 4131 | AD16: 4672 | AE16: 4607 | AF16: 4434 | AG16: 4593 | AH16: 4554 | AI16: 4590 | AJ16: 4891 | AK16: 5257 | AL16: 5155 | AM16: 5008 | AN16: 5066 | AO16: 5302 | AP16: 4845 | AQ16: 5153 | AR16: 5381 | AS16: 6102 | AT16: 6199
A17: Total assets | B17: 82490 | C17: 82242 | D17: 78969 | E17: 78342 | F17: 78307 | G17: 78300 | H17: 76402 | I17: 74704 | J17: 77549 | K17: 78510 | L17: 78560 | M17: 76962 | N17: 78014 | O17: 78987 | P17: 78209 | Q17: 78509 | R17: 78726 | S17: 79187 | T17: 77993 | U17: 78453 | V17: 75894 | W17: 76566 | X17: 76741 | Y17: 78324 | Z17: 80729 | AA17: 81697 | AB17: 80784 | AC17: 82793 | AD17: 82276 | AE17: 81107 | AF17: 80907 | AG17: 81943 | AH17: 83649 | AI17: 85427 | AJ17: 86791 | AK17: 87476 | AL17: 83741 | AM17: 83336 | AN17: 86273 | AO17: 87764 | AP17: 84974 | AQ17: 90325 | AR17: 93722 | AS17: 98585 | AT17: 95550
A18: Machinery, Energy & Transportation | B18: 8 | C18: 14 | D18: 12 | E18: 9 | F18: 13 | G18: 263 | H18: 263 | I18: 209 | J18: 436 | K18: 5 | L18: 11 | M18: 1 | N18: 7 | O18: 35 | P18: 59 | R18: 4 | U18: 5 | W18: 13 | Y18: 10 | Z18: 0 | AA18: 4 | AC18: 9 | AD18: 0 | AF18: 3 | AG18: 3
A19: Financial Products | B19: 5259 | C19: 6226 | D19: 6068 | E19: 6958 | F19: 7804 | G19: 7220 | H19: 6702 | I19: 7094 | J19: 7385 | K19: 6775 | L19: 5459 | M19: 4836 | N19: 5726 | O19: 6185 | P19: 4462 | Q19: 5723 | R19: 5586 | S19: 5266 | T19: 4268 | U19: 5161 | V19: 4789 | W19: 4301 | X19: 2660 | Y19: 2005 | Z19: 3625 | AA19: 3421 | AB19: 3247 | AC19: 5395 | AD19: 4501 | AE19: 5002 | AF19: 4199 | AG19: 5954 | AH19: 5841 | AI19: 5548 | AJ19: 4218 | AK19: 4643 | AL19: 3568 | AM19: 5298 | AN19: 3725 | AO19: 4393 | AP19: 3454 | AQ19: 4485 | AR19: 4509 | AS19: 5514 | AT19: 4729
A20: Accounts payable | B20: 6328 | C20: 5862 | D20: 5206 | E20: 5023 | F20: 5101 | G20: 5104 | H20: 4713 | I20: 4614 | J20: 5302 | K20: 5778 | L20: 6113 | M20: 6487 | N20: 6938 | O20: 6831 | P20: 6788 | Q20: 7051 | R20: 7198 | S20: 7022 | T20: 6141 | U20: 5957 | V20: 5769 | W20: 5083 | X20: 5193 | Y20: 6128 | Z20: 6694 | AA20: 6921 | AB20: 7218 | AC20: 8154 | AD20: 8361 | AE20: 8092 | AF20: 8260 | AG20: 8689 | AH20: 8951 | AI20: 8443 | AJ20: 7827 | AK20: 7906 | AL20: 7778 | AM20: 7575 | AN20: 7705 | AO20: 7675 | AP20: 7792 | AQ20: 8563 | AR20: 8729 | AS20: 8968 | AT20: 9641
A21: Accrued expenses | B21: 3531 | C21: 3311 | D21: 3306 | E21: 3116 | F21: 3142 | G21: 3127 | H21: 3022 | I21: 3003 | J21: 3086 | K21: 3211 | L21: 3114 | M21: 3220 | N21: 3551 | O21: 3450 | P21: 3423 | Q21: 3573 | R21: 3746 | S21: 3789 | T21: 3727 | U21: 3750 | V21: 3776 | W21: 3547 | X21: 3510 | Y21: 3642 | Z21: 3574 | AA21: 3556 | AB21: 3579 | AC21: 3757 | AD21: 3846 | AE21: 3782 | AF21: 4013 | AG21: 4080 | AH21: 4121 | AI21: 4493 | AJ21: 4669 | AK21: 4958 | AL21: 4821 | AM21: 4947 | AN21: 4980 | AO21: 5243 | AP21: 4990 | AQ21: 5207 | AR21: 5187 | AS21: 5587 | AT21: 5454
A22: Accrued wages, salaries and employee benefits | B22: 1358 | C22: 1597 | D22: 1678 | E22: 1994 | F22: 1158 | G22: 1265 | H22: 1286 | I22: 1296 | J22: 1666 | K22: 1986 | L22: 2333 | M22: 2559 | N22: 1474 | O22: 1789 | P22: 2132 | Q22: 2384 | R22: 1200 | S22: 1411 | T22: 1518 | U22: 1629 | V22: 878 | W22: 958 | X22: 1069 | Y22: 1096 | Z22: 1283 | AA22: 1759 | AB22: 2075 | AC22: 2242 | AD22: 1275 | AE22: 1772 | AF22: 2204 | AG22: 2313 | AH22: 1368 | AI22: 1755 | AJ22: 2300 | AK22: 2757 | AL22: 1291 | AM22: 1677 | AN22: 2078 | AO22: 2391 | AP22: 1259 | AQ22: 1618 | AR22: 2126 | AS22: 2554 | AT22: 1434
A23: Customer advances | B23: 1636 | C23: 1754 | D23: 1610 | E23: 1146 | F23: 1328 | G23: 1259 | H23: 1161 | I23: 1167 | J23: 1383 | K23: 1533 | L23: 1510 | M23: 1426 | N23: 1399 | O23: 1378 | P23: 1491 | Q23: 1243 | R23: 1354 | S23: 1263 | T23: 1309 | U23: 1187 | V23: 1295 | W23: 1227 | X23: 1209 | Y23: 1108 | Z23: 1168 | AA23: 1157 | AB23: 1155 | AC23: 1087 | AD23: 1388 | AE23: 1608 | AF23: 1831 | AG23: 1860 | AH23: 2202 | AI23: 2137 | AJ23: 2333 | AK23: 1929 | AL23: 2194 | AM23: 2324 | AN23: 2404 | AO23: 2322 | AP23: 2951 | AQ23: 3412 | AR23: 3391 | AS23: 3314 | AT23: 4382
A24: Dividends payable | C24: 463 | E24: 448 | G24: 450 | I24: 452 | K24: 461 | M24: 466 | O24: 511 | Q24: 495 | S24: 579 | U24: 567 | W24: 558 | Y24: 562 | AA24: 608 | AC24: 595 | AE24: 633 | AG24: 620 | AI24: 663 | AK24: 649 | AM24: 684 | AO24: 674 | AQ24: 707 | AS24: 703
A25: Other current liabilities | B25: 1741 | C25: 1744 | D25: 1698 | E25: 1671 | F25: 1593 | G25: 1635 | H25: 1620 | I25: 1635 | J25: 1641 | K25: 1787 | L25: 1744 | M25: 1742 | N25: 1890 | O25: 1871 | P25: 1867 | Q25: 1919 | R25: 2348 | S25: 2157 | T25: 2188 | U25: 2155 | V25: 2074 | W25: 2143 | X25: 1978 | Y25: 2017 | Z25: 2035 | AA25: 2126 | AB25: 2319 | AC25: 2256 | AD25: 2355 | AE25: 2333 | AF25: 2878 | AG25: 2690 | AH25: 3035 | AI25: 3109 | AJ25: 3115 | AK25: 3123 | AL25: 3265 | AM25: 2882 | AN25: 2934 | AO25: 2909 | AP25: 2834 | AQ25: 2627 | AR25: 2760 | AS25: 2798 | AT25: 2567
A26: Machinery, Power & Energy | B26: 513 | C26: 12 | D26: 516 | E26: 517 | F26: 568 | G26: 1055 | H26: 553 | I26: 507 | J26: 505 | K26: 5 | L26: 5 | M26: 6 | N26: 8 | O26: 9 | P26: 10 | Q26: 10 | R26: 13 | S26: 13 | T26: 25 | U26: 16 | V26: 143 | W26: 1395 | X26: 1397 | Y26: 1420 | Z26: 1301 | AA26: 50 | AB26: 48 | AC26: 45 | AD26: 127 | AE26: 124 | AF26: 120 | AG26: 120 | AH26: 37 | AI26: 1043 | AJ26: 1043 | AK26: 1044 | AL26: 1045 | AM26: 45 | AN26: 46 | AO26: 46 | AP26: 29 | AQ26: 30 | AR26: 32 | AS26: 35 | AT26: 35
A27: Financial Products | B27: 6192 | C27: 4623 | D27: 5739 | E27: 5360 | F27: 5508 | G27: 5805 | H27: 5970 | I27: 6155 | J27: 6231 | K27: 6592 | L27: 5614 | M27: 6188 | N27: 6409 | O27: 6241 | P27: 5801 | Q27: 5820 | R27: 5939 | S27: 6235 | T27: 8025 | U27: 6194 | V27: 7792 | W27: 6006 | X27: 7962 | Y27: 7729 | Z27: 6898 | AA27: 7906 | AB27: 6335 | AC27: 6307 | AD27: 7679 | AE27: 5617 | AF27: 6694 | AG27: 5202 | AH27: 6287 | AI27: 8123 | AJ27: 7619 | AK27: 7719 | AL27: 8409 | AM27: 8132 | AN27: 8346 | AO27: 6619 | AP27: 9286 | AQ27: 8285 | AR27: 9257 | AS27: 7085 | AT27: 7660
A28: Total current liabilities | B28: 26566 | C28: 25606 | D28: 25833 | E28: 26242 | F28: 26215 | G28: 27183 | H28: 25290 | I28: 26132 | J28: 27635 | K28: 28133 | L28: 25903 | M28: 26931 | N28: 27402 | O28: 28300 | P28: 26033 | Q28: 28218 | R28: 27388 | S28: 27735 | T28: 27201 | U28: 26621 | V28: 26516 | W28: 25231 | X28: 24978 | Y28: 25717 | Z28: 26578 | AA28: 27508 | AB28: 25976 | AC28: 29847 | AD28: 29532 | AE28: 28963 | AF28: 30202 | AG28: 31531 | AH28: 31842 | AI28: 35314 | AJ28: 33124 | AK28: 34728 | AL28: 32371 | AM28: 33564 | AN28: 32218 | AO28: 32272 | AP28: 32595 | AQ28: 34934 | AR28: 35991 | AS28: 36558 | AT28: 35902
A29: Machinery, Power & Energy | B29: 9495 | C29: 9497 | D29: 8997 | E29: 8960 | F29: 8914 | G29: 8434 | H29: 8432 | I29: 8436 | J29: 8804 | K29: 8815 | L29: 8820 | M29: 7929 | N29: 7980 | O29: 7982 | P29: 7991 | Q29: 8005 | R29: 7650 | S29: 7657 | T29: 9134 | U29: 9141 | V29: 8998 | W29: 9729 | X29: 9742 | Y29: 9749 | Z29: 9751 | AA29: 9752 | AB29: 9759 | AC29: 9746 | AD29: 9636 | AE29: 9589 | AF29: 9479 | AG29: 9498 | AH29: 9558 | AI29: 8535 | AJ29: 8470 | AK29: 8579 | AL29: 8539 | AM29: 8537 | AN29: 8634 | AO29: 8564 | AP29: 8618 | AQ29: 10654 | AR29: 10669 | AS29: 10678 | AT29: 10671
A30: Financial Products | B30: 17308 | C30: 17948 | D30: 16211 | E30: 16209 | F30: 15556 | G30: 15546 | H30: 15190 | I30: 14382 | J30: 14921 | K30: 15000 | L30: 16015 | M30: 15918 | N30: 15185 | O30: 15717 | P30: 17450 | Q30: 16995 | R30: 16590 | S30: 17107 | T30: 16454 | U30: 17140 | V30: 15371 | W30: 17178 | X30: 16365 | Y30: 16250 | Z30: 16605 | AA30: 16452 | AB30: 17395 | AC30: 16287 | AD30: 15641 | AE30: 16630 | AF30: 16030 | AG30: 16216 | AH30: 15315 | AI30: 14450 | AJ30: 15789 | AK30: 15893 | AL30: 16292 | AM30: 15299 | AN30: 17150 | AO30: 18787 | AP30: 17201 | AQ30: 17294 | AR30: 17067 | AS30: 20018 | AT30: 19971
A31: Liability for postemployment benefits | B31: 8877 | C31: 8759 | D31: 8638 | E31: 8843 | F31: 8600 | G31: 8533 | H31: 8499 | I31: 9357 | J31: 9291 | K31: 9248 | L31: 8973 | M31: 8365 | N31: 8233 | O31: 8092 | P31: 7046 | Q31: 7455 | R31: 7441 | S31: 7448 | T31: 5900 | U31: 6599 | V31: 6333 | W31: 6285 | X31: 6254 | Y31: 6872 | Z31: 6698 | AA31: 6581 | AB31: 6395 | AC31: 5592 | AD31: 5363 | AE31: 5160 | AF31: 5038 | AG31: 4203 | AH31: 4069 | AI31: 4084 | AJ31: 4060 | AK31: 4098 | AL31: 4068 | AM31: 3993 | AN31: 4029 | AO31: 3757 | AP31: 3575 | AQ31: 3611 | AR31: 3664 | AS31: 3838 | AT31: 3659
A32: Other liabilities | B32: 3206 | C32: 3271 | D32: 3322 | E32: 3203 | F32: 3269 | G32: 3301 | H32: 3276 | I32: 3184 | J32: 3238 | K32: 3235 | L32: 3152 | M32: 4053 | N32: 3942 | O32: 3954 | P32: 3799 | Q32: 3756 | R32: 4179 | S32: 4362 | T32: 4311 | U32: 4323 | V32: 4437 | W32: 4366 | X32: 4408 | Y32: 4358 | Z32: 4480 | AA32: 4524 | AB32: 4564 | AC32: 4805 | AD32: 5007 | AE32: 5006 | AF32: 4536 | AG32: 4604 | AH32: 4695 | AI32: 4788 | AJ32: 4841 | AK32: 4675 | AL32: 4826 | AM32: 4807 | AN32: 4839 | AO32: 4890 | AP32: 4915 | AQ32: 5169 | AR32: 5672 | AS32: 6175 | AT32: 6687
A33: Total liabilities | B33: 65452 | C33: 65081 | D33: 63001 | E33: 63457 | F33: 62554 | G33: 62997 | H33: 60687 | I33: 61491 | J33: 63889 | K33: 64431 | L33: 62863 | M33: 63196 | N33: 62742 | O33: 64045 | P33: 62319 | Q33: 64429 | R33: 63248 | S33: 64309 | T33: 63000 | U33: 63824 | V33: 61655 | W33: 62789 | X33: 61747 | Y33: 62946 | Z33: 64112 | AA33: 64817 | AB33: 64089 | AC33: 66277 | AD33: 65179 | AE33: 65348 | AF33: 65285 | AG33: 66052 | AH33: 65479 | AI33: 67171 | AJ33: 66284 | AK33: 67973 | AL33: 66096 | AM33: 66200 | AN33: 66870 | AO33: 68270 | AP33: 66904 | AQ33: 71662 | AR33: 73063 | AS33: 77267 | AT33: 76890
A34: Issued shares at paid-in amount | B34: 5101 | C34: 5142 | D34: 5190 | E34: 5238 | F34: 5247 | G34: 5277 | H34: 5266 | I34: 5277 | J34: 5222 | K34: 5316 | L34: 5460 | M34: 5593 | N34: 5640 | O34: 5746 | P34: 5715 | Q34: 5827 | R34: 5804 | S34: 5822 | T34: 5951 | U34: 5935 | V34: 6046 | W34: 6120 | X34: 6204 | Y34: 6230 | Z34: 6215 | AA34: 6293 | AB34: 6352 | AC34: 6398 | AD34: 6281 | AE34: 6464 | AF34: 6523 | AG34: 6560 | AH34: 6546 | AI34: 6478 | AJ34: 6698 | AK34: 6403 | AL34: 5663 | AM34: 5517 | AN34: 5584 | AO34: 6941 | AP34: 6043 | AQ34: 6143 | AR34: 6223 | AS34: 7181 | AT34: 5852
A35: Treasury stock at cost | B35: -16036 | C35: -16144 | D35: -17642 | E35: -17640 | F35: -17595 | G35: -17579 | H35: -17544 | I35: -17478 | J35: -17391 | K35: -17307 | L35: -17130 | M35: -17005 | N35: -17347 | O35: -18028 | P35: -18681 | Q35: -20531 | R35: -21214 | S35: -22467 | T35: -23693 | U35: -24217 | V35: -25341 | W35: -25412 | X35: -25315 | Y35: -25178 | Z35: -25049 | AA35: -25240 | AB35: -26608 | AC35: -27643 | AD35: -28326 | AE35: -29501 | AF35: -30883 | AG35: -31748 | AH35: -32108 | AI35: -33391 | AJ35: -33865 | AK35: -36339 | AL35: -40039 | AM35: -41612 | AN35: -42390 | AO35: -44331 | AP35: -47127 | AQ35: -47958 | AR35: -48302 | AS35: -49539 | AT35: -53307
A36: Retained Earnings | B36: 34998 | C36: 34823 | D36: 35191 | E36: 29246 | F36: 29517 | G36: 29167 | H36: 29450 | I36: 27377 | J36: 27584 | K36: 27471 | L36: 28530 | M36: 26301 | N36: 27929 | O36: 28657 | P36: 30384 | Q36: 30427 | R36: 32435 | S36: 32981 | T36: 34477 | U36: 34437 | V36: 35504 | W36: 34841 | X36: 35508 | Y36: 35167 | Z36: 36697 | AA36: 36934 | AB36: 38361 | AC36: 39282 | AD36: 40820 | AE36: 41263 | AF36: 43304 | AG36: 43514 | AH36: 45457 | AI36: 47094 | AJ36: 49888 | AK36: 51250 | AL36: 54108 | AM36: 55455 | AN36: 57920 | AO36: 59352 | AP36: 61356 | AQ36: 62160 | AR36: 64460 | AS36: 65448 | AT36: 67997
A37: Accumulated other comprehensive income | B37: -7101 | C37: -6729 | D37: -6843 | E37: -2035 | F37: -1493 | G37: -1633 | H37: -1527 | I37: -2039 | J37: -1827 | K37: -1471 | L37: -1233 | M37: -1192 | N37: -1016 | O37: -1496 | P37: -1568 | Q37: -1684 | R37: -1588 | S37: -1499 | T37: -1783 | U37: -1567 | V37: -2012 | W37: -1815 | X37: -1448 | Y37: -888 | Z37: -1290 | AA37: -1154 | AB37: -1440 | AC37: -1553 | AD37: -1710 | AE37: -2499 | AF37: -3353 | AG37: -2457 | AH37: -1746 | AI37: -1946 | AJ37: -2232 | AK37: -1820 | AL37: -2093 | AM37: -2230 | AN37: -1717 | AO37: -2471 | AP37: -2205 | AQ37: -1684 | AR37: -1723 | AS37: -1772 | AT37: -1881
A38: Noncontrolling interests | B38: 76 | C38: 69 | D38: 72 | E38: 76 | F38: 77 | G38: 71 | H38: 70 | I38: 76 | J38: 72 | K38: 70 | L38: 70 | M38: 69 | N38: 66 | O38: 63 | P38: 40 | Q38: 41 | R38: 41 | S38: 41 | T38: 41 | U38: 41 | V38: 42 | W38: 43 | X38: 45 | Y38: 47 | Z38: 44 | AA38: 47 | AB38: 30 | AC38: 32 | AD38: 32 | AE38: 32 | AF38: 31 | AG38: 22 | AH38: 21 | AI38: 21 | AJ38: 18 | AK38: 9 | AL38: 6 | AM38: 6 | AN38: 6 | AO38: 3 | AP38: 3 | AQ38: 2 | AR38: 1 | AT38: -1
A39: Total shareholders' equity | B39: 17038 | C39: 17161 | D39: 15968 | E39: 14885 | F39: 15753 | G39: 15303 | H39: 15715 | I39: 13213 | J39: 13660 | K39: 14079 | L39: 15697 | M39: 13766 | N39: 15272 | O39: 14942 | P39: 15890 | Q39: 14080 | R39: 15478 | S39: 14878 | T39: 14993 | U39: 14629 | V39: 14239 | W39: 13777 | X39: 14994 | Y39: 15378 | Z39: 16617 | AA39: 16880 | AB39: 16695 | AC39: 16516 | AD39: 17097 | AE39: 15759 | AF39: 15622 | AG39: 15891 | AH39: 18170 | AI39: 18256 | AJ39: 20507 | AK39: 19503 | AL39: 17645 | AM39: 17136 | AN39: 19403 | AO39: 19494 | AP39: 18070 | AQ39: 18663 | AR39: 20659 | AS39: 21318 | AT39: 18660
A40: Total liabilities and shareholders' equity | C40: 82242 | D40: 78969 | E40: 78342 | F40: 78307 | G40: 78300 | H40: 76402 | I40: 74704 | J40: 77549 | K40: 78510 | L40: 78560 | M40: 76962 | N40: 78014 | O40: 78987 | P40: 78209 | Q40: 78509 | R40: 78726 | S40: 79187 | T40: 77993 | U40: 78453 | V40: 75894 | W40: 76566 | X40: 76741 | Y40: 78324 | Z40: 80729 | AA40: 81697 | AB40: 80784 | AC40: 82793 | AD40: 82276 | AE40: 81107 | AF40: 80907 | AG40: 81943 | AH40: 83649 | AI40: 85427 | AJ40: 86791 | AK40: 87476 | AL40: 83741 | AM40: 83336 | AN40: 86273 | AO40: 87764 | AP40: 84974 | AQ40: 90325 | AR40: 93722 | AS40: 98585 | AT40: 95550

Sheet Cash-Flow-Quarterly
A1: Date | B1: 2015-03-31 | C1: 2015-06-30 | D1: 2015-09-30 | E1: 2015-12-31 | F1: 2016-03-31 | G1: 2016-06-30 | H1: 2016-09-30 | I1: 2016-12-31 | J1: 2017-03-31 | K1: 2017-06-30 | L1: 2017-09-30 | M1: 2017-12-31 | N1: 2018-03-31 | O1: 2018-06-30 | P1: 2018-09-30 | Q1: 2018-12-31 | R1: 2019-03-31 | S1: 2019-06-30 | T1: 2019-09-30 | U1: 2019-12-31 | V1: 2020-03-31 | W1: 2020-06-30 | X1: 2020-09-30 | Y1: 2020-12-31 | Z1: 2021-03-31 | AA1: 2021-06-30 | AB1: 2021-09-30 | AC1: 2021-12-31 | AD1: 2022-03-31 | AE1: 2022-06-30 | AF1: 2022-09-30 | AG1: 2022-12-31 | AH1: 2023-03-31 | AI1: 2023-06-30 | AJ1: 2023-09-30 | AK1: 2023-12-31 | AL1: 2024-03-31 | AM1: 2024-06-30 | AN1: 2024-09-30 | AO1: 2024-12-31 | AP1: 2025-03-31 | AQ1: 2025-06-30 | AR1: 2025-09-30 | AS1: 2025-12-31 | AT1: 2026-03-31
A2: Profit of consolidated and affiliated companies | B2: 1248 | C2: 803 | D2: 562 | E2: -90 | F2: 272 | G2: 553 | H2: 283 | I2: -1167 | J2: 194 | K2: 803 | L2: 1061 | M2: -1299 | N2: 1667 | O2: 1705 | P2: 1727 | Q2: 1049 | R2: 1884 | S2: 1619 | T2: 1494 | U2: 1097 | V2: 1093 | W2: 459 | X2: 671 | Y2: 780 | Z2: 1531 | AA2: 1414 | AB2: 1428 | AC2: 2120 | AD2: 1537 | AE2: 1673 | AF2: 2040 | AG2: 1454 | AH2: 1942 | AI2: 2924 | AJ2: 2793 | AK2: 2673 | AL2: 2854 | AM2: 2681 | AN2: 2463 | AO2: 2790 | AP2: 2003 | AQ2: 2179 | AR2: 2299 | AS2: 2401 | AT2: 2548
A3: Depreciation and amortization | B3: 753 | C3: 761 | D3: 758 | E3: 774 | F3: 740 | G3: 754 | H3: 761 | I3: 779 | J3: 710 | K3: 720 | L3: 723 | M3: 724 | N3: 681 | O3: 686 | P3: 698 | Q3: 701 | R3: 641 | S3: 647 | T3: 645 | U3: 644 | V3: 614 | W3: 608 | X3: 593 | Y3: 617 | Z3: 586 | AA3: 587 | AB3: 593 | AC3: 586 | AD3: 557 | AE3: 553 | AF3: 551 | AG3: 558 | AH3: 532 | AI3: 542 | AJ3: 525 | AK3: 545 | AL3: 524 | AM3: 531 | AN3: 543 | AO3: 555 | AP3: 540 | AQ3: 554 | AR3: 570 | AS3: 598 | AT3: 595
A4: Actuarial Gain on Pension and Postretirement Benefits | S4: -32 | T4: 32 | U4: 468 | V4: -254 | W4: 122 | X4: 77 | Y4: 438
A5: Provision for deferred income taxes | R5: -11 | S5: -23 | T5: 21 | U5: 41 | V5: 20 | W5: -54 | X5: -6 | Y5: -36 | Z5: 109 | AA5: -41 | AB5: -389 | AC5: -62 | AD5: -99 | AE5: -184 | AF5: -66 | AG5: -28 | AH5: -191 | AI5: -164 | AJ5: -93 | AK5: -144 | AL5: -54 | AM5: -79 | AN5: -196 | AO5: -292 | AP5: -38 | AQ5: -92 | AR5: 410 | AS5: 165 | AT5: 534
A6: Gain on Divestiture | AH6: 572 | AI6: 0 | AJ6: 0 | AK6: 0 | AL6: -64 | AM6: 228 | AN6: 0 | AO6: -57 | AR6: 509 | AS6: -479
A7: Other | B7: -88 | C7: 230 | D7: 181 | E7: 130 | F7: 269 | G7: 99 | H7: 272 | I7: 219 | J7: 302 | K7: 188 | L7: 106 | M7: 154 | N7: 148 | O7: 298 | P7: 184 | Q7: 376 | R7: 88 | S7: 352 | T7: 187 | U7: 48 | V7: 534 | W7: 140 | X7: 245 | Y7: 81 | Z7: -104 | AA7: 84 | AB7: 122 | AC7: 114 | AD7: -52 | AE7: 101 | AF7: 83 | AG7: 569 | AH7: 117 | AI7: -11 | AJ7: 99 | AK7: 170 | AL7: -5 | AM7: 110 | AN7: 116 | AO7: 594 | AP7: 78 | AQ7: 320 | AR7: -1186 | AS7: 1530 | AT7: 68
A8: Receivables - trade and other | B8: 6 | C8: 377 | D8: 231 | E8: 150 | F8: 14 | G8: 559 | H8: 555 | I8: -299 | J8: -353 | K8: -89 | L8: -13 | M8: -696 | N8: -326 | O8: -377 | P8: -22 | Q8: -894 | R8: -150 | S8: -16 | T8: 593 | U8: -256 | V8: 500 | W8: 676 | X8: 297 | Y8: -31 | Z8: -543 | AA8: 200 | AB8: 17 | AC8: -933 | AD8: -372 | AE8: 655 | AF8: 82 | AG8: -585 | AH8: -329 | AI8: -136 | AJ8: 146 | AK8: -118 | AL8: -81 | AM8: -164 | AN8: 215 | AO8: 621 | AP8: 155 | AQ8: -474 | AR8: -1696 | AS8: -123 | AT8: -801
A9: Inventories | B9: -89 | C9: 421 | D9: 508 | E9: 1434 | F9: -74 | G9: 379 | H9: 26 | I9: 778 | J9: -444 | K9: -244 | L9: -801 | M9: 194 | N9: -803 | O9: -405 | P9: -614 | Q9: 243 | R9: -813 | S9: 326 | T9: -189 | U9: 950 | V9: -541 | W9: 396 | X9: 6 | Y9: 105 | Z9: -657 | AA9: -522 | AB9: -1016 | AC9: -391 | AD9: -1032 | AE9: -971 | AF9: -1085 | AG9: 499 | AH9: -1403 | AI9: -157 | AJ9: 136 | AK9: 1060 | AL9: -439 | AM9: -204 | AN9: -138 | AO9: -318 | AP9: -990 | AQ9: -649 | AR9: 2725 | AS9: -2563 | AT9: -1501
A10: Accounts payable | B10: 228 | C10: -554 | D10: -567 | E10: -272 | F10: 211 | G10: -3 | H10: -371 | I10: -37 | J10: 732 | K10: 381 | L10: 258 | M10: 107 | N10: 486 | O10: 59 | P10: -49 | Q10: 213 | R10: 355 | S10: -221 | T10: -803 | U10: -356 | V10: 90 | W10: -745 | X10: 59 | Y10: 694 | Z10: 733 | AA10: 160 | AB10: 339 | AC10: 809 | AD10: 452 | AE10: -25 | AF10: 359 | AG10: 12 | AH10: 477 | AI10: -443 | AJ10: -566 | AK10: -222 | AL10: 203 | AM10: -224 | AN10: -75 | AO10: -291 | AP10: 401 | AQ10: 572 | AR10: -922 | AS10: 1128 | AT10: 938
