Workbook

Sheet Description
A1: Intel Corporation
A2: Basic Stats
A3: In Millions
A5: INTC | B5: 65
A6: Shares | B6: ='Income Statement'!F28 -> 4530
A7: MC | B7: =B5*B6 -> 294450
A8: Cash | B8: ='Balance Sheet'!F7+'Balance Sheet'!F8+'Balance Sheet'!F9 -> 37416
A9: Debt | B9: ='Balance Sheet'!F25+'Balance Sheet'!F31 -> 46585
A10: EV | B10: =B7-B8+B9 -> 303619
A12: Multiples:
A13: EV/FCF (less SBC) | B13: =B10/'Summary Stats'!F23 -> -41.124069
A14: P/E | B14: =B5/'Summary Stats'!F9 -> 172.90076
A15: EV/EBIT | B15: =B10/'Summary Stats'!F6 -> -13200.826
A16: EV/EBITDA | B16: =B10/'Summary Stats'!F7 -> 25.988102

Sheet KPIs
A1: Intel Corporation
A2: Segment Revenue and Operating Income
A3: In Millions
B4: FY2021 | C4: FY2022 | D4: FY2023 | E4: FY2024 | F4: FY2025
A5: REVENUE
A6: Client Computing Group | B6: =SUM(B7:B8) -> 41081 | C6: =SUM(C7:C8) -> 31773 | D6: =SUM(D7:D8) -> 29258 | E6: =SUM(E7:E8) -> 30290 | F6: =SUM(F7:F8) -> 32228
A7: Client combined (Notebook + Desktop) | B7: 37880 | C7: 29442 | D7: 27156 | E7: 28800 | F7: 27600
A8: Other Client Computing Group | B8: 3201 | C8: 2331 | D8: 2102 | E8: 1490 | F8: 4628
A10: Data Center and AI | B10: 22774 | C10: 16856 | D10: 12635 | E10: 12817 | F10: 16919
A12: Network and Edge | B12: 7665 | C12: 8409 | D12: 5774 | E12: 5842 | F12: 0
A14: Intel Foundry (formerly Intel Foundry Services) | B14: 347 | C14: 27491 | D14: 18910 | E14: 17543 | F14: 17826
A15: Intel Foundry External Revenue | B15: 347 | C15: 469 | D15: 952 | E15: 159 | F15: 307
A17: All Other | B17: 7157 | C17: 5530 | D17: 5608 | E17: 3824 | F17: 3563
A19: Intersegment Eliminations | B19: 0 | C19: -27005 | D19: -17957 | E19: -17215 | F19: -17683
A21: Total Net Revenue | B21: =SUM(B6,B10,B12,B14,B17,B19) -> 79024 | C21: =SUM(C6,C10,C12,C14,C17,C19) -> 63054 | D21: =SUM(D6,D10,D12,D14,D17,D19) -> 54228 | E21: =SUM(E6,E10,E12,E14,E17,E19) -> 53101 | F21: =SUM(F6,F10,F12,F14,F17,F19) -> 52853
A22: Note: FY2021 uses old segment structure (Intel Foundry Services = external revenue only, Mobileye as standalone segment, no intersegment eliminations shown). FY2022-FY2024 show Intel Foundry total including intersegment.
A23: FY2025: Network and Edge integrated into Client Computing Group and Data Center and AI; 'Other Client Computing Group' includes former Network and Edge revenue allocated to Client Computing Group. Desktop and Notebook not separately disclosed under new structure.
A25: OPERATING INCOME (LOSS)
A26: Client Computing Group | B26: 15523 | C26: 8207 | D26: 9513 | E26: 10920 | F26: 9317
A27: Data Center and AI | B27: 7376 | C27: 4198 | D27: 1620 | E27: 1338 | F27: 3422
A28: Network and Edge | B28: 1935 | C28: 1532 | D28: 204 | E28: 931 | F28: 0
A29: Intel Foundry (formerly Intel Foundry Services) | B29: 76 | C29: -5169 | D29: -6955 | E29: -13408 | F29: -10318
A30: All Other | B30: -5454 | C30: 1174 | D30: 1079 | E30: -84 | F30: 264
A31: Corporate Unallocated | B31: 0 | C31: -5633 | D31: -5165 | E31: -11218 | F31: -5518
A32: Intersegment Eliminations | B32: 0 | C32: -1975 | D32: -203 | E32: -157 | F32: 619
A33: Total Operating Income (Loss) | B33: =SUM(B26:B32) -> 19456 | C33: =SUM(C26:C32) -> 2334 | D33: =SUM(D26:D32) -> 93 | E33: =SUM(E26:E32) -> -11678 | F33: =SUM(F26:F32) -> -2214
A34: Note: FY2021 Corporate Unallocated is embedded in All Other (not separately broken out in old structure).
A36: SEGMENT OPERATING MARGIN (%)
A37: Client Computing Group | B37: =B26/B6 -> 0.37786325 | C37: =C26/C6 -> 0.25830107 | D37: =D26/D6 -> 0.32514184 | E37: =E26/E6 -> 0.36051502 | F37: =F26/F6 -> 0.28909644
A38: Data Center and AI | B38: =B27/B10 -> 0.32387811 | C38: =C27/C10 -> 0.24905078 | D38: =D27/D10 -> 0.12821528 | E38: =E27/E10 -> 0.1043926 | F38: =F27/F10 -> 0.20225782
A39: Network and Edge | B39: =B28/B12 -> 0.25244618 | C39: =C28/C12 -> 0.18218575 | D39: =D28/D12 -> 0.035330793 | E39: =E28/E12 -> 0.15936323 | F39: 0
A40: Intel Foundry (formerly Intel Foundry Services) | B40: =B29/B14 -> 0.21902017 | C40: =C29/C14 -> -0.18802517 | D40: =D29/D14 -> -0.36779482 | E40: =E29/E14 -> -0.76429345 | F40: =F29/F14 -> -0.57881746
A41: Other | B41: =B30/B17 -> -0.76205114 | C41: =C30/C17 -> 0.21229656 | D41: =D30/D17 -> 0.19240371 | E41: =E30/E17 -> -0.021966527 | F41: =F30/F17 -> 0.074094864
A42: Total OP margin | B42: =B33/B21 -> 0.24620368 | C42: =C33/C21 -> 0.037015891 | D42: =D33/D21 -> 0.0017149812 | E42: =E33/E21 -> -0.21992053 | F42: =F33/F21 -> -0.04188977

Sheet Income Statement
A1: Intel Corporation
A2: Consolidated Statements of Operations
A3: In Millions, Except Per Share Amounts
B4: FY2021 | C4: FY2022 | D4: FY2023 | E4: FY2024 | F4: FY2025
A6: Net revenue | B6: 79024 | C6: 63054 | D6: 54228 | E6: 53101 | F6: 52853
A7: Cost of sales | B7: 35209 | C7: 36188 | D7: 32517 | E7: 35756 | F7: 34478
A8: Gross profit | B8: =B6-B7 -> 43815 | C8: =C6-C7 -> 26866 | D8: =D6-D7 -> 21711 | E8: =E6-E7 -> 17345 | F8: =F6-F7 -> 18375
A9: Operating expenses:
A10: Research and development | B10: 15190 | C10: 17528 | D10: 16046 | E10: 16546 | F10: 13774
A11: Marketing, general, and administrative | B11: 6543 | C11: 7002 | D11: 5634 | E11: 5507 | F11: 4624
A12: Restructuring and other charges | B12: 2626 | C12: 2 | D12: -62 | E12: 6970 | F12: 2191
A13: Operating income (loss) | B13: =B8-B10-B11-B12 -> 19456 | C13: =C8-C10-C11-C12 -> 2334 | D13: =D8-D10-D11-D12 -> 93 | E13: =E8-E10-E11-E12 -> -11678 | F13: =F8-F10-F11-F12 -> -2214
A14: Gains (losses) on equity investments, net | B14: 2729 | C14: 4268 | D14: 40 | E14: 242 | F14: 514
A15: Interest and other, net | B15: -482 | C15: 1166 | D15: 629 | E15: 226 | F15: 3257
A16: Income (loss) before taxes | B16: =SUM(B13:B15) -> 21703 | C16: =SUM(C13:C15) -> 7768 | D16: =SUM(D13:D15) -> 762 | E16: =SUM(E13:E15) -> -11210 | F16: =SUM(F13:F15) -> 1557
A17: Provision for (benefit from) taxes | B17: 1835 | C17: -249 | D17: -913 | E17: 8023 | F17: 1531
A18: Net income (loss) | B18: =B16-B17 -> 19868 | C18: =C16-C17 -> 8017 | D18: =D16-D17 -> 1675 | E18: =E16-E17 -> -19233 | F18: =F16-F17 -> 26
A19: Less: Net income (loss) attributable to non-controlling interests | B19: 0 | C19: 3 | D19: -14 | E19: -477 | F19: 293
A20: Net income (loss) attributable to Intel | B20: =B18-B19 -> 19868 | C20: =C18-C19 -> 8014 | D20: =D18-D19 -> 1689 | E20: =E18-E19 -> -18756 | F20: =F18-F19 -> -267
A22: Per share data (attributable to Intel):
A23: Earnings (loss) per share - basic | B23: =B$20/B27 -> 4.8948017 | C23: =C$20/C27 -> 1.9508277 | D23: =D$20/D27 -> 0.40310263 | E23: =E$20/E27 -> -4.382243 | F23: =F$20/F27 -> -0.058940397
A24: Earnings (loss) per share - diluted | B24: =B$20/B28 -> 4.8577017 | C24: =C$20/C28 -> 1.9437303 | D24: =D$20/D28 -> 0.40099715 | E24: =E$20/E28 -> -4.382243 | F24: =F$20/F28 -> -0.058940397
A26: Weighted average shares outstanding (millions):
A27: Basic | B27: 4059 | C27: 4108 | D27: 4190 | E27: 4280 | F27: 4530
A28: Diluted | B28: 4090 | C28: 4123 | D28: 4212 | E28: 4280 | F28: 4530

Sheet Balance Sheet
A1: Intel Corporation
A2: Consolidated Balance Sheets
A3: In Millions
B4: FY2021 | C4: FY2022 | D4: FY2023 | E4: FY2024 | F4: FY2025
A5: ASSETS
A6: Current assets:
A7: Cash and cash equivalents | B7: 4827 | C7: 11144 | D7: 7079 | E7: 8249 | F7: 14265
A8: Short-term investments | B8: 2103 | C8: 17194 | D8: 17955 | E8: 13813 | F8: 23151
A9: Trading assets | B9: 21483 | C9: 0 | D9: 0 | E9: 0 | F9: 0
A10: Accounts receivable, net | B10: 9457 | C10: 4133 | D10: 3402 | E10: 3478 | F10: 3839
A11: Inventories | B11: 10776 | C11: 13224 | D11: 11127 | E11: 12198 | F11: 11618
A12: Assets held for sale | B12: 6942 | C12: 0 | D12: 0 | E12: 0 | F12: 0
A13: Other current assets | B13: 2130 | C13: 4712 | D13: 3706 | E13: 9586 | F13: 10815
A14: Total current assets | B14: =SUM(B7:B13) -> 57718 | C14: =SUM(C7:C13) -> 50407 | D14: =SUM(D7:D13) -> 43269 | E14: =SUM(E7:E13) -> 47324 | F14: =SUM(F7:F13) -> 63688
A15: Property, plant and equipment, net | B15: 63245 | C15: 80860 | D15: 96647 | E15: 107919 | F15: 105414
A16: Equity investments | B16: 6298 | C16: 5912 | D16: 5829 | E16: 5383 | F16: 8512
A17: Other long-term investments | B17: 840 | C17: 0 | D17: 0 | E17: 0 | F17: 0
A18: Goodwill | B18: 26963 | C18: 27591 | D18: 27591 | E18: 24693 | F18: 23912
A19: Identified intangible assets, net | B19: 7270 | C19: 6018 | D19: 4589 | E19: 3691 | F19: 2772
A20: Other long-term assets | B20: 6072 | C20: 11315 | D20: 13647 | E20: 7475 | F20: 7131
A21: Total assets | B21: =SUM(B14:B20) -> 168406 | C21: =SUM(C14:C20) -> 182103 | D21: =SUM(D14:D20) -> 191572 | E21: =SUM(E14:E20) -> 196485 | F21: =SUM(F14:F20) -> 211429
A23: LIABILITIES AND STOCKHOLDERS' EQUITY
A24: Current liabilities:
A25: Short-term debt | B25: 4591 | C25: 4367 | D25: 2288 | E25: 3729 | F25: 2499
A26: Accounts payable | B26: 5747 | C26: 9595 | D26: 8578 | E26: 12556 | F26: 9882
A27: Accrued compensation and benefits | B27: 4535 | C27: 4084 | D27: 3655 | E27: 3343 | F27: 3990
A28: Income taxes payable | B28: 0 | C28: 2251 | D28: 1107 | E28: 1756 | F28: 604
A29: Other accrued liabilities | B29: 12589 | C29: 11858 | D29: 12425 | E29: 14282 | F29: 14600
A30: Total current liabilities | B30: =SUM(B25:B29) -> 27462 | C30: =SUM(C25:C29) -> 32155 | D30: =SUM(D25:D29) -> 28053 | E30: =SUM(E25:E29) -> 35666 | F30: =SUM(F25:F29) -> 31575
A31: Long-term debt | B31: 33510 | C31: 37684 | D31: 46978 | E31: 46282 | F31: 44086
A32: Contract liabilities | B32: 185 | C32: 0 | D32: 0 | E32: 0 | F32: 0
A33: Income taxes payable (non-current) | B33: 4305 | C33: 0 | D33: 0 | E33: 0 | F33: 0
A34: Deferred income taxes | B34: 2667 | C34: 0 | D34: 0 | E34: 0 | F34: 0
A35: Other long-term liabilities | B35: 4886 | C35: 8978 | D35: 6576 | E35: 9505 | F35: 9408
A36: Total liabilities | B36: =SUM(B30:B35) -> 73015 | C36: =SUM(C30:C35) -> 78817 | D36: =SUM(D30:D35) -> 81607 | E36: =SUM(E30:E35) -> 91453 | F36: =SUM(F30:F35) -> 85069
A37: Stockholders' equity:
A38: Common stock and capital in excess of par value | B38: 28006 | C38: 31580 | D38: 36649 | E38: 50949 | F38: 65185
A39: Accumulated other comprehensive income (loss) | B39: -880 | C39: -562 | D39: -215 | E39: -711 | F39: 113
A40: Retained earnings | B40: 68265 | C40: 70405 | D40: 69156 | E40: 49032 | F40: 48983
A41: Total Intel stockholders' equity | B41: =SUM(B38:B40) -> 95391 | C41: =SUM(C38:C40) -> 101423 | D41: =SUM(D38:D40) -> 105590 | E41: =SUM(E38:E40) -> 99270 | F41: =SUM(F38:F40) -> 114281
...

Sheet Cash Flow Statement
A1: Intel Corporation
A2: Consolidated Statements of Cash Flows
A3: In Millions
B4: FY2021 | C4: FY2022 | D4: FY2023 | E4: FY2024 | F4: FY2025
A6: Cash and cash equivalents, beginning of period | B6: 5865 | C6: =B60 -> 4827 | D6: =C60 -> 11144 | E6: =D60 -> 7079 | F6: =E60 -> 8249
A8: OPERATING ACTIVITIES
A9: Net income (loss) | B9: ='Income Statement'!B18 -> 19868 | C9: ='Income Statement'!C18 -> 8017 | D9: ='Income Statement'!D18 -> 1675 | E9: ='Income Statement'!E18 -> -19233 | F9: ='Income Statement'!F18 -> 26
A10: Adjustments to reconcile net income (loss) to net cash from operations:
A11: Depreciation | B11: 9953 | C11: 11128 | D11: 7847 | E11: 9951 | F11: 10757
A12: Share-based compensation | B12: 2036 | C12: 3128 | D12: 3229 | E12: 3410 | F12: 2434
A13: Restructuring and other charges | B13: 2626 | C13: 1074 | D13: -424 | E13: 3491 | F13: 476
A14: Amortization of intangibles | B14: 1839 | C14: 1907 | D14: 1755 | E14: 1428 | F14: 949
A15: (Gains) losses on equity investments, net | B15: -1458 | C15: -4254 | D15: -42 | E15: -246 | F15: -514
A16: (Gains) losses on divestitures | B16: 0 | C16: -1059 | D16: 0 | E16: 0 | F16: -5323
A17: Deferred taxes | B17: 0 | C17: 0 | D17: -2033 | E17: 6132 | F17: 328
A18: Impairments and net loss on retirement of property, plant and equipment | B18: 0 | C18: 0 | D18: 33 | E18: 2252 | F18: 515
A19: Mark-to-market losses on Escrowed Shares | B19: 0 | C19: 0 | D19: 0 | E19: 0 | F19: 1796
A20: Changes in assets and liabilities:
A21: Accounts receivable | B21: -2674 | C21: 5327 | D21: 731 | E21: -75 | F21: -449
A22: Inventories | B22: -2339 | C22: -2436 | D22: 2097 | E22: -1105 | F22: -138
A23: Accounts payable | B23: 1190 | C23: -29 | D23: -801 | E23: 634 | F23: 297
A24: Accrued compensation and benefits | B24: 515 | C24: -1533 | D24: -614 | E24: -218 | F24: 788
A25: Prepaid customer supply agreements | B25: -1583 | C25: -24 | D25: 0 | E25: 0 | F25: 0
A26: Income taxes | B26: -441 | C26: -4535 | D26: -1498 | E26: -356 | F26: -995
A27: Other assets and liabilities | B27: -76 | C27: -1278 | D27: -484 | E27: 2223 | F27: -1250
A28: Net cash provided by (used for) operating activities | B28: =SUM(B9:B27) -> 29456 | C28: =SUM(C9:C27) -> 15433 | D28: =SUM(D9:D27) -> 11471 | E28: =SUM(E9:E27) -> 8288 | F28: =SUM(F9:F27) -> 9697
A30: INVESTING ACTIVITIES
A31: Additions to property, plant and equipment | B31: -18733 | C31: -24844 | D31: -25750 | E31: -23944 | F31: -14646
A32: Additions to held for sale NAND property, plant and equipment | B32: -1596 | C32: -206 | D32: 0 | E32: 0 | F32: 0
A33: Proceeds from capital-related government incentives | B33: 166 | C33: 246 | D33: 1011 | E33: 1936 | F33: 1577
A34: Purchases of short-term investments | B34: -40554 | C34: -43647 | D34: -44414 | E34: -37940 | F34: -24319
A35: Maturities and sales of short-term investments | B35: 35299 | C35: 48730 | D35: 44077 | E35: 41463 | F35: 15387
A36: Purchases of equity investments | B36: -613 | C36: -510 | D36: 0 | E36: 0 | F36: 0
A37: Sales of equity investments | B37: 581 | C37: 4961 | D37: 472 | E37: 1047 | F37: 671
A38: Proceeds from divestitures, net | B38: 0 | C38: 6579 | D38: 0 | E38: 0 | F38: 6157
A39: Other investing | B39: 1167 | C39: -1540 | D39: 563 | E39: -818 | F39: 352
A40: Net cash provided by (used for) investing activities | B40: =SUM(B31:B39) -> -24283 | C40: =SUM(C31:C39) -> -10231 | D40: =SUM(D31:D39) -> -24041 | E40: =SUM(E31:E39) -> -18256 | F40: =SUM(F31:F39) -> -14821
A42: FINANCING ACTIVITIES
A43: Issuance of commercial paper, net of issuance costs | B43: 0 | C43: 3945 | D43: 0 | E43: 7349 | F43: 3493
A44: Repayment of commercial paper | B44: 0 | C44: 0 | D44: -3944 | E44: -7349 | F44: -3493
...

Sheet Summary Stats
A1: Intel Corporation
A2: Summary
A3: In Millions
B4: FY2021 | C4: FY2022 | D4: FY2023 | E4: FY2024 | F4: FY2025
A6: EBIT | B6: ='Income Statement'!B8-'Income Statement'!B10-'Income Statement'!B11 -> 22082 | C6: ='Income Statement'!C8-'Income Statement'!C10-'Income Statement'!C11 -> 2336 | D6: ='Income Statement'!D8-'Income Statement'!D10-'Income Statement'!D11 -> 31 | E6: ='Income Statement'!E8-'Income Statement'!E10-'Income Statement'!E11 -> -4708 | F6: ='Income Statement'!F8-'Income Statement'!F10-'Income Statement'!F11 -> -23
A7: EBITDA | B7: =B6+'Cash Flow Statement'!B11+'Cash Flow Statement'!B14 -> 33874 | C7: =C6+'Cash Flow Statement'!C11+'Cash Flow Statement'!C14 -> 15371 | D7: =D6+'Cash Flow Statement'!D11+'Cash Flow Statement'!D14 -> 9633 | E7: =E6+'Cash Flow Statement'!E11+'Cash Flow Statement'!E14 -> 6671 | F7: =F6+'Cash Flow Statement'!F11+'Cash Flow Statement'!F14 -> 11683
A8: Normalized Earnings | B8: =B6+'Income Statement'!B15-'Income Statement'!B17 -> 19765 | C8: =C6+'Income Statement'!C15-'Income Statement'!C17 -> 3751 | D8: =D6+'Income Statement'!D15-'Income Statement'!D17 -> 1573 | E8: =E6+'Income Statement'!E15-'Income Statement'!E17 -> -12505 | F8: =F6+'Income Statement'!F15-'Income Statement'!F17 -> 1703
A9: Normalized EPS | B9: =B8/'Income Statement'!B28 -> 4.8325183 | C9: =C8/'Income Statement'!C28 -> 0.90977444 | D9: =D8/'Income Statement'!D28 -> 0.37345679 | E9: =E8/'Income Statement'!E28 -> -2.921729 | F9: =F8/'Income Statement'!F28 -> 0.37593819
A11: Margins:
A12: Gross | B12: ='Income Statement'!B8/'Income Statement'!B6 -> 0.55445181 | C12: ='Income Statement'!C8/'Income Statement'!C6 -> 0.42607923 | D12: ='Income Statement'!D8/'Income Statement'!D6 -> 0.40036513 | E12: ='Income Statement'!E8/'Income Statement'!E6 -> 0.32664168 | F12: ='Income Statement'!F8/'Income Statement'!F6 -> 0.34766238
A13: EBIT | B13: =B6/'Income Statement'!B6 -> 0.2794341 | C13: =C6/'Income Statement'!C6 -> 0.03704761 | D13: =D6/'Income Statement'!D6 -> 0.0005716604 | E13: =E6/'Income Statement'!E6 -> -0.08866123 | F13: =F6/'Income Statement'!F6 -> -0.00043516924
A14: EBITDA | B14: =B7/'Income Statement'!B6 -> 0.42865459 | C14: =C7/'Income Statement'!C6 -> 0.24377518 | D14: =D7/'Income Statement'!D6 -> 0.17763886 | E14: =E7/'Income Statement'!E6 -> 0.12562852 | F14: =F7/'Income Statement'!F6 -> 0.22104706
A15: Net income | B15: =B8/'Income Statement'!B6 -> 0.25011389 | C15: =C8/'Income Statement'!C6 -> 0.059488692 | D15: =D8/'Income Statement'!D6 -> 0.029007155 | E15: =E8/'Income Statement'!E6 -> -0.23549462 | F15: =F8/'Income Statement'!F6 -> 0.032221444
A17: NOWC | B17: ='Balance Sheet'!B14-'Balance Sheet'!B7-'Balance Sheet'!B8-'Balance Sheet'!B9-'Balance Sheet'!B12-'Balance Sheet'!B30-'Balance Sheet'!B25 -> -9690 | C17: ='Balance Sheet'!C14-'Balance Sheet'!C7-'Balance Sheet'!C8-'Balance Sheet'!C9-'Balance Sheet'!C12-'Balance Sheet'!C30-'Balance Sheet'!C25 -> -14453 | D17: ='Balance Sheet'!D14-'Balance Sheet'!D7-'Balance Sheet'!D8-'Balance Sheet'!D9-'Balance Sheet'!D12-'Balance Sheet'!D30-'Balance Sheet'!D25 -> -12106 | E17: ='Balance Sheet'!E14-'Balance Sheet'!E7-'Balance Sheet'!E8-'Balance Sheet'!E9-'Balance Sheet'!E12-'Balance Sheet'!E30-'Balance Sheet'!E25 -> -14133 | F17: ='Balance Sheet'!F14-'Balance Sheet'!F7-'Balance Sheet'!F8-'Balance Sheet'!F9-'Balance Sheet'!F12-'Balance Sheet'!F30-'Balance Sheet'!F25 -> -7802
A18: Chng in NOWC | C18: =C17-B17 -> -4763 | D18: =D17-C17 -> 2347 | E18: =E17-D17 -> -2027 | F18: =F17-E17 -> 6331
A20: NOPAT | B20: =B6-'Income Statement'!B17 -> 20247 | C20: =C6-'Income Statement'!C17 -> 2585 | D20: =D6-'Income Statement'!D17 -> 944 | E20: =E6-'Income Statement'!E17 -> -12731 | F20: =F6-'Income Statement'!F17 -> -1554
A21: ROIC | B21: =B20/('Balance Sheet'!B41+'Balance Sheet'!B25+'Balance Sheet'!B31-'Balance Sheet'!B7-'Balance Sheet'!B8-'Balance Sheet'!B9) -> 0.1926836 | C21: =C20/('Balance Sheet'!C41+'Balance Sheet'!C25+'Balance Sheet'!C31-'Balance Sheet'!C7-'Balance Sheet'!C8-'Balance Sheet'!C9) -> 0.022451709 | D21: =D20/('Balance Sheet'!D41+'Balance Sheet'!D25+'Balance Sheet'!D31-'Balance Sheet'!D7-'Balance Sheet'!D8-'Balance Sheet'!D9) -> 0.0072714948 | E21: =E20/('Balance Sheet'!E41+'Balance Sheet'!E25+'Balance Sheet'!E31-'Balance Sheet'!E7-'Balance Sheet'!E8-'Balance Sheet'!E9) -> -0.10007153 | F21: =F20/('Balance Sheet'!F41+'Balance Sheet'!F25+'Balance Sheet'!F31-'Balance Sheet'!F7-'Balance Sheet'!F8-'Balance Sheet'!F9) -> -0.012588092
A23: FCF (less SBC) | B23: ='Cash Flow Statement'!B28+'Cash Flow Statement'!B31-'Cash Flow Statement'!B12 -> 8687 | C23: ='Cash Flow Statement'!C28+'Cash Flow Statement'!C31-'Cash Flow Statement'!C12 -> -12539 | D23: ='Cash Flow Statement'!D28+'Cash Flow Statement'!D31-'Cash Flow Statement'!D12 -> -17508 | E23: ='Cash Flow Statement'!E28+'Cash Flow Statement'!E31-'Cash Flow Statement'!E12 -> -19066 | F23: ='Cash Flow Statement'!F28+'Cash Flow Statement'!F31-'Cash Flow Statement'!F12 -> -7383
A25: Total Debt | B25: ='Balance Sheet'!B25+'Balance Sheet'!B31 -> 38101 | C25: ='Balance Sheet'!C25+'Balance Sheet'!C31 -> 42051 | D25: ='Balance Sheet'!D25+'Balance Sheet'!D31 -> 49266 | E25: ='Balance Sheet'!E25+'Balance Sheet'!E31 -> 50011 | F25: ='Balance Sheet'!F25+'Balance Sheet'!F31 -> 46585
A26: Cash & Equivalents | B26: ='Balance Sheet'!B7+'Balance Sheet'!B8+'Balance Sheet'!B9 -> 28413 | C26: ='Balance Sheet'!C7+'Balance Sheet'!C8+'Balance Sheet'!C9 -> 28338 | D26: ='Balance Sheet'!D7+'Balance Sheet'!D8+'Balance Sheet'!D9 -> 25034 | E26: ='Balance Sheet'!E7+'Balance Sheet'!E8+'Balance Sheet'!E9 -> 22062 | F26: ='Balance Sheet'!F7+'Balance Sheet'!F8+'Balance Sheet'!F9 -> 37416
A27: Net Debt | B27: =B25-B26 -> 9688 | C27: =C25-C26 -> 13713 | D27: =D25-D26 -> 24232 | E27: =E25-E26 -> 27949 | F27: =F25-F26 -> 9169
A28: DTE | B28: =B25/'Balance Sheet'!B41 -> 0.39941923 | C28: =C25/'Balance Sheet'!C41 -> 0.4146101 | D28: =D25/'Balance Sheet'!D41 -> 0.46657827 | E28: =E25/'Balance Sheet'!E41 -> 0.50378765 | F28: =F25/'Balance Sheet'!F41 -> 0.40763556
A30: Total Debt Growth | C30: =C25/B25-1 -> 0.10367182 | D30: =D25/C25-1 -> 0.17157737 | E30: =E25/D25-1 -> 0.015121991 | F30: =F25/E25-1 -> -0.068504929
A31: Cash Growth | C31: =C26/B26-1 -> -0.0026396368 | D31: =D26/C26-1 -> -0.11659256 | E31: =E26/D26-1 -> -0.11871854 | F31: =F26/E26-1 -> 0.69594778
A32: Net Debt Growth | C32: =C27/B27-1 -> 0.41546243 | D32: =D27/C27-1 -> 0.76708233 | E32: =E27/D27-1 -> 0.15339221 | F32: =F27/E27-1 -> -0.67193817
A34: Capital Issuance | B34: ='Cash Flow Statement'!B43+'Cash Flow Statement'!B46+'Cash Flow Statement'!B47+'Cash Flow Statement'!B49+'Cash Flow Statement'!B51+'Cash Flow Statement'!B52 -> 5994 | C34: ='Cash Flow Statement'!C43+'Cash Flow Statement'!C46+'Cash Flow Statement'!C47+'Cash Flow Statement'!C49+'Cash Flow Statement'!C51+'Cash Flow Statement'!C52 -> 13376 | D34: ='Cash Flow Statement'!D43+'Cash Flow Statement'!D46+'Cash Flow Statement'!D47+'Cash Flow Statement'!D49+'Cash Flow Statement'!D51+'Cash Flow Statement'!D52 -> 16903 | E34: ='Cash Flow Statement'!E43+'Cash Flow Statement'!E46+'Cash Flow Statement'!E47+'Cash Flow Statement'!E49+'Cash Flow Statement'!E51+'Cash Flow Statement'!E52 -> 24025 | F34: ='Cash Flow Statement'!F43+'Cash Flow Statement'!F46+'Cash Flow Statement'!F47+'Cash Flow Statement'!F49+'Cash Flow Statement'!F51+'Cash Flow Statement'!F52 -> 22999
A35: Capital Return | B35: =SUM('Cash Flow Statement'!B44,'Cash Flow Statement'!B45,'Cash Flow Statement'!B48,'Cash Flow Statement'!B50,'Cash Flow Statement'!B53:B56) -> -12205 | C35: =SUM('Cash Flow Statement'!C44,'Cash Flow Statement'!C45,'Cash Flow Statement'!C48,'Cash Flow Statement'!C50,'Cash Flow Statement'!C53:C56) -> -12261 | D35: =SUM('Cash Flow Statement'!D44,'Cash Flow Statement'!D45,'Cash Flow Statement'!D48,'Cash Flow Statement'!D50,'Cash Flow Statement'!D53:D56) -> -8398 | E35: =SUM('Cash Flow Statement'!E44,'Cash Flow Statement'!E45,'Cash Flow Statement'!E48,'Cash Flow Statement'!E50,'Cash Flow Statement'!E53:E56) -> -12887 | F35: =SUM('Cash Flow Statement'!F44,'Cash Flow Statement'!F45,'Cash Flow Statement'!F48,'Cash Flow Statement'!F50,'Cash Flow Statement'!F53:F56) -> -11412
A36: Cash from financing activities | B36: =SUM(B34:B35) -> -6211 | C36: =SUM(C34:C35) -> 1115 | D36: =SUM(D34:D35) -> 8505 | E36: =SUM(E34:E35) -> 11138 | F36: =SUM(F34:F35) -> 11587

Sheet Notes
A1: Intel Corporation
A2: SWOT
B4: Strengths:
A6: 1 | B6: IDM model puts INTC in a prime position to navigate volatile international affairs such as tariff drama or international conflicts.
B7: Nuance: while INTC designs and builds chips in-house, they still rely on a vast international supply chain to produce their product. They are still highly exposed to conflict and tariffs that effect inputs or supply chains- just less than their competitors like NVDA.
A9: 2 | B9: INTC is one of the largest chip sellers in the world with the number one market share spot for CPUs.
B10: Nuance: while this is true, the leading AI and HPC workloads primarily run on AMD and NVDA hardware. This is important because AI and HPC are the leading categories of growth and margin expansion for chip makers.
A12: 3 | B12: INTC is essentially the longest tenured chip designer in existence. They have decades of industry experience, leadership, and relationships behind them that reinforce their ecosystem and growth even in rougher climates
B13: Nuance: INTC does have long-standing enterprise experience and relationships but the current expansion of the AI market is a new frontier of compute that is being dominated by the first movers being NVDA and AMD. INTC may have the rug pulled beneath their feet as the industry they jumpstarted rearrages itself around INTC's competitors
B15: Weaknesses:
A16: 1 | B16: CapEx Intensive IDM model lowers returns compared to AMD. All else held constant, fabless will always produce a more efficient and streamlined business
B17: Nuance: None
A19: 2 | B19: Business Turnaround has been extremely expensive and has lead to a staggering LT debt load ($11B more debt in 5 years)
B20: Nuance: They are beginning to shift their capital structure more towards equity as seen with the recent $12B in equity issuance
B23: Opportunities:
A25: 1 | B25: INTC can potentially land external fabrication business with newer chip makers that do not have long standing relations with TSMC
B26: Nuance: This is a tiny list of labs that will produce very little revenue for INTC due to lack of scale
A28: 2 | B28: INTC ha the opportunity to take advantage of a market that is systemically undersupplied of data center GPUs. This may push firms like Oracle and other hyperscalers to experiment and shift some of their buildouts with INTC GPUs.
B29: Nuance: Many firms have stated that they get fewer GPUs from NVDA than they want due to supply constraints, but it is still not probable that INTC absorbs a material portion of that vacuum primarily on the count of the fact that their hardware is vastly disadvantaged in ecosystm and accompanying software stack when compared to first movers like AMD and NVDA. These are the factors that make NVDA hardware so dominant and hard to beat in performance and efficiency at scale for the highest level (and highest margin) AI and HPC workloads.
