Workbook

Sheet Exec Summary
B2: Kioxia Holdings Corporation (TSE: 285A / OTC ADR: KXIAY)
B3: Market-Implied vs. Most-Likely Scenario DCF — All Figures in USD
B5: Valuation Date | C5: 2026-06-16
B6: Fiscal Year End | C6: March 31
B7: Base Year (Historical, Hardcoded) | C7: FY26A (year ended Mar-2026), Actual — user-provided 285A-financials.xlsx
B8: Forecast Period | C8: FY27E to FY31E (5 fiscal years)
B9: Source Financials Currency | C9: USD (already converted; no FX layer in the operating model)
B10: Spot USD/JPY (for share-price translation only) | C10: 160.44
B11: Current Share Price, Ordinary (TSE 285A, JPY) | C11: 94720
B12: Current Share Price, Ordinary (USD) | C12: 590.37646
B13: Diluted Shares Outstanding (mm) | C13: 549.461
B14: Current Market Cap (USD mm) | C14: 324388.84
B15: Cash (USD mm, FY26A) | C15: 2934.077
B16: Total Debt (USD mm, FY26A) | C16: 7811.5537
B17: Net Debt (USD mm, FY26A) | C17: 4877.4767
B18: WACC, USD-equivalent, fundamental build (no beta) | C18: 0.15729681
B21: FY26A Historical Snapshot (from user-provided file)
B22: Revenue ($mm) | C22: 14571.231
B23: Gross Margin | C23: 0.43330419
B24: EBIT Margin | C24: 0.37059917
B25: EBITDA ($mm) | C25: 7350.0371
B26: D&A % of Revenue | C26: 0.13382198
B27: Capex % of Revenue | C27: 0.12023384
B28: Effective Tax Rate | C28: 0.29282039
B31: Scenario Engine Results (USD)
B32: Total Scenarios Run | C32: 2000
B33: Minimum Implied Price (USD) | C33: 0.55647889
B34: Median Implied Price (USD) | C34: 172.40484
B35: Maximum Implied Price (USD) | C35: 974.01892
B36: Scenarios within ±5% of Current Price | C36: 14
B37: Scenarios Rejected — Impossible | C37: 0
B38: Scenarios Rejected — Implausible | C38: 427
B39: Scenarios Classified Probable | C39: 8
B42: Selected Market-Priced Scenario (what the price implies)
B43: Scenario ID / Name | C43: #1240 (Random Scenario 1224)
B44: Implied Share Price (USD) | C44: 577.81682
B45: Current Share Price (USD) | C45: 590.37646
B46: % Difference vs. Current Price | C46: -0.021273964
B47: Market Pricing Fit Score (0-100) | C47: 90.915894
B48: Probability Score (0-100) | C48: 50.664354
...

Sheet Sources
B2: Sources
B4: # | C4: Name | D4: Type | E4: Date | F4: Data Used / Assumption Supported | G4: Link / Citation | H4: Quality Tier | I4: Reliability Note
B5: 1 | C5: 285A-financials.xlsx (user-provided) | D5: Reconciled financial statement export | E5: 2026-06-16 (FY26A as of 2026-03-31) | F5: FY26A Income Statement, Balance Sheet, Cash Flow, Ratios (Annual/Quarterly/TTM). All historical hardcodes on the Model tab (revenue, COGS, opex, EBIT, tax rate, D&A, capex, cash, debt, shares) sourced from this file. | G5: User-provided file, Downloads folder | H5: Tier 1 | I5: Internally reconciled across statements (e.g. FY25 cash plus FY26 net cash flow equals FY26 cash, verified); supersedes prior session web-sourced balance sheet figures
B6: 2 | C6: Kioxia (285A) TSE share price | D6: Exchange data (Investing.com / stockanalysis.com) | E6: 2026-06-16 | F6: Current ordinary share price 94,720 yen; used as the current-price anchor | G6: WebSearch result, June 2026 | H6: Tier 1 | I6: Primary liquid listing
B7: 3 | C7: KXIAY OTC ADR quote | D7: OTC Markets / Yahoo Finance | E7: 2026-06-09 | F7: Quoted ADR price approximately $476.78 - does not reconcile with theoretical parity (1 ADS to 0.1 ordinary) at spot FX; NOT used | G7: WebSearch result, June 2026 | H7: Weak | I7: Unsponsored Pink Limited ADR, thin liquidity; ordinary TSE price used instead
B8: 4 | C8: USD/JPY spot exchange rate | D8: FX market data | E8: 2026-06-16 | F8: Spot USD/JPY 160.44; used only to translate the JPY-quoted current share price to USD (no longer used in the operating model, since FY26A financials are already USD-denominated) | G8: WebSearch result, June 2026 | H8: Tier 1 | I8: Liquid FX market
B9: 5 | C9: Japan 10-Year JGB yield | D9: Bloomberg / Investing.com | E9: 2026-06-02 | F9: Risk-free rate input to cost of equity build, 2.57% | G9: WebSearch result, June 2026 | H9: Tier 1 | I9: Benchmark government bond yield
B10: 6 | C10: US 10-Year Treasury yield | D10: Federal Reserve H.15 / CNBC | E10: 2026-06-16 | F10: Used for USD-JPY risk-free differential in WACC, 4.47% | G10: WebSearch result, June 2026 | H10: Tier 1 | I10: Official Fed release data
B11: 7 | C11: NAND industry bit demand/supply growth, capacity timing | D11: TrendForce / IDC / Gartner | E11: 2025 Q4 - 2026 Q2 | F11: Bit demand CAGR approximately 16% through 2029; 2026 demand growth 20-22% vs supply 15-17%; no major new fab capacity before late 2027/2028; Kioxia targeting 2x capacity by FY29 | G11: WebSearch results, industry trackers | H11: Tier 3 | I11: Industry tracker consensus; directionally reliable
B12: 8 | C12: 2026 AI-driven NAND/DRAM price spike | D12: TrendForce / Tom's Hardware / Nikkei / Bloomberg | E12: 2026 Q1-Q2 | F12: NAND contract prices +55% to +95% QoQ in 1H26 on AI data-center demand and HBM-driven supply diversion away from NAND | G12: WebSearch results, June 2026 | H12: Tier 3 | I12: Cross-validated against the user-provided file's own Q4 FY26A actual (+189% YoY revenue, 64.1% gross margin)
B13: 9 | C13: Kioxia stock rally / market cap surge narrative | D13: Bloomberg / Nikkei Asia / Yahoo Finance | E13: 2026-02 to 2026-06 | F13: Shares +660% YTD, overtook Toyota as Japan's most valuable listed company, single-quarter net profit guided up approximately 46x YoY | G13: WebSearch results, June 2026 | H13: Tier 3 | I13: Corroborates the magnitude of the re-rating; cross-checked against Ratios-Annual market cap snapshot in source file
B14: 10 | C14: Kioxia FY27E sell-side consensus (revenue/earnings) | D14: Simply Wall St / Yahoo Finance analyst aggregation | E14: Late 2025 / early 2026 | F14: Consensus FY27E revenue/earnings figures found in earlier research were stale relative to the Q4 FY26A actual print; NOT used as a driver anchor | G14: WebSearch result, June 2026 | H14: Weak | I14: Excluded; superseded by the user-provided file's own actual quarterly trend

Sheet WACC
B2: Cost of Capital — Fundamental Build (No Beta)
B4: Cost of Equity, Fundamental Risk Build
B5: Risk-Free Rate (Japan 10Y JGB, 2026-06-02) | C5: 0.0257 | D5: Bloomberg / Investing.com
B6: Equity Risk Premium (Japan, long-run) | C6: 0.06 | D6: Long-run Japan ERP assumption
B7: (+) NAND Cyclicality Premium | C7: 0.03 | D7: Historical revenue/margin swings are extreme - FY24A gross margin was -4.9%, FY26A was 43.3%
B8: (+) Customer Concentration Premium | C8: 0.005 | D8: Top customers concentrated among hyperscalers/OEMs
B9: (+) Capital Intensity / Execution Risk | C9: 0.015 | D9: 12-27% capex intensity range, fab ramp and node-transition risk
B10: (+) China NAND Capacity Risk (YMTC) | C10: 0.01 | D10: Chinese state-backed supply build threat
B11: (-) Scale / Technology Position Discount | C11: -0.005 | D11: BiCS8/9 roadmap, #3 global share, established IP
B12: Cost of Equity (JPY) | C12: =SUM(C5:C11) -> 0.1407
B14: Cost of Debt
B15: Pre-Tax Cost of Debt | C15: 0.055 | D15: Recent issuance / BB-area credit profile
B16: Effective Tax Rate | C16: 0.3 | D16: Japanese statutory rate
B17: After-Tax Cost of Debt | C17: =C15*(1-C16) -> 0.0385
B19: Target Capital Structure
B20: Market Cap (USD mm) | C20: 324388.84
B21: Total Debt (USD mm, FY26A actual) | C21: 7811.5537
B22: Total Capitalization | C22: =C20+C21 -> 332200.4
B23: Weight of Equity | C23: =C20/C22 -> 0.97648542
B24: Weight of Debt | C24: =C21/C22 -> 0.023514583
B26: WACC
B27: WACC (JPY-based) | C27: =C23*C12+C24*C17 -> 0.13829681
B28: (+) USD-JPY Risk-Free Differential | C28: 0.019 | D28: US 10Y (Fed H.15) less JGB 10Y
B29: WACC (USD-equivalent) | C29: =C27+C28 -> 0.15729681
B31: Note: Beta is intentionally excluded.
B32: Fundamental risk factors used instead of beta: (a) NAND demand/price cyclicality (now confirmed extreme by actual history: FY24A gross margin -4.9%, FY26A 43.3%, Q4 FY26A 64.1%), (b) customer concentration among a few hyperscalers/OEMs, (c) capex execution risk on fab ramps and node transitions, (d) Chinese (YMTC) supply threat, offset by an established #3 global share and BiCS IP position. WACC range tested in the scenario engine: 10.0%-19.5%, bracketing this point estimate.

Sheet Scenario Library
B2: Scenario Library — Named Scenarios (selector source)
B3: Select a scenario by name on the Assumptions tab; values below are pulled via INDEX/MATCH.
B5: Scenario Name | C5: demand_peak | D5: demand_trough | E5: demand_exit | F5: supply_peak | G5: supply_trough | H5: supply_exit | I5: share_fy27 | J5: share_fy29 | K5: share_fy31 | L5: asp_peak | M5: asp_trough | N5: asp_exit | O5: gm_peak | P5: gm_trough | Q5: gm_exit | R5: opex_fy27 | S5: opex_fy31 | T5: da_fy27 | U5: da_fy31 | V5: capex_fy27 | W5: capex_fy31 | X5: tax_rate | Y5: nwc_pct | Z5: wacc | AA5: exit_multiple | AB5: terminal_g
B6: Base Case | C6: 0.22 | D6: 0.16 | E6: 0.13 | F6: 0.16 | G6: 0.2 | H6: 0.13 | I6: 0.145 | J6: 0.15 | K6: 0.155 | L6: 0.7 | M6: -0.15 | N6: -0.05 | O6: 0.55 | P6: 0.28 | Q6: 0.33 | R6: 0.075 | S6: 0.11 | T6: 0.134 | U6: 0.16 | V6: 0.18 | W6: 0.145 | X6: 0.293 | Y6: 0.05 | Z6: 0.15729681 | AA6: 5.5 | AB6: 0.025
B7: Low Case (all drivers low) | C7: 0.16 | D7: 0.1 | E7: 0.1 | F7: 0.13 | G7: 0.14 | H7: 0.1 | I7: 0.135 | J7: 0.13 | K7: 0.13 | L7: 0.3 | M7: -0.35 | N7: -0.2 | O7: 0.44 | P7: -0.1 | Q7: 0.24 | R7: 0.055 | S7: 0.09 | T7: 0.11 | U7: 0.14 | V7: 0.12 | W7: 0.11 | X7: 0.27 | Y7: 0.02 | Z7: 0.1 | AA7: 3 | AB7: 0.01
B8: High Case (all drivers high) | C8: 0.32 | D8: 0.22 | E8: 0.18 | F8: 0.22 | G8: 0.26 | H8: 0.18 | I8: 0.155 | J8: 0.165 | K8: 0.18 | L8: 1.4 | M8: 0 | N8: 0.1 | O8: 0.7 | P8: 0.45 | Q8: 0.46 | R8: 0.095 | S8: 0.14 | T8: 0.155 | U8: 0.185 | V8: 0.27 | W8: 0.19 | X8: 0.31 | Y8: 0.09 | Z8: 0.195 | AA8: 14 | AB8: 0.045
B9: Demand-Constrained Downside | C9: 0.16 | D9: 0.1 | E9: 0.1 | F9: 0.16 | G9: 0.2 | H9: 0.13 | I9: 0.145 | J9: 0.15 | K9: 0.155 | L9: 0.1 | M9: -0.35 | N9: -0.18 | O9: 0.46 | P9: -0.05 | Q9: 0.24 | R9: 0.075 | S9: 0.11 | T9: 0.134 | U9: 0.16 | V9: 0.18 | W9: 0.145 | X9: 0.293 | Y9: 0.05 | Z9: 0.15729681 | AA9: 5.5 | AB9: 0.025
B10: Supply-Constrained Upside | C10: 0.22 | D10: 0.16 | E10: 0.13 | F10: 0.13 | G10: 0.14 | H10: 0.1 | I10: 0.145 | J10: 0.15 | K10: 0.155 | L10: 0.32 | M10: -0.05 | N10: 0.02 | O10: 0.55 | P10: 0.35 | Q10: 0.38 | R10: 0.075 | S10: 0.11 | T10: 0.134 | U10: 0.16 | V10: 0.18 | W10: 0.145 | X10: 0.293 | Y10: 0.05 | Z10: 0.15729681 | AA10: 5.5 | AB10: 0.025
B11: Margin Compression Stress | C11: 0.22 | D11: 0.16 | E11: 0.13 | F11: 0.22 | G11: 0.26 | H11: 0.18 | I11: 0.145 | J11: 0.15 | K11: 0.155 | L11: 0.7 | M11: -0.35 | N11: -0.05 | O11: 0.55 | P11: -0.08 | Q11: 0.22 | R11: 0.075 | S11: 0.11 | T11: 0.134 | U11: 0.16 | V11: 0.18 | W11: 0.145 | X11: 0.293 | Y11: 0.05 | Z11: 0.15729681 | AA11: 5.5 | AB11: 0.025
B12: Margin Expansion Bull | C12: 0.22 | D12: 0.16 | E12: 0.13 | F12: 0.16 | G12: 0.2 | H12: 0.13 | I12: 0.145 | J12: 0.15 | K12: 0.155 | L12: 0.7 | M12: -0.15 | N12: -0.05 | O12: 0.59 | P12: 0.37 | Q12: 0.4 | R12: 0.075 | S12: 0.1 | T12: 0.134 | U12: 0.16 | V12: 0.18 | W12: 0.145 | X12: 0.293 | Y12: 0.05 | Z12: 0.15729681 | AA12: 5.5 | AB12: 0.025
B13: High CapEx Share-Gain Case | C13: 0.22 | D13: 0.16 | E13: 0.13 | F13: 0.16 | G13: 0.2 | H13: 0.13 | I13: 0.15 | J13: 0.16 | K13: 0.18 | L13: 0.7 | M13: -0.15 | N13: -0.05 | O13: 0.55 | P13: 0.28 | Q13: 0.33 | R13: 0.075 | S13: 0.11 | T13: 0.134 | U13: 0.16 | V13: 0.27 | W13: 0.19 | X13: 0.293 | Y13: 0.05 | Z13: 0.15729681 | AA13: 5.5 | AB13: 0.025
B14: Low CapEx Harvest Case | C14: 0.22 | D14: 0.16 | E14: 0.13 | F14: 0.16 | G14: 0.2 | H14: 0.13 | I14: 0.145 | J14: 0.15 | K14: 0.13 | L14: 0.7 | M14: -0.15 | N14: -0.05 | O14: 0.55 | P14: 0.28 | Q14: 0.33 | R14: 0.075 | S14: 0.11 | T14: 0.134 | U14: 0.16 | V14: 0.12 | W14: 0.11 | X14: 0.293 | Y14: 0.05 | Z14: 0.15729681 | AA14: 5.5 | AB14: 0.025
B15: Working Capital Stress Case | C15: 0.3 | D15: 0.2 | E15: 0.13 | F15: 0.16 | G15: 0.2 | H15: 0.13 | I15: 0.145 | J15: 0.15 | K15: 0.155 | L15: 0.7 | M15: -0.15 | N15: -0.05 | O15: 0.55 | P15: 0.28 | Q15: 0.33 | R15: 0.075 | S15: 0.11 | T15: 0.134 | U15: 0.16 | V15: 0.18 | W15: 0.145 | X15: 0.293 | Y15: 0.09 | Z15: 0.15729681 | AA15: 5.5 | AB15: 0.025
B16: Rich Terminal Multiple Case | C16: 0.22 | D16: 0.16 | E16: 0.13 | F16: 0.16 | G16: 0.2 | H16: 0.13 | I16: 0.145 | J16: 0.15 | K16: 0.155 | L16: 0.7 | M16: -0.15 | N16: -0.05 | O16: 0.55 | P16: 0.28 | Q16: 0.33 | R16: 0.075 | S16: 0.11 | T16: 0.134 | U16: 0.16 | V16: 0.18 | W16: 0.145 | X16: 0.293 | Y16: 0.05 | Z16: 0.15729681 | AA16: 8 | AB16: 0.04
B17: Cheap Terminal Multiple Case | C17: 0.22 | D17: 0.16 | E17: 0.13 | F17: 0.16 | G17: 0.2 | H17: 0.13 | I17: 0.145 | J17: 0.15 | K17: 0.155 | L17: 0.7 | M17: -0.15 | N17: -0.05 | O17: 0.55 | P17: 0.28 | Q17: 0.33 | R17: 0.075 | S17: 0.11 | T17: 0.134 | U17: 0.16 | V17: 0.18 | W17: 0.145 | X17: 0.293 | Y17: 0.05 | Z17: 0.15729681 | AA17: 3 | AB17: 0.01
... B21: Stacked-Unfavorable Mixed Bear | C21: 0.16 | D21: 0.1 | E21: 0.1 | F21: 0.22 | G21: 0.26 | H21: 0.13 | I21: 0.145 | J21: 0.15 | K21: 0.13 | L21: 0.7 | M21: -0.35 | N21: -0.05 | O21: 0.44 | P21: -0.1 | Q21: 0.22 | R21: 0.075 | S21: 0.11 | T21: 0.134 | U21: 0.16 | V21: 0.27 | W21: 0.145 | X21: 0.293 | Y21: 0.05 | Z21: 0.195 | AA21: 3 | AB21: 0.01

Sheet Assumptions
B2: Assumptions — Driver Inputs (Scenario-Selectable)
B4: Scenario Selector: | C4: Base Case | D4: <- choose a named scenario; Model tab recalculates automatically
B6: Driver | C6: Low | D6: Base | E6: High | F6: Active (Selected Scenario) | G6: Source / Economic Rationale
B7: Industry Bit Demand Growth — FY27 Peak (YoY) | C7: 0.16 | D7: 0.22 | E7: 0.32 | F7: =INDEX('Scenario Library'!$C$6:$C$21,MATCH($C$4,'Scenario Library'!$B$6:$B$21,0)) -> 0.22 | G7: TrendForce/IDC industry trackers; AI data-center build-out
B8: Industry Bit Demand Growth — FY29 Trough (YoY) | C8: 0.1 | D8: 0.16 | E8: 0.22 | F8: =INDEX('Scenario Library'!$D$6:$D$21,MATCH($C$4,'Scenario Library'!$B$6:$B$21,0)) -> 0.16 | G8: Mean reversion after initial AI-driven spike
B9: Industry Bit Demand Growth — FY31 Exit (YoY) | C9: 0.1 | D9: 0.13 | E9: 0.18 | F9: =INDEX('Scenario Library'!$E$6:$E$21,MATCH($C$4,'Scenario Library'!$B$6:$B$21,0)) -> 0.13 | G9: Long-run bit-CAGR consensus ~13-16%
B10: Industry Bit Supply Growth — FY27 Peak (YoY) | C10: 0.13 | D10: 0.16 | E10: 0.22 | F10: =INDEX('Scenario Library'!$F$6:$F$21,MATCH($C$4,'Scenario Library'!$B$6:$B$21,0)) -> 0.16 | G10: Capacity additions lag; no major new fab online before late FY28
B11: Industry Bit Supply Growth — FY29 Trough (YoY) | C11: 0.14 | D11: 0.2 | E11: 0.26 | F11: =INDEX('Scenario Library'!$G$6:$G$21,MATCH($C$4,'Scenario Library'!$B$6:$B$21,0)) -> 0.2 | G11: Catch-up capacity from 2x-by-FY29 plans across industry
B12: Industry Bit Supply Growth — FY31 Exit (YoY) | C12: 0.1 | D12: 0.13 | E12: 0.18 | F12: =INDEX('Scenario Library'!$H$6:$H$21,MATCH($C$4,'Scenario Library'!$B$6:$B$21,0)) -> 0.13 | G12: Normalization toward long-run capacity growth
B13: Kioxia Bit Market Share — FY27 | C13: 0.135 | D13: 0.145 | E13: 0.155 | F13: =INDEX('Scenario Library'!$I$6:$I$21,MATCH($C$4,'Scenario Library'!$B$6:$B$21,0)) -> 0.145 | G13: Current ~13.5-14.5% share (industry tracker), #3 global supplier
B14: Kioxia Bit Market Share — FY29 | C14: 0.13 | D14: 0.15 | E14: 0.165 | F14: =INDEX('Scenario Library'!$J$6:$J$21,MATCH($C$4,'Scenario Library'!$B$6:$B$21,0)) -> 0.15 | G14: Share path under capacity investment plan
B15: Kioxia Bit Market Share — FY31 | C15: 0.13 | D15: 0.155 | E15: 0.18 | F15: =INDEX('Scenario Library'!$K$6:$K$21,MATCH($C$4,'Scenario Library'!$B$6:$B$21,0)) -> 0.155 | G15: Upper bound capped at an 18% physical/competitive ceiling
B16: NAND ASP % YoY — FY27 Peak | C16: 0.3 | D16: 0.7 | E16: 1.4 | F16: =INDEX('Scenario Library'!$L$6:$L$21,MATCH($C$4,'Scenario Library'!$B$6:$B$21,0)) -> 0.7 | G16: Sourced 2026 supercycle: NAND contract prices +55% to +95% QoQ; user file's own Q4 FY26A revenue was +189% YoY
B17: NAND ASP % YoY — FY29 Trough | C17: -0.35 | D17: -0.15 | E17: 0 | F17: =INDEX('Scenario Library'!$M$6:$M$21,MATCH($C$4,'Scenario Library'!$B$6:$B$21,0)) -> -0.15 | G17: Historical post-shortage price correction pattern
B18: NAND ASP % YoY — FY31 Exit | C18: -0.2 | D18: -0.05 | E18: 0.1 | F18: =INDEX('Scenario Library'!$N$6:$N$21,MATCH($C$4,'Scenario Library'!$B$6:$B$21,0)) -> -0.05 | G18: Partial normalization toward long-run price-decline trend
B19: Gross Margin — FY27 Peak | C19: 0.44 | D19: 0.55 | E19: 0.7 | F19: =INDEX('Scenario Library'!$O$6:$O$21,MATCH($C$4,'Scenario Library'!$B$6:$B$21,0)) -> 0.55 | G19: User file's own Q4 FY26A actual was 64.1%; largely fixed/fab-amortized cost base amplifies margin in shortage
B20: Gross Margin — FY29 Trough | C20: -0.1 | D20: 0.28 | E20: 0.45 | F20: =INDEX('Scenario Library'!$P$6:$P$21,MATCH($C$4,'Scenario Library'!$B$6:$B$21,0)) -> 0.28 | G20: Floor set by user file's own FY24A actual trough of -4.9%
B21: Gross Margin — FY31 Exit | C21: 0.24 | D21: 0.33 | E21: 0.46 | F21: =INDEX('Scenario Library'!$Q$6:$Q$21,MATCH($C$4,'Scenario Library'!$B$6:$B$21,0)) -> 0.33 | G21: Structural margin versus FY26A actual (43.3%) on mix
B22: Opex % of Revenue — FY27 | C22: 0.055 | D22: 0.075 | E22: 0.095 | F22: =INDEX('Scenario Library'!$R$6:$R$21,MATCH($C$4,'Scenario Library'!$B$6:$B$21,0)) -> 0.075 | G22: FY26A actual was 6.3% of revenue (SG&A only; R&D reported as $0 in FY26A)
B23: Opex % of Revenue — FY31 | C23: 0.09 | D23: 0.11 | E23: 0.14 | F23: =INDEX('Scenario Library'!$S$6:$S$21,MATCH($C$4,'Scenario Library'!$B$6:$B$21,0)) -> 0.11 | G23: Normalized opex ratio as revenue growth decelerates
B24: D&A % of Revenue — FY27 | C24: 0.11 | D24: 0.134 | E24: 0.155 | F24: =INDEX('Scenario Library'!$T$6:$T$21,MATCH($C$4,'Scenario Library'!$B$6:$B$21,0)) -> 0.134 | G24: FY26A actual was 13.4% of revenue
B25: D&A % of Revenue — FY31 | C25: 0.14 | D25: 0.16 | E25: 0.185 | F25: =INDEX('Scenario Library'!$U$6:$U$21,MATCH($C$4,'Scenario Library'!$B$6:$B$21,0)) -> 0.16 | G25: Rises as capacity build-out depreciation phases in
B26: Capex % of Revenue — FY27 | C26: 0.12 | D26: 0.18 | E26: 0.27 | F26: =INDEX('Scenario Library'!$V$6:$V$21,MATCH($C$4,'Scenario Library'!$B$6:$B$21,0)) -> 0.18 | G26: FY26A actual was 12.0% of revenue; capacity build continues
B27: Capex % of Revenue — FY31 | C27: 0.11 | D27: 0.145 | E27: 0.19 | F27: =INDEX('Scenario Library'!$W$6:$W$21,MATCH($C$4,'Scenario Library'!$B$6:$B$21,0)) -> 0.145 | G27: Capex intensity normalizes post capacity-doubling plan (2x by FY29)
B28: Effective Tax Rate | C28: 0.27 | D28: 0.293 | E28: 0.31 | F28: =INDEX('Scenario Library'!$X$6:$X$21,MATCH($C$4,'Scenario Library'!$B$6:$B$21,0)) -> 0.293 | G28: FY26A actual effective rate was 29.3%
B29: Net Working Capital Investment, % of Δ Revenue | C29: 0.02 | D29: 0.05 | E29: 0.09 | F29: =INDEX('Scenario Library'!$Y$6:$Y$21,MATCH($C$4,'Scenario Library'!$B$6:$B$21,0)) -> 0.05 | G29: Funds receivables/inventory build as revenue scales
B30: WACC, USD-equivalent | C30: 0.1 | D30: 0.15729681 | E30: 0.195 | F30: =INDEX('Scenario Library'!$Z$6:$Z$21,MATCH($C$4,'Scenario Library'!$B$6:$B$21,0)) -> 0.15729681 | G30: Fundamental build derived on WACC tab (=WACC!C29 base case); independently scenario-ranged 10.0%-19.5% above
B31: Terminal Exit EV/EBITDA Multiple | C31: 3 | D31: 5.5 | E31: 14 | F31: =INDEX('Scenario Library'!$AA$6:$AA$21,MATCH($C$4,'Scenario Library'!$B$6:$B$21,0)) -> 5.5 | G31: User file's own FYE Mar-26 EV/EBITDA was 9.4x on FY26A EBITDA (already including the Q4 spike); range allows further AI-cycle peer re-rating
B32: Terminal Growth Rate (Gordon Growth) | C32: 0.01 | D32: 0.025 | E32: 0.045 | F32: =INDEX('Scenario Library'!$AB$6:$AB$21,MATCH($C$4,'Scenario Library'!$B$6:$B$21,0)) -> 0.025 | G32: Mature commodity memory business; capped near nominal GDP+

Sheet Model
B2: Model — Active Scenario (selector on Assumptions tab)
B3: All figures in $mm except per-share and EB/ASP rows. Active scenario shown in Assumptions!C4.
B5: Fiscal Year | C5: FY26A | D5: FY27E | E5: FY28E | F5: FY29E | G5: FY30E | H5: FY31E
B7: Bottom-Up Bit-Shipment x ASP Revenue Build
B8: Industry Bit Demand Growth (YoY %) | D8: =Assumptions!$F$7 -> 0.22 | E8: =AVERAGE(D8,F8) -> 0.19 | F8: =Assumptions!$F$8 -> 0.16 | G8: =AVERAGE(F8,H8) -> 0.145 | H8: =Assumptions!$F$9 -> 0.13
B9: Industry Bit Shipments (EB) | C9: 850 | D9: =C9*(1+D8) -> 1037 | E9: =D9*(1+E8) -> 1234.03 | F9: =E9*(1+F8) -> 1431.4748 | G9: =F9*(1+G8) -> 1639.0386 | H9: =G9*(1+H8) -> 1852.1137
B10: Industry Bit Supply Growth (YoY %, memo) | D10: =Assumptions!$F$10 -> 0.16 | E10: =AVERAGE(D10,F10) -> 0.18 | F10: =Assumptions!$F$11 -> 0.2 | G10: =AVERAGE(F10,H10) -> 0.165 | H10: =Assumptions!$F$12 -> 0.13
B11: Kioxia Bit Market Share | C11: 0.135 | D11: =Assumptions!$F$13 -> 0.145 | E11: =AVERAGE(D11,F11) -> 0.1475 | F11: =Assumptions!$F$14 -> 0.15 | G11: =AVERAGE(F11,H11) -> 0.1525 | H11: =Assumptions!$F$15 -> 0.155
B12: Kioxia Bit Shipments (EB) | C12: =C9*C11 -> 114.75 | D12: =D9*D11 -> 150.365 | E12: =E9*E11 -> 182.01942 | F12: =F9*F11 -> 214.72122 | G12: =G9*G11 -> 249.95339 | H12: =H9*H11 -> 287.07762
B13: NAND ASP, YoY % Change | D13: =Assumptions!$F$16 -> 0.7 | E13: =AVERAGE(D13,F13) -> 0.275 | F13: =Assumptions!$F$17 -> -0.15 | G13: =AVERAGE(F13,H13) -> -0.1 | H13: =Assumptions!$F$18 -> -0.05
B14: NAND ASP ($/GB-equivalent) | C14: 116.82381 | D14: =C14*(1+D13) -> 198.60048 | E14: =D14*(1+E13) -> 253.21562 | F14: =E14*(1+F13) -> 215.23327 | G14: =F14*(1+G13) -> 193.70995 | H14: =G14*(1+H13) -> 184.02445
B15: NAND Revenue ($mm) | C15: =C12*C14 -> 13405.533 | D15: =D12*D14 -> 29862.562 | E15: =E12*E14 -> 46090.161 | F15: =F12*F14 -> 46215.151 | G15: =G12*G14 -> 48418.458 | H15: =H12*H14 -> 52829.301
B16: Other Revenue ($mm) | C16: 1165.6985 | D16: =$C$16 -> 1165.6985 | E16: =$C$16 -> 1165.6985 | F16: =$C$16 -> 1165.6985 | G16: =$C$16 -> 1165.6985 | H16: =$C$16 -> 1165.6985
B17: Total Revenue ($mm) | C17: =C15+C16 -> 14571.231 | D17: =D15+D16 -> 31028.26 | E17: =E15+E16 -> 47255.859 | F17: =F15+F16 -> 47380.85 | G17: =G15+G16 -> 49584.157 | H17: =H15+H16 -> 53994.999
B18: Revenue Growth (YoY %) | D18: =D17/C17-1 -> 1.1294193 | E18: =E17/D17-1 -> 0.52299417 | F18: =F17/E17-1 -> 0.0026449687 | G18: =G17/F17-1 -> 0.046502065 | H18: =H17/G17-1 -> 0.088956684
B20: Income Statement ($mm)
B21: Gross Margin % | C21: 0.43330419 | D21: =Assumptions!$F$19 -> 0.55 | E21: =AVERAGE(D21,F21) -> 0.415 | F21: =Assumptions!$F$20 -> 0.28 | G21: =AVERAGE(F21,H21) -> 0.305 | H21: =Assumptions!$F$21 -> 0.33
B22: Gross Profit ($mm) | C22: =C17*C21 -> 6313.7754 | D22: =D17*D21 -> 17065.543 | E22: =E17*E21 -> 19611.182 | F22: =F17*F21 -> 13266.638 | G22: =G17*G21 -> 15123.168 | H22: =H17*H21 -> 17818.35
B23: Operating Expenses % of Revenue | C23: 0.062705016 | D23: =Assumptions!$F$22 -> 0.075 | E23: =D23+(H23-D23)*1/4 -> 0.08375 | F23: =D23+(H23-D23)*2/4 -> 0.0925 | G23: =D23+(H23-D23)*3/4 -> 0.10125 | H23: =Assumptions!$F$23 -> 0.11
B24: Operating Expenses ($mm) | C24: =C17*C23 -> 913.68927 | D24: =D17*D23 -> 2327.1195 | E24: =E17*E23 -> 3957.6782 | F24: =F17*F23 -> 4382.7286 | G24: =G17*G23 -> 5020.3959 | H24: =H17*H23 -> 5939.4499
B25: EBIT ($mm) | C25: =C22-C24 -> 5400.0862 | D25: =D22-D24 -> 14738.424 | E25: =E22-E24 -> 15653.503 | F25: =F22-F24 -> 8883.9093 | G25: =G22-G24 -> 10102.772 | H25: =H22-H24 -> 11878.9
B26: EBIT Margin % | C26: =C25/C17 -> 0.37059917 | D26: =D25/D17 -> 0.475 | E26: =E25/E17 -> 0.33125 | F26: =F25/F17 -> 0.1875 | G26: =G25/G17 -> 0.20375 | H26: =H25/H17 -> 0.22
B27: Effective Tax Rate | C27: 0.29282039 | D27: =Assumptions!$F$28 -> 0.293 | E27: =Assumptions!$F$28 -> 0.293 | F27: =Assumptions!$F$28 -> 0.293 | G27: =Assumptions!$F$28 -> 0.293 | H27: =Assumptions!$F$28 -> 0.293
B28: (-) Taxes on EBIT | C28: =-C25*C27 -> -1581.2553 | D28: =-D25*D27 -> -4318.3581 | E28: =-E25*E27 -> -4586.4765 | F28: =-F25*F27 -> -2602.9854 | G28: =-G25*G27 -> -2960.1122 | H28: =-H25*H27 -> -3480.5176
B29: NOPAT ($mm) | C29: =C25+C28 -> 3818.8309 | D29: =D25+D28 -> 10420.065 | E29: =E25+E28 -> 11067.027 | F29: =F25+F28 -> 6280.9239 | G29: =G25+G28 -> 7142.6598 | H29: =H25+H28 -> 8398.3822
B31: Unlevered Free Cash Flow Bridge ($mm)
B32: D&A % of Revenue | C32: 0.13382198 | D32: =Assumptions!$F$24 -> 0.134 | E32: =D32+(H32-D32)*1/4 -> 0.1405 | F32: =D32+(H32-D32)*2/4 -> 0.147 | G32: =D32+(H32-D32)*3/4 -> 0.1535 | H32: =Assumptions!$F$25 -> 0.16
B33: (+) D&A ($mm) | C33: =C17*C32 -> 1949.951 | D33: =D17*D32 -> 4157.7869 | E33: =E17*E32 -> 6639.4482 | F33: =F17*F32 -> 6964.9849 | G33: =G17*G32 -> 7611.1681 | H33: =H17*H32 -> 8639.1999
B34: Capex % of Revenue | C34: 0.12023384 | D34: =Assumptions!$F$26 -> 0.18 | E34: =D34+(H34-D34)*1/4 -> 0.17125 | F34: =D34+(H34-D34)*2/4 -> 0.1625 | G34: =D34+(H34-D34)*3/4 -> 0.15375 | H34: =Assumptions!$F$27 -> 0.145
B35: (-) Capex ($mm) | C35: =-C17*C34 -> -1751.9551 | D35: =-D17*D34 -> -5585.0868 | E35: =-E17*E34 -> -8092.5659 | F35: =-F17*F34 -> -7699.3881 | G35: =-G17*G34 -> -7623.5641 | H35: =-H17*H34 -> -7829.2749
B36: Δ Revenue ($mm) | D36: =D17-C17 -> 16457.029 | E36: =E17-D17 -> 16227.599 | F36: =F17-E17 -> 124.99027 | G36: =G17-F17 -> 2203.3073 | H36: =H17-G17 -> 4410.8422
B37: NWC Investment, % of Δ Revenue | D37: =Assumptions!$F$29 -> 0.05 | E37: =Assumptions!$F$29 -> 0.05 | F37: =Assumptions!$F$29 -> 0.05 | G37: =Assumptions!$F$29 -> 0.05 | H37: =Assumptions!$F$29 -> 0.05
B38: (-) Δ Net Working Capital ($mm) | D38: =-D36*D37 -> -822.85145 | E38: =-E36*E37 -> -811.37996 | F38: =-F36*F37 -> -6.2495133 | G38: =-G36*G37 -> -110.16537 | H38: =-H36*H37 -> -220.54211
B39: Unlevered FCF ($mm) | D39: =D29+D33+D35+D38 -> 8169.914 | E39: =E29+E33+E35+E38 -> 8802.5293 | F39: =F29+F33+F35+F38 -> 5540.2712 | G39: =G29+G33+G35+G38 -> 7020.0984 | H39: =H29+H33+H35+H38 -> 8987.765
B40: FCF Margin % | D40: =D39/D17 -> 0.26330558 | E40: =E39/E17 -> 0.18627382 | F40: =F39/F17 -> 0.1169306 | G40: =G39/G17 -> 0.14157946 | H40: =H39/H17 -> 0.16645551
B42: Present Value Calculation
B43: WACC (USD) | D43: =Assumptions!$F$30 -> 0.15729681 | E43: =Assumptions!$F$30 -> 0.15729681 | F43: =Assumptions!$F$30 -> 0.15729681 | G43: =Assumptions!$F$30 -> 0.15729681 | H43: =Assumptions!$F$30 -> 0.15729681
B44: Discount Period (mid-year) | C44: 0 | D44: 0.5 | E44: 1.5 | F44: 2.5 | G44: 3.5 | H44: 4.5
B45: Discount Factor | D45: =1/(1+D43)^D44 -> 0.92956042 | E45: =1/(1+E43)^E44 -> 0.80321695 | F45: =1/(1+F43)^F44 -> 0.69404577 | G45: =1/(1+G43)^G44 -> 0.59971285 | H45: =1/(1+H43)^H44 -> 0.51820142
B46: PV of UFCF ($mm) | D46: =D39*D45 -> 7594.4287 | E46: =E39*E45 -> 7070.3407 | F46: =F39*F45 -> 3845.2018 | G46: =G39*G45 -> 4210.0432 | H46: =H39*H45 -> 4657.4726
...

Sheet Summary
B2: Summary — Full Scenario Log (All Scenarios Run)
B3: Total scenarios logged: 2000. All valuation figures in USD.
B5: Scenario # | C5: Name | D5: Demand Peak | E5: ASP Peak YoY | F5: GM Peak | G5: GM Exit | H5: Capex FY27 | I5: Exit Multiple | J5: Terminal g | K5: WACC | L5: Implied Price (USD) | M5: % Diff vs Current | N5: Within +/-5% | O5: Market Fit Score | P5: Probability Score | Q5: Classification | R5: Rejection Reason | S5: Market-Priced Candidate | T5: Most-Likely Candidate
B6: 1 | C6: Base Case | D6: 0.22 | E6: 0.7 | F6: 0.55 | G6: 0.33 | H6: 0.18 | I6: 5.5 | J6: 0.025 | K6: 0.15729681 | L6: 127.00051 | M6: -0.78488215 | N6: No | O6: 3.9070708 | P6: 94.237043 | Q6: Probable | R6: - | S6: No | T6: Yes
B7: 2 | C7: Low Case (all drivers low) | D7: 0.16 | E7: 0.3 | F7: 0.44 | G7: 0.24 | H7: 0.12 | I7: 3 | J7: 0.01 | K7: 0.1 | L7: 20.856984 | M7: -0.96467172 | N7: No | O7: 0 | P7: 34.960251 | Q7: Plausible-Weak | R7: Plausible but probability score <50; weak evidence support | S7: No | T7: No
B8: 3 | C8: High Case (all drivers high) | D8: 0.32 | E8: 1.4 | F8: 0.7 | G8: 0.46 | H8: 0.27 | I8: 14 | J8: 0.045 | K8: 0.195 | L8: 974.01892 | M8: 0.64982681 | N8: No | O8: 12.010392 | P8: 0 | Q8: Implausible | R8: Stacks both an extreme peak AND an extreme trough margin without evidence of structural cost change; Stacks a >95% YoY ASP spike with no subsequent give-back, ignoring memory's historical post-shortage price correction pattern | S8: No | T8: No
B9: 4 | C9: Demand-Constrained Downside | D9: 0.16 | E9: 0.1 | F9: 0.46 | G9: 0.24 | H9: 0.18 | I9: 5.5 | J9: 0.025 | K9: 0.15729681 | L9: 12.245518 | M9: -0.97925812 | N9: No | O9: 0 | P9: 56.646434 | Q9: Plausible-Uncertain | R9: Plausible but probability score 50-74; insufficient evidence concentration to call Probable | S9: No | T9: No
B10: 5 | C10: Supply-Constrained Upside | D10: 0.22 | E10: 0.32 | F10: 0.55 | G10: 0.38 | H10: 0.18 | I10: 5.5 | J10: 0.025 | K10: 0.15729681 | L10: 128.06448 | M10: -0.78307997 | N10: No | O10: 4.0152017 | P10: 72.899671 | Q10: Plausible-Uncertain | R10: Plausible but probability score 50-74; insufficient evidence concentration to call Probable | S10: No | T10: No
B11: 6 | C11: Margin Compression Stress | D11: 0.22 | E11: 0.7 | F11: 0.55 | G11: 0.22 | H11: 0.18 | I11: 5.5 | J11: 0.025 | K11: 0.15729681 | L11: 40.96983 | M11: -0.93060389 | N11: No | O11: 0 | P11: 54.377189 | Q11: Plausible-Uncertain | R11: Plausible but probability score 50-74; insufficient evidence concentration to call Probable | S11: No | T11: No
B12: 7 | C12: Margin Expansion Bull | D12: 0.22 | E12: 0.7 | F12: 0.59 | G12: 0.4 | H12: 0.18 | I12: 5.5 | J12: 0.025 | K12: 0.15729681 | L12: 164.3902 | M12: -0.72155021 | N12: No | O12: 7.7069872 | P12: 86.514336 | Q12: Probable | R12: - | S12: No | T12: Yes
B13: 8 | C13: High CapEx Share-Gain Case | D13: 0.22 | E13: 0.7 | F13: 0.55 | G13: 0.33 | H13: 0.27 | I13: 5.5 | J13: 0.025 | K13: 0.15729681 | L13: 112.3512 | M13: -0.80969567 | N13: No | O13: 2.4182599 | P13: 67.101067 | Q13: Plausible-Uncertain | R13: Plausible but probability score 50-74; insufficient evidence concentration to call Probable | S13: No | T13: No
B14: 9 | C14: Low CapEx Harvest Case | D14: 0.22 | E14: 0.7 | F14: 0.55 | G14: 0.33 | H14: 0.12 | I14: 5.5 | J14: 0.025 | K14: 0.15729681 | L14: 131.63822 | M14: -0.77702665 | N14: No | O14: 4.3784008 | P14: 75.048251 | Q14: Probable | R14: - | S14: No | T14: No
B15: 10 | C15: Working Capital Stress Case | D15: 0.3 | E15: 0.7 | F15: 0.55 | G15: 0.33 | H15: 0.18 | I15: 5.5 | J15: 0.025 | K15: 0.15729681 | L15: 144.27934 | M15: -0.75561468 | N15: No | O15: 5.6631195 | P15: 77.425666 | Q15: Probable | R15: - | S15: No | T15: No
B16: 11 | C16: Rich Terminal Multiple Case | D16: 0.22 | E16: 0.7 | F16: 0.55 | G16: 0.33 | H16: 0.18 | I16: 8 | J16: 0.04 | K16: 0.15729681 | L16: 155.93016 | M16: -0.73588012 | N16: No | O16: 6.8471929 | P16: 83.757109 | Q16: Probable | R16: - | S16: No | T16: Yes
B17: 12 | C17: Cheap Terminal Multiple Case | D17: 0.22 | E17: 0.7 | F17: 0.55 | G17: 0.33 | H17: 0.18 | I17: 3 | J17: 0.01 | K17: 0.15729681 | L17: 99.036497 | M17: -0.83224857 | N17: No | O17: 1.0650859 | P17: 83.757109 | Q17: Probable | R17: - | S17: No | T17: Yes
... B2005: 2000 | C2005: Random Scenario 1984 | D2005: 0.23727502 | E2005: 1.2774065 | F2005: 0.56941732 | G2005: 0.25131514 | H2005: 0.26529369 | I2005: 6.3990467 | J2005: 0.044485315 | K2005: 0.10432712 | L2005: 124.6699 | M2005: -0.78882982 | N2005: No | O2005: 3.6702106 | P2005: 44.360573 | Q2005: Plausible-Weak | R2005: Plausible but probability score <50; weak evidence support | S2005: No | T2005: No

Sheet 3 Ps Filter
B2: 3 Ps Filter — Possible, Plausible, Probable
B4: Filter Funnel (All Scenarios)
B5: Total Scenarios Run | D5: 2000
B6: Rejected — Impossible (fails Possible test) | D6: 0
B7: Remaining after Possible test | D7: 2000
B8: Rejected — Implausible (fails Plausible test) | D8: 427
B9: Remaining after Plausible test | D9: 1573
B10: — Classified Probable (score >= 75) | D10: 8
B11: — Classified Plausible-Uncertain (score 50-74) | D11: 1380
B12: — Classified Plausible-Weak (score < 50) | D12: 185
B14: Near-Stock-Price Scenarios (within +/-5%) — 3 Ps Outcome
B15: Scenario # | C15: Implied Price (USD) | D15: % Diff | E15: Classification | F15: Rejection Reason (if any) | G15: Survives to Market-Priced Candidate?
B16: 32 | C16: 567.38979 | D16: -0.038935626 | E16: Plausible-Weak | F16: Plausible but probability score <50; weak evidence support | G16: Yes
B17: 86 | C17: 574.25395 | D17: -0.027308864 | E17: Plausible-Weak | F17: Plausible but probability score <50; weak evidence support | G17: Yes
B18: 158 | C18: 582.24761 | D18: -0.013768937 | E18: Implausible | F18: Capex below D&A while share still rising contradicts disclosed 2x-capacity-by-FY29 plan | G18: No
B19: 171 | C19: 560.87535 | D19: -0.049969999 | E19: Implausible | F19: Stacks a >95% YoY ASP spike with no subsequent give-back, ignoring memory's historical post-shortage price correction pattern | G19: No
B20: 298 | C20: 575.78736 | D20: -0.024711536 | E20: Implausible | F20: Stacks a >95% YoY ASP spike with no subsequent give-back, ignoring memory's historical post-shortage price correction pattern | G20: No
B21: 467 | C21: 577.69684 | D21: -0.021477177 | E21: Implausible | F21: Capex below D&A while share still rising contradicts disclosed 2x-capacity-by-FY29 plan | G21: No
B22: 496 | C22: 569.63959 | D22: -0.035124827 | E22: Implausible | F22: Stacks a >95% YoY ASP spike with no subsequent give-back, ignoring memory's historical post-shortage price correction pattern | G22: No
B23: 789 | C23: 573.61241 | D23: -0.028395536 | E23: Implausible | F23: Capex below D&A while share still rising contradicts disclosed 2x-capacity-by-FY29 plan; Stacks a >95% YoY ASP spike with no subsequent give-back, ignoring memory's historical post-shortage price correction pattern | G23: No
B24: 813 | C24: 590.01612 | D24: -0.00061036517 | E24: Implausible | F24: Stacks both an extreme peak AND an extreme trough margin without evidence of structural cost change; Stacks a >95% YoY ASP spike with no subsequent give-back, ignoring memory's historical post-shortage price correction pattern | G24: No
B25: 1016 | C25: 569.31849 | D25: -0.035668727 | E25: Implausible | F25: Capex below D&A while share still rising contradicts disclosed 2x-capacity-by-FY29 plan | G25: No
B26: 1240 | C26: 577.81682 | D26: -0.021273964 | E26: Plausible-Uncertain | F26: Plausible but probability score 50-74; insufficient evidence concentration to call Probable | G26: Yes
B27: 1478 | C27: 563.25743 | D27: -0.045935149 | E27: Plausible-Uncertain | F27: Plausible but probability score 50-74; insufficient evidence concentration to call Probable | G27: Yes
... B29: 1625 | C29: 598.46393 | D29: 0.013698827 | E29: Implausible | F29: Stacks a >95% YoY ASP spike with no subsequent give-back, ignoring memory's historical post-shortage price correction pattern | G29: No
B31: High-Probability Candidates (score >= 75) — All Pass Possible+Plausible
B32: Scenario # | C32: Name | D32: Implied Price (USD) | E32: % Diff vs Current | F32: Probability Score | G32: Most-Likely Candidate?
B33: 1 | C33: Base Case | D33: 127.00051 | E33: -0.78488215 | F33: 94.237043 | G33: Yes
B34: 14 | C34: WACC Sensitivity - High Discount Rate | D34: 108.21777 | E34: -0.81669701 | F34: 87.779296 | G34: Yes
B35: 7 | C35: Margin Expansion Bull | D35: 164.3902 | E35: -0.72155021 | F35: 86.514336 | G35: Yes
B36: 11 | C36: Rich Terminal Multiple Case | D36: 155.93016 | E36: -0.73588012 | F36: 83.757109 | G36: Yes
B37: 12 | C37: Cheap Terminal Multiple Case | D37: 99.036497 | E37: -0.83224857 | F37: 83.757109 | G37: Yes
B38: 13 | C38: WACC Sensitivity - Low Discount Rate | D38: 178.74898 | E38: -0.69722882 | F38: 81.828784 | G38: No
B39: 10 | C39: Working Capital Stress Case | D39: 144.27934 | E39: -0.75561468 | F39: 77.425666 | G39: No
B40: 9 | C40: Low CapEx Harvest Case | D40: 131.63822 | E40: -0.77702665 | F40: 75.048251 | G40: No
B42: Final Candidates
B43: Market-Priced Candidates (top, by fit score, passing Possible+Plausible)
B44: #1240 Random Scenario 1224 — $577.82 (-2.1%), Plausible-Uncertain, fit 90.9, prob 50.7
B45: #86 Random Scenario 70 — $574.25 (-2.7%), Plausible-Weak, fit 88.6, prob 46.4
B46: #32 Random Scenario 16 — $567.39 (-3.9%), Plausible-Weak, fit 84.2, prob 47.5
...
