Workbook

Sheet Stress Test Log
A1: MercadoLibre (MELI) | Assumption Stress Test - changed to best-fit real-life case
A2: Source: MELI Q4 2025 8-K (filed Feb 24 2026) and Q1 2026 results (May 7 2026). Edited cells = Probable (active) case and Valuation inputs.
A4: Item | B4: Driver | C4: Old | D4: New | E4: Why (real-life anchor)
A5: BASE ANCHORS (2025A)
A6: Fintech take rate | B6: B19 | C6: 4.58% | D6: 4.54% | E6: Mercado Pago rev $12.6bn / TPV $277.8bn = 4.54%
A7: Credit portfolio | B7: B23 | C7: $13,000mm | D7: $12,500mm | E7: Reported FY25 credit book = $12.5bn (+90% YoY)
A8: REVENUE BUILD (Probable case)
A9: Active buyer growth 2026 | B9: D65 | C9: 23.0% | D9: 24.0% | E9: Q1 26 Brazil buyer growth +32% YoY, fastest in 5 yrs
A10: Commerce take rate 26-30 | B10: D70:P70 | C10: 25.0->25.4% | D10: 25.2->26.0% | E10: Mercado Ads +67% YoY, near-zero marginal cost lifts take
A11: Fintech MAU growth 26/27 | B11: D73,G73 | C11: 22%/17% | D11: 24%/18% | E11: Actual fintech MAU growth ~27-30% in 2025
A12: Fintech take rate 26-30 | B12: D78:P78 | C12: 4.55->4.48% | D12: 4.58->4.74% | E12: Monetization RISING (4.37% in 24 -> 4.54% in 25); model had it falling
A13: Credit portfolio growth | B13: D83:P83 | C13: 65->14% | D13: 80->18% | E13: Book grew 90% in 25, 87% in Q1 26; near-term too low
A14: MARGIN DRIVERS (Probable case)
A15: Gross margin 29/30 | B15: M85,P85 | C15: 43.8/44.2% | D15: 43.6/44.0% | E15: Free-shipping investment keeps COGS elevated; slower recovery
A16: SG&A % 27-30 | B16: G86:P86 | C16: 15.1->13.6% | D16: 15.2->14.0% | E16: Less operating leverage than modeled; reinvestment ongoing
A17: R&D % 28-30 | B17: J87:P87 | C17: 7.5->7.1% | D17: 7.6->7.4% | E17: Heavy AI / tech spend held higher
A18: Other opex % 26-30 | B18: D88:P88 | C18: 12.8->10.8% | D18: 12.6->11.7% | E18: Bad-debt provisions stay elevated as credit book grows 80-90%
A19: -> Op margin 2030 | B19: memo | C19: 12.7% | D19: 10.9% | E19: Recovers toward, not back to, the 2024 peak
A20: VALUATION
A21: Current share price | B21: C7 | C21: $1,650.13 | D21: $1,584 | E21: MELI close 6/23/2026
A22: WACC | B22: C8 | C22: 14.0% | D22: 13.5% | E22: Build-up (no beta): 4.4% RF + 5.0% ERP + 3.5% LatAm CRP + 0.75% co-specific = 13.65% Ke; clean WACC ~12.7%; +0.8% for un-haircut FX
A23: Terminal EV/EBIT | B23: C9 | C23: 10.0x on row27 | D23: 15.0x on op income | E23: Re-pointed to TRUE operating income (row13); row27 EBIT excluded credit provisions (~2x). 15x = ~8% implied continuing growth at 13.5%
A24: RESULT
A25: Implied value / share | B25: C13 | C25: -- | D25: $2,163 | E25: Refined case
A26: Upside to current | B26: C14 | C26: -- | D26: +37% | E26: Essentially on top of street target ~$2,217

Sheet Annual
A1: MercadoLibre, Inc. (NASDAQ: MELI) | Integrated Operating Model
A2: $ in millions, except per share data. Shares in millions. Fiscal year ends December 31. Actuals 2005-2025 | Estimates 2026E-2030E
A4: ($ in millions) | B4: 2005 | C4: 2006 | D4: 2007 | E4: 2008 | F4: 2009 | G4: 2010 | H4: 2011 | I4: 2012 | J4: 2013 | K4: 2014 | L4: 2015 | M4: 2016 | N4: 2017 | O4: 2018 | P4: 2019 | Q4: 2020 | R4: 2021 | S4: 2022 | T4: 2023 | U4: 2024 | V4: 2025 | W4: 2026E | X4: 2027E | Y4: 2028E | Z4: 2029E | AA4: 2030E
A5: INCOME STATEMENT
A6: Revenue | B6: 28.249677 | C6: 52.05889 | D6: 85.126341 | E6: 137.02262 | F6: 172.84362 | G6: 216.71571 | H6: 298.93162 | I6: 373.60149 | J6: 472.595 | K6: 556.536 | L6: 651.79 | M6: 844.396 | N6: 1216.542 | O6: 1439.653 | P6: 2296.314 | Q6: 3974 | R6: 7069 | S6: 10780 | T6: 15107 | U6: 20777 | V6: 28893 | W6: ='Assumptions (Annual)'!C21 -> 39916.237 | X6: ='Assumptions (Annual)'!D21 -> 51458.663 | Y6: ='Assumptions (Annual)'!E21 -> 63236.229 | Z6: ='Assumptions (Annual)'!F21 -> 74631.355 | AA6: ='Assumptions (Annual)'!G21 -> 85669.337
A7: Cost of Revenue | B7: 6.138732 | C7: 12.085648 | D7: 18.27294 | E7: 27.536573 | F7: 35.95805 | G7: 46.549845 | H7: 72.055835 | I7: 98.085644 | J7: 130.077 | K7: 158.978 | L7: 214.994 | M7: 307.538 | N7: 496.942 | O7: 742.645 | P7: 1194.191 | Q7: 2265 | R7: 4064 | S7: 5582 | T7: 7517 | U7: 11200 | V7: 16035 | W7: =W6*(1-'Assumptions (Annual)'!C26) -> 22951.836 | X7: =X6*(1-'Assumptions (Annual)'!D26) -> 29434.355 | Y7: =Y6*(1-'Assumptions (Annual)'!E26) -> 35918.178 | Z7: =Z6*(1-'Assumptions (Annual)'!F26) -> 42092.084 | AA7: =AA6*(1-'Assumptions (Annual)'!G26) -> 47974.829
A8: Gross Profit | B8: =B6-B7 -> 22.110945 | C8: =C6-C7 -> 39.973242 | D8: =D6-D7 -> 66.853401 | E8: =E6-E7 -> 109.48605 | F8: =F6-F7 -> 136.88557 | G8: =G6-G7 -> 170.16587 | H8: =H6-H7 -> 226.87579 | I8: =I6-I7 -> 275.51585 | ... AA8: =AA6-AA7 -> 37694.508
A9: Selling, General & Administrative | B9: 19.112863 | C9: 31.509009 | D9: 40.822205 | E9: 62.735238 | F9: 68.711331 | G9: 79.711313 | H9: 103.75384 | I9: 117.2311 | J9: 148.091 | K9: 173.991 | L9: 204.951 | M9: 243.606 | N9: 447.569 | O9: 620.217 | P9: 1031.477 | Q9: 1095 | R9: 1539 | S9: 1957 | T9: 2502 | U9: 3154 | V9: 4297 | W9: =W6*'Assumptions (Annual)'!C27 -> 6187.0167 | X9: =X6*'Assumptions (Annual)'!D27 -> 7821.7168 | Y9: =Y6*'Assumptions (Annual)'!E27 -> 9358.9618 | Z9: =Z6*'Assumptions (Annual)'!F27 -> 10746.915 | AA9: =AA6*'Assumptions (Annual)'!G27 -> 11993.707
A10: Research & Development | B10: 2.18622 | C10: 3.066304 | D10: 4.369376 | E10: 7.307008 | F10: 12.140521 | G10: 15.855992 | H10: 23.349787 | I10: 28.62688 | J10: 40.888 | K10: 53.6 | L10: 76.423 | M10: 98.479 | N10: 127.16 | O10: 146.273 | P10: 223.807 | Q10: 353 | R10: 590 | S10: 1099 | T10: 1831 | U10: 1934 | V10: 2269 | W10: =W6*'Assumptions (Annual)'!C28 -> 3113.4665 | X10: =X6*'Assumptions (Annual)'!D28 -> 3962.3171 | Y10: =Y6*'Assumptions (Annual)'!E28 -> 4805.9534 | Z10: =Z6*'Assumptions (Annual)'!F28 -> 5597.3516 | AA10: =AA6*'Assumptions (Annual)'!G28 -> 6339.5309
A11: Other Operating Expenses | B11: 0 | C11: 0 | D11: 0 | E11: 1.91987 | F11: 0 | G11: 0 | H11: 0 | I11: 0 | J11: 0 | K11: 49.496 | L11: 16.226 | M11: 13.717 | N11: 88.598 | O11: 0 | P11: 0 | Q11: 133 | R11: 435 | S11: 1073 | T11: 1050 | U11: 1858 | V11: 3091 | W11: =W6*'Assumptions (Annual)'!C29 -> 5029.4458 | X11: =X6*'Assumptions (Annual)'!D29 -> 6380.8743 | Y11: =Y6*'Assumptions (Annual)'!E29 -> 7714.8199 | Z11: =Z6*'Assumptions (Annual)'!F29 -> 8955.7626 | AA11: =AA6*'Assumptions (Annual)'!G29 -> 10023.312
A12: Total Operating Expenses | B12: =B9+B10+B11 -> 21.299083 | C12: =C9+C10+C11 -> 34.575313 | D12: =D9+D10+D11 -> 45.191581 | E12: =E9+E10+E11 -> 71.962116 | F12: =F9+F10+F11 -> 80.851852 | G12: =G9+G10+G11 -> 95.567305 | H12: =H9+H10+H11 -> 127.10362 | I12: =I9+I10+I11 -> 145.85798 | ... AA12: =AA9+AA10+AA11 -> 28356.55
A13: Operating Income | B13: =B8-B12 -> 0.811862 | C13: =C8-C12 -> 5.397929 | D13: =D8-D12 -> 21.66182 | E13: =E8-E12 -> 37.523931 | F13: =F8-F12 -> 56.033719 | G13: =G8-G12 -> 74.598563 | H13: =H8-H12 -> 99.772165 | I13: =I8-I12 -> 129.65787 | ... AA13: =AA8-AA12 -> 9337.9577
A14: Interest Expense / (Income) | B14: 0.45643 | C14: 1.743315 | D14: 2.737901 | E14: 8.442427 | F14: 13.357554 | G14: 7.601671 | H14: 3.648733 | I14: 1.138379 | J14: 2.356 | K14: 11.659 | L14: 20.391 | M14: 25.605 | N14: 26.469 | O14: 56.249 | P14: 65.876 | Q14: 107 | R14: 229 | S14: 135 | T14: 174 | U14: 165 | V14: 160 | W14: =W6*'Assumptions (Annual)'!C30+'Assumptions (Annual)'!C34*0 -> 339.28801 | X14: =X6*'Assumptions (Annual)'!D30+'Assumptions (Annual)'!D34*W110 -> 411.66931 | Y14: =Y6*'Assumptions (Annual)'!E30+'Assumptions (Annual)'!E34*X110 -> 474.27171 | Z14: =Z6*'Assumptions (Annual)'!F30+'Assumptions (Annual)'!F34*Y110 -> 522.41948 | AA14: =AA6*'Assumptions (Annual)'!G30+'Assumptions (Annual)'!G34*Z110 -> 556.85069
A15: Other Expense / (Income) | B15: -0.629342 | C15: 1.339693 | D15: 4.503528 | E15: -0.3644 | F15: -0.036633 | G15: -4.868768 | H15: -12.316442 | I15: -11.599185 | J15: -11.907 | K15: -12.912 | L15: -31.686 | M15: -29.877 | N15: -24.266 | O15: -60.279 | P15: -111.791 | Q15: -60 | R15: -20 | S15: 154 | T15: 477 | U15: 34 | V15: 199 | W15: =W6*'Assumptions (Annual)'!C31 -> 199.58118 | X15: =X6*'Assumptions (Annual)'!D31 -> 257.29332 | Y15: =Y6*'Assumptions (Annual)'!E31 -> 316.18114 | Z15: =Z6*'Assumptions (Annual)'!F31 -> 373.15677 | AA15: =AA6*'Assumptions (Annual)'!G31 -> 428.34668
A16: Pretax Income | B16: =B13-B14-B15 -> 0.984774 | C16: =C13-C14-C15 -> 2.314921 | D16: =D13-D14-D15 -> 14.420391 | E16: =E13-E14-E15 -> 29.445904 | F16: =F13-F14-F15 -> 42.712798 | G16: =G13-G14-G15 -> 71.86566 | H16: =H13-H14-H15 -> 108.43987 | I16: =I13-I14-I15 -> 140.11868 | ... AA16: =AA13-AA14-AA15 -> 8352.7603
A17: Income Tax | B17: -1.369362 | C17: 1.242838 | D17: 4.727451 | E17: 10.634243 | F17: 9.504005 | G17: 15.840641 | H17: 31.659821 | I17: 38.871379 | J17: 45.583 | K17: 49.143 | L17: 44.702 | M17: 48.962 | N17: 40.29 | O17: -28.867 | P17: 64.753 | Q17: 82 | R17: 149 | S17: 298 | T17: 569 | U17: 521 | V17: 845 | W17: =W16*'Assumptions (Annual)'!C32 -> 618.20272 | X17: =X16*'Assumptions (Annual)'!D32 -> 941.17895 | Y17: =Y16*'Assumptions (Annual)'!E32 -> 1371.1195 | Z17: =Z16*'Assumptions (Annual)'!F32 -> 1871.3812 | AA17: =AA16*'Assumptions (Annual)'!G32 -> 2464.0643
A18: Net Income | B18: =B16-B17 -> 2.354136 | C18: =C16-C17 -> 1.072083 | D18: =D16-D17 -> 9.69294 | E18: =E16-E17 -> 18.811661 | F18: =F16-F17 -> 33.208793 | G18: =G16-G17 -> 56.025019 | H18: =H16-H17 -> 76.780053 | I18: =I16-I17 -> 101.2473 | ... AA18: =AA16-AA17 -> 5888.696
A19: Preferred Dividends | B19: 0.494878 | C19: 0.494878 | D19: 0.309299 | E19: 0 | F19: 0 | G19: 0 | H19: 0 | I19: 0 | J19: 0 | K19: 0 | L19: 0 | M19: 0 | N19: 0 | O19: 0 | P19: 0 | Q19: 0 | R19: 0 | S19: 0 | T19: 0 | U19: 0 | V19: 0 | W19: ='Assumptions (Annual)'!C44 -> 0 | X19: ='Assumptions (Annual)'!D44 -> 0 | Y19: ='Assumptions (Annual)'!E44 -> 0 | Z19: ='Assumptions (Annual)'!F44 -> 0 | AA19: ='Assumptions (Annual)'!G44 -> 0
A20: Net Income to Common | B20: =B18-B19 -> 1.859258 | C20: =C18-C19 -> 0.577205 | D20: =D18-D19 -> 9.383641 | E20: =E18-E19 -> 18.811661 | F20: =F18-F19 -> 33.208793 | G20: =G18-G19 -> 56.025019 | H20: =H18-H19 -> 76.780053 | I20: =I18-I19 -> 101.2473 | ... AA20: =AA18-AA19 -> 5888.696
A22: Shares Outstanding (Basic) | B22: 13.065496 | C22: 13.149139 | D22: 25.149405 | E22: 44.239443 | F22: 44.086892 | G22: 44.124018 | H22: 44.138397 | I22: 44.147861 | J22: 44.1526 | K22: 44.153884 | L22: 44.15568 | M22: 44.157251 | N22: 44.157364 | O22: 44.529614 | P22: 48.692906 | Q22: 49.740407 | R22: 49.802993 | S22: 50.345353 | T22: 50.262302 | U22: 50.697428 | V22: 50.697299 | W22: =V22*(1+'Assumptions (Annual)'!C33) -> 50.595904 | X22: =W22*(1+'Assumptions (Annual)'!D33) -> 50.494713 | Y22: =X22*(1+'Assumptions (Annual)'!E33) -> 50.393723 | Z22: =Y22*(1+'Assumptions (Annual)'!F33) -> 50.292936 | AA22: =Z22*(1+'Assumptions (Annual)'!G33) -> 50.19235
A23: Shares Outstanding (Diluted) | B23: 13.671359 | C23: =C22 -> 13.149139 | D23: 25.478336 | E23: 44.34895 | F23: 44.144368 | G23: 44.146858 | H23: 44.151437 | I23: 44.149838 | J23: 44.1526 | K23: 44.153884 | L23: 44.15568 | M23: 44.157251 | N23: 44.157364 | O23: 44.529614 | P23: 48.692906 | Q23: 49.740407 | R23: 49.802993 | S23: 51.335621 | T23: 51.00686 | U23: 50.697428 | V23: 50.69732 | W23: =V23*(1+'Assumptions (Annual)'!C33) -> 50.595925 | X23: =W23*(1+'Assumptions (Annual)'!D33) -> 50.494734 | Y23: =X23*(1+'Assumptions (Annual)'!E33) -> 50.393744 | Z23: =Y23*(1+'Assumptions (Annual)'!F33) -> 50.292957 | AA23: =Z23*(1+'Assumptions (Annual)'!G33) -> 50.192371
A24: EPS (Basic) | B24: =IF(B22=0,"",B20/B22) -> 0.1423029 | C24: =IF(C22=0,"",C20/C22) -> 0.043896791 | D24: =IF(D22=0,"",D20/D22) -> 0.37311583 | E24: =IF(E22=0,"",E20/E22) -> 0.42522373 | F24: =IF(F22=0,"",F20/F22) -> 0.75325775 | G24: =IF(G22=0,"",G20/G22) -> 1.2697171 | H24: =IF(H22=0,"",H20/H22) -> 1.7395297 | I24: =IF(I22=0,"",I20/I22) -> 2.2933681 | ... V24: =IF(V22=0,"",V20/V22) -> 39.390659 | W24: =W20/W22 -> 29.199986 | X24: =X20/X22 -> 44.54443 | Y24: =Y20/Y22 -> 65.022846 | Z24: =Z20/Z22 -> 88.924694 | AA24: =AA20/AA22 -> 117.32258
A25: EPS (Diluted) | B25: =IF(B23=0,"",B20/B23) -> 0.13599658 | C25: =IF(C23=0,"",C20/C23) -> 0.043896791 | D25: =IF(D23=0,"",D20/D23) -> 0.36829882 | E25: =IF(E23=0,"",E20/E23) -> 0.42417376 | F25: =IF(F23=0,"",F20/F23) -> 0.75227701 | G25: =IF(G23=0,"",G20/G23) -> 1.2690602 | H25: =IF(H23=0,"",H20/H23) -> 1.7390159 | I25: =IF(I23=0,"",I20/I23) -> 2.2932654 | ... V25: =IF(V23=0,"",V20/V23) -> 39.390642 | W25: =W20/W23 -> 29.199974 | X25: =X20/X23 -> 44.544411 | Y25: =Y20/Y23 -> 65.022819 | Z25: =Z20/Z23 -> 88.924658 | AA25: =AA20/AA23 -> 117.32253
A27: EBIT | B27: =B8-B9-B10 -> 0.811862 | C27: =C8-C9-C10 -> 5.397929 | D27: =D8-D9-D10 -> 21.66182 | E27: =E8-E9-E10 -> 39.443801 | F27: =F8-F9-F10 -> 56.033719 | G27: =G8-G9-G10 -> 74.598563 | H27: =H8-H9-H10 -> 99.772165 | I27: =I8-I9-I10 -> 129.65787 | ... AA27: =AA8-AA9-AA10 -> 19361.27
A28: Normalized Earnings | B28: =B27+B14-B17-B19 -> 2.142776 | C28: =C27+C14-C17-C19 -> 5.403528 | D28: =D27+D14-D17-D19 -> 19.362971 | E28: =E27+E14-E17-E19 -> 37.251985 | F28: =F27+F14-F17-F19 -> 59.887268 | G28: =G27+G14-G17-G19 -> 66.359593 | H28: =H27+H14-H17-H19 -> 71.761077 | I28: =I27+I14-I17-I19 -> 91.924871 | ... V28: =V27+V14-V17-V19 -> 5607 | W28: =W27*(1-'Assumptions (Annual)'!C32) -> 5403.0618 | X28: =X27*(1-'Assumptions (Annual)'!D32) -> 7219.3932 | Y28: =Y27*(1-'Assumptions (Annual)'!E32) -> 9272.9606 | Z28: =Z27*(1-'Assumptions (Annual)'!F32) -> 11417.478 | AA28: =AA27*(1-'Assumptions (Annual)'!G32) -> 13649.695
A29: Normalized EPS | B29: =B28/B23 -> 0.15673467 | C29: =C28/C23 -> 0.41094158 | D29: =D28/D23 -> 0.75997785 | E29: =E28/E23 -> 0.83997445 | F29: =F28/F23 -> 1.3566231 | G29: =G28/G23 -> 1.5031555 | H29: =H28/H23 -> 1.6253396 | I29: =I28/I23 -> 2.0821112 | ... AA29: =AA28/AA23 -> 271.94761
A31: Sales Growth | C31: =C6/B6-1 -> 0.84281364 | D31: =D6/C6-1 -> 0.63519316 | E31: =E6/D6-1 -> 0.60963831 | F31: =F6/E6-1 -> 0.261424 | G31: =G6/F6-1 -> 0.25382535 | H31: =H6/G6-1 -> 0.37937218 | I31: =I6/H6-1 -> 0.24978912 | J31: =J6/I6-1 -> 0.26497085 | ... AA31: =AA6/Z6-1 -> 0.14790006
A32: Gross Margin | B32: =B8/B6 -> 0.78269727 | C32: =C8/C6 -> 0.76784661 | D32: =D8/D6 -> 0.78534329 | E32: =E8/E6 -> 0.7990363 | F32: =F8/F6 -> 0.79196195 | G32: =G8/G6 -> 0.78520318 | H32: =H8/H6 -> 0.75895546 | I32: =I8/I6 -> 0.73745918 | ... AA32: =AA8/AA6 -> 0.44
A33: EBIT Margin | B33: =B27/B6 -> 0.028738806 | C33: =C27/C6 -> 0.1036889 | D33: =D27/D6 -> 0.25446671 | E33: =E27/E6 -> 0.28786343 | F33: =F27/F6 -> 0.32418737 | G33: =G27/G6 -> 0.34422314 | H33: =H27/H6 -> 0.3337625 | I33: =I27/I6 -> 0.34704859 | ... AA33: =AA27/AA6 -> 0.226
A34: Normalized Net Margin | B34: =B28/B6 -> 0.075851345 | C34: =C28/C6 -> 0.10379645 | D34: =D28/D6 -> 0.22746157 | E34: =E28/E6 -> 0.27186741 | F34: =F28/F6 -> 0.34648237 | G34: =G28/G6 -> 0.30620573 | H34: =H28/H6 -> 0.2400585 | I34: =I28/I6 -> 0.2460506 | ... AA34: =AA28/AA6 -> 0.15933
A36: BALANCE SHEET
A37: Cash & Equivalents | B37: 8.979838 | C37: 7.143027 | D37: 15.677407 | E37: 17.474112 | F37: 49.803402 | G37: 56.830466 | H37: 67.381677 | I37: 101.489 | J37: 140.2851 | K37: 223.144 | L37: 166.881 | M37: 234.14 | N37: 388.26 | O37: 464.695 | P37: 1451.424 | Q37: 2508.224 | R37: 3648 | S37: 3363 | T37: 3848 | U37: 4699 | V37: 13537 | W37: =V37+W97 -> 17418.805 | X37: =W37+X97 -> 21094.185 | Y37: =X37+Y97 -> 25929.53 | Z37: =Y37+Z97 -> 31441.813 | AA37: =Z37+AA97 -> 38245.448
A38: Short-Term Investments | B38: 3.411266 | C38: 6.320656 | D38: 52.300007 | E38: 31.6394 | F38: 14.580185 | G38: 5.342766 | H38: 74.92862 | I38: 93.694805 | J38: 76.593214 | K38: 148.81 | L38: 202.112 | M38: 259.604 | N38: 282.841 | O38: 557.319 | P38: 1779.346 | Q38: 1626.342 | R38: 2009 | S38: 4043 | T38: 6109 | U38: 9201 | V38: 11484 | W38: =W6*'Assumptions (Annual)'!C49 -> 13571.521 | X38: =X6*'Assumptions (Annual)'!D49 -> 16981.359 | Y38: =Y6*'Assumptions (Annual)'!E49 -> 20235.593 | Z38: =Z6*'Assumptions (Annual)'!F49 -> 23135.72 | AA38: =AA6*'Assumptions (Annual)'!G49 -> 25700.801
A39: Total Cash & Short-Term Investments | B39: =B37+B38 -> 12.391104 | C39: =C37+C38 -> 13.463683 | D39: =D37+D38 -> 67.977414 | E39: =E37+E38 -> 49.113512 | F39: =F37+F38 -> 64.383587 | G39: =G37+G38 -> 62.173232 | H39: =H37+H38 -> 142.3103 | I39: =I37+I38 -> 195.18381 | ... AA39: =AA37+AA38 -> 63946.249
A40: Receivables | B40: 6.548564 | C40: 12.171715 | D40: 32.374015 | E40: 6.178808 | F40: 8.654179 | G40: 18.769691 | H40: 40.670776 | I40: 55.653528 | J40: 77.930111 | K40: 131.834 | L40: 160.374 | M40: 333.339 | N40: 549.298 | O40: 395.451 | P40: 415.415 | Q40: 912.764 | R40: 1937 | S40: 3076 | T40: 3788 | U40: 5543 | V40: 7415 | W40: =W6*'Assumptions (Annual)'!C46 -> 11974.871 | X40: =X6*'Assumptions (Annual)'!D46 -> 16466.772 | Y40: =Y6*'Assumptions (Annual)'!E46 -> 20867.955 | Z40: =Z6*'Assumptions (Annual)'!F46 -> 25374.661 | AA40: =AA6*'Assumptions (Annual)'!G46 -> 29984.268
A41: Inventory | B41: 0 | C41: 0 | D41: 0 | E41: 0 | F41: 0 | G41: 0 | H41: 0 | I41: 0 | J41: 0 | K41: 0 | L41: 0.222 | M41: 1.103 | N41: 2.549 | O41: 4.612 | P41: 8.626 | Q41: 118.14 | R41: 253 | S41: 152 | T41: 238 | U41: 296 | V41: 570 | W41: =W6*'Assumptions (Annual)'!C47 -> 997.90592 | X41: =X6*'Assumptions (Annual)'!D47 -> 1389.3839 | Y41: =Y6*'Assumptions (Annual)'!E47 -> 1833.8506 | Z41: =Z6*'Assumptions (Annual)'!F47 -> 2238.9406 | AA41: =AA6*'Assumptions (Annual)'!G47 -> 2741.4188
A42: Other Current Assets | B42: 1.159354 | C42: 3.48448 | D42: 4.622741 | E42: 5.008904 | F42: 9.09725 | G42: 20.692285 | H42: 17.264482 | I42: 24.52384 | J42: 31.355806 | K42: 28.962 | L42: 15.584 | M42: 41.275 | N42: 63.971 | O42: 89.046 | P42: 134.045 | Q42: 181.337 | R42: 328 | S42: 319 | T42: 277 | U42: 403 | V42: 567 | W42: =W6*'Assumptions (Annual)'!C48 -> 798.32474 | X42: =X6*'Assumptions (Annual)'!D48 -> 1029.1733 | Y42: =Y6*'Assumptions (Annual)'!E48 -> 1264.7246 | Z42: =Z6*'Assumptions (Annual)'!F48 -> 1492.6271 | AA42: =AA6*'Assumptions (Annual)'!G48 -> 1713.3867
A43: Total Current Assets | B43: =B39+B40+B41+B42 -> 20.099022 | C43: =C39+C40+C41+C42 -> 29.119878 | D43: =D39+D40+D41+D42 -> 104.97417 | E43: =E39+E40+E41+E42 -> 60.301224 | F43: =F39+F40+F41+F42 -> 82.135016 | G43: =G39+G40+G41+G42 -> 101.63521 | H43: =H39+H40+H41+H42 -> 200.24555 | I43: =I39+I40+I41+I42 -> 275.36118 | ... AA43: =AA39+AA40+AA41+AA42 -> 98385.322
A44: Property, Plant & Equipment | B44: 2.343623 | C44: 2.93147 | D44: 4.143204 | E44: 5.94016 | F44: 5.948276 | G44: 20.817712 | H44: 30.877719 | I44: 37.726222 | J44: 131.37191 | K44: 91.545 | L44: 81.633 | M44: 124.261 | N44: 114.837 | O44: 165.614 | P44: 444.706 | Q44: 694.898 | R44: 1268 | S44: 1649 | T44: 2149 | U44: 2478 | V44: 4504 | W44: =V44+W6*'Assumptions (Annual)'!C39-W6*'Assumptions (Annual)'!C37 -> 5901.0683 | X44: =W44+X6*'Assumptions (Annual)'!D39-X6*'Assumptions (Annual)'!D37 -> 7393.3695 | Y44: =X44+Y6*'Assumptions (Annual)'!E39-Y6*'Assumptions (Annual)'!E37 -> 8911.039 | Z44: =Y44+Z6*'Assumptions (Annual)'!F39-Z6*'Assumptions (Annual)'!F37 -> 10403.666 | AA44: =Z44+AA6*'Assumptions (Annual)'!G39-AA6*'Assumptions (Annual)'!G37 -> 11860.045
A45: Long-Term Investments | B45: 0 | C45: 0 | D45: 1.323789 | E45: 9.218153 | F45: 26.627357 | G45: 78.846281 | H45: 43.933316 | I45: 85.955584 | J45: 45.719737 | K45: 205.265 | L45: 187.621 | M45: 153.803 | N45: 34.72 | O45: 276.136 | P45: 270.422 | Q45: 182.73 | R45: 150 | S45: 354 | T45: 227 | U45: 1382 | V45: 2274 | W45: =V45*(1+'Assumptions (Annual)'!C55) -> 2455.92 | X45: =W45*(1+'Assumptions (Annual)'!D55) -> 2627.8344 | Y45: =X45*(1+'Assumptions (Annual)'!E55) -> 2785.5045 | Z45: =Y45*(1+'Assumptions (Annual)'!F55) -> 2924.7797 | AA45: =Z45*(1+'Assumptions (Annual)'!G55) -> 3071.0187
...

Sheet Quarterly
A1: MercadoLibre, Inc. (NASDAQ: MELI) | Integrated Operating Model - Quarterly
A2: $ in millions, except per share data. Shares in millions. Actuals through Q1 2026 | Estimates Q2 2026E-Q4 2027E
A4: ($ in millions) | B4: Q4'06 | C4: Q1'07 | D4: Q2'07 | E4: Q3'07 | F4: Q4'07 | G4: Q1'08 | H4: Q2'08 | I4: Q3'08 | J4: Q4'08 | K4: Q1'09 | L4: Q2'09 | M4: Q3'09 | N4: Q4'09 | O4: Q1'10 | P4: Q2'10 | Q4: Q3'10 | R4: Q4'10 | S4: Q1'11 | T4: Q2'11 | U4: Q3'11 | V4: Q4'11 | W4: Q1'12 | X4: Q2'12 | Y4: Q3'12 | Z4: Q4'12 | AA4: Q1'13 | AB4: Q2'13 | AC4: Q3'13 | AD4: Q4'13 | AE4: Q1'14 | AF4: Q2'14 | AG4: Q3'14 | AH4: Q4'14 | AI4: Q1'15 | AJ4: Q2'15 | AK4: Q3'15 | AL4: Q4'15 | AM4: Q1'16 | AN4: Q2'16 | AO4: Q3'16 | AP4: Q4'16 | AQ4: Q1'17 | AR4: Q2'17 | AS4: Q3'17 | AT4: Q4'17 | AU4: Q1'18 | AV4: Q2'18 | AW4: Q3'18 | AX4: Q4'18 | AY4: Q1'19 | AZ4: Q2'19 | BA4: Q3'19 | BB4: Q4'19 | BC4: Q1'20 | BD4: Q2'20 | BE4: Q3'20 | BF4: Q4'20 | BG4: Q1'21 | BH4: Q2'21 | BI4: Q3'21 | BJ4: Q4'21 | BK4: Q1'22 | BL4: Q2'22 | BM4: Q3'22 | BN4: Q4'22 | BO4: Q1'23 | BP4: Q2'23 | BQ4: Q3'23 | BR4: Q4'23 | BS4: Q1'24 | BT4: Q2'24 | BU4: Q3'24 | BV4: Q4'24 | BW4: Q1'25 | BX4: Q2'25 | BY4: Q3'25 | BZ4: Q4'25 | CA4: Q1'26 | CB4: Q2'26E | CC4: Q3'26E | CD4: Q4'26E | CE4: Q1'27E | CF4: Q2'27E | CG4: Q3'27E | CH4: Q4'27E
A5: INCOME STATEMENT
A6: Revenue | B6: 15.462397 | C6: 16.459337 | D6: 18.973288 | E6: 22.80013 | F6: 26.893586 | G6: 28.84073 | H6: 34.471508 | I6: 40.260643 | J6: 33.449739 | K6: 32.322501 | L6: 40.901799 | M6: 50.599276 | N6: 49.020045 | O6: 45.937774 | P6: 52.510331 | Q6: 55.951378 | R6: 62.31623 | S6: 61.459668 | T6: 69.37816 | U6: 81.628144 | V6: 86.465653 | W6: 83.736006 | X6: 88.844059 | Y6: 97.266784 | Z6: 103.75465 | AA6: 102.72575 | AB6: 112.18336 | AC6: 123.05543 | AD6: 134.63046 | AE6: 115.382 | AF6: 131.849 | AG6: 147.935 | AH6: 161.37 | AI6: 148.103 | AJ6: 154.314 | AK6: 168.641 | AL6: 180.732 | AM6: 157.63 | AN6: 199.644 | AO6: 230.847 | AP6: 256.275 | AQ6: 269.675 | AR6: 283.882 | AS6: 304.921 | AT6: 358.063 | AU6: 320.976 | AV6: 335.377 | AW6: 355.281 | AX6: 428.019 | AY6: 473.77 | AZ6: 545.242 | BA6: 603.031 | BB6: 674.271 | BC6: 652.091 | BD6: 878.369 | BE6: 1115.701 | BF6: 1327.839 | BG6: 1378 | BH6: 1703 | BI6: 1858 | BJ6: 2130 | BK6: 2248 | BL6: 2597 | BM6: 2690 | BN6: 3245 | BO6: 3186 | BP6: 3585 | BQ6: 3927 | BR6: 4409 | BS6: 4333 | BT6: 5073 | BU6: 5312 | BV6: 6059 | BW6: 5935 | BX6: 6790 | BY6: 7409 | BZ6: 8759 | CA6: 8845 | CB6: ='Assumptions (Quarterly)'!F13 -> 9130.66 | CC6: ='Assumptions (Quarterly)'!G13 -> 10109.82 | CD6: ='Assumptions (Quarterly)'!H13 -> 11654.815 | CE6: ='Assumptions (Quarterly)'!I13 -> 11500.64 | CF6: ='Assumptions (Quarterly)'!J13 -> 11593.531 | CG6: ='Assumptions (Quarterly)'!K13 -> 12625.39 | CH6: ='Assumptions (Quarterly)'!L13 -> 14281.798
A7: Cost of Revenue | B7: 3.653165 | C7: 3.487339 | D7: 3.999922 | E7: 4.882048 | F7: 5.90363 | G7: 6.018281 | H7: 6.901503 | I7: 8.153862 | J7: 6.461529 | K7: 6.633986 | L7: 8.595477 | M7: 10.390671 | N7: 10.337916 | O7: 9.893051 | P7: 11.411561 | Q7: 11.450919 | R7: 13.794314 | S7: 14.331703 | T7: 16.939118 | U7: 20.060474 | V7: 20.72454 | W7: 21.096297 | X7: 23.892881 | Y7: 25.693605 | Z7: 27.402862 | AA7: 28.649167 | AB7: 31.077211 | AC7: 34.144989 | AD7: 36.205632 | AE7: 31.54 | AF7: 36.372 | AG7: 43.402 | AH7: 47.665 | AI7: 44.708 | AJ7: 50.311 | AK7: 56.813 | AL7: 63.162 | AM7: 55.448 | AN7: 73.346 | AO7: 85.199 | AP7: 93.545 | AQ7: 100.819 | AR7: 112.328 | AS7: 129.094 | AT7: 154.701 | AU7: 158.218 | AV7: 175.629 | AW7: 185.563 | AX7: 223.235 | AY7: 236.766 | AZ7: 272.812 | BA7: 318.689 | BB7: 365.924 | BC7: 339.277 | BD7: 451.197 | BE7: 635.511 | BF7: 839.015 | BG7: 787 | BH7: 949 | BI7: 1051 | BJ7: 1277 | BK7: 1175 | BL7: 1313 | BM7: 1342 | BN7: 1752 | BO7: 1572 | BP7: 1754 | BQ7: 1832 | BR7: 2359 | BS7: 2309 | BT7: 2708 | BU7: 2873 | BV7: 3310 | BW7: 3164 | BX7: 3696 | BY7: 4200 | BZ7: 4975 | CA7: 4983 | CB7: =CB6*(1-'Assumptions (Quarterly)'!F15) -> 5113.1696 | CC7: =CC6*(1-'Assumptions (Quarterly)'!G15) -> 5641.2795 | CD7: =CD6*(1-'Assumptions (Quarterly)'!H15) -> 6468.4223 | CE7: =CE6*(1-'Assumptions (Quarterly)'!I15) -> 6440.3584 | CF7: =CF6*(1-'Assumptions (Quarterly)'!J15) -> 6457.5969 | CG7: =CG6*(1-'Assumptions (Quarterly)'!K15) -> 7007.0917 | CH7: =CH6*(1-'Assumptions (Quarterly)'!L15) -> 7883.5525
A8: Gross Profit | B8: =B6-B7 -> 11.809232 | C8: =C6-C7 -> 12.971998 | D8: =D6-D7 -> 14.973366 | E8: =E6-E7 -> 17.918082 | F8: =F6-F7 -> 20.989956 | G8: =G6-G7 -> 22.822449 | H8: =H6-H7 -> 27.570005 | I8: =I6-I7 -> 32.106781 | ... CH8: =CH6-CH7 -> 6398.2455
A9: Selling, General & Administrative | B9: 8.967412 | C9: 8.991513 | D9: 9.141326 | E9: 10.466394 | F9: 12.222972 | G9: 14.162263 | H9: 16.144958 | I9: 18.686236 | J9: 13.741782 | K9: 16.287552 | L9: 16.806893 | M9: 17.930819 | N9: 17.686067 | O9: 17.315682 | P9: 18.307737 | Q9: 20.965277 | R9: 23.122616 | S9: 22.679919 | T9: 25.368753 | U9: 25.678928 | V9: 30.026238 | W9: 30.122891 | X9: 26.932439 | Y9: 29.876191 | Z9: 30.299578 | AA9: 36.123007 | AB9: 35.896634 | AC9: 39.436793 | AD9: 36.635004 | AE9: 37.584 | AF9: 40.153 | AG9: 43.812 | AH9: 52.44 | AI9: 44.336 | AJ9: 49.727 | AK9: 49.506 | AL9: 61.382 | AM9: 49.752 | AN9: 56.178 | AO9: 65.873 | AP9: 71.802 | AQ9: 75.24 | AR9: 108.354 | AS9: 115.905 | AT9: 148.069 | AU9: 153.781 | AV9: 154.553 | AW9: 145.243 | AX9: 166.64 | AY9: 174.496 | AZ9: 230.995 | BA9: 306.772 | BB9: 319.214 | BC9: 269.073 | BD9: 254.48 | BE9: 308.32 | BF9: 263.127 | BG9: 374 | BH9: 359 | BI9: 404 | BJ9: 486 | BK9: 445 | BL9: 469 | BM9: 486 | BN9: 556 | BO9: 563 | BP9: 572 | BQ9: 637 | BR9: 730 | BS9: 664 | BT9: 729 | BU9: 871 | BV9: 890 | BW9: 854 | BX9: 1012 | BY9: 1103 | BZ9: 1328 | CA9: 1308 | CB9: =CB6*'Assumptions (Quarterly)'!F16 -> 1333.0764 | CC9: =CC6*'Assumptions (Quarterly)'!G16 -> 1465.9239 | CD9: =CD6*'Assumptions (Quarterly)'!H16 -> 1654.9837 | CE9: =CE6*'Assumptions (Quarterly)'!I16 -> 1656.0922 | CF9: =CF6*'Assumptions (Quarterly)'!J16 -> 1646.2814 | CG9: =CG6*'Assumptions (Quarterly)'!K16 -> 1780.18 | CH9: =CH6*'Assumptions (Quarterly)'!L16 -> 1970.8881
A10: Research & Development | B10: 0.814537 | C10: 0.97362 | D10: 1.029096 | E10: 1.154317 | F10: 1.212343 | G10: 1.744511 | H10: 1.73078 | I10: 1.744608 | J10: 2.088506 | K10: 2.633419 | L10: 3.087206 | M10: 3.295436 | N10: 3.12446 | O10: 3.224775 | P10: 3.976466 | Q10: 4.224476 | R10: 4.430276 | S10: 5.15689 | T10: 5.518892 | U10: 5.925019 | V10: 6.748985 | W10: 7.586074 | X10: 6.133819 | Y10: 7.983301 | Z10: 6.923686 | AA10: 9.382389 | AB10: 9.76022 | AC10: 12.074586 | AD10: 9.670805 | AE10: 12.257 | AF10: 11.741 | AG10: 13.574 | AH10: 16.028 | AI10: 17.245 | AJ10: 19.639 | AK10: 17.042 | AL10: 22.496 | AM10: 21.941 | AN10: 24.216 | AO10: 26.066 | AP10: 26.256 | AQ10: 30.302 | AR10: 30.338 | AS10: 32.38 | AT10: 34.141 | AU10: 38.396 | AV10: 33.437 | AW10: 35.478 | AX10: 38.962 | AY10: 52.369 | AZ10: 53.923 | BA10: 59.495 | BB10: 58.02 | BC10: 73.435 | BD10: 73.254 | BE10: 88.796 | BF10: 117.515 | BG10: 126 | BH10: 147 | BI10: 138 | BJ10: 179 | BK10: 234 | BL10: 262 | BM10: 278 | BN10: 325 | BO10: 381 | BP10: 368 | BQ10: 396 | BR10: 686 | BS10: 458 | BT10: 460 | BU10: 504 | BV10: 512 | BW10: 551 | BX10: 567 | BY10: 567 | BZ10: 584 | CA10: 699 | CB10: =CB6*'Assumptions (Quarterly)'!F17 -> 721.32214 | CC10: =CC6*'Assumptions (Quarterly)'!G17 -> 788.56595 | CD10: =CD6*'Assumptions (Quarterly)'!H17 -> 897.42075 | CE10: =CE6*'Assumptions (Quarterly)'!I17 -> 897.04992 | CF10: =CF6*'Assumptions (Quarterly)'!J17 -> 892.7019 | CG10: =CG6*'Assumptions (Quarterly)'!K17 -> 959.52967 | CH10: =CH6*'Assumptions (Quarterly)'!L17 -> 1071.1349
A11: Other Operating Expenses | B11: 0 | C11: 0 | D11: 0 | E11: 0 | F11: 0 | G11: 0.373473 | H11: 1.546397 | I11: 0 | J11: 0 | K11: 0 | L11: 0 | M11: 0 | N11: 0 | O11: 0 | P11: 0 | Q11: 0 | R11: 0 | S11: 0 | T11: 0 | U11: 0 | V11: 0 | W11: 0 | X11: 0 | Y11: 0 | Z11: 0 | AA11: 0 | AB11: 0 | AC11: 0 | AD11: 0 | AE11: 0 | AF11: 49.496 | AG11: 0 | AH11: 0 | AI11: 16.226 | AJ11: 0 | AK11: 0 | AL11: 0 | AM11: 0 | AN11: 13.717 | AO11: 0 | AP11: 0 | AQ11: 0 | AR11: 2.837 | AS11: 0 | AT11: 85.761 | AU11: 0 | AV11: 0 | AW11: 0 | AX11: 0 | AY11: 0 | AZ11: 0 | BA11: 0 | BB11: 0 | BC11: 0 | BD11: 0 | BE11: 0 | BF11: 133 | BG11: 0 | BH11: 82 | BI11: 105 | BJ11: 164 | BK11: 255 | BL11: 303 | BM11: 288 | BN11: 228 | BO11: 252 | BP11: 222 | BQ11: 277 | BR11: 299 | BS11: 374 | BT11: 450 | BU11: 507 | BV11: 527 | BW11: 603 | BX11: 690 | BY11: 815 | BZ11: 983 | CA11: 1244 | CB11: =CB6*'Assumptions (Quarterly)'!F18 -> 1141.3325 | CC11: =CC6*'Assumptions (Quarterly)'!G18 -> 1213.1784 | CD11: =CD6*'Assumptions (Quarterly)'!H18 -> 1340.3037 | CE11: =CE6*'Assumptions (Quarterly)'!I18 -> 1403.0781 | CF11: =CF6*'Assumptions (Quarterly)'!J18 -> 1368.0367 | CG11: =CG6*'Assumptions (Quarterly)'!K18 -> 1439.2945 | CH11: =CH6*'Assumptions (Quarterly)'!L18 -> 1570.9978
A12: Total Operating Expenses | B12: =B9+B10+B11 -> 9.781949 | C12: =C9+C10+C11 -> 9.965133 | D12: =D9+D10+D11 -> 10.170422 | E12: =E9+E10+E11 -> 11.620711 | F12: =F9+F10+F11 -> 13.435315 | G12: =G9+G10+G11 -> 16.280247 | H12: =H9+H10+H11 -> 19.422135 | I12: =I9+I10+I11 -> 20.430844 | ... CH12: =CH9+CH10+CH11 -> 4613.0208
A13: Operating Income | B13: =B8-B12 -> 2.027283 | C13: =C8-C12 -> 3.006865 | D13: =D8-D12 -> 4.802944 | E13: =E8-E12 -> 6.297371 | F13: =F8-F12 -> 7.554641 | G13: =G8-G12 -> 6.542202 | H13: =H8-H12 -> 8.14787 | I13: =I8-I12 -> 11.675937 | ... CH13: =CH8-CH12 -> 1785.2248
A14: Interest Expense / (Income) | B14: 0.465986 | C14: 0.535861 | D14: 0.451783 | E14: 0.700631 | F14: 1.049626 | G14: 1.3628 | H14: 0.958348 | I14: 1.132524 | J14: 4.988756 | K14: 2.510184 | L14: 3.334589 | M14: 3.87323 | N14: 3.639551 | O14: 2.995418 | P14: 3.355921 | Q14: 0.567969 | R14: 0.682364 | S14: 0.62895 | T14: 0.880819 | U14: 1.052865 | V14: 1.0861 | W14: 0.077317 | X14: 0.4743 | Y14: 0.31286 | Z14: 0.273902 | AA14: 0.360352 | AB14: 0.531668 | AC14: 0.487496 | AD14: 0.976484 | AE14: 1.027 | AF14: 0.778 | AG14: 4.913 | AH14: 4.941 | AI14: 4.95 | AJ14: 5.201 | AK14: 6.011 | AL14: 4.229 | AM14: 5.684 | AN14: 6.631 | AO14: 6.492 | AP14: 6.798 | AQ14: 6.471 | AR14: 6.506 | AS14: 6.709 | AT14: 6.783 | AU14: 10.734 | AV14: 13.202 | AW14: 15.869 | AX14: 16.444 | AY14: 15.559 | AZ14: 14.679 | BA14: 14.451 | BB14: 21.187 | BC14: 23.584 | BD14: 26.977 | BE14: 24.522 | BF14: 31.917 | BG14: 91 | BH14: 40 | BI14: 44 | BJ14: 54 | BK14: 56 | BL14: 73 | BM14: 92 | BN14: -86 | BO14: 34 | BP14: 49 | BQ14: 53 | BR14: 38 | BS14: 38 | BT14: 39 | BU14: 40 | BV14: 48 | BW14: 39 | BX14: 36 | BY14: 35 | BZ14: 50 | CA14: 65 | CB14: =CB6*'Assumptions (Quarterly)'!F19+'Assumptions (Quarterly)'!F23*0 -> 63.91462 | CC14: =CC6*'Assumptions (Quarterly)'!G19+'Assumptions (Quarterly)'!G23*CB93 -> 70.768739 | CD14: =CD6*'Assumptions (Quarterly)'!H19+'Assumptions (Quarterly)'!H23*CC93 -> 81.583705 | CE14: =CE6*'Assumptions (Quarterly)'!I19+'Assumptions (Quarterly)'!I23*CD93 -> 80.50448 | CF14: =CF6*'Assumptions (Quarterly)'!J19+'Assumptions (Quarterly)'!J23*CE93 -> 81.154718 | CG14: =CG6*'Assumptions (Quarterly)'!K19+'Assumptions (Quarterly)'!K23*CF93 -> 75.752342 | CH14: =CH6*'Assumptions (Quarterly)'!L19+'Assumptions (Quarterly)'!L23*CG93 -> 85.690788
A15: Other Expense / (Income) | B15: 0.056983 | C15: 0.591695 | D15: 1.939297 | E15: 1.409738 | F15: 0.562799 | G15: 0.239361 | H15: 1.779777 | I15: 2.278858 | J15: -4.662396 | K15: -2.805149 | L15: 0.744099 | M15: 2.719595 | N15: -0.695178 | O15: -1.191114 | P15: -0.88191 | Q15: -1.00768 | R15: -1.788066 | S15: -1.393457 | T15: -1.787281 | U15: -6.189972 | V15: -2.94573 | W15: -2.048902 | X15: -3.70867 | Y15: -2.527873 | Z15: -3.313741 | AA15: 2.901779 | AB15: -5.762196 | AC15: -4.448093 | AD15: -4.598487 | AE15: -6.065 | AF15: 12.398 | AG15: -9.594 | AH15: -9.65 | AI15: 4.262 | AJ15: -4.035 | AK15: -8.347 | AL15: -23.565 | AM15: -12.398 | AN15: -2.662 | AO15: -5.069 | AP15: -9.747 | AQ15: -12.82 | AR15: 11.097 | AS15: -15.822 | AT15: -6.721 | AU15: -14.796 | AV15: -22.492 | AW15: -12.56 | AX15: -10.431 | AY15: -20.775 | AZ15: -34.467 | BA15: -29.449 | BB15: -27.1 | BC15: -36.598 | BD15: -16.879 | BE15: 5.882 | BF15: -12.405 | BG15: -10 | BH15: -12 | BI15: -10 | BJ15: 12 | BK15: -28 | BL15: 15 | BM15: 6 | BN15: 161 | BO15: 61 | BP15: 148 | BQ15: 201 | BR15: 67 | BS15: 9 | BT15: 19 | BU15: -3 | BV15: 9 | BW15: 18 | BX15: 73 | BY15: 53 | BZ15: 55 | CA15: -33 | CB15: =CB6*'Assumptions (Quarterly)'!F20 -> 45.6533 | CC15: =CC6*'Assumptions (Quarterly)'!G20 -> 50.549099 | CD15: =CD6*'Assumptions (Quarterly)'!H20 -> 58.274075 | CE15: =CE6*'Assumptions (Quarterly)'!I20 -> 57.5032 | CF15: =CF6*'Assumptions (Quarterly)'!J20 -> 57.967656 | CG15: =CG6*'Assumptions (Quarterly)'!K20 -> 63.126952 | CH15: =CH6*'Assumptions (Quarterly)'!L20 -> 71.40899
A16: Pretax Income | B16: =B13-B14-B15 -> 1.504314 | C16: =C13-C14-C15 -> 1.879309 | D16: =D13-D14-D15 -> 2.411864 | E16: =E13-E14-E15 -> 4.187002 | F16: =F13-F14-F15 -> 5.942216 | G16: =G13-G14-G15 -> 4.940041 | H16: =H13-H14-H15 -> 5.409745 | I16: =I13-I14-I15 -> 8.264555 | ... CH16: =CH13-CH14-CH15 -> 1628.125
A17: Income Tax | B17: -0.340772 | C17: 0.885122 | D17: 1.820978 | E17: 1.401528 | F17: 0.619823 | G17: 2.872364 | H17: 2.46265 | I17: 2.388763 | J17: 2.910465 | K17: 1.671333 | L17: 1.653756 | M17: 2.537257 | N17: 3.641659 | O17: 4.079361 | P17: 4.666593 | Q17: 0.959454 | R17: 6.135233 | S17: 5.998029 | T17: 7.637033 | U17: 8.804905 | V17: 9.219854 | W17: 7.267719 | X17: 9.740098 | Y17: 9.885607 | Z17: 11.977954 | AA17: 7.8288 | AB17: 10.701182 | AC17: 12.075486 | AD17: 14.977533 | AE17: 8.775 | AF17: 6.506 | AG17: 18.062 | AH17: 15.8 | AI17: 14.655 | AJ17: 14.008 | AK17: 1.976 | AL17: 14.063 | AM17: 6.956 | AN17: 12.36 | AO17: 13.374 | AP17: 16.272 | AQ17: 21.145 | AR17: 7.106 | AS17: 8.989 | AT17: 3.049 | AU17: -12.438 | AV17: -7.7 | AW17: -4.234 | AX17: -4.495 | AY17: 3.491 | AZ17: -8.917 | BA17: 79.155 | BB17: -8.976 | BC17: 4.429 | BD17: 33.393 | BE17: 37.635 | BF17: 6.543 | BG17: 44 | BH17: 70 | BI17: 31 | BJ17: 4 | BK17: 46 | BL17: 39 | BM17: 69 | BN17: 144 | BO17: 122 | BP17: 210 | BQ17: 172 | BR17: 65 | BS17: 137 | BT17: 137 | BU17: 123 | BV17: 124 | BW17: 212 | BX17: 193 | BY17: 215 | BZ17: 225 | CA17: 162 | CB17: =CB16*'Assumptions (Quarterly)'!F21 -> 206.53553 | CC17: =CC16*'Assumptions (Quarterly)'!G21 -> 255.07075 | CD17: =CD16*'Assumptions (Quarterly)'!H21 -> 334.60974 | CE17: =CE16*'Assumptions (Quarterly)'!I21 -> 280.15559 | CF17: =CF16*'Assumptions (Quarterly)'!J21 -> 316.03966 | CG17: =CG16*'Assumptions (Quarterly)'!K21 -> 377.12041 | CH17: =CH16*'Assumptions (Quarterly)'!L21 -> 472.15624
A18: Net Income | B18: =B16-B17 -> 1.845086 | C18: =C16-C17 -> 0.994187 | D18: =D16-D17 -> 0.590886 | E18: =E16-E17 -> 2.785474 | F18: =F16-F17 -> 5.322393 | G18: =G16-G17 -> 2.067677 | H18: =H16-H17 -> 2.947095 | I18: =I16-I17 -> 5.875792 | ... CH18: =CH16-CH17 -> 1155.9687
A19: Preferred Dividends | B19: 0.12372 | C19: 0.123719 | D19: 0.12372 | E19: 0.06186 | F19: 0 | G19: 0 | H19: 0 | I19: 0 | J19: 0 | K19: 0 | L19: 0 | M19: 0 | N19: 0 | O19: 0 | P19: 0 | Q19: 0 | R19: 0 | S19: 0 | T19: 0 | U19: 0 | V19: 0 | W19: 0 | X19: 0 | Y19: 0 | Z19: 0 | AA19: 0 | AB19: 0 | AC19: 0 | AD19: 0 | AE19: 0 | AF19: 0 | AG19: 0 | AH19: 0 | AI19: 0 | AJ19: 0 | AK19: 0 | AL19: 0 | AM19: 0 | AN19: 0 | AO19: 0 | AP19: 0 | AQ19: 0 | AR19: 0 | AS19: 0 | AT19: 0 | AU19: 0 | AV19: 0 | AW19: 0 | AX19: 0 | AY19: 0 | AZ19: 0 | BA19: 0 | BB19: 0 | BC19: 0 | BD19: 0 | BE19: 0 | BF19: 0 | BG19: 0 | BH19: 0 | BI19: 0 | BJ19: 0 | BK19: 0 | BL19: 0 | BM19: 0 | BN19: 0 | BO19: 0 | BP19: 0 | BQ19: 0 | BR19: 0 | BS19: 0 | BT19: 0 | BU19: 0 | BV19: 0 | BW19: 0 | BX19: 0 | BY19: 0 | BZ19: 0 | CA19: 0 | CB19: ='Assumptions (Quarterly)'!F33 -> 0 | CC19: ='Assumptions (Quarterly)'!G33 -> 0 | CD19: ='Assumptions (Quarterly)'!H33 -> 0 | CE19: ='Assumptions (Quarterly)'!I33 -> 0 | CF19: ='Assumptions (Quarterly)'!J33 -> 0 | CG19: ='Assumptions (Quarterly)'!K33 -> 0 | CH19: ='Assumptions (Quarterly)'!L33 -> 0
A20: Net Income to Common | B20: =B18-B19 -> 1.721366 | C20: =C18-C19 -> 0.870468 | D20: =D18-D19 -> 0.467166 | E20: =E18-E19 -> 2.723614 | F20: =F18-F19 -> 5.322393 | G20: =G18-G19 -> 2.067677 | H20: =H18-H19 -> 2.947095 | I20: =I18-I19 -> 5.875792 | ... CH20: =CH18-CH19 -> 1155.9687
A22: Shares Outstanding (Basic) | B22: 13.199908 | C22: 13.375482 | D22: 13.575158 | E22: 27.538652 | F22: 25.149405 | G22: 44.22746 | H22: 44.238166 | I22: 44.29054 | J22: 44.189817 | K22: 44.069134 | L22: 44.078235 | M22: 44.088936 | N22: 44.110055 | O22: 44.113595 | P22: 44.121087 | Q22: 44.129762 | R22: 44.131455 | S22: 44.131383 | T22: 44.138105 | U22: 44.141925 | V22: 44.14206 | W22: 44.142076 | X22: 44.147999 | Y22: 44.150387 | Z22: 44.150942 | AA22: 44.151323 | AB22: 44.152933 | AC22: 44.152933 | AD22: 44.153194 | AE22: 44.153818 | AF22: 44.153892 | AG22: 44.153892 | AH22: 44.153935 | AI22: 44.154796 | AJ22: 44.155271 | AK22: 44.15583 | AL22: 44.156811 | AM22: 44.156961 | AN22: 44.157341 | AO22: 44.157341 | AP22: 44.157359 | AQ22: 44.157364 | AR22: 44.157364 | AS22: 44.157364 | AT22: 44.157364 | AU22: 44.157364 | AV22: 44.157364 | AW22: 44.588704 | AX22: 45.210284 | AY22: 45.980255 | AZ22: 49.318522 | BA22: 49.710723 | BB22: 49.721129 | BC22: 49.709955 | BD22: 49.709973 | BE22: 49.720854 | BF22: 49.820765 | BG22: 49.867625 | BH22: 49.822272 | BI22: 49.597157 | BJ22: 49.927892 | BK22: 50.408754 | BL22: 50.364529 | BM22: 50.325075 | BN22: 50.283973 | BO22: 50.245073 | BP22: 50.162687 | BQ22: 50.00832 | BR22: 50.63573 | BS22: 50.697442 | BT22: 50.697447 | BU22: 50.697438 | BV22: 50.697386 | BW22: 50.697375 | BX22: 50.697375 | BY22: 50.697265 | BZ22: 50.697182 | CA22: 50.697182 | CB22: =CA22*(1+'Assumptions (Quarterly)'!F22) -> 50.646485 | CC22: =CB22*(1+'Assumptions (Quarterly)'!G22) -> 50.595838 | CD22: =CC22*(1+'Assumptions (Quarterly)'!H22) -> 50.545242 | CE22: =CD22*(1+'Assumptions (Quarterly)'!I22) -> 50.494697 | CF22: =CE22*(1+'Assumptions (Quarterly)'!J22) -> 50.444203 | CG22: =CF22*(1+'Assumptions (Quarterly)'!K22) -> 50.393758 | CH22: =CG22*(1+'Assumptions (Quarterly)'!L22) -> 50.343365
A23: Shares Outstanding (Diluted) | B23: 0 | C23: 13.375482 | D23: 13.987128 | E23: 27.685028 | F23: 25.478336 | G23: 44.368011 | H23: 44.369317 | I23: 44.379682 | J23: 44.273428 | K23: 44.130866 | L23: 44.132204 | M23: 44.138031 | N23: 44.187238 | O23: 44.1497 | P23: 44.145255 | Q23: 44.151367 | R23: 44.153398 | S23: 44.147667 | T23: 44.152296 | U23: 44.151218 | V23: 44.153132 | W23: 44.147796 | X23: 44.152133 | Y23: 44.157321 | Z23: 44.138018 | AA23: 44.151357 | AB23: 44.152933 | AC23: 44.152933 | AD23: 44.153194 | AE23: 44.153818 | AF23: 44.182668 | AG23: 44.153892 | AH23: 44.153935 | AI23: 44.154796 | AJ23: 44.155271 | AK23: 44.15583 | AL23: 44.156811 | AM23: 44.156961 | AN23: 44.157341 | AO23: 44.157341 | AP23: 44.157359 | AQ23: 44.157364 | AR23: 44.157364 | AS23: 44.157364 | AT23: 44.157364 | AU23: 44.157364 | AV23: 44.157364 | AW23: 44.588704 | AX23: 45.210284 | AY23: 45.980255 | AZ23: 49.318522 | BA23: 49.710723 | BB23: 49.721129 | BC23: 49.709955 | BD23: 49.709973 | BE23: 49.720854 | BF23: 49.820765 | BG23: 49.867625 | BH23: 49.822272 | BI23: 49.597157 | BJ23: 49.927892 | BK23: 50.408754 | BL23: 50.364529 | BM23: 51.315343 | BN23: 51.274241 | BO23: 51.235341 | BP23: 51.152955 | BQ23: 50.209439 | BR23: 53.010605 | BS23: 50.697442 | BT23: 50.697447 | BU23: 50.697438 | BV23: 50.697386 | BW23: 50.697375 | BX23: 50.697375 | BY23: 50.697284 | BZ23: 50.697248 | CA23: 50.697298 | CB23: =CA23*(1+'Assumptions (Quarterly)'!F22) -> 50.646601 | CC23: =CB23*(1+'Assumptions (Quarterly)'!G22) -> 50.595954 | CD23: =CC23*(1+'Assumptions (Quarterly)'!H22) -> 50.545358 | CE23: =CD23*(1+'Assumptions (Quarterly)'!I22) -> 50.494813 | CF23: =CE23*(1+'Assumptions (Quarterly)'!J22) -> 50.444318 | CG23: =CF23*(1+'Assumptions (Quarterly)'!K22) -> 50.393874 | CH23: =CG23*(1+'Assumptions (Quarterly)'!L22) -> 50.34348
A24: EPS (Basic) | B24: =IF(B22=0,"",B20/B22) -> 0.13040742 | C24: =IF(C22=0,"",C20/C22) -> 0.065079374 | D24: =IF(D22=0,"",D20/D22) -> 0.034413301 | E24: =IF(E22=0,"",E20/E22) -> 0.0989015 | F24: =IF(F22=0,"",F20/F22) -> 0.21163097 | G24: =IF(G22=0,"",G20/G22) -> 0.046750978 | H24: =IF(H22=0,"",H20/H22) -> 0.066618833 | I24: =IF(I22=0,"",I20/I22) -> 0.13266472 | ... CA24: =IF(CA22=0,"",CA20/CA22) -> 8.2253092 | CB24: =CB20/CB22 -> 9.9840286 | CC24: =CC20/CC22 -> 12.342588 | CD24: =CD20/CD22 -> 16.207598 | CE24: =CE20/CE22 -> 13.583568 | CF24: =CF20/CF22 -> 15.338775 | CG24: =CG20/CG22 -> 18.32161 | CH24: =CH20/CH22 -> 22.96169
A25: EPS (Diluted) | B25: =IF(B23=0,"",B20/B23) | C25: =IF(C23=0,"",C20/C23) -> 0.065079374 | D25: =IF(D23=0,"",D20/D23) -> 0.033399709 | E25: =IF(E23=0,"",E20/E23) -> 0.098378589 | F25: =IF(F23=0,"",F20/F23) -> 0.20889877 | G25: =IF(G23=0,"",G20/G23) -> 0.046602878 | H25: =IF(H23=0,"",H20/H23) -> 0.066421915 | I25: =IF(I23=0,"",I20/I23) -> 0.13239824 | ... CA25: =IF(CA23=0,"",CA20/CA23) -> 8.2252904 | CB25: =CB20/CB23 -> 9.9840057 | CC25: =CC20/CC23 -> 12.342559 | CD25: =CD20/CD23 -> 16.20756 | CE25: =CE20/CE23 -> 13.583537 | CF25: =CF20/CF23 -> 15.33874 | CG25: =CG20/CG23 -> 18.321568 | CH25: =CH20/CH23 -> 22.961637
A27: BALANCE SHEET
A28: Cash & Equivalents | B28: 7.143027 | C28: 6.390163 | D28: 9.09493 | E28: 14.53598 | F28: 15.677407 | G28: 13.947927 | H28: 17.674256 | I28: 10.403585 | J28: 17.474112 | K28: 17.006309 | L28: 19.374901 | M28: 33.332506 | N28: 49.803402 | O28: 34.634299 | P28: 31.56872 | Q28: 44.4519 | R28: 56.830466 | S28: 50.968258 | T28: 44.250132 | U28: 59.083417 | V28: 67.381677 | W28: 75.874938 | X28: 87.59573 | Y28: 98.171852 | Z28: 101.489 | AA28: 122.16738 | AB28: 131.19135 | AC28: 128.09699 | AD28: 140.2851 | AE28: 131.13955 | AF28: 385.52012 | AG28: 237.50391 | AH28: 223.144 | AI28: 219.768 | AJ28: 170.391 | AK28: 173.024 | AL28: 166.881 | AM28: 144.885 | AN28: 144.016 | AO28: 187.995 | AP28: 234.14 | AQ28: 301.388 | AR28: 382.791 | AS28: 461.198 | AT28: 388.26 | AU28: 350.411 | AV28: 524.011 | AW28: 1077.73 | AX28: 464.695 | AY28: 1306.261 | AZ28: 1128.322 | BA28: 1456.965 | BB28: 1451.424 | BC28: 1265.383 | BD28: 1663.358 | BE28: 1624.129 | BF28: 2508.224 | BG28: 1188.356 | BH28: 1431.089 | BI28: 1422.561 | BJ28: 3648 | BK28: 2414 | BL28: 2253 | BM28: 2528 | BN28: 3363 | BO28: 3524 | BP28: 3824 | BQ28: 3256 | BR28: 3848 | BS28: 3818 | BT28: 3823 | BU28: 3478 | BV28: 4699 | BW28: 4498 | BX28: 6888 | BY28: 9199 | BZ28: 13537 | CA28: 15141 | CB28: =CA28+CB81 -> 16107.472 | CC28: =CB28+CC81 -> 18221.023 | CD28: =CC28+CD81 -> 21239.266 | CE28: =CD28+CE81 -> 21965.247 | CF28: =CE28+CF81 -> 23429.2 | CG28: =CF28+CG81 -> 26140.893 | CH28: =CG28+CH81 -> 29485.223
A29: Short-Term Investments | B29: 6.320656 | C29: 7.736592 | D29: 7.141477 | E29: 48.373617 | F29: 52.300007 | G29: 37.921663 | H29: 31.743124 | I29: 20.489006 | J29: 31.6394 | K29: 29.354094 | L29: 28.647386 | M29: 19.867077 | N29: 14.580185 | O29: 7.077862 | P29: 11.27962 | Q29: 6.584453 | R29: 5.342766 | S29: 3.179205 | T29: 72.384019 | U29: 67.578494 | V29: 74.92862 | W29: 82.72215 | X29: 83.016176 | Y29: 79.390492 | Z29: 93.694805 | AA29: 75.545528 | AB29: 71.299941 | AC29: 91.330179 | AD29: 76.593214 | AE29: 87.390844 | AF29: 105.22866 | AG29: 169.84359 | AH29: 148.81 | AI29: 148.052 | AJ29: 167.161 | AK29: 168.015 | AL29: 202.112 | AM29: 195.569 | AN29: 251.416 | AO29: 283.65 | AP29: 259.604 | AQ29: 276.545 | AR29: 231.455 | AS29: 227.008 | AT29: 282.841 | AU29: 281.774 | AV29: 181.498 | AW29: 157.868 | AX29: 557.319 | AY29: 1783.097 | AZ29: 1982.235 | BA29: 1902.263 | BB29: 1779.346 | BC29: 1699.744 | BD29: 2264.02 | BE29: 2426.614 | BF29: 1626.342 | BG29: 1396.676 | BH29: 1445.55 | BI29: 1814.621 | BJ29: 2009 | BK29: 3069 | BL29: 3435 | BM29: 3667 | BN29: 4043 | BO29: 4356 | BP29: 4890 | BQ29: 5656 | BR29: 6109 | BS29: 6790 | BT29: 7513 | BU29: 8759 | BV29: 9201 | BW29: 10583 | BX29: 11241 | BY29: 11525 | BZ29: 11484 | CA29: 12142 | CB29: =CB6*'Assumptions (Quarterly)'!F38 -> 12509.004 | CC29: =CC6*'Assumptions (Quarterly)'!G38 -> 13648.257 | CD29: =CD6*'Assumptions (Quarterly)'!H38 -> 15151.26 | CE29: =CE6*'Assumptions (Quarterly)'!I38 -> 14950.832 | CF29: =CF6*'Assumptions (Quarterly)'!J38 -> 14839.72 | CG29: =CG6*'Assumptions (Quarterly)'!K38 -> 15907.992 | CH29: =CH6*'Assumptions (Quarterly)'!L38 -> 17709.43
A30: Total Cash & Short-Term Investments | B30: =B28+B29 -> 13.463683 | C30: =C28+C29 -> 14.126755 | D30: =D28+D29 -> 16.236407 | E30: =E28+E29 -> 62.909597 | F30: =F28+F29 -> 67.977414 | G30: =G28+G29 -> 51.86959 | H30: =H28+H29 -> 49.41738 | I30: =I28+I29 -> 30.892591 | ... CH30: =CH28+CH29 -> 47194.653
A31: Receivables | B31: 12.171715 | C31: 12.375465 | D31: 13.353793 | E31: 19.716352 | F31: 32.374015 | G31: 28.678864 | H31: 39.60244 | I31: 40.608683 | J31: 6.178808 | K31: 6.691454 | L31: 6.430542 | M31: 7.842202 | N31: 8.654179 | O31: 10.816958 | P31: 12.403569 | Q31: 15.821176 | R31: 18.769691 | S31: 19.080174 | T31: 22.89457 | U31: 28.673498 | V31: 40.670776 | W31: 40.302502 | X31: 44.581635 | Y31: 56.246485 | Z31: 55.653528 | AA31: 61.118162 | AB31: 82.942389 | AC31: 64.489304 | AD31: 77.930111 | AE31: 84.653793 | AF31: 94.123106 | AG31: 125.71238 | AH31: 131.834 | AI31: 187.698 | AJ31: 177.094 | AK31: 242.117 | AL31: 160.374 | AM31: 240.784 | AN31: 255.492 | AO31: 257.904 | AP31: 333.339 | AQ31: 324.709 | AR31: 289.945 | AS31: 435.447 | AT31: 549.298 | AU31: 560.099 | AV31: 335.084 | AW31: 293.602 | AX31: 395.451 | AY31: 342.992 | AZ31: 473.221 | BA31: 324.379 | BB31: 415.415 | BC31: 400.863 | BD31: 689.162 | BE31: 701.293 | BF31: 912.764 | BG31: 948.485 | BH31: 1259.646 | BI31: 1498.996 | BJ31: 1937 | BK31: 2610 | BL31: 2603 | BM31: 2658 | BN31: 3076 | BO31: 2931 | BP31: 2995 | BQ31: 3536 | BR31: 3788 | BS31: 4132 | BT31: 4358 | BU31: 4801 | BV31: 5543 | BW31: 5793 | BX31: 6865 | BY31: 6946 | BZ31: 7415 | CA31: 8504 | CB31: =CB6*'Assumptions (Quarterly)'!F35 -> 8765.4336 | CC31: =CC6*'Assumptions (Quarterly)'!G35 -> 9705.427 | CD31: =CD6*'Assumptions (Quarterly)'!H35 -> 11072.074 | CE31: =CE6*'Assumptions (Quarterly)'!I35 -> 11040.614 | CF31: =CF6*'Assumptions (Quarterly)'!J35 -> 11129.79 | CG31: =CG6*'Assumptions (Quarterly)'!K35 -> 12120.375 | CH31: =CH6*'Assumptions (Quarterly)'!L35 -> 13567.708
A32: Inventory | B32: 0 | C32: 0 | D32: 0 | E32: 0 | F32: 0 | G32: 0 | H32: 0 | I32: 0 | J32: 0 | K32: 0 | L32: 0 | M32: 0 | N32: 0 | O32: 0 | P32: 0 | Q32: 0 | R32: 0 | S32: 0 | T32: 0 | U32: 0 | V32: 0 | W32: 0 | X32: 0 | Y32: 0 | Z32: 0 | AA32: 0 | AB32: 0 | AC32: 0 | AD32: 0 | AE32: 0 | AF32: 0 | AG32: 0 | AH32: 0 | AI32: 0 | AJ32: 0 | AK32: 0.135 | AL32: 0.222 | AM32: 0.42 | AN32: 0.99 | AO32: 1.388 | AP32: 1.103 | AQ32: 0.432 | AR32: 1.034 | AS32: 2.309 | AT32: 2.549 | AU32: 3.362 | AV32: 7.938 | AW32: 7.395 | AX32: 4.612 | AY32: 3.003 | AZ32: 5.95 | BA32: 10.132 | BB32: 8.626 | BC32: 12.114 | BD32: 20.831 | BE32: 46.644 | BF32: 118.14 | BG32: 131.46 | BH32: 169.449 | BI32: 226.694 | BJ32: 253 | BK32: 239 | BL32: 183 | BM32: 160 | BN32: 152 | BO32: 199 | BP32: 236 | BQ32: 246 | BR32: 238 | BS32: 223 | BT32: 257 | BU32: 322 | BV32: 296 | BW32: 358 | BX32: 434 | BY32: 532 | BZ32: 570 | CA32: 677 | CB32: =CB6*'Assumptions (Quarterly)'!F36 -> 703.06082 | CC32: =CC6*'Assumptions (Quarterly)'!G36 -> 778.45613 | CD32: =CD6*'Assumptions (Quarterly)'!H36 -> 885.76594 | CE32: =CE6*'Assumptions (Quarterly)'!I36 -> 885.54928 | CF32: =CF6*'Assumptions (Quarterly)'!J36 -> 892.7019 | CG32: =CG6*'Assumptions (Quarterly)'!K36 -> 972.15506 | CH32: =CH6*'Assumptions (Quarterly)'!L36 -> 1085.4166
A33: Other Current Assets | B33: 3.48448 | C33: 3.878033 | D33: 3.816206 | E33: 3.455271 | F33: 4.622741 | G33: 7.296034 | H33: 6.173713 | I33: 7.614242 | J33: 5.008904 | K33: 4.22251 | L33: 9.944814 | M33: 13.350809 | N33: 9.09725 | O33: 9.366018 | P33: 12.03249 | Q33: 18.57764 | R33: 20.692285 | S33: 20.996826 | T33: 19.692995 | U33: 19.155538 | V33: 17.264482 | W33: 18.299573 | X33: 18.350863 | Y33: 21.102893 | Z33: 24.52384 | AA33: 29.733988 | AB33: 27.565935 | AC33: 33.832618 | AD33: 31.355806 | AE33: 34.026946 | AF33: 29.344268 | AG33: 36.831743 | AH33: 28.962 | AI33: 32.657 | AJ33: 32.708 | AK33: 41.923 | AL33: 15.584 | AM33: 23.391 | AN33: 21.353 | AO33: 28.17 | AP33: 41.275 | AQ33: 43.318 | AR33: 52.96 | AS33: 56.194 | AT33: 63.971 | AU33: 89.914 | AV33: 76.623 | AW33: 65.084 | AX33: 89.046 | AY33: 85.1 | AZ33: 86.704 | BA33: 86.891 | BB33: 134.045 | BC33: 132.17 | BD33: 117.183 | BE33: 125.211 | BF33: 181.337 | BG33: 235.214 | BH33: 261.917 | BI33: 320.249 | BJ33: 328 | BK33: 373 | BL33: 389 | BM33: 338 | BN33: 319 | BO33: 326 | BP33: 345 | BQ33: 356 | BR33: 277 | BS33: 542 | BT33: 528 | BU33: 464 | BV33: 403 | BW33: 508 | BX33: 634 | BY33: 593 | BZ33: 567 | CA33: 659 | CB33: =CB6*'Assumptions (Quarterly)'!F37 -> 684.7995 | CC33: =CC6*'Assumptions (Quarterly)'!G37 -> 758.23649 | CD33: =CD6*'Assumptions (Quarterly)'!H37 -> 862.45631 | CE33: =CE6*'Assumptions (Quarterly)'!I37 -> 862.548 | CF33: =CF6*'Assumptions (Quarterly)'!J37 -> 869.51484 | CG33: =CG6*'Assumptions (Quarterly)'!K37 -> 946.90428 | CH33: =CH6*'Assumptions (Quarterly)'!L37 -> 1056.8531
A34: Total Current Assets | B34: =B30+B31+B32+B33 -> 29.119878 | C34: =C30+C31+C32+C33 -> 30.380253 | D34: =D30+D31+D32+D33 -> 33.406406 | E34: =E30+E31+E32+E33 -> 86.08122 | F34: =F30+F31+F32+F33 -> 104.97417 | G34: =G30+G31+G32+G33 -> 87.844488 | H34: =H30+H31+H32+H33 -> 95.193533 | I34: =I30+I31+I32+I33 -> 79.115516 | ... CH34: =CH30+CH31+CH32+CH33 -> 62904.63
A35: Property, Plant & Equipment | B35: 2.93147 | C35: 3.076521 | D35: 4.017032 | E35: 4.171087 | F35: 4.143204 | G35: 4.732349 | H35: 5.676382 | I35: 5.874868 | J35: 5.94016 | K35: 6.730431 | L35: 6.402482 | M35: 6.394512 | N35: 5.948276 | O35: 7.263001 | P35: 7.6891 | Q35: 19.062411 | R35: 20.817712 | S35: 22.672952 | T35: 31.316388 | U35: 31.351966 | V35: 30.877719 | W35: 33.117055 | X35: 35.103153 | Y35: 35.217386 | Z35: 37.726222 | AA35: 38.0172 | AB35: 80.081659 | AC35: 80.00011 | AD35: 131.37191 | AE35: 129.46493 | AF35: 83.780843 | AG35: 83.926941 | AH35: 91.545 | AI35: 75.945 | AJ35: 82.735 | AK35: 82.51 | AL35: 81.633 | AM35: 89.932 | AN35: 104.808 | AO35: 121.006 | AP35: 124.261 | AQ35: 131.968 | AR35: 130.594 | AS35: 136.101 | AT35: 114.837 | AU35: 122.859 | AV35: 113.17 | AW35: 138.417 | AX35: 165.614 | AY35: 342.455 | AZ35: 373.848 | BA35: 395.876 | BB35: 444.706 | BC35: 422.783 | BD35: 449.892 | BE35: 527.834 | BF35: 694.898 | BG35: 803.953 | BH35: 1015.25 | BI35: 1092.334 | BJ35: 1268 | BK35: 1509 | BL35: 1457 | BM35: 1532 | BN35: 1649 | BO35: 1733 | BP35: 1869 | BQ35: 1877 | BR35: 2149 | BS35: 2132 | BT35: 1993 | BU35: 2251 | BV35: 2478 | BW35: 2825 | BX35: 3463 | BY35: 4100 | BZ35: 4504 | CA35: 4815 | CB35: =CA35+CB6*'Assumptions (Quarterly)'!F28-CB6*'Assumptions (Quarterly)'!F26 -> 4961.0906 | CC35: =CB35+CC6*'Assumptions (Quarterly)'!G28-CC6*'Assumptions (Quarterly)'!G26 -> 5122.8477 | CD35: =CC35+CD6*'Assumptions (Quarterly)'!H28-CD6*'Assumptions (Quarterly)'!H26 -> 5297.6699 | CE35: =CD35+CE6*'Assumptions (Quarterly)'!I28-CE6*'Assumptions (Quarterly)'!I26 -> 5470.1795 | CF35: =CE35+CF6*'Assumptions (Quarterly)'!J28-CF6*'Assumptions (Quarterly)'!J26 -> 5632.4889 | CG35: =CF35+CG6*'Assumptions (Quarterly)'!K28-CG6*'Assumptions (Quarterly)'!K26 -> 5796.619 | CH35: =CG35+CH6*'Assumptions (Quarterly)'!L28-CH6*'Assumptions (Quarterly)'!L26 -> 5968.0006
A36: Long-Term Investments | B36: 0 | C36: 1.437402 | D36: 1.447859 | E36: 1.459271 | F36: 1.323789 | G36: 1.427431 | H36: 2.244276 | I36: 3.057065 | J36: 9.218153 | K36: 13.763469 | L36: 22.402035 | M36: 24.314404 | N36: 26.627357 | O36: 54.864792 | P36: 66.112729 | Q36: 65.852573 | R36: 78.846281 | S36: 101.82432 | T36: 50.201025 | U36: 41.002762 | V36: 43.933316 | W36: 43.084473 | X36: 49.571882 | Y36: 59.418012 | Z36: 85.955584 | AA36: 94.956562 | AB36: 59.437585 | AC36: 69.806906 | AD36: 45.719737 | AE36: 45.001998 | AF36: 52.145285 | AG36: 158.83905 | AH36: 205.265 | AI36: 190.152 | AJ36: 209.324 | AK36: 185.733 | AL36: 187.621 | AM36: 187.889 | AN36: 157.832 | AO36: 155.178 | AP36: 153.803 | AQ36: 170.352 | AR36: 186.322 | AS36: 45.55 | AT36: 34.72 | AU36: 33.41 | AV36: 11.394 | AW36: 2.823 | AX36: 276.136 | AY36: 275.432 | AZ36: 207.047 | BA36: 3.595 | BB36: 270.422 | BC36: 276.834 | BD36: 10.845 | BE36: 21.963 | BF36: 182.73 | BG36: 194.45 | BH36: 204.68 | BI36: 69.211 | BJ36: 150 | BK36: 201 | BL36: 511 | BM36: 417 | BN36: 354 | BO36: 309 | BP36: 225 | BQ36: 191 | BR36: 227 | BS36: 335 | BT36: 527 | BU36: 1382 | BV36: 1382 | BW36: 1546 | BX36: 1665 | BY36: 1718 | BZ36: 2274 | CA36: 2262 | CB36: =CA36*(1+'Assumptions (Quarterly)'!F44) -> 2318.55 | CC36: =CB36*(1+'Assumptions (Quarterly)'!G44) -> 2376.5138 | CD36: =CC36*(1+'Assumptions (Quarterly)'!H44) -> 2435.9266 | CE36: =CD36*(1+'Assumptions (Quarterly)'!I44) -> 2496.8248 | CF36: =CE36*(1+'Assumptions (Quarterly)'!J44) -> 2559.2454 | CG36: =CF36*(1+'Assumptions (Quarterly)'!K44) -> 2623.2265 | CH36: =CG36*(1+'Assumptions (Quarterly)'!L44) -> 2688.8072
A37: Goodwill & Intangibles | B37: 21.342315 | C37: 21.707341 | D37: 22.645835 | E37: 23.018001 | F37: 23.428646 | G37: 42.812153 | H37: 43.893181 | I37: 80.592075 | J37: 72.911546 | K37: 71.431003 | L37: 74.488034 | M37: 75.525514 | N37: 64.338564 | O37: 63.769288 | P37: 62.932379 | Q37: 64.790278 | R37: 64.637481 | S37: 64.459731 | T37: 65.17578 | U37: 69.571885 | V37: 68.588805 | W37: 70.562274 | X37: 68.7351 | Y37: 68.892998 | Z37: 67.645928 | AA37: 69.986076 | AB37: 66.275789 | AC37: 64.294149 | AD37: 61.692803 | AE37: 58.353034 | AF37: 95.950947 | AG37: 90.373013 | AH37: 92 | AI37: 88.378 | AJ37: 136.105 | AK37: 122.366 | AL37: 115.536 | AM37: 120.435 | AN37: 125.276 | AO37: 122.218 | AP37: 118.074 | AQ37: 122.076 | AR37: 119.477 | AS37: 119.891 | AT37: 115.453 | AU37: 116.106 | AV37: 102.893 | AW37: 107.369 | AX37: 107.464 | AY37: 107.51 | AZ37: 107.183 | BA37: 101.228 | BB37: 101.884 | BC37: 99.416 | BD37: 97.741 | BE37: 93.294 | BF37: 99.366 | BG37: 103.101 | BH37: 109.059 | BI37: 111.658 | BJ37: 193 | BK37: 205 | BL37: 180 | BM37: 176 | BN37: 178 | BO37: 184 | BP37: 188 | BQ37: 180 | BR37: 198 | BS37: 210 | BT37: 198 | BU37: 195 | BV37: 210 | BW37: 247 | BX37: 268 | BY37: 277 | BZ37: 196 | CA37: 198 | CB37: ='Assumptions (Quarterly)'!F46 -> 198 | CC37: ='Assumptions (Quarterly)'!G46 -> 198 | CD37: ='Assumptions (Quarterly)'!H46 -> 198 | CE37: ='Assumptions (Quarterly)'!I46 -> 198 | CF37: ='Assumptions (Quarterly)'!J46 -> 198 | CG37: ='Assumptions (Quarterly)'!K46 -> 198 | CH37: ='Assumptions (Quarterly)'!L46 -> 198
A38: Other Long-Term Assets | B38: 0.418909 | C38: 0.577082 | D38: 0.706186 | E38: 0.728962 | F38: 0.622991 | G38: 0.260147 | H38: 0.40884 | I38: 0.485237 | J38: 8.367666 | K38: 11.69922 | L38: 15.529518 | M38: 14.856998 | N38: 3.565436 | O38: 4.545014 | P38: 4.623123 | Q38: 5.592221 | R38: 3.746341 | S38: 3.551709 | T38: 2.611067 | U38: 8.92603 | V38: 12.286041 | W38: 12.606491 | X38: 11.597194 | Y38: 12.184434 | Z38: 11.980367 | AA38: 11.695895 | AB38: 10.787587 | AC38: 37.470985 | AD38: 27.414089 | AE38: 27.827577 | AF38: 41.871676 | AG38: 36.167992 | AH38: 45.288 | AI38: 34.133 | AJ38: 45.117 | AK38: 53.005 | AL38: 73.643 | AM38: 80.164 | AN38: 78.966 | AO38: 98.548 | AP38: 101.836 | AQ38: 112.858 | AR38: 116.86 | AS38: 134.594 | AT38: 121.258 | AU38: 161.752 | AV38: 166.83 | AW38: 168.063 | AX38: 179.182 | AY38: 202.31 | AZ38: 230.982 | BA38: 158.012 | BB38: 175.823 | BC38: 148.773 | BD38: 139.704 | BE38: 170.737 | BF38: 202.531 | BG38: 196.16 | BH38: 246.054 | BI38: 243.693 | BJ38: 315 | BK38: 403 | BL38: 436 | BM38: 486 | BN38: 602 | BO38: 639 | BP38: 671 | BQ38: 826 | BR38: 778 | BS38: 880 | BT38: 833 | BU38: 971 | BV38: 984 | BW38: 1324 | BX38: 1490 | BY38: 1801 | BZ38: 2120 | CA38: 2536 | CB38: =CB6*'Assumptions (Quarterly)'!F42 -> 2620.4994 | CC38: =CC6*'Assumptions (Quarterly)'!G42 -> 2901.5183 | CD38: =CD6*'Assumptions (Quarterly)'!H42 -> 3344.9319 | CE38: =CE6*'Assumptions (Quarterly)'!I42 -> 3300.6837 | CF38: =CF6*'Assumptions (Quarterly)'!J42 -> 3327.3435 | CG38: =CG6*'Assumptions (Quarterly)'!K42 -> 3623.487 | CH38: =CH6*'Assumptions (Quarterly)'!L42 -> 4098.876
A39: Total Long-Term Assets | B39: =B35+B36+B37+B38 -> 24.692694 | C39: =C35+C36+C37+C38 -> 26.798346 | D39: =D35+D36+D37+D38 -> 28.816912 | E39: =E35+E36+E37+E38 -> 29.377321 | F39: =F35+F36+F37+F38 -> 29.51863 | G39: =G35+G36+G37+G38 -> 49.23208 | H39: =H35+H36+H37+H38 -> 52.222679 | I39: =I35+I36+I37+I38 -> 90.009245 | ... CH39: =CH35+CH36+CH37+CH38 -> 12953.684
A40: Total Assets | B40: =B34+B39 -> 53.812572 | C40: =C34+C39 -> 57.178599 | D40: =D34+D39 -> 62.223318 | E40: =E34+E39 -> 115.45854 | F40: =F34+F39 -> 134.4928 | G40: =G34+G39 -> 137.07657 | H40: =H34+H39 -> 147.41621 | I40: =I34+I39 -> 169.12476 | ... CH40: =CH34+CH39 -> 75858.314
A42: Accounts Payable | B42: 17.516569 | C42: 18.523162 | D42: 19.217765 | E42: 23.939185 | F42: 29.474551 | G42: 32.697175 | H42: 36.478364 | I42: 42.278878 | J42: 36.396861 | K42: 38.59461 | L42: 43.93758 | M42: 51.31934 | N42: 43.053044 | O42: 46.408974 | P42: 49.797292 | Q42: 54.929348 | R42: 66.020328 | S42: 70.716898 | T42: 78.509696 | U42: 78.873056 | V42: 106.83696 | W42: 92.21449 | X42: 120.5434 | Y42: 130.02019 | Z42: 148.87618 | AA42: 164.37241 | AB42: 171.55803 | AC42: 187.36745 | AD42: 195.81208 | AE42: 201.09901 | AF42: 215.27997 | AG42: 254.492 | AH42: 263.143 | AI42: 299.753 | AJ42: 303.703 | AK42: 338.216 | AL42: 308.625 | AM42: 350.219 | AN42: 406.621 | AO42: 468.284 | AP42: 540.87 | AQ42: 590.834 | AR42: 646.723 | AS42: 784.269 | AT42: 894.257 | AU42: 938.51 | AV42: 793.89 | AW42: 836.849 | AX42: 991.28 | AY42: 1035.463 | AZ42: 1194.486 | BA42: 1170.994 | BB42: 1395.01 | BC42: 1130.178 | BD42: 1882.587 | BE42: 2117.247 | BF42: 2757.641 | BG42: 2354.038 | BH42: 2919.934 | BI42: 3193.656 | BJ42: 4083 | BK42: 4258 | BL42: 4373 | BM42: 4480 | BN42: 5736 | BO42: 5829 | BP42: 6600 | BQ42: 7202 | BR42: 8229 | BS42: 9145 | BT42: 9946 | BU42: 11175 | BV42: 12841 | BW42: 13553 | BX42: 16555 | BY42: 18519 | BZ42: 22218 | CA42: 24555 | CB42: =CB6*'Assumptions (Quarterly)'!F39 -> 25383.235 | CC42: =CC6*'Assumptions (Quarterly)'!G39 -> 28307.495 | CD42: =CD6*'Assumptions (Quarterly)'!H39 -> 32400.386 | CE42: =CE6*'Assumptions (Quarterly)'!I39 -> 32201.792 | CF42: =CF6*'Assumptions (Quarterly)'!J39 -> 32693.758 | CG42: =CG6*'Assumptions (Quarterly)'!K39 -> 35856.109 | CH42: =CH6*'Assumptions (Quarterly)'!L39 -> 40274.67
A43: Deferred Revenue | B43: 0 | C43: 0 | D43: 0 | E43: 0 | F43: 0 | G43: 0 | H43: 0 | I43: 0 | J43: 0 | K43: 0 | L43: 0 | M43: 0 | N43: 0 | O43: 0 | P43: 0 | Q43: 0 | R43: 0 | S43: 0 | T43: 0 | U43: 0 | V43: 0 | W43: 0 | X43: 0 | Y43: 0 | Z43: 0 | AA43: 0 | AB43: 0 | AC43: 0 | AD43: 0 | AE43: 0 | AF43: 0 | AG43: 0 | AH43: 0 | AI43: 0 | AJ43: 0 | AK43: 0 | AL43: 0 | AM43: 0 | AN43: 0 | AO43: 0 | AP43: 0 | AQ43: 0 | AR43: 0 | AS43: 0 | AT43: 0 | AU43: 0 | AV43: 0 | AW43: 0 | AX43: 0 | AY43: 0 | AZ43: 0 | BA43: 0 | BB43: 0 | BC43: 0 | BD43: 0 | BE43: 0 | BF43: 0 | BG43: 0 | BH43: 0 | BI43: 0 | BJ43: 0 | BK43: 0 | BL43: 0 | BM43: 0 | BN43: 0 | BO43: 0 | BP43: 0 | BQ43: 0 | BR43: 0 | BS43: 0 | BT43: 0 | BU43: 0 | BV43: 0 | BW43: 0 | BX43: 0 | BY43: 0 | BZ43: 0 | CA43: 0 | CB43: 0 | CC43: 0 | CD43: 0 | CE43: 0 | CF43: 0 | CG43: 0 | CH43: 0
