Workbook

Sheet Financials
A1: MRVL — Equity Research Model
A2: All figures in $mm unless noted | Blue = forecast
B3: Q2FY23 | C3: Q3FY23 | D3: Q4FY23 | E3: Q1FY24 | F3: Q2FY24 | G3: Q3FY24 | H3: Q4FY24 | I3: Q1FY25 | J3: Q2FY25 | K3: Q3FY25 | L3: Q4FY25 | M3: Q1FY26 | N3: Q2FY26 | O3: Q3FY26 | P3: Q4FY26 | Q3: Q1FY27 | R3: Q2FY27E | S3: Q3FY27E | T3: Q4FY27E | U3: Q1FY28E | V3: Q2FY28E | W3: Q3FY28E | X3: Q4FY28E | Y3: Q1FY29E
A4: Stock
A5: Current Stock Price | B5: 290.79
A6: Market Cap ($mm) | B6: =$B$5*$Q$37
A7: Cash ($mm) | B7: =Q48+Q49
A8: Debt ($mm) | B8: =Q62+Q63+Q67
A9: Enterprise Value ($mm) | B9: =$B$6+$B$8-$B$7
A10: Trailing P/E | B10: =$B$5/($N$35+$O$35+$P$35+$Q$35)
A11: Trailing EV/EBIT | B11: =$B$9/($N$39+$O$39+$P$39+$Q$39)
A12: Trailing EV/EBITDA | B12: =$B$9/($N$40+$O$40+$P$40+$Q$40)
A13: Trailing EV/FCFE | B13: =$B$9/($N$109+$O$109+$P$109+$Q$109)
A14: EPS Yield | B14: =($N$35+$O$35+$P$35+$Q$35)/($B$5)
A16: INCOME STATEMENT
B17: Q2FY23 | C17: Q3FY23 | D17: Q4FY23 | E17: Q1FY24 | F17: Q2FY24 | G17: Q3FY24 | H17: Q4FY24 | I17: Q1FY25 | J17: Q2FY25 | K17: Q3FY25 | L17: Q4FY25 | M17: Q1FY26 | N17: Q2FY26 | O17: Q3FY26 | P17: Q4FY26 | Q17: Q1FY27 | R17: Q2FY27E | S17: Q3FY27E | T17: Q4FY27E | U17: Q1FY28E | V17: Q2FY28E | W17: Q3FY28E | X17: Q4FY28E | Y17: Q1FY29E
A18: Total Revenue | B18: 1516.9 | C18: 1537.3 | D18: 1418.5 | E18: 1321.7 | F18: 1340.9 | G18: 1418.6 | H18: 1426.5 | I18: 1160.9 | J18: 1272.9 | K18: 1516.1 | L18: 1817.4 | M18: 1895.3 | N18: 2006.1 | O18: 2074.5 | P18: 2218.7 | Q18: 2417.8 | R18: ='Assumptions'!$R$5 | S18: ='Assumptions'!$S$5 | T18: ='Assumptions'!$T$5 | U18: ='Assumptions'!$U$5 | V18: ='Assumptions'!$V$5 | W18: ='Assumptions'!$W$5 | X18: ='Assumptions'!$X$5 | Y18: ='Assumptions'!$Y$5
A19: Cost of Revenue | B19: 730.9 | C19: 760 | D19: 745.2 | E19: 764.5 | F19: 819.8 | G19: 867.4 | H19: 762.4 | I19: 633.1 | J19: 685.3 | K19: 1166.7 | L19: 900 | M19: 942.9 | N19: 995.5 | O19: 1004.7 | P19: 1070.8 | Q19: 1157 | R19: =$R$18*(1-'Assumptions'!$R$9) | S19: =$S$18*(1-'Assumptions'!$S$9) | T19: =$T$18*(1-'Assumptions'!$T$9) | U19: =$U$18*(1-'Assumptions'!$U$9) | V19: =$V$18*(1-'Assumptions'!$V$9) | W19: =$W$18*(1-'Assumptions'!$W$9) | X19: =$X$18*(1-'Assumptions'!$X$9) | Y19: =$Y$18*(1-'Assumptions'!$Y$9)
A20: Gross Profit | B20: 786 | C20: 777.3 | D20: 673.3 | E20: 557.2 | F20: 521.1 | G20: 551.2 | H20: 664.1 | I20: 527.8 | J20: 587.6 | K20: 349.4 | L20: 917.4 | M20: 952.4 | N20: 1010.6 | O20: 1069.8 | P20: 1147.9 | Q20: 1260.8 | R20: =$R$18-$R$19 | S20: =$S$18-$S$19 | T20: =$T$18-$T$19 | U20: =$U$18-$U$19 | V20: =$V$18-$V$19 | W20: =$W$18-$W$19 | X20: =$X$18-$X$19 | Y20: =$Y$18-$Y$19
A21: -- Gross Margin % | B21: 0.51816204 | C21: 0.50562675 | D21: 0.47465633 | E21: 0.42157827 | F21: 0.38861958 | G21: 0.38855209 | H21: 0.46554504 | I21: 0.45464726 | J21: 0.46162307 | K21: 0.23045973 | L21: 0.50478706 | M21: 0.5025062 | N21: 0.50376352 | O21: 0.51569053 | P21: 0.51737504 | Q21: 0.5214658 | R21: =$R$20/$R$18 | S21: =$S$20/$S$18 | T21: =$T$20/$T$18 | U21: =$U$20/$U$18 | V21: =$V$20/$V$18 | W21: =$W$20/$W$18 | X21: =$X$20/$X$18 | Y21: =$Y$20/$Y$18
A22: Research & Development | B22: 449 | C22: 448.1 | D22: 443.1 | E22: 480.7 | F22: 474.8 | G22: 481.1 | H22: 459.6 | I22: 476.1 | J22: 486.7 | K22: 488.6 | L22: 499 | M22: 507.7 | N22: 519 | O22: 512.5 | P22: 536 | Q22: 652.3 | R22: ='Assumptions'!$R$11 | S22: ='Assumptions'!$S$11 | T22: ='Assumptions'!$T$11 | U22: ='Assumptions'!$U$11 | V22: ='Assumptions'!$V$11 | W22: ='Assumptions'!$W$11 | X22: ='Assumptions'!$X$11 | Y22: ='Assumptions'!$Y$11
A23: Sales, General & Administrative | B23: 211.7 | C23: 207.8 | D23: 203.4 | E23: 199 | F23: 210 | G23: 213 | H23: 212 | I23: 199.9 | J23: 197.3 | K23: 205.3 | L23: 195.7 | M23: 186.4 | N23: 192.8 | O23: 189.9 | P23: 198 | Q23: 258.4 | R23: ='Assumptions'!$R$13 | S23: ='Assumptions'!$S$13 | T23: ='Assumptions'!$T$13 | U23: ='Assumptions'!$U$13 | V23: ='Assumptions'!$V$13 | W23: ='Assumptions'!$W$13 | X23: ='Assumptions'!$X$13 | Y23: ='Assumptions'!$Y$13
A24: Total Operating Expenses | R24: =$R$22+$R$23 | S24: =$S$22+$S$23 | T24: =$T$22+$T$23 | U24: =$U$22+$U$23 | V24: =$V$22+$V$23 | W24: =$W$22+$W$23 | X24: =$X$22+$X$23 | Y24: =$Y$22+$Y$23
A25: Operating Income (EBIT) | B25: 39.1 | C25: 105.8 | D25: 23.3 | E25: -182.4 | F25: -205.7 | G25: -146.3 | H25: -33.3 | I25: -152.3 | J25: -100.4 | K25: -702.8 | L25: 235.2 | M25: 270.6 | N25: 290.1 | O25: 357.8 | P25: 404.4 | Q25: 339.4 | R25: =$R$20-$R$24 | S25: =$S$20-$S$24 | T25: =$T$20-$T$24 | U25: =$U$20-$U$24 | V25: =$V$20-$V$24 | W25: =$W$20-$W$24 | X25: =$X$20-$X$24 | Y25: =$Y$20-$Y$24
A26: -- Operating Margin % | B26: 0.025776254 | C26: 0.068821961 | D26: 0.016425802 | E26: -0.13800409 | F26: -0.15340443 | G26: -0.10312985 | H26: -0.023343849 | I26: -0.13119132 | J26: -0.07887501 | K26: -0.46355781 | L26: 0.12941565 | M26: 0.14277423 | N26: 0.14460894 | O26: 0.1724753 | P26: 0.1822689 | Q26: 0.14037555 | R26: =$R$25/$R$18 | S26: =$S$25/$S$18 | T26: =$T$25/$T$18 | U26: =$U$25/$U$18 | V26: =$V$25/$V$18 | W26: =$W$25/$W$18 | X26: =$X$25/$X$18 | Y26: =$Y$25/$Y$18
A27: Interest Income | B27: 0.8 | C27: 1.5 | D27: 2.5 | E27: 2.5 | F27: 1.6 | G27: 1.7 | H27: 3 | R27: ='Assumptions'!$R$22 | S27: ='Assumptions'!$S$22 | T27: ='Assumptions'!$T$22 | U27: ='Assumptions'!$U$22 | V27: ='Assumptions'!$V$22 | W27: ='Assumptions'!$W$22 | X27: ='Assumptions'!$X$22 | Y27: ='Assumptions'!$Y$22
A28: Interest Expense | B28: 37.4 | C28: 42.4 | D28: 46.9 | E28: 50.5 | F28: 51.9 | G28: 49.6 | H28: 50.9 | I28: 46.8 | J28: 46.5 | K28: 45.6 | L28: 44.1 | M28: 44.8 | N28: 46.8 | O28: 47.9 | P28: 47.8 | Q28: 50 | R28: ='Assumptions'!$R$23 | S28: ='Assumptions'!$S$23 | T28: ='Assumptions'!$T$23 | U28: ='Assumptions'!$U$23 | V28: ='Assumptions'!$V$23 | W28: ='Assumptions'!$W$23 | X28: ='Assumptions'!$X$23 | Y28: ='Assumptions'!$Y$23
A29: Other Income (Expense), net | D29: -152.9 | E29: -49.9 | F29: -45.9 | G29: -41.2 | H29: -54 | I29: -45.5 | J29: -45.8 | K29: -47.7 | L29: -35.4 | M29: -54.7 | N29: -56.4 | O29: 1857.6 | P29: -22.8 | Q29: -256.1 | R29: =0 | S29: =0 | T29: =0 | U29: =0 | V29: =0 | W29: =0 | X29: =0 | Y29: =0
A30: Pretax Income | B30: 3.8 | C30: 65.3 | D30: -23.2 | E30: -232.3 | F30: -251.6 | G30: -187.5 | H30: -87.3 | I30: -197.8 | J30: -146.2 | K30: -750.5 | L30: 199.8 | M30: 215.9 | N30: 233.7 | O30: 2215.4 | P30: 381.6 | Q30: 83.3 | R30: =$R$25+$R$27-$R$28+$R$29 | S30: =$S$25+$S$27-$S$28+$S$29 | T30: =$T$25+$T$27-$T$28+$T$29 | U30: =$U$25+$U$27-$U$28+$U$29 | V30: =$V$25+$V$27-$V$28+$V$29 | W30: =$W$25+$W$27-$W$28+$W$29 | X30: =$X$25+$X$27-$X$28+$X$29 | Y30: =$Y$25+$Y$27-$Y$28+$Y$29
A31: Income Tax Expense | B31: -0.5 | C31: 52 | D31: -7.8 | E31: -63.4 | F31: -44.1 | G31: -23.2 | H31: 305.4 | I31: 17.8 | J31: 47.1 | K31: -74.2 | L31: -0.4 | M31: 38 | N31: 38.9 | O31: 314.1 | P31: -14.5 | Q31: 48.8 | R31: =$R$30*'Assumptions'!$R$24 | S31: =$S$30*'Assumptions'!$S$24 | T31: =$T$30*'Assumptions'!$T$24 | U31: =$U$30*'Assumptions'!$U$24 | V31: =$V$30*'Assumptions'!$V$24 | W31: =$W$30*'Assumptions'!$W$24 | X31: =$X$30*'Assumptions'!$X$24 | Y31: =$Y$30*'Assumptions'!$Y$24
A32: -- Effective Tax Rate % | B32: -0.13157895 | C32: 0.79632466 | D32: 0.3362069 | E32: 0.27292294 | F32: 0.17527822 | G32: 0.12373333 | H32: -3.4982818 | I32: -0.089989889 | J32: -0.32216142 | K32: 0.098867422 | L32: -0.002002002 | M32: 0.17600741 | N32: 0.16645272 | O32: 0.14178027 | P32: -0.037997904 | Q32: 0.58583433 | R32: ='Assumptions'!$R$24 | S32: ='Assumptions'!$S$24 | T32: ='Assumptions'!$T$24 | U32: ='Assumptions'!$U$24 | V32: ='Assumptions'!$V$24 | W32: ='Assumptions'!$W$24 | X32: ='Assumptions'!$X$24 | Y32: ='Assumptions'!$Y$24
A33: Net Income | B33: 4.3 | C33: 13.3 | D33: -15.4 | E33: -168.9 | F33: -207.5 | G33: -164.3 | H33: -392.7 | I33: -215.6 | J33: -193.3 | K33: -676.3 | L33: 200.2 | M33: 177.9 | N33: 194.8 | O33: 1901.3 | P33: 396.1 | Q33: 34.5 | R33: =$R$30-$R$31 | S33: =$S$30-$S$31 | T33: =$T$30-$T$31 | U33: =$U$30-$U$31 | V33: =$V$30-$V$31 | W33: =$W$30-$W$31 | X33: =$X$30-$X$31 | Y33: =$Y$30-$Y$31
A34: EPS (Basic) | B34: 0.01 | C34: 0.02 | D34: -0.018 | E34: -0.2 | F34: -0.24 | G34: -0.19 | H34: -0.454 | I34: -0.25 | J34: -0.22 | K34: -0.78 | L34: 0.2313 | M34: 0.21 | N34: 0.23 | O34: 2.22 | P34: 0.4602 | Q34: 0.04
A35: EPS (Diluted) | B35: 0.01 | C35: 0.02 | D35: -0.0183 | E35: -0.2 | F35: -0.24 | G35: -0.19 | H35: -0.454 | I35: -0.25 | J35: -0.22 | K35: -0.78 | L35: 0.2313 | M35: 0.2 | N35: 0.22 | O35: 2.2 | P35: 0.4558 | Q35: 0.04
A36: Shares (Basic, mm) | B36: 850.9 | C36: 852.6 | D36: 854.1 | E36: 856.7 | F36: 860.9 | G36: 862.6 | H36: 865 | I36: 865 | J36: 865.7 | K36: 865.7 | L36: 865.6 | M36: 864.8 | N36: 862.6 | O36: 855.8 | P36: 860.8 | Q36: 882 | R36: ='Assumptions'!$R$28 | S36: ='Assumptions'!$S$28 | T36: ='Assumptions'!$T$28 | U36: ='Assumptions'!$U$28 | V36: ='Assumptions'!$V$28 | W36: ='Assumptions'!$W$28 | X36: ='Assumptions'!$X$28 | Y36: ='Assumptions'!$Y$28
A37: Shares (Diluted, mm) | B37: 857.9 | C37: 858.4 | D37: 841.3 | E37: 856.7 | F37: 860.9 | G37: 862.6 | H37: 865 | I37: 865 | J37: 865.7 | K37: 865.7 | L37: 865.6 | M37: 875.6 | N37: 870.4 | O37: 863.7 | P37: 869.1 | Q37: 893.3 | R37: ='Assumptions'!$R$26 | S37: ='Assumptions'!$S$26 | T37: ='Assumptions'!$T$26 | U37: ='Assumptions'!$U$26 | V37: ='Assumptions'!$V$26 | W37: ='Assumptions'!$W$26 | X37: ='Assumptions'!$X$26 | Y37: ='Assumptions'!$Y$26
A38: NON-GAAP KPIs
A39: Clean EBIT | B39: 39.1 | C39: 105.8 | D39: 23.3 | E39: -182.4 | F39: -205.7 | G39: -146.3 | H39: -33.3 | I39: -152.3 | J39: -100.4 | K39: -702.8 | L39: 235.2 | M39: 270.6 | N39: 290.1 | O39: 357.8 | P39: 404.4 | Q39: 339.4 | R39: =$R$25 | S39: =$S$25 | T39: =$T$25 | U39: =$U$25 | V39: =$V$25 | W39: =$W$25 | X39: =$X$25 | Y39: =$Y$25
A40: Clean EBITDA | B40: 387.8 | C40: 450.1 | D40: 374.4 | E40: 166 | F40: 141.6 | G40: 195.6 | H40: 326.8 | I40: 185.2 | J40: 251.6 | K40: -361.3 | L40: 561.1 | M40: 600.5 | N40: 617.9 | O40: 673.7 | P40: 721.4 | Q40: 660
A41: Depreciation & Amortization | B41: 348.7 | C41: 344.3 | D41: 351.1 | E41: 348.4 | F41: 347.3 | G41: 341.9 | H41: 360.1 | I41: 337.5 | J41: 352 | K41: 341.5 | L41: 325.9 | M41: 329.9 | N41: 327.8 | O41: 315.9 | P41: 317 | Q41: 320.6 | R41: ='Assumptions'!$R$16 | S41: ='Assumptions'!$S$16 | T41: ='Assumptions'!$T$16 | U41: ='Assumptions'!$U$16 | V41: ='Assumptions'!$V$16 | W41: ='Assumptions'!$W$16 | X41: ='Assumptions'!$X$16 | Y41: ='Assumptions'!$Y$16
...

Sheet Assumptions
A1: MRVL — Model Assumptions
A2: Yellow = editable forecast inputs | Blue shading = forecast period
B3: Q2FY23 | C3: Q3FY23 | D3: Q4FY23 | E3: Q1FY24 | F3: Q2FY24 | G3: Q3FY24 | H3: Q4FY24 | I3: Q1FY25 | J3: Q2FY25 | K3: Q3FY25 | L3: Q4FY25 | M3: Q1FY26 | N3: Q2FY26 | O3: Q3FY26 | P3: Q4FY26 | Q3: Q1FY27 | R3: Q2FY27E | S3: Q3FY27E | T3: Q4FY27E | U3: Q1FY28E | V3: Q2FY28E | W3: Q3FY28E | X3: Q4FY28E | Y3: Q1FY29E
A4: REVENUE DRIVERS
A5: Total Revenue ($mm) | B5: 1516.9 | C5: 1537.3 | D5: 1418.5 | E5: 1321.7 | F5: 1340.9 | G5: 1418.6 | H5: 1426.5 | I5: 1160.9 | J5: 1272.9 | K5: 1516.1 | L5: 1817.4 | M5: 1895.3 | N5: 2006.1 | O5: 2074.5 | P5: 2218.7 | Q5: 2417.8 | R5: =Q5*(1+R6) | S5: =R5*(1+S6) | T5: =S5*(1+T6) | U5: =T5*(1+U6) | V5: =U5*(1+V6) | W5: =V5*(1+W6) | X5: =W5*(1+X6) | Y5: =X5*(1+Y6)
A6: Revenue Growth % (QoQ) | C6: =C5/B5-1 | D6: =D5/C5-1 | E6: =E5/D5-1 | F6: =F5/E5-1 | G6: =G5/F5-1 | H6: =H5/G5-1 | I6: =I5/H5-1 | J6: =J5/I5-1 | ... Q6: =Q5/P5-1 | R6: 0.063 | S6: 0.063 | T6: 0.063 | U6: 0.063 | V6: 0.063 | W6: 0.063 | X6: 0.063 | Y6: 0.063
A7: Revenue Growth % (YoY) | F7: =F5/B5-1 | G7: =G5/C5-1 | H7: =H5/D5-1 | I7: =I5/E5-1 | J7: =J5/F5-1 | K7: =K5/G5-1 | L7: =L5/H5-1 | M7: =M5/I5-1 | ... Y7: =Y5/U5-1
A8: MARGIN DRIVERS
A9: Gross Margin % | B9: 0.51816204 | C9: 0.50562675 | D9: 0.47465633 | E9: 0.42157827 | F9: 0.38861958 | G9: 0.38855209 | H9: 0.46554504 | I9: 0.45464726 | J9: 0.46162307 | K9: 0.23045973 | L9: 0.50478706 | M9: 0.5025062 | N9: 0.50376352 | O9: 0.51569053 | P9: 0.51737504 | Q9: 0.5214658 | R9: 0.5215 | S9: 0.5215 | T9: 0.5215 | U9: 0.5215 | V9: 0.5215 | W9: 0.5215 | X9: 0.5215 | Y9: 0.5215
A10: OPEX DRIVERS
A11: R&D ($mm) | B11: 449 | C11: 448.1 | D11: 443.1 | E11: 480.7 | F11: 474.8 | G11: 481.1 | H11: 459.6 | I11: 476.1 | J11: 486.7 | K11: 488.6 | L11: 499 | M11: 507.7 | N11: 519 | O11: 512.5 | P11: 536 | Q11: 652.3 | R11: 652.3 | S11: 652.3 | T11: 652.3 | U11: 652.3 | V11: 652.3 | W11: 652.3 | X11: 652.3 | Y11: 652.3
A12: R&D % of Revenue | B12: 0.296 | C12: 0.2915 | D12: 0.3124 | E12: 0.3637 | F12: 0.3541 | G12: 0.3391 | H12: 0.3222 | I12: 0.4101 | J12: 0.3824 | K12: 0.3223 | L12: 0.2746 | M12: 0.2679 | N12: 0.2587 | O12: 0.247 | P12: 0.2416 | Q12: 0.2698 | R12: 0.2698 | S12: 0.2698 | T12: 0.2698 | U12: 0.2698 | V12: 0.2698 | W12: 0.2698 | X12: 0.2698 | Y12: 0.2698
A13: SG&A ($mm) | B13: 211.7 | C13: 207.8 | D13: 203.4 | E13: 199 | F13: 210 | G13: 213 | H13: 212 | I13: 199.9 | J13: 197.3 | K13: 205.3 | L13: 195.7 | M13: 186.4 | N13: 192.8 | O13: 189.9 | P13: 198 | Q13: 258.4 | R13: 258.4 | S13: 258.4 | T13: 258.4 | U13: 258.4 | V13: 258.4 | W13: 258.4 | X13: 258.4 | Y13: 258.4
A14: SG&A % of Revenue | B14: 0.1396 | C14: 0.1352 | D14: 0.1434 | E14: 0.1506 | F14: 0.1566 | G14: 0.1501 | H14: 0.1486 | I14: 0.1722 | J14: 0.155 | K14: 0.1354 | L14: 0.1077 | M14: 0.0983 | N14: 0.0961 | O14: 0.0915 | P14: 0.0892 | Q14: 0.1069 | R14: 0.1069 | S14: 0.1069 | T14: 0.1069 | U14: 0.1069 | V14: 0.1069 | W14: 0.1069 | X14: 0.1069 | Y14: 0.1069
A15: D&A & CAPEX
A16: Depreciation & Amortization ($mm) | B16: 348.7 | C16: 344.3 | D16: 351.1 | E16: 348.4 | F16: 347.3 | G16: 341.9 | H16: 360.1 | I16: 337.5 | J16: 352 | K16: 341.5 | L16: 325.9 | M16: 329.9 | N16: 327.8 | O16: 315.9 | P16: 317 | Q16: 320.6 | R16: 320.6 | S16: 320.6 | T16: 320.6 | U16: 320.6 | V16: 320.6 | W16: 320.6 | X16: 320.6 | Y16: 320.6
A17: Capital Expenditures ($mm) | B17: -72.6 | C17: -42.7 | D17: -54 | E17: -99.8 | F17: -111.1 | G17: -54.4 | H17: -71 | I17: -91.5 | J17: -48.2 | K17: -75 | L17: -69.9 | M17: -118.8 | N17: -47.5 | O17: -73.5 | P17: -114.3 | Q17: -155.7 | R17: -155.7 | S17: -155.7 | T17: -155.7 | U17: -155.7 | V17: -155.7 | W17: -155.7 | X17: -155.7 | Y17: -155.7
A18: Capex % of Revenue | B18: 0.0479 | C18: 0.0278 | D18: 0.0381 | E18: 0.0755 | F18: 0.0829 | G18: 0.0383 | H18: 0.0498 | I18: 0.0788 | J18: 0.0379 | K18: 0.0495 | L18: 0.0385 | M18: 0.0627 | N18: 0.0237 | O18: 0.0354 | P18: 0.0515 | Q18: 0.0644 | R18: 0.0644 | S18: 0.0644 | T18: 0.0644 | U18: 0.0644 | V18: 0.0644 | W18: 0.0644 | X18: 0.0644 | Y18: 0.0644
A19: OTHER
A20: Stock-Based Compensation ($mm) | B20: 144.5 | C20: 146.1 | D20: 130.7 | E20: 143.2 | F20: 152.8 | G20: 158.5 | H20: 155.3 | I20: 136.5 | J20: 154.9 | K20: 158.4 | L20: 147.6 | M20: 142.1 | N20: 153.6 | O20: 152.1 | P20: 143 | Q20: 207.6 | R20: 207.6 | S20: 207.6 | T20: 207.6 | U20: 207.6 | V20: 207.6 | W20: 207.6 | X20: 207.6 | Y20: 207.6
A21: SBC % of Revenue | B21: 0.0953 | C21: 0.095 | D21: 0.0921 | E21: 0.1083 | F21: 0.114 | G21: 0.1117 | H21: 0.1089 | I21: 0.1176 | J21: 0.1217 | K21: 0.1045 | L21: 0.0812 | M21: 0.075 | N21: 0.0766 | O21: 0.0733 | P21: 0.0645 | Q21: 0.0859 | R21: 0.0859 | S21: 0.0859 | T21: 0.0859 | U21: 0.0859 | V21: 0.0859 | W21: 0.0859 | X21: 0.0859 | Y21: 0.0859
A22: Interest Income ($mm) | B22: 0.8 | C22: 1.5 | D22: 2.5 | E22: 2.5 | F22: 1.6 | G22: 1.7 | H22: 3 | R22: 0 | S22: 0 | T22: 0 | U22: 0 | V22: 0 | W22: 0 | X22: 0 | Y22: 0
A23: Interest Expense ($mm) | B23: 37.4 | C23: 42.4 | D23: 46.9 | E23: 50.5 | F23: 51.9 | G23: 49.6 | H23: 50.9 | I23: 46.8 | J23: 46.5 | K23: 45.6 | L23: 44.1 | M23: 44.8 | N23: 46.8 | O23: 47.9 | P23: 47.8 | Q23: 50 | R23: 50 | S23: 50 | T23: 50 | U23: 50 | V23: 50 | W23: 50 | X23: 50 | Y23: 50
A24: Effective Tax Rate % | B24: -0.13157895 | C24: 0.79632466 | D24: 0.3362069 | E24: 0.27292294 | F24: 0.17527822 | G24: 0.12373333 | H24: -3.4982818 | I24: -0.089989889 | J24: -0.32216142 | K24: 0.098867422 | L24: -0.002002002 | M24: 0.17600741 | N24: 0.16645272 | O24: 0.14178027 | P24: -0.037997904 | Q24: 0.58583433 | R24: 0.5858 | S24: 0.5858 | T24: 0.5858 | U24: 0.5858 | V24: 0.5858 | W24: 0.5858 | X24: 0.5858 | Y24: 0.5858
A25: SHARES
A26: Diluted Shares (mm) | B26: 857.9 | C26: 858.4 | D26: 841.3 | E26: 856.7 | F26: 860.9 | G26: 862.6 | H26: 865 | I26: 865 | J26: 865.7 | K26: 865.7 | L26: 865.6 | M26: 875.6 | N26: 870.4 | O26: 863.7 | P26: 869.1 | Q26: 893.3 | R26: 893.3 | S26: 893.3 | T26: 893.3 | U26: 893.3 | V26: 893.3 | W26: 893.3 | X26: 893.3 | Y26: 893.3
A27: QoQ Share Change (mm) | C27: =C26-B26 | D27: =D26-C26 | E27: =E26-D26 | F27: =F26-E26 | G27: =G26-F26 | H27: =H26-G26 | I27: =I26-H26 | J27: =J26-I26 | ... Y27: =Y26-X26
A28: Basic Shares (mm) | B28: 850.9 | C28: 852.6 | D28: 854.1 | E28: 856.7 | F28: 860.9 | G28: 862.6 | H28: 865 | I28: 865 | J28: 865.7 | K28: 865.7 | L28: 865.6 | M28: 864.8 | N28: 862.6 | O28: 855.8 | P28: 860.8 | Q28: 882 | R28: 882 | S28: 882 | T28: 882 | U28: 882 | V28: 882 | W28: 882 | X28: 882 | Y28: 882
A29: WORKING CAPITAL DAYS
A30: Days Sales Outstanding | B30: 77.5 | C30: 82.3 | D30: 76.5 | E30: 68.9 | F30: 82.1 | G30: 77.9 | H30: 71.5 | I30: 69.1 | J30: 75.8 | K30: 59.9 | L30: 51.5 | M30: 54.9 | N30: 65.9 | O30: 67.8 | P30: 89.7 | Q30: 70.4 | R30: 73.5 | S30: 73.5 | T30: 73.5 | U30: 73.5 | V30: 73.5 | W30: 73.5 | X30: 73.5 | Y30: 73.5
A31: Inventory Days | B31: 113.7 | C31: 114.6 | D31: 130.5 | E31: 122.1 | F31: 112.8 | G31: 98.8 | H31: 103.2 | I31: 118.8 | J31: 108.6 | K31: 67 | L31: 104.1 | M31: 103.4 | N31: 96.1 | O31: 91.9 | P31: 118 | Q31: 110.2 | R31: 104 | S31: 104 | T31: 104 | U31: 104 | V31: 104 | W31: 104 | X31: 104 | Y31: 104
A32: Days Payable Outstanding | B32: 61 | C32: 57 | D32: 56.9 | E32: 46.2 | F32: 45.8 | G32: 44 | H32: 49.1 | I32: 46.1 | J32: 60.2 | K32: 42 | L32: 62.9 | M32: 54.3 | N32: 55.8 | O32: 57.4 | P32: 91.3 | Q32: 55.8 | R32: 65.1 | S32: 65.1 | T32: 65.1 | U32: 65.1 | V32: 65.1 | W32: 65.1 | X32: 65.1 | Y32: 65.1
A33: DEBT SCHEDULE
A34: Short-term Debt ($mm) | B34: 653.5 | C34: 584 | D34: 584.4 | E34: 1517.6 | F34: 1018.6 | G34: 96.3 | H34: 107.3 | I34: 118.3 | J34: 129.3 | K34: 129.4 | L34: 129.5 | M34: 1255.2 | N34: 499.3 | O34: 499.5 | P34: 499.8 | Q34: 0 | R34: 0 | S34: 0 | T34: 0 | U34: 0 | V34: 0 | W34: 0 | X34: 0 | Y34: 0
A35: Long-term Debt ($mm) | B35: 3947.4 | C35: 3927.6 | D35: 3907.7 | E35: 3154.9 | F35: 3134.5 | G35: 4089.6 | H35: 4058.6 | I35: 4027.6 | J35: 3996.5 | K35: 3965.5 | L35: 3934.3 | M35: 2977.4 | N35: 3967.9 | O35: 3969.4 | P35: 3970.8 | Q35: 4961.3 | R35: 4961.3 | S35: 4961.3 | T35: 4961.3 | U35: 4961.3 | V35: 4961.3 | W35: 4961.3 | X35: 4961.3 | Y35: 4961.3
A36: Total Debt ($mm) | B36: =B34+B35 | C36: =C34+C35 | D36: =D34+D35 | E36: =E34+E35 | F36: =F34+F35 | G36: =G34+G35 | H36: =H34+H35 | I36: =I34+I35 | ... Y36: =Y34+Y35
