Workbook

Sheet Assumptions
A1: MSI v3 Assumptions ($mm unless noted). Blue = inputs. Yellow = Low confidence. Orange = CALIBRATION_ONLY (2026 only; reverts to historical rate after).
A3: Variable | B3: 2026 | C3: 2027 | D3: 2028 | E3: 2029 | F3: 2030 | G3: Confidence | H3: Status | I3: Damodaran | J3: Source
A4: psi_beginning_backlog | B4: 3812 | G4: High | H4: Confirmed | I4: Probable | J4: MSI FY2025 Form 10-K (SEC EDGAR, msi-20251231.htm), Item 1 Backlog table
A5: ss_beginning_backlog | B5: 11930 | G5: High | H5: Confirmed | I5: Probable | J5: MSI FY2025 Form 10-K (SEC EDGAR, msi-20251231.htm), Item 1 Backlog table
A6: psi_bookings_prior_year | B6: 6930 | G6: High | H6: Confirmed | I6: Probable | J6: MSI FY2025 Form 10-K (SEC EDGAR, msi-20251231.htm) backlog roll-forward identity
A7: ss_bookings_prior_year | B7: 5797 | G7: High | H7: Confirmed | I7: Probable | J7: MSI FY2025 Form 10-K (SEC EDGAR, msi-20251231.htm) backlog roll-forward identity
A8: company_2026_backlog_recognition_control | B8: 4800 | G8: High | H8: Confirmed | I8: Probable | J8: MSI FY2025 Form 10-K (SEC EDGAR, msi-20251231.htm) recognition sentence
A9: psi_bb_recognition_rate | B9: 0.5433 | C9: 0.57 | D9: 0.57 | E9: 0.57 | F9: 0.57 | G9: Medium | H9: Confirmed | I9: Plausible | J9: MSI FY2024 Form 10-K (SEC EDGAR, msi-20241231.htm): '~57% of P&SI segment backlog and ~24% of S&S segment backlog expected to be recognized as revenue during 2025'; 2026 value scales the disclosed 57% by 0.953 so segments sum to the $4.8B FY2025 10-K control
A10: ss_bb_recognition_rate | B10: 0.2288 | C10: 0.24 | D10: 0.24 | E10: 0.24 | F10: 0.24 | G10: Medium | H10: Confirmed | I10: Plausible | J10: MSI FY2024 Form 10-K (SEC EDGAR, msi-20241231.htm): '~57% of P&SI segment backlog and ~24% of S&S segment backlog expected to be recognized as revenue during 2025'; 2026 value scales the disclosed 24% by 0.953 so segments sum to the $4.8B FY2025 10-K control
A11: psi_bookings_yoy_change | B11: 0.1 | C11: 0.04 | D11: 0.04 | E11: 0.03 | F11: 0.03 | G11: Medium | H11: Confirmed | I11: Plausible | J11: MSI Q4/FY2025 press release, Feb 11, 2026 (record orders +26%; OBBBA) and MSI Q1 2026 press release, May 7, 2026 (Silvus 2026 revenue $750M; record Q1 orders)
A12: ss_bookings_yoy_change | B12: 0.12 | C12: 0.1 | D12: 0.08 | E12: 0.07 | F12: 0.06 | G12: Medium | H12: Confirmed | I12: Plausible | J12: MSI Q4/FY2025 press release, Feb 11, 2026 (S&S backlog +13%) and MSI Q1 2026 press release, May 7, 2026 (Q1 S&S revenue +18%; record Q1 backlog)
A13: psi_same_year_booking_conversion | B13: 0.745 | C13: 0.7065 | D13: 0.7065 | E13: 0.7065 | F13: 0.7065 | G13: Medium | H13: CALIBRATION_ONLY | I13: Plausible | J13: 2026: CALIBRATION_ONLY, solved against $12.8B guidance (74.5%). 2027+: 70.6% derived from MSI FY2024 Form 10-K (SEC EDGAR, msi-20241231.htm): '~57% of P&SI segment backlog and ~24% of S&S segment backlog expected to be recognized as revenue during 2025' disclosed 2025 expectation and the filed bookings identity
A14: ss_same_year_booking_conversion | B14: 0.3575 | C14: 0.3267 | D14: 0.3267 | E14: 0.3267 | F14: 0.3267 | G14: Medium | H14: CALIBRATION_ONLY | I14: Plausible | J14: 2026: CALIBRATION_ONLY, solved against $12.8B guidance (35.8%). 2027+: 32.7% derived from MSI FY2024 Form 10-K (SEC EDGAR, msi-20241231.htm): '~57% of P&SI segment backlog and ~24% of S&S segment backlog expected to be recognized as revenue during 2025' disclosed 2025 expectation and the filed bookings identity
A15: dfend_revenue | B15: 0 | C15: 240 | D15: 310 | E15: 390 | F15: 470 | G15: Low | H15: Confirmed | I15: Plausible | J15: D-Fend press release, June 1, 2026 ($185M expected FY2026 standalone; 50%+ growth last three years; Q4 2026 close)
A16: dfend_operating_margin | B16: 0.25 | C16: 0.25 | D16: 0.25 | E16: 0.25 | F16: 0.25 | G16: Low | H16: Confirmed | I16: Possible | J16: No disclosure; judgment placeholder near P&SI segment margin; full 10-35% sensitivity table published
A17: psi_segment_operating_margin | B17: 0.243 | C17: 0.245 | D17: 0.247 | E17: 0.248 | F17: 0.249 | G17: High | H17: Confirmed | I17: Probable | J17: MSI Q4/FY2025 press release, Feb 11, 2026 segment table: 24.3% GAAP FY2024 and FY2025
A18: ss_segment_operating_margin | B18: 0.285 | C18: 0.292 | D18: 0.298 | E18: 0.303 | F18: 0.307 | G18: Medium | H18: Confirmed | I18: Plausible | J18: MSI Q4/FY2025 press release, Feb 11, 2026 segment table: 25.7% to 27.7% GAAP
A19: net_interest_expense | B19: 430 | C19: 490 | D19: 475 | E19: 460 | F19: 445 | G19: Medium | H19: Confirmed | I19: Plausible | J19: MSI Q4/FY2025 press release, Feb 11, 2026 (Q4 run-rate ~$440M; $200M term loan repaid) and D-Fend press release, June 1, 2026 (financing undisclosed, ~5% assumed from 2027, sensitivity-tested)
A20: effective_tax_rate | B20: 0.225 | C20: 0.23 | D20: 0.23 | E20: 0.23 | F20: 0.23 | G20: Medium | H20: Confirmed | I20: Probable | J20: MSI Q4/FY2025 press release, Feb 11, 2026 (FY2025 GAAP ETR 23.2%; ~22.5% guided non-GAAP rate)
... A28: capex_pct_of_revenue | B28: 0.023 | C28: 0.023 | D28: 0.023 | E28: 0.023 | F28: 0.023 | G28: High | H28: Confirmed | I28: Probable | J28: Uploaded statements and Q4 release (2.2-2.8% five-year band)
A29: share_count_prior_year | B29: 169 | G29: High | H29: Confirmed | I29: Probable | J29: MSI Q4/FY2025 press release, Feb 11, 2026 GAAP-2 (FY2025 weighted diluted 169.0M)
A30: annual_buyback_dollars | B30: 1200 | C30: 1250 | D30: 1300 | E30: 1350 | F30: 1400 | G30: Medium | H30: Confirmed | I30: Plausible | J30: MSI Q4/FY2025 press release, Feb 11, 2026 ($1,154M FY2025 at $420.21 avg); authorization remaining USER_REQUIRED
A31: repurchase_trailing_pe_multiple | B31: 33 | C31: 33 | D31: 33 | E31: 33 | F31: 33 | G31: Low | H31: Confirmed | I31: Possible | J31: MSI ~$433 on May 7, 2026 vs FY2025 GAAP EPS $12.75 = ~34x trailing; 33x used
A32: annual_issuance_shares | B32: 0.9 | C32: 0.9 | D32: 0.9 | E32: 0.9 | F32: 0.9 | G32: Medium | H32: Confirmed | I32: Plausible | J32: FY2025 buyback bridge: diluted fell 1.8M while ~2.7M repurchased, implying ~0.9M issuance

Sheet Model
A1: Motorola Solutions (MSI) v3 - Decomposed Backlog Model ($mm except per-share). Label: PLAUSIBLE-to-PROBABLE (2026 probable-grade; outer years plausible).
A2: Allocation: FY2024 10-K disclosed recognition rates (57% P&SI / 24% S&S) scaled 0.953 to the $4.8B FY2025 10-K control. 2026 conversions CALIBRATION_ONLY; 2027+ revert to historically derived rates.
A4: Line item | B4: 2021 | C4: 2022 | D4: 2023 | E4: 2024 | F4: 2025 | G4: 2026 | H4: 2027 | I4: 2028 | J4: 2029 | K4: 2030
A5: P&SI bookings | F5: 6930 | G5: =F5*(1+Assumptions!B11) -> 7623 | H5: =G5*(1+Assumptions!C11) -> 7927.92 | I5: =H5*(1+Assumptions!D11) -> 8245.0368 | J5: =I5*(1+Assumptions!E11) -> 8492.3879 | K5: =J5*(1+Assumptions!F11) -> 8747.1595
A6: S&S bookings | F6: 5797 | G6: =F6*(1+Assumptions!B12) -> 6492.64 | H6: =G6*(1+Assumptions!C12) -> 7141.904 | I6: =H6*(1+Assumptions!D12) -> 7713.2563 | J6: =I6*(1+Assumptions!E12) -> 8253.1843 | K6: =J6*(1+Assumptions!F12) -> 8748.3753
A7: P&SI beginning backlog | G7: =Assumptions!$B$4 -> 3812 | H7: =G22 -> 3684.8054 | I7: =H22 -> 3911.3108 | J7: =I22 -> 4101.782 | K7: =J22 -> 4256.2821
A8: S&S beginning backlog | G8: =Assumptions!$B$5 -> 11930 | H8: =G23 -> 13371.937 | I8: =H23 -> 14971.316 | J8: =I23 -> 16571.536 | K8: =J23 -> 18151.236
A9: P&SI revenue from beginning backlog | G9: =G7*Assumptions!B9 -> 2071.0596 | H9: =H7*Assumptions!C9 -> 2100.3391 | I9: =I7*Assumptions!D9 -> 2229.4472 | J9: =J7*Assumptions!E9 -> 2338.0157 | K9: =K7*Assumptions!F9 -> 2426.0808
A10: P&SI revenue from same-year bookings | G10: =G5*Assumptions!B13 -> 5679.135 | H10: =H5*Assumptions!C13 -> 5601.0755 | I10: =I5*Assumptions!D13 -> 5825.1185 | J10: =J5*Assumptions!E13 -> 5999.8721 | K10: =K5*Assumptions!F13 -> 6179.8682
A11: P&SI revenue | E11: 6883 | F11: 7253 | G11: =G9+G10 -> 7750.1946 | H11: =H9+H10 -> 7701.4146 | I11: =I9+I10 -> 8054.5657 | J11: =J9+J10 -> 8337.8878 | K11: =K9+K10 -> 8605.949
A12: S&S revenue from beginning backlog | G12: =G8*Assumptions!B10 -> 2729.584 | H12: =H8*Assumptions!C10 -> 3209.2649 | I12: =I8*Assumptions!D10 -> 3593.1159 | J12: =J8*Assumptions!E10 -> 3977.1686 | K12: =K8*Assumptions!F10 -> 4356.2967
A13: S&S revenue from same-year bookings | G13: =G6*Assumptions!B14 -> 2321.1188 | H13: =H6*Assumptions!C14 -> 2333.26 | I13: =I6*Assumptions!D14 -> 2519.9208 | J13: =J6*Assumptions!E14 -> 2696.3153 | K13: =K6*Assumptions!F14 -> 2858.0942
A14: S&S revenue | E14: 3934 | F14: 4429 | G14: =G12+G13 -> 5050.7028 | H14: =H12+H13 -> 5542.525 | I14: =I12+I13 -> 6113.0367 | J14: =J12+J13 -> 6673.4839 | K14: =K12+K13 -> 7214.3909
A15: Beginning-backlog revenue vs $4.8B control | G15: =G9+G12-Assumptions!$B$8 -> 0.6436
A16: Acquisition revenue (D-Fend, from 2027) | G16: =Assumptions!B15 -> 0 | H16: =Assumptions!C15 -> 240 | I16: =Assumptions!D15 -> 310 | J16: =Assumptions!E15 -> 390 | K16: =Assumptions!F15 -> 470
A17: Total revenue | B17: 8171 | C17: 9112 | D17: 9978 | E17: 10817 | F17: 11682 | G17: =G11+G14+G16 -> 12800.897 | H17: =H11+H14+H16 -> 13483.94 | I17: =I11+I14+I16 -> 14477.602 | J17: =J11+J14+J16 -> 15401.372 | K17: =K11+K14+K16 -> 16290.34
A18: Revenue change YoY | C18: =C17/B17-1 -> 0.11516338 | D18: =D17/C17-1 -> 0.095039508 | E18: =E17/D17-1 -> 0.084084987 | F18: =F17/E17-1 -> 0.079966719 | G18: =G17/F17-1 -> 0.09577961 | H18: =H17/G17-1 -> 0.053358925 | I18: =I17/H17-1 -> 0.073692328 | J18: =J17/I17-1 -> 0.063806784 | K18: =K17/J17-1 -> 0.057720069
A19: Acquired backlog added | G19: 0 | H19: 0 | I19: 0 | J19: 0 | K19: 0
A20: Cancellations / scope changes | G20: 0 | H20: 0 | I20: 0 | J20: 0 | K20: 0
A21: FX impact on backlog | G21: 0 | H21: 0 | I21: 0 | J21: 0 | K21: 0
A22: P&SI ending backlog | D22: 4993 | E22: 4135 | F22: 3812 | G22: =G7+G5+G19-G20+G21-G9-G10 -> 3684.8054 | H22: =H7+H5+H19-H20+H21-H9-H10 -> 3911.3108 | I22: =I7+I5+I19-I20+I21-I9-I10 -> 4101.782 | J22: =J7+J5+J19-J20+J21-J9-J10 -> 4256.2821 | K22: =K7+K5+K19-K20+K21-K9-K10 -> 4397.4926
A23: S&S ending backlog | D23: 9266 | E23: 10562 | F23: 11930 | G23: =G8+G6-G12-G13 -> 13371.937 | H23: =H8+H6-H12-H13 -> 14971.316 | I23: =I8+I6-I12-I13 -> 16571.536 | J23: =J8+J6-J12-J13 -> 18151.236 | K23: =K8+K6-K12-K13 -> 19685.221
A24: Total ending backlog | D24: =D22+D23 -> 14259 | E24: =E22+E23 -> 14697 | F24: =F22+F23 -> 15742 | G24: =G22+G23 -> 17056.743 | H24: =H22+H23 -> 18882.627 | I24: =I22+I23 -> 20673.318 | J24: =J22+J23 -> 22407.518 | K24: =K22+K23 -> 24082.713
A25: P&SI book-to-bill | F25: =F5/F11 -> 0.9554667 | G25: =G5/G11 -> 0.98358821 | H25: =H5/H11 -> 1.0294109 | I25: =I5/I11 -> 1.0236476 | J25: =J5/J11 -> 1.0185299 | K25: =K5/K11 -> 1.0164085
A26: S&S book-to-bill | F26: =F6/F14 -> 1.3088733 | G26: =G6/G14 -> 1.2854924 | H26: =H6/H14 -> 1.2885651 | I26: =I6/I14 -> 1.2617716 | J26: =J6/J14 -> 1.236713 | K26: =K6/K14 -> 1.2126284
A27: Ending backlog / revenue | F27: =F24/F17 -> 1.3475432 | G27: =G24/G17 -> 1.3324646 | H27: =H24/H17 -> 1.4003791 | I27: =I24/I17 -> 1.4279518 | J27: =J24/J17 -> 1.4549041 | K27: =K24/K17 -> 1.4783432
A28: P&SI operating margin | G28: =Assumptions!B17 -> 0.243 | H28: =Assumptions!C17 -> 0.245 | I28: =Assumptions!D17 -> 0.247 | J28: =Assumptions!E17 -> 0.248 | K28: =Assumptions!F17 -> 0.249
A29: S&S operating margin | G29: =Assumptions!B18 -> 0.285 | H29: =Assumptions!C18 -> 0.292 | I29: =Assumptions!D18 -> 0.298 | J29: =Assumptions!E18 -> 0.303 | K29: =Assumptions!F18 -> 0.307
A30: Operating income (GAAP) | B30: 1667 | C30: 1661 | D30: 2294 | E30: 2688 | F30: 2988 | G30: =G11*G28+G14*G29+G16*Assumptions!B16 -> 3322.7476 | H30: =H11*H28+H14*H29+H16*Assumptions!C16 -> 3565.2639 | I30: =I11*I28+I14*I29+I16*Assumptions!D16 -> 3888.6627 | J30: =J11*J28+J14*J29+J16*Assumptions!E16 -> 4187.3618 | K30: =K11*K28+K14*K29+K16*Assumptions!F16 -> 4475.1993
A31: Operating margin | B31: =B30/B17 -> 0.2040142 | C31: =C30/C17 -> 0.18228709 | D31: =D30/D17 -> 0.22990579 | E31: =E30/E17 -> 0.24849774 | F31: =F30/F17 -> 0.25577812 | G31: =G30/G17 -> 0.25957146 | H31: =H30/H17 -> 0.26440818 | I31: =I30/I17 -> 0.26859853 | ... K31: =K30/K17 -> 0.27471491
A32: Net interest expense | B32: 208 | C32: 226 | D32: 216 | E32: 227 | F32: 302 | G32: =Assumptions!B19 -> 430 | H32: =Assumptions!C19 -> 490 | I32: =Assumptions!D19 -> 475 | J32: =Assumptions!E19 -> 460 | K32: =Assumptions!F19 -> 445
A33: Pretax income | G33: =G30-G32 -> 2892.7476 | H33: =H30-H32 -> 3075.2639 | I33: =I30-I32 -> 3413.6627 | J33: =J30-J32 -> 3727.3618 | K33: =K30-K32 -> 4030.1993
A34: Tax expense | B34: 302 | C34: 148 | D34: 432 | E34: 390 | F34: 652 | G34: =G33*Assumptions!B20 -> 650.86821 | H34: =H33*Assumptions!C20 -> 707.31069 | I34: =I33*Assumptions!D20 -> 785.14241 | J34: =J33*Assumptions!E20 -> 857.29321 | K34: =K33*Assumptions!F20 -> 926.94584
A35: Noncontrolling interest | B35: 5 | C35: 4 | D35: 5 | E35: 5 | F35: 6 | G35: =Assumptions!B21 -> 6 | H35: =Assumptions!C21 -> 6 | I35: =Assumptions!D21 -> 6 | J35: =Assumptions!E21 -> 6 | K35: =Assumptions!F21 -> 6
A36: Net income to common | B36: 1245 | C36: 1363 | D36: 1709 | E36: 1577 | F36: 2154 | G36: =G33-G34-G35 -> 2235.8794 | H36: =H33-H34-H35 -> 2361.9532 | I36: =I33-I34-I35 -> 2622.5203 | J36: =J33-J34-J35 -> 2864.0686 | K36: =K33-K34-K35 -> 3097.2535
A37: D&A | B37: 438 | C37: 440 | D37: 356 | E37: 336 | F37: 425 | G37: =Assumptions!B22 -> 570 | H37: =Assumptions!C22 -> 645 | I37: =Assumptions!D22 -> 605 | J37: =Assumptions!E22 -> 570 | K37: =Assumptions!F22 -> 540
A38: Share-based comp | B38: 129 | C38: 172 | D38: 212 | E38: 243 | F38: 293 | G38: =G17*Assumptions!B24 -> 320.02244 | H38: =H17*Assumptions!C24 -> 337.09849 | I38: =I17*Assumptions!D24 -> 361.94006 | J38: =J17*Assumptions!E24 -> 385.03429 | K38: =K17*Assumptions!F24 -> 407.2585
A39: Working capital outflow | G39: =(G17-F17)*Assumptions!B27 -> 167.83461 | H39: =(H17-G17)*Assumptions!C27 -> 102.45632 | I39: =(I17-H17)*Assumptions!D27 -> 149.04943 | J39: =(J17-I17)*Assumptions!E27 -> 138.56539 | K39: =(K17-J17)*Assumptions!F27 -> 133.34524
A40: Operating cash flow | B40: 1837 | C40: 1823 | D40: 2044 | E40: 2391 | F40: 2837 | G40: =G36+G35+G37+G38-G39 -> 2964.0672 | H40: =H36+H35+H37+H38-H39 -> 3247.5953 | I40: =I36+I35+I37+I38-I39 -> 3446.4109 | J40: =J36+J35+J37+J38-J39 -> 3686.5375 | K40: =K36+K35+K37+K38-K39 -> 3917.1667
A41: Capital expenditures | B41: 243 | C41: 256 | D41: 253 | E41: 257 | F41: 265 | G41: =G17*Assumptions!B28 -> 294.42064 | H41: =H17*Assumptions!C28 -> 310.13061 | I41: =I17*Assumptions!D28 -> 332.98486 | J41: =J17*Assumptions!E28 -> 354.23155 | K41: =K17*Assumptions!F28 -> 374.67782
...

Sheet NonGAAP
A1: GAAP to Non-GAAP EPS Bridge (approximate: company provides no quantitative forward reconciliation)
A3: Line | B3: 2026 | C3: 2027 | D3: 2028 | E3: 2029 | F3: 2030
A4: GAAP net income to common | B4: =Model!G36 -> 2235.8794 | C4: =Model!H36 -> 2361.9532 | D4: =Model!I36 -> 2622.5203 | E4: =Model!J36 -> 2864.0686 | F4: =Model!K36 -> 3097.2535
A5: + Share-based compensation | B5: =Model!G38 -> 320.02244 | C5: =Model!H38 -> 337.09849 | D5: =Model!I38 -> 361.94006 | E5: =Model!J38 -> 385.03429 | F5: =Model!K38 -> 407.2585
A6: + Intangible amortization | B6: =Assumptions!B23 -> 380 | C6: =Assumptions!C23 -> 455 | D6: =Assumptions!D23 -> 420 | E6: =Assumptions!E23 -> 390 | F6: =Assumptions!F23 -> 365
A7: + Acquisition and integration costs (est.) | B7: =Assumptions!B26 -> 40 | C7: =Assumptions!C26 -> 20 | D7: =Assumptions!D26 -> 10 | E7: =Assumptions!E26 -> 10 | F7: =Assumptions!F26 -> 10
A8: - Hytera legal gains | B8: =-Assumptions!B25 -> -40 | C8: =-Assumptions!C25 -> 0 | D8: =-Assumptions!D25 -> 0 | E8: =-Assumptions!E25 -> 0 | F8: =-Assumptions!F25 -> 0
A9: Pretax adjustments | B9: =SUM(B5:B8) -> 700.02244 | C9: =SUM(C5:C8) -> 812.09849 | D9: =SUM(D5:D8) -> 791.94006 | E9: =SUM(E5:E8) -> 785.03429 | F9: =SUM(F5:F8) -> 782.2585
A10: Tax effect of adjustments (22.5%) | B10: =-B9*0.225 -> -157.50505 | C10: =-C9*0.225 -> -182.72216 | D10: =-D9*0.225 -> -178.18651 | E10: =-E9*0.225 -> -176.63272 | F10: =-F9*0.225 -> -176.00816
A11: After-tax adjustments | B11: =B9+B10 -> 542.51739 | C11: =C9+C10 -> 629.37633 | D11: =D9+D10 -> 613.75355 | E11: =E9+E10 -> 608.40158 | F11: =F9+F10 -> 606.25034
A12: Non-GAAP net income | B12: =B4+B11 -> 2778.3968 | C12: =C4+C11 -> 2991.3295 | D12: =D4+D11 -> 3236.2738 | E12: =E4+E11 -> 3472.4702 | F12: =F4+F11 -> 3703.5038
A13: Diluted shares (M) | B13: =Model!G47 -> 167.04696 | C13: =Model!H47 -> 165.11696 | D13: =Model!I47 -> 163.26305 | E13: =Model!J47 -> 161.61628 | F13: =Model!K47 -> 160.12233
A14: Non-GAAP EPS | B14: =B12/B13 -> 16.63243 | C14: =C12/C13 -> 18.116428 | D14: =D12/D13 -> 19.822451 | E14: =E12/E13 -> 21.485893 | F14: =F12/F13 -> 23.129215
A15: GAAP EPS | B15: =Model!G48 -> 13.384736 | C15: =Model!H48 -> 14.304728 | D15: =Model!I48 -> 16.063159 | E15: =Model!J48 -> 17.721411 | F15: =Model!K48 -> 19.343045
A16: Non-GAAP EPS (= row 11) | B16: =B14 -> 16.63243 | C16: =C14 -> 18.116428 | D16: =D14 -> 19.822451 | E16: =E14 -> 21.485893 | F16: =F14 -> 23.129215
A17: Guidance midpoint (2026 only) | B17: 16.93
A18: Variance vs guidance | B18: =B16/B17-1 -> -0.01757651

Sheet Calibration
A1: Calibration Variables (isolated per skill patch: solved values are not forecast assumptions)
A3: Variable | B3: Historical (derived 2025) | C3: Calibrated 2026 | D3: Difference (pts) | E3: Evidence grade | F3: Damodaran | G3: Use beyond 2026? | H3: Post-2026 value
A4: P&SI same-year booking conversion | B4: 0.7064 | C4: 0.745 | D4: =C4-B4 -> 0.0386 | E4: Derived from FY2024 10-K disclosed 57% P&SI recognition + filed bookings identity | F4: Plausible | G4: No | H4: 0.7064
A5: S&S same-year booking conversion | B5: 0.3267 | C5: 0.3575 | D5: =C5-B5 -> 0.0308 | E5: Derived from FY2024 10-K disclosed 24% S&S recognition + filed bookings identity | F5: Plausible | G5: No | H5: 0.3267
A7: Derivation: 2025 expected BB recognition = disclosed rate x filed 2024 backlog. P&SI: 57% x 4,135 = 2,357. S&S: 24% x 10,562 = 2,535.
A8: Same-year conversion = (segment revenue - expected BB recognition) / derived bookings. P&SI: (7,253-2,357)/6,930. S&S: (4,429-2,535)/5,797.
A9: The 2026 calibrated values are solved against the raised $12.8B guidance and sit 3.9pts (P&SI) and 3.1pts (S&S) above the historical derivation.
A10: Interpretation: hitting 2026 guidance requires modestly above-trend in-year conversion; the model reverts to historical rates from 2027, which produces the small P&SI dip in 2027.

Sheet TieOut-Bridges
A1: Controls, Allocation Bridge, D-Fend Margin Sensitivity
A3: FILING TIE-OUTS | B3: Filed | C3: Model | D3: Diff
A4: P&SI ending backlog 2025 | B4: 3812 | C4: =Model!F22 -> 3812 | D4: =C4-B4 -> 0
A5: S&S ending backlog 2025 | B5: 11930 | C5: =Model!F23 -> 11930 | D5: =C5-B5 -> 0
A6: Total backlog 2025 | B6: 15742 | C6: =Model!F24 -> 15742 | D6: =C6-B6 -> 0
A7: 2026 backlog recognition control | B7: 4800 | C7: =Model!G9+Model!G12 -> 4800.6436 | D7: =C7-B7 -> 0.6436
A8: RPO total (recorded) | B8: 9600 | C8: n/a
A9: RPO next 12 months (recorded) | B9: 4000 | C9: n/a
A11: GUIDANCE BRIDGES (May 7, 2026) | B11: Guidance | C11: Model | D11: Var %
A12: 2026 revenue | B12: 12800 | C12: =Model!G17 -> 12800.897 | D12: =C12/B12-1 -> 7.0109375e-05
A13: 2026 non-GAAP EPS (midpoint; approx bridge) | B13: 16.93 | C13: =NonGAAP!B14 -> 16.63243 | D13: =C13/B13-1 -> -0.01757651
A14: 2026 diluted shares | B14: 168 | C14: =Model!G47 -> 167.04696 | D14: =C14/B14-1 -> -0.0056728748
A16: ALLOCATION BRIDGE: $4.8B control split (2026) | B16: Method | C16: P&SI BB | D16: S&S BB | E16: P&SI rev | F16: S&S rev | G16: Op income | H16: EPS
A17: A_proportionate_to_backlog | B17: proportional | C17: 1162 | D17: 3638 | E17: 6841 | F17: 5959 | G17: 3361 | H17: 13.56
A18: B_historical_mix_scaled (model) | B18: historical_mix | C18: 2071 | D18: 2729 | E18: 7750 | F18: 5050 | G18: 3323 | H18: 13.38
A19: C_service_slower (S&S at 20%) | B19: judgment | C19: 2414 | D19: 2386 | E19: 8093 | F19: 4707 | G19: 3308 | H19: 13.32
A20: Note: total revenue and EPS nearly invariant across cases; the control pins total BB revenue, so the split moves segment mix, not company earnings.
A22: D-FEND MARGIN SENSITIVITY (2030) | B22: Margin | C22: Op income | D22: Net income | E22: EPS
B23: 0.1 | C23: 4405 | D23: 3043 | E23: 19.02
B24: 0.2 | C24: 4452 | D24: 3079 | E24: 19.23
A25: base | B25: 0.25 | C25: 4475 | D25: 3097 | E25: 19.34
B26: 0.3 | C26: 4499 | D26: 3115 | E26: 19.45
B27: 0.35 | C27: 4522 | D27: 3133 | E27: 19.56
A28: Note: full plus/minus 20% sensitivity across all variables is in sensitivity_report.csv.
