Workbook

Sheet Assumptions
A1: NAVITAS SEMICONDUCTOR (NVTS) | REVENUE AND P&L ASSUMPTIONS | FY2025-FY2030
A2: Assumption | B2: Source / Rationale | C2: FY2025 | D2: FY2026 | E2: FY2027 | F2: FY2028 | G2: FY2029 | H2: FY2030
A3: Blue = hardcoded input Black = formula Yellow = USER_REQUIRED or MISSING_EVIDENCE
A4: REVENUE DRIVER ASSUMPTIONS | Driver: MW Addressed x Content ($/MW) / 1,000,000 = Revenue ($M)
A5: DATA CENTER
A6: MW Addressed (MW) | B6: MW of hyperscaler AI/GPU server power capacity addressed. FY2025 early ramp per 10-K FY2024. FY2030 implies ~30% of hyperscaler AI power consumption; USER_REQUIRED: validate vs disclosed capex plans. | C6: 100 | D6: 300 | E6: 800 | F6: 1500 | G6: 2500 | H6: 4000
A7: SiC Content ($/MW) | B7: SiC in PSU rectifier stage. $17,500/MW is ~1-2% of total PSU BOM at scale. Source: Gemini V2. | C7: 17500 | D7: 17500 | E7: 17500 | F7: 17500 | G7: 17500 | H7: 17500
A8: GaN Content ($/MW) | B8: GaN in AC/DC totem-pole topology in AI server power delivery. Source: Gemini V2. | C8: 12500 | D8: 12500 | E8: 12500 | F8: 12500 | G8: 12500 | H8: 12500
A10: MOBILE AND CONSUMER ELECTRONICS
A11: MW Addressed (MW) | B11: MW equivalent of GaN charger ICs shipped into USB-PD and fast-charger sockets. ~2-4% attach rate on global smartphone charger shipments. Growth capped by ASP erosion from Chinese GaN entrants. | C11: 1400 | D11: 1500 | E11: 1650 | F11: 1875 | G11: 2250 | H11: 2625
A12: SiC Content ($/MW) | B12: No SiC in mobile/consumer. Pure GaN segment. | C12: 0 | D12: 0 | E12: 0 | F12: 0 | G12: 0 | H12: 0
A13: GaN Content ($/MW) | B13: Derived from Gemini V2 ($20M / 1,500 MW FY2026). USER_REQUIRED: reconcile against NVTS disclosed ASP data. | C13: 13333 | D13: 13333 | E13: 13333 | F13: 13333 | G13: 13333 | H13: 13333
A15: ELECTRIC VEHICLES
A16: MW Addressed (MW) | B16: MW equivalent of EV on-board charger and DC/DC converter power addressed. FY2025 pre-production. FY2030 implies ~5-6% of global EV production. USER_REQUIRED: validate against named customer SOPs. | C16: 8000 | D16: 15000 | E16: 30000 | F16: 52500 | G16: 82500 | H16: 120000
A17: SiC Content ($/MW) | B17: $400/MW is below STM and Wolfspeed OBC pricing, reflecting NVTS competitive positioning. MISSING_EVIDENCE: no NVTS EV contract pricing disclosed. Source: Gemini V2. | C17: 400 | D17: 400 | E17: 400 | F17: 400 | G17: 400 | H17: 400
A18: GaN Content ($/MW) | B18: GaN in auxiliary power stages. Smaller BOM share than SiC in EV powertrain. Source: Gemini V2. | C18: 100 | D18: 100 | E18: 100 | F18: 100 | G18: 100 | H18: 100
A20: SOLAR AND ENERGY STORAGE
A21: MW Addressed (MW) | B21: MW of string inverter and storage inverter capacity addressed. Ramp begins FY2026. FY2030 consistent with global solar installation growth ~10-12% per year. | C21: 500 | D21: 800 | E21: 1400 | F21: 2200 | G21: 3400 | H21: 5000
A22: SiC Content ($/MW) | B22: SiC dominates solar inverter at 1,200V. $5,000/MW credible for residential/C&I string inverter. NVTS GeneSiC differentiated at this voltage. Source: Gemini V2. | C22: 5000 | D22: 5000 | E22: 5000 | F22: 5000 | G22: 5000 | H22: 5000
A23: GaN Content ($/MW) | B23: Minimal GaN in solar inverter. SiC preferred for 650V+ breakdown voltage. Source: Gemini V2. | C23: 0 | D23: 0 | E23: 0 | F23: 0 | G23: 0 | H23: 0
A25: INDUSTRIAL AND MOTOR DRIVES
A26: MW Addressed (MW) | B26: MW of motor drive, servo drive, and HVAC compressor power addressed. MISSING_EVIDENCE: no NVTS industrial customer names disclosed. Source: Gemini V2. | C26: 700 | D26: 1000 | E26: 1800 | F26: 2800 | G26: 4200 | H26: 6000
A27: SiC Content ($/MW) | B27: SiC in servo drives and HVAC compressors. Source: Gemini V2. | C27: 3000 | D27: 3000 | E27: 3000 | F27: 3000 | G27: 3000 | H27: 3000
A28: GaN Content ($/MW) | B28: GaN in lower-power motor drive auxiliary stages. Source: Gemini V2. | C28: 1000 | D28: 1000 | E28: 1000 | F28: 1000 | G28: 1000 | H28: 1000
A30: P&L ASSUMPTIONS | Gross Margin by Segment | R&D and SG&A as % of Total Corporate Revenue
A31: GROSS MARGIN (% of Segment Revenue) - Revenue minus wafer, assembly, and test cost
A32: Data Center | B32: Premium segment. High ASP, limited direct competition in AI PSU silicon. Expands toward 55% at scale. MISSING_EVIDENCE: NVTS does not disclose segment-level gross margin. | C32: 0.48 | D32: 0.5 | E32: 0.52 | F32: 0.53 | G32: 0.54 | H32: 0.55
A33: Mobile / Consumer | B33: Most competitive segment. Innoscience, Navitas, GaN Systems competing for USB-PD socket. ASP erosion 3-5% per year. USER_REQUIRED: confirm against NVTS pricing commentary. | C33: 0.36 | D33: 0.35 | E33: 0.34 | F33: 0.34 | G33: 0.33 | H33: 0.33
A34: Electric Vehicles | B34: Severe OEM pricing pressure. Margin recovery requires volume scale and SiC IP leverage. MISSING_EVIDENCE: no NVTS EV contract pricing disclosed. | C34: 0.3 | D34: 0.31 | E34: 0.33 | F34: 0.35 | G34: 0.36 | H34: 0.38
A35: Solar / Storage | B35: SiC-dominant. String inverter OEMs pay premium for efficiency at 1,200V. NVTS GeneSiC differentiated. Margin expands with volume. | C35: 0.42 | D35: 0.43 | E35: 0.44 | F35: 0.45 | G35: 0.46 | H35: 0.47
A36: Industrial / Motor Drives | B36: Custom-adjacent applications with smaller runs and design-in stickiness. Better mix than mobile. MISSING_EVIDENCE: no industrial segment margin disclosure from NVTS. | C36: 0.44 | D36: 0.44 | E36: 0.45 | F36: 0.46 | G36: 0.47 | H36: 0.48
A38: R&D EXPENSE (% of Total Corporate Revenue) - Allocated to segments by revenue mix
A39: R&D Rate | B39: NVTS FY2024 R&D/revenue ~38-40% per 10-K. Fabless model requires heavy GaN and SiC IP investment. Leverages down as revenue scales. Long-term target ~25%, consistent with fabless semis at maturity. | C39: 0.38 | D39: 0.35 | E39: 0.32 | F39: 0.3 | G39: 0.28 | H39: 0.26
A41: SG&A EXPENSE (% of Total Corporate Revenue) - Allocated to segments by revenue mix
A42: SG&A Rate | B42: NVTS FY2024 SG&A/revenue ~20-22% per 10-K. Long-term target ~12-14%, consistent with Monolithic Power Systems at scale. | C42: 0.22 | D42: 0.2 | E42: 0.18 | F42: 0.16 | G42: 0.15 | H42: 0.14

Sheet Revenue Model
A1: NAVITAS SEMICONDUCTOR (NVTS) | SEGMENT REVENUE MODEL | FY2025-FY2030 ($M)
A2: Driver: MW Addressed x $ Content per MW | Blue = input | Black = formula | Green = cross-sheet link
A3: Segment | B3: Driver | C3: FY2025 | D3: FY2026 | E3: FY2027 | F3: FY2028 | G3: FY2029 | H3: FY2030
A5: DATA CENTER
A6: MW Addressed | B6: Input (MW) | C6: =Assumptions!C6 -> 100 | D6: =Assumptions!D6 -> 300 | E6: =Assumptions!E6 -> 800 | F6: =Assumptions!F6 -> 1500 | G6: =Assumptions!G6 -> 2500 | H6: =Assumptions!H6 -> 4000
A7: SiC Revenue | B7: MW x SiC$/MW /1M | C7: =C6*Assumptions!C7/1000000 -> 1.75 | D7: =D6*Assumptions!D7/1000000 -> 5.25 | E7: =E6*Assumptions!E7/1000000 -> 14 | F7: =F6*Assumptions!F7/1000000 -> 26.25 | G7: =G6*Assumptions!G7/1000000 -> 43.75 | H7: =H6*Assumptions!H7/1000000 -> 70
A8: GaN Revenue | B8: MW x GaN$/MW /1M | C8: =C6*Assumptions!C8/1000000 -> 1.25 | D8: =D6*Assumptions!D8/1000000 -> 3.75 | E8: =E6*Assumptions!E8/1000000 -> 10 | F8: =F6*Assumptions!F8/1000000 -> 18.75 | G8: =G6*Assumptions!G8/1000000 -> 31.25 | H8: =H6*Assumptions!H8/1000000 -> 50
A9: Total Data Center | B9: SiC + GaN | C9: =C7+C8 -> 3 | D9: =D7+D8 -> 9 | E9: =E7+E8 -> 24 | F9: =F7+F8 -> 45 | G9: =G7+G8 -> 75 | H9: =H7+H8 -> 120
A11: MOBILE / CONSUMER
A12: MW Addressed | B12: Input (MW) | C12: =Assumptions!C11 -> 1400 | D12: =Assumptions!D11 -> 1500 | E12: =Assumptions!E11 -> 1650 | F12: =Assumptions!F11 -> 1875 | G12: =Assumptions!G11 -> 2250 | H12: =Assumptions!H11 -> 2625
A13: SiC Revenue | B13: MW x SiC$/MW /1M | C13: =C12*Assumptions!C12/1000000 -> 0 | D13: =D12*Assumptions!D12/1000000 -> 0 | E13: =E12*Assumptions!E12/1000000 -> 0 | F13: =F12*Assumptions!F12/1000000 -> 0 | G13: =G12*Assumptions!G12/1000000 -> 0 | H13: =H12*Assumptions!H12/1000000 -> 0
A14: GaN Revenue | B14: MW x GaN$/MW /1M | C14: =C12*Assumptions!C13/1000000 -> 18.6662 | D14: =D12*Assumptions!D13/1000000 -> 19.9995 | E14: =E12*Assumptions!E13/1000000 -> 21.99945 | F14: =F12*Assumptions!F13/1000000 -> 24.999375 | G14: =G12*Assumptions!G13/1000000 -> 29.99925 | H14: =H12*Assumptions!H13/1000000 -> 34.999125
A15: Total Mobile / Consumer | B15: SiC + GaN | C15: =C13+C14 -> 18.6662 | D15: =D13+D14 -> 19.9995 | E15: =E13+E14 -> 21.99945 | F15: =F13+F14 -> 24.999375 | G15: =G13+G14 -> 29.99925 | H15: =H13+H14 -> 34.999125
A17: ELECTRIC VEHICLES
A18: MW Addressed | B18: Input (MW) | C18: =Assumptions!C16 -> 8000 | D18: =Assumptions!D16 -> 15000 | E18: =Assumptions!E16 -> 30000 | F18: =Assumptions!F16 -> 52500 | G18: =Assumptions!G16 -> 82500 | H18: =Assumptions!H16 -> 120000
A19: SiC Revenue | B19: MW x SiC$/MW /1M | C19: =C18*Assumptions!C17/1000000 -> 3.2 | D19: =D18*Assumptions!D17/1000000 -> 6 | E19: =E18*Assumptions!E17/1000000 -> 12 | F19: =F18*Assumptions!F17/1000000 -> 21 | G19: =G18*Assumptions!G17/1000000 -> 33 | H19: =H18*Assumptions!H17/1000000 -> 48
A20: GaN Revenue | B20: MW x GaN$/MW /1M | C20: =C18*Assumptions!C18/1000000 -> 0.8 | D20: =D18*Assumptions!D18/1000000 -> 1.5 | E20: =E18*Assumptions!E18/1000000 -> 3 | F20: =F18*Assumptions!F18/1000000 -> 5.25 | G20: =G18*Assumptions!G18/1000000 -> 8.25 | H20: =H18*Assumptions!H18/1000000 -> 12
A21: Total Electric Vehicles | B21: SiC + GaN | C21: =C19+C20 -> 4 | D21: =D19+D20 -> 7.5 | E21: =E19+E20 -> 15 | F21: =F19+F20 -> 26.25 | G21: =G19+G20 -> 41.25 | H21: =H19+H20 -> 60
A23: SOLAR / STORAGE
A24: MW Addressed | B24: Input (MW) | C24: =Assumptions!C21 -> 500 | D24: =Assumptions!D21 -> 800 | E24: =Assumptions!E21 -> 1400 | F24: =Assumptions!F21 -> 2200 | G24: =Assumptions!G21 -> 3400 | H24: =Assumptions!H21 -> 5000
A25: SiC Revenue | B25: MW x SiC$/MW /1M | C25: =C24*Assumptions!C22/1000000 -> 2.5 | D25: =D24*Assumptions!D22/1000000 -> 4 | E25: =E24*Assumptions!E22/1000000 -> 7 | F25: =F24*Assumptions!F22/1000000 -> 11 | G25: =G24*Assumptions!G22/1000000 -> 17 | H25: =H24*Assumptions!H22/1000000 -> 25
A26: GaN Revenue | B26: MW x GaN$/MW /1M | C26: =C24*Assumptions!C23/1000000 -> 0 | D26: =D24*Assumptions!D23/1000000 -> 0 | E26: =E24*Assumptions!E23/1000000 -> 0 | F26: =F24*Assumptions!F23/1000000 -> 0 | G26: =G24*Assumptions!G23/1000000 -> 0 | H26: =H24*Assumptions!H23/1000000 -> 0
A27: Total Solar / Storage | B27: SiC + GaN | C27: =C25+C26 -> 2.5 | D27: =D25+D26 -> 4 | E27: =E25+E26 -> 7 | F27: =F25+F26 -> 11 | G27: =G25+G26 -> 17 | H27: =H25+H26 -> 25
A29: INDUSTRIAL / MOTOR DRIVES
A30: MW Addressed | B30: Input (MW) | C30: =Assumptions!C26 -> 700 | D30: =Assumptions!D26 -> 1000 | E30: =Assumptions!E26 -> 1800 | F30: =Assumptions!F26 -> 2800 | G30: =Assumptions!G26 -> 4200 | H30: =Assumptions!H26 -> 6000
A31: SiC Revenue | B31: MW x SiC$/MW /1M | C31: =C30*Assumptions!C27/1000000 -> 2.1 | D31: =D30*Assumptions!D27/1000000 -> 3 | E31: =E30*Assumptions!E27/1000000 -> 5.4 | F31: =F30*Assumptions!F27/1000000 -> 8.4 | G31: =G30*Assumptions!G27/1000000 -> 12.6 | H31: =H30*Assumptions!H27/1000000 -> 18
A32: GaN Revenue | B32: MW x GaN$/MW /1M | C32: =C30*Assumptions!C28/1000000 -> 0.7 | D32: =D30*Assumptions!D28/1000000 -> 1 | E32: =E30*Assumptions!E28/1000000 -> 1.8 | F32: =F30*Assumptions!F28/1000000 -> 2.8 | G32: =G30*Assumptions!G28/1000000 -> 4.2 | H32: =H30*Assumptions!H28/1000000 -> 6
A33: Total Industrial / Motor Drives | B33: SiC + GaN | C33: =C31+C32 -> 2.8 | D33: =D31+D32 -> 4 | E33: =E31+E32 -> 7.2 | F33: =F31+F32 -> 11.2 | G33: =G31+G32 -> 16.8 | H33: =H31+H32 -> 24
A35: TOTAL CORPORATE REVENUE ($M)
A36: Data Center | C36: ='Revenue Model'!C9 -> 3 | D36: ='Revenue Model'!D9 -> 9 | E36: ='Revenue Model'!E9 -> 24 | F36: ='Revenue Model'!F9 -> 45 | G36: ='Revenue Model'!G9 -> 75 | H36: ='Revenue Model'!H9 -> 120
A37: Mobile / Consumer | C37: ='Revenue Model'!C15 -> 18.6662 | D37: ='Revenue Model'!D15 -> 19.9995 | E37: ='Revenue Model'!E15 -> 21.99945 | F37: ='Revenue Model'!F15 -> 24.999375 | G37: ='Revenue Model'!G15 -> 29.99925 | H37: ='Revenue Model'!H15 -> 34.999125
A38: Electric Vehicles | C38: ='Revenue Model'!C21 -> 4 | D38: ='Revenue Model'!D21 -> 7.5 | E38: ='Revenue Model'!E21 -> 15 | F38: ='Revenue Model'!F21 -> 26.25 | G38: ='Revenue Model'!G21 -> 41.25 | H38: ='Revenue Model'!H21 -> 60
A39: Solar / Storage | C39: ='Revenue Model'!C27 -> 2.5 | D39: ='Revenue Model'!D27 -> 4 | E39: ='Revenue Model'!E27 -> 7 | F39: ='Revenue Model'!F27 -> 11 | G39: ='Revenue Model'!G27 -> 17 | H39: ='Revenue Model'!H27 -> 25
A40: Industrial / Motor Drives | C40: ='Revenue Model'!C33 -> 2.8 | D40: ='Revenue Model'!D33 -> 4 | E40: ='Revenue Model'!E33 -> 7.2 | F40: ='Revenue Model'!F33 -> 11.2 | G40: ='Revenue Model'!G33 -> 16.8 | H40: ='Revenue Model'!H33 -> 24
A41: Total SiC Revenue | B41: SUM of SiC rows | C41: =C7+C13+C19+C25+C31 -> 9.55 | D41: =D7+D13+D19+D25+D31 -> 18.25 | E41: =E7+E13+E19+E25+E31 -> 38.4 | F41: =F7+F13+F19+F25+F31 -> 66.65 | G41: =G7+G13+G19+G25+G31 -> 106.35 | H41: =H7+H13+H19+H25+H31 -> 161
A42: Total GaN Revenue | B42: SUM of GaN rows | C42: =C8+C14+C20+C26+C32 -> 21.4162 | D42: =D8+D14+D20+D26+D32 -> 26.2495 | E42: =E8+E14+E20+E26+E32 -> 36.79945 | F42: =F8+F14+F20+F26+F32 -> 51.799375 | G42: =G8+G14+G20+G26+G32 -> 73.69925 | H42: =H8+H14+H20+H26+H32 -> 102.99912
A43: TOTAL CORPORATE REVENUE | B43: All Segments | C43: =C9+C15+C21+C27+C33 -> 30.9662 | D43: =D9+D15+D21+D27+D33 -> 44.4995 | E43: =E9+E15+E21+E27+E33 -> 75.19945 | F43: =F9+F15+F21+F27+F33 -> 118.44938 | G43: =G9+G15+G21+G27+G33 -> 180.04925 | H43: =H9+H15+H21+H27+H33 -> 263.99912
A45: YoY REVENUE GROWTH
A46: Data Center | C46: n/a | D46: =IF(C9=0,"-",(D9-C9)/C9) -> 2 | E46: =IF(D9=0,"-",(E9-D9)/D9) -> 1.6666667 | F46: =IF(E9=0,"-",(F9-E9)/E9) -> 0.875 | G46: =IF(F9=0,"-",(G9-F9)/F9) -> 0.66666667 | H46: =IF(G9=0,"-",(H9-G9)/G9) -> 0.6
A47: Mobile / Consumer | C47: n/a | D47: =IF(C15=0,"-",(D15-C15)/C15) -> 0.071428571 | E47: =IF(D15=0,"-",(E15-D15)/D15) -> 0.1 | F47: =IF(E15=0,"-",(F15-E15)/E15) -> 0.13636364 | G47: =IF(F15=0,"-",(G15-F15)/F15) -> 0.2 | H47: =IF(G15=0,"-",(H15-G15)/G15) -> 0.16666667
...
