Workbook

Sheet Summary
A1: Oracle–OpenAI AI Infrastructure Project | Investment Summary | B1: Oracle–OpenAI AI Infrastructure Project | Investment Summary | C1: Oracle–OpenAI AI Infrastructure Project | Investment Summary | D1: Oracle–OpenAI AI Infrastructure Project | Investment Summary | E1: Oracle–OpenAI AI Infrastructure Project | Investment Summary | F1: Oracle–OpenAI AI Infrastructure Project | Investment Summary | G1: Oracle–OpenAI AI Infrastructure Project | Investment Summary | H1: Oracle–OpenAI AI Infrastructure Project | Investment Summary
A2: Base case extends through the full 17-year data-center lease. Post-2031 redeployment revenue is an underwriting assumption and is not treated as contracted backlog. | B2: Base case extends through the full 17-year data-center lease. Post-2031 redeployment revenue is an underwriting assumption and is not treated as contracted backlog. | C2: Base case extends through the full 17-year data-center lease. Post-2031 redeployment revenue is an underwriting assumption and is not treated as contracted backlog. | D2: Base case extends through the full 17-year data-center lease. Post-2031 redeployment revenue is an underwriting assumption and is not treated as contracted backlog. | E2: Base case extends through the full 17-year data-center lease. Post-2031 redeployment revenue is an underwriting assumption and is not treated as contracted backlog. | F2: Base case extends through the full 17-year data-center lease. Post-2031 redeployment revenue is an underwriting assumption and is not treated as contracted backlog. | G2: Base case extends through the full 17-year data-center lease. Post-2031 redeployment revenue is an underwriting assumption and is not treated as contracted backlog. | H2: Base case extends through the full 17-year data-center lease. Post-2031 redeployment revenue is an underwriting assumption and is not treated as contracted backlog.
A4: Key Project Returns | B4: Key Project Returns | C4: Key Project Returns | D4: Key Project Returns | E4: Key Project Returns | F4: Key Project Returns | G4: Key Project Returns | H4: Key Project Returns
A5: Full-Lease Project IRR | B5: =IRR('FCFF Model'!C57:V57) -> 0.12191358 | D5: Lease Term | E5: =Assumptions!$C$8 -> 17
A6: Full-Lease Project NPV ($mm) | B6: =NPV(Assumptions!$C$50,'FCFF Model'!D57:V57)+'FCFF Model'!C57 -> 671.14652 | D6: Contract End Year | E6: =Assumptions!$C$11 -> 2031
A7: Project MOIC | B7: =SUMIF('FCFF Model'!C57:V57,">0",'FCFF Model'!C57:V57)/-SUMIF('FCFF Model'!C57:V57,"<0",'FCFF Model'!C57:V57) -> 1.2077836 | D7: Total Capacity (GW) | E7: =Assumptions!$C$15 -> 4.5
A8: Sustained Payback Year | B8: =INDEX('FCFF Model'!C3:V3,1,MATCH(1,'FCFF Model'!C62:V62,0)) -> 2033 | D8: Initial Cost / GW ($mm) | E8: =Assumptions!$C$16 -> 40000
A9: Sustained Discounted Payback Year | B9: =INDEX('FCFF Model'!C3:V3,1,MATCH(1,'FCFF Model'!C63:V63,0)) -> 2043 | D9: Contract Value ($mm) | E9: =Assumptions!$C$24 -> 340000
A10: Peak Funding Requirement ($mm) | B10: =-MIN('FCFF Model'!C60:V60) -> 133784.78 | D10: Initial Tail Utilization | E10: =Assumptions!$C$32 -> 0.7
A11: Total Initial Hardware Capex ($mm) | B11: =-SUM('FCFF Model'!C41:V41) -> 180000 | D11: Stabilized Tail Utilization | E11: =Assumptions!$C$33 -> 0.85
A12: Total Revenue ($mm) | B12: =SUM('FCFF Model'!C14:V14) -> 822358.67 | D12: Annual Revenue / GW Decline | E12: =Assumptions!$C$35 -> 0.1
A13: Total Operating FCFF ($mm) | B13: =SUM('FCFF Model'!C48:V48) -> 237261.96 | D13: Refresh Interval | E13: =Assumptions!$C$18 -> 6
A14: Terminal Cash Flow ($mm) | B14: =SUM('FCFF Model'!C54:V54) -> 7637.4946 | D14: Refresh Cost | E14: =Assumptions!$C$20 -> 0.65
A15: Lease End Year | B15: =Assumptions!$C$9 -> 2043 | D15: Discount Rate | E15: =Assumptions!$C$50 -> 0.12
A17: Value Decomposition | B17: Value Decomposition | C17: Value Decomposition | D17: Value Decomposition | E17: Value Decomposition | F17: Value Decomposition | G17: Value Decomposition | H17: Value Decomposition
A18: Contract-Period NPV Through 2031 ($mm) | B18: =NPV(Assumptions!$C$50,'FCFF Model'!D57:H57)+'FCFF Model'!C57 -> 1556.4554 | D18: Critical underwriting point: The OpenAI contract revenue ends in 2031, while the base lease continues through 2043. The model assumes the capacity is redeployed at 70% utilization in 2032, ramping to 85%, while revenue per utilized GW declines 10% annually. Major hardware refreshes occur every six years. Change these assumptions on the Assumptions sheet to test the lease-tail risk. | E18: Critical underwriting point: The OpenAI contract revenue ends in 2031, while the base lease continues through 2043. The model assumes the capacity is redeployed at 70% utilization in 2032, ramping to 85%, while revenue per utilized GW declines 10% annually. Major hardware refreshes occur every six years. Change these assumptions on the Assumptions sheet to test the lease-tail risk. | F18: Critical underwriting point: The OpenAI contract revenue ends in 2031, while the base lease continues through 2043. The model assumes the capacity is redeployed at 70% utilization in 2032, ramping to 85%, while revenue per utilized GW declines 10% annually. Major hardware refreshes occur every six years. Change these assumptions on the Assumptions sheet to test the lease-tail risk. | G18: Critical underwriting point: The OpenAI contract revenue ends in 2031, while the base lease continues through 2043. The model assumes the capacity is redeployed at 70% utilization in 2032, ramping to 85%, while revenue per utilized GW declines 10% annually. Major hardware refreshes occur every six years. Change these assumptions on the Assumptions sheet to test the lease-tail risk. | H18: Critical underwriting point: The OpenAI contract revenue ends in 2031, while the base lease continues through 2043. The model assumes the capacity is redeployed at 70% utilization in 2032, ramping to 85%, while revenue per utilized GW declines 10% annually. Major hardware refreshes occur every six years. Change these assumptions on the Assumptions sheet to test the lease-tail risk.
A19: Post-Contract / Lease-Tail PV Contribution ($mm) | B19: =B6-B18 -> -885.30891 | D19: Critical underwriting point: The OpenAI contract revenue ends in 2031, while the base lease continues through 2043. The model assumes the capacity is redeployed at 70% utilization in 2032, ramping to 85%, while revenue per utilized GW declines 10% annually. Major hardware refreshes occur every six years. Change these assumptions on the Assumptions sheet to test the lease-tail risk. | E19: Critical underwriting point: The OpenAI contract revenue ends in 2031, while the base lease continues through 2043. The model assumes the capacity is redeployed at 70% utilization in 2032, ramping to 85%, while revenue per utilized GW declines 10% annually. Major hardware refreshes occur every six years. Change these assumptions on the Assumptions sheet to test the lease-tail risk. | F19: Critical underwriting point: The OpenAI contract revenue ends in 2031, while the base lease continues through 2043. The model assumes the capacity is redeployed at 70% utilization in 2032, ramping to 85%, while revenue per utilized GW declines 10% annually. Major hardware refreshes occur every six years. Change these assumptions on the Assumptions sheet to test the lease-tail risk. | G19: Critical underwriting point: The OpenAI contract revenue ends in 2031, while the base lease continues through 2043. The model assumes the capacity is redeployed at 70% utilization in 2032, ramping to 85%, while revenue per utilized GW declines 10% annually. Major hardware refreshes occur every six years. Change these assumptions on the Assumptions sheet to test the lease-tail risk. | H19: Critical underwriting point: The OpenAI contract revenue ends in 2031, while the base lease continues through 2043. The model assumes the capacity is redeployed at 70% utilization in 2032, ramping to 85%, while revenue per utilized GW declines 10% annually. Major hardware refreshes occur every six years. Change these assumptions on the Assumptions sheet to test the lease-tail risk.
A20: PV of Facility Lease Payments ($mm) | B20: =-SUMPRODUCT('FCFF Model'!C18:V18,'FCFF Model'!C58:V58) -> 59718.187 | D20: Critical underwriting point: The OpenAI contract revenue ends in 2031, while the base lease continues through 2043. The model assumes the capacity is redeployed at 70% utilization in 2032, ramping to 85%, while revenue per utilized GW declines 10% annually. Major hardware refreshes occur every six years. Change these assumptions on the Assumptions sheet to test the lease-tail risk. | E20: Critical underwriting point: The OpenAI contract revenue ends in 2031, while the base lease continues through 2043. The model assumes the capacity is redeployed at 70% utilization in 2032, ramping to 85%, while revenue per utilized GW declines 10% annually. Major hardware refreshes occur every six years. Change these assumptions on the Assumptions sheet to test the lease-tail risk. | F20: Critical underwriting point: The OpenAI contract revenue ends in 2031, while the base lease continues through 2043. The model assumes the capacity is redeployed at 70% utilization in 2032, ramping to 85%, while revenue per utilized GW declines 10% annually. Major hardware refreshes occur every six years. Change these assumptions on the Assumptions sheet to test the lease-tail risk. | G20: Critical underwriting point: The OpenAI contract revenue ends in 2031, while the base lease continues through 2043. The model assumes the capacity is redeployed at 70% utilization in 2032, ramping to 85%, while revenue per utilized GW declines 10% annually. Major hardware refreshes occur every six years. Change these assumptions on the Assumptions sheet to test the lease-tail risk. | H20: Critical underwriting point: The OpenAI contract revenue ends in 2031, while the base lease continues through 2043. The model assumes the capacity is redeployed at 70% utilization in 2032, ramping to 85%, while revenue per utilized GW declines 10% annually. Major hardware refreshes occur every six years. Change these assumptions on the Assumptions sheet to test the lease-tail risk.
A21: PV of Major Refresh Capex ($mm) | B21: =-SUMPRODUCT('FCFF Model'!C47:V47,'FCFF Model'!C58:V58) -> 89306.827 | D21: Critical underwriting point: The OpenAI contract revenue ends in 2031, while the base lease continues through 2043. The model assumes the capacity is redeployed at 70% utilization in 2032, ramping to 85%, while revenue per utilized GW declines 10% annually. Major hardware refreshes occur every six years. Change these assumptions on the Assumptions sheet to test the lease-tail risk. | E21: Critical underwriting point: The OpenAI contract revenue ends in 2031, while the base lease continues through 2043. The model assumes the capacity is redeployed at 70% utilization in 2032, ramping to 85%, while revenue per utilized GW declines 10% annually. Major hardware refreshes occur every six years. Change these assumptions on the Assumptions sheet to test the lease-tail risk. | F21: Critical underwriting point: The OpenAI contract revenue ends in 2031, while the base lease continues through 2043. The model assumes the capacity is redeployed at 70% utilization in 2032, ramping to 85%, while revenue per utilized GW declines 10% annually. Major hardware refreshes occur every six years. Change these assumptions on the Assumptions sheet to test the lease-tail risk. | G21: Critical underwriting point: The OpenAI contract revenue ends in 2031, while the base lease continues through 2043. The model assumes the capacity is redeployed at 70% utilization in 2032, ramping to 85%, while revenue per utilized GW declines 10% annually. Major hardware refreshes occur every six years. Change these assumptions on the Assumptions sheet to test the lease-tail risk. | H21: Critical underwriting point: The OpenAI contract revenue ends in 2031, while the base lease continues through 2043. The model assumes the capacity is redeployed at 70% utilization in 2032, ramping to 85%, while revenue per utilized GW declines 10% annually. Major hardware refreshes occur every six years. Change these assumptions on the Assumptions sheet to test the lease-tail risk.
A22: PV of Total Ongoing Expenses ($mm) | B22: =-SUMPRODUCT('FCFF Model'!C25:V25,'FCFF Model'!C58:V58) -> 95956.153 | D22: Critical underwriting point: The OpenAI contract revenue ends in 2031, while the base lease continues through 2043. The model assumes the capacity is redeployed at 70% utilization in 2032, ramping to 85%, while revenue per utilized GW declines 10% annually. Major hardware refreshes occur every six years. Change these assumptions on the Assumptions sheet to test the lease-tail risk. | E22: Critical underwriting point: The OpenAI contract revenue ends in 2031, while the base lease continues through 2043. The model assumes the capacity is redeployed at 70% utilization in 2032, ramping to 85%, while revenue per utilized GW declines 10% annually. Major hardware refreshes occur every six years. Change these assumptions on the Assumptions sheet to test the lease-tail risk. | F22: Critical underwriting point: The OpenAI contract revenue ends in 2031, while the base lease continues through 2043. The model assumes the capacity is redeployed at 70% utilization in 2032, ramping to 85%, while revenue per utilized GW declines 10% annually. Major hardware refreshes occur every six years. Change these assumptions on the Assumptions sheet to test the lease-tail risk. | G22: Critical underwriting point: The OpenAI contract revenue ends in 2031, while the base lease continues through 2043. The model assumes the capacity is redeployed at 70% utilization in 2032, ramping to 85%, while revenue per utilized GW declines 10% annually. Major hardware refreshes occur every six years. Change these assumptions on the Assumptions sheet to test the lease-tail risk. | H22: Critical underwriting point: The OpenAI contract revenue ends in 2031, while the base lease continues through 2043. The model assumes the capacity is redeployed at 70% utilization in 2032, ramping to 85%, while revenue per utilized GW declines 10% annually. Major hardware refreshes occur every six years. Change these assumptions on the Assumptions sheet to test the lease-tail risk.
A23: Ending Cumulative FCFF ($mm) | B23: ='FCFF Model'!V60 -> 64899.452 | D23: Critical underwriting point: The OpenAI contract revenue ends in 2031, while the base lease continues through 2043. The model assumes the capacity is redeployed at 70% utilization in 2032, ramping to 85%, while revenue per utilized GW declines 10% annually. Major hardware refreshes occur every six years. Change these assumptions on the Assumptions sheet to test the lease-tail risk. | E23: Critical underwriting point: The OpenAI contract revenue ends in 2031, while the base lease continues through 2043. The model assumes the capacity is redeployed at 70% utilization in 2032, ramping to 85%, while revenue per utilized GW declines 10% annually. Major hardware refreshes occur every six years. Change these assumptions on the Assumptions sheet to test the lease-tail risk. | F23: Critical underwriting point: The OpenAI contract revenue ends in 2031, while the base lease continues through 2043. The model assumes the capacity is redeployed at 70% utilization in 2032, ramping to 85%, while revenue per utilized GW declines 10% annually. Major hardware refreshes occur every six years. Change these assumptions on the Assumptions sheet to test the lease-tail risk. | G23: Critical underwriting point: The OpenAI contract revenue ends in 2031, while the base lease continues through 2043. The model assumes the capacity is redeployed at 70% utilization in 2032, ramping to 85%, while revenue per utilized GW declines 10% annually. Major hardware refreshes occur every six years. Change these assumptions on the Assumptions sheet to test the lease-tail risk. | H23: Critical underwriting point: The OpenAI contract revenue ends in 2031, while the base lease continues through 2043. The model assumes the capacity is redeployed at 70% utilization in 2032, ramping to 85%, while revenue per utilized GW declines 10% annually. Major hardware refreshes occur every six years. Change these assumptions on the Assumptions sheet to test the lease-tail risk.
A25: NPV Sensitivity to Discount Rate | B25: NPV Sensitivity to Discount Rate | C25: NPV Sensitivity to Discount Rate | D25: NPV Sensitivity to Discount Rate | E25: NPV Sensitivity to Discount Rate | F25: NPV Sensitivity to Discount Rate | G25: NPV Sensitivity to Discount Rate | H25: NPV Sensitivity to Discount Rate
A26: Discount Rate | B26: Project NPV ($mm)
A27: 0.1 | B27: =NPV(A27,'FCFF Model'!D57:V57)+'FCFF Model'!C57 -> 8182.3922
A28: 0.11 | B28: =NPV(A28,'FCFF Model'!D57:V57)+'FCFF Model'!C57 -> 4310.1302
A29: 0.12 | B29: =NPV(A29,'FCFF Model'!D57:V57)+'FCFF Model'!C57 -> 671.14652
A30: 0.13 | B30: =NPV(A30,'FCFF Model'!D57:V57)+'FCFF Model'!C57 -> -2750.9206
A31: 0.14 | B31: =NPV(A31,'FCFF Model'!D57:V57)+'FCFF Model'!C57 -> -5970.9956

Sheet Assumptions
A1: Oracle–OpenAI AI Infrastructure Project | Assumptions | B1: Oracle–OpenAI AI Infrastructure Project | Assumptions | C1: Oracle–OpenAI AI Infrastructure Project | Assumptions | D1: Oracle–OpenAI AI Infrastructure Project | Assumptions | E1: Oracle–OpenAI AI Infrastructure Project | Assumptions | F1: Oracle–OpenAI AI Infrastructure Project | Assumptions
A2: Nominal USD in $mm unless otherwise noted. Blue-font cells are editable inputs; formula cells are black. Public disclosures and underwriting assumptions are separately identified. | B2: Nominal USD in $mm unless otherwise noted. Blue-font cells are editable inputs; formula cells are black. Public disclosures and underwriting assumptions are separately identified. | C2: Nominal USD in $mm unless otherwise noted. Blue-font cells are editable inputs; formula cells are black. Public disclosures and underwriting assumptions are separately identified. | D2: Nominal USD in $mm unless otherwise noted. Blue-font cells are editable inputs; formula cells are black. Public disclosures and underwriting assumptions are separately identified. | E2: Nominal USD in $mm unless otherwise noted. Blue-font cells are editable inputs; formula cells are black. Public disclosures and underwriting assumptions are separately identified. | F2: Nominal USD in $mm unless otherwise noted. Blue-font cells are editable inputs; formula cells are black. Public disclosures and underwriting assumptions are separately identified.
A4: Section | B4: Assumption | C4: Value | D4: Units | E4: Basis / Note | F4: Source ID
A5: Project Timing
B6: Valuation year | C6: 2026 | D6: year | E6: Initial project year | F6: [M]
B7: Lease start year | C7: 2027 | D7: year | E7: First operating year | F7: [O1]/[M]
B8: Lease term | C8: 17 | D8: years | E8: Midpoint of Oracle's disclosed 15–19 year range | F8: [O1]
B9: Lease end year | C9: =C7+C8-1 -> 2043 | D9: year | E9: Calculated from start year and lease term | F9: [F]
B10: Contract term | C10: 5 | D10: years | E10: OpenAI contract modeling period | F10: [U]
B11: Contract end year | C11: =C7+C10-1 -> 2031 | D11: year | E11: Calculated from start year and contract term | F11: [F]
B12: Maximum modeled lease term | C12: 19 | D12: years | E12: Allows disclosed upper-end lease case | F12: [O1]
B13: Maximum modeled end year | C13: =C7+C12-1 -> 2045 | D13: year | E13: Lease start plus maximum modeled term | F13: [F]
A14: Capacity & Investment
B15: Total leased capacity | C15: 4.5 | D15: GW | E15: Capacity assumption carried from source model | F15: [U]
B16: Initial hardware cost / GW | C16: 40000 | D16: $mm/GW | E16: Oracle-funded hardware and fit-out assumption | F16: [U]/[M]
B17: Total initial hardware cost | C17: =C15*C16 -> 180000 | D17: $mm | E17: Capacity multiplied by cost per GW | F17: [F]
B18: Hardware useful life / refresh interval | C18: 6 | D18: years | E18: Oracle reports servers and networking at six years | F18: [O1]
B19: Annual maintenance capex | C19: 0.015 | D19: % installed basis | E19: Routine sustaining capital; separate from major refresh | F19: [M]
B20: Major refresh cost | C20: 0.65 | D20: % initial cost | E20: Replaces compute-heavy portion each refresh cycle | F20: [M]
B21: Residual hardware value | C21: 0.05 | D21: % initial cost | E21: Conservative end-of-lease salvage value | F21: [M]
B22: Decommissioning / exit cost | C22: 0.01 | D22: % initial cost | E22: Removal, restoration and disposal allowance | F22: [M]
A23: Contract Revenue
B24: Contract value | C24: 340000 | D24: $mm | E24: Value and timing retained from source workbook | F24: [U]
B25: 2027 revenue mix | C25: 0.05 | D25: % contract | E25: Contract-period revenue schedule | F25: [U]
B26: 2028 revenue mix | C26: 0.15 | D26: % contract | E26: Contract-period revenue schedule | F26: [U]
B27: 2029 revenue mix | C27: 0.266 | D27: % contract | E27: Contract-period revenue schedule | F27: [U]
B28: 2030 revenue mix | C28: 0.266 | D28: % contract | E28: Contract-period revenue schedule | F28: [U]
B29: 2031 revenue mix | C29: 0.268 | D29: % contract | E29: Contract-period revenue schedule | F29: [U]
B30: Revenue mix check | C30: =SUM(C25:C29) -> 1 | D30: % | E30: Must equal 100.0% | F30: [F]
A31: Post-Contract Redeployment
B32: Initial post-contract utilization | C32: 0.7 | D32: % available GW | E32: Uncontracted underwriting assumption beginning 2032 | F32: [M]
B33: Stabilized post-contract utilization | C33: 0.85 | D33: % available GW | E33: Uncontracted underwriting assumption | F33: [M]
B34: Utilization ramp | C34: 3 | D34: years | E34: Linear ramp from initial to stabilized utilization | F34: [M]
B35: Annual compute revenue / GW decline | C35: 0.1 | D35: % per year | E35: Reflects technology price/performance deflation | F35: [M]
A36: Operating Costs
B37: Facility lease / available GW | C37: 1869.962 | D37: $mm/GW | E37: Fixed while capacity is under lease | F37: [U]
B38: Electricity and fuel / utilized GW | C38: 634.662 | D38: $mm/GW | E38: Variable with utilized capacity | F38: [U]
B39: Staffing and security / available GW | C39: 125 | D39: $mm/GW | E39: Primarily fixed by available capacity | F39: [U]
B40: Facility maintenance / available GW | C40: 250 | D40: $mm/GW | E40: Primarily fixed by available capacity | F40: [U]
B41: Networking / utilized GW | C41: 125 | D41: $mm/GW | E41: Variable with utilized capacity | F41: [U]
...

Sheet FCFF Model
A1: Oracle–OpenAI AI Infrastructure Project | Lease-Term FCFF Model | B1: Oracle–OpenAI AI Infrastructure Project | Lease-Term FCFF Model | C1: Oracle–OpenAI AI Infrastructure Project | Lease-Term FCFF Model | D1: Oracle–OpenAI AI Infrastructure Project | Lease-Term FCFF Model | E1: Oracle–OpenAI AI Infrastructure Project | Lease-Term FCFF Model | F1: Oracle–OpenAI AI Infrastructure Project | Lease-Term FCFF Model | G1: Oracle–OpenAI AI Infrastructure Project | Lease-Term FCFF Model | H1: Oracle–OpenAI AI Infrastructure Project | Lease-Term FCFF Model | I1: Oracle–OpenAI AI Infrastructure Project | Lease-Term FCFF Model | J1: Oracle–OpenAI AI Infrastructure Project | Lease-Term FCFF Model | K1: Oracle–OpenAI AI Infrastructure Project | Lease-Term FCFF Model | L1: Oracle–OpenAI AI Infrastructure Project | Lease-Term FCFF Model | M1: Oracle–OpenAI AI Infrastructure Project | Lease-Term FCFF Model | N1: Oracle–OpenAI AI Infrastructure Project | Lease-Term FCFF Model | O1: Oracle–OpenAI AI Infrastructure Project | Lease-Term FCFF Model | P1: Oracle–OpenAI AI Infrastructure Project | Lease-Term FCFF Model | Q1: Oracle–OpenAI AI Infrastructure Project | Lease-Term FCFF Model | R1: Oracle–OpenAI AI Infrastructure Project | Lease-Term FCFF Model | S1: Oracle–OpenAI AI Infrastructure Project | Lease-Term FCFF Model | T1: Oracle–OpenAI AI Infrastructure Project | Lease-Term FCFF Model | U1: Oracle–OpenAI AI Infrastructure Project | Lease-Term FCFF Model | V1: Oracle–OpenAI AI Infrastructure Project | Lease-Term FCFF Model | W1: Oracle–OpenAI AI Infrastructure Project | Lease-Term FCFF Model
B3: Year | C3: 2026 | D3: 2027 | E3: 2028 | F3: 2029 | G3: 2030 | H3: 2031 | I3: 2032 | J3: 2033 | K3: 2034 | L3: 2035 | M3: 2036 | N3: 2037 | O3: 2038 | P3: 2039 | Q3: 2040 | R3: 2041 | S3: 2042 | T3: 2043 | U3: 2044 | V3: 2045 | W3: Total
B4: Project Year | C4: =C$3-Assumptions!$C$6 -> 0 | D4: =D$3-Assumptions!$C$6 -> 1 | E4: =E$3-Assumptions!$C$6 -> 2 | F4: =F$3-Assumptions!$C$6 -> 3 | G4: =G$3-Assumptions!$C$6 -> 4 | H4: =H$3-Assumptions!$C$6 -> 5 | I4: =I$3-Assumptions!$C$6 -> 6 | J4: =J$3-Assumptions!$C$6 -> 7 | ... V4: =V$3-Assumptions!$C$6 -> 19
B5: Phase | C5: =IF(C$3<Assumptions!$C$7,"Build",IF(C$3<=Assumptions!$C$11,"Contract",IF(C$3<=Assumptions!$C$9,"Redeployment","Post-Lease"))) -> Build | D5: =IF(D$3<Assumptions!$C$7,"Build",IF(D$3<=Assumptions!$C$11,"Contract",IF(D$3<=Assumptions!$C$9,"Redeployment","Post-Lease"))) -> Contract | E5: =IF(E$3<Assumptions!$C$7,"Build",IF(E$3<=Assumptions!$C$11,"Contract",IF(E$3<=Assumptions!$C$9,"Redeployment","Post-Lease"))) -> Contract | F5: =IF(F$3<Assumptions!$C$7,"Build",IF(F$3<=Assumptions!$C$11,"Contract",IF(F$3<=Assumptions!$C$9,"Redeployment","Post-Lease"))) -> Contract | G5: =IF(G$3<Assumptions!$C$7,"Build",IF(G$3<=Assumptions!$C$11,"Contract",IF(G$3<=Assumptions!$C$9,"Redeployment","Post-Lease"))) -> Contract | H5: =IF(H$3<Assumptions!$C$7,"Build",IF(H$3<=Assumptions!$C$11,"Contract",IF(H$3<=Assumptions!$C$9,"Redeployment","Post-Lease"))) -> Contract | I5: Redep. | J5: Redep. | K5: Redep. | L5: Redep. | M5: Redep. | N5: Redep. | O5: Redep. | P5: Redep. | Q5: Redep. | R5: Redep. | S5: Redep. | T5: Redep. | U5: Redep. | V5: Redep.
B6: Lease Active | C6: =IF(AND(C$3>=Assumptions!$C$7,C$3<=Assumptions!$C$9),1,0) -> 0 | D6: =IF(AND(D$3>=Assumptions!$C$7,D$3<=Assumptions!$C$9),1,0) -> 1 | E6: =IF(AND(E$3>=Assumptions!$C$7,E$3<=Assumptions!$C$9),1,0) -> 1 | F6: =IF(AND(F$3>=Assumptions!$C$7,F$3<=Assumptions!$C$9),1,0) -> 1 | G6: =IF(AND(G$3>=Assumptions!$C$7,G$3<=Assumptions!$C$9),1,0) -> 1 | H6: =IF(AND(H$3>=Assumptions!$C$7,H$3<=Assumptions!$C$9),1,0) -> 1 | I6: =IF(AND(I$3>=Assumptions!$C$7,I$3<=Assumptions!$C$9),1,0) -> 1 | J6: =IF(AND(J$3>=Assumptions!$C$7,J$3<=Assumptions!$C$9),1,0) -> 1 | ... V6: =IF(AND(V$3>=Assumptions!$C$7,V$3<=Assumptions!$C$9),1,0) -> 0
B7: Contract Active | C7: =IF(AND(C$3>=Assumptions!$C$7,C$3<=Assumptions!$C$11),1,0) -> 0 | D7: =IF(AND(D$3>=Assumptions!$C$7,D$3<=Assumptions!$C$11),1,0) -> 1 | E7: =IF(AND(E$3>=Assumptions!$C$7,E$3<=Assumptions!$C$11),1,0) -> 1 | F7: =IF(AND(F$3>=Assumptions!$C$7,F$3<=Assumptions!$C$11),1,0) -> 1 | G7: =IF(AND(G$3>=Assumptions!$C$7,G$3<=Assumptions!$C$11),1,0) -> 1 | H7: =IF(AND(H$3>=Assumptions!$C$7,H$3<=Assumptions!$C$11),1,0) -> 1 | I7: =IF(AND(I$3>=Assumptions!$C$7,I$3<=Assumptions!$C$11),1,0) -> 0 | J7: =IF(AND(J$3>=Assumptions!$C$7,J$3<=Assumptions!$C$11),1,0) -> 0 | ... V7: =IF(AND(V$3>=Assumptions!$C$7,V$3<=Assumptions!$C$11),1,0) -> 0
B8: Available / Leased GW | C8: =IF(C6=0,0,IF(C7=1,Assumptions!$C$15*C12/MAX($D$12:$H$12),Assumptions!$C$15)) -> 0 | D8: =IF(D6=0,0,IF(D7=1,Assumptions!$C$15*D12/MAX($D$12:$H$12),Assumptions!$C$15)) -> 0.83955224 | E8: =IF(E6=0,0,IF(E7=1,Assumptions!$C$15*E12/MAX($D$12:$H$12),Assumptions!$C$15)) -> 2.5186567 | F8: =IF(F6=0,0,IF(F7=1,Assumptions!$C$15*F12/MAX($D$12:$H$12),Assumptions!$C$15)) -> 4.4664179 | G8: =IF(G6=0,0,IF(G7=1,Assumptions!$C$15*G12/MAX($D$12:$H$12),Assumptions!$C$15)) -> 4.4664179 | H8: =IF(H6=0,0,IF(H7=1,Assumptions!$C$15*H12/MAX($D$12:$H$12),Assumptions!$C$15)) -> 4.5 | I8: =IF(I6=0,0,IF(I7=1,Assumptions!$C$15*I12/MAX($D$12:$H$12),Assumptions!$C$15)) -> 4.5 | J8: =IF(J6=0,0,IF(J7=1,Assumptions!$C$15*J12/MAX($D$12:$H$12),Assumptions!$C$15)) -> 4.5 | ... V8: =IF(V6=0,0,IF(V7=1,Assumptions!$C$15*V12/MAX($D$12:$H$12),Assumptions!$C$15)) -> 0 | W8: =MAX(C8:V8) -> 4.5
B9: Utilization | C9: =IF(C7=1,100%,IF(C6=1,MIN(Assumptions!$C$33,Assumptions!$C$32+(C$3-Assumptions!$C$11-1)*(Assumptions!$C$33-Assumptions!$C$32)/(Assumptions!$C$34-1)),0)) -> 0 | D9: =IF(D7=1,100%,IF(D6=1,MIN(Assumptions!$C$33,Assumptions!$C$32+(D$3-Assumptions!$C$11-1)*(Assumptions!$C$33-Assumptions!$C$32)/(Assumptions!$C$34-1)),0)) -> 1 | E9: =IF(E7=1,100%,IF(E6=1,MIN(Assumptions!$C$33,Assumptions!$C$32+(E$3-Assumptions!$C$11-1)*(Assumptions!$C$33-Assumptions!$C$32)/(Assumptions!$C$34-1)),0)) -> 1 | F9: =IF(F7=1,100%,IF(F6=1,MIN(Assumptions!$C$33,Assumptions!$C$32+(F$3-Assumptions!$C$11-1)*(Assumptions!$C$33-Assumptions!$C$32)/(Assumptions!$C$34-1)),0)) -> 1 | G9: =IF(G7=1,100%,IF(G6=1,MIN(Assumptions!$C$33,Assumptions!$C$32+(G$3-Assumptions!$C$11-1)*(Assumptions!$C$33-Assumptions!$C$32)/(Assumptions!$C$34-1)),0)) -> 1 | H9: =IF(H7=1,100%,IF(H6=1,MIN(Assumptions!$C$33,Assumptions!$C$32+(H$3-Assumptions!$C$11-1)*(Assumptions!$C$33-Assumptions!$C$32)/(Assumptions!$C$34-1)),0)) -> 1 | I9: =IF(I7=1,100%,IF(I6=1,MIN(Assumptions!$C$33,Assumptions!$C$32+(I$3-Assumptions!$C$11-1)*(Assumptions!$C$33-Assumptions!$C$32)/(Assumptions!$C$34-1)),0)) -> 0.7 | J9: =IF(J7=1,100%,IF(J6=1,MIN(Assumptions!$C$33,Assumptions!$C$32+(J$3-Assumptions!$C$11-1)*(Assumptions!$C$33-Assumptions!$C$32)/(Assumptions!$C$34-1)),0)) -> 0.775 | ... V9: =IF(V7=1,100%,IF(V6=1,MIN(Assumptions!$C$33,Assumptions!$C$32+(V$3-Assumptions!$C$11-1)*(Assumptions!$C$33-Assumptions!$C$32)/(Assumptions!$C$34-1)),0)) -> 0 | W9: =AVERAGEIF(C9:V9,">0") -> 0.88088235
B10: Utilized GW | C10: =C8*C9 -> 0 | D10: =D8*D9 -> 0.83955224 | E10: =E8*E9 -> 2.5186567 | F10: =F8*F9 -> 4.4664179 | G10: =G8*G9 -> 4.4664179 | H10: =H8*H9 -> 4.5 | I10: =I8*I9 -> 3.15 | J10: =J8*J9 -> 3.4875 | ... V10: =V8*V9 -> 0 | W10: =MAX(C10:V10) -> 4.5
B11: Revenue / Utilized GW ($mm) | C11: =0 -> 0 | D11: =IF(D7=1,IFERROR(D12/D10,0),IF(D6=1,C11*(1-Assumptions!$C$35),0)) -> 20248.889 | E11: =IF(E7=1,IFERROR(E12/E10,0),IF(E6=1,D11*(1-Assumptions!$C$35),0)) -> 20248.889 | F11: =IF(F7=1,IFERROR(F12/F10,0),IF(F6=1,E11*(1-Assumptions!$C$35),0)) -> 20248.889 | G11: =IF(G7=1,IFERROR(G12/G10,0),IF(G6=1,F11*(1-Assumptions!$C$35),0)) -> 20248.889 | H11: =IF(H7=1,IFERROR(H12/H10,0),IF(H6=1,G11*(1-Assumptions!$C$35),0)) -> 20248.889 | I11: =IF(I7=1,IFERROR(I12/I10,0),IF(I6=1,H11*(1-Assumptions!$C$35),0)) -> 18224 | J11: =IF(J7=1,IFERROR(J12/J10,0),IF(J6=1,I11*(1-Assumptions!$C$35),0)) -> 16401.6 | K11: =IF(K7=1,IFERROR(K12/K10,0),IF(K6=1,J11*(1-Assumptions!$C$35),0)) -> 14761.44 | ... V11: =IF(V7=1,IFERROR(V12/V10,0),IF(V6=1,U11*(1-Assumptions!$C$35),0)) -> 0 | W11: =AVERAGEIF(C11:V11,">0") -> 13647.911
B12: Contract Revenue | C12: =0 -> 0 | D12: =Assumptions!$C$24*Assumptions!$C$25 -> 17000 | E12: =Assumptions!$C$24*Assumptions!$C$26 -> 51000 | F12: =Assumptions!$C$24*Assumptions!$C$27 -> 90440 | G12: =Assumptions!$C$24*Assumptions!$C$28 -> 90440 | H12: =Assumptions!$C$24*Assumptions!$C$29 -> 91120 | I12: =0 -> 0 | J12: =0 -> 0 | K12: =0 -> 0 | L12: =0 -> 0 | M12: =0 -> 0 | N12: =0 -> 0 | O12: =0 -> 0 | P12: =0 -> 0 | ... V12: =0 -> 0 | W12: =SUM(C12:V12) -> 340000
B13: Redeployment Revenue | C13: =IF(AND(C6=1,C7=0),C10*C11,0) -> 0 | D13: =IF(AND(D6=1,D7=0),D10*D11,0) -> 0 | E13: =IF(AND(E6=1,E7=0),E10*E11,0) -> 0 | F13: =IF(AND(F6=1,F7=0),F10*F11,0) -> 0 | G13: =IF(AND(G6=1,G7=0),G10*G11,0) -> 0 | H13: =IF(AND(H6=1,H7=0),H10*H11,0) -> 0 | I13: =IF(AND(I6=1,I7=0),I10*I11,0) -> 57405.6 | J13: =IF(AND(J6=1,J7=0),J10*J11,0) -> 57200.58 | ... V13: =IF(AND(V6=1,V7=0),V10*V11,0) -> 0 | W13: =SUM(C13:V13) -> 482358.67
B14: Total Revenue | C14: =SUM(C12:C13) -> 0 | D14: =SUM(D12:D13) -> 17000 | E14: =SUM(E12:E13) -> 51000 | F14: =SUM(F12:F13) -> 90440 | G14: =SUM(G12:G13) -> 90440 | H14: =SUM(H12:H13) -> 91120 | I14: =SUM(I12:I13) -> 57405.6 | J14: =SUM(J12:J13) -> 57200.58 | ... V14: =SUM(V12:V13) -> 0 | W14: =SUM(C14:V14) -> 822358.67
B15: % Growth | C15: =0 -> 0 | D15: =IF(C14=0,0,D14/C14-1) -> 0 | E15: =IF(D14=0,0,E14/D14-1) -> 2 | F15: =IF(E14=0,0,F14/E14-1) -> 0.77333333 | G15: =IF(F14=0,0,G14/F14-1) -> 0 | H15: =IF(G14=0,0,H14/G14-1) -> 0.007518797 | I15: =IF(H14=0,0,I14/H14-1) -> -0.37 | J15: =IF(I14=0,0,J14/I14-1) -> -0.0035714286 | K15: =IF(J14=0,0,K14/J14-1) -> -0.012903226 | ... V15: =IF(U14=0,0,V14/U14-1) -> 0 | W15: =IFERROR(V14/C14-1,0) -> 0
A17: Ongoing Expenses | B17: Ongoing Expenses | C17: Ongoing Expenses | D17: Ongoing Expenses | E17: Ongoing Expenses | F17: Ongoing Expenses | G17: Ongoing Expenses | H17: Ongoing Expenses | I17: Ongoing Expenses | J17: Ongoing Expenses | K17: Ongoing Expenses | L17: Ongoing Expenses | M17: Ongoing Expenses | N17: Ongoing Expenses | O17: Ongoing Expenses | P17: Ongoing Expenses | Q17: Ongoing Expenses | R17: Ongoing Expenses | S17: Ongoing Expenses | T17: Ongoing Expenses | U17: Ongoing Expenses | V17: Ongoing Expenses | W17: Ongoing Expenses
B18: Facility Lease | C18: =-C8*Assumptions!$C$37*(1+Assumptions!$C$44)^MAX(0,C$3-Assumptions!$C$7) -> 0 | D18: =-D8*Assumptions!$C$37*(1+Assumptions!$C$44)^MAX(0,D$3-Assumptions!$C$7) -> -1569.9308 | E18: =-E8*Assumptions!$C$37*(1+Assumptions!$C$44)^MAX(0,E$3-Assumptions!$C$7) -> -4827.5372 | F18: =-F8*Assumptions!$C$37*(1+Assumptions!$C$44)^MAX(0,F$3-Assumptions!$C$7) -> -8774.8534 | G18: =-G8*Assumptions!$C$37*(1+Assumptions!$C$44)^MAX(0,G$3-Assumptions!$C$7) -> -8994.2247 | H18: =-H8*Assumptions!$C$37*(1+Assumptions!$C$44)^MAX(0,H$3-Assumptions!$C$7) -> -9288.3967 | I18: =-I8*Assumptions!$C$37*(1+Assumptions!$C$44)^MAX(0,I$3-Assumptions!$C$7) -> -9520.6066 | J18: =-J8*Assumptions!$C$37*(1+Assumptions!$C$44)^MAX(0,J$3-Assumptions!$C$7) -> -9758.6218 | ... V18: =-V8*Assumptions!$C$37*(1+Assumptions!$C$44)^MAX(0,V$3-Assumptions!$C$7) -> 0 | W18: =SUM(C18:V18) -> -164796.98
B19: Electricity and Fuel | C19: =-C10*Assumptions!$C$38*(1+Assumptions!$C$45)^MAX(0,C$3-Assumptions!$C$7) -> 0 | D19: =-D10*Assumptions!$C$38*(1+Assumptions!$C$45)^MAX(0,D$3-Assumptions!$C$7) -> -532.8319 | E19: =-E10*Assumptions!$C$38*(1+Assumptions!$C$45)^MAX(0,E$3-Assumptions!$C$7) -> -1630.4656 | F19: =-F10*Assumptions!$C$38*(1+Assumptions!$C$45)^MAX(0,F$3-Assumptions!$C$7) -> -2949.1862 | G19: =-G10*Assumptions!$C$38*(1+Assumptions!$C$45)^MAX(0,G$3-Assumptions!$C$7) -> -3008.1699 | H19: =-H10*Assumptions!$C$38*(1+Assumptions!$C$45)^MAX(0,H$3-Assumptions!$C$7) -> -3091.4035 | I19: =-I10*Assumptions!$C$38*(1+Assumptions!$C$45)^MAX(0,I$3-Assumptions!$C$7) -> -2207.2621 | J19: =-J10*Assumptions!$C$38*(1+Assumptions!$C$45)^MAX(0,J$3-Assumptions!$C$7) -> -2492.6296 | ... V19: =-V10*Assumptions!$C$38*(1+Assumptions!$C$45)^MAX(0,V$3-Assumptions!$C$7) -> 0 | W19: =SUM(C19:V19) -> -46445.561
B20: Staffing and Security | C20: =-C8*Assumptions!$C$39*(1+Assumptions!$C$46)^MAX(0,C$3-Assumptions!$C$7) -> 0 | D20: =-D8*Assumptions!$C$39*(1+Assumptions!$C$46)^MAX(0,D$3-Assumptions!$C$7) -> -104.94403 | E20: =-E8*Assumptions!$C$39*(1+Assumptions!$C$46)^MAX(0,E$3-Assumptions!$C$7) -> -322.70289 | F20: =-F8*Assumptions!$C$39*(1+Assumptions!$C$46)^MAX(0,F$3-Assumptions!$C$7) -> -586.56629 | G20: =-G8*Assumptions!$C$39*(1+Assumptions!$C$46)^MAX(0,G$3-Assumptions!$C$7) -> -601.23045 | H20: =-H8*Assumptions!$C$39*(1+Assumptions!$C$46)^MAX(0,H$3-Assumptions!$C$7) -> -620.89475 | I20: =-I8*Assumptions!$C$39*(1+Assumptions!$C$46)^MAX(0,I$3-Assumptions!$C$7) -> -636.41712 | J20: =-J8*Assumptions!$C$39*(1+Assumptions!$C$46)^MAX(0,J$3-Assumptions!$C$7) -> -652.32755 | ... V20: =-V8*Assumptions!$C$39*(1+Assumptions!$C$46)^MAX(0,V$3-Assumptions!$C$7) -> 0 | W20: =SUM(C20:V20) -> -11016.064
B21: Facility Maintenance | C21: =-C8*Assumptions!$C$40*(1+Assumptions!$C$46)^MAX(0,C$3-Assumptions!$C$7) -> 0 | D21: =-D8*Assumptions!$C$40*(1+Assumptions!$C$46)^MAX(0,D$3-Assumptions!$C$7) -> -209.88806 | E21: =-E8*Assumptions!$C$40*(1+Assumptions!$C$46)^MAX(0,E$3-Assumptions!$C$7) -> -645.40578 | F21: =-F8*Assumptions!$C$40*(1+Assumptions!$C$46)^MAX(0,F$3-Assumptions!$C$7) -> -1173.1326 | G21: =-G8*Assumptions!$C$40*(1+Assumptions!$C$46)^MAX(0,G$3-Assumptions!$C$7) -> -1202.4609 | H21: =-H8*Assumptions!$C$40*(1+Assumptions!$C$46)^MAX(0,H$3-Assumptions!$C$7) -> -1241.7895 | I21: =-I8*Assumptions!$C$40*(1+Assumptions!$C$46)^MAX(0,I$3-Assumptions!$C$7) -> -1272.8342 | J21: =-J8*Assumptions!$C$40*(1+Assumptions!$C$46)^MAX(0,J$3-Assumptions!$C$7) -> -1304.6551 | ... V21: =-V8*Assumptions!$C$40*(1+Assumptions!$C$46)^MAX(0,V$3-Assumptions!$C$7) -> 0 | W21: =SUM(C21:V21) -> -22032.129
B22: Networking and Connectivity | C22: =-C10*Assumptions!$C$41*(1+Assumptions!$C$46)^MAX(0,C$3-Assumptions!$C$7) -> 0 | D22: =-D10*Assumptions!$C$41*(1+Assumptions!$C$46)^MAX(0,D$3-Assumptions!$C$7) -> -104.94403 | E22: =-E10*Assumptions!$C$41*(1+Assumptions!$C$46)^MAX(0,E$3-Assumptions!$C$7) -> -322.70289 | F22: =-F10*Assumptions!$C$41*(1+Assumptions!$C$46)^MAX(0,F$3-Assumptions!$C$7) -> -586.56629 | G22: =-G10*Assumptions!$C$41*(1+Assumptions!$C$46)^MAX(0,G$3-Assumptions!$C$7) -> -601.23045 | H22: =-H10*Assumptions!$C$41*(1+Assumptions!$C$46)^MAX(0,H$3-Assumptions!$C$7) -> -620.89475 | I22: =-I10*Assumptions!$C$41*(1+Assumptions!$C$46)^MAX(0,I$3-Assumptions!$C$7) -> -445.49198 | J22: =-J10*Assumptions!$C$41*(1+Assumptions!$C$46)^MAX(0,J$3-Assumptions!$C$7) -> -505.55385 | ... V22: =-V10*Assumptions!$C$41*(1+Assumptions!$C$46)^MAX(0,V$3-Assumptions!$C$7) -> 0 | W22: =SUM(C22:V22) -> -9554.7184
B23: Insurance, Taxes and Compliance | C23: =-C8*Assumptions!$C$42*(1+Assumptions!$C$46)^MAX(0,C$3-Assumptions!$C$7) -> 0 | D23: =-D8*Assumptions!$C$42*(1+Assumptions!$C$46)^MAX(0,D$3-Assumptions!$C$7) -> -83.955224 | E23: =-E8*Assumptions!$C$42*(1+Assumptions!$C$46)^MAX(0,E$3-Assumptions!$C$7) -> -258.16231 | F23: =-F8*Assumptions!$C$42*(1+Assumptions!$C$46)^MAX(0,F$3-Assumptions!$C$7) -> -469.25303 | G23: =-G8*Assumptions!$C$42*(1+Assumptions!$C$46)^MAX(0,G$3-Assumptions!$C$7) -> -480.98436 | H23: =-H8*Assumptions!$C$42*(1+Assumptions!$C$46)^MAX(0,H$3-Assumptions!$C$7) -> -496.7158 | I23: =-I8*Assumptions!$C$42*(1+Assumptions!$C$46)^MAX(0,I$3-Assumptions!$C$7) -> -509.1337 | J23: =-J8*Assumptions!$C$42*(1+Assumptions!$C$46)^MAX(0,J$3-Assumptions!$C$7) -> -521.86204 | ... V23: =-V8*Assumptions!$C$42*(1+Assumptions!$C$46)^MAX(0,V$3-Assumptions!$C$7) -> 0 | W23: =SUM(C23:V23) -> -8812.8516
B24: Water | C24: =-C10*Assumptions!$C$43*(1+Assumptions!$C$46)^MAX(0,C$3-Assumptions!$C$7) -> 0 | D24: =-D10*Assumptions!$C$43*(1+Assumptions!$C$46)^MAX(0,D$3-Assumptions!$C$7) -> -2.0988806 | E24: =-E10*Assumptions!$C$43*(1+Assumptions!$C$46)^MAX(0,E$3-Assumptions!$C$7) -> -6.4540578 | F24: =-F10*Assumptions!$C$43*(1+Assumptions!$C$46)^MAX(0,F$3-Assumptions!$C$7) -> -11.731326 | G24: =-G10*Assumptions!$C$43*(1+Assumptions!$C$46)^MAX(0,G$3-Assumptions!$C$7) -> -12.024609 | H24: =-H10*Assumptions!$C$43*(1+Assumptions!$C$46)^MAX(0,H$3-Assumptions!$C$7) -> -12.417895 | I24: =-I10*Assumptions!$C$43*(1+Assumptions!$C$46)^MAX(0,I$3-Assumptions!$C$7) -> -8.9098397 | J24: =-J10*Assumptions!$C$43*(1+Assumptions!$C$46)^MAX(0,J$3-Assumptions!$C$7) -> -10.111077 | ... V24: =-V10*Assumptions!$C$43*(1+Assumptions!$C$46)^MAX(0,V$3-Assumptions!$C$7) -> 0 | W24: =SUM(C24:V24) -> -191.09437
B25: Total Ongoing Expenses | C25: =SUM(C18:C24) -> 0 | D25: =SUM(D18:D24) -> -2608.5929 | E25: =SUM(E18:E24) -> -8013.4307 | F25: =SUM(F18:F24) -> -14551.289 | G25: =SUM(G18:G24) -> -14900.325 | H25: =SUM(H18:H24) -> -15372.513 | I25: =SUM(I18:I24) -> -14600.656 | J25: =SUM(J18:J24) -> -15245.761 | ... V25: =SUM(V18:V24) -> 0 | W25: =SUM(C25:V25) -> -262849.4
B26: EBITDA | C26: =SUM(C14,C25) -> 0 | D26: =SUM(D14,D25) -> 14391.407 | E26: =SUM(E14,E25) -> 42986.569 | F26: =SUM(F14,F25) -> 75888.711 | G26: =SUM(G14,G25) -> 75539.675 | H26: =SUM(H14,H25) -> 75747.487 | I26: =SUM(I14,I25) -> 42804.944 | J26: =SUM(J14,J25) -> 41954.819 | ... V26: =SUM(V14,V25) -> 0 | W26: =SUM(C26:V26) -> 559509.27
B27: EBITDA Margin | C27: =IFERROR(C26/C14,0) -> 0 | D27: =IFERROR(D26/D14,0) -> 0.84655336 | E27: =IFERROR(E26/E14,0) -> 0.84287391 | F27: =IFERROR(F26/F14,0) -> 0.8391056 | G27: =IFERROR(G26/G14,0) -> 0.83524629 | H27: =IFERROR(H26/H14,0) -> 0.83129376 | I27: =IFERROR(I26/I14,0) -> 0.74565799 | J27: =IFERROR(J26/J14,0) -> 0.73346842 | ... W27: =IFERROR(W26/W14,0) -> 0.68037134
A29: Taxes, Depreciation and Working Capital | B29: Taxes, Depreciation and Working Capital | C29: Taxes, Depreciation and Working Capital | D29: Taxes, Depreciation and Working Capital | E29: Taxes, Depreciation and Working Capital | F29: Taxes, Depreciation and Working Capital | G29: Taxes, Depreciation and Working Capital | H29: Taxes, Depreciation and Working Capital | I29: Taxes, Depreciation and Working Capital | J29: Taxes, Depreciation and Working Capital | K29: Taxes, Depreciation and Working Capital | L29: Taxes, Depreciation and Working Capital | M29: Taxes, Depreciation and Working Capital | N29: Taxes, Depreciation and Working Capital | O29: Taxes, Depreciation and Working Capital | P29: Taxes, Depreciation and Working Capital | Q29: Taxes, Depreciation and Working Capital | R29: Taxes, Depreciation and Working Capital | S29: Taxes, Depreciation and Working Capital | T29: Taxes, Depreciation and Working Capital | U29: Taxes, Depreciation and Working Capital | V29: Taxes, Depreciation and Working Capital | W29: Taxes, Depreciation and Working Capital
B30: Depreciable Capital Additions | C30: =-SUM(C41,C46,C47) -> 33582.09 | D30: =-SUM(D41,D46,D47) -> 68675.373 | E30: =-SUM(E41,E46,E47) -> 80590.299 | F30: =-SUM(F41,F46,F47) -> 2679.8507 | G30: =-SUM(G41,G46,G47) -> 4043.2836 | H30: =-SUM(H41,H46,H47) -> 2700 | I30: =-SUM(I41,I46,I47) -> 119700 | J30: =-SUM(J41,J46,J47) -> 2700 | ... V30: =-SUM(V41,V46,V47) -> 0 | W30: =SUM(C30:V30) -> 458670.9
B31: Depreciation | C31: =0 -> 0 | D31: =IF(D6=1,SUMPRODUCT(--($C$3:C$3>=D$3-Assumptions!$C$18),$C$30:C$30)/Assumptions!$C$18,0) -> 5597.0149 | E31: =IF(E6=1,SUMPRODUCT(--($C$3:D$3>=E$3-Assumptions!$C$18),$C$30:D$30)/Assumptions!$C$18,0) -> 17042.91 | F31: =IF(F6=1,SUMPRODUCT(--($C$3:E$3>=F$3-Assumptions!$C$18),$C$30:E$30)/Assumptions!$C$18,0) -> 30474.627 | G31: =IF(G6=1,SUMPRODUCT(--($C$3:F$3>=G$3-Assumptions!$C$18),$C$30:F$30)/Assumptions!$C$18,0) -> 30921.269 | H31: =IF(H6=1,SUMPRODUCT(--($C$3:G$3>=H$3-Assumptions!$C$18),$C$30:G$30)/Assumptions!$C$18,0) -> 31595.149 | I31: =IF(I6=1,SUMPRODUCT(--($C$3:H$3>=I$3-Assumptions!$C$18),$C$30:H$30)/Assumptions!$C$18,0) -> 32045.149 | J31: =IF(J6=1,SUMPRODUCT(--($C$3:I$3>=J$3-Assumptions!$C$18),$C$30:I$30)/Assumptions!$C$18,0) -> 46398.134 | K31: =IF(K6=1,SUMPRODUCT(--($C$3:J$3>=K$3-Assumptions!$C$18),$C$30:J$30)/Assumptions!$C$18,0) -> 35402.239 | ... V31: =IF(V6=1,SUMPRODUCT(--($C$3:U$3>=V$3-Assumptions!$C$18),$C$30:U$30)/Assumptions!$C$18,0) -> 0 | W31: =SUM(C31:V31) -> 429720.9
B32: EBIT | C32: =C26-C31 -> 0 | D32: =D26-D31 -> 8794.3922 | E32: =E26-E31 -> 25943.659 | F32: =F26-F31 -> 45414.084 | G32: =G26-G31 -> 44618.406 | H32: =H26-H31 -> 44152.338 | I32: =I26-I31 -> 10759.795 | J32: =J26-J31 -> -4443.3153 | ... V32: =V26-V31 -> 0 | W32: =SUM(C32:V32) -> 129788.38
B33: Cash Taxes | C33: =-MAX(0,C32*Assumptions!$C$48) -> 0 | D33: =-MAX(0,D32*Assumptions!$C$48) -> -1846.8224 | E33: =-MAX(0,E32*Assumptions!$C$48) -> -5448.1684 | F33: =-MAX(0,F32*Assumptions!$C$48) -> -9536.9576 | G33: =-MAX(0,G32*Assumptions!$C$48) -> -9369.8652 | H33: =-MAX(0,H32*Assumptions!$C$48) -> -9271.9909 | I33: =-MAX(0,I32*Assumptions!$C$48) -> -2259.557 | J33: =-MAX(0,J32*Assumptions!$C$48) -> 0 | ... V33: =-MAX(0,V32*Assumptions!$C$48) -> 0 | W33: =SUM(C33:V33) -> -43138.925
B34: NOPAT | C34: =SUM(C32:C33) -> 0 | D34: =SUM(D32:D33) -> 6947.5698 | E34: =SUM(E32:E33) -> 20495.49 | F34: =SUM(F32:F33) -> 35877.126 | G34: =SUM(G32:G33) -> 35248.541 | H34: =SUM(H32:H33) -> 34880.347 | I34: =SUM(I32:I33) -> 8500.2381 | J34: =SUM(J32:J33) -> -4443.3153 | ... V34: =SUM(V32:V33) -> 0 | W34: =SUM(C34:V34) -> 86649.452
B35: Add: Depreciation | C35: =C31 -> 0 | D35: =D31 -> 5597.0149 | E35: =E31 -> 17042.91 | F35: =F31 -> 30474.627 | G35: =G31 -> 30921.269 | H35: =H31 -> 31595.149 | I35: =I31 -> 32045.149 | J35: =J31 -> 46398.134 | ... V35: =V31 -> 0 | W35: =SUM(C35:V35) -> 429720.9
B36: NWC Balance | C36: =C14*Assumptions!$C$49 -> 0 | D36: =D14*Assumptions!$C$49 -> 340 | E36: =E14*Assumptions!$C$49 -> 1020 | F36: =F14*Assumptions!$C$49 -> 1808.8 | G36: =G14*Assumptions!$C$49 -> 1808.8 | H36: =H14*Assumptions!$C$49 -> 1822.4 | I36: =I14*Assumptions!$C$49 -> 1148.112 | J36: =J14*Assumptions!$C$49 -> 1144.0116 | ... V36: =V14*Assumptions!$C$49 -> 0 | W36: =INDEX(C36:V36,1,MATCH(Assumptions!$C$9,C3:V3,0)) -> 437.49465
B37: Change in NWC | C37: =-C36 -> 0 | D37: =IF(D$3<=Assumptions!$C$9,-(D36-C36),0) -> -340 | E37: =IF(E$3<=Assumptions!$C$9,-(E36-D36),0) -> -680 | F37: =IF(F$3<=Assumptions!$C$9,-(F36-E36),0) -> -788.8 | G37: =IF(G$3<=Assumptions!$C$9,-(G36-F36),0) -> 0 | H37: =IF(H$3<=Assumptions!$C$9,-(H36-G36),0) -> -13.6 | I37: =IF(I$3<=Assumptions!$C$9,-(I36-H36),0) -> 674.288 | J37: =IF(J$3<=Assumptions!$C$9,-(J36-I36),0) -> 4.1004 | K37: =IF(K$3<=Assumptions!$C$9,-(K36-J36),0) -> 14.76144 | ... V37: =IF(V$3<=Assumptions!$C$9,-(V36-U36),0) -> 0 | W37: =SUM(C37:V37) -> -437.49465
B38: Operating Cash Flow Before Reinvestment | C38: =SUM(C34:C35,C37) -> 0 | D38: =SUM(D34:D35,D37) -> 12204.585 | E38: =SUM(E34:E35,E37) -> 36858.401 | F38: =SUM(F34:F35,F37) -> 65562.953 | G38: =SUM(G34:G35,G37) -> 66169.809 | H38: =SUM(H34:H35,H37) -> 66461.896 | I38: =SUM(I34:I35,I37) -> 41219.675 | J38: =SUM(J34:J35,J37) -> 41958.919 | ... V38: =SUM(V34:V35,V37) -> 0 | W38: =SUM(C38:V38) -> 515932.85
A40: Initial Cash Flow (ICF) | B40: Initial Cash Flow (ICF) | C40: Initial Cash Flow (ICF) | D40: Initial Cash Flow (ICF) | E40: Initial Cash Flow (ICF) | F40: Initial Cash Flow (ICF) | G40: Initial Cash Flow (ICF) | H40: Initial Cash Flow (ICF) | I40: Initial Cash Flow (ICF) | J40: Initial Cash Flow (ICF) | K40: Initial Cash Flow (ICF) | L40: Initial Cash Flow (ICF) | M40: Initial Cash Flow (ICF) | N40: Initial Cash Flow (ICF) | O40: Initial Cash Flow (ICF) | P40: Initial Cash Flow (ICF) | Q40: Initial Cash Flow (ICF) | R40: Initial Cash Flow (ICF) | S40: Initial Cash Flow (ICF) | T40: Initial Cash Flow (ICF) | U40: Initial Cash Flow (ICF) | V40: Initial Cash Flow (ICF) | W40: Initial Cash Flow (ICF)
B41: Initial Hardware Build Capex | C41: =-MAX(0,D8-C8)*Assumptions!$C$16 -> -33582.09 | D41: =-MAX(0,E8-D8)*Assumptions!$C$16 -> -67164.179 | E41: =-MAX(0,F8-E8)*Assumptions!$C$16 -> -77910.448 | F41: =-MAX(0,G8-F8)*Assumptions!$C$16 -> 0 | G41: =-MAX(0,H8-G8)*Assumptions!$C$16 -> -1343.2836 | H41: =-MAX(0,I8-H8)*Assumptions!$C$16 -> 0 | I41: =-MAX(0,J8-I8)*Assumptions!$C$16 -> 0 | J41: =-MAX(0,K8-J8)*Assumptions!$C$16 -> 0 | ... U41: =-MAX(0,V8-U8)*Assumptions!$C$16 -> 0 | V41: =0 -> 0 | W41: =SUM(C41:V41) -> -180000
B42: Initial Cash Flow (ICF) | C42: =C41 -> -33582.09 | D42: =D41 -> -67164.179 | E42: =E41 -> -77910.448 | F42: =F41 -> 0 | G42: =G41 -> -1343.2836 | H42: =H41 -> 0 | I42: =I41 -> 0 | J42: =J41 -> 0 | ... V42: =V41 -> 0 | W42: =SUM(C42:V42) -> -180000
A44: Operating FCFF (OCF) | B44: Operating FCFF (OCF) | C44: Operating FCFF (OCF) | D44: Operating FCFF (OCF) | E44: Operating FCFF (OCF) | F44: Operating FCFF (OCF) | G44: Operating FCFF (OCF) | H44: Operating FCFF (OCF) | I44: Operating FCFF (OCF) | J44: Operating FCFF (OCF) | K44: Operating FCFF (OCF) | L44: Operating FCFF (OCF) | M44: Operating FCFF (OCF) | N44: Operating FCFF (OCF) | O44: Operating FCFF (OCF) | P44: Operating FCFF (OCF) | Q44: Operating FCFF (OCF) | R44: Operating FCFF (OCF) | S44: Operating FCFF (OCF) | T44: Operating FCFF (OCF) | U44: Operating FCFF (OCF) | V44: Operating FCFF (OCF) | W44: Operating FCFF (OCF)
B45: Installed Initial Hardware Basis | C45: =-SUM($C$41:C41) -> 33582.09 | D45: =-SUM($C$41:D41) -> 100746.27 | E45: =-SUM($C$41:E41) -> 178656.72 | F45: =-SUM($C$41:F41) -> 178656.72 | G45: =-SUM($C$41:G41) -> 180000 | H45: =-SUM($C$41:H41) -> 180000 | I45: =-SUM($C$41:I41) -> 180000 | J45: =-SUM($C$41:J41) -> 180000 | ... V45: =-SUM($C$41:V41) -> 180000 | W45: =MAX(C45:V45) -> 180000
...
