Workbook

Sheet Cover
A1: Everpure, Inc. (NYSE: PSTG) — Equity Research Financial Model
A3: Ticker / Exchange | B3: PSTG / NYSE
A4: Legal name | B4: Everpure, Inc. (formerly Pure Storage, Inc.)
A5: Fiscal year end | B5: Saturday/Sunday nearest Jan 31 (52/53-week fiscal year)
A6: Units | B6: USD millions unless noted; per-share in USD
A7: Build date | B7: 2026-06-18
A8: Model version | B8: 1.0
A9: Rating | B9: SELL
A10: Price target | B10: =DCF!B48 -> 47.660043
A11: Current price (as-of Jun 18, 2026) | B11: 74.57
A12: Implied return | B12: =Cover!B10/Cover!B11-1 -> -0.3608684
A14: Color convention
A15: Blue font | B15: Hardcoded input (historical actual or forecast assumption)
A16: Black font | B16: Formula referencing same sheet
A17: Green font | B17: Formula referencing another sheet
A18: Red font | B18: Check / cross-check cell

Sheet Historicals
A1: Historicals — Everpure, Inc. ($M, GAAP unless noted) — sourced 10-K FY2025/FY2026; FY22-24 from data export, cross-checked
A3: Fiscal Year | B3: FY2022 | C3: FY2023 | D3: FY2024 | E3: FY2025 | F3: FY2026
A4: Product revenue | B4: 1442.3 | C4: 1792.2 | D4: 1622.9 | E4: 1699.5 | F4: 1971.7
A5: Subscription revenue | B5: 738.5 | C5: 961.3 | D5: 1207.8 | E5: 1468.7 | F5: 1691.2
A6: Product COGS | E6: 575.3 | F6: 651.4
A7: Subscription COGS | E7: 380.1 | F7: 433.4
A8: R&D | B8: 581.9 | C8: 692.5 | D8: 736.8 | E8: 804.4 | F8: 963.3
A9: S&M | E9: 1020.9 | F9: 1181.5
A10: G&A | E10: 286.2 | F10: 318.4
A11: Other income (expense), net | B11: 30.1 | E11: 62.6 | F11: 109.5
A12: Income tax expense | B12: 14.8 | C12: 18.7 | D12: 29.3 | E12: 41.1 | F12: 36.1
A13: Stock-based compensation (total) | B13: 287 | D13: 331.4 | E13: 421.3 | F13: 481.7
A14: D&A | B14: 83.2 | C14: 100.4 | D14: 124.4 | E14: 126.7 | F14: 147.8
A15: Capex | B15: 102.3 | D15: 195.2 | E15: 226.7 | F15: 264.3
A16: Accounts receivable | B16: 542.1 | D16: 662.2 | E16: 680.9 | F16: 944.8
A17: Inventory | B17: 38.9 | D17: 42.7 | E17: 42.8 | F17: 75.9
A18: Prepaid + other current assets | B18: 187.3 | D18: 252.5 | E18: 222.5 | F18: 356
A19: Accounts payable | B19: 70.7 | D19: 82.8 | E19: 112.4 | F19: 153.3
A20: Deferred revenue (total) | B20: 1079.9 | D20: 1594.5 | E20: 1795.3 | F20: 2227.5
A21: Cash + ST investments | B21: 1423.8 | D21: 1540.7 | E21: 1534.4 | F21: 1555
A22: Total debt | B22: 915.4 | D22: 267.9 | E22: 280.8 | F22: 216.1
A23: Net PP&E | E23: 461.7 | F23: 587
A24: Retained earnings / (accumulated deficit) | B24: -1708.3 | D24: -1475.8 | E24: -1369 | F24: -1180.8
A25: Diluted weighted-avg shares | B25: 285.9 | C25: 332.6 | D25: 332.6 | E25: 342.7 | F25: 343
A26: Subscription ARR (FYE) | B26: 848.8 | C26: 1101.3 | D26: 1373.5 | E26: 1657.8 | F26: 1924.3
A27: Subscription NDR | E27: 1.17 | F27: 1.13
A28: Remaining performance obligations (RPO) | F28: 3700
A29: Total revenue | B29: =B4+B5 -> 2180.8 | C29: =C4+C5 -> 2753.5 | D29: =D4+D5 -> 2830.7 | E29: =E4+E5 -> 3168.2 | F29: =F4+F5 -> 3662.9
A30: Total COGS | B30: =IF(AND(B6<>"",B7<>""),B6+B7,"") | C30: =IF(AND(C6<>"",C7<>""),C6+C7,"") | D30: =IF(AND(D6<>"",D7<>""),D6+D7,"") | E30: =IF(AND(E6<>"",E7<>""),E6+E7,"") -> 955.4 | F30: =IF(AND(F6<>"",F7<>""),F6+F7,"") -> 1084.8
A31: Gross profit | B31: =IF(B30<>"",B29-B30,"") | C31: =IF(C30<>"",C29-C30,"") | D31: =IF(D30<>"",D29-D30,"") | E31: =IF(E30<>"",E29-E30,"") -> 2212.8 | F31: =IF(F30<>"",F29-F30,"") -> 2578.1
A32: Gross margin % | B32: =IF(B31<>"",B31/B29,"") | C32: =IF(C31<>"",C31/C29,"") | D32: =IF(D31<>"",D31/D29,"") | E32: =IF(E31<>"",E31/E29,"") -> 0.69844076 | F32: =IF(F31<>"",F31/F29,"") -> 0.70384122
A33: Total opex | B33: =IF(AND(B9<>"",B10<>""),B8+B9+B10,"") | C33: =IF(AND(C9<>"",C10<>""),C8+C9+C10,"") | D33: =IF(AND(D9<>"",D10<>""),D8+D9+D10,"") | E33: =IF(AND(E9<>"",E10<>""),E8+E9+E10,"") -> 2111.5 | F33: =IF(AND(F9<>"",F10<>""),F8+F9+F10,"") -> 2463.2
A34: GAAP operating income | B34: =IF(AND(B31<>"",B33<>""),B31-B33,"") | C34: =IF(AND(C31<>"",C33<>""),C31-C33,"") | D34: =IF(AND(D31<>"",D33<>""),D31-D33,"") | E34: =IF(AND(E31<>"",E33<>""),E31-E33,"") -> 101.3 | F34: =IF(AND(F31<>"",F33<>""),F31-F33,"") -> 114.9
A35: Operating margin % | B35: =IF(B34<>"",B34/B29,"") | C35: =IF(C34<>"",C34/C29,"") | D35: =IF(D34<>"",D34/D29,"") | E35: =IF(E34<>"",E34/E29,"") -> 0.031973992 | F35: =IF(F34<>"",F34/F29,"") -> 0.031368588
A36: Pretax income | B36: =IF(AND(B34<>"",B11<>""),B34+B11,"") | C36: =IF(AND(C34<>"",C11<>""),C34+C11,"") | D36: =IF(AND(D34<>"",D11<>""),D34+D11,"") | E36: =IF(AND(E34<>"",E11<>""),E34+E11,"") -> 163.9 | F36: =IF(AND(F34<>"",F11<>""),F34+F11,"") -> 224.4
A37: Net income | B37: =IF(B36<>"",B36-B12,"") | C37: =IF(C36<>"",C36-C12,"") | D37: =IF(D36<>"",D36-D12,"") | E37: =IF(E36<>"",E36-E12,"") -> 122.8 | F37: =IF(F36<>"",F36-F12,"") -> 188.3
A38: Effective tax rate % | B38: =IF(B36<>"",B12/B36,"") | C38: =IF(C36<>"",C12/C36,"") | D38: =IF(D36<>"",D12/D36,"") | E38: =IF(E36<>"",E12/E36,"") -> 0.25076266 | F38: =IF(F36<>"",F12/F36,"") -> 0.16087344
A39: SBC % of revenue | B39: =IF(B13<>"",B13/B29,"") -> 0.13160308 | C39: =IF(C13<>"",C13/C29,"") | D39: =IF(D13<>"",D13/D29,"") -> 0.11707352 | E39: =IF(E13<>"",E13/E29,"") -> 0.13297772 | F39: =IF(F13<>"",F13/F29,"") -> 0.13150782
A40: Net operating working capital | B40: =IF(AND(B16<>"",B20<>""),B16+B17+B18-B19-B20,"") -> -382.3 | C40: =IF(AND(C16<>"",C20<>""),C16+C17+C18-C19-C20,"") | D40: =IF(AND(D16<>"",D20<>""),D16+D17+D18-D19-D20,"") -> -719.9 | E40: =IF(AND(E16<>"",E20<>""),E16+E17+E18-E19-E20,"") -> -961.5 | F40: =IF(AND(F16<>"",F20<>""),F16+F17+F18-F19-F20,"") -> -1004.1
A41: Net cash (debt) | B41: =B21-B22 -> 508.4 | C41: =C21-C22 -> 0 | D41: =D21-D22 -> 1272.8 | E41: =E21-E22 -> 1253.6 | F41: =F21-F22 -> 1338.9

Sheet Assumptions
A1: Assumptions — forecast inputs (HARDCODED ONLY — drives all forecast tabs by formula)
A3: ID / Driver | B3: FY2027E | C3: FY2028E | D3: FY2029E | E3: FY2030E | F3: FY2031E | G3: Rationale (basis for the assumption)
A4: A.REV.ARR.GROWTH — Subscription ARR YoY growth | B4: 0.18 | C4: 0.174 | D4: 0.15 | E4: 0.132 | F4: 0.111 | G4: Decelerating from FY26's 16% as NDR continues its observed 117%->113% decline on a larger base; company framed FY27 ARR growth as 'high-teens' on the Q1 FY27 call
A5: A.REV.ARR.RECOG — ARR-to-subscription-revenue recognition ratio | B5: 0.88 | C5: 0.88 | D5: 0.89 | E5: 0.89 | F5: 0.9 | G5: Calibrated to historical FY25 (0.886) and FY26 (0.879) ratios of reported subscription revenue to FYE ARR
A6: A.REV.CORE.GROWTH — Core enterprise product revenue growth | B6: 0.15 | C6: 0.15 | D6: 0.13 | E6: 0.1 | F6: 0.1 | G6: Enterprise flash-refresh cycle + DirectFlash density/ASP uplift from AI-driven larger configs; decelerating as base scales
A7: A.REV.HYPER — Hyperscaler product revenue ($M, Lower Confidence — not separately disclosed by company) | B7: 346.7 | C7: 527.4 | D7: 764.1 | E7: 1113.3 | F7: 1490.9 | G7: Back-solved residual so total revenue ties exactly to the company's raised FY27 guidance midpoint ($4.46B) and the report's assumed growth glide path, given Core (15%/15%/13%/10%/10% growth off FY26 actual) and Subscription (ARR-average x recognition-ratio method) are built independently above. Not a disclosed company figure.
A8: A.COGS.PRODUCT.GM — Product gross margin (GAAP) | B8: 0.64 | C8: 0.655 | D8: 0.67 | E8: 0.68 | F8: 0.685 | G8: Compresses from FY26's 67% on the 2026 NAND shortage (TrendForce: 95% QoQ Q1 CY26, 70-75% QoQ Q2 CY26); recovers as new fab capacity arrives late 2027/2028
A9: A.COGS.SUB.GM — Subscription gross margin (GAAP) | B9: 0.74 | C9: 0.745 | D9: 0.75 | E9: 0.755 | F9: 0.76 | G9: Less NAND-exposed (service/support cost base more fixed); modest efficiency gains as Evergreen scales
A10: A.OPEX.NONGAAP.OPMARGIN — Non-GAAP operating margin | B10: 0.188 | C10: 0.205 | D10: 0.22 | E10: 0.23 | F10: 0.235 | G10: FY27 midpoint ties to company-raised guidance ($820-860M / $4.41-4.51B revenue); FY28-31 assume continued opex leverage
A11: A.OPEX.SBC.PCT — SBC % of revenue | B11: 0.12 | C11: 0.11 | D11: 0.105 | E11: 0.1 | F11: 0.095 | G11: Gradual normalization from FY26's 13.2%, consistent with multi-year SBC dilution-management commentary
A12: A.PPE.CAPEX.PCT — Capex % of revenue | B12: 0.075 | C12: 0.073 | D12: 0.07 | E12: 0.068 | F12: 0.065 | G12: Elevated near-term for hyperscaler infrastructure scale-up (10-K), normalizing thereafter
A13: A.PPE.DA.PCT — D&A % of revenue | B13: 0.04 | C13: 0.039 | D13: 0.038 | E13: 0.037 | F13: 0.036 | G13: Held near FY26 actual of 4.0% of revenue
A14: A.TAX.RATE — Effective tax rate | B14: 0.18 | C14: 0.19 | D14: 0.2 | E14: 0.21 | F14: 0.21 | G14: FY26 actual 16.1% was depressed by OBBBA Section 174 R&D-capitalization repeal; normalizing upward
A15: A.OI.OTHER — Other income, net ($M) | B15: 50 | C15: 55 | D15: 60 | E15: 65 | F15: 70 | G15: Normalized interest income on cash balance; FY26's $109.5M was inflated by a one-time equity-security gain
... A30: A.DCF.EXIT_MULT — Terminal exit multiple (EV/EBITDA) | B30: 13 | C30: 13 | D30: 13 | E30: 13 | F30: 13 | G30: Below current peer average (~17x: NetApp 16.2x, Dell 21.2x, HPE 14.0x), reflecting Everpure's smaller scale/single-segment risk at the terminal year

Sheet Revenue_Build
A1: Revenue Build — Q x P decomposition (formulas reference Assumptions + prior-period actuals)
A3: Line | B3: FY2027E | C3: FY2028E | D3: FY2029E | E3: FY2030E | F3: FY2031E
A4: Subscription ARR, beginning | B4: =Historicals!F26 -> 1924.3 | C4: =B6 -> 2270.674 | D4: =C6 -> 2665.7713 | E4: =D6 -> 3065.637 | F4: =E6 -> 3470.301
A5: ARR growth % (driver, from Assumptions) | B5: =Assumptions!B4 -> 0.18 | C5: =Assumptions!C4 -> 0.174 | D5: =Assumptions!D4 -> 0.15 | E5: =Assumptions!E4 -> 0.132 | F5: =Assumptions!F4 -> 0.111
A6: Subscription ARR, ending | B6: =B4*(1+B5) -> 2270.674 | C6: =C4*(1+C5) -> 2665.7713 | D6: =D4*(1+D5) -> 3065.637 | E6: =E4*(1+E5) -> 3470.301 | F6: =F4*(1+F5) -> 3855.5045
A7: Average ARR | B7: =AVERAGE(B4,B6) -> 2097.487 | C7: =AVERAGE(C4,C6) -> 2468.2226 | D7: =AVERAGE(D4,D6) -> 2865.7041 | E7: =AVERAGE(E4,E6) -> 3267.969 | F7: =AVERAGE(F4,F6) -> 3662.9028
A8: ARR-to-revenue recognition ratio (Assumptions) | B8: =Assumptions!B5 -> 0.88 | C8: =Assumptions!C5 -> 0.88 | D8: =Assumptions!D5 -> 0.89 | E8: =Assumptions!E5 -> 0.89 | F8: =Assumptions!F5 -> 0.9
A9: Subscription revenue | B9: =B7*B8 -> 1845.7886 | C9: =C7*C8 -> 2172.0359 | D9: =D7*D8 -> 2550.4767 | E9: =E7*E8 -> 2908.4924 | F9: =F7*F8 -> 3296.6125
A11: Core enterprise product revenue, prior period | B11: =Historicals!F4 -> 1971.7 | C11: =B13 -> 2267.455 | D11: =C13 -> 2607.5732 | E11: =D13 -> 2946.5578 | F11: =E13 -> 3241.2135
A12: Core product growth % (driver, from Assumptions) | B12: =Assumptions!B6 -> 0.15 | C12: =Assumptions!C6 -> 0.15 | D12: =Assumptions!D6 -> 0.13 | E12: =Assumptions!E6 -> 0.1 | F12: =Assumptions!F6 -> 0.1
A13: Core enterprise product revenue | B13: =B11*(1+B12) -> 2267.455 | C13: =C11*(1+C12) -> 2607.5732 | D13: =D11*(1+D12) -> 2946.5578 | E13: =E11*(1+E12) -> 3241.2135 | F13: =F11*(1+F12) -> 3565.3349
A14: Hyperscaler product revenue (Lower Confidence — Assumptions) | B14: =Assumptions!B7 -> 346.7 | C14: =Assumptions!C7 -> 527.4 | D14: =Assumptions!D7 -> 764.1 | E14: =Assumptions!E7 -> 1113.3 | F14: =Assumptions!F7 -> 1490.9
A15: Total product revenue | B15: =B13+B14 -> 2614.155 | C15: =C13+C14 -> 3134.9733 | D15: =D13+D14 -> 3710.6578 | E15: =E13+E14 -> 4354.5135 | F15: =F13+F14 -> 5056.2349
A17: TOTAL REVENUE | B17: =B15+B9 -> 4459.9436 | C17: =C15+C9 -> 5307.0092 | D17: =D15+D9 -> 6261.1344 | E17: =E15+E9 -> 7263.006 | F17: =F15+F9 -> 8352.8474
A18: Total revenue growth % | B18: =B17/Historicals!F29-1 -> 0.21759905 | C18: =C17/B17-1 -> 0.18992743 | D18: =D17/C17-1 -> 0.17978587 | E18: =E17/D17-1 -> 0.16001438 | F18: =F17/E17-1 -> 0.15005377

Sheet Forecast
A1: Forecast — Income Statement, Working Capital, Cash/PP&E/Retained-Earnings Roll-forward, FCFF
A3: Line | B3: FY2027E | C3: FY2028E | D3: FY2029E | E3: FY2030E | F3: FY2031E
A4: Product revenue | B4: =Revenue_Build!B15 -> 2614.155 | C4: =Revenue_Build!C15 -> 3134.9733 | D4: =Revenue_Build!D15 -> 3710.6578 | E4: =Revenue_Build!E15 -> 4354.5135 | F4: =Revenue_Build!F15 -> 5056.2349
A5: Subscription revenue | B5: =Revenue_Build!B9 -> 1845.7886 | C5: =Revenue_Build!C9 -> 2172.0359 | D5: =Revenue_Build!D9 -> 2550.4767 | E5: =Revenue_Build!E9 -> 2908.4924 | F5: =Revenue_Build!F9 -> 3296.6125
A6: Total revenue | B6: =Revenue_Build!B17 -> 4459.9436 | C6: =Revenue_Build!C17 -> 5307.0092 | D6: =Revenue_Build!D17 -> 6261.1344 | E6: =Revenue_Build!E17 -> 7263.006 | F6: =Revenue_Build!F17 -> 8352.8474
A7: Product gross margin % (Assumptions) | B7: =Assumptions!B8 -> 0.64 | C7: =Assumptions!C8 -> 0.655 | D7: =Assumptions!D8 -> 0.67 | E7: =Assumptions!E8 -> 0.68 | F7: =Assumptions!F8 -> 0.685
A8: Subscription gross margin % (Assumptions) | B8: =Assumptions!B9 -> 0.74 | C8: =Assumptions!C9 -> 0.745 | D8: =Assumptions!D9 -> 0.75 | E8: =Assumptions!E9 -> 0.755 | F8: =Assumptions!F9 -> 0.76
A9: Product COGS | B9: =B4*(1-B7) -> 941.0958 | C9: =C4*(1-C7) -> 1081.5658 | D9: =D4*(1-D7) -> 1224.5171 | E9: =E4*(1-E7) -> 1393.4443 | F9: =F4*(1-F7) -> 1592.714
A10: Subscription COGS | B10: =B5*(1-B8) -> 479.90503 | C10: =C5*(1-C8) -> 553.86916 | D10: =D5*(1-D8) -> 637.61917 | E10: =E5*(1-E8) -> 712.58064 | F10: =F5*(1-F8) -> 791.187
A11: Total COGS | B11: =B9+B10 -> 1421.0008 | C11: =C9+C10 -> 1635.4349 | D11: =D9+D10 -> 1862.1362 | E11: =E9+E10 -> 2106.025 | F11: =F9+F10 -> 2383.901
A12: Gross profit | B12: =B6-B11 -> 3038.9427 | C12: =C6-C11 -> 3671.5742 | D12: =D6-D11 -> 4398.9982 | E12: =E6-E11 -> 5156.981 | F12: =F6-F11 -> 5968.9464
A13: Blended gross margin % | B13: =B12/B6 -> 0.68138592 | C13: =C12/C6 -> 0.69183492 | D13: =D12/D6 -> 0.70258805 | E13: =E12/E6 -> 0.71003397 | F13: =F12/F6 -> 0.7146002
A14: Non-GAAP operating margin % (Assumptions) | B14: =Assumptions!B10 -> 0.188 | C14: =Assumptions!C10 -> 0.205 | D14: =Assumptions!D10 -> 0.22 | E14: =Assumptions!E10 -> 0.23 | F14: =Assumptions!F10 -> 0.235
A15: Non-GAAP operating income | B15: =B6*B14 -> 838.46939 | C15: =C6*C14 -> 1087.9369 | D15: =D6*D14 -> 1377.4496 | E15: =E6*E14 -> 1670.4914 | F15: =F6*F14 -> 1962.9191
A16: SBC % of revenue (Assumptions) | B16: =Assumptions!B11 -> 0.12 | C16: =Assumptions!C11 -> 0.11 | D16: =Assumptions!D11 -> 0.105 | E16: =Assumptions!E11 -> 0.1 | F16: =Assumptions!F11 -> 0.095
A17: Stock-based compensation | B17: =B6*B16 -> 535.19323 | C17: =C6*C16 -> 583.77101 | D17: =D6*D16 -> 657.41912 | E17: =E6*E16 -> 726.3006 | F17: =F6*F16 -> 793.5205
A18: GAAP operating income (EBIT) | B18: =B15-B17 -> 303.27616 | C18: =C15-C17 -> 504.16587 | D18: =D15-D17 -> 720.03046 | E18: =E15-E17 -> 944.19078 | F18: =F15-F17 -> 1169.3986
A19: GAAP operating margin % | B19: =B18/B6 -> 0.068 | C19: =C18/C6 -> 0.095 | D19: =D18/D6 -> 0.115 | E19: =E18/E6 -> 0.13 | F19: =F18/F6 -> 0.14
A20: D&A % of revenue (Assumptions) | B20: =Assumptions!B13 -> 0.04 | C20: =Assumptions!C13 -> 0.039 | D20: =Assumptions!D13 -> 0.038 | E20: =Assumptions!E13 -> 0.037 | F20: =Assumptions!F13 -> 0.036
A21: D&A | B21: =B6*B20 -> 178.39774 | C21: =C6*C20 -> 206.97336 | D21: =D6*D20 -> 237.92311 | E21: =E6*E20 -> 268.73122 | F21: =F6*F20 -> 300.70251
A22: EBITDA | B22: =B18+B21 -> 481.6739 | C22: =C18+C21 -> 711.13923 | D22: =D18+D21 -> 957.95357 | E22: =E18+E21 -> 1212.922 | F22: =F18+F21 -> 1470.1011
A23: Other income, net (Assumptions) | B23: =Assumptions!B15 -> 50 | C23: =Assumptions!C15 -> 55 | D23: =Assumptions!D15 -> 60 | E23: =Assumptions!E15 -> 65 | F23: =Assumptions!F15 -> 70
A24: Pretax income | B24: =B18+B23 -> 353.27616 | C24: =C18+C23 -> 559.16587 | D24: =D18+D23 -> 780.03046 | E24: =E18+E23 -> 1009.1908 | F24: =F18+F23 -> 1239.3986
A25: Tax rate (Assumptions) | B25: =Assumptions!B14 -> 0.18 | C25: =Assumptions!C14 -> 0.19 | D25: =Assumptions!D14 -> 0.2 | E25: =Assumptions!E14 -> 0.21 | F25: =Assumptions!F14 -> 0.21
A26: Income tax expense | B26: =B24*B25 -> 63.589709 | C26: =C24*C25 -> 106.24152 | D26: =D24*D25 -> 156.00609 | E26: =E24*E25 -> 211.93006 | F26: =F24*F25 -> 260.27371
A27: Net income | B27: =B24-B26 -> 289.68645 | C27: =C24-C26 -> 452.92436 | D27: =D24-D26 -> 624.02437 | E27: =E24-E26 -> 797.26071 | F27: =F24-F26 -> 979.12492
A29: Working Capital Schedule
A30: DSO days (Assumptions) | B30: =Assumptions!B16 -> 94 | C30: =Assumptions!C16 -> 92 | D30: =Assumptions!D16 -> 90 | E30: =Assumptions!E16 -> 88 | F30: =Assumptions!F16 -> 86
A31: DPO days (Assumptions) | B31: =Assumptions!B17 -> 52 | C31: =Assumptions!C17 -> 52 | D31: =Assumptions!D17 -> 52 | E31: =Assumptions!E17 -> 52 | F31: =Assumptions!F17 -> 52
A32: DIO days (Assumptions) | B32: =Assumptions!B18 -> 25.5 | C32: =Assumptions!C18 -> 25.5 | D32: =Assumptions!D18 -> 25.5 | E32: =Assumptions!E18 -> 25.5 | F32: =Assumptions!F18 -> 25.5
A33: Prepaid % of revenue (Assumptions) | B33: =Assumptions!B19 -> 0.097 | C33: =Assumptions!C19 -> 0.095 | D33: =Assumptions!D19 -> 0.093 | E33: =Assumptions!E19 -> 0.091 | F33: =Assumptions!F19 -> 0.09
A34: Deferred revenue % of revenue (Assumptions) | B34: =Assumptions!B20 -> 0.615 | C34: =Assumptions!C20 -> 0.625 | D34: =Assumptions!D20 -> 0.635 | E34: =Assumptions!E20 -> 0.645 | F34: =Assumptions!F20 -> 0.65
A35: Accounts receivable | B35: =B30*B6/365 -> 1148.5882 | C35: =C30*C6/365 -> 1337.6571 | D35: =D30*D6/365 -> 1543.8414 | E35: =E30*E6/365 -> 1751.0809 | F35: =F30*F6/365 -> 1968.0682
A36: Inventory | B36: =B32*B11/365 -> 99.2754 | C36: =C32*C11/365 -> 114.25641 | D36: =D32*D11/365 -> 130.09445 | E36: =E32*E11/365 -> 147.13325 | F36: =F32*F11/365 -> 166.54651
A37: Prepaid + other current assets | B37: =B33*B6 -> 432.61453 | C37: =C33*C6 -> 504.16587 | D37: =D33*D6 -> 582.2855 | E37: =E33*E6 -> 660.93354 | F37: =F33*F6 -> 751.75626
A38: Accounts payable | B38: =B31*B11/365 -> 202.44395 | C38: =C31*C11/365 -> 232.99347 | D38: =D31*D11/365 -> 265.29064 | E38: =E31*E11/365 -> 300.03644 | F38: =F31*F11/365 -> 339.62425
A39: Deferred revenue | B39: =B34*B6 -> 2742.8653 | C39: =C34*C6 -> 3316.8807 | D39: =D34*D6 -> 3975.8204 | E39: =E34*E6 -> 4684.6388 | F39: =F34*F6 -> 5429.3508
A40: Net operating working capital (NWC) | B40: =B35+B36+B37-B38-B39 -> -1264.8311 | C40: =C35+C36+C37-C38-C39 -> -1593.7948 | D40: =D35+D36+D37-D38-D39 -> -1984.8897 | E40: =E35+E36+E37-E38-E39 -> -2425.5276 | F40: =F35+F36+F37-F38-F39 -> -2882.6041
A41: Change in NWC (this period - prior) | B41: =B40-Historicals!F40 -> -260.73111 | C41: =C40-B40 -> -328.9637 | D41: =D40-C40 -> -391.09488 | E41: =E40-D40 -> -440.63791 | F41: =F40-E40 -> -457.07653
A43: Free Cash Flow Build
...

Sheet DCF
A1: DCF — WACC build (CAPM), FCFF discounting, terminal value cross-check, price target
A3: WACC Build
A4: Risk-free rate (10Y UST) | B4: =Assumptions!B24 -> 0.0449 | C4: Jun 17, 2026 close
A5: Beta (5yr) | B5: =Assumptions!B25 -> 1.33
A6: Equity risk premium | B6: =Assumptions!B26 -> 0.0423 | C6: Damodaran implied ERP, Jan 2026
A7: Cost of equity (Ke) = Rf + Beta x ERP | B7: =B4+B5*B6 -> 0.101159
A8: Pretax cost of debt | B8: =Assumptions!B27 -> 0.054
A9: Tax rate (FY27E, for after-tax Kd) | B9: =Assumptions!B14 -> 0.18
A10: After-tax cost of debt | B10: =B8*(1-B9) -> 0.04428
A11: Weight of debt (book value) | B11: =Assumptions!B28 -> 0.009
A12: Weight of equity | B12: =1-B11 -> 0.991
A13: WACC | B13: =B12*B7+B11*B10 -> 0.10064709
A15: FCFF Discounting (mid-year convention)
A16: Fiscal year | B16: FY2027E | C16: FY2028E | D16: FY2029E | E16: FY2030E | F16: FY2031E
A17: FCFF | B17: =Forecast!B47 -> 353.31954 | C17: =Forecast!C47 -> 556.89974 | D17: =Forecast!D47 -> 766.76295 | E17: =Forecast!E47 -> 961.39544 | F17: =Forecast!F47 -> 1138.6689
A18: Discount period (mid-year) | B18: 0.5 | C18: 1.5 | D18: 2.5 | E18: 3.5 | F18: 4.5
A19: PV of FCFF | B19: =B17/(1+$B$13)^B18 -> 336.77792 | C19: =C17/(1+$B$13)^C18 -> 482.28625 | D19: =D17/(1+$B$13)^D18 -> 603.31051 | E19: =E17/(1+$B$13)^E18 -> 687.28006 | F19: =F17/(1+$B$13)^F18 -> 739.573
A20: Sum PV of explicit FCFF (FY27-31) | B20: =SUM(B19:F19) -> 2849.2277
A22: Terminal Value — two methods, cross-checked
A23: Terminal growth rate g (Gordon) | B23: =Assumptions!B29 -> 0.03
A24: FY31E EBITDA | B24: =Forecast!F22 -> 1470.1011
A25: Terminal exit multiple (EV/EBITDA) | B25: =Assumptions!B30 -> 13
A26: TV (Gordon) = FCFF31 x (1+g) / (WACC-g) | B26: =F17*(1+B23)/(B13-B23) -> 16601.235
A27: PV (TV, Gordon) | B27: =B26/(1+B13)^5 -> 10277.795
A28: TV (Exit multiple) = EBITDA31 x multiple | B28: =B24*B25 -> 19111.315
A29: PV (TV, Exit multiple) | B29: =B28/(1+B13)^5 -> 11831.781
A30: Cross-check: implied g from exit-multiple TV | B30: =(B28*B13-F17)/(B28+F17) -> 0.038757035 | C30: Solve TV_exit = FCFF31*(1+g)/(WACC-g) for g algebraically: g=(TV*WACC - FCFF31)/(TV+FCFF31)
A31: Cross-check: implied exit multiple from Gordon TV | B31: =B26/B24 -> 11.29258
A33: Enterprise Value -> Equity Value -> Price Target
A34: EV (Gordon method) | B34: =B20+B27 -> 13127.023
A35: EV (Exit-multiple method) | B35: =B20+B29 -> 14681.009
A36: EV (Blended average) | B36: =AVERAGE(B34,B35) -> 13904.016
A37: Net cash (Q1 FY27, most recent reported) | B37: =Historicals!F41 -> 1338.9 | C37: 10-K/10-Q ; held at FY26 level as a conservative proxy for the most recent balance sheet
A38: Equity value (Gordon) | B38: =B34+B37 -> 14465.923
A39: Equity value (Exit multiple) | B39: =B35+B37 -> 16019.909
A40: Equity value (Blended) | B40: =B36+B37 -> 15242.916
A41: Diluted shares outstanding (Q1 FY27 10-Q) | B41: 343.5
A42: Implied price/share (Gordon) | B42: =B38/B41 -> 42.113313
A43: Implied price/share (Exit multiple) | B43: =B39/B41 -> 46.637289
A44: DCF price/share (blended) | B44: =B40/B41 -> 44.375301
...

Sheet Comps
A1: Comparable Companies — cross-check ONLY (does not set the price target)
A3: Everpure current market data
A4: Shares outstanding (basic) | B4: 332.4 | C4: stockanalysis.com, Jun 18 2026
A5: Market cap (basic shares x current price) | B5: =B4*DCF!B49 -> 24787.068
A6: EV = Market cap + total debt - net cash | B6: =B5+Historicals!F22-DCF!B37 -> 23664.268
A7: EV / NTM revenue (FY27E) | B7: =B6/Forecast!B6 -> 5.3059568
A8: EV / NTM EBITDA, GAAP (FY27E) | B8: =B6/Forecast!B22 -> 49.12923
A10: Peer comparison
A11: Company | B11: EV/Revenue | C11: EV/EBITDA | D11: P/E | E11: Rev growth (3yr fwd) | F11: Gross margin | G11: Op margin
A12: Everpure (PSTG) — current | B12: =B7 -> 5.3059568 | C12: =B8 -> 49.12923 | D12: 111.8
A13: NetApp (NTAP) | B13: 4.41 | C13: 16.2 | D13: 25.13 | E13: 0.064 | F13: 0.707 | G13: 0.245
A14: Dell Technologies (DELL) | B14: 2.22 | C14: 21.15 | D14: 33.52 | E14: 0.218 | F14: 0.192 | G14: 0.084
A15: HPE | B15: 2.03 | C15: 13.98 | D15: 44.97 | E15: 0.148 | F15: 0.338 | G15: 0.06
A16: Peer average (NTAP/DELL/HPE) | B16: =AVERAGE(B13:B15) -> 2.8866667 | C16: =AVERAGE(C13:C15) -> 17.11 | D16: =AVERAGE(D13:D15) -> 34.54 | E16: =AVERAGE(E13:E15) -> 0.14333333 | F16: =AVERAGE(F13:F15) -> 0.41233333 | G16: =AVERAGE(G13:G15) -> 0.12966667
A18: Cross-check: comps-implied price
A19: Chosen EV/Revenue multiple (growth/quality-adjusted) | B19: 3.75 | C19: Above peer average (~2.89x) given Everpure's superior gross margin/growth; below a pure-SaaS multiple given hardware mix and NAND-cycle risk
A20: Implied EV = multiple x FY27E revenue | B20: =B19*Forecast!B6 -> 16724.788
A21: Implied equity value = EV + net cash | B21: =B20+DCF!B37 -> 18063.688
A22: COMPS-IMPLIED PRICE/SHARE | B22: =B21/DCF!B41 -> 52.587157
