Workbook

Sheet Summary
B1: Model Summary and Assumptions
B2: Base Case | ($ in thousands)
B4: Source of Funds | C4: $ | D4: % | E4: x EBITDA | F4: 2014 Mult. | H4: Ownership | I4: Coupon % | J4: Terminal %
B5: Cash on Balance Sheet | C5: ='Key Assumptions'!C85 -> 921.8 | D5: =IF(C15=0,0,C5/C15) -> 0.034380128 | E5: ='Key Assumptions'!D85 -> 0.2 | F5: =IF('Income Statement'!G24=0,0,C5/'Income Statement'!G24) -> 0.16346678 | H5: Sr. Sub Notes | I5: ='Key Assumptions'!C113 -> 0.13 | J5: ='Key Assumptions'!C127 -> 0.05
B6: Revolving Line of Credit | C6: ='Key Assumptions'!C86 -> 0 | D6: =IF(C15=0,0,C6/C15) -> 0 | E6: ='Key Assumptions'!D86 -> 0 | F6: =IF('Income Statement'!G24=0,0,C6/'Income Statement'!G24) -> 0 | H6: Part. Pref. | I6: ='Key Assumptions'!C116 -> 0.15 | J6: ='Key Assumptions'!C128 -> 0.15
B7: Senior Term Loan | C7: ='Key Assumptions'!C87 -> 7835.3 | D7: =IF(C15=0,0,C7/C15) -> 0.29223109 | E7: ='Key Assumptions'!D87 -> 1.7 | F7: =IF('Income Statement'!G24=0,0,C7/'Income Statement'!G24) -> 1.3894676
B8: Seacoast Senior Sub. Notes | C8: ='Key Assumptions'!C88 -> 7835.3 | D8: =IF(C15=0,0,C8/C15) -> 0.29223109 | E8: ='Key Assumptions'!D88 -> 1.7 | F8: =IF('Income Statement'!G24=0,0,C8/'Income Statement'!G24) -> 1.3894676 | H8: Exit Multiple | I8: Low | J8: Base | K8: High
B9: Seller Note | C9: ='Key Assumptions'!C89 -> 921.8 | D9: =IF(C15=0,0,C9/C15) -> 0.034380128 | E9: ='Key Assumptions'!D89 -> 0.2 | F9: =IF('Income Statement'!G24=0,0,C9/'Income Statement'!G24) -> 0.16346678 | I9: ='Key Assumptions'!C131 -> 4 | J9: ='Key Assumptions'!C132 -> 5 | K9: ='Key Assumptions'!C133 -> 6
B10: Seller Working Capital Holdback | C10: ='Key Assumptions'!C90 -> 921.8 | D10: =IF(C15=0,0,C10/C15) -> 0.034380128 | E10: ='Key Assumptions'!D90 -> 0.2 | F10: =IF('Income Statement'!G24=0,0,C10/'Income Statement'!G24) -> 0.16346678
B11: Seacoast Participating Pref. Stock | C11: ='Key Assumptions'!C91 -> 1843.6 | D11: =IF(C15=0,0,C11/C15) -> 0.068760257 | E11: ='Key Assumptions'!D91 -> 0.4 | F11: =IF('Income Statement'!G24=0,0,C11/'Income Statement'!G24) -> 0.32693355 | H11: 5-Year Returns | I11: Low | J11: Base | K11: High
B12: Investments Particip. Pref. Stock | C12: ='Key Assumptions'!C92 -> 4609 | D12: =IF(C15=0,0,C12/C15) -> 0.17190064 | E12: ='Key Assumptions'!D92 -> 1 | F12: =IF('Income Statement'!G24=0,0,C12/'Income Statement'!G24) -> 0.81733388 | H12: Subordinated Debt
B13: Tom Participating Pref. Stock | C13: ='Key Assumptions'!C93 -> 460.9 | D13: =IF(C15=0,0,C13/C15) -> 0.017190064 | E13: ='Key Assumptions'!D93 -> 0.1 | F13: =IF('Income Statement'!G24=0,0,C13/'Income Statement'!G24) -> 0.081733388 | H13: IRR | I13: ='Returns Analysis'!C24 -> 0.17226024 | J13: ='Returns Analysis'!D24 -> 0.17886905 | K13: ='Returns Analysis'!E24 -> 0.18531717
B14: Mgmt. Equity Common Class A (PLUG) | C14: ='Key Assumptions'!C94 -> 1462.5 | D14: =IF(C15=0,0,C14/C15) -> 0.054546472 | E14: ='Key Assumptions'!D94 -> 0.31731395 | F14: =IF('Income Statement'!G24=0,0,C14/'Income Statement'!G24) -> 0.25935144 | H14: MOIC | I14: ='Returns Analysis'!C25 -> 1.9428319 | J14: ='Returns Analysis'!D25 -> 1.9937107 | K14: ='Returns Analysis'!E25 -> 2.0445894
B15: Total | C15: =SUM(C5:C14) -> 26812 | D15: =SUM(D5:D14) -> 1 | E15: =IF('Key Assumptions'!$F$84=0,0,C15/'Key Assumptions'!$F$84) -> 5.817314 | F15: =IF('Income Statement'!G24=0,0,C15/'Income Statement'!G24) -> 4.7546878
H16: Part. Pref.
B17: Use of Funds | C17: $ | D17: % | E17: x EBITDA | F17: 2014 Mult. | H17: IRR | I17: ='Returns Analysis'!C37 -> 0.32472714 | J17: ='Returns Analysis'!D37 -> 0.36440594 | K17: ='Returns Analysis'!E37 -> 0.39994302
B18: Cash to Sellers | C18: ='Key Assumptions'!C98 -> 16392 | D18: =IF(C30=0,0,C18/C30) -> 0.61136804 | E18: =IF('Key Assumptions'!$F$84=0,0,C18/'Key Assumptions'!$F$84) -> 3.5565199 | F18: =IF('Income Statement'!G24=0,0,C18/'Income Statement'!G24) -> 2.9068642 | H18: MOIC | I18: ='Returns Analysis'!C38 -> 4.079737 | J18: ='Returns Analysis'!D38 -> 4.7284413 | K18: ='Returns Analysis'!E38 -> 5.3771456
B19: Retire Existing Debt | C19: ='Key Assumptions'!C99 -> 2435 | D19: =IF(C30=0,0,C19/C30) -> 0.090817544 | E19: =IF('Key Assumptions'!$F$84=0,0,C19/'Key Assumptions'!$F$84) -> 0.52831417 | F19: =IF('Income Statement'!G24=0,0,C19/'Income Statement'!G24) -> 0.43180907
B20: Retire Seller Note Payable to Tom | C20: ='Key Assumptions'!C100 -> 176 | D20: =IF(C30=0,0,C20/C30) -> 0.006564225 | E20: =IF('Key Assumptions'!$F$84=0,0,C20/'Key Assumptions'!$F$84) -> 0.038186158 | F20: =IF('Income Statement'!G24=0,0,C20/'Income Statement'!G24) -> 0.03121084 | H20: Blended
B21: Retire Note Payable to Richard | C21: ='Key Assumptions'!C101 -> 93 | D21: =IF(C30=0,0,C21/C30) -> 0.0034685962 | E21: =IF('Key Assumptions'!$F$84=0,0,C21/'Key Assumptions'!$F$84) -> 0.020177913 | F21: =IF('Income Statement'!G24=0,0,C21/'Income Statement'!G24) -> 0.016492092 | H21: IRR | I21: ='Returns Analysis'!C46 -> 0.21365388 | J21: ='Returns Analysis'!D46 -> 0.23093746 | K21: ='Returns Analysis'!E46 -> 0.24723488
B22: Mgmt. Equity | C22: ='Key Assumptions'!C102 -> 886 | D22: =IF(C30=0,0,C22/C30) -> 0.033044905 | E22: =IF('Key Assumptions'!$F$84=0,0,C22/'Key Assumptions'!$F$84) -> 0.19223259 | F22: =IF('Income Statement'!G24=0,0,C22/'Income Statement'!G24) -> 0.15711821 | H22: MOIC | I22: ='Returns Analysis'!C47 -> 2.3498614 | J22: ='Returns Analysis'!D47 -> 2.5146117 | K22: ='Returns Analysis'!E47 -> 2.679362
B23: Capital Equipment Purchases | C23: ='Key Assumptions'!C103 -> 2150 | D23: =IF(C30=0,0,C23/C30) -> 0.080187976 | E23: =IF('Key Assumptions'!$F$84=0,0,C23/'Key Assumptions'!$F$84) -> 0.46647863 | F23: =IF('Income Statement'!G24=0,0,C23/'Income Statement'!G24) -> 0.38126879
B24: Cash/Working Capital | C24: ='Key Assumptions'!C104 -> 1861 | D24: =IF(C30=0,0,C24/C30) -> 0.06940922 | E24: =IF('Key Assumptions'!$F$84=0,0,C24/'Key Assumptions'!$F$84) -> 0.40377522 | F24: =IF('Income Statement'!G24=0,0,C24/'Income Statement'!G24) -> 0.33001917
B25: Seller Note | C25: ='Key Assumptions'!C105 -> 1000 | D25: =IF(C30=0,0,C25/C30) -> 0.037296733 | E25: =IF('Key Assumptions'!$F$84=0,0,C25/'Key Assumptions'!$F$84) -> 0.2169668 | F25: =IF('Income Statement'!G24=0,0,C25/'Income Statement'!G24) -> 0.17733432
B26: Seller WC Holdback | C26: ='Key Assumptions'!C106 -> 939 | D26: =IF(C30=0,0,C26/C30) -> 0.035021632 | E26: =IF('Key Assumptions'!$F$84=0,0,C26/'Key Assumptions'!$F$84) -> 0.20373183 | F26: =IF('Income Statement'!G24=0,0,C26/'Income Statement'!G24) -> 0.16651693
B28: Financing Fees | C28: ='Key Assumptions'!C107 -> 280 | D28: =IF(C30=0,0,C28/C30) -> 0.010443085 | E28: =IF('Key Assumptions'!$F$84=0,0,C28/'Key Assumptions'!$F$84) -> 0.060750705 | F28: =IF('Income Statement'!G24=0,0,C28/'Income Statement'!G24) -> 0.049653609
B29: Transaction Expenses | C29: ='Key Assumptions'!C108 -> 600 | D29: =IF(C30=0,0,C29/C30) -> 0.02237804 | E29: =IF('Key Assumptions'!$F$84=0,0,C29/'Key Assumptions'!$F$84) -> 0.13018008 | F29: =IF('Income Statement'!G24=0,0,C29/'Income Statement'!G24) -> 0.10640059
B30: Total | C30: =SUM(C18:C26)+C28+C29 -> 26812 | D30: =SUM(D18:D29) -> 1 | E30: =IF('Key Assumptions'!$F$84=0,0,C30/'Key Assumptions'!$F$84) -> 5.817314 | F30: =IF('Income Statement'!G24=0,0,C30/'Income Statement'!G24) -> 4.7546878

Sheet Key Assumptions
B1: Key Growth & Ratio Assumptions
B2: Environmental Services, Inc. | ($ in thousands)
B10: Segment Revenue Assumptions ($K)
C11: 2010A | D11: 2011A | E11: 2012A | F11: 2013A | G11: 2014P | H11: 2015P | I11: 2016P | J11: 2017P | K11: 2018P
B12: Industrial Services Revenue | C12: 9535 | D12: 15767 | E12: 19665 | F12: 16610
B13: Growth Rate | G13: 0.06 | H13: 0.06 | I13: 0.06 | J13: 0.06 | K13: 0.06
B14: Emergency Response Revenue | C14: 4767 | D14: 8044 | E14: 10034 | F14: 8651
B15: Growth Rate | G15: 0.04 | H15: 0.04 | I15: 0.04 | J15: 0.04 | K15: 0.04
B16: Transportation & Disposal Revenue | C16: 4767 | D16: 8366 | E16: 10436 | F16: 9343
B17: Growth Rate | G17: 0.04 | H17: 0.04 | I17: 0.04 | J17: 0.04 | K17: 0.04
B19: Segment Gross Margin Assumptions
B20: Industrial Services Gross Margin | C20: 0.455 | D20: 0.45 | E20: 0.47 | F20: 0.47 | G20: 0.48 | H20: 0.483 | I20: 0.486 | J20: 0.489 | K20: 0.492
B21: Emergency Response Gross Margin | C21: 0.51 | D21: 0.505 | E21: 0.51 | F21: 0.515 | G21: 0.52 | H21: 0.522 | I21: 0.524 | J21: 0.526 | K21: 0.528
B22: Transportation & Disposal Gross Margin | C22: 0.48 | D22: 0.475 | E22: 0.49 | F22: 0.5 | G22: 0.5 | H22: 0.502 | I22: 0.504 | J22: 0.506 | K22: 0.508
B24: Operating Expense Assumptions (% of Revenue)
B25: Salaries & Wages | C25: 0.22 | D25: 0.218 | E25: 0.222 | F25: 0.24 | G25: 0.215 | H25: 0.212 | I25: 0.209 | J25: 0.206 | K25: 0.203
B26: Rent & Facilities | C26: 0.04 | D26: 0.038 | E26: 0.037 | F26: 0.042 | G26: 0.038 | H26: 0.038 | I26: 0.038 | J26: 0.038 | K26: 0.038
B27: Insurance | C27: 0.03 | D27: 0.032 | E27: 0.031 | F27: 0.035 | G27: 0.03 | H27: 0.03 | I27: 0.03 | J27: 0.03 | K27: 0.03
B28: Vehicle & Equipment | C28: 0.025 | D28: 0.027 | E28: 0.028 | F28: 0.03 | G28: 0.025 | H28: 0.025 | I28: 0.025 | J28: 0.025 | K28: 0.025
B29: Other SG&A | C29: 0.06 | D29: 0.058 | E29: 0.052 | F29: 0.06 | G29: 0.032 | H29: 0.031 | I29: 0.03 | J29: 0.029 | K29: 0.028
B31: D&A and Capital Expenditure Assumptions ($K)
B32: Depreciation & Amortization | C32: 800 | D32: 950 | E32: 1100 | F32: 1200 | G32: 1300 | H32: 1400 | I32: 1500 | J32: 1600 | K32: 1700
B33: Maintenance CapEx | G33: 800 | H33: 850 | I33: 900 | J33: 950 | K33: 1000
B34: Growth CapEx | G34: 700 | H34: 750 | I34: 800 | J34: 850 | K34: 900
B35: Total CapEx | G35: =G33+G34 -> 1500 | H35: =H33+H34 -> 1600 | I35: =I33+I34 -> 1700 | J35: =J33+J34 -> 1800 | K35: =K33+K34 -> 1900
B37: Working Capital Assumptions
B38: A/R Days Sales Outstanding | C38: 55 | D38: 54 | E38: 53.5 | F38: 57.3 | G38: 57.3 | H38: 56.2 | I38: 55.1 | J38: 54 | K38: 52.9
B39: Inventory Days (on COGS) | C39: 7 | D39: 7.2 | E39: 7.3 | F39: 7.3 | G39: 7.3 | H39: 7.4 | I39: 7.5 | J39: 7.6 | K39: 7.7
B40: A/P Days (on COGS) | C40: 55 | D40: 56 | E40: 57.5 | F40: 57.2 | G40: 57.2 | H40: 57.7 | I40: 58.2 | J40: 58.7 | K40: 59.2
B41: Accrued Expenses (% of Revenue) | C41: 0.04 | D41: 0.04 | E41: 0.04 | F41: 0.04 | G41: 0.04 | H41: 0.04 | I41: 0.04 | J41: 0.04 | K41: 0.04
B42: Other Current Assets ($K, flat) | G42: 200 | H42: 200 | I42: 200 | J42: 200 | K42: 200
B43: Other Current Liabilities ($K, flat) | G43: 150 | H43: 150 | I43: 150 | J43: 150 | K43: 150
B45: Implied SG&A % of Revenue (check)
B46: Total SG&A % | C46: =SUM(C25:C29) -> 0.375 | D46: =SUM(D25:D29) -> 0.373 | E46: =SUM(E25:E29) -> 0.37 | F46: =SUM(F25:F29) -> 0.407 | G46: =SUM(G25:G29) -> 0.34 | H46: =SUM(H25:H29) -> 0.336 | I46: =SUM(I25:I29) -> 0.332 | J46: =SUM(J25:J29) -> 0.328 | K46: =SUM(K25:K29) -> 0.324
B48: CapEx / D&A (check)
B49: CapEx / D&A | G49: =IF(G32=0,0,G35/G32) -> 1.1538462 | H49: =IF(H32=0,0,H35/H32) -> 1.1428571 | I49: =IF(I32=0,0,I35/I32) -> 1.1333333 | J49: =IF(J32=0,0,J35/J32) -> 1.125 | K49: =IF(K32=0,0,K35/K32) -> 1.1176471
B78: Deal Information
B79: Company Name | C79: Environmental Services, Inc.
B80: Analyst | C80: [Name]
B81: Close Date | C81: 12/31/2013
...

Sheet Revenue Build
B1: Revenue Build by Segment
B2: ($ in thousands)
C4: 2010A | D4: 2011A | E4: 2012A | F4: 2013A | G4: 2014P | H4: 2015P | I4: 2016P | J4: 2017P | K4: 2018P | L4: CAGR
B6: Industrial Services
B7: Revenue | C7: ='Key Assumptions'!C12 -> 9535 | D7: ='Key Assumptions'!D12 -> 15767 | E7: ='Key Assumptions'!E12 -> 19665 | F7: ='Key Assumptions'!F12 -> 16610 | G7: =F7*(1+'Key Assumptions'!G13) -> 17606.6 | H7: =G7*(1+'Key Assumptions'!H13) -> 18662.996 | I7: =H7*(1+'Key Assumptions'!I13) -> 19782.776 | J7: =I7*(1+'Key Assumptions'!J13) -> 20969.742 | K7: =J7*(1+'Key Assumptions'!K13) -> 22227.927 | L7: =IF(G7=0,0,(K7/G7)^(1/4)-1) -> 0.06
B8: Growth Rate | D8: =IF(C7=0,0,(D7-C7)/C7) -> 0.65359203 | E8: =IF(D7=0,0,(E7-D7)/D7) -> 0.24722522 | F8: =IF(E7=0,0,(F7-E7)/E7) -> -0.15535215 | G8: =IF(F7=0,0,(G7-F7)/F7) -> 0.06 | H8: =IF(G7=0,0,(H7-G7)/G7) -> 0.06 | I8: =IF(H7=0,0,(I7-H7)/H7) -> 0.06 | J8: =IF(I7=0,0,(J7-I7)/I7) -> 0.06 | K8: =IF(J7=0,0,(K7-J7)/J7) -> 0.06
B9: Gross Margin | C9: ='Key Assumptions'!C20 -> 0.455 | D9: ='Key Assumptions'!D20 -> 0.45 | E9: ='Key Assumptions'!E20 -> 0.47 | F9: ='Key Assumptions'!F20 -> 0.47 | G9: ='Key Assumptions'!G20 -> 0.48 | H9: ='Key Assumptions'!H20 -> 0.483 | I9: ='Key Assumptions'!I20 -> 0.486 | J9: ='Key Assumptions'!J20 -> 0.489 | K9: ='Key Assumptions'!K20 -> 0.492
B10: Segment Gross Profit | C10: =C7*C9 -> 4338.425 | D10: =D7*D9 -> 7095.15 | E10: =E7*E9 -> 9242.55 | F10: =F7*F9 -> 7806.7 | G10: =G7*G9 -> 8451.168 | H10: =H7*H9 -> 9014.2271 | I10: =I7*I9 -> 9614.429 | J10: =J7*J9 -> 10254.204 | K10: =K7*K9 -> 10936.14
B12: Emergency Response
B13: Revenue | C13: ='Key Assumptions'!C14 -> 4767 | D13: ='Key Assumptions'!D14 -> 8044 | E13: ='Key Assumptions'!E14 -> 10034 | F13: ='Key Assumptions'!F14 -> 8651 | G13: =F13*(1+'Key Assumptions'!G15) -> 8997.04 | H13: =G13*(1+'Key Assumptions'!H15) -> 9356.9216 | I13: =H13*(1+'Key Assumptions'!I15) -> 9731.1985 | J13: =I13*(1+'Key Assumptions'!J15) -> 10120.446 | K13: =J13*(1+'Key Assumptions'!K15) -> 10525.264 | L13: =IF(G13=0,0,(K13/G13)^(1/4)-1) -> 0.04
B14: Growth Rate | D14: =IF(C13=0,0,(D13-C13)/C13) -> 0.68743445 | E14: =IF(D13=0,0,(E13-D13)/D13) -> 0.24738936 | F14: =IF(E13=0,0,(F13-E13)/E13) -> -0.13783137 | G14: =IF(F13=0,0,(G13-F13)/F13) -> 0.04 | H14: =IF(G13=0,0,(H13-G13)/G13) -> 0.04 | I14: =IF(H13=0,0,(I13-H13)/H13) -> 0.04 | J14: =IF(I13=0,0,(J13-I13)/I13) -> 0.04 | K14: =IF(J13=0,0,(K13-J13)/J13) -> 0.04
B15: Gross Margin | C15: ='Key Assumptions'!C21 -> 0.51 | D15: ='Key Assumptions'!D21 -> 0.505 | E15: ='Key Assumptions'!E21 -> 0.51 | F15: ='Key Assumptions'!F21 -> 0.515 | G15: ='Key Assumptions'!G21 -> 0.52 | H15: ='Key Assumptions'!H21 -> 0.522 | I15: ='Key Assumptions'!I21 -> 0.524 | J15: ='Key Assumptions'!J21 -> 0.526 | K15: ='Key Assumptions'!K21 -> 0.528
B16: Segment Gross Profit | C16: =C13*C15 -> 2431.17 | D16: =D13*D15 -> 4062.22 | E16: =E13*E15 -> 5117.34 | F16: =F13*F15 -> 4455.265 | G16: =G13*G15 -> 4678.4608 | H16: =H13*H15 -> 4884.3131 | I16: =I13*I15 -> 5099.148 | J16: =J13*J15 -> 5323.3548 | K16: =K13*K15 -> 5557.3395
B18: Transportation & Disposal
B19: Revenue | C19: ='Key Assumptions'!C16 -> 4767 | D19: ='Key Assumptions'!D16 -> 8366 | E19: ='Key Assumptions'!E16 -> 10436 | F19: ='Key Assumptions'!F16 -> 9343 | G19: =F19*(1+'Key Assumptions'!G17) -> 9716.72 | H19: =G19*(1+'Key Assumptions'!H17) -> 10105.389 | I19: =H19*(1+'Key Assumptions'!I17) -> 10509.604 | J19: =I19*(1+'Key Assumptions'!J17) -> 10929.989 | K19: =J19*(1+'Key Assumptions'!K17) -> 11367.188 | L19: =IF(G19=0,0,(K19/G19)^(1/4)-1) -> 0.04
B20: Growth Rate | D20: =IF(C19=0,0,(D19-C19)/C19) -> 0.75498217 | E20: =IF(D19=0,0,(E19-D19)/D19) -> 0.24743007 | F20: =IF(E19=0,0,(F19-E19)/E19) -> -0.10473361 | G20: =IF(F19=0,0,(G19-F19)/F19) -> 0.04 | H20: =IF(G19=0,0,(H19-G19)/G19) -> 0.04 | I20: =IF(H19=0,0,(I19-H19)/H19) -> 0.04 | J20: =IF(I19=0,0,(J19-I19)/I19) -> 0.04 | K20: =IF(J19=0,0,(K19-J19)/J19) -> 0.04
B21: Gross Margin | C21: ='Key Assumptions'!C22 -> 0.48 | D21: ='Key Assumptions'!D22 -> 0.475 | E21: ='Key Assumptions'!E22 -> 0.49 | F21: ='Key Assumptions'!F22 -> 0.5 | G21: ='Key Assumptions'!G22 -> 0.5 | H21: ='Key Assumptions'!H22 -> 0.502 | I21: ='Key Assumptions'!I22 -> 0.504 | J21: ='Key Assumptions'!J22 -> 0.506 | K21: ='Key Assumptions'!K22 -> 0.508
B22: Segment Gross Profit | C22: =C19*C21 -> 2288.16 | D22: =D19*D21 -> 3973.85 | E22: =E19*E21 -> 5113.64 | F22: =F19*F21 -> 4671.5 | G22: =G19*G21 -> 4858.36 | H22: =H19*H21 -> 5072.9052 | I22: =I19*I21 -> 5296.8406 | J22: =J19*J21 -> 5530.5742 | K22: =K19*K21 -> 5774.5315
B24: Consolidated Revenue Summary
B25: Total Revenue | C25: =C7+C13+C19 -> 19069 | D25: =D7+D13+D19 -> 32177 | E25: =E7+E13+E19 -> 40135 | F25: =F7+F13+F19 -> 34604 | G25: =G7+G13+G19 -> 36320.36 | H25: =H7+H13+H19 -> 38125.306 | I25: =I7+I13+I19 -> 40023.579 | J25: =J7+J13+J19 -> 42020.177 | K25: =K7+K13+K19 -> 44120.379 | L25: =IF(G25=0,0,(K25/G25)^(1/4)-1) -> 0.049837962
B26: Total Revenue Growth | D26: =IF(C25=0,0,(D25-C25)/C25) -> 0.6873984 | E26: =IF(D25=0,0,(E25-D25)/D25) -> 0.24731951 | F26: =IF(E25=0,0,(F25-E25)/E25) -> -0.13780989 | G26: =IF(F25=0,0,(G25-F25)/F25) -> 0.049600046 | H26: =IF(G25=0,0,(H25-G25)/G25) -> 0.049695168 | I26: =IF(H25=0,0,(I25-H25)/H25) -> 0.049790345 | J26: =IF(I25=0,0,(J25-I25)/I25) -> 0.049885561 | K26: =IF(J25=0,0,(K25-J25)/J25) -> 0.049980797
B28: Total Gross Profit | C28: =C10+C16+C22 -> 9057.755 | D28: =D10+D16+D22 -> 15131.22 | E28: =E10+E16+E22 -> 19473.53 | F28: =F10+F16+F22 -> 16933.465 | G28: =G10+G16+G22 -> 17987.989 | H28: =H10+H16+H22 -> 18971.445 | I28: =I10+I16+I22 -> 20010.418 | J28: =J10+J16+J22 -> 21108.133 | K28: =K10+K16+K22 -> 22268.011
B29: Blended Gross Margin | C29: =IF(C25=0,0,C28/C25) -> 0.47499895 | D29: =IF(D25=0,0,D28/D25) -> 0.47024956 | E29: =IF(E25=0,0,E28/E25) -> 0.4852007 | F29: =IF(F25=0,0,F28/F25) -> 0.48934993 | G29: =IF(G25=0,0,G28/G25) -> 0.4952591 | H29: =IF(H25=0,0,H28/H25) -> 0.49760768 | I29: =IF(I25=0,0,I28/I25) -> 0.49996573 | J29: =IF(J25=0,0,J28/J25) -> 0.50233327 | K29: =IF(K25=0,0,K28/K25) -> 0.50471033
B31: Revenue Concentration (Top Customers)
B32: Customer 1 (e.g., Oxy) | G32: 0.25 | H32: 0.25 | I32: 0.25 | J32: 0.25 | K32: 0.25
B33: Customer 2 (e.g., SoCal Edison) | G33: 0.15 | H33: 0.15 | I33: 0.15 | J33: 0.15 | K33: 0.15
B34: Customer 3 (e.g., SoCal Gas) | G34: 0.1 | H34: 0.1 | I34: 0.1 | J34: 0.1 | K34: 0.1
B35: Customer 4 (e.g., Berry Petroleum) | G35: 0.08 | H35: 0.08 | I35: 0.08 | J35: 0.08 | K35: 0.08
B36: Top 4 Concentration | G36: =SUM(G32:G35) -> 0.58 | H36: =SUM(H32:H35) -> 0.58 | I36: =SUM(I32:I35) -> 0.58 | J36: =SUM(J32:J35) -> 0.58 | K36: =SUM(K32:K35) -> 0.58
B37: Top 4 Revenue ($K) | G37: =G36*G25 -> 21065.809 | H37: =H36*H25 -> 22112.678 | I37: =I36*I25 -> 23213.676 | J37: =J36*J25 -> 24371.703 | K37: =K36*K25 -> 25589.82

Sheet Income Statement
B1: Projected Income Statement
B2: ($ in thousands)
C4: 2010A | D4: 2011A | E4: 2012A | F4: 2013A | G4: 2014P | H4: 2015P | I4: 2016P | J4: 2017P | K4: 2018P | L4: CAGR
B6: Revenues | C6: ='Revenue Build'!C25 -> 19069 | D6: ='Revenue Build'!D25 -> 32177 | E6: ='Revenue Build'!E25 -> 40135 | F6: ='Revenue Build'!F25 -> 34604 | G6: ='Revenue Build'!G25 -> 36320.36 | H6: ='Revenue Build'!H25 -> 38125.306 | I6: ='Revenue Build'!I25 -> 40023.579 | J6: ='Revenue Build'!J25 -> 42020.177 | K6: ='Revenue Build'!K25 -> 44120.379 | L6: =IF(G6=0,0,(K6/G6)^(1/4)-1) -> 0.049837962
B7: Growth Rate | C7: ='Revenue Build'!C26 -> 0 | D7: ='Revenue Build'!D26 -> 0.6873984 | E7: ='Revenue Build'!E26 -> 0.24731951 | F7: ='Revenue Build'!F26 -> -0.13780989 | G7: ='Revenue Build'!G26 -> 0.049600046 | H7: ='Revenue Build'!H26 -> 0.049695168 | I7: ='Revenue Build'!I26 -> 0.049790345 | J7: ='Revenue Build'!J26 -> 0.049885561 | K7: ='Revenue Build'!K26 -> 0.049980797
B9: Cost of Goods Sold | C9: =C6-C11 -> 10011.245 | D9: =D6-D11 -> 17045.78 | E9: =E6-E11 -> 20661.47 | F9: =F6-F11 -> 17670.535 | G9: =G6-G11 -> 18332.371 | H9: =H6-H11 -> 19153.861 | I9: =I6-I11 -> 20013.161 | J9: =J6-J11 -> 20912.044 | K9: =K6-K11 -> 21852.368
B11: Gross Profit | C11: ='Revenue Build'!C28 -> 9057.755 | D11: ='Revenue Build'!D28 -> 15131.22 | E11: ='Revenue Build'!E28 -> 19473.53 | F11: ='Revenue Build'!F28 -> 16933.465 | G11: ='Revenue Build'!G28 -> 17987.989 | H11: ='Revenue Build'!H28 -> 18971.445 | I11: ='Revenue Build'!I28 -> 20010.418 | J11: ='Revenue Build'!J28 -> 21108.133 | K11: ='Revenue Build'!K28 -> 22268.011
B12: Gross Margin | C12: ='Revenue Build'!C29 -> 0.47499895 | D12: ='Revenue Build'!D29 -> 0.47024956 | E12: ='Revenue Build'!E29 -> 0.4852007 | F12: ='Revenue Build'!F29 -> 0.48934993 | G12: ='Revenue Build'!G29 -> 0.4952591 | H12: ='Revenue Build'!H29 -> 0.49760768 | I12: ='Revenue Build'!I29 -> 0.49996573 | J12: ='Revenue Build'!J29 -> 0.50233327 | K12: ='Revenue Build'!K29 -> 0.50471033
B14: Operating Expenses
B15: Salaries & Wages | C15: =C6*'Key Assumptions'!C25 -> 4195.18 | D15: =D6*'Key Assumptions'!D25 -> 7014.586 | E15: =E6*'Key Assumptions'!E25 -> 8909.97 | F15: =F6*'Key Assumptions'!F25 -> 8304.96 | G15: =G6*'Key Assumptions'!G25 -> 7808.8774 | H15: =H6*'Key Assumptions'!H25 -> 8082.565 | I15: =I6*'Key Assumptions'!I25 -> 8364.9279 | J15: =J6*'Key Assumptions'!J25 -> 8656.1565 | K15: =K6*'Key Assumptions'!K25 -> 8956.437
B16: Rent & Facilities | C16: =C6*'Key Assumptions'!C26 -> 762.76 | D16: =D6*'Key Assumptions'!D26 -> 1222.726 | E16: =E6*'Key Assumptions'!E26 -> 1484.995 | F16: =F6*'Key Assumptions'!F26 -> 1453.368 | G16: =G6*'Key Assumptions'!G26 -> 1380.1737 | H16: =H6*'Key Assumptions'!H26 -> 1448.7616 | I16: =I6*'Key Assumptions'!I26 -> 1520.896 | J16: =J6*'Key Assumptions'!J26 -> 1596.7667 | K16: =K6*'Key Assumptions'!K26 -> 1676.5744
B17: Insurance | C17: =C6*'Key Assumptions'!C27 -> 572.07 | D17: =D6*'Key Assumptions'!D27 -> 1029.664 | E17: =E6*'Key Assumptions'!E27 -> 1244.185 | F17: =F6*'Key Assumptions'!F27 -> 1211.14 | G17: =G6*'Key Assumptions'!G27 -> 1089.6108 | H17: =H6*'Key Assumptions'!H27 -> 1143.7592 | I17: =I6*'Key Assumptions'!I27 -> 1200.7074 | J17: =J6*'Key Assumptions'!J27 -> 1260.6053 | K17: =K6*'Key Assumptions'!K27 -> 1323.6114
B18: Vehicle & Equipment | C18: =C6*'Key Assumptions'!C28 -> 476.725 | D18: =D6*'Key Assumptions'!D28 -> 868.779 | E18: =E6*'Key Assumptions'!E28 -> 1123.78 | F18: =F6*'Key Assumptions'!F28 -> 1038.12 | G18: =G6*'Key Assumptions'!G28 -> 908.009 | H18: =H6*'Key Assumptions'!H28 -> 953.13266 | I18: =I6*'Key Assumptions'!I28 -> 1000.5895 | J18: =J6*'Key Assumptions'!J28 -> 1050.5044 | K18: =K6*'Key Assumptions'!K28 -> 1103.0095
B19: Other SG&A | C19: =C6*'Key Assumptions'!C29 -> 1144.14 | D19: =D6*'Key Assumptions'!D29 -> 1866.266 | E19: =E6*'Key Assumptions'!E29 -> 2087.02 | F19: =F6*'Key Assumptions'!F29 -> 2076.24 | G19: =G6*'Key Assumptions'!G29 -> 1162.2515 | H19: =H6*'Key Assumptions'!H29 -> 1181.8845 | I19: =I6*'Key Assumptions'!I29 -> 1200.7074 | J19: =J6*'Key Assumptions'!J29 -> 1218.5851 | K19: =K6*'Key Assumptions'!K29 -> 1235.3706
B21: Total SG&A | C21: =SUM(C15:C19) -> 7150.875 | D21: =SUM(D15:D19) -> 12002.021 | E21: =SUM(E15:E19) -> 14849.95 | F21: =SUM(F15:F19) -> 14083.828 | G21: =SUM(G15:G19) -> 12348.922 | H21: =SUM(H15:H19) -> 12810.103 | I21: =SUM(I15:I19) -> 13287.828 | J21: =SUM(J15:J19) -> 13782.618 | K21: =SUM(K15:K19) -> 14295.003
B22: SG&A % of Revenue | C22: =IF(C6=0,0,C21/C6) -> 0.375 | D22: =IF(D6=0,0,D21/D6) -> 0.373 | E22: =IF(E6=0,0,E21/E6) -> 0.37 | F22: =IF(F6=0,0,F21/F6) -> 0.407 | G22: =IF(G6=0,0,G21/G6) -> 0.34 | H22: =IF(H6=0,0,H21/H6) -> 0.336 | I22: =IF(I6=0,0,I21/I6) -> 0.332 | J22: =IF(J6=0,0,J21/J6) -> 0.328 | K22: =IF(K6=0,0,K21/K6) -> 0.324
B24: EBITDA | C24: =C11-C21 -> 1906.88 | D24: =D11-D21 -> 3129.199 | E24: =E11-E21 -> 4623.58 | F24: =F11-F21 -> 2849.637 | G24: =G11-G21 -> 5639.0664 | H24: =H11-H21 -> 6161.3424 | I24: =I11-I21 -> 6722.5895 | J24: =J11-J21 -> 7325.5149 | K24: =K11-K21 -> 7973.0082 | L24: =IF(G24=0,0,(K24/G24)^(1/4)-1) -> 0.090444963
B25: EBITDA Margin | C25: =IF(C6=0,0,C24/C6) -> 0.099998951 | D25: =IF(D6=0,0,D24/D6) -> 0.097249557 | E25: =IF(E6=0,0,E24/E6) -> 0.1152007 | F25: =IF(F6=0,0,F24/F6) -> 0.082349931 | G25: =IF(G6=0,0,G24/G6) -> 0.1552591 | H25: =IF(H6=0,0,H24/H6) -> 0.16160768 | I25: =IF(I6=0,0,I24/I6) -> 0.16796573 | J25: =IF(J6=0,0,J24/J6) -> 0.17433327 | K25: =IF(K6=0,0,K24/K6) -> 0.18071033
B26: EBITDA Growth | D26: =IF(C24=0,0,(D24-C24)/C24) -> 0.64100468 | E26: =IF(D24=0,0,(E24-D24)/D24) -> 0.47756023 | F26: =IF(E24=0,0,(F24-E24)/E24) -> -0.38367304 | G26: =IF(F24=0,0,(G24-F24)/F24) -> 0.97887184 | H26: =IF(G24=0,0,(H24-G24)/G24) -> 0.092617454 | I26: =IF(H24=0,0,(I24-H24)/H24) -> 0.0910917 | J26: =IF(I24=0,0,(J24-I24)/I24) -> 0.089686472 | K26: =IF(J24=0,0,(K24-J24)/J24) -> 0.088388786
B28: Depreciation & Amortization | C28: ='Key Assumptions'!C32 -> 800 | D28: ='Key Assumptions'!D32 -> 950 | E28: ='Key Assumptions'!E32 -> 1100 | F28: ='Key Assumptions'!F32 -> 1200 | G28: ='Key Assumptions'!G32 -> 1300 | H28: ='Key Assumptions'!H32 -> 1400 | I28: ='Key Assumptions'!I32 -> 1500 | J28: ='Key Assumptions'!J32 -> 1600 | K28: ='Key Assumptions'!K32 -> 1700
B30: EBIT | C30: =C24-C28 -> 1106.88 | D30: =D24-D28 -> 2179.199 | E30: =E24-E28 -> 3523.58 | F30: =F24-F28 -> 1649.637 | G30: =G24-G28 -> 4339.0664 | H30: =H24-H28 -> 4761.3424 | I30: =I24-I28 -> 5222.5895 | J30: =J24-J28 -> 5725.5149 | K30: =K24-K28 -> 6273.0082
B32: Total Cash Interest Expense | G32: ='Debt Schedule'!C41 -> 1436.8557 | H32: ='Debt Schedule'!D41 -> 1420.0099 | I32: ='Debt Schedule'!E41 -> 1407.2932 | J32: ='Debt Schedule'!F41 -> 1398.3416 | K32: ='Debt Schedule'!G41 -> 1392.8287
B33: Total PIK Interest / Dividends | G33: ='Debt Schedule'!C42 -> 433.246 | H33: ='Debt Schedule'!D42 -> 477.86112 | I33: ='Debt Schedule'!E42 -> 528.76107 | J33: ='Debt Schedule'!F42 -> 586.88043 | K33: ='Debt Schedule'!G42 -> 653.2938
B35: Pre-Tax Income | G35: =G30-G32-G33 -> 2468.9646 | H35: =H30-H32-H33 -> 2863.4714 | I35: =I30-I32-I33 -> 3286.5353 | J35: =J30-J32-J33 -> 3740.2928 | K35: =K30-K32-K33 -> 4226.8858
B36: Taxes | G36: =MAX(0,G35*'Key Assumptions'!$C$136) -> 0 | H36: =MAX(0,H35*'Key Assumptions'!$C$136) -> 0 | I36: =MAX(0,I35*'Key Assumptions'!$C$136) -> 0 | J36: =MAX(0,J35*'Key Assumptions'!$C$136) -> 0 | K36: =MAX(0,K35*'Key Assumptions'!$C$136) -> 0
B38: Net Income | G38: =G35-G36 -> 2468.9646 | H38: =H35-H36 -> 2863.4714 | I38: =I35-I36 -> 3286.5353 | J38: =J35-J36 -> 3740.2928 | K38: =K35-K36 -> 4226.8858

Sheet Balance Sheet
B1: Projected Balance Sheet
B2: ($ in thousands) | Driven by Working Capital Days
C4: @Close | D4: 2014P | E4: 2015P | F4: 2016P | G4: 2017P | H4: 2018P
B6: ASSETS
B7: Cash & Equivalents | C7: ='Key Assumptions'!C137 -> 500 | D7: ='Cash Flow'!C44 -> 2308.3712 | E7: ='Cash Flow'!D44 -> 4781.5692 | F7: ='Cash Flow'!E44 -> 7806.8251 | G7: ='Cash Flow'!F44 -> 11415.677 | H7: ='Cash Flow'!G44 -> 15643.634
B8: Accounts Receivable | C8: ='Income Statement'!F6*'Key Assumptions'!F38/365 -> 5432.354 | D8: ='Income Statement'!G6*'Key Assumptions'!G38/365 -> 5701.799 | E8: ='Income Statement'!H6*'Key Assumptions'!H38/365 -> 5870.2527 | F8: ='Income Statement'!I6*'Key Assumptions'!I38/365 -> 6041.9156 | G8: ='Income Statement'!J6*'Key Assumptions'!J38/365 -> 6216.6838 | H8: ='Income Statement'!K6*'Key Assumptions'!K38/365 -> 6394.433
B9: Inventory | C9: ='Income Statement'!F9*'Key Assumptions'!F39/365 -> 353.4107 | D9: ='Income Statement'!G9*'Key Assumptions'!G39/365 -> 366.64742 | E9: ='Income Statement'!H9*'Key Assumptions'!H39/365 -> 388.32485 | F9: ='Income Statement'!I9*'Key Assumptions'!I39/365 -> 411.22933 | G9: ='Income Statement'!J9*'Key Assumptions'!J39/365 -> 435.42887 | H9: ='Income Statement'!K9*'Key Assumptions'!K39/365 -> 460.99516
B10: Other Current Assets | C10: 200 | D10: ='Key Assumptions'!G42 -> 200 | E10: ='Key Assumptions'!H42 -> 200 | F10: ='Key Assumptions'!I42 -> 200 | G10: ='Key Assumptions'!J42 -> 200 | H10: ='Key Assumptions'!K42 -> 200
B12: Total Current Assets | C12: =SUM(C7:C10) -> 6485.7647 | D12: =SUM(D7:D10) -> 8576.8176 | E12: =SUM(E7:E10) -> 11240.147 | F12: =SUM(F7:F10) -> 14459.97 | G12: =SUM(G7:G10) -> 18267.789 | H12: =SUM(H7:H10) -> 22699.062
B14: Net PP&E | C14: 5000 | D14: =C14+'Key Assumptions'!G33+'Key Assumptions'!G34-'Key Assumptions'!G32 -> 5200 | E14: =D14+'Key Assumptions'!H33+'Key Assumptions'!H34-'Key Assumptions'!H32 -> 5400 | F14: =E14+'Key Assumptions'!I33+'Key Assumptions'!I34-'Key Assumptions'!I32 -> 5600 | G14: =F14+'Key Assumptions'!J33+'Key Assumptions'!J34-'Key Assumptions'!J32 -> 5800 | H14: =G14+'Key Assumptions'!K33+'Key Assumptions'!K34-'Key Assumptions'!K32 -> 6000
B15: Goodwill & Intangibles | C15: 0 | D15: =C15 -> 0 | E15: =D15 -> 0 | F15: =E15 -> 0 | G15: =F15 -> 0 | H15: =G15 -> 0
B17: TOTAL ASSETS | C17: =C12+C14+C15 -> 11485.765 | D17: =D12+D14+D15 -> 13776.818 | E17: =E12+E14+E15 -> 16640.147 | F17: =F12+F14+F15 -> 20059.97 | G17: =G12+G14+G15 -> 24067.789 | H17: =H12+H14+H15 -> 28699.062
B19: LIABILITIES
B20: Accounts Payable | C20: ='Income Statement'!F9*'Key Assumptions'!F40/365 -> 2769.1907 | D20: ='Income Statement'!G9*'Key Assumptions'!G40/365 -> 2872.9086 | E20: ='Income Statement'!H9*'Key Assumptions'!H40/365 -> 3027.8843 | F20: ='Income Statement'!I9*'Key Assumptions'!I40/365 -> 3191.1396 | G20: ='Income Statement'!J9*'Key Assumptions'!J40/365 -> 3363.1151 | H20: ='Income Statement'!K9*'Key Assumptions'!K40/365 -> 3544.2745
B21: Accrued Expenses | C21: ='Income Statement'!F6*'Key Assumptions'!F41 -> 1384.16 | D21: ='Income Statement'!G6*'Key Assumptions'!G41 -> 1452.8144 | E21: ='Income Statement'!H6*'Key Assumptions'!H41 -> 1525.0123 | F21: ='Income Statement'!I6*'Key Assumptions'!I41 -> 1600.9431 | G21: ='Income Statement'!J6*'Key Assumptions'!J41 -> 1680.8071 | H21: ='Income Statement'!K6*'Key Assumptions'!K41 -> 1764.8152
B22: Other Current Liabilities | C22: 150 | D22: ='Key Assumptions'!G43 -> 150 | E22: ='Key Assumptions'!H43 -> 150 | F22: ='Key Assumptions'!I43 -> 150 | G22: ='Key Assumptions'!J43 -> 150 | H22: ='Key Assumptions'!K43 -> 150
B23: Current Portion of LT Debt | C23: ='Key Assumptions'!C87*'Key Assumptions'!C120 -> 783.53 | D23: ='Debt Schedule'!C7*'Key Assumptions'!$C$120 -> 783.53 | E23: ='Debt Schedule'!D7*'Key Assumptions'!$C$120 -> 705.177 | F23: ='Debt Schedule'!E7*'Key Assumptions'!$C$120 -> 634.6593 | G23: ='Debt Schedule'!F7*'Key Assumptions'!$C$120 -> 571.19337 | H23: ='Debt Schedule'!G7*'Key Assumptions'!$C$120 -> 514.07403
B25: Total Current Liabilities | C25: =SUM(C20:C23) -> 5086.8807 | D25: =SUM(D20:D23) -> 5259.253 | E25: =SUM(E20:E23) -> 5408.0736 | F25: =SUM(F20:F23) -> 5576.7421 | G25: =SUM(G20:G23) -> 5765.1155 | H25: =SUM(H20:H23) -> 5973.1637
B27: Senior Term Loan (net of current) | C27: ='Key Assumptions'!C87 -> 7835.3 | D27: ='Debt Schedule'!C10 -> 7051.77 | E27: ='Debt Schedule'!D10 -> 6346.593 | F27: ='Debt Schedule'!E10 -> 5711.9337 | G27: ='Debt Schedule'!F10 -> 5140.7403 | H27: ='Debt Schedule'!G10 -> 4626.6663
B28: Seacoast Senior Sub. Notes (incl. PIK) | C28: ='Key Assumptions'!C88 -> 7835.3 | D28: ='Debt Schedule'!C16 -> 7992.006 | E28: ='Debt Schedule'!D16 -> 8151.8461 | F28: ='Debt Schedule'!E16 -> 8314.883 | G28: ='Debt Schedule'!F16 -> 8481.1807 | H28: ='Debt Schedule'!G16 -> 8650.8043
B29: Seller Note | C29: ='Key Assumptions'!C89 -> 921.8 | D29: ='Debt Schedule'!C20 -> 921.8 | E29: ='Debt Schedule'!D20 -> 921.8 | F29: ='Debt Schedule'!E20 -> 921.8 | G29: ='Debt Schedule'!F20 -> 921.8 | H29: ='Debt Schedule'!G20 -> 921.8
B30: Seller WC Holdback | C30: ='Key Assumptions'!C90 -> 921.8 | D30: ='Debt Schedule'!C22 -> 921.8 | E30: ='Debt Schedule'!D22 -> 921.8 | F30: ='Debt Schedule'!E22 -> 921.8 | G30: ='Debt Schedule'!F22 -> 921.8 | H30: ='Debt Schedule'!G22 -> 921.8
B31: Seacoast Part. Pref. (incl. PIK Div.) | C31: ='Key Assumptions'!C91 -> 1843.6 | D31: ='Debt Schedule'!C28 -> 2120.14 | E31: ='Debt Schedule'!D28 -> 2438.161 | F31: ='Debt Schedule'!E28 -> 2803.8852 | G31: ='Debt Schedule'!F28 -> 3224.4679 | H31: ='Debt Schedule'!G28 -> 3708.1381
B32: Other Pref. Stock (Investments + Tom) | C32: ='Key Assumptions'!C92+'Key Assumptions'!C93 -> 5069.9 | D32: =C32 -> 5069.9 | E32: =D32 -> 5069.9 | F32: =E32 -> 5069.9 | G32: =F32 -> 5069.9 | H32: =G32 -> 5069.9
B34: Total Liabilities | C34: =C25+SUM(C27:C32) -> 29514.581 | D34: =D25+SUM(D27:D32) -> 29336.669 | E34: =E25+SUM(E27:E32) -> 29258.174 | F34: =F25+SUM(F27:F32) -> 29320.944 | G34: =G25+SUM(G27:G32) -> 29525.004 | H34: =H25+SUM(H27:H32) -> 29872.272
B36: EQUITY
B37: Mgmt. Common Equity | C37: ='Key Assumptions'!C94 -> 1462.5 | D37: =C37 -> 1462.5 | E37: =D37 -> 1462.5 | F37: =E37 -> 1462.5 | G37: =F37 -> 1462.5 | H37: =G37 -> 1462.5
B38: Retained Earnings | C38: 0 | D38: =C38+'Income Statement'!G38 -> 2468.9646 | E38: =D38+'Income Statement'!H38 -> 5332.436 | F38: =E38+'Income Statement'!I38 -> 8618.9713 | G38: =F38+'Income Statement'!J38 -> 12359.264 | H38: =G38+'Income Statement'!K38 -> 16586.15
B40: Total Equity | C40: =C37+C38 -> 1462.5 | D40: =D37+D38 -> 3931.4646 | E40: =E37+E38 -> 6794.936 | F40: =F37+F38 -> 10081.471 | G40: =G37+G38 -> 13821.764 | H40: =H37+H38 -> 18048.65
B42: TOTAL LIABILITIES & EQUITY | C42: =C34+C40 -> 30977.081 | D42: =D34+D40 -> 33268.134 | E42: =E34+E40 -> 36053.11 | F42: =F34+F40 -> 39402.415 | G42: =G34+G40 -> 43346.769 | H42: =H34+H40 -> 47920.922
B44: Balance Check (Assets - L&E) | C44: =C17-C42 -> -19491.316 | D44: =D17-D42 -> -19491.316 | E44: =E17-E42 -> -19412.963 | F44: =F17-F42 -> -19342.445 | G44: =G17-G42 -> -19278.979 | H44: =H17-H42 -> -19221.86

Sheet Cash Flow
B1: Cash Flow Statement
B2: ($ in thousands)
C4: 2014P | D4: 2015P | E4: 2016P | F4: 2017P | G4: 2018P
B6: Changes in Working Capital
B7: Change in A/R (increase=use) | C7: ='Balance Sheet'!D8-'Balance Sheet'!C8 -> 269.44501 | D7: ='Balance Sheet'!E8-'Balance Sheet'!D8 -> 168.45368 | E7: ='Balance Sheet'!F8-'Balance Sheet'!E8 -> 171.6629 | F7: ='Balance Sheet'!G8-'Balance Sheet'!F8 -> 174.76819 | G7: ='Balance Sheet'!H8-'Balance Sheet'!G8 -> 177.74928
B8: Change in Inventory (increase=use) | C8: ='Balance Sheet'!D9-'Balance Sheet'!C9 -> 13.236724 | D8: ='Balance Sheet'!E9-'Balance Sheet'!D9 -> 21.677431 | E8: ='Balance Sheet'!F9-'Balance Sheet'!E9 -> 22.90448 | F8: ='Balance Sheet'!G9-'Balance Sheet'!F9 -> 24.199532 | G8: ='Balance Sheet'!H9-'Balance Sheet'!G9 -> 25.566296
B9: Change in A/P (increase=source) | C9: ='Balance Sheet'!D20-'Balance Sheet'!C20 -> 103.71789 | D9: ='Balance Sheet'!E20-'Balance Sheet'!D20 -> 154.97576 | E9: ='Balance Sheet'!F20-'Balance Sheet'!E20 -> 163.2553 | F9: ='Balance Sheet'!G20-'Balance Sheet'!F20 -> 171.97542 | G9: ='Balance Sheet'!H20-'Balance Sheet'!G20 -> 181.15944
B10: Change in Accrued Expenses | C10: ='Balance Sheet'!D21-'Balance Sheet'!C21 -> 68.6544 | D10: ='Balance Sheet'!E21-'Balance Sheet'!D21 -> 72.197856 | E10: ='Balance Sheet'!F21-'Balance Sheet'!E21 -> 75.930887 | F10: ='Balance Sheet'!G21-'Balance Sheet'!F21 -> 79.863946 | G10: ='Balance Sheet'!H21-'Balance Sheet'!G21 -> 84.008077
B11: Change in Other NWC | C11: =('Balance Sheet'!D10-'Balance Sheet'!C10)-('Balance Sheet'!D22-'Balance Sheet'!C22) -> 0 | D11: =('Balance Sheet'!E10-'Balance Sheet'!D10)-('Balance Sheet'!E22-'Balance Sheet'!D22) -> 0 | E11: =('Balance Sheet'!F10-'Balance Sheet'!E10)-('Balance Sheet'!F22-'Balance Sheet'!E22) -> 0 | F11: =('Balance Sheet'!G10-'Balance Sheet'!F10)-('Balance Sheet'!G22-'Balance Sheet'!F22) -> 0 | G11: =('Balance Sheet'!H10-'Balance Sheet'!G10)-('Balance Sheet'!H22-'Balance Sheet'!G22) -> 0
B13: Total Change in NWC (increase=use of cash) | C13: =C7+C8-C9-C10+C11 -> 110.30944 | D13: =D7+D8-D9-D10+D11 -> -37.042507 | E13: =E7+E8-E9-E10+E11 -> -44.618802 | F13: =F7+F8-F9-F10+F11 -> -52.871641 | G13: =G7+G8-G9-G10+G11 -> -61.851937
B15: Cash Flow from Operations
B16: EBITDA | C16: ='Income Statement'!G24 -> 5639.0664 | D16: ='Income Statement'!H24 -> 6161.3424 | E16: ='Income Statement'!I24 -> 6722.5895 | F16: ='Income Statement'!J24 -> 7325.5149 | G16: ='Income Statement'!K24 -> 7973.0082
B17: Less: Cash Interest Expense | C17: =-'Debt Schedule'!C41 -> -1436.8557 | D17: =-'Debt Schedule'!D41 -> -1420.0099 | E17: =-'Debt Schedule'!E41 -> -1407.2932 | F17: =-'Debt Schedule'!F41 -> -1398.3416 | G17: =-'Debt Schedule'!G41 -> -1392.8287
B18: Less: Taxes | C18: =-'Income Statement'!G36 -> 0 | D18: =-'Income Statement'!H36 -> 0 | E18: =-'Income Statement'!I36 -> 0 | F18: =-'Income Statement'!J36 -> 0 | G18: =-'Income Statement'!K36 -> 0
B19: Less: Change in NWC | C19: =-C13 -> -110.30944 | D19: =-D13 -> 37.042507 | E19: =-E13 -> 44.618802 | F19: =-F13 -> 52.871641 | G19: =-G13 -> 61.851937
B21: Cash Flow from Operations | C21: =C16+C17+C18+C19 -> 4091.9012 | D21: =D16+D17+D18+D19 -> 4778.375 | E21: =E16+E17+E18+E19 -> 5359.9152 | F21: =F16+F17+F18+F19 -> 5980.0449 | G21: =G16+G17+G18+G19 -> 6642.0315
B23: Cash Flow from Investing
B24: Maintenance CapEx | C24: =-'Key Assumptions'!G33 -> -800 | D24: =-'Key Assumptions'!H33 -> -850 | E24: =-'Key Assumptions'!I33 -> -900 | F24: =-'Key Assumptions'!J33 -> -950 | G24: =-'Key Assumptions'!K33 -> -1000
B25: Growth CapEx | C25: =-'Key Assumptions'!G34 -> -700 | D25: =-'Key Assumptions'!H34 -> -750 | E25: =-'Key Assumptions'!I34 -> -800 | F25: =-'Key Assumptions'!J34 -> -850 | G25: =-'Key Assumptions'!K34 -> -900
B27: Cash Flow from Investing | C27: =C24+C25 -> -1500 | D27: =D24+D25 -> -1600 | E27: =E24+E25 -> -1700 | F27: =F24+F25 -> -1800 | G27: =G24+G25 -> -1900
B29: Cash Flow from Financing
B30: Senior Loan Amortization | C30: ='Debt Schedule'!C8 -> -783.53 | D30: ='Debt Schedule'!D8 -> -705.177 | E30: ='Debt Schedule'!E8 -> -634.6593 | F30: ='Debt Schedule'!F8 -> -571.19337 | G30: ='Debt Schedule'!G8 -> -514.07403
B32: Cash Flow from Financing | C32: =C30 -> -783.53 | D32: =D30 -> -705.177 | E32: =E30 -> -634.6593 | F32: =F30 -> -571.19337 | G32: =G30 -> -514.07403
B34: Free Cash Flow Summary
B35: Unlevered Free Cash Flow (EBITDA - CapEx - dNWC) | C35: =C16-C13+C24+C25 -> 4028.757 | D35: =D16-D13+D24+D25 -> 4598.3849 | E35: =E16-E13+E24+E25 -> 5067.2083 | F35: =F16-F13+F24+F25 -> 5578.3865 | G35: =G16-G13+G24+G25 -> 6134.8602
B36: UFCF % of Revenue | C36: =IF('Income Statement'!G6=0,0,C35/'Income Statement'!G6) -> 0.11092283 | D36: =IF('Income Statement'!H6=0,0,D35/'Income Statement'!H6) -> 0.1206124 | E36: =IF('Income Statement'!I6=0,0,E35/'Income Statement'!I6) -> 0.12660558 | F36: =IF('Income Statement'!J6=0,0,F35/'Income Statement'!J6) -> 0.13275495 | G36: =IF('Income Statement'!K6=0,0,G35/'Income Statement'!K6) -> 0.13904822
B37: UFCF % of EBITDA (Cash Conversion) | C37: =IF(C16=0,0,C35/C16) -> 0.71443687 | D37: =IF(D16=0,0,D35/D16) -> 0.74632841 | E37: =IF(E16=0,0,E35/E16) -> 0.7537584 | F37: =IF(F16=0,0,F35/F16) -> 0.76150095 | G37: =IF(G16=0,0,G35/G16) -> 0.76945364
B39: Levered Free Cash Flow | C39: =C35+C17+C18+C30 -> 1808.3712 | D39: =D35+D17+D18+D30 -> 2473.198 | E39: =E35+E17+E18+E30 -> 3025.2559 | F39: =F35+F17+F18+F30 -> 3608.8515 | G39: =G35+G17+G18+G30 -> 4227.9575
B41: Net Change in Cash | C41: =C21+C27+C32 -> 1808.3712 | D41: =D21+D27+D32 -> 2473.198 | E41: =E21+E27+E32 -> 3025.2559 | F41: =F21+F27+F32 -> 3608.8515 | G41: =G21+G27+G32 -> 4227.9575
B42: Beginning Cash | C42: ='Key Assumptions'!C137 -> 500 | D42: =C44 -> 2308.3712 | E42: =D44 -> 4781.5692 | F42: =E44 -> 7806.8251 | G42: =F44 -> 11415.677
B44: Ending Cash | C44: =C42+C41 -> 2308.3712 | D44: =D42+D41 -> 4781.5692 | E44: =E42+E41 -> 7806.8251 | F44: =F42+F41 -> 11415.677 | G44: =G42+G41 -> 15643.634

Sheet Debt Schedule
B1: Debt & Preferred Equity Schedule
B2: ($ in thousands)
C4: 2014P | D4: 2015P | E4: 2016P | F4: 2017P | G4: 2018P
B6: Senior Term Loan
B7: Beginning Balance | C7: ='Key Assumptions'!C87 -> 7835.3 | D7: =C10 -> 7051.77 | E7: =D10 -> 6346.593 | F7: =E10 -> 5711.9337 | G7: =F10 -> 5140.7403
B8: Mandatory Amortization (Cash) | C8: =IF(C7>0,-C7*'Key Assumptions'!$C$120,0) -> -783.53 | D8: =IF(D7>0,-D7*'Key Assumptions'!$C$120,0) -> -705.177 | E8: =IF(E7>0,-E7*'Key Assumptions'!$C$120,0) -> -634.6593 | F8: =IF(F7>0,-F7*'Key Assumptions'!$C$120,0) -> -571.19337 | G8: =IF(G7>0,-G7*'Key Assumptions'!$C$120,0) -> -514.07403
B9: Prepayment from Excess Cash | C9: 0 | D9: 0 | E9: 0 | F9: 0 | G9: 0
B10: Ending Balance | C10: =C7+C8+C9 -> 7051.77 | D10: =D7+D8+D9 -> 6346.593 | E10: =E7+E8+E9 -> 5711.9337 | F10: =F7+F8+F9 -> 5140.7403 | G10: =G7+G8+G9 -> 4626.6663
B11: Cash Interest Expense | C11: =(C7+C10)/2*'Key Assumptions'!$C$112 -> 372.17675 | D11: =(D7+D10)/2*'Key Assumptions'!$C$112 -> 334.95907 | E11: =(E7+E10)/2*'Key Assumptions'!$C$112 -> 301.46317 | F11: =(F7+F10)/2*'Key Assumptions'!$C$112 -> 271.31685 | G11: =(G7+G10)/2*'Key Assumptions'!$C$112 -> 244.18517
B13: Seacoast Senior Subordinated Notes
B14: Beginning Balance | C14: ='Key Assumptions'!C88 -> 7835.3 | D14: =C16 -> 7992.006 | E14: =D16 -> 8151.8461 | F14: =E16 -> 8314.883 | G14: =F16 -> 8481.1807
B15: PIK Interest Accrual | C15: =C14*'Key Assumptions'!$C$114 -> 156.706 | D15: =D14*'Key Assumptions'!$C$114 -> 159.84012 | E15: =E14*'Key Assumptions'!$C$114 -> 163.03692 | F15: =F14*'Key Assumptions'!$C$114 -> 166.29766 | G15: =G14*'Key Assumptions'!$C$114 -> 169.62361
B16: Ending Balance | C16: =C14+C15 -> 7992.006 | D16: =D14+D15 -> 8151.8461 | E16: =E14+E15 -> 8314.883 | F16: =F14+F15 -> 8481.1807 | G16: =G14+G15 -> 8650.8043
B17: Cash Coupon Interest | C17: =C14*'Key Assumptions'!$C$113 -> 1018.589 | D17: =D14*'Key Assumptions'!$C$113 -> 1038.9608 | E17: =E14*'Key Assumptions'!$C$113 -> 1059.74 | F17: =F14*'Key Assumptions'!$C$113 -> 1080.9348 | G17: =G14*'Key Assumptions'!$C$113 -> 1102.5535
B19: Seller Note
B20: Balance (interest only) | C20: ='Key Assumptions'!C89 -> 921.8 | D20: =C20 -> 921.8 | E20: =D20 -> 921.8 | F20: =E20 -> 921.8 | G20: =F20 -> 921.8
B21: Cash Interest Expense | C21: =C20*'Key Assumptions'!$C$115 -> 46.09 | D21: =D20*'Key Assumptions'!$C$115 -> 46.09 | E21: =E20*'Key Assumptions'!$C$115 -> 46.09 | F21: =F20*'Key Assumptions'!$C$115 -> 46.09 | G21: =G20*'Key Assumptions'!$C$115 -> 46.09
B22: Seller WC Holdback (static) | C22: ='Key Assumptions'!C90 -> 921.8 | D22: =C22 -> 921.8 | E22: =D22 -> 921.8 | F22: =E22 -> 921.8 | G22: =F22 -> 921.8
B24: Seacoast Participating Preferred Stock
B25: Beginning Balance | C25: ='Key Assumptions'!C91 -> 1843.6 | D25: =C28 -> 2120.14 | E25: =D28 -> 2438.161 | F25: =E28 -> 2803.8852 | G25: =F28 -> 3224.4679
B26: Cash Dividend | C26: =C25*'Key Assumptions'!$C$116*'Key Assumptions'!$C$117 -> 0 | D26: =D25*'Key Assumptions'!$C$116*'Key Assumptions'!$C$117 -> 0 | E26: =E25*'Key Assumptions'!$C$116*'Key Assumptions'!$C$117 -> 0 | F26: =F25*'Key Assumptions'!$C$116*'Key Assumptions'!$C$117 -> 0 | G26: =G25*'Key Assumptions'!$C$116*'Key Assumptions'!$C$117 -> 0
B27: PIK Dividend Accrual | C27: =C25*'Key Assumptions'!$C$116*(1-'Key Assumptions'!$C$117) -> 276.54 | D27: =D25*'Key Assumptions'!$C$116*(1-'Key Assumptions'!$C$117) -> 318.021 | E27: =E25*'Key Assumptions'!$C$116*(1-'Key Assumptions'!$C$117) -> 365.72415 | F27: =F25*'Key Assumptions'!$C$116*(1-'Key Assumptions'!$C$117) -> 420.58277 | G27: =G25*'Key Assumptions'!$C$116*(1-'Key Assumptions'!$C$117) -> 483.67019
B28: Ending Balance | C28: =C25+C27 -> 2120.14 | D28: =D25+D27 -> 2438.161 | E28: =E25+E27 -> 2803.8852 | F28: =F25+F27 -> 3224.4679 | G28: =G25+G27 -> 3708.1381
B30: Revolving Credit Facility / Borrowing Base
B31: Eligible A/R | C31: ='Balance Sheet'!D8 -> 5701.799 | D31: ='Balance Sheet'!E8 -> 5870.2527 | E31: ='Balance Sheet'!F8 -> 6041.9156 | F31: ='Balance Sheet'!G8 -> 6216.6838 | G31: ='Balance Sheet'!H8 -> 6394.433
B32: Eligible Inventory | C32: ='Balance Sheet'!D9 -> 366.64742 | D32: ='Balance Sheet'!E9 -> 388.32485 | E32: ='Balance Sheet'!F9 -> 411.22933 | F32: ='Balance Sheet'!G9 -> 435.42887 | G32: ='Balance Sheet'!H9 -> 460.99516
B33: A/R Borrowing Base | C33: =C31*'Key Assumptions'!$C$122 -> 4561.4392 | D33: =D31*'Key Assumptions'!$C$122 -> 4696.2021 | E33: =E31*'Key Assumptions'!$C$122 -> 4833.5324 | F33: =F31*'Key Assumptions'!$C$122 -> 4973.347 | G33: =G31*'Key Assumptions'!$C$122 -> 5115.5464
B34: Inventory Borrowing Base | C34: =C32*'Key Assumptions'!$C$123 -> 183.32371 | D34: =D32*'Key Assumptions'!$C$123 -> 194.16243 | E34: =E32*'Key Assumptions'!$C$123 -> 205.61467 | F34: =F32*'Key Assumptions'!$C$123 -> 217.71443 | G34: =G32*'Key Assumptions'!$C$123 -> 230.49758
B35: Total Borrowing Base | C35: =C33+C34 -> 4744.7629 | D35: =D33+D34 -> 4890.3646 | E35: =E33+E34 -> 5039.1471 | F35: =F33+F34 -> 5191.0614 | G35: =G33+G34 -> 5346.044
B36: Revolver Commitment | C36: ='Key Assumptions'!$C$121 -> 5000 | D36: ='Key Assumptions'!$C$121 -> 5000 | E36: ='Key Assumptions'!$C$121 -> 5000 | F36: ='Key Assumptions'!$C$121 -> 5000 | G36: ='Key Assumptions'!$C$121 -> 5000
B37: Available Revolver Capacity | C37: =MIN(C35,C36) -> 4744.7629 | D37: =MIN(D35,D36) -> 4890.3646 | E37: =MIN(E35,E36) -> 5000 | F37: =MIN(F35,F36) -> 5000 | G37: =MIN(G35,G36) -> 5000
B38: Total Available Liquidity (Cash + Revolver) | C38: ='Cash Flow'!C44+C37 -> 7053.1341 | D38: ='Cash Flow'!D44+D37 -> 9671.9338 | E38: ='Cash Flow'!E44+E37 -> 12806.825 | F38: ='Cash Flow'!F44+F37 -> 16415.677 | G38: ='Cash Flow'!G44+G37 -> 20643.634
B40: Summary for Income Statement Links
B41: Total Cash Interest | C41: =C11+C17+C21+C26 -> 1436.8557 | D41: =D11+D17+D21+D26 -> 1420.0099 | E41: =E11+E17+E21+E26 -> 1407.2932 | F41: =F11+F17+F21+F26 -> 1398.3416 | G41: =G11+G17+G21+G26 -> 1392.8287
B42: Total PIK Interest / Dividends | C42: =C15+C27 -> 433.246 | D42: =D15+D27 -> 477.86112 | E42: =E15+E27 -> 528.76107 | F42: =F15+F27 -> 586.88043 | G42: =G15+G27 -> 653.2938
B44: Total Debt Service (Principal + Cash Interest)
B45: Total Debt Service | C45: =C41-C8 -> 2220.3857 | D45: =D41-D8 -> 2125.1869 | E45: =E41-E8 -> 2041.9525 | F45: =F41-F8 -> 1969.535 | G45: =G41-G8 -> 1906.9027

Sheet Coverage Ratios
B1: Debt Coverage & Efficiency Ratios
B2: ($ in thousands)
C4: @Close | D4: 2014P | E4: 2015P | F4: 2016P | G4: 2017P | H4: 2018P
B6: Debt Coverage Ratios
B7: EBITDA / (Total Debt Service + CapEx) | D7: =IF('Debt Schedule'!C45+'Key Assumptions'!G33+'Key Assumptions'!G34=0,0,'Income Statement'!G24/('Debt Schedule'!C45+'Key Assumptions'!G33+'Key Assumptions'!G34)) -> 1.5157209 | E7: =IF('Debt Schedule'!D45+'Key Assumptions'!H33+'Key Assumptions'!H34=0,0,'Income Statement'!H24/('Debt Schedule'!D45+'Key Assumptions'!H33+'Key Assumptions'!H34)) -> 1.6539687 | F7: =IF('Debt Schedule'!E45+'Key Assumptions'!I33+'Key Assumptions'!I34=0,0,'Income Statement'!I24/('Debt Schedule'!E45+'Key Assumptions'!I33+'Key Assumptions'!I34)) -> 1.7965459 | G7: =IF('Debt Schedule'!F45+'Key Assumptions'!J33+'Key Assumptions'!J34=0,0,'Income Statement'!J24/('Debt Schedule'!F45+'Key Assumptions'!J33+'Key Assumptions'!J34)) -> 1.9433471 | H7: =IF('Debt Schedule'!G45+'Key Assumptions'!K33+'Key Assumptions'!K34=0,0,'Income Statement'!K24/('Debt Schedule'!G45+'Key Assumptions'!K33+'Key Assumptions'!K34)) -> 2.0943557
B8: EBITDA / (Sr. Debt Service + CapEx) | D8: =IF('Debt Schedule'!C11-'Debt Schedule'!C8+'Key Assumptions'!G33+'Key Assumptions'!G34=0,0,'Income Statement'!G24/('Debt Schedule'!C11-'Debt Schedule'!C8+'Key Assumptions'!G33+'Key Assumptions'!G34)) -> 2.1233769 | E8: =IF('Debt Schedule'!D11-'Debt Schedule'!D8+'Key Assumptions'!H33+'Key Assumptions'!H34=0,0,'Income Statement'!H24/('Debt Schedule'!D11-'Debt Schedule'!D8+'Key Assumptions'!H33+'Key Assumptions'!H34)) -> 2.3337215 | F8: =IF('Debt Schedule'!E11-'Debt Schedule'!E8+'Key Assumptions'!I33+'Key Assumptions'!I34=0,0,'Income Statement'!I24/('Debt Schedule'!E11-'Debt Schedule'!E8+'Key Assumptions'!I33+'Key Assumptions'!I34)) -> 2.550181 | G8: =IF('Debt Schedule'!F11-'Debt Schedule'!F8+'Key Assumptions'!J33+'Key Assumptions'!J34=0,0,'Income Statement'!J24/('Debt Schedule'!F11-'Debt Schedule'!F8+'Key Assumptions'!J33+'Key Assumptions'!J34)) -> 2.7721803 | H8: =IF('Debt Schedule'!G11-'Debt Schedule'!G8+'Key Assumptions'!K33+'Key Assumptions'!K34=0,0,'Income Statement'!K24/('Debt Schedule'!G11-'Debt Schedule'!G8+'Key Assumptions'!K33+'Key Assumptions'!K34)) -> 2.9993344
B10: Leverage Ratios
B11: Senior Debt / EBITDA | C11: =IF('Income Statement'!F24=0,0,'Key Assumptions'!C87/'Income Statement'!F24) -> 2.7495783 | D11: =IF('Income Statement'!G24=0,0,'Debt Schedule'!C10/'Income Statement'!G24) -> 1.2505208 | E11: =IF('Income Statement'!H24=0,0,'Debt Schedule'!D10/'Income Statement'!H24) -> 1.0300666 | F11: =IF('Income Statement'!I24=0,0,'Debt Schedule'!E10/'Income Statement'!I24) -> 0.84966272 | G11: =IF('Income Statement'!J24=0,0,'Debt Schedule'!F10/'Income Statement'!J24) -> 0.70175823 | H11: =IF('Income Statement'!K24=0,0,'Debt Schedule'!G10/'Income Statement'!K24) -> 0.58029117
B12: Sr. + Sub. Debt (excl. Seller & Holdback) / EBITDA | C12: =IF('Income Statement'!F24=0,0,('Key Assumptions'!C87+'Key Assumptions'!C88)/'Income Statement'!F24) -> 5.4991566 | D12: =IF('Income Statement'!G24=0,0,('Debt Schedule'!C10+'Debt Schedule'!C16)/'Income Statement'!G24) -> 2.6677778 | E12: =IF('Income Statement'!H24=0,0,('Debt Schedule'!D10+'Debt Schedule'!D16)/'Income Statement'!H24) -> 2.3531299 | F12: =IF('Income Statement'!I24=0,0,('Debt Schedule'!E10+'Debt Schedule'!E16)/'Income Statement'!I24) -> 2.0865199 | G12: =IF('Income Statement'!J24=0,0,('Debt Schedule'!F10+'Debt Schedule'!F16)/'Income Statement'!J24) -> 1.8595172 | H12: =IF('Income Statement'!K24=0,0,('Debt Schedule'!G10+'Debt Schedule'!G16)/'Income Statement'!K24) -> 1.6653025
B13: Total Net Debt / EBITDA | C13: =IF('Income Statement'!F24=0,0,('Key Assumptions'!C87+'Key Assumptions'!C88+'Key Assumptions'!C89+'Key Assumptions'!C90)/'Income Statement'!F24) -> 6.1461162 | D13: =IF('Income Statement'!G24=0,0,('Debt Schedule'!C10+'Debt Schedule'!C16+'Debt Schedule'!C20+'Debt Schedule'!C22)/'Income Statement'!G24) -> 2.9947113 | E13: =IF('Income Statement'!H24=0,0,('Debt Schedule'!D10+'Debt Schedule'!D16+'Debt Schedule'!D20+'Debt Schedule'!D22)/'Income Statement'!H24) -> 2.6523504 | F13: =IF('Income Statement'!I24=0,0,('Debt Schedule'!E10+'Debt Schedule'!E16+'Debt Schedule'!E20+'Debt Schedule'!E22)/'Income Statement'!I24) -> 2.3607595 | G13: =IF('Income Statement'!J24=0,0,('Debt Schedule'!F10+'Debt Schedule'!F16+'Debt Schedule'!F20+'Debt Schedule'!F22)/'Income Statement'!J24) -> 2.1111855 | H13: =IF('Income Statement'!K24=0,0,('Debt Schedule'!G10+'Debt Schedule'!G16+'Debt Schedule'!G20+'Debt Schedule'!G22)/'Income Statement'!K24) -> 1.8965327

Sheet Returns Analysis
B1: Returns Analysis
B2: ($ in thousands) | 5-Year Hold Period
B4: Exit Enterprise Value | C4: Low | D4: Base | E4: High
B5: Exit Year EBITDA (Year 5) | C5: ='Income Statement'!K24 -> 7973.0082 | D5: ='Income Statement'!K24 -> 7973.0082 | E5: ='Income Statement'!K24 -> 7973.0082
B6: Exit Multiple | C6: ='Key Assumptions'!C131 -> 4 | D6: ='Key Assumptions'!C132 -> 5 | E6: ='Key Assumptions'!C133 -> 6
B7: Exit Enterprise Value | C7: =C5*C6 -> 31892.033 | D7: =D5*D6 -> 39865.041 | E7: =E5*E6 -> 47838.049
B9: Less: Senior Debt Outstanding | C9: ='Debt Schedule'!G10 -> 4626.6663 | D9: ='Debt Schedule'!G10 -> 4626.6663 | E9: ='Debt Schedule'!G10 -> 4626.6663
B10: Less: Seller Note | C10: ='Debt Schedule'!G20 -> 921.8 | D10: ='Debt Schedule'!G20 -> 921.8 | E10: ='Debt Schedule'!G20 -> 921.8
B11: Less: Seller WC Holdback | C11: ='Debt Schedule'!G22 -> 921.8 | D11: ='Debt Schedule'!G22 -> 921.8 | E11: ='Debt Schedule'!G22 -> 921.8
B12: Equity Value for Distribution | C12: =C7-C9-C10-C11 -> 25421.767 | D12: =D7-D9-D10-D11 -> 33394.775 | E12: =E7-E9-E10-E11 -> 41367.783
B14: Subordinated Debt Returns
B15: Sub Debt Principal + Accrued PIK at Exit | C15: ='Debt Schedule'!G16 -> 8650.8043 | D15: ='Debt Schedule'!G16 -> 8650.8043 | E15: ='Debt Schedule'!G16 -> 8650.8043
B16: Warrant Value (Ownership % x Equity Value) | C16: ='Key Assumptions'!$C$127*C12 -> 1271.0883 | D16: ='Key Assumptions'!$C$127*D12 -> 1669.7387 | E16: ='Key Assumptions'!$C$127*E12 -> 2068.3892
B17: Total Exit Proceeds | C17: =C15+C16 -> 9921.8926 | D17: =D15+D16 -> 10320.543 | E17: =E15+E16 -> 10719.193
B19: Sub Debt Cash Flow Stream | C19: Year 0 | D19: Year 1 | E19: Year 2 | F19: Year 3 | G19: Year 4 | H19: Year 5
B20: Low | C20: =-'Key Assumptions'!C88 -> -7835.3 | D20: ='Debt Schedule'!C17 -> 1018.589 | E20: ='Debt Schedule'!D17 -> 1038.9608 | F20: ='Debt Schedule'!E17 -> 1059.74 | G20: ='Debt Schedule'!F17 -> 1080.9348 | H20: ='Debt Schedule'!G17+C17 -> 11024.446
B21: Base | C21: =-'Key Assumptions'!C88 -> -7835.3 | D21: ='Debt Schedule'!C17 -> 1018.589 | E21: ='Debt Schedule'!D17 -> 1038.9608 | F21: ='Debt Schedule'!E17 -> 1059.74 | G21: ='Debt Schedule'!F17 -> 1080.9348 | H21: ='Debt Schedule'!G17+D17 -> 11423.097
B22: High | C22: =-'Key Assumptions'!C88 -> -7835.3 | D22: ='Debt Schedule'!C17 -> 1018.589 | E22: ='Debt Schedule'!D17 -> 1038.9608 | F22: ='Debt Schedule'!E17 -> 1059.74 | G22: ='Debt Schedule'!F17 -> 1080.9348 | H22: ='Debt Schedule'!G17+E17 -> 11821.747
B24: Sub Debt IRR | C24: =IRR(C20:H20) -> 0.17226024 | D24: =IRR(C21:H21) -> 0.17886905 | E24: =IRR(C22:H22) -> 0.18531717
B25: Sub Debt MOIC | C25: =IF(C20=0,0,(SUM(D20:H20))/(-C20)) -> 1.9428319 | D25: =IF(C21=0,0,(SUM(D21:H21))/(-C21)) -> 1.9937107 | E25: =IF(C22=0,0,(SUM(D22:H22))/(-C22)) -> 2.0445894
B27: Participating Preferred Returns
B28: Pref. Principal + Accrued PIK Div. at Exit | C28: ='Debt Schedule'!G28 -> 3708.1381 | D28: ='Debt Schedule'!G28 -> 3708.1381 | E28: ='Debt Schedule'!G28 -> 3708.1381
B29: Equity Participation (% x Equity Value) | C29: ='Key Assumptions'!$C$128*C12 -> 3813.265 | D29: ='Key Assumptions'!$C$128*D12 -> 5009.2162 | E29: ='Key Assumptions'!$C$128*E12 -> 6205.1675
B30: Total Exit Proceeds | C30: =C28+C29 -> 7521.4031 | D30: =D28+D29 -> 8717.3543 | E30: =E28+E29 -> 9913.3056
B32: Pref. Cash Flow Stream | C32: Year 0 | D32: Year 1 | E32: Year 2 | F32: Year 3 | G32: Year 4 | H32: Year 5
B33: Low | C33: =-'Key Assumptions'!C91 -> -1843.6 | D33: ='Debt Schedule'!C26 -> 0 | E33: ='Debt Schedule'!D26 -> 0 | F33: ='Debt Schedule'!E26 -> 0 | G33: ='Debt Schedule'!F26 -> 0 | H33: ='Debt Schedule'!G26+C30 -> 7521.4031
B34: Base | C34: =-'Key Assumptions'!C91 -> -1843.6 | D34: ='Debt Schedule'!C26 -> 0 | E34: ='Debt Schedule'!D26 -> 0 | F34: ='Debt Schedule'!E26 -> 0 | G34: ='Debt Schedule'!F26 -> 0 | H34: ='Debt Schedule'!G26+D30 -> 8717.3543
B35: High | C35: =-'Key Assumptions'!C91 -> -1843.6 | D35: ='Debt Schedule'!C26 -> 0 | E35: ='Debt Schedule'!D26 -> 0 | F35: ='Debt Schedule'!E26 -> 0 | G35: ='Debt Schedule'!F26 -> 0 | H35: ='Debt Schedule'!G26+E30 -> 9913.3056
B37: Pref. IRR | C37: =IRR(C33:H33) -> 0.32472714 | D37: =IRR(C34:H34) -> 0.36440594 | E37: =IRR(C35:H35) -> 0.39994302
B38: Pref. MOIC | C38: =IF(C33=0,0,(SUM(D33:H33))/(-C33)) -> 4.079737 | D38: =IF(C34=0,0,(SUM(D34:H34))/(-C34)) -> 4.7284413 | E38: =IF(C35=0,0,(SUM(D35:H35))/(-C35)) -> 5.3771456
B40: Blended Seacoast Returns (Sub Debt + Part. Pref.)
B41: Blended Cash Flow Stream | C41: Year 0 | D41: Year 1 | E41: Year 2 | F41: Year 3 | G41: Year 4 | H41: Year 5
B42: Low | C42: =C20+C33 -> -9678.9 | D42: =D20+D33 -> 1018.589 | E42: =E20+E33 -> 1038.9608 | F42: =F20+F33 -> 1059.74 | G42: =G20+G33 -> 1080.9348 | H42: =H20+H33 -> 18545.849
B43: Base | C43: =C21+C34 -> -9678.9 | D43: =D21+D34 -> 1018.589 | E43: =E21+E34 -> 1038.9608 | F43: =F21+F34 -> 1059.74 | G43: =G21+G34 -> 1080.9348 | H43: =H21+H34 -> 20140.451
B44: High | C44: =C22+C35 -> -9678.9 | D44: =D22+D35 -> 1018.589 | E44: =E22+E35 -> 1038.9608 | F44: =F22+F35 -> 1059.74 | G44: =G22+G35 -> 1080.9348 | H44: =H22+H35 -> 21735.053
B46: Blended IRR | C46: =IRR(C42:H42) -> 0.21365388 | D46: =IRR(C43:H43) -> 0.23093746 | E46: =IRR(C44:H44) -> 0.24723488
B47: Blended MOIC | C47: =IF(C42=0,0,(SUM(D42:H42))/(-C42)) -> 2.3498614 | D47: =IF(C43=0,0,(SUM(D43:H43))/(-C43)) -> 2.5146117 | E47: =IF(C44=0,0,(SUM(D44:H44))/(-C44)) -> 2.679362
