Workbook

Sheet README-Assumptions
A1: SK hynix (000660.KS) - Value-Driven Bottom-Up Forecast: Sales to FCF less SBC
A2: DRAM (HBM + conventional) and NAND separated; contracted base + spot layered; wafer-to-bit cross-check. Units: bits in petabytes (PB=1e6 GB); ASP in $/GB; $ in millions.
A4: COLOR LEGEND | B4: blue = hardcoded input / lever black = formula green = cross-sheet link yellow fill = key assumption to tune
A5: DISCLOSED (your file + IR) | B5: FY2025 rev $64,898M, GM 60.4%, OpInc $31,283M, NI $28,672M, capex $18,994M, FCF $20,357M. Q4-25 DRAM W24.9T / NAND W7.6T. Q1-26 rev ~$34.5B, GM 79%. 2026 output committed; DRAM bits +>20%, NAND +high-teens.
A6: NOT DISCLOSED (estimated here) | B6: SK hynix does NOT publish bit shipments, ASP, DRAM/NAND split, or wafer capacity. Every driver is an analyst estimate calibrated to the FY2025 filed total and IR/TrendForce/BofA commentary. Tune the blue grids freely.
A7: CYCLE VIEW (core call) | B7: 2026-27 super-cycle peak (AI + shortage), 2028-29 glut as M15X/Yongin/Micron-ID1/China capacity lands, 2030-31 recovery. Extrapolating 2026 forever is the biggest error to avoid.
A8: SBC NOTE | B8: SK hynix SBC is immaterial (Korean cash comp). FCF less SBC sits within ~$80M of FCF; unlike Micron/Nvidia the SBC line does not move the answer.
A9: FX NOTE | B9: File converted at ~1,497 KRW/USD. Reported USD moves with FX independent of operations.
A11: SCENARIO LEVER
B12: ASP scenario multiplier on 2028-29 commodity trough (1.00 base; 1.15 shallow glut; 0.80 deep glut) | C12: 1

Sheet Income-to-FCF
A1: Income Statement to Free Cash Flow (less SBC)
A2: Revenue linked from Segment-Revenue. Gross margin is the cyclical lever (anchored to disclosed FY23 -1.6% / FY24 48% / FY25 60% range). FY2025 column reconciles to your file.
B4: ($M unless noted) | C4: FY2025A | D4: FY2026E | E4: FY2027E | F4: FY2028E | G4: FY2029E | H4: FY2030E | I4: FY2031E
A5: INCOME STATEMENT
B6: Revenue | C6: 64898 | D6: ='Segment-Revenue'!D28 -> 136139.97 | E6: ='Segment-Revenue'!E28 -> 155443.24 | F6: ='Segment-Revenue'!F28 -> 119938.01 | G6: ='Segment-Revenue'!G28 -> 125493.18 | H6: ='Segment-Revenue'!H28 -> 163487.32 | I6: ='Segment-Revenue'!I28 -> 199824.79
B7: DRAM revenue | C7: 49326 | D7: ='Segment-Revenue'!D16 -> 102157.45 | E7: ='Segment-Revenue'!E16 -> 119306.33 | F7: ='Segment-Revenue'!F16 -> 97349.563 | G7: ='Segment-Revenue'!G16 -> 102777.87 | H7: ='Segment-Revenue'!H16 -> 131791.14 | I7: ='Segment-Revenue'!I16 -> 159969.26
B8: NAND revenue | C8: 14927 | D8: ='Segment-Revenue'!D25 -> 33982.523 | E8: ='Segment-Revenue'!E25 -> 36136.907 | F8: ='Segment-Revenue'!F25 -> 22588.448 | G8: ='Segment-Revenue'!G25 -> 22715.316 | H8: ='Segment-Revenue'!H25 -> 31696.179 | I8: ='Segment-Revenue'!I25 -> 39855.529
B9: Gross margin (lever) | C9: 0.604 | D9: 0.72 | E9: 0.66 | F9: 0.5 | G9: 0.48 | H9: 0.57 | I9: 0.6
B10: Gross profit | C10: =C6*C9 -> 39198.392 | D10: =D6*D9 -> 98020.779 | E10: =E6*E9 -> 102592.54 | F10: =F6*F9 -> 59969.005 | G10: =G6*G9 -> 60236.727 | H10: =H6*H9 -> 93187.772 | I10: =I6*I9 -> 119894.87
B11: Cost of revenue | C11: =C6-C10 -> 25699.608 | D11: =D6-D10 -> 38119.192 | E11: =E6-E10 -> 52850.701 | F11: =F6-F10 -> 59969.005 | G11: =G6-G10 -> 65256.455 | H11: =H6-H10 -> 70299.547 | I11: =I6-I10 -> 79929.916
B12: R&D (fixed) | C12: 4319 | D12: 5000 | E12: 6000 | F12: 6800 | G12: 7400 | H12: 8200 | I12: 9000
B13: SG&A % of revenue | C13: 0.0517 | D13: 0.045 | E13: 0.045 | F13: 0.045 | G13: 0.045 | H13: 0.045 | I13: 0.045
B14: SG&A | C14: =C6*C13 -> 3355.2266 | D14: =D6*D13 -> 6126.2987 | E14: =E6*E13 -> 6994.9457 | F14: =F6*F13 -> 5397.2105 | G14: =G6*G13 -> 5647.1932 | H14: =H6*H13 -> 7356.9294 | I14: =I6*I13 -> 8992.1155
B15: Operating income (EBIT) | C15: =C10-C12-C14 -> 31524.165 | D15: =D10-D12-D14 -> 86894.48 | E15: =E10-E12-E14 -> 89597.591 | F15: =F10-F12-F14 -> 47771.795 | G15: =G10-G12-G14 -> 47189.534 | H15: =H10-H12-H14 -> 77630.843 | I15: =I10-I12-I14 -> 101902.76
B16: Operating margin | C16: =C15/C6 -> 0.48574941 | D16: =D15/D6 -> 0.63827309 | E16: =E15/E6 -> 0.5764007 | F16: =F15/F6 -> 0.39830405 | G16: =G15/G6 -> 0.37603265 | H16: =H15/H6 -> 0.4748432 | I16: =I15/I6 -> 0.50996054
B17: Net financial income (net-cash) | C17: 2411 | D17: 1500 | E17: 2500 | F17: 2000 | G17: 1500 | H17: 2500 | I17: 3000
B18: Pretax income | C18: =C15+C17 -> 33935.165 | D18: =D15+D17 -> 88394.48 | E18: =E15+E17 -> 92097.591 | F18: =F15+F17 -> 49771.795 | G18: =G15+G17 -> 48689.534 | H18: =H15+H17 -> 80130.843 | I18: =I15+I17 -> 104902.76
B19: Cash tax rate | C19: 0.149 | D19: 0.2 | E19: 0.2 | F19: 0.19 | G19: 0.18 | H19: 0.2 | I19: 0.21
B20: Tax | C20: =MAX(C18*C19,0) -> 5056.3396 | D20: =MAX(D18*D19,0) -> 17678.896 | E20: =MAX(E18*E19,0) -> 18419.518 | F20: =MAX(F18*F19,0) -> 9456.6411 | G20: =MAX(G18*G19,0) -> 8764.1162 | H20: =MAX(H18*H19,0) -> 16026.169 | I20: =MAX(I18*I19,0) -> 22029.579
B21: Net income | C21: =C18-C20 -> 28878.826 | D21: =D18-D20 -> 70715.584 | E21: =E18-E20 -> 73678.073 | F21: =F18-F20 -> 40315.154 | G21: =G18-G20 -> 39925.418 | H21: =H18-H20 -> 64104.674 | I21: =I18-I20 -> 82873.179
B22: Net margin | C22: =C21/C6 -> 0.44498792 | D22: =D21/D6 -> 0.51943293 | E22: =E21/E6 -> 0.47398699 | F22: =F21/F6 -> 0.33613325 | G22: =G21/G6 -> 0.3181481 | H22: =H21/H6 -> 0.39210793 | I22: =I21/I6 -> 0.41472922
B23: Diluted shares (M) | C23: 711.08 | D23: 711.08 | E23: 711.08 | F23: 711.08 | G23: 711.08 | H23: 711.08 | I23: 711.08
B24: EPS ($, actual share basis) | C24: =C21/C23 -> 40.612626 | D24: =D21/D23 -> 99.448141 | E24: =E21/E23 -> 103.61432 | F24: =F21/F23 -> 56.695666 | G24: =G21/G23 -> 56.147576 | H24: =H21/H23 -> 90.151142 | I24: =I21/I23 -> 116.54551
A25: CASH FLOW TO FCF
B26: Net income | C26: =C21 -> 28878.826 | D26: =D21 -> 70715.584 | E26: =E21 -> 73678.073 | F26: =F21 -> 40315.154 | G26: =G21 -> 39925.418 | H26: =H21 -> 64104.674 | I26: =I21 -> 82873.179
B27: + D&A | C27: 11500 | D27: 14000 | E27: 17000 | F27: 19500 | G27: 21000 | H27: 22500 | I27: 24000
B28: + SBC (immaterial) | C28: 0 | D28: 80 | E28: 80 | F28: 80 | G28: 80 | H28: 80 | I28: 80
B29: DSO / DIO / DPO (days) | C29: 68 | D29: 68 | E29: 68 | F29: 68 | G29: 68 | H29: 68 | I29: 68
B30: Accounts receivable | C30: =C6*68/365 -> 12090.586 | D30: =D6*68/365 -> 25363.063 | E30: =E6*68/365 -> 28959.288 | F30: =F6*68/365 -> 22344.616 | G30: =G6*68/365 -> 23379.552 | H30: =H6*68/365 -> 30457.912 | I30: =I6*68/365 -> 37227.632
B31: Inventory | C31: =(C6-C10)*135/365 -> 9505.3345 | D31: =(D6-D10)*135/365 -> 14098.879 | E31: =(E6-E10)*135/365 -> 19547.519 | F31: =(F6-F10)*135/365 -> 22180.317 | G31: =(G6-G10)*135/365 -> 24135.949 | H31: =(H6-H10)*135/365 -> 26001.202 | I31: =(I6-I10)*135/365 -> 29563.119
B32: Accounts payable | C32: =(C6-C10)*150/365 -> 10561.483 | D32: =(D6-D10)*150/365 -> 15665.421 | E32: =(E6-E10)*150/365 -> 21719.466 | F32: =(F6-F10)*150/365 -> 24644.797 | G32: =(G6-G10)*150/365 -> 26817.721 | H32: =(H6-H10)*150/365 -> 28890.225 | I32: =(I6-I10)*150/365 -> 32847.911
B33: Net working capital | C33: =C30+C31-C32 -> 11034.438 | D33: =D30+D31-D32 -> 23796.521 | E33: =E30+E31-E32 -> 26787.342 | F33: =F30+F31-F32 -> 19880.136 | G33: =G30+G31-G32 -> 20697.78 | H33: =H30+H31-H32 -> 27568.889 | I33: =I30+I31-I32 -> 33942.841
B34: - Change in NWC | D34: =D33-C33 -> 12762.083 | E34: =E33-D33 -> 2990.8205 | F34: =F33-E33 -> -6907.2054 | G34: =G33-F33 -> 817.64355 | H34: =H33-G33 -> 6871.1095 | I34: =I33-H33 -> 6373.9518
B35: Operating cash flow | C35: =C26+C27+C28 -> 40378.826 | D35: =D26+D27+D28-D34 -> 72033.501 | E35: =E26+E27+E28-E34 -> 87767.252 | F35: =F26+F27+F28-F34 -> 66802.359 | G35: =G26+G27+G28-G34 -> 60187.774 | H35: =H26+H27+H28-H34 -> 79813.565 | I35: =I26+I27+I28-I34 -> 100579.23
B36: - Capex | C36: 18994 | D36: 27000 | E36: 30000 | F36: 24000 | G36: 22000 | H36: 26000 | I36: 29000
B37: Free cash flow | C37: =C35-C36 -> 21384.826 | D37: =D35-D36 -> 45033.501 | E37: =E35-E36 -> 57767.252 | F37: =F35-F36 -> 42802.359 | G37: =G35-G36 -> 38187.774 | H37: =H35-H36 -> 53813.565 | I37: =I35-I36 -> 71579.227
B38: Free cash flow less SBC | C38: =C37-C28 -> 21384.826 | D38: =D37-D28 -> 44953.501 | E38: =E37-E28 -> 57687.252 | F38: =F37-F28 -> 42722.359 | G38: =G37-G28 -> 38107.774 | H38: =H37-H28 -> 53733.565 | I38: =I37-I28 -> 71499.227
B39: FCF margin | C39: =C37/C6 -> 0.3295144 | D39: =D37/D6 -> 0.33078824 | E39: =E37/E6 -> 0.37162924 | F39: =F37/F6 -> 0.35687068 | G39: =G37/G6 -> 0.30430159 | H39: =H37/H6 -> 0.32916048 | I39: =I37/I6 -> 0.35820995
D41: 0.48 | E41: =D41+1 -> 1.48 | F41: =E41+1 -> 2.48 | G41: =F41+1 -> 3.48 | H41: =G41+1 -> 4.48 | I41: =H41+1 -> 5.48
B42: Disc FCF | D42: =D38/(1+$C$44)^D41 -> 42943.262 | E42: =E38/(1+$C$44)^E41 -> 50097.803 | F42: =F38/(1+$C$44)^F41 -> 33728.837 | G42: =G38/(1+$C$44)^G41 -> 27350.612 | H42: =H38/(1+$C$44)^H41 -> 35059.557 | I42: =I38/(1+$C$44)^I41 -> 42410.113
...

Sheet Segment-Revenue
A1: Segment Revenue Build - DRAM (HBM + Conventional) and NAND, Contracted Base + Spot
A2: Revenue = bits (PB) x ASP ($/GB). Contracted layer = committed/LTA volume; spot layer = uncommitted (spot ASP = contract ASP x spot multiplier). Scenario lever rescales 2028-29 commodity ASP. Blue = tunable driver.
B4: ($M; bits in PB; ASP in $/GB) | C4: FY2025A | D4: FY2026E | E4: FY2027E | F4: FY2028E | G4: FY2029E | H4: FY2030E | I4: FY2031E
A5: DRAM - HBM (100% contracted / LTA)
B6: HBM bits (PB) | C6: 1151 | D6: 1784.05 | E6: 2533.35 | F6: 3293.36 | G6: 4017.89 | H6: 4741.12 | I6: 5452.28
B7: HBM ASP ($/GB) | C7: 18 | D7: 21.96 | E7: 20.6424 | F7: 16.10107 | G7: 14.49096 | H7: 14.92569 | I7: 15.52272
B8: HBM revenue | C8: =C6*C7 -> 20718 | D8: =D6*D7 -> 39177.738 | E8: =E6*E7 -> 52294.424 | F8: =F6*F7 -> 53026.62 | G8: =G6*G7 -> 58223.083 | H8: =H6*H7 -> 70764.487 | I8: =I6*I7 -> 84634.216
A9: DRAM - Conventional (contracted 90% + spot 10%)
B10: Conv DRAM contracted bits (PB) | C10: 8582.4 | D10: 9612.29 | E10: 11150.25 | F10: 12934.29 | G10: 14745.1 | H10: 16661.96 | I10: 18661.39
B11: Conv DRAM contract ASP ($/GB) | C11: 3 | D11: 5.85 | E11: 5.382 | F11: 3.12156 | G11: 2.74697 | H11: 3.29637 | I11: 3.626
B12: Conv DRAM contracted revenue | C12: =C10*C11 -> 25747.2 | D12: =D10*D11 -> 56231.897 | E12: =E10*E11 -> 60010.645 | F12: =F10*F11*'README-Assumptions'!$C$12 -> 40375.162 | G12: =G10*G11*'README-Assumptions'!$C$12 -> 40504.347 | H12: =H10*H11 -> 54923.985 | I12: =I10*I11 -> 67666.2
B13: Conv DRAM spot bits (PB) | C13: 953.6 | D13: 1068.03 | E13: 1238.92 | F13: 1437.14 | G13: 1638.34 | H13: 1851.33 | I13: 2073.49
B14: Conv DRAM spot ASP ($/GB) | C14: 3.15 | D14: 6.318 | E14: 5.6511 | F14: 2.74697 | G14: 2.47228 | H14: 3.29637 | I14: 3.69852
B15: Conv DRAM spot revenue | C15: =C13*C14 -> 3003.84 | D15: =D13*D14 -> 6747.8135 | E15: =E13*E14 -> 7001.2608 | F15: =F13*F14*'README-Assumptions'!$C$12 -> 3947.7805 | G15: =G13*G14*'README-Assumptions'!$C$12 -> 4050.4352 | H15: =H13*H14 -> 6102.6687 | I15: =I13*I14 -> 7668.8442
B16: DRAM total revenue | C16: =C8+C12+C15 -> 49469.04 | D16: =D8+D12+D15 -> 102157.45 | E16: =E8+E12+E15 -> 119306.33 | F16: =F8+F12+F15 -> 97349.563 | G16: =G8+G12+G15 -> 102777.87 | H16: =H8+H12+H15 -> 131791.14 | I16: =I8+I12+I15 -> 159969.26
B17: DRAM total bits (PB) [->Wafer tab] | C17: =C6+C10+C13 -> 10687 | D17: =D6+D10+D13 -> 12464.37 | E17: =E6+E10+E13 -> 14922.52 | F17: =F6+F10+F13 -> 17664.79 | G17: =G6+G10+G13 -> 20401.33 | H17: =H6+H10+H13 -> 23254.41 | I17: =I6+I10+I13 -> 26187.16
A18: NAND (contracted 88% + spot 12%)
B19: NAND contracted bits (PB) | C19: 218922.88 | D19: 240815.17 | E19: 279345.59 | F19: 324040.89 | G19: 369406.61 | H19: 417429.47 | I19: 467521.01
B20: NAND contract ASP ($/GB) | C20: 0.06 | D20: 0.123 | E20: 0.11316 | F20: 0.06224 | G20: 0.05477 | H20: 0.06682 | I20: 0.07484
B21: NAND contracted revenue | C21: =C19*C20 -> 13135.373 | D21: =D19*D20 -> 29620.266 | E21: =E19*E20 -> 31610.747 | F21: =F19*F20*'README-Assumptions'!$C$12 -> 20168.305 | G21: =G19*G20*'README-Assumptions'!$C$12 -> 20232.4 | H21: =H19*H20 -> 27892.637 | I21: =I19*I20 -> 34989.272
B22: NAND spot bits (PB) | C22: 29853.12 | D22: 32838.43 | E22: 38092.58 | F22: 44187.39 | G22: 50373.63 | H22: 56922.2 | I22: 63752.87
B23: NAND spot ASP ($/GB) | C23: 0.063 | D23: 0.13284 | E23: 0.11882 | F23: 0.05477 | G23: 0.04929 | H23: 0.06682 | I23: 0.07633
B24: NAND spot revenue | C24: =C22*C23 -> 1880.7466 | D24: =D22*D23 -> 4362.257 | E24: =E22*E23 -> 4526.1604 | F24: =F22*F23*'README-Assumptions'!$C$12 -> 2420.1434 | G24: =G22*G23*'README-Assumptions'!$C$12 -> 2482.9162 | H24: =H22*H23 -> 3803.5414 | I24: =I22*I23 -> 4866.2566
B25: NAND total revenue | C25: =C21+C24 -> 15016.119 | D25: =D21+D24 -> 33982.523 | E25: =E21+E24 -> 36136.907 | F25: =F21+F24 -> 22588.448 | G25: =G21+G24 -> 22715.316 | H25: =H21+H24 -> 31696.179 | I25: =I21+I24 -> 39855.529
B26: NAND total bits (PB) [->Wafer tab] | C26: =C19+C22 -> 248776 | D26: =D19+D22 -> 273653.6 | E26: =E19+E22 -> 317438.17 | F26: =F19+F22 -> 368228.28 | G26: =G19+G22 -> 419780.24 | H26: =H19+H22 -> 474351.67 | I26: =I19+I22 -> 531273.88
A27: TOTAL
B28: Total revenue | C28: =C16+C25 -> 64485.159 | D28: =D16+D25 -> 136139.97 | E28: =E16+E25 -> 155443.24 | F28: =F16+F25 -> 119938.01 | G28: =G16+G25 -> 125493.18 | H28: =H16+H25 -> 163487.32 | I28: =I16+I25 -> 199824.79
B29: DRAM % of revenue | C29: =C16/C28 -> 0.76713837 | D29: =D16/D28 -> 0.75038541 | E29: =E16/E28 -> 0.76752345 | F29: =F16/F28 -> 0.81166564 | G29: =G16/G28 -> 0.81899163 | H29: =H16/H28 -> 0.80612454 | I29: =I16/I28 -> 0.80054762
B30: HBM % of DRAM revenue | C30: =C8/C16 -> 0.4188074 | D30: =D8/D16 -> 0.38350349 | E30: =E8/E16 -> 0.43832061 | F30: =F8/F16 -> 0.54470322 | G30: =G8/G16 -> 0.56649438 | H30: =H8/H16 -> 0.53694419 | I30: =I8/I16 -> 0.52906549
B31: memo: YoY revenue change | D31: =D28/C28-1 -> 1.111183 | E31: =E28/D28-1 -> 0.14178985 | F31: =F28/E28-1 -> -0.22841281 | G31: =G28/F28-1 -> 0.046317019 | H31: =H28/G28-1 -> 0.30275858 | I31: =I28/H28-1 -> 0.22226476

Sheet Wafer-to-Bit
A1: Wafer-Starts to Bit-Supply Conversion (capacity cross-check)
A2: PLACEHOLDER engineering inputs - SK hynix does not disclose these. Bits produced = supply ceiling; revenue-tab bits shipped must sit at/below it. Overwrite blue cells with your own capacity model.
B4: Conversion (annual) | C4: FY2025A | D4: FY2026E | E4: FY2027E | F4: FY2028E | G4: FY2029E | H4: FY2030E | I4: FY2031E
A5: DRAM
B6: Wafer starts (K wafers / month) | C6: 600 | D6: 610 | E6: 625 | F6: 640 | G6: 655 | H6: 670 | I6: 685
B7: Net good die per wafer | C7: 820 | D7: 820 | E7: 810 | F7: 800 | G7: 800 | H7: 800 | I7: 800
B8: Average Gb per die | C8: 19 | D8: 20 | E8: 21 | F8: 22 | G8: 23 | H8: 24 | I8: 25
B9: Yield | C9: 0.9 | D9: 0.9 | E9: 0.91 | F9: 0.91 | G9: 0.92 | H9: 0.92 | I9: 0.92
B10: = DRAM bits PRODUCED (PB) | C10: =(C6*1000*12*C7*C8*C9)/8/1000000 -> 12619.8 | D10: =(D6*1000*12*D7*D8*D9)/8/1000000 -> 13505.4 | E10: =(E6*1000*12*E7*E8*E9)/8/1000000 -> 14511.656 | F10: =(F6*1000*12*F7*F8*F9)/8/1000000 -> 15375.36 | G10: =(G6*1000*12*G7*G8*G9)/8/1000000 -> 16631.76 | H10: =(H6*1000*12*H7*H8*H9)/8/1000000 -> 17752.32 | I10: =(I6*1000*12*I7*I8*I9)/8/1000000 -> 18906
B11: DRAM bits SHIPPED in revenue build (PB) | C11: ='Segment-Revenue'!C17 -> 10687 | D11: ='Segment-Revenue'!D17 -> 12464.37 | E11: ='Segment-Revenue'!E17 -> 14922.52 | F11: ='Segment-Revenue'!F17 -> 17664.79 | G11: ='Segment-Revenue'!G17 -> 20401.33 | H11: ='Segment-Revenue'!H17 -> 23254.41 | I11: ='Segment-Revenue'!I17 -> 26187.16
B12: Utilization vs ceiling | C12: =C11/C10 -> 0.84684385 | D12: =D11/D10 -> 0.9229175 | E12: =E11/E10 -> 1.0283127 | F12: =F11/F10 -> 1.1489025 | G12: =G11/G10 -> 1.2266489 | H12: =H11/H10 -> 1.3099364 | I12: =I11/I10 -> 1.3851243
A13: NAND
B14: Wafer starts (K wafers / month) | C14: 150 | D14: 152 | E14: 155 | F14: 158 | G14: 161 | H14: 164 | I14: 167
B15: Net good die per wafer | C15: 350 | D15: 350 | E15: 345 | F15: 340 | G15: 340 | H15: 340 | I15: 340
B16: Average Gb per die (QLC/321-layer) | C16: 1024 | D16: 1130 | E16: 1240 | F16: 1360 | G16: 1490 | H16: 1630 | I16: 1780
B17: Yield | C17: 0.88 | D17: 0.88 | E17: 0.89 | F17: 0.9 | G17: 0.9 | H17: 0.91 | I17: 0.91
B18: = NAND bits PRODUCED (PB) | C18: =(C14*1000*12*C15*C16*C17)/8/1000000 -> 70963.2 | D18: =(D14*1000*12*D15*D16*D17)/8/1000000 -> 79353.12 | E18: =(E14*1000*12*E15*E16*E17)/8/1000000 -> 88522.515 | F18: =(F14*1000*12*F15*F16*F17)/8/1000000 -> 98629.92 | G18: =(G14*1000*12*G15*G16*G17)/8/1000000 -> 110109.51 | H18: =(H14*1000*12*H15*H16*H17)/8/1000000 -> 124063.21 | I18: =(I14*1000*12*I15*I16*I17)/8/1000000 -> 137958.37
B19: NAND bits SHIPPED in revenue build (PB) | C19: ='Segment-Revenue'!C26 -> 248776 | D19: ='Segment-Revenue'!D26 -> 273653.6 | E19: ='Segment-Revenue'!E26 -> 317438.17 | F19: ='Segment-Revenue'!F26 -> 368228.28 | G19: ='Segment-Revenue'!G26 -> 419780.24 | H19: ='Segment-Revenue'!H26 -> 474351.67 | I19: ='Segment-Revenue'!I26 -> 531273.88
B20: Utilization vs ceiling | C20: =C19/C18 -> 3.5057044 | D20: =D19/D18 -> 3.448555 | E20: =E19/E18 -> 3.5859597 | F20: =F19/F18 -> 3.7334338 | G20: =G19/G18 -> 3.8123886 | H20: =H19/H18 -> 3.8234676 | I20: =I19/I18 -> 3.8509725

Sheet Historicals-FY23-25
A1: Historical Anchors (from uploaded file; USD $M)
A2: Source: skhy-financials.xlsx (consolidated, K-IFRS, ~1,497 KRW/USD). These are the only filed figures; all forward drivers are estimates.
C4: FY2023 | D4: FY2024 | E4: FY2025
B5: Revenue | C5: 21889 | D5: 44220 | E5: 64898
B6: Gross profit | C6: -356 | D6: 21263 | E6: 39208
B7: Gross margin | C7: -0.016 | D7: 0.481 | E7: 0.604
B8: Operating income | C8: -5655 | D8: 15565 | E8: 31283
B9: Operating margin | C9: -0.258 | D9: 0.352 | E9: 0.482
B10: Net income | C10: -6088 | D10: 13220 | E10: 28672
B11: Operating cash flow | C11: 4468 | D11: 20877 | E11: 39351
B12: Capex | C12: 4836 | D12: 11087 | E12: 18994
B13: Free cash flow | C13: -368 | D13: 9790 | E13: 20357
B14: FCF margin | C14: -0.017 | D14: 0.221 | E14: 0.314
B15: AR / Inventory / AP (FY25)
B16: AR 12,158 | Inv 9,546 | AP 10,663 (FY2025 balance sheet)
