Workbook

Sheet Financials
A1: SMCI — Equity Research Model
A2: All figures in $mm unless noted | Blue = forecast
B3: Q4FY22 | C3: Q1FY23 | D3: Q2FY23 | E3: Q3FY23 | F3: Q4FY23 | G3: Q1FY24 | H3: Q2FY24 | I3: Q3FY24 | J3: Q4FY24 | K3: Q1FY25 | L3: Q2FY25 | M3: Q3FY25 | N3: Q4FY25 | O3: Q1FY26 | P3: Q2FY26 | Q3: Q3FY26 | R3: Q4FY26E | S3: Q1FY27E | T3: Q2FY27E | U3: Q3FY27E | V3: Q4FY27E | W3: Q1FY28E | X3: Q2FY28E | Y3: Q3FY28E
A4: Stock
A5: Current Stock Price | B5: 47.16
A6: Market Cap ($mm) | B6: =$B$5*$Q$37 -> 32643.633
A7: Cash ($mm) | B7: =Q48 -> 1290.324
A8: Debt ($mm) | B8: =Q59+Q60+Q63 -> 8773.101
A9: Enterprise Value ($mm) | B9: =$B$6+$B$8-$B$7 -> 40126.41
A10: Trailing P/E | B10: =$B$5/($N$35+$O$35+$P$35+$Q$35) -> 24.86686
A11: Trailing EV/EBIT | B11: =$B$9/($N$39+$O$39+$P$39+$Q$39) -> 26.559482
A12: Trailing EV/EBITDA | B12: =$B$9/($N$40+$O$40+$P$40+$Q$40) -> 25.70866
A13: Trailing EV/FCFE | B13: =$B$9/($N$94+$O$94+$P$94+$Q$94) -> -5.4691598
A14: EPS Yield | B14: =($N$35+$O$35+$P$35+$Q$35)/($B$5) -> 0.040214165
A16: INCOME STATEMENT
B17: Q4FY22 | C17: Q1FY23 | D17: Q2FY23 | E17: Q3FY23 | F17: Q4FY23 | G17: Q1FY24 | H17: Q2FY24 | I17: Q3FY24 | J17: Q4FY24 | K17: Q1FY25 | L17: Q2FY25 | M17: Q3FY25 | N17: Q4FY25 | O17: Q1FY26 | P17: Q2FY26 | Q17: Q3FY26 | R17: Q4FY26E | S17: Q1FY27E | T17: Q2FY27E | U17: Q3FY27E | V17: Q4FY27E | W17: Q1FY28E | X17: Q2FY28E | Y17: Q3FY28E
A18: Total Revenue | B18: 1635.46 | C18: 1852.13 | D18: 1803.195 | E18: 1283.296 | F18: 2184.861 | G18: 2119.672 | H18: 3664.924 | I18: 3850.066 | J18: 5354.589 | K18: 5937.256 | L18: 5677.962 | M18: 4599.913 | N18: 5756.911 | O18: 5017.79 | P18: 12682.491 | Q18: 10243.014 | R18: =Assumptions!$R$5 -> 10634.217 | S18: =Assumptions!$S$5 -> 11040.253 | T18: =Assumptions!$T$5 -> 11464.35 | U18: =Assumptions!$U$5 -> 11907.003 | V18: =Assumptions!$V$5 -> 12364.012 | W18: =Assumptions!$W$5 -> 12843.904 | X18: =Assumptions!$X$5 -> 13338.768 | Y18: =Assumptions!$Y$5 -> 13858.572
A19: Cost of Revenue | B19: 1348.116 | C19: 1504.595 | D19: 1465.773 | E19: 1056.937 | F19: 1813.165 | G19: 1765.981 | H19: 3100.602 | I19: 3252.698 | J19: 4808.56 | K19: 5161.676 | L19: 5007.94 | M19: 4159.695 | N19: 5212.809 | O19: 4550.417 | P19: 11883.924 | Q19: 9224.334 | R19: =$R$18*(1-Assumptions!$R$9) -> 9623.9663 | S19: =$S$18*(1-Assumptions!$S$9) -> 9985.9093 | T19: =$T$18*(1-Assumptions!$T$9) -> 10363.772 | U19: =$U$18*(1-Assumptions!$U$9) -> 10757.977 | V19: =$V$18*(1-Assumptions!$V$9) -> 11158.521 | W19: =$W$18*(1-Assumptions!$W$9) -> 11578.779 | X19: =$X$18*(1-Assumptions!$X$9) -> 12011.561 | Y19: =$Y$18*(1-Assumptions!$Y$9) -> 12472.715
A20: Gross Profit | B20: 287.344 | C20: 347.535 | D20: 337.422 | E20: 226.359 | F20: 371.696 | G20: 353.691 | H20: 564.322 | I20: 597.368 | J20: 546.029 | K20: 775.58 | L20: 670.022 | M20: 440.218 | N20: 544.102 | O20: 467.373 | P20: 798.567 | Q20: 1018.68 | R20: =$R$18-$R$19 -> 1010.2506 | S20: =$S$18-$S$19 -> 1054.3442 | T20: =$T$18-$T$19 -> 1100.5776 | U20: =$U$18-$U$19 -> 1149.0258 | V20: =$V$18-$V$19 -> 1205.4912 | W20: =$W$18-$W$19 -> 1265.1245 | X20: =$X$18-$X$19 -> 1327.2074 | Y20: =$Y$18-$Y$19 -> 1385.8572
A21: -- Gross Margin % | B21: 0.17569613 | C21: 0.18764072 | D21: 0.18712452 | E21: 0.17638877 | F21: 0.17012341 | G21: 0.16686119 | H21: 0.15397918 | I21: 0.15515786 | J21: 0.10197403 | K21: 0.13062937 | L21: 0.11800396 | M21: 0.095701375 | N21: 0.094512839 | O21: 0.093143197 | P21: 0.0629661 | Q21: 0.099451197 | R21: =$R$20/$R$18 -> 0.095 | S21: =$S$20/$S$18 -> 0.0955 | T21: =$T$20/$T$18 -> 0.096 | U21: =$U$20/$U$18 -> 0.0965 | V21: =$V$20/$V$18 -> 0.0975 | W21: =$W$20/$W$18 -> 0.0985 | X21: =$X$20/$X$18 -> 0.0995 | Y21: =$Y$20/$Y$18 -> 0.1
A22: Research & Development | B22: 70.79 | C22: 74.243 | D22: 70.7 | E22: 77.515 | F22: 84.802 | G22: 111.027 | H22: 108.824 | I22: 116.226 | J22: 127.471 | K22: 132.243 | L22: 158.229 | M22: 162.857 | N22: 183.221 | O22: 173.314 | P22: 180.761 | Q22: 215.659 | R22: =Assumptions!$R$11 -> 215.7 | S22: =Assumptions!$S$11 -> 215.7 | T22: =Assumptions!$T$11 -> 215.7 | U22: =Assumptions!$U$11 -> 215.7 | V22: =Assumptions!$V$11 -> 215.7 | W22: =Assumptions!$W$11 -> 215.7 | X22: =Assumptions!$X$11 -> 215.7 | Y22: =Assumptions!$Y$11 -> 215.7
A23: Sales, General & Administrative | B23: 51.341 | C23: 53.169 | D23: 51.54 | E23: 49.762 | F23: 60.139 | G23: 70.154 | H23: 84.034 | I23: 102.828 | J23: 130.072 | K23: 134.138 | L23: 143.169 | M23: 130.581 | N23: 132.49 | O23: 111.803 | P23: 143.508 | Q23: 177.153 | R23: =Assumptions!$R$13 -> 177.2 | S23: =Assumptions!$S$13 -> 177.2 | T23: =Assumptions!$T$13 -> 177.2 | U23: =Assumptions!$U$13 -> 177.2 | V23: =Assumptions!$V$13 -> 177.2 | W23: =Assumptions!$W$13 -> 177.2 | X23: =Assumptions!$X$13 -> 177.2 | Y23: =Assumptions!$Y$13 -> 177.2
A24: Total Operating Expenses | B24: 122.131 | C24: 127.412 | D24: 122.24 | E24: 127.277 | F24: 144.941 | G24: 181.181 | H24: 192.858 | I24: 219.054 | J24: 257.543 | K24: 266.381 | L24: 301.398 | M24: 293.438 | N24: 315.711 | O24: 285.117 | P24: 324.269 | Q24: 392.812 | R24: =$R$22+$R$23 -> 392.9 | S24: =$S$22+$S$23 -> 392.9 | T24: =$T$22+$T$23 -> 392.9 | U24: =$U$22+$U$23 -> 392.9 | V24: =$V$22+$V$23 -> 392.9 | W24: =$W$22+$W$23 -> 392.9 | X24: =$X$22+$X$23 -> 392.9 | Y24: =$Y$22+$Y$23 -> 392.9
A25: Operating Income (EBIT) | B25: 165.213 | C25: 220.123 | D25: 215.182 | E25: 99.082 | F25: 226.755 | G25: 172.51 | H25: 371.464 | I25: 378.314 | J25: 288.486 | K25: 509.199 | L25: 368.624 | M25: 146.78 | N25: 228.391 | O25: 182.256 | P25: 474.298 | Q25: 625.868 | R25: =$R$20-$R$24 -> 617.35061 | S25: =$S$20-$S$24 -> 661.44421 | T25: =$T$20-$T$24 -> 707.6776 | U25: =$U$20-$U$24 -> 756.12576 | V25: =$V$20-$V$24 -> 812.59115 | W25: =$W$20-$W$24 -> 872.22454 | X25: =$X$20-$X$24 -> 934.30744 | Y25: =$Y$20-$Y$24 -> 992.95724
A26: -- Operating Margin % | B26: 0.10101929 | C26: 0.11884857 | D26: 0.11933374 | E26: 0.077208999 | F26: 0.10378463 | G26: 0.081385233 | H26: 0.10135654 | I26: 0.098261692 | J26: 0.053876404 | K26: 0.085763356 | L26: 0.064921886 | M26: 0.031909299 | N26: 0.039672491 | O26: 0.036321966 | P26: 0.037397858 | Q26: 0.061101937 | R26: =$R$25/$R$18 -> 0.058053227 | S26: =$S$25/$S$18 -> 0.059912049 | T26: =$T$25/$T$18 -> 0.061728541 | U26: =$U$25/$U$18 -> 0.063502611 | V26: =$V$25/$V$18 -> 0.065722288 | W26: =$W$25/$W$18 -> 0.067909612 | X26: =$X$25/$X$18 -> 0.070044507 | Y26: =$Y$25/$Y$18 -> 0.071649316
A27: Interest Income | L27: 8.776 | M27: 14.654 | P27: 51.042 | Q27: 45.437 | R27: =Assumptions!$R$22 -> 43.6 | S27: =Assumptions!$S$22 -> 41.9 | T27: =Assumptions!$T$22 -> 40.2 | U27: =Assumptions!$U$22 -> 38.6 | V27: =Assumptions!$V$22 -> 37 | W27: =Assumptions!$W$22 -> 35.6 | X27: =Assumptions!$X$22 -> 34.1 | Y27: =Assumptions!$Y$22 -> 32.8
A28: Interest Expense | B28: 2.928 | C28: 3.938 | D28: 1.756 | E28: 1.288 | F28: 3.509 | G28: 1.863 | H28: 8.131 | I28: 6.246 | R28: =Assumptions!$R$23 -> 109.66375 | S28: =Assumptions!$S$23 -> 109.66375 | T28: =Assumptions!$T$23 -> 109.66375 | U28: =Assumptions!$U$23 -> 109.66375 | V28: =Assumptions!$V$23 -> 109.66375 | W28: =Assumptions!$W$23 -> 109.66375 | X28: =Assumptions!$X$23 -> 109.66375 | Y28: =Assumptions!$Y$23 -> 109.66375
A29: Other Income (Expense), net | B29: 3.973 | C29: 8.054 | D29: -6.335 | E29: -0.078 | F29: 2.005 | G29: 6.613 | H29: -7.886 | I29: 10.035 | J29: 13.955 | K29: 7.233 | L29: 12.959 | M29: -18.313 | N29: 16.616 | O29: 51.227 | R29: =0 -> 0 | S29: =0 -> 0 | T29: =0 -> 0 | U29: =0 -> 0 | V29: =0 -> 0 | W29: =0 -> 0 | X29: =0 -> 0 | Y29: =0 -> 0
A30: Pretax Income | B30: 166.582 | C30: 223.35 | D30: 205.74 | E30: 96.703 | F30: 224.871 | G30: 177.21 | H30: 357.471 | I30: 382.476 | J30: 298.803 | K30: 499.059 | L30: 377.565 | M30: 114.62 | N30: 214.461 | O30: 208.446 | P30: 499.715 | Q30: 610.274 | R30: =$R$25+$R$27-$R$28+$R$29 -> 551.28686 | S30: =$S$25+$S$27-$S$28+$S$29 -> 593.68046 | T30: =$T$25+$T$27-$T$28+$T$29 -> 638.21385 | U30: =$U$25+$U$27-$U$28+$U$29 -> 685.06201 | V30: =$V$25+$V$27-$V$28+$V$29 -> 739.9274 | W30: =$W$25+$W$27-$W$28+$W$29 -> 798.16079 | X30: =$X$25+$X$27-$X$28+$X$29 -> 858.74369 | Y30: =$Y$25+$Y$27-$Y$28+$Y$29 -> 916.09349
A31: Income Tax Expense | B31: 25.76 | C31: 38.934 | D31: 29.573 | E31: 10.857 | F31: 31.302 | G31: 20.215 | H31: 61.503 | I31: -19.983 | J31: 1.559 | K31: 74.732 | L31: 56.969 | M31: 5.843 | N31: 19.307 | O31: 40.161 | P31: 99.151 | Q31: 126.887 | R31: =$R$30*Assumptions!$R$24 -> 114.61254 | S31: =$S$30*Assumptions!$S$24 -> 123.42617 | T31: =$T$30*Assumptions!$T$24 -> 132.68466 | U31: =$U$30*Assumptions!$U$24 -> 142.42439 | V31: =$V$30*Assumptions!$V$24 -> 153.83091 | W31: =$W$30*Assumptions!$W$24 -> 165.93763 | X31: =$X$30*Assumptions!$X$24 -> 178.53281 | Y31: =$Y$30*Assumptions!$Y$24 -> 190.45584
A32: -- Effective Tax Rate % | B32: 0.15463856 | C32: 0.17431833 | D32: 0.14373967 | E32: 0.11227159 | F32: 0.13919981 | G32: 0.1140737 | H32: 0.17205032 | I32: -0.052246415 | J32: 0.0052174844 | K32: 0.14974582 | L32: 0.15088528 | M32: 0.050977142 | N32: 0.090025692 | O32: 0.1926686 | P32: 0.1984151 | Q32: 0.20791808 | R32: =Assumptions!$R$24 -> 0.2079 | S32: =Assumptions!$S$24 -> 0.2079 | T32: =Assumptions!$T$24 -> 0.2079 | U32: =Assumptions!$U$24 -> 0.2079 | V32: =Assumptions!$V$24 -> 0.2079 | W32: =Assumptions!$W$24 -> 0.2079 | X32: =Assumptions!$X$24 -> 0.2079 | Y32: =Assumptions!$Y$24 -> 0.2079
A33: Net Income | B33: 140.822 | C33: 184.416 | D33: 176.167 | E33: 85.846 | F33: 193.569 | G33: 156.995 | H33: 295.968 | I33: 402.459 | J33: 297.244 | K33: 424.327 | L33: 320.596 | M33: 108.777 | N33: 195.154 | O33: 168.285 | P33: 400.564 | Q33: 483.387 | R33: =$R$30-$R$31 -> 436.67432 | S33: =$S$30-$S$31 -> 470.25429 | T33: =$T$30-$T$31 -> 505.52919 | U33: =$U$30-$U$31 -> 542.63761 | V33: =$V$30-$V$31 -> 586.09649 | W33: =$W$30-$W$31 -> 632.22316 | X33: =$X$30-$X$31 -> 680.21088 | Y33: =$Y$30-$Y$31 -> 725.63765
A34: EPS (Basic) | B34: 0.2772 | C34: 0.351 | D34: 0.331 | E34: 0.161 | F34: 0.368 | G34: 0.3 | H34: 0.55 | I34: 0.71 | J34: 0.5069 | K34: 0.72 | L34: 0.54 | M34: 0.18 | N34: 0.3266 | O34: 0.28 | P34: 0.67 | Q34: 0.81 | R34: =$R$33/$R$36 -> 0.72754802 | S34: =$S$33/$S$36 -> 0.78349599 | T34: =$T$33/$T$36 -> 0.8422679 | U34: =$U$33/$U$36 -> 0.90409466 | V34: =$V$33/$V$36 -> 0.97650199 | W34: =$W$33/$W$36 -> 1.0533542 | X34: =$X$33/$X$36 -> 1.133307 | Y34: =$Y$33/$Y$36 -> 1.2089931
A35: EPS (Diluted) | B35: 0.2661 | C35: 0.335 | D35: 0.314 | E35: 0.153 | F35: 0.3518 | G35: 0.27 | H35: 0.51 | I35: 0.66 | J35: 0.4633 | K35: 0.67 | L35: 0.51 | M35: 0.17 | N35: 0.3165 | O35: 0.26 | P35: 0.6 | Q35: 0.72 | R35: =$R$33/$R$37 -> 0.63084993 | S35: =$S$33/$S$37 -> 0.67936188 | T35: =$T$33/$T$37 -> 0.73032244 | U35: =$U$33/$U$37 -> 0.78393183 | V35: =$V$33/$V$37 -> 0.84671554 | W35: =$W$33/$W$37 -> 0.91335331 | X35: =$X$33/$X$37 -> 0.98267969 | Y35: =$Y$33/$Y$37 -> 1.0483063
A36: Shares (Basic, mm) | B36: 507.96 | C36: 525.98 | D36: 531.6 | E36: 532.8 | F36: 525.98 | G36: 530.928 | H36: 541.354 | I36: 564.78 | J36: 586.45 | K36: 589.558 | L36: 592.507 | M36: 595.041 | N36: 597.554 | O36: 595.624 | P36: 598.004 | Q36: 600.205 | R36: =Assumptions!$R$28 -> 600.2 | S36: =Assumptions!$S$28 -> 600.2 | T36: =Assumptions!$T$28 -> 600.2 | U36: =Assumptions!$U$28 -> 600.2 | V36: =Assumptions!$V$28 -> 600.2 | W36: =Assumptions!$W$28 -> 600.2 | X36: =Assumptions!$X$28 -> 600.2 | Y36: =Assumptions!$Y$28 -> 600.2
A37: Shares (Diluted, mm) | B37: 529.16 | C37: 550.17 | D37: 561.44 | E37: 562.33 | F37: 550.17 | G37: 571.853 | H37: 580.777 | I37: 614.31 | J37: 641.644 | K37: 639.148 | L37: 636.047 | M37: 621.809 | N37: 616.604 | O37: 663.235 | P37: 693.989 | Q37: 692.189 | R37: =Assumptions!$R$26 -> 692.2 | S37: =Assumptions!$S$26 -> 692.2 | T37: =Assumptions!$T$26 -> 692.2 | U37: =Assumptions!$U$26 -> 692.2 | V37: =Assumptions!$V$26 -> 692.2 | W37: =Assumptions!$W$26 -> 692.2 | X37: =Assumptions!$X$26 -> 692.2 | Y37: =Assumptions!$Y$26 -> 692.2
A38: NON-GAAP KPIs
A39: Clean EBIT | B39: 165.213 | C39: 220.123 | D39: 215.182 | E39: 99.082 | F39: 226.755 | G39: 172.51 | H39: 371.464 | I39: 378.314 | J39: 288.486 | K39: 509.199 | L39: 368.624 | M39: 146.78 | N39: 228.391 | O39: 182.256 | P39: 474.298 | Q39: 625.868 | R39: =$R$25 -> 617.35061 | S39: =$S$25 -> 661.44421 | T39: =$T$25 -> 707.6776 | U39: =$U$25 -> 756.12576 | V39: =$V$25 -> 812.59115 | W39: =$W$25 -> 872.22454 | X39: =$X$25 -> 934.30744 | Y39: =$Y$25 -> 992.95724
A40: Clean EBITDA | B40: 165.964 | C40: 228.67 | D40: 223.831 | E40: 107.818 | F40: 227.723 | G40: 179.51 | H40: 378.764 | I40: 385.914 | J40: 296.686 | K40: 518.199 | L40: 378.124 | M40: 157.68 | N40: 239.991 | O40: 194.356 | P40: 487.098 | Q40: 639.368 | R40: =$R$39+$R$41 -> 630.85061 | S40: =$S$39+$S$41 -> 674.94421 | T40: =$T$39+$T$41 -> 721.1776 | U40: =$U$39+$U$41 -> 769.62576 | V40: =$V$39+$V$41 -> 826.09115 | W40: =$W$39+$W$41 -> 885.72454 | X40: =$X$39+$X$41 -> 947.80744 | Y40: =$Y$39+$Y$41 -> 1006.4572
A41: Depreciation & Amortization | B41: 0.751 | C41: 8.547 | D41: 8.649 | E41: 8.736 | F41: 0.968 | G41: 7 | H41: 7.3 | I41: 7.6 | J41: 8.2 | K41: 9 | L41: 9.5 | M41: 10.9 | N41: 11.6 | O41: 12.1 | P41: 12.8 | Q41: 13.5 | R41: =Assumptions!$R$16 -> 13.5 | S41: =Assumptions!$S$16 -> 13.5 | T41: =Assumptions!$T$16 -> 13.5 | U41: =Assumptions!$U$16 -> 13.5 | V41: =Assumptions!$V$16 -> 13.5 | W41: =Assumptions!$W$16 -> 13.5 | X41: =Assumptions!$X$16 -> 13.5 | Y41: =Assumptions!$Y$16 -> 13.5
...

Sheet Assumptions
A1: SMCI — Model Assumptions
A2: Yellow = editable forecast inputs | Blue shading = forecast period
B3: Q4FY22 | C3: Q1FY23 | D3: Q2FY23 | E3: Q3FY23 | F3: Q4FY23 | G3: Q1FY24 | H3: Q2FY24 | I3: Q3FY24 | J3: Q4FY24 | K3: Q1FY25 | L3: Q2FY25 | M3: Q3FY25 | N3: Q4FY25 | O3: Q1FY26 | P3: Q2FY26 | Q3: Q3FY26 | R3: Q4FY26E | S3: Q1FY27E | T3: Q2FY27E | U3: Q3FY27E | V3: Q4FY27E | W3: Q1FY28E | X3: Q2FY28E | Y3: Q3FY28E
A4: REVENUE DRIVERS
A5: Total Revenue ($mm) | B5: 1635.46 | C5: 1852.13 | D5: 1803.195 | E5: 1283.296 | F5: 2184.861 | G5: 2119.672 | H5: 3664.924 | I5: 3850.066 | J5: 5354.589 | K5: 5937.256 | L5: 5677.962 | M5: 4599.913 | N5: 5756.911 | O5: 5017.79 | P5: 12682.491 | Q5: 10243.014 | R5: =R46 -> 10634.217 | S5: =S46 -> 11040.253 | T5: =T46 -> 11464.35 | U5: =U46 -> 11907.003 | V5: =V46 -> 12364.012 | W5: =W46 -> 12843.904 | X5: =X46 -> 13338.768 | Y5: =Y46 -> 13858.572
A6: Revenue Growth % (QoQ) | C6: =C5/B5-1 -> 0.1324826 | D6: =D5/C5-1 -> -0.026420932 | E6: =E5/D5-1 -> -0.28832101 | F6: =F5/E5-1 -> 0.70253862 | G6: =G5/F5-1 -> -0.029836681 | H6: =H5/G5-1 -> 0.72900524 | I6: =I5/H5-1 -> 0.050517282 | J6: =J5/I5-1 -> 0.3907785 | ... Y6: =Y5/X5-1 -> 0.038969422
A7: Revenue Growth % (YoY) | F7: =F5/B5-1 -> 0.33593056 | G7: =G5/C5-1 -> 0.14445098 | H7: =H5/D5-1 -> 1.0324613 | I7: =I5/E5-1 -> 2.0001387 | J7: =J5/F5-1 -> 1.4507687 | K7: =K5/G5-1 -> 1.8010258 | L7: =L5/H5-1 -> 0.54927142 | M7: =M5/I5-1 -> 0.19476212 | ... Y7: =Y5/U5-1 -> 0.16390101
A8: MARGIN DRIVERS
A9: Gross Margin % | B9: 0.17569613 | C9: 0.18764072 | D9: 0.18712452 | E9: 0.17638877 | F9: 0.17012341 | G9: 0.16686119 | H9: 0.15397918 | I9: 0.15515786 | J9: 0.10197403 | K9: 0.13062937 | L9: 0.11800396 | M9: 0.095701375 | N9: 0.094512839 | O9: 0.093143197 | P9: 0.0629661 | Q9: 0.099451197 | R9: 0.095 | S9: 0.0955 | T9: 0.096 | U9: 0.0965 | V9: 0.0975 | W9: 0.0985 | X9: 0.0995 | Y9: 0.1 | AA9: AI-mix GM: stabilize ~9.5%->10.0%
A10: OPEX DRIVERS
A11: R&D ($mm) | B11: 70.79 | C11: 74.243 | D11: 70.7 | E11: 77.515 | F11: 84.802 | G11: 111.027 | H11: 108.824 | I11: 116.226 | J11: 127.471 | K11: 132.243 | L11: 158.229 | M11: 162.857 | N11: 183.221 | O11: 173.314 | P11: 180.761 | Q11: 215.659 | R11: 215.7 | S11: 215.7 | T11: 215.7 | U11: 215.7 | V11: 215.7 | W11: 215.7 | X11: 215.7 | Y11: 215.7
A12: R&D % of Revenue | B12: 0.0433 | C12: 0.0401 | D12: 0.0392 | E12: 0.0604 | F12: 0.0388 | G12: 0.0524 | H12: 0.0297 | I12: 0.0302 | J12: 0.0238 | K12: 0.0223 | L12: 0.0279 | M12: 0.0354 | N12: 0.0318 | O12: 0.0345 | P12: 0.0143 | Q12: 0.0211 | R12: 0.0211 | S12: 0.0211 | T12: 0.0211 | U12: 0.0211 | V12: 0.0211 | W12: 0.0211 | X12: 0.0211 | Y12: 0.0211
A13: SG&A ($mm) | B13: 51.341 | C13: 53.169 | D13: 51.54 | E13: 49.762 | F13: 60.139 | G13: 70.154 | H13: 84.034 | I13: 102.828 | J13: 130.072 | K13: 134.138 | L13: 143.169 | M13: 130.581 | N13: 132.49 | O13: 111.803 | P13: 143.508 | Q13: 177.153 | R13: 177.2 | S13: 177.2 | T13: 177.2 | U13: 177.2 | V13: 177.2 | W13: 177.2 | X13: 177.2 | Y13: 177.2
A14: SG&A % of Revenue | B14: 0.0314 | C14: 0.0287 | D14: 0.0286 | E14: 0.0388 | F14: 0.0275 | G14: 0.0331 | H14: 0.0229 | I14: 0.0267 | J14: 0.0243 | K14: 0.0226 | L14: 0.0252 | M14: 0.0284 | N14: 0.023 | O14: 0.0223 | P14: 0.0113 | Q14: 0.0173 | R14: 0.0173 | S14: 0.0173 | T14: 0.0173 | U14: 0.0173 | V14: 0.0173 | W14: 0.0173 | X14: 0.0173 | Y14: 0.0173
A15: D&A & CAPEX
A16: Depreciation & Amortization ($mm) | B16: 0.751 | C16: 8.547 | D16: 8.649 | E16: 8.736 | F16: 0.968 | G16: 7 | H16: 7.3 | I16: 7.6 | J16: 8.2 | K16: 9 | L16: 9.5 | M16: 10.9 | N16: 11.6 | O16: 12.1 | P16: 12.8 | Q16: 13.5 | R16: 13.5 | S16: 13.5 | T16: 13.5 | U16: 13.5 | V16: 13.5 | W16: 13.5 | X16: 13.5 | Y16: 13.5
A17: Capital Expenditures ($mm) | B17: -11.025 | C17: -10.746 | D17: -9.885 | E17: -7.987 | F17: -8.175 | G17: -2.631 | H17: -14.72 | I17: -92.945 | J17: -13.983 | K17: -44.3 | L17: -27.536 | M17: -32.7 | N17: -22.678 | O17: -32.27 | P17: -21.221 | Q17: -80.278 | R17: -80.3 | S17: -80.3 | T17: -80.3 | U17: -80.3 | V17: -80.3 | W17: -80.3 | X17: -80.3 | Y17: -80.3
A18: Capex % of Revenue | B18: 0.0067 | C18: 0.0058 | D18: 0.0055 | E18: 0.0062 | F18: 0.0037 | G18: 0.0012 | H18: 0.004 | I18: 0.0241 | J18: 0.0026 | K18: 0.0075 | L18: 0.0048 | M18: 0.0071 | N18: 0.0039 | O18: 0.0064 | P18: 0.0017 | Q18: 0.0078 | R18: 0.0078 | S18: 0.0078 | T18: 0.0078 | U18: 0.0078 | V18: 0.0078 | W18: 0.0078 | X18: 0.0078 | Y18: 0.0078
A19: OTHER
A20: Stock-Based Compensation ($mm) | B20: 8.884 | C20: 11.014 | D20: 16.981 | E20: 13.652 | F20: 12.786 | G20: 57.379 | H20: 43.061 | I20: 56.107 | J20: 74.96 | K20: 64.014 | L20: 82.122 | M20: 84.704 | N20: 83.612 | O20: 89.139 | P20: 90.485 | Q20: 125.934 | R20: 125.9 | S20: 125.9 | T20: 125.9 | U20: 125.9 | V20: 125.9 | W20: 125.9 | X20: 125.9 | Y20: 125.9
A21: SBC % of Revenue | B21: 0.0054 | C21: 0.0059 | D21: 0.0094 | E21: 0.0106 | F21: 0.0059 | G21: 0.0271 | H21: 0.0117 | I21: 0.0146 | J21: 0.014 | K21: 0.0108 | L21: 0.0145 | M21: 0.0184 | N21: 0.0145 | O21: 0.0178 | P21: 0.0071 | Q21: 0.0123 | R21: 0.0123 | S21: 0.0123 | T21: 0.0123 | U21: 0.0123 | V21: 0.0123 | W21: 0.0123 | X21: 0.0123 | Y21: 0.0123
A22: Interest Income ($mm) | L22: 8.776 | M22: 14.654 | P22: 51.042 | Q22: 45.437 | R22: 43.6 | S22: 41.9 | T22: 40.2 | U22: 38.6 | V22: 37 | W22: 35.6 | X22: 34.1 | Y22: 32.8 | AA22: EST ~$45mm/qtr tapering -4%/qtr as cash deployed
A23: Interest Expense ($mm) | B23: 2.928 | C23: 3.938 | D23: 1.756 | E23: 1.288 | F23: 3.509 | G23: 1.863 | H23: 8.131 | I23: 6.246 | R23: =R53 -> 109.66375 | S23: =S53 -> 109.66375 | T23: =T53 -> 109.66375 | U23: =U53 -> 109.66375 | V23: =V53 -> 109.66375 | W23: =W53 -> 109.66375 | X23: =X53 -> 109.66375 | Y23: =Y53 -> 109.66375
A24: Effective Tax Rate % | B24: 0.15463856 | C24: 0.17431833 | D24: 0.14373967 | E24: 0.11227159 | F24: 0.13919981 | G24: 0.1140737 | H24: 0.17205032 | I24: -0.052246415 | J24: 0.0052174844 | K24: 0.14974582 | L24: 0.15088528 | M24: 0.050977142 | N24: 0.090025692 | O24: 0.1926686 | P24: 0.1984151 | Q24: 0.20791808 | R24: 0.2079 | S24: 0.2079 | T24: 0.2079 | U24: 0.2079 | V24: 0.2079 | W24: 0.2079 | X24: 0.2079 | Y24: 0.2079
A25: SHARES
A26: Diluted Shares (mm) | B26: 529.16 | C26: 550.17 | D26: 561.44 | E26: 562.33 | F26: 550.17 | G26: 571.853 | H26: 580.777 | I26: 614.31 | J26: 641.644 | K26: 639.148 | L26: 636.047 | M26: 621.809 | N26: 616.604 | O26: 663.235 | P26: 693.989 | Q26: 692.189 | R26: 692.2 | S26: 692.2 | T26: 692.2 | U26: 692.2 | V26: 692.2 | W26: 692.2 | X26: 692.2 | Y26: 692.2
A27: QoQ Share Change (mm) | C27: =C26-B26 -> 21.01 | D27: =D26-C26 -> 11.27 | E27: =E26-D26 -> 0.89 | F27: =F26-E26 -> -12.16 | G27: =G26-F26 -> 21.683 | H27: =H26-G26 -> 8.924 | I27: =I26-H26 -> 33.533 | J27: =J26-I26 -> 27.334 | ... Y27: =Y26-X26 -> 0
A28: Basic Shares (mm) | B28: 507.96 | C28: 525.98 | D28: 531.6 | E28: 532.8 | F28: 525.98 | G28: 530.928 | H28: 541.354 | I28: 564.78 | J28: 586.45 | K28: 589.558 | L28: 592.507 | M28: 595.041 | N28: 597.554 | O28: 595.624 | P28: 598.004 | Q28: 600.205 | R28: 600.2 | S28: 600.2 | T28: 600.2 | U28: 600.2 | V28: 600.2 | W28: 600.2 | X28: 600.2 | Y28: 600.2
A29: WORKING CAPITAL DAYS
A30: Days Sales Outstanding | B30: 46.4 | C30: 36.2 | D30: 38.8 | E30: 47.7 | F30: 47.8 | G30: 36.3 | H30: 37.3 | I30: 39 | J30: 46.5 | K30: 41.9 | L30: 49 | M30: 52.3 | N30: 34.8 | O30: 45.8 | P30: 79 | Q30: 74.7 | R30: 58.6 | S30: 58.6 | T30: 58.6 | U30: 58.6 | V30: 58.6 | W30: 58.6 | X30: 58.6 | Y30: 58.6
A31: Inventory Days | B31: 104.3 | C31: 105 | D31: 88.3 | E31: 132.6 | F31: 72.6 | G31: 105.8 | H31: 72.4 | I31: 115.4 | J31: 82 | K31: 86.9 | L31: 65.3 | M31: 84.7 | N31: 81.7 | O31: 114.6 | P31: 81.1 | Q31: 109.5 | R31: 96.7 | S31: 96.7 | T31: 96.7 | U31: 96.7 | V31: 96.7 | W31: 96.7 | X31: 96.7 | Y31: 96.7
A32: Days Payable Outstanding | B32: 44.2 | C32: 47.5 | D32: 34.8 | E32: 55.3 | F32: 39 | G32: 55.9 | H32: 37 | I32: 30.6 | J32: 27.9 | K32: 29.7 | L32: 10 | M32: 14.1 | N32: 22.4 | O32: 25.6 | P32: 105.3 | Q32: 36.4 | R32: 47.4 | S32: 47.4 | T32: 47.4 | U32: 47.4 | V32: 47.4 | W32: 47.4 | X32: 47.4 | Y32: 47.4
A33: DEBT SCHEDULE
A34: Short-term Debt ($mm) | B34: 449.146 | C34: 101.173 | F34: 170.123 | R34: 0 | S34: 0 | T34: 0 | U34: 0 | V34: 0 | W34: 0 | X34: 0 | Y34: 0
A35: Long-term Debt ($mm) | B35: 147.618 | C35: 212.064 | D35: 131.366 | E35: 147.947 | F35: 120.179 | G35: 105.389 | H35: 333.008 | I35: 126.043 | J35: 1771.799 | K35: 2217.124 | L35: 1868.888 | M35: 2452.489 | N35: 4682.593 | O35: 4756.936 | P35: 4859.584 | Q35: 6967.219 | R35: =R49+R50 -> 8773.1 | S35: =S49+S50 -> 8773.1 | T35: =T49+T50 -> 8773.1 | U35: =U49+U50 -> 8773.1 | V35: =V49+V50 -> 8773.1 | W35: =W49+W50 -> 8773.1 | X35: =X49+X50 -> 8773.1 | Y35: =Y49+Y50 -> 8773.1
A36: Total Debt ($mm) | B36: =B34+B35 -> 596.764 | C36: =C34+C35 -> 313.237 | D36: =D34+D35 -> 131.366 | E36: =E34+E35 -> 147.947 | F36: =F34+F35 -> 290.302 | G36: =G34+G35 -> 105.389 | H36: =H34+H35 -> 333.008 | I36: =I34+I35 -> 126.043 | ... Y36: =Y34+Y35 -> 8773.1
A39: --- SMCI BOTTOM-UP REVENUE BUILD (assumptions-architect) ---
A40: Source: SMCI 10-K product disaggregation (Systems vs Subsystems & Accessories). Units & ASP are ANALYST ESTIMATES (SMCI discloses no units); AI-platform mix per company commentary.
A41: Server & Storage Systems - Units (000s) | B41: 135.2971 | C41: 146.882 | D41: 137.4936 | E41: 93.4239 | F41: 148.5705 | G41: 134.4895 | H41: 189.3544 | I41: 189.4638 | J41: 209.7214 | K41: 207.804 | L41: 192.2396 | M41: 167.1891 | N41: 182.3022 | O41: 154.0947 | P41: 254.1783 | Q41: 223.0184 | R41: 229.71 | S41: 236.6 | T41: 243.7 | U41: 251.01 | V41: 258.54 | W41: 266.3 | X41: 274.28 | Y41: 282.51 | AA41: EST units; +3% QoQ vol
A42: Server & Storage Systems - ASP ($000s) | B42: 11 | C42: 11.5 | D42: 12 | E42: 12.5 | F42: 13.5 | G42: 14.5 | H42: 18 | I42: 19 | J42: 24 | K42: 27 | L42: 28 | M42: 26 | N42: 30 | O42: 31 | P42: 48 | Q42: 44 | R42: 44.44 | S42: 44.88 | T42: 45.33 | U42: 45.79 | V42: 46.24 | W42: 46.71 | X42: 47.17 | Y42: 47.65 | AA42: EST blended ASP; +1% QoQ
...
