Workbook

Sheet Summary
B2: TOST | C2: 26.47
B3: Shares | C3: ='Income Statement'!E47 -> 607
B4: MC | C4: =C3*C2 -> 16067.29
B5: Cash | C5: =Metrics!E34 -> 1991
B6: Debt | C6: =Metrics!E33 -> 20
B7: EV | C7: =C4-C5+C6 -> 14096.29
B8: P/E | C8: =C2/Metrics!E12 -> 45.775755
B9: EV/EBIT | C9: =C7/Metrics!E9 -> 46.369375
B10: EV/EBITDA | C10: =C7/Metrics!E10 -> 38.305136
B11: EV/FCF | C11: =C7/Metrics!E46 -> 38.619973

Sheet Rev COGS Buildout 
A1: TOAST, INC.
A2: Revenue + COGS Forecast
A3: (in millions, except per share amounts)
A5: Year Ended December 31, | B5: 2022 | C5: =B5+1 -> 2023 | D5: =C5+1 -> 2024 | E5: =D5+1 -> 2025 | F5: =E5+1 -> 2026 | G5: =F5+1 -> 2027 | H5: =G5+1 -> 2028 | I5: =H5+1 -> 2029 | J5: =I5+1 -> 2030
A7: SUBSCRIPTION SALES CALCS:
A9: Sub Revenue / Location | B9: =(B25/B14)*1000000 -> 4101.2658 | C9: =(C25/C14)*1000000 -> 4716.9811 | D9: =(D25/D14)*1000000 -> 5268.6567 | E9: =(E25/E14)*1000000 -> 5707.3171 | F9: =E9*(1+F10) -> 6125.4265 | G9: =F9*(1+G10) -> 6512.9116 | H9: =G9*(1+H10) -> 6859.7794 | I9: =H9*(1+I10) -> 7156.5231 | J9: =I9*(1+J10) -> 7394.5381
A10: ARR per Location growth % | C10: =C9/B9-1 -> 0.15012812 | D10: =D9/C9-1 -> 0.11695522 | E10: =E9/D9-1 -> 0.083258481 | F10: =E10-1% -> 0.073258481 | G10: =F10-1% -> 0.063258481 | H10: =G10-1% -> 0.053258481 | I10: =H10-1% -> 0.043258481 | J10: =I10-1% -> 0.033258481
A12: FINTECH SALES CALCS:
A13: Gross Payment Volume | B13: 91700 | C13: 126100 | D13: 159100 | E13: 195100 | F13: =F14*F16 -> 231019.81 | G13: =G14*G16 -> 261051.2 | H13: =H14*H16 -> 289949.21 | I13: =I14*I16 -> 314127.15 | J13: =J14*J16 -> 335961.98
A14: Locations | B14: 79000 | C14: 106000 | D14: 134000 | E14: 164000 | F14: =E14+F15 -> 194000 | G14: =F14+G15 -> 219000 | H14: =G14+H15 -> 243000 | I14: =H14+I15 -> 263000 | J14: =I14+J15 -> 281000
A15: Location growth | C15: =C14-B14 -> 27000 | D15: =D14-C14 -> 28000 | E15: =E14-D14 -> 30000 | F15: 30000 | G15: 25000 | H15: 24000 | I15: 20000 | J15: 18000
A16: GPV / Location | B16: =B13/B14 -> 1.1607595 | C16: =C13/C14 -> 1.1896226 | D16: =D13/D14 -> 1.1873134 | E16: =E13/E14 -> 1.1896341 | F16: =E16*(1+F17) -> 1.1908238 | G16: =F16*(1+G17) -> 1.1920146 | H16: =G16*(1+H17) -> 1.1932066 | I16: =H16*(1+I17) -> 1.1943998 | J16: =I16*(1+J17) -> 1.1955942
A17: GPV / Location % Growth | C17: =C16/B16-1 -> 0.024865744 | D17: =D16/C16-1 -> -0.001941127 | E17: =E16/D16-1 -> 0.0019545921 | F17: 0.001 | G17: 0.001 | H17: 0.001 | I17: 0.001 | J17: 0.001
A18: Fintech Sales / GPV | B18: =B26/B13 -> 0.024732824 | C18: =C26/C13 -> 0.025289453 | D18: =D26/D13 -> 0.025474544 | E18: =E26/E13 -> 0.025817529 | F18: =E18 -> 0.025817529 | G18: =F18 -> 0.025817529 | H18: =G18 -> 0.025817529 | I18: =H18 -> 0.025817529 | J18: =I18 -> 0.025817529
A19: Fintech Sales / Location (Not $mm) | B19: =(B26/B14)*1000000 -> 28708.861 | C19: =(C26/C14)*1000000 -> 30084.906 | D19: =(D26/D14)*1000000 -> 30246.269 | E19: =(E26/E14)*1000000 -> 30713.415 | F19: =(F26/F14)*1000000 -> 30744.128 | G19: =(G26/G14)*1000000 -> 30774.872 | H19: =(H26/H14)*1000000 -> 30805.647 | I19: =(I26/I14)*1000000 -> 30836.453 | J19: =(J26/J14)*1000000 -> 30867.289
A21: HARDWARE SALES CALCS:
A22: Hardware Growth Rate | C22: =C27/B27-1 -> 0.26618705 | D22: =D27/C27-1 -> 0.14204545 | E22: =E27/D27-1 -> -0.10447761 | F22: =AVERAGE(C22:E22) -> 0.10125163 | G22: =F22 -> 0.10125163 | H22: =G22 -> 0.10125163 | I22: =H22 -> 0.10125163 | J22: =I22 -> 0.10125163
A24: Revenue:
A25: Subscription services | B25: 324 | C25: 500 | D25: 706 | E25: 936 | F25: =(F9*F13)/1000000 -> 1415.0949 | G25: =(G9*G13)/1000000 -> 1700.2034 | H25: =(H9*H13)/1000000 -> 1988.9876 | I25: =(I9*I13)/1000000 -> 2248.0582 | J25: =(J9*J13)/1000000 -> 2484.2837
A26: Financial technology solutions | B26: 2268 | C26: 3189 | D26: 4053 | E26: 5037 | F26: =F18*F13 -> 5964.3608 | G26: =G18*G13 -> 6739.697 | H26: =H18*H13 -> 7485.7722 | I26: =I18*I13 -> 8109.9871 | J26: =J18*J13 -> 8673.7083
A27: Hardware and professional services | B27: 139 | C27: 176 | D27: 201 | E27: 180 | F27: =E27*(1+F22) -> 198.22529 | G27: =F27*(1+G22) -> 218.29593 | H27: =G27*(1+H22) -> 240.39875 | I27: =H27*(1+I22) -> 264.73951 | J27: =I27*(1+J22) -> 291.54482
A28: Total revenue | B28: =SUM(B25:B27) -> 2731 | C28: =SUM(C25:C27) -> 3865 | D28: =SUM(D25:D27) -> 4960 | E28: =SUM(E25:E27) -> 6153 | F28: =SUM(F25:F27) -> 7577.681 | G28: =SUM(G25:G27) -> 8658.1963 | H28: =SUM(H25:H27) -> 9715.1586 | I28: =SUM(I25:I27) -> 10622.785 | J28: =SUM(J25:J27) -> 11449.537
A30: Revenue Growth YoY:
A31: Subscription services | C31: =C25/B25-1 -> 0.54320988 | D31: =D25/C25-1 -> 0.412 | E31: =E25/D25-1 -> 0.32577904 | F31: =F25/E25-1 -> 0.5118535 | G31: =G25/F25-1 -> 0.2014766 | H31: =H25/G25-1 -> 0.16985275 | I31: =I25/H25-1 -> 0.1302525 | J31: =J25/I25-1 -> 0.10507977
A32: Financial technology solutions | C32: =C26/B26-1 -> 0.40608466 | D32: =D26/C26-1 -> 0.27093133 | E32: =E26/D26-1 -> 0.24278312 | F32: =F26/E26-1 -> 0.18410976 | G32: =G26/F26-1 -> 0.12999485 | H32: =H26/G26-1 -> 0.11069863 | I32: =I26/H26-1 -> 0.083386831 | J32: =J26/I26-1 -> 0.069509506
A33: Hardware and professional services | C33: =C27/B27-1 -> 0.26618705 | D33: =D27/C27-1 -> 0.14204545 | E33: =E27/D27-1 -> -0.10447761 | F33: =F27/E27-1 -> 0.10125163 | G33: =G27/F27-1 -> 0.10125163 | H33: =H27/G27-1 -> 0.10125163 | I33: =I27/H27-1 -> 0.10125163 | J33: =J27/I27-1 -> 0.10125163
A34: Total Revenue | C34: =C28/B28-1 -> 0.41523252 | D34: =D28/C28-1 -> 0.28331177 | E34: =E28/D28-1 -> 0.24052419 | F34: =F28/E28-1 -> 0.2315425 | G34: =G28/F28-1 -> 0.14259182 | H34: =H28/G28-1 -> 0.1220765 | I34: =I28/H28-1 -> 0.093423714 | J34: =J28/I28-1 -> 0.077828173
A36: Revenue % Breakdown:
A37: Subscription services | B37: =B25/B$28 -> 0.11863786 | C37: =C25/C$28 -> 0.12936611 | D37: =D25/D$28 -> 0.14233871 | E37: =E25/E$28 -> 0.15212092 | F37: =F25/F$28 -> 0.18674511 | G37: =G25/G$28 -> 0.19636923 | H37: =H25/H$28 -> 0.20473033 | I37: =I25/I$28 -> 0.21162607 | J37: =J25/J$28 -> 0.21697678
A38: Financial technology solutions | B38: =B26/B$28 -> 0.83046503 | C38: =C26/C$28 -> 0.82509702 | D38: =D26/D$28 -> 0.8171371 | E38: =E26/E$28 -> 0.81862506 | F38: =F26/F$28 -> 0.78709579 | G38: =G26/G$28 -> 0.77841813 | H38: =H26/H$28 -> 0.77052497 | I38: =I26/I$28 -> 0.76345207 | J38: =J26/J$28 -> 0.75755976
A39: Hardware and professional services | B39: =B27/B$28 -> 0.050897107 | C39: =C27/C$28 -> 0.045536869 | D39: =D27/D$28 -> 0.040524194 | E39: =E27/E$28 -> 0.029254022 | F39: =F27/F$28 -> 0.026159097 | G39: =G27/G$28 -> 0.025212633 | H39: =H27/H$28 -> 0.024744706 | I39: =I27/I$28 -> 0.024921856 | J39: =J27/J$28 -> 0.02546346
A40: Total Revenue | B40: =B28/B$28 -> 1 | C40: =C28/C$28 -> 1 | D40: =D28/D$28 -> 1 | E40: =E28/E$28 -> 1 | F40: =F28/F$28 -> 1 | G40: =G28/G$28 -> 1 | H40: =H28/H$28 -> 1 | I40: =I28/I$28 -> 1 | J40: =J28/J$28 -> 1
A42: ARR | B42: 901 | C42: 1218 | D42: 1626 | E42: 2047 | F42: =F43*F28 -> 2520.9675 | G42: =G43*G28 -> 2880.4368 | H42: =H43*H28 -> 3232.0705 | I42: =I43*I28 -> 3534.0225 | J42: =J43*J28 -> 3809.069
A43: ARR / Total Sales | B43: =B42/B28 -> 0.32991578 | C43: =C42/C28 -> 0.31513583 | D43: =D42/D28 -> 0.32782258 | E43: =E42/E28 -> 0.33268324 | F43: =E43 -> 0.33268324 | G43: =F43 -> 0.33268324 | H43: =G43 -> 0.33268324 | I43: =H43 -> 0.33268324 | J43: =I43 -> 0.33268324
A45: Costs of revenue:
A46: Subscription services | B46: 112 | C46: 166 | D46: 219 | E46: 264 | F46: =F53*F25 -> 377.9029 | G46: =G53*G25 -> 430.23865 | H46: =H53*H25 -> 477.45903 | I46: =I53*I25 -> 512.67256 | J46: =J53*J25 -> 539.21695
A47: Financial technology solutions | B47: 1792 | C47: 2503 | D47: 3175 | E47: 3891 | F47: =F56*F26 -> 4572.3009 | G47: =G56*G26 -> 5130.4173 | H47: =H56*H26 -> 5661.8173 | I47: =I56*I26 -> 6098.417 | J47: =J56*J26 -> 6488.6615
A48: Hardware and professional services | B48: 311 | C48: 357 | D48: 371 | E48: 400 | F48: =F59*F27 -> 440.50065 | G48: =G59*G27 -> 485.10206 | H48: =H59*H27 -> 534.21944 | I48: =I59*I27 -> 588.31003 | J48: =J59*J27 -> 647.87738
A49: Amortization of acquired intangible assets | B49: 5 | C49: 5 | D49: 5 | E49: 5 | F49: 0 | G49: 0 | H49: 0 | I49: 0 | J49: 0
A50: Total costs of revenue | B50: =SUM(B46:B49) -> 2220 | C50: =SUM(C46:C49) -> 3031 | D50: =SUM(D46:D49) -> 3770 | E50: =SUM(E46:E49) -> 4560 | F50: =SUM(F46:F49) -> 5390.7045 | G50: =SUM(G46:G49) -> 6045.758 | H50: =SUM(H46:H49) -> 6673.4958 | I50: =SUM(I46:I49) -> 7199.3996 | J50: =SUM(J46:J49) -> 7675.7558
...

Sheet Assumptions
A1: TOAST, INC.
A2: Core Assumptions
A3: (in millions, except per share amounts)
A5: Year Ended December 31, | B5: 2022 | C5: =B5+1 -> 2023 | D5: =C5+1 -> 2024 | E5: =D5+1 -> 2025 | F5: =E5+1 -> 2026 | G5: =F5+1 -> 2027 | H5: =G5+1 -> 2028 | I5: =H5+1 -> 2029 | J5: =I5+1 -> 2030
A7: INCOME STATEMENT
A8: Sales and marketing- % of sales | B8: ='Income Statement'!B23/'Income Statement'!B$11 -> 0.11680703 | C8: ='Income Statement'!C23/'Income Statement'!C$11 -> 0.10375162 | D8: ='Income Statement'!D23/'Income Statement'!D$11 -> 0.094758065 | E8: ='Income Statement'!E23/'Income Statement'!E$11 -> 0.09280026 | F8: =E8-0.5% -> 0.08780026 | G8: =F8-0.5% -> 0.08280026 | H8: 0.08 | I8: 0.08 | J8: 0.08
A9: Research and development- % of sales | B9: ='Income Statement'!B24/'Income Statement'!B$11 -> 0.10325888 | C9: ='Income Statement'!C24/'Income Statement'!C$11 -> 0.092626132 | D9: ='Income Statement'!D24/'Income Statement'!D$11 -> 0.070766129 | E9: ='Income Statement'!E24/'Income Statement'!E$11 -> 0.060783358 | F9: 0.055 | G9: 0.053 | H9: 0.05 | I9: 0.05 | J9: 0.05
A10: General and administrative- $ | B10: ='Income Statement'!B25 -> 294 | C10: ='Income Statement'!C25 -> 362 | D10: ='Income Statement'!D25 -> 307 | E10: ='Income Statement'!E25 -> 344 | F10: 350 | G10: 375 | H10: 400 | I10: 415 | J10: 420
A11: Restructuring expenses- $ | B11: ='Income Statement'!B26 -> 0 | C11: ='Income Statement'!C26 -> 0 | D11: ='Income Statement'!D26 -> 46 | E11: ='Income Statement'!E26 -> 12 | F11: 0 | G11: 0 | H11: 0 | I11: 0 | J11: 0
A12: Change in fair value of warrant liability- $ | B12: ='Income Statement'!B33 -> 95 | C12: ='Income Statement'!C33 -> 3 | D12: ='Income Statement'!D33 -> -49 | E12: ='Income Statement'!E33 -> 3 | F12: 0 | G12: 0 | H12: 0 | I12: 0 | J12: 0
A13: Change in fair value of derivative liability- $ | B13: ='Income Statement'!B34 -> 0 | C13: ='Income Statement'!C34 -> 0 | D13: ='Income Statement'!D34 -> 0 | E13: ='Income Statement'!E34 -> 0 | F13: 0 | G13: 0 | H13: 0 | I13: 0 | J13: 0
A14: Loss on debt extinguishment- $ | B14: ='Income Statement'!B35 -> 0 | C14: ='Income Statement'!C35 -> 0 | D14: ='Income Statement'!D35 -> 0 | E14: ='Income Statement'!E35 -> 0 | F14: 0 | G14: 0 | H14: 0 | I14: 0 | J14: 0
A15: Other income, net- $ | B15: ='Income Statement'!B36 -> 1 | C15: ='Income Statement'!C36 -> 3 | D15: ='Income Statement'!D36 -> 13 | E15: ='Income Statement'!E36 -> 0 | F15: 0 | G15: 0 | H15: 0 | I15: 0 | J15: 0
A16: ETR | B16: ='Income Statement'!B39/-'Income Statement'!B38 -> 0.0072202166 | C16: ='Income Statement'!C39/-'Income Statement'!C38 -> -0.0081967213 | D16: ='Income Statement'!D39/-'Income Statement'!D38 -> 0.13636364 | E16: ='Income Statement'!E39/-'Income Statement'!E38 -> 0.011560694 | F16: 0.24 | G16: 0.24 | H16: 0.24 | I16: 0.24 | J16: 0.24
A17: Basic WASO | B17: ='Income Statement'!B46 -> 512 | C17: ='Income Statement'!C46 -> 532 | D17: ='Income Statement'!D46 -> 559 | E17: ='Income Statement'!E46 -> 582 | F17: =E17+8 -> 590 | G17: =F17+8 -> 598 | H17: =G17+8 -> 606 | I17: =H17+8 -> 614 | J17: =I17+8 -> 622
A18: Diluted WASO | B18: ='Income Statement'!B47 -> 512 | C18: ='Income Statement'!C47 -> 533 | D18: ='Income Statement'!D47 -> 591 | E18: ='Income Statement'!E47 -> 607 | F18: =E18+8 -> 615 | G18: =F18+8 -> 623 | H18: =G18+8 -> 631 | I18: =H18+8 -> 639 | J18: =I18+8 -> 647
A20: BALANCE SHEET
A21: Marketable securities- $ | B21: =+'Balance Sheet'!B10 -> 474 | C21: =+'Balance Sheet'!C10 -> 519 | D21: =+'Balance Sheet'!D10 -> 514 | E21: =+'Balance Sheet'!E10 -> 638 | F21: 0 | G21: 0 | H21: 0 | I21: 0 | J21: 0
A22: Accounts receivable, net- % of sales | B22: ='Balance Sheet'!B11/'Rev COGS Buildout '!B$28 -> 0.0281948 | C22: ='Balance Sheet'!C11/'Rev COGS Buildout '!C$28 -> 0.017852523 | D22: ='Balance Sheet'!D11/'Rev COGS Buildout '!D$28 -> 0.023185484 | E22: ='Balance Sheet'!E11/'Rev COGS Buildout '!E$28 -> 0.020640338 | F22: 0.02 | G22: 0.02 | H22: 0.02 | I22: 0.02 | J22: 0.02
A23: Inventories, net- % of COGS | B23: ='Balance Sheet'!B12/'Income Statement'!B$18 -> 0.04954955 | C23: ='Balance Sheet'!C12/'Income Statement'!C$18 -> 0.038931046 | D23: ='Balance Sheet'!D12/'Income Statement'!D$18 -> 0.031299735 | E23: ='Balance Sheet'!E12/'Income Statement'!E$18 -> 0.025 | F23: =E23-0.2% -> 0.023 | G23: =F23-0.2% -> 0.021 | H23: 0.02 | I23: 0.02 | J23: 0.02
A24: Other current assets- % of sales | B24: ='Balance Sheet'!B13/'Rev COGS Buildout '!B$28 -> 0.072867082 | C24: ='Balance Sheet'!C13/'Rev COGS Buildout '!C$28 -> 0.067011643 | D24: ='Balance Sheet'!D13/'Rev COGS Buildout '!D$28 -> 0.065524194 | E24: ='Balance Sheet'!E13/'Rev COGS Buildout '!E$28 -> 0.071022266 | F24: 0.065 | G24: 0.065 | H24: 0.065 | I24: 0.065 | J24: 0.065
A26: Operating lease right-of-use assets- $ | B26: ='Balance Sheet'!B17 -> 77 | C26: ='Balance Sheet'!C17 -> 36 | D26: ='Balance Sheet'!D17 -> 25 | E26: ='Balance Sheet'!E17 -> 27 | F26: =E26 -> 27 | G26: =F26 -> 27 | H26: =G26 -> 27 | I26: =H26 -> 27 | J26: =I26 -> 27
A27: Goodwill- $ | B27: ='Balance Sheet'!B19 -> 107 | C27: ='Balance Sheet'!C19 -> 113 | D27: ='Balance Sheet'!D19 -> 113 | E27: ='Balance Sheet'!E19 -> 113 | F27: =E27 -> 113 | G27: =F27 -> 113 | H27: =G27 -> 113 | I27: =H27 -> 113 | J27: =I27 -> 113
A28: Restricted cash- $ | B28: ='Balance Sheet'!B20 -> 28 | C28: ='Balance Sheet'!C20 -> 55 | D28: ='Balance Sheet'!D20 -> 59 | E28: ='Balance Sheet'!E20 -> 71 | F28: 0 | G28: 0 | H28: 0 | I28: 0 | J28: 0
A29: Other non-current assets- % of Sales | B29: ='Balance Sheet'!B21/'Income Statement'!B11 -> 0.019040644 | C29: ='Balance Sheet'!C21/'Income Statement'!C11 -> 0.021474774 | D29: ='Balance Sheet'!D21/'Income Statement'!D11 -> 0.023790323 | E29: ='Balance Sheet'!E21/'Income Statement'!E11 -> 0.023728263 | F29: 0.022 | G29: 0.022 | H29: 0.022 | I29: 0.022 | J29: 0.022
A31: Accounts payable- % of COGS | B31: ='Balance Sheet'!B28/'Income Statement'!B$18 -> 0.013513514 | C31: ='Balance Sheet'!C28/'Income Statement'!C$18 -> 0.010557572 | D31: ='Balance Sheet'!D28/'Income Statement'!D$18 -> 0.0098143236 | E31: ='Balance Sheet'!E28/'Income Statement'!E$18 -> 0.010307018 | F31: 0.01 | G31: 0.01 | H31: 0.01 | I31: 0.01 | J31: 0.01
A32: Deferred revenue- % of Sales | B32: ='Balance Sheet'!B29/'Income Statement'!B11 -> 0.014280483 | C32: ='Balance Sheet'!C29/'Income Statement'!C11 -> 0.010090556 | D32: ='Balance Sheet'!D29/'Income Statement'!D11 -> 0.011895161 | E32: ='Balance Sheet'!E29/'Income Statement'!E11 -> 0.01105152 | F32: 0.01 | G32: 0.01 | H32: 0.01 | I32: 0.01 | J32: 0.01
A33: Accrued expenses and other current liabilities- % of COGS | B33: ='Balance Sheet'!B30/'Income Statement'!B$18 -> 0.19234234 | C33: ='Balance Sheet'!C30/'Income Statement'!C$18 -> 0.19531508 | D33: ='Balance Sheet'!D30/'Income Statement'!D$18 -> 0.18965517 | E33: ='Balance Sheet'!E30/'Income Statement'!E$18 -> 0.1872807 | F33: 0.19 | G33: 0.19 | H33: 0.19 | I33: 0.19 | J33: 0.19
A35: Warrants to purchase common stock- $ | B35: ='Balance Sheet'!B34 -> 68 | C35: ='Balance Sheet'!C34 -> 64 | D35: ='Balance Sheet'!D34 -> 22 | E35: ='Balance Sheet'!E34 -> 19 | F35: =E35 -> 19 | G35: =F35 -> 19 | H35: =G35 -> 19 | I35: =H35 -> 19 | J35: =I35 -> 19
A36: Operating lease liabilities, non-current- $ | B36: ='Balance Sheet'!B35 -> 80 | C36: ='Balance Sheet'!C35 -> 33 | D36: ='Balance Sheet'!D35 -> 24 | E36: ='Balance Sheet'!E35 -> 20 | F36: =E36 -> 20 | G36: =F36 -> 20 | H36: =G36 -> 20 | I36: =H36 -> 20 | J36: =I36 -> 20
A37: Other long-term liabilities- % of COGS | B37: ='Balance Sheet'!B36/'Income Statement'!B18 -> 0.0085585586 | C37: ='Balance Sheet'!C36/'Income Statement'!C18 -> 0.0013196965 | D37: ='Balance Sheet'!D36/'Income Statement'!D18 -> 0.0015915119 | E37: ='Balance Sheet'!E36/'Income Statement'!E18 -> 0.0028508772 | F37: =E37 -> 0.0028508772 | G37: =F37 -> 0.0028508772 | H37: =G37 -> 0.0028508772 | I37: =H37 -> 0.0028508772 | J37: =I37 -> 0.0028508772
A39: Preferred stock- $ | B39: ='Balance Sheet'!B41 -> 0 | C39: ='Balance Sheet'!C41 -> 0 | D39: ='Balance Sheet'!D41 -> 0 | E39: ='Balance Sheet'!E41 -> 0 | F39: =E39 -> 0 | G39: =F39 -> 0 | H39: =G39 -> 0 | I39: =H39 -> 0 | J39: =I39 -> 0
A40: Common stock- $ | B40: ='Balance Sheet'!B42 -> 0 | C40: ='Balance Sheet'!C42 -> 0 | D40: ='Balance Sheet'!D42 -> 0 | E40: ='Balance Sheet'!E42 -> 0 | F40: =E40 -> 0 | G40: =F40 -> 0 | H40: =G40 -> 0 | I40: =H40 -> 0 | J40: =I40 -> 0
A41: Treasury stock- $ | B41: ='Balance Sheet'!B43 -> 0 | C41: ='Balance Sheet'!C43 -> 0 | D41: ='Balance Sheet'!D43 -> 0 | E41: ='Balance Sheet'!E43 -> 0 | F41: =E41 -> 0 | G41: =F41 -> 0 | H41: =G41 -> 0 | I41: =H41 -> 0 | J41: =I41 -> 0
A42: Accumulated other comprehensive income (loss)- $ | B42: ='Balance Sheet'!B44 -> -2 | C42: ='Balance Sheet'!C44 -> 0 | D42: ='Balance Sheet'!D44 -> -1 | E42: ='Balance Sheet'!E44 -> 2 | F42: =E42 -> 2 | G42: =F42 -> 2 | H42: =G42 -> 2 | I42: =H42 -> 2 | J42: =I42 -> 2
A43: Additional paid-in capital- $ | B43: ='Balance Sheet'!B45 -> 2477 | C43: ='Balance Sheet'!C45 -> 2817 | D43: ='Balance Sheet'!D45 -> 3150 | E43: ='Balance Sheet'!E45 -> 3384 | F43: =E43 -> 3384 | G43: =F43 -> 3384 | H43: =G43 -> 3384 | I43: =H43 -> 3384 | J43: =I43 -> 3384
A45: OTHER
A46: Depreciation- % of Prev PPE | C46: ='Cash Flow'!C10/'Balance Sheet'!B16 -> 0.18032787 | D46: ='Cash Flow'!D10/'Balance Sheet'!C16 -> 0.13333333 | E46: ='Cash Flow'!E10/'Balance Sheet'!D16 -> 0.10204082 | F46: 0.09 | G46: 0.08 | H46: 0.07 | I46: 0.06 | J46: 0.06
A47: Amortization- % of Prev Intangibles | C47: ='Cash Flow'!C11/'Balance Sheet'!B18 -> 0.72413793 | D47: ='Cash Flow'!D11/'Balance Sheet'!C18 -> 1.3846154 | E47: ='Cash Flow'!E11/'Balance Sheet'!D18 -> 2.7 | F47: 0.3 | G47: 0.3 | H47: 0.3 | I47: 0.3 | J47: 0.3
A48: CapEx- % of Sales | B48: ='Cash Flow'!B37/-'Income Statement'!B11 -> 0.012083486 | C48: ='Cash Flow'!C37/-'Income Statement'!C11 -> 0.010866753 | D48: ='Cash Flow'!D37/-'Income Statement'!D11 -> 0.010887097 | E48: ='Cash Flow'!E37/-'Income Statement'!E11 -> 0.0086136844 | F48: 0.01 | G48: 0.01 | H48: 0.01 | I48: 0.01 | J48: 0.01
...

Sheet Income Statement
A1: TOAST, INC.
A2: Consolidated Statements of Operations
A3: (in millions, except per share amounts)
A5: Year Ended December 31, | B5: 2022 | C5: =B5+1 -> 2023 | D5: =C5+1 -> 2024 | E5: =D5+1 -> 2025 | F5: =E5+1 -> 2026 | G5: =F5+1 -> 2027 | H5: =G5+1 -> 2028 | I5: =H5+1 -> 2029 | J5: =I5+1 -> 2030
A7: Revenue:
A8: Subscription services | B8: 324 | C8: 500 | D8: 706 | E8: 936 | F8: ='Rev COGS Buildout '!F25 -> 1415.0949 | G8: ='Rev COGS Buildout '!G25 -> 1700.2034 | H8: ='Rev COGS Buildout '!H25 -> 1988.9876 | I8: ='Rev COGS Buildout '!I25 -> 2248.0582 | J8: ='Rev COGS Buildout '!J25 -> 2484.2837
A9: Financial technology solutions | B9: 2268 | C9: 3189 | D9: 4053 | E9: 5037 | F9: ='Rev COGS Buildout '!F26 -> 5964.3608 | G9: ='Rev COGS Buildout '!G26 -> 6739.697 | H9: ='Rev COGS Buildout '!H26 -> 7485.7722 | I9: ='Rev COGS Buildout '!I26 -> 8109.9871 | J9: ='Rev COGS Buildout '!J26 -> 8673.7083
A10: Hardware and professional services | B10: 139 | C10: 176 | D10: 201 | E10: 180 | F10: ='Rev COGS Buildout '!F27 -> 198.22529 | G10: ='Rev COGS Buildout '!G27 -> 218.29593 | H10: ='Rev COGS Buildout '!H27 -> 240.39875 | I10: ='Rev COGS Buildout '!I27 -> 264.73951 | J10: ='Rev COGS Buildout '!J27 -> 291.54482
A11: Total revenue | B11: =SUM(B8:B10) -> 2731 | C11: =SUM(C8:C10) -> 3865 | D11: =SUM(D8:D10) -> 4960 | E11: =SUM(E8:E10) -> 6153 | F11: =SUM(F8:F10) -> 7577.681 | G11: =SUM(G8:G10) -> 8658.1963 | H11: =SUM(H8:H10) -> 9715.1586 | I11: =SUM(I8:I10) -> 10622.785 | J11: =SUM(J8:J10) -> 11449.537
A13: Costs of revenue:
A14: Subscription services | B14: 112 | C14: 166 | D14: 219 | E14: 264 | F14: ='Rev COGS Buildout '!F46 -> 377.9029 | G14: ='Rev COGS Buildout '!G46 -> 430.23865 | H14: ='Rev COGS Buildout '!H46 -> 477.45903 | I14: ='Rev COGS Buildout '!I46 -> 512.67256 | J14: ='Rev COGS Buildout '!J46 -> 539.21695
A15: Financial technology solutions | B15: 1792 | C15: 2503 | D15: 3175 | E15: 3891 | F15: ='Rev COGS Buildout '!F47 -> 4572.3009 | G15: ='Rev COGS Buildout '!G47 -> 5130.4173 | H15: ='Rev COGS Buildout '!H47 -> 5661.8173 | I15: ='Rev COGS Buildout '!I47 -> 6098.417 | J15: ='Rev COGS Buildout '!J47 -> 6488.6615
A16: Hardware and professional services | B16: 311 | C16: 357 | D16: 371 | E16: 400 | F16: ='Rev COGS Buildout '!F48 -> 440.50065 | G16: ='Rev COGS Buildout '!G48 -> 485.10206 | H16: ='Rev COGS Buildout '!H48 -> 534.21944 | I16: ='Rev COGS Buildout '!I48 -> 588.31003 | J16: ='Rev COGS Buildout '!J48 -> 647.87738
A17: Amortization of acquired intangible assets | B17: 5 | C17: 5 | D17: 5 | E17: 5 | F17: ='Rev COGS Buildout '!F49 -> 0 | G17: ='Rev COGS Buildout '!G49 -> 0 | H17: ='Rev COGS Buildout '!H49 -> 0 | I17: ='Rev COGS Buildout '!I49 -> 0 | J17: ='Rev COGS Buildout '!J49 -> 0
A18: Total costs of revenue | B18: =SUM(B14:B17) -> 2220 | C18: =SUM(C14:C17) -> 3031 | D18: =SUM(D14:D17) -> 3770 | E18: =SUM(E14:E17) -> 4560 | F18: =SUM(F14:F17) -> 5390.7045 | G18: =SUM(G14:G17) -> 6045.758 | H18: =SUM(H14:H17) -> 6673.4958 | I18: =SUM(I14:I17) -> 7199.3996 | J18: =SUM(J14:J17) -> 7675.7558
A20: Gross profit | B20: =B11-B18 -> 511 | C20: =C11-C18 -> 834 | D20: =D11-D18 -> 1190 | E20: =E11-E18 -> 1593 | F20: =F11-F18 -> 2186.9765 | G20: =G11-G18 -> 2612.4383 | H20: =H11-H18 -> 3041.6628 | I20: =I11-I18 -> 3423.3852 | J20: =J11-J18 -> 3773.7809
A22: Operating expenses:
A23: Sales and marketing | B23: 319 | C23: 401 | D23: 470 | E23: 571 | F23: =F$11*Assumptions!F8 -> 665.32236 | G23: =G$11*Assumptions!G8 -> 716.90091 | H23: =H$11*Assumptions!H8 -> 777.21269 | I23: =I$11*Assumptions!I8 -> 849.82278 | J23: =J$11*Assumptions!J8 -> 915.96294
A24: Research and development | B24: 282 | C24: 358 | D24: 351 | E24: 374 | F24: =F$11*Assumptions!F9 -> 416.77246 | G24: =G$11*Assumptions!G9 -> 458.8844 | H24: =H$11*Assumptions!H9 -> 485.75793 | I24: =I$11*Assumptions!I9 -> 531.13924 | J24: =J$11*Assumptions!J9 -> 572.47684
A25: General and administrative | B25: 294 | C25: 362 | D25: 307 | E25: 344 | F25: =Assumptions!F10 -> 350 | G25: =Assumptions!G10 -> 375 | H25: =Assumptions!H10 -> 400 | I25: =Assumptions!I10 -> 415 | J25: =Assumptions!J10 -> 420
A26: Restructuring expenses | B26: 0 | C26: 0 | D26: 46 | E26: 12 | F26: =Assumptions!F11 -> 0 | G26: =Assumptions!G11 -> 0 | H26: =Assumptions!H11 -> 0 | I26: =Assumptions!I11 -> 0 | J26: =Assumptions!J11 -> 0
A28: Income (loss) from operations | B28: =B20-B23-B24-B25-B26 -> -384 | C28: =C20-C23-C24-C25-C26 -> -287 | D28: =D20-D23-D24-D25-D26 -> 16 | E28: =E20-E23-E24-E25-E26 -> 292 | F28: =F20-F23-F24-F25-F26 -> 754.88169 | G28: =G20-G23-G24-G25-G26 -> 1061.653 | H28: =H20-H23-H24-H25-H26 -> 1378.6922 | I28: =I20-I23-I24-I25-I26 -> 1627.4232 | J28: =J20-J23-J24-J25-J26 -> 1865.3412
A30: Other income (expenses):
A31: Interest income | B31: 11 | C31: 37 | D31: 42 | E31: 51 | F31: =Calcs!F34 -> 79.64 | G31: =Calcs!G34 -> 98.18251 | H31: =Calcs!H34 -> 113.54308 | I31: =Calcs!I34 -> 130.93345 | J31: =Calcs!J34 -> 152.50625
A32: Interest Expense | B32: 0 | C32: 0 | D32: 0 | E32: 0 | F32: =Calcs!F39 -> 0 | G32: =Calcs!G39 -> 0 | H32: =Calcs!H39 -> 0 | I32: =Calcs!I39 -> 0 | J32: =Calcs!J39 -> 0
A33: Change in fair value of warrant liability | B33: 95 | C33: 3 | D33: -49 | E33: 3 | F33: =Assumptions!F12 -> 0 | G33: =Assumptions!G12 -> 0 | H33: =Assumptions!H12 -> 0 | I33: =Assumptions!I12 -> 0 | J33: =Assumptions!J12 -> 0
A34: Change in fair value of derivative liability | B34: 0 | C34: 0 | D34: 0 | E34: 0 | F34: =Assumptions!F13 -> 0 | G34: =Assumptions!G13 -> 0 | H34: =Assumptions!H13 -> 0 | I34: =Assumptions!I13 -> 0 | J34: =Assumptions!J13 -> 0
A35: Loss on debt extinguishment | B35: 0 | C35: 0 | D35: 0 | E35: 0 | F35: =Assumptions!F14 -> 0 | G35: =Assumptions!G14 -> 0 | H35: =Assumptions!H14 -> 0 | I35: =Assumptions!I14 -> 0 | J35: =Assumptions!J14 -> 0
A36: Other income, net | B36: 1 | C36: 3 | D36: 13 | E36: 0 | F36: =Assumptions!F15 -> 0 | G36: =Assumptions!G15 -> 0 | H36: =Assumptions!H15 -> 0 | I36: =Assumptions!I15 -> 0 | J36: =Assumptions!J15 -> 0
A38: Income (loss) before income taxes | B38: =SUM(B28:B36) -> -277 | C38: =SUM(C28:C36) -> -244 | D38: =SUM(D28:D36) -> 22 | E38: =SUM(E28:E36) -> 346 | F38: =SUM(F28:F36) -> 834.52169 | G38: =SUM(G28:G36) -> 1159.8355 | H38: =SUM(H28:H36) -> 1492.2353 | I38: =SUM(I28:I36) -> 1758.3566 | J38: =SUM(J28:J36) -> 2017.8474
A39: Income tax (expense) benefit | B39: 2 | C39: -2 | D39: -3 | E39: -4 | F39: =-Assumptions!F16*'Income Statement'!F38 -> -200.28521 | G39: =-Assumptions!G16*'Income Statement'!G38 -> -278.36052 | H39: =-Assumptions!H16*'Income Statement'!H38 -> -358.13647 | I39: =-Assumptions!I16*'Income Statement'!I38 -> -422.00559 | J39: =-Assumptions!J16*'Income Statement'!J38 -> -484.28338
A41: Net income (loss) | B41: =SUM(B38:B39) -> -275 | C41: =SUM(C38:C39) -> -246 | D41: =SUM(D38:D39) -> 19 | E41: =SUM(E38:E39) -> 342 | F41: =SUM(F38:F39) -> 634.23649 | G41: =SUM(G38:G39) -> 881.47499 | H41: =SUM(H38:H39) -> 1134.0988 | I41: =SUM(I38:I39) -> 1336.351 | J41: =SUM(J38:J39) -> 1533.564
A43: Basic | B43: =B41/B46 -> -0.53710938 | C43: =C41/C46 -> -0.46240602 | D43: =D41/D46 -> 0.033989267 | E43: =E41/E46 -> 0.58762887 | F43: =F41/F46 -> 1.0749771 | G43: =G41/G46 -> 1.4740384 | H43: =H41/H46 -> 1.8714502 | I43: =I41/I46 -> 2.1764675 | J43: =J41/J46 -> 2.465537
A44: Diluted | B44: =B41/B47 -> -0.53710938 | C44: =C41/C47 -> -0.46153846 | D44: =D41/D47 -> 0.0321489 | E44: =E41/E47 -> 0.56342669 | F44: =F41/F47 -> 1.0312788 | G44: =G41/G47 -> 1.4148876 | H44: =H41/H47 -> 1.797304 | I44: =I41/I47 -> 2.0913162 | J44: =J41/J47 -> 2.370269
A46: Basic | B46: 512 | C46: 532 | D46: 559 | E46: 582 | F46: =Assumptions!F17 -> 590 | G46: =Assumptions!G17 -> 598 | H46: =Assumptions!H17 -> 606 | I46: =Assumptions!I17 -> 614 | J46: =Assumptions!J17 -> 622
A47: Diluted | B47: 512 | C47: 533 | D47: 591 | E47: 607 | F47: =Assumptions!F18 -> 615 | G47: =Assumptions!G18 -> 623 | H47: =Assumptions!H18 -> 631 | I47: =Assumptions!I18 -> 639 | J47: =Assumptions!J18 -> 647

Sheet Balance Sheet
A1: TOAST, INC.
A2: Consolidated Balance Sheets
A3: (in millions, except for number of shares and par value)
A5: December 31, | B5: 2022 | C5: =B5+1 -> 2023 | D5: =C5+1 -> 2024 | E5: =D5+1 -> 2025 | F5: =E5+1 -> 2026 | G5: =F5+1 -> 2027 | H5: =G5+1 -> 2028 | I5: =H5+1 -> 2029 | J5: =I5+1 -> 2030
A7: Assets:
A8: Current Assets:
A9: Cash and cash equivalents | B9: 547 | C9: 605 | D9: 903 | E9: 1353 | F9: =MAX('CFS new'!F41,0) -> 2583.7503 | G9: =MAX('CFS new'!G41,0) -> 3244.0879 | H9: =MAX('CFS new'!H41,0) -> 4091.6704 | I9: =MAX('CFS new'!I41,0) -> 5083.5418 | J9: =MAX('CFS new'!J41,0) -> 6228.4752
A10: Marketable securities | B10: 474 | C10: 519 | D10: 514 | E10: 638 | F10: =Assumptions!F21 -> 0 | G10: =Assumptions!G21 -> 0 | H10: =Assumptions!H21 -> 0 | I10: =Assumptions!I21 -> 0 | J10: =Assumptions!J21 -> 0
A11: Accounts receivable, net | B11: 77 | C11: 69 | D11: 115 | E11: 127 | F11: =Assumptions!F22*'Income Statement'!F11 -> 151.55362 | G11: =Assumptions!G22*'Income Statement'!G11 -> 173.16393 | H11: =Assumptions!H22*'Income Statement'!H11 -> 194.30317 | I11: =Assumptions!I22*'Income Statement'!I11 -> 212.4557 | J11: =Assumptions!J22*'Income Statement'!J11 -> 228.99073
A12: Inventories, net | B12: 110 | C12: 118 | D12: 118 | E12: 114 | F12: =Assumptions!F23*'Income Statement'!F18 -> 123.9862 | G12: =Assumptions!G23*'Income Statement'!G18 -> 126.96092 | H12: =Assumptions!H23*'Income Statement'!H18 -> 133.46992 | I12: =Assumptions!I23*'Income Statement'!I18 -> 143.98799 | J12: =Assumptions!J23*'Income Statement'!J18 -> 153.51512
A13: Other current assets | B13: 199 | C13: 259 | D13: 325 | E13: 437 | F13: =Assumptions!F24*'Income Statement'!F11 -> 492.54927 | G13: =Assumptions!G24*'Income Statement'!G11 -> 562.78276 | H13: =Assumptions!H24*'Income Statement'!H11 -> 631.48531 | I13: =Assumptions!I24*'Income Statement'!I11 -> 690.48101 | J13: =Assumptions!J24*'Income Statement'!J11 -> 744.21989
A14: Total current assets | B14: =SUM(B9:B13) -> 1407 | C14: =SUM(C9:C13) -> 1570 | D14: =SUM(D9:D13) -> 1975 | E14: =SUM(E9:E13) -> 2669 | F14: =SUM(F9:F13) -> 3351.8393 | G14: =SUM(G9:G13) -> 4106.9955 | H14: =SUM(H9:H13) -> 5050.9288 | I14: =SUM(I9:I13) -> 6130.4665 | J14: =SUM(J9:J13) -> 7355.201
A16: Property and equipment, net | B16: 61 | C16: 75 | D16: 98 | E16: 105 | F16: =Calcs!F11 -> 171.32681 | G16: =Calcs!G11 -> 244.20263 | H16: =Calcs!H11 -> 324.26003 | I16: =Calcs!I11 -> 411.03228 | J16: =Calcs!J11 -> 500.86571
A17: Operating lease right-of-use assets | B17: 77 | C17: 36 | D17: 25 | E17: 27 | F17: =Assumptions!F26 -> 27 | G17: =Assumptions!G26 -> 27 | H17: =Assumptions!H26 -> 27 | I17: =Assumptions!I26 -> 27 | J17: =Assumptions!J26 -> 27
A18: Intangible assets, net | B18: 29 | C18: 26 | D18: 20 | E18: 14 | F18: =Calcs!F17 -> 9.8 | G18: =Calcs!G17 -> 6.86 | H18: =Calcs!H17 -> 4.802 | I18: =Calcs!I17 -> 3.3614 | J18: =Calcs!J17 -> 2.35298
A19: Goodwill | B19: 107 | C19: 113 | D19: 113 | E19: 113 | F19: =Assumptions!F27 -> 113 | G19: =Assumptions!G27 -> 113 | H19: =Assumptions!H27 -> 113 | I19: =Assumptions!I27 -> 113 | J19: =Assumptions!J27 -> 113
A20: Restricted cash | B20: 28 | C20: 55 | D20: 59 | E20: 71 | F20: =Assumptions!F28 -> 0 | G20: =Assumptions!G28 -> 0 | H20: =Assumptions!H28 -> 0 | I20: =Assumptions!I28 -> 0 | J20: =Assumptions!J28 -> 0
A21: Other non-current assets | B21: 52 | C21: 83 | D21: 118 | E21: 146 | F21: =Assumptions!F29*'Income Statement'!F11 -> 166.70898 | G21: =Assumptions!G29*'Income Statement'!G11 -> 190.48032 | H21: =Assumptions!H29*'Income Statement'!H11 -> 213.73349 | I21: =Assumptions!I29*'Income Statement'!I11 -> 233.70127 | J21: =Assumptions!J29*'Income Statement'!J11 -> 251.88981
A22: Total non-current assets | B22: =SUM(B16:B21) -> 354 | C22: =SUM(C16:C21) -> 388 | D22: =SUM(D16:D21) -> 433 | E22: =SUM(E16:E21) -> 476 | F22: =SUM(F16:F21) -> 487.83579 | G22: =SUM(G16:G21) -> 581.54295 | H22: =SUM(H16:H21) -> 682.79552 | I22: =SUM(I16:I21) -> 788.09494 | J22: =SUM(J16:J21) -> 895.1085
A23: Total assets | B23: =SUM(B22,B14) -> 1761 | C23: =SUM(C22,C14) -> 1958 | D23: =SUM(D22,D14) -> 2408 | E23: =SUM(E22,E14) -> 3145 | F23: =SUM(F22,F14) -> 3839.6751 | G23: =SUM(G22,G14) -> 4688.5385 | H23: =SUM(H22,H14) -> 5733.7243 | I23: =SUM(I22,I14) -> 6918.5614 | J23: =SUM(J22,J14) -> 8250.3094
A25: Liabilities and Stockholders' Equity
A26: Current liabilities:
A27: Revolver | B27: 0 | C27: 0 | D27: 0 | E27: 0 | F27: =-MIN('CFS new'!F41,0) -> 0 | G27: =-MIN('CFS new'!G41,0) -> 0 | H27: =-MIN('CFS new'!H41,0) -> 0 | I27: =-MIN('CFS new'!I41,0) -> 0 | J27: =-MIN('CFS new'!J41,0) -> 0
A28: Accounts payable | B28: 30 | C28: 32 | D28: 37 | E28: 47 | F28: =Assumptions!F31*'Income Statement'!F18 -> 53.907045 | G28: =Assumptions!G31*'Income Statement'!G18 -> 60.45758 | H28: =Assumptions!H31*'Income Statement'!H18 -> 66.734958 | I28: =Assumptions!I31*'Income Statement'!I18 -> 71.993996 | J28: =Assumptions!J31*'Income Statement'!J18 -> 76.757558
A29: Deferred revenue | B29: 39 | C29: 39 | D29: 59 | E29: 68 | F29: =Assumptions!F32*'Income Statement'!F11 -> 75.77681 | G29: =Assumptions!G32*'Income Statement'!G11 -> 86.581963 | H29: =Assumptions!H32*'Income Statement'!H11 -> 97.151586 | I29: =Assumptions!I32*'Income Statement'!I11 -> 106.22785 | J29: =Assumptions!J32*'Income Statement'!J11 -> 114.49537
A30: Accrued expenses and other current liabilities | B30: 427 | C30: 592 | D30: 715 | E30: 854 | F30: =Assumptions!F33*'Income Statement'!F18 -> 1024.2339 | G30: =Assumptions!G33*'Income Statement'!G18 -> 1148.694 | H30: =Assumptions!H33*'Income Statement'!H18 -> 1267.9642 | I30: =Assumptions!I33*'Income Statement'!I18 -> 1367.8859 | J30: =Assumptions!J33*'Income Statement'!J18 -> 1458.3936
A31: Total current liabilities | B31: =SUM(B27:B30) -> 496 | C31: =SUM(C27:C30) -> 663 | D31: =SUM(D27:D30) -> 811 | E31: =SUM(E27:E30) -> 969 | F31: =SUM(F27:F30) -> 1153.9177 | G31: =SUM(G27:G30) -> 1295.7336 | H31: =SUM(H27:H30) -> 1431.8507 | I31: =SUM(I27:I30) -> 1546.1078 | J31: =SUM(J27:J30) -> 1649.6465
A33: LT Debt | B33: 0 | C33: 0 | D33: 0 | E33: 0 | F33: =Calcs!F29 -> 0 | G33: =Calcs!G29 -> 0 | H33: =Calcs!H29 -> 0 | I33: =Calcs!I29 -> 0 | J33: =Calcs!J29 -> 0
A34: Warrants to purchase common stock | B34: 68 | C34: 64 | D34: 22 | E34: 19 | F34: =Assumptions!F35 -> 19 | G34: =Assumptions!G35 -> 19 | H34: =Assumptions!H35 -> 19 | I34: =Assumptions!I35 -> 19 | J34: =Assumptions!J35 -> 19
A35: Operating lease liabilities, non-current | B35: 80 | C35: 33 | D35: 24 | E35: 20 | F35: =Assumptions!F36 -> 20 | G35: =Assumptions!G36 -> 20 | H35: =Assumptions!H36 -> 20 | I35: =Assumptions!I36 -> 20 | J35: =Assumptions!J36 -> 20
A36: Other long-term liabilities | B36: 19 | C36: 4 | D36: 6 | E36: 13 | F36: =Assumptions!F37*'Income Statement'!F18 -> 15.368237 | G36: =Assumptions!G37*'Income Statement'!G18 -> 17.235714 | H36: =Assumptions!H37*'Income Statement'!H18 -> 19.025317 | I36: =Assumptions!I37*'Income Statement'!I18 -> 20.524604 | J36: =Assumptions!J37*'Income Statement'!J18 -> 21.882637
A37: Total long-term liabilities | B37: =SUM(B33:B36) -> 167 | C37: =SUM(C33:C36) -> 101 | D37: =SUM(D33:D36) -> 52 | E37: =SUM(E33:E36) -> 52 | F37: =SUM(F33:F36) -> 54.368237 | G37: =SUM(G33:G36) -> 56.235714 | H37: =SUM(H33:H36) -> 58.025317 | I37: =SUM(I33:I36) -> 59.524604 | J37: =SUM(J33:J36) -> 60.882637
A38: Total liabilities | B38: =B37+B31 -> 663 | C38: =C37+C31 -> 764 | D38: =D37+D31 -> 863 | E38: =E37+E31 -> 1021 | F38: =F37+F31 -> 1208.2859 | G38: =G37+G31 -> 1351.9693 | H38: =H37+H31 -> 1489.8761 | I38: =I37+I31 -> 1605.6324 | J38: =J37+J31 -> 1710.5292
A40: Stockholders' Equity:
A41: Preferred stock | B41: 0 | C41: 0 | D41: 0 | E41: 0 | F41: =Assumptions!F39 -> 0 | G41: =Assumptions!G39 -> 0 | H41: =Assumptions!H39 -> 0 | I41: =Assumptions!I39 -> 0 | J41: =Assumptions!J39 -> 0
A42: Common stock | B42: 0 | C42: 0 | D42: 0 | E42: 0 | F42: =Assumptions!F40 -> 0 | G42: =Assumptions!G40 -> 0 | H42: =Assumptions!H40 -> 0 | I42: =Assumptions!I40 -> 0 | J42: =Assumptions!J40 -> 0
A43: Treasury stock | B43: 0 | C43: 0 | D43: 0 | E43: 0 | F43: =Assumptions!F41 -> 0 | G43: =Assumptions!G41 -> 0 | H43: =Assumptions!H41 -> 0 | I43: =Assumptions!I41 -> 0 | J43: =Assumptions!J41 -> 0
A44: Accumulated other comprehensive income (loss) | B44: -2 | C44: 0 | D44: -1 | E44: 2 | F44: =Assumptions!F42 -> 2 | G44: =Assumptions!G42 -> 2 | H44: =Assumptions!H42 -> 2 | I44: =Assumptions!I42 -> 2 | J44: =Assumptions!J42 -> 2
A45: Additional paid-in capital | B45: 2477 | C45: 2817 | D45: 3150 | E45: 3384 | F45: =Assumptions!F43 -> 3384 | G45: =Assumptions!G43 -> 3384 | H45: =Assumptions!H43 -> 3384 | I45: =Assumptions!I43 -> 3384 | J45: =Assumptions!J43 -> 3384
A46: Accumulated deficit | B46: -1377 | C46: -1623 | D46: -1604 | E46: -1262 | F46: =Calcs!F23 -> -754.61081 | G46: =Calcs!G23 -> -49.430821 | H46: =Calcs!H23 -> 857.84823 | I46: =Calcs!I23 -> 1926.9291 | J46: =Calcs!J23 -> 3153.7803
...

Sheet Cash Flow
A1: TOAST, INC.
A2: Consolidated Statements of Cash Flows
A3: (in millions)
A5: Year Ended December 31, | B5: 2022 | C5: 2023 | D5: 2024 | E5: 2025
A7: Cash flows from operating activities:
A8: Net income (loss) | B8: ='Income Statement'!B41 -> -275 | C8: ='Income Statement'!C41 -> -246 | D8: ='Income Statement'!D41 -> 19 | E8: ='Income Statement'!E41 -> 342
A9: Adjustments to reconcile net income (loss) to net cash provided by (used in) operating activities:
A10: Depreciation | B10: 8 | C10: 11 | D10: 10 | E10: 10
A11: Amortization | B11: 16 | C11: 21 | D11: 36 | E11: 54
A12: Stock-based compensation expense | B12: 228 | C12: 277 | D12: 253 | E12: 242
A13: Amortization of deferred contract acquisition costs | B13: 44 | C13: 62 | D13: 82 | E13: 99
A14: Change in fair value of derivative liability | B14: 0 | C14: 0 | D14: 0 | E14: 0
A15: Change in fair value of warrant liability | B15: -95 | C15: -3 | D15: 49 | E15: -3
A16: Loss on debt extinguishment | B16: 0 | C16: 0 | D16: 0 | E16: 0
A17: Credit loss expense | B17: 34 | C17: 64 | D17: 70 | E17: 91
A18: Non-cash interest on convertible notes | B18: 0 | C18: 0 | D18: 0 | E18: 0
A19: Stock-based charitable contribution expense | B19: 10 | C19: 10 | D19: 5 | E19: 6
A20: Asset impairments | B20: 0 | C20: 15 | D20: 5 | E20: 3
A21: Gain on warrant extinguishment | B21: 0 | C21: 0 | D21: -14 | E21: 0
A22: Other non-cash items | B22: 3 | C22: -17 | D22: -7 | E22: 8
A23: Changes in operating assets and liabilities:
A24: Accounts receivable, net | B24: -35 | C24: -3 | D24: -72 | E24: -33
A25: Other current assets | B25: -36 | C25: -12 | D25: -15 | E25: -52
A26: Deferred contract acquisition costs | B26: -71 | C26: -107 | D26: -130 | E26: -147
A27: Inventories, net | B27: -68 | C27: -7 | D27: 0 | E27: 4
A28: Accounts payable | B28: -11 | C28: 1 | D28: 5 | E28: 11
A29: Accrued expenses and other current liabilities | B29: 116 | C29: 81 | D29: 48 | E29: 21
A30: Deferred revenue | B30: -11 | C30: -5 | D30: 23 | E30: 6
A31: Operating lease right-of-use assets and operating lease liabilities, net | B31: 0 | C31: 1 | D31: -4 | E31: -6
A32: Other assets and liabilities | B32: -13 | C32: -8 | D32: -3 | E32: 5
A33: Net cash provided by (used in) operating activities | B33: =SUM(B8:B32) -> -156 | C33: =SUM(C8:C32) -> 135 | D33: =SUM(D8:D32) -> 360 | E33: =SUM(E8:E32) -> 661
A35: Cash flows from investing activities:
A36: Cash paid for acquisition, net of cash acquired | B36: -46 | C36: -9 | D36: 0 | E36: 0
A37: Capital expenditures | B37: -33 | C37: -42 | D37: -54 | E37: -53
A38: Purchases of marketable securities | B38: -434 | C38: -623 | D38: -473 | E38: -633
A39: Proceeds from the sale of marketable securities | B39: 46 | C39: 35 | D39: 126 | E39: 178
A40: Maturities of marketable securities | B40: 369 | C40: 556 | D40: 362 | E40: 336
A41: Other investing activities | B41: 0 | C41: -3 | D41: 0 | E41: 0
A42: Net cash used in investing activities | B42: =SUM(B36:B41) -> -98 | C42: =SUM(C36:C41) -> -86 | D42: =SUM(D36:D41) -> -39 | E42: =SUM(E36:E41) -> -172
A44: Cash flows from financing activities:
...

Sheet CFS new
A1: TOAST, INC.
A2: Forecasted Cash Flow
A3: (in millions)
A5: Year Ended December 31, | B5: 2022 | C5: =B5+1 -> 2023 | D5: =C5+1 -> 2024 | E5: =D5+1 -> 2025 | F5: =E5+1 -> 2026 | G5: =F5+1 -> 2027 | H5: =G5+1 -> 2028 | I5: =H5+1 -> 2029 | J5: =I5+1 -> 2030
A7: Net Income | F7: ='Income Statement'!F41 -> 634.23649 | G7: ='Income Statement'!G41 -> 881.47499 | H7: ='Income Statement'!H41 -> 1134.0988 | I7: ='Income Statement'!I41 -> 1336.351 | J7: ='Income Statement'!J41 -> 1533.564
A8: D&A | F8: =Calcs!F9+Calcs!F15 -> 13.65 | G8: =Calcs!G9+Calcs!G15 -> 16.646145 | H8: =Calcs!H9+Calcs!H15 -> 19.152184 | I8: =Calcs!I9+Calcs!I15 -> 20.896202 | J8: =Calcs!J9+Calcs!J15 -> 25.670357
A9: Accounts receivable, net | F9: ='Balance Sheet'!E11-'Balance Sheet'!F11 -> -24.55362 | G9: ='Balance Sheet'!F11-'Balance Sheet'!G11 -> -21.610306 | H9: ='Balance Sheet'!G11-'Balance Sheet'!H11 -> -21.139245 | I9: ='Balance Sheet'!H11-'Balance Sheet'!I11 -> -18.152524 | J9: ='Balance Sheet'!I11-'Balance Sheet'!J11 -> -16.535039
A10: Inventories, net | F10: ='Balance Sheet'!E12-'Balance Sheet'!F12 -> -9.9862035 | G10: ='Balance Sheet'!F12-'Balance Sheet'!G12 -> -2.9747147 | H10: ='Balance Sheet'!G12-'Balance Sheet'!H12 -> -6.5089973 | I10: ='Balance Sheet'!H12-'Balance Sheet'!I12 -> -10.518077 | J10: ='Balance Sheet'!I12-'Balance Sheet'!J12 -> -9.5271236
A11: Other current assets | F11: ='Balance Sheet'!E13-'Balance Sheet'!F13 -> -55.549266 | G11: ='Balance Sheet'!F13-'Balance Sheet'!G13 -> -70.233495 | H11: ='Balance Sheet'!G13-'Balance Sheet'!H13 -> -68.702548 | I11: ='Balance Sheet'!H13-'Balance Sheet'!I13 -> -58.995703 | J11: ='Balance Sheet'!I13-'Balance Sheet'!J13 -> -53.738876
A12: Operating lease right-of-use assets | F12: ='Balance Sheet'!E17-'Balance Sheet'!F17 -> 0 | G12: ='Balance Sheet'!F17-'Balance Sheet'!G17 -> 0 | H12: ='Balance Sheet'!G17-'Balance Sheet'!H17 -> 0 | I12: ='Balance Sheet'!H17-'Balance Sheet'!I17 -> 0 | J12: ='Balance Sheet'!I17-'Balance Sheet'!J17 -> 0
A13: Goodwill | F13: ='Balance Sheet'!E19-'Balance Sheet'!F19 -> 0 | G13: ='Balance Sheet'!F19-'Balance Sheet'!G19 -> 0 | H13: ='Balance Sheet'!G19-'Balance Sheet'!H19 -> 0 | I13: ='Balance Sheet'!H19-'Balance Sheet'!I19 -> 0 | J13: ='Balance Sheet'!I19-'Balance Sheet'!J19 -> 0
A14: Restricted cash | F14: ='Balance Sheet'!E20-'Balance Sheet'!F20 -> 71 | G14: ='Balance Sheet'!F20-'Balance Sheet'!G20 -> 0 | H14: ='Balance Sheet'!G20-'Balance Sheet'!H20 -> 0 | I14: ='Balance Sheet'!H20-'Balance Sheet'!I20 -> 0 | J14: ='Balance Sheet'!I20-'Balance Sheet'!J20 -> 0
A15: Other non-current assets | F15: ='Balance Sheet'!E21-'Balance Sheet'!F21 -> -20.708982 | G15: ='Balance Sheet'!F21-'Balance Sheet'!G21 -> -23.771337 | H15: ='Balance Sheet'!G21-'Balance Sheet'!H21 -> -23.25317 | I15: ='Balance Sheet'!H21-'Balance Sheet'!I21 -> -19.967776 | J15: ='Balance Sheet'!I21-'Balance Sheet'!J21 -> -18.188543
A16: Accounts payable | F16: ='Balance Sheet'!F28-'Balance Sheet'!E28 -> 6.907045 | G16: ='Balance Sheet'!G28-'Balance Sheet'!F28 -> 6.5505351 | H16: ='Balance Sheet'!H28-'Balance Sheet'!G28 -> 6.2773776 | I16: ='Balance Sheet'!I28-'Balance Sheet'!H28 -> 5.2590383 | J16: ='Balance Sheet'!J28-'Balance Sheet'!I28 -> 4.7635618
A17: Deferred revenue | F17: ='Balance Sheet'!F29-'Balance Sheet'!E29 -> 7.7768101 | G17: ='Balance Sheet'!G29-'Balance Sheet'!F29 -> 10.805153 | H17: ='Balance Sheet'!H29-'Balance Sheet'!G29 -> 10.569623 | I17: ='Balance Sheet'!I29-'Balance Sheet'!H29 -> 9.076262 | J17: ='Balance Sheet'!J29-'Balance Sheet'!I29 -> 8.2675193
A18: Accrued expenses and other current liabilities | F18: ='Balance Sheet'!F30-'Balance Sheet'!E30 -> 170.23385 | G18: ='Balance Sheet'!G30-'Balance Sheet'!F30 -> 124.46017 | H18: ='Balance Sheet'!H30-'Balance Sheet'!G30 -> 119.27018 | I18: ='Balance Sheet'!I30-'Balance Sheet'!H30 -> 99.921727 | J18: ='Balance Sheet'!J30-'Balance Sheet'!I30 -> 90.507675
A19: Operating lease liabilities, non-current | F19: ='Balance Sheet'!F35-'Balance Sheet'!E35 -> 0 | G19: ='Balance Sheet'!G35-'Balance Sheet'!F35 -> 0 | H19: ='Balance Sheet'!H35-'Balance Sheet'!G35 -> 0 | I19: ='Balance Sheet'!I35-'Balance Sheet'!H35 -> 0 | J19: ='Balance Sheet'!J35-'Balance Sheet'!I35 -> 0
A20: Other long-term liabilities | F20: ='Balance Sheet'!F36-'Balance Sheet'!E36 -> 2.3682365 | G20: ='Balance Sheet'!G36-'Balance Sheet'!F36 -> 1.8674771 | H20: ='Balance Sheet'!H36-'Balance Sheet'!G36 -> 1.7896033 | I20: ='Balance Sheet'!I36-'Balance Sheet'!H36 -> 1.4992872 | J20: ='Balance Sheet'!J36-'Balance Sheet'!I36 -> 1.358033
A21: CFFO | F21: =SUM(F7:F20) -> 795.37436 | G21: =SUM(G7:G20) -> 923.21461 | H21: =SUM(H7:H20) -> 1171.5538 | I21: =SUM(I7:I20) -> 1365.3695 | J21: =SUM(J7:J20) -> 1566.1416
A23: CapEx | F23: =-Calcs!F10 -> -75.77681 | G23: =-Calcs!G10 -> -86.581963 | H23: =-Calcs!H10 -> -97.151586 | I23: =-Calcs!I10 -> -106.22785 | J23: =-Calcs!J10 -> -114.49537
A24: Additions to intangibles | F24: =-Calcs!F16 -> 0 | G24: =-Calcs!G16 -> 0 | H24: =-Calcs!H16 -> 0 | I24: =-Calcs!I16 -> 0 | J24: =-Calcs!J16 -> 0
A25: Marketable security change | F25: ='Balance Sheet'!E10-'Balance Sheet'!F10 -> 638 | G25: ='Balance Sheet'!F10-'Balance Sheet'!G10 -> 0 | H25: ='Balance Sheet'!G10-'Balance Sheet'!H10 -> 0 | I25: ='Balance Sheet'!H10-'Balance Sheet'!I10 -> 0 | J25: ='Balance Sheet'!I10-'Balance Sheet'!J10 -> 0
A26: CFFI | F26: =SUM(F23:F25) -> 562.22319 | G26: =SUM(G23:G25) -> -86.581963 | H26: =SUM(H23:H25) -> -97.151586 | I26: =SUM(I23:I25) -> -106.22785 | J26: =SUM(J23:J25) -> -114.49537
A28: Warrant repurchase change | F28: ='Balance Sheet'!F34-'Balance Sheet'!E34 -> 0 | G28: ='Balance Sheet'!G34-'Balance Sheet'!F34 -> 0 | H28: ='Balance Sheet'!H34-'Balance Sheet'!G34 -> 0 | I28: ='Balance Sheet'!I34-'Balance Sheet'!H34 -> 0 | J28: ='Balance Sheet'!J34-'Balance Sheet'!I34 -> 0
A29: Preferred stock | F29: ='Balance Sheet'!F41-'Balance Sheet'!E41 -> 0 | G29: ='Balance Sheet'!G41-'Balance Sheet'!F41 -> 0 | H29: ='Balance Sheet'!H41-'Balance Sheet'!G41 -> 0 | I29: ='Balance Sheet'!I41-'Balance Sheet'!H41 -> 0 | J29: ='Balance Sheet'!J41-'Balance Sheet'!I41 -> 0
A30: Common stock | F30: ='Balance Sheet'!F42-'Balance Sheet'!E42 -> 0 | G30: ='Balance Sheet'!G42-'Balance Sheet'!F42 -> 0 | H30: ='Balance Sheet'!H42-'Balance Sheet'!G42 -> 0 | I30: ='Balance Sheet'!I42-'Balance Sheet'!H42 -> 0 | J30: ='Balance Sheet'!J42-'Balance Sheet'!I42 -> 0
A31: Treasury stock | F31: ='Balance Sheet'!F43-'Balance Sheet'!E43 -> 0 | G31: ='Balance Sheet'!G43-'Balance Sheet'!F43 -> 0 | H31: ='Balance Sheet'!H43-'Balance Sheet'!G43 -> 0 | I31: ='Balance Sheet'!I43-'Balance Sheet'!H43 -> 0 | J31: ='Balance Sheet'!J43-'Balance Sheet'!I43 -> 0
A32: Accumulated other comprehensive income (loss) | F32: ='Balance Sheet'!F44-'Balance Sheet'!E44 -> 0 | G32: ='Balance Sheet'!G44-'Balance Sheet'!F44 -> 0 | H32: ='Balance Sheet'!H44-'Balance Sheet'!G44 -> 0 | I32: ='Balance Sheet'!I44-'Balance Sheet'!H44 -> 0 | J32: ='Balance Sheet'!J44-'Balance Sheet'!I44 -> 0
A33: Additional paid-in capital | F33: ='Balance Sheet'!F45-'Balance Sheet'!E45 -> 0 | G33: ='Balance Sheet'!G45-'Balance Sheet'!F45 -> 0 | H33: ='Balance Sheet'!H45-'Balance Sheet'!G45 -> 0 | I33: ='Balance Sheet'!I45-'Balance Sheet'!H45 -> 0 | J33: ='Balance Sheet'!J45-'Balance Sheet'!I45 -> 0
A34: Debt Issuance | F34: =Calcs!F28 -> 0 | G34: =Calcs!G28 -> 0 | H34: =Calcs!H28 -> 0 | I34: =Calcs!I28 -> 0 | J34: =Calcs!J28 -> 0
A35: Debt Repayment | F35: =-Calcs!F27 -> 0 | G35: =-Calcs!G27 -> 0 | H35: =-Calcs!H27 -> 0 | I35: =-Calcs!I27 -> 0 | J35: =-Calcs!J27 -> 0
A36: Shareholder return | F36: =-Calcs!F21 -> -126.8473 | G36: =-Calcs!G21 -> -176.295 | H36: =-Calcs!H21 -> -226.81976 | I36: =-Calcs!I21 -> -267.27021 | J36: =-Calcs!J21 -> -306.71281
A37: CFFF | F37: =SUM(F28:F36) -> -126.8473 | G37: =SUM(G28:G36) -> -176.295 | H37: =SUM(H28:H36) -> -226.81976 | I37: =SUM(I28:I36) -> -267.27021 | J37: =SUM(J28:J36) -> -306.71281
A39: Change in cash | F39: =SUM(F37,F26,F21) -> 1230.7503 | G39: =SUM(G37,G26,G21) -> 660.33765 | H39: =SUM(H37,H26,H21) -> 847.58247 | I39: =SUM(I37,I26,I21) -> 991.87141 | J39: =SUM(J37,J26,J21) -> 1144.9334
A40: Beginning cash | F40: =E41 -> 1353 | G40: =F41 -> 2583.7503 | H40: =G41 -> 3244.0879 | I40: =H41 -> 4091.6704 | J40: =I41 -> 5083.5418
A41: Ending cash | E41: ='Balance Sheet'!E9 -> 1353 | F41: =SUM(F39:F40) -> 2583.7503 | G41: =SUM(G39:G40) -> 3244.0879 | H41: =SUM(H39:H40) -> 4091.6704 | I41: =SUM(I39:I40) -> 5083.5418 | J41: =SUM(J39:J40) -> 6228.4752

Sheet Calcs
A1: TOAST, INC.
A2: Calculations
A3: (in millions, except per share amounts)
A5: Year Ended December 31, | B5: 2022 | C5: =B5+1 -> 2023 | D5: =C5+1 -> 2024 | E5: =D5+1 -> 2025 | F5: =E5+1 -> 2026 | G5: =F5+1 -> 2027 | H5: =G5+1 -> 2028 | I5: =H5+1 -> 2029 | J5: =I5+1 -> 2030
A7: PPE Schedule
A8: Beginning | F8: =E11 -> 105 | G8: =F11 -> 171.32681 | H8: =G11 -> 244.20263 | I8: =H11 -> 324.26003 | J8: =I11 -> 411.03228
A9: Depreciation | F9: =Assumptions!F46*Calcs!E11 -> 9.45 | G9: =Assumptions!G46*Calcs!F11 -> 13.706145 | H9: =Assumptions!H46*Calcs!G11 -> 17.094184 | I9: =Assumptions!I46*Calcs!H11 -> 19.455602 | J9: =Assumptions!J46*Calcs!I11 -> 24.661937
A10: CapEx | F10: =Assumptions!F48*'Income Statement'!F11 -> 75.77681 | G10: =Assumptions!G48*'Income Statement'!G11 -> 86.581963 | H10: =Assumptions!H48*'Income Statement'!H11 -> 97.151586 | I10: =Assumptions!I48*'Income Statement'!I11 -> 106.22785 | J10: =Assumptions!J48*'Income Statement'!J11 -> 114.49537
A11: Ending | E11: ='Balance Sheet'!E16 -> 105 | F11: =F8-F9+F10 -> 171.32681 | G11: =G8-G9+G10 -> 244.20263 | H11: =H8-H9+H10 -> 324.26003 | I11: =I8-I9+I10 -> 411.03228 | J11: =J8-J9+J10 -> 500.86571
A13: Intangibles Schedule
A14: Beginning | F14: =E17 -> 14 | G14: =F17 -> 9.8 | H14: =G17 -> 6.86 | I14: =H17 -> 4.802 | J14: =I17 -> 3.3614
A15: Amortization | F15: =E17*Assumptions!F47 -> 4.2 | G15: =F17*Assumptions!G47 -> 2.94 | H15: =G17*Assumptions!H47 -> 2.058 | I15: =H17*Assumptions!I47 -> 1.4406 | J15: =I17*Assumptions!J47 -> 1.00842
A16: Additions to | F16: =Assumptions!F49 -> 0 | G16: =Assumptions!G49 -> 0 | H16: =Assumptions!H49 -> 0 | I16: =Assumptions!I49 -> 0 | J16: =Assumptions!J49 -> 0
A17: Ending | E17: ='Balance Sheet'!E18 -> 14 | F17: =F14-F15+F16 -> 9.8 | G17: =G14-G15+G16 -> 6.86 | H17: =H14-H15+H16 -> 4.802 | I17: =I14-I15+I16 -> 3.3614 | J17: =J14-J15+J16 -> 2.35298
A19: RE Schedule
A20: Beginning | F20: =E23 -> -1262 | G20: =F23 -> -754.61081 | H20: =G23 -> -49.430821 | I20: =H23 -> 857.84823 | J20: =I23 -> 1926.9291
A21: Shareholder return | F21: =Assumptions!F50*'Income Statement'!F41 -> 126.8473 | G21: =Assumptions!G50*'Income Statement'!G41 -> 176.295 | H21: =Assumptions!H50*'Income Statement'!H41 -> 226.81976 | I21: =Assumptions!I50*'Income Statement'!I41 -> 267.27021 | J21: =Assumptions!J50*'Income Statement'!J41 -> 306.71281
A22: Net income | F22: ='Income Statement'!F41 -> 634.23649 | G22: ='Income Statement'!G41 -> 881.47499 | H22: ='Income Statement'!H41 -> 1134.0988 | I22: ='Income Statement'!I41 -> 1336.351 | J22: ='Income Statement'!J41 -> 1533.564
A23: Ending | E23: ='Balance Sheet'!E46 -> -1262 | F23: =F20-F21+F22 -> -754.61081 | G23: =G20-G21+G22 -> -49.430821 | H23: =H20-H21+H22 -> 857.84823 | I23: =I20-I21+I22 -> 1926.9291 | J23: =J20-J21+J22 -> 3153.7803
A25: Debt Schedule
A26: Beginning | F26: =E29 -> 0 | G26: =F29 -> 0 | H26: =G29 -> 0 | I26: =H29 -> 0 | J26: =I29 -> 0
A27: Repayments | F27: =Assumptions!F53 -> 0 | G27: =Assumptions!G53 -> 0 | H27: =Assumptions!H53 -> 0 | I27: =Assumptions!I53 -> 0 | J27: =Assumptions!J53 -> 0
A28: Issuance | F28: =Assumptions!F54 -> 0 | G28: =Assumptions!G54 -> 0 | H28: =Assumptions!H54 -> 0 | I28: =Assumptions!I54 -> 0 | J28: =Assumptions!J54 -> 0
A29: Ending | E29: ='Balance Sheet'!E33 -> 0 | F29: =F26-F27+F28 -> 0 | G29: =G26-G27+G28 -> 0 | H29: =H26-H27+H28 -> 0 | I29: =I26-I27+I28 -> 0 | J29: =J26-J27+J28 -> 0
A31: Interest Income Schedule
A32: Cash + marketable securities | E32: ='Balance Sheet'!E9+'Balance Sheet'!E10 -> 1991 | F32: ='Balance Sheet'!F9+'Balance Sheet'!F10 -> 2583.7503 | G32: ='Balance Sheet'!G9+'Balance Sheet'!G10 -> 3244.0879 | H32: ='Balance Sheet'!H9+'Balance Sheet'!H10 -> 4091.6704 | I32: ='Balance Sheet'!I9+'Balance Sheet'!I10 -> 5083.5418 | J32: ='Balance Sheet'!J9+'Balance Sheet'!J10 -> 6228.4752
A33: Rate earned | F33: =Assumptions!F51 -> 0.04 | G33: =Assumptions!G51 -> 0.038 | H33: =Assumptions!H51 -> 0.035 | I33: =Assumptions!I51 -> 0.032 | J33: =Assumptions!J51 -> 0.03
A34: Income | F34: =F33*E32 -> 79.64 | G34: =G33*F32 -> 98.18251 | H34: =H33*G32 -> 113.54308 | I34: =I33*H32 -> 130.93345 | J34: =J33*I32 -> 152.50625
A36: Interest Expense Schedule
A37: Debt | E37: ='Balance Sheet'!E27+'Balance Sheet'!E33 -> 0 | F37: ='Balance Sheet'!F27+'Balance Sheet'!F33 -> 0 | G37: ='Balance Sheet'!G27+'Balance Sheet'!G33 -> 0 | H37: ='Balance Sheet'!H27+'Balance Sheet'!H33 -> 0 | I37: ='Balance Sheet'!I27+'Balance Sheet'!I33 -> 0 | J37: ='Balance Sheet'!J27+'Balance Sheet'!J33 -> 0
A38: Rate payed | F38: =Assumptions!F52 -> 0.06 | G38: =Assumptions!G52 -> 0.06 | H38: =Assumptions!H52 -> 0.06 | I38: =Assumptions!I52 -> 0.06 | J38: =Assumptions!J52 -> 0.06
A39: Expense | F39: =F38*E37 -> 0 | G39: =G38*F37 -> 0 | H39: =H38*G37 -> 0 | I39: =I38*H37 -> 0 | J39: =J38*I37 -> 0

Sheet Metrics
A1: TOAST, INC.
A2: Metrics
A3: (in millions, except per share amounts)
A5: Year Ended December 31, | B5: 2022 | C5: 2023 | D5: 2024 | E5: =D5+1 -> 2025 | F5: =E5+1 -> 2026 | G5: =F5+1 -> 2027 | H5: =G5+1 -> 2028 | I5: =H5+1 -> 2029 | J5: =I5+1 -> 2030
A7: INCOME STATEMENT
A9: EBIT | B9: ='Income Statement'!B20-'Income Statement'!B23-'Income Statement'!B24-'Income Statement'!B25 -> -384 | C9: ='Income Statement'!C20-'Income Statement'!C23-'Income Statement'!C24-'Income Statement'!C25 -> -287 | D9: ='Income Statement'!D20-'Income Statement'!D23-'Income Statement'!D24-'Income Statement'!D25 -> 62 | E9: ='Income Statement'!E20-'Income Statement'!E23-'Income Statement'!E24-'Income Statement'!E25 -> 304 | F9: ='Income Statement'!F20-'Income Statement'!F23-'Income Statement'!F24-'Income Statement'!F25 -> 754.88169 | G9: ='Income Statement'!G20-'Income Statement'!G23-'Income Statement'!G24-'Income Statement'!G25 -> 1061.653 | H9: ='Income Statement'!H20-'Income Statement'!H23-'Income Statement'!H24-'Income Statement'!H25 -> 1378.6922 | I9: ='Income Statement'!I20-'Income Statement'!I23-'Income Statement'!I24-'Income Statement'!I25 -> 1627.4232 | J9: ='Income Statement'!J20-'Income Statement'!J23-'Income Statement'!J24-'Income Statement'!J25 -> 1865.3412
A10: EBITDA | B10: =B9+'Cash Flow'!B10+'Cash Flow'!B11 -> -360 | C10: =C9+'Cash Flow'!C10+'Cash Flow'!C11 -> -255 | D10: =D9+'Cash Flow'!D10+'Cash Flow'!D11 -> 108 | E10: =E9+'Cash Flow'!E10+'Cash Flow'!E11 -> 368 | F10: =F9+'CFS new'!F8 -> 768.53169 | G10: =G9+'CFS new'!G8 -> 1078.2991 | H10: =H9+'CFS new'!H8 -> 1397.8444 | I10: =I9+'CFS new'!I8 -> 1648.3194 | J10: =J9+'CFS new'!J8 -> 1891.0115
A11: Normalized Earnings | B11: =B9+'Income Statement'!B31+'Income Statement'!B39 -> -371 | C11: =C9+'Income Statement'!C31+'Income Statement'!C39 -> -252 | D11: =D9+'Income Statement'!D31+'Income Statement'!D39 -> 101 | E11: =E9+'Income Statement'!E31+'Income Statement'!E39 -> 351 | F11: =F9+'Income Statement'!F31+'Income Statement'!F39 -> 634.23649 | G11: =G9+'Income Statement'!G31+'Income Statement'!G39 -> 881.47499 | H11: =H9+'Income Statement'!H31+'Income Statement'!H39 -> 1134.0988 | I11: =I9+'Income Statement'!I31+'Income Statement'!I39 -> 1336.351 | J11: =J9+'Income Statement'!J31+'Income Statement'!J39 -> 1533.564
A12: Normalized EPS | B12: =B11/'Income Statement'!B47 -> -0.72460938 | C12: =C11/'Income Statement'!C47 -> -0.4727955 | D12: =D11/'Income Statement'!D47 -> 0.17089679 | E12: =E11/'Income Statement'!E47 -> 0.57825371 | F12: =F11/'Income Statement'!F47 -> 1.0312788 | G12: =G11/'Income Statement'!G47 -> 1.4148876 | H12: =H11/'Income Statement'!H47 -> 1.797304 | I12: =I11/'Income Statement'!I47 -> 2.0913162 | J12: =J11/'Income Statement'!J47 -> 2.370269
A14: Growth Rates:
A15: EBIT
A16: EBITDA | C16: =C10/B10-1 -> -0.29166667 | D16: =D10/C10-1 -> -1.4235294 | E16: =E10/D10-1 -> 2.4074074 | F16: =F10/E10-1 -> 1.0884013 | G16: =G10/F10-1 -> 0.40306399 | H16: =H10/G10-1 -> 0.29634192 | I16: =I10/H10-1 -> 0.1791866 | J16: =J10/I10-1 -> 0.14723612
A17: Net Income | C17: =C9/B9-1 -> -0.25260417 | D17: =D9/C9-1 -> -1.2160279 | E17: =E9/D9-1 -> 3.9032258 | F17: =F9/E9-1 -> 1.4831635 | G17: =G9/F9-1 -> 0.40638329 | H17: =H9/G9-1 -> 0.2986279 | I17: =I9/H9-1 -> 0.1804108 | J17: =J9/I9-1 -> 0.14619308
C18: =C11/B11 -> 0.67924528 | D18: =D11/C11 -> -0.40079365 | E18: =E11/D11 -> 3.4752475 | F18: =F11/E11 -> 1.8069416 | G18: =G11/F11 -> 1.3898207 | H18: =H11/G11 -> 1.2865922 | I18: =I11/H11 -> 1.1783374 | J18: =J11/I11 -> 1.1475758
A19: Margins:
A20: EBIT | B20: =B9/'Income Statement'!B11 -> -0.14060784 | C20: =C9/'Income Statement'!C11 -> -0.074256145 | D20: =D9/'Income Statement'!D11 -> 0.0125 | E20: =E9/'Income Statement'!E11 -> 0.049406793 | F20: =F9/'Income Statement'!F11 -> 0.099619091 | G20: =G9/'Income Statement'!G11 -> 0.12261826 | H20: =H9/'Income Statement'!H11 -> 0.14191145 | I20: =I9/'Income Statement'!I11 -> 0.15320118 | J20: =J9/'Income Statement'!J11 -> 0.16291848
A21: EBITDA | B21: =B10/'Income Statement'!B11 -> -0.13181985 | C21: =C10/'Income Statement'!C11 -> -0.065976714 | D21: =D10/'Income Statement'!D11 -> 0.021774194 | E21: =E10/'Income Statement'!E11 -> 0.059808224 | F21: =F10/'Income Statement'!F11 -> 0.10142043 | G21: =G10/'Income Statement'!G11 -> 0.12454085 | H21: =H10/'Income Statement'!H11 -> 0.14388282 | I21: =I10/'Income Statement'!I11 -> 0.15516829 | J21: =J10/'Income Statement'!J11 -> 0.16516053
A22: Net Income | B22: =B11/'Income Statement'!B11 -> -0.13584767 | C22: =C11/'Income Statement'!C11 -> -0.065200517 | D22: =D11/'Income Statement'!D11 -> 0.020362903 | E22: =E11/'Income Statement'!E11 -> 0.057045344 | F22: =F11/'Income Statement'!F11 -> 0.083697966 | G22: =G11/'Income Statement'!G11 -> 0.10180815 | H22: =H11/'Income Statement'!H11 -> 0.11673498 | I22: =I11/'Income Statement'!I11 -> 0.12580044 | J22: =J11/'Income Statement'!J11 -> 0.13394114
A23: Sales and marketing | B23: ='Income Statement'!B23/'Income Statement'!B$11 -> 0.11680703 | C23: ='Income Statement'!C23/'Income Statement'!C$11 -> 0.10375162 | D23: ='Income Statement'!D23/'Income Statement'!D$11 -> 0.094758065 | E23: ='Income Statement'!E23/'Income Statement'!E$11 -> 0.09280026 | F23: ='Income Statement'!F23/'Income Statement'!F$11 -> 0.08780026 | G23: ='Income Statement'!G23/'Income Statement'!G$11 -> 0.08280026 | H23: ='Income Statement'!H23/'Income Statement'!H$11 -> 0.08 | I23: ='Income Statement'!I23/'Income Statement'!I$11 -> 0.08 | J23: ='Income Statement'!J23/'Income Statement'!J$11 -> 0.08
A24: Research and development | B24: ='Income Statement'!B24/'Income Statement'!B$11 -> 0.10325888 | C24: ='Income Statement'!C24/'Income Statement'!C$11 -> 0.092626132 | D24: ='Income Statement'!D24/'Income Statement'!D$11 -> 0.070766129 | E24: ='Income Statement'!E24/'Income Statement'!E$11 -> 0.060783358 | F24: ='Income Statement'!F24/'Income Statement'!F$11 -> 0.055 | G24: ='Income Statement'!G24/'Income Statement'!G$11 -> 0.053 | H24: ='Income Statement'!H24/'Income Statement'!H$11 -> 0.05 | I24: ='Income Statement'!I24/'Income Statement'!I$11 -> 0.05 | J24: ='Income Statement'!J24/'Income Statement'!J$11 -> 0.05
A25: General and administrative | B25: ='Income Statement'!B25/'Income Statement'!B$11 -> 0.10765287 | C25: ='Income Statement'!C25/'Income Statement'!C$11 -> 0.093661061 | D25: ='Income Statement'!D25/'Income Statement'!D$11 -> 0.061895161 | E25: ='Income Statement'!E25/'Income Statement'!E$11 -> 0.055907687 | F25: ='Income Statement'!F25/'Income Statement'!F$11 -> 0.046188273 | G25: ='Income Statement'!G25/'Income Statement'!G$11 -> 0.043311561 | H25: ='Income Statement'!H25/'Income Statement'!H$11 -> 0.041172771 | I25: ='Income Statement'!I25/'Income Statement'!I$11 -> 0.039066969 | J25: ='Income Statement'!J25/'Income Statement'!J$11 -> 0.036682707
A27: Basic WASO Change | C27: ='Income Statement'!C46/'Income Statement'!B46-1 -> 0.0390625 | D27: ='Income Statement'!D46/'Income Statement'!C46-1 -> 0.05075188 | E27: ='Income Statement'!E46/'Income Statement'!D46-1 -> 0.041144902 | F27: ='Income Statement'!F46/'Income Statement'!E46-1 -> 0.013745704 | G27: ='Income Statement'!G46/'Income Statement'!F46-1 -> 0.013559322 | H27: ='Income Statement'!H46/'Income Statement'!G46-1 -> 0.013377926 | I27: ='Income Statement'!I46/'Income Statement'!H46-1 -> 0.01320132 | J27: ='Income Statement'!J46/'Income Statement'!I46-1 -> 0.013029316
